
# Created by Ruins mod version 14.6 Ingame Parser
# authoring Player: ArchNihil

weight=1
embed_into_distance=0
acceptable_target_blocks=
unacceptable_target_blocks=flowing_water,water,flowing_lava,lava
dimensions=169,27,35
allowable_overhang=0
max_leveling=2
leveling_buffer=0
preserve_water=0
preserve_lava=0

rule1=0,100,Railcraft:tile.railcraft.residual.heat-0
rule2=0,100,UndergroundBiomes:igneousStone-7
rule3=0,100,minecraft:dirt-0
rule4=0,100,TwilightForest:tile.TFFirefly-5
rule5=0,100,minecraft:leaves-12
rule6=0,100,minecraft:leaves-4
rule7=0,100,minecraft:grass-0
rule8=0,100,minecraft:log-0
rule9=0,100,BiomesOPlenty:planks-9
rule10=0,100,ExtraUtilities:colorWoodPlanks-13
rule11=0,100,ExtraUtilities:colorWoodPlanks-5
rule12=0,100,BiomesOPlenty:logs1-5
rule13=0,100,BiomesOPlenty:logs1-9
rule14=0,100,BiomesOPlenty:logs1-1
rule15=0,100,minecraft:vine-4
rule16=0,100,minecraft:gravel-0
rule17=0,100,minecraft:water-4
rule18=0,100,minecraft:water-3
rule19=0,100,minecraft:log-4
rule20=0,100,minecraft:vine-12
rule21=0,100,BiomesOPlenty:planks-1
rule22=0,100,minecraft:water-2
rule23=0,100,minecraft:log-8
rule24=0,100,minecraft:water-1
rule25=0,100,minecraft:water-0
rule26=0,100,BiomesOPlenty:logs3-1
rule27=0,100,BiomesOPlenty:cherryStairs-3
rule28=0,100,minecraft:wooden_door-3
rule29=0,100,BiomesOPlenty:cherryStairs-2
rule30=0,100,BiomesOPlenty:woodenDoubleSlab1-1
rule31=0,100,TwilightForest:tile.TFFirefly-1
rule32=0,100,TwilightForest:tile.TFPlant-3
rule33=0,100,minecraft:double_plant-2
rule34=0,100,minecraft:fence-0
rule35=0,100,BiomesOPlenty:moss-8
rule36=0,100,BiomesOPlenty:moss-11
rule37=0,100,TwilightForest:tile.TFFirefly-4
rule38=0,100,minecraft:wooden_door-1
rule39=0,100,minecraft:wooden_door-8
rule40=0,100,minecraft:wooden_door-2
rule41=0,100,minecraft:vine-2
rule42=0,100,minecraft:vine-0
rule43=0,100,minecraft:vine-9
rule44=0,100,minecraft:vine-1
rule45=0,100,Natura:BerryBush-8
rule46=0,100,Natura:BerryBush-12
rule47=0,100,minecraft:double_plant-8
rule48=0,100,BiomesOPlenty:moss-2
rule49=0,100,BiomesOPlenty:moss-10
rule50=0,100,TConstruct:GlassBlock-0
rule51=0,100,minecraft:leaves-0
rule52=0,100,BiomesOPlenty:flowerVine-1
rule53=0,100,BiomesOPlenty:flowerVine-9
rule54=0,100,TwilightForest:tile.TFFirefly-3
rule55=0,100,TwilightForest:tile.TFFirefly-2
rule56=0,100,minecraft:tallgrass-1
rule57=0,100,minecraft:vine-3
rule58=0,100,Natura:BerryBush-9
rule59=0,100,Natura:BerryBush-0
rule60=0,100,BiomesOPlenty:foliage-8
rule61=0,100,BiomesOPlenty:foliage-14
rule62=0,100,BiomesOPlenty:mushrooms-4
rule63=0,100,BiomesOPlenty:foliage-10
rule64=0,100,Natura:BerryBush-10
rule65=0,100,Natura:BerryBush-4
rule66=0,100,minecraft:vine-8
rule67=0,100,minecraft:yellow_flower-0
rule68=0,100,BiomesOPlenty:logs3-9
rule69=0,100,BiomesOPlenty:logs3-5
rule70=0,100,BiomesOPlenty:flowerVine-2
rule71=0,100,TwilightForest:tile.TFFirefly-6
rule72=0,100,BiomesOPlenty:flowerVine-8
rule73=0,100,minecraft:vine-6
rule74=0,100,Natura:Thornvines-4
rule75=0,100,BiomesOPlenty:foliage-2
rule76=0,100,minecraft:planks-0
rule77=0,100,BiomesOPlenty:flowerVine-5
rule78=0,100,minecraft:brown_mushroom-0
rule79=0,100,minecraft:vine-7
rule80=0,100,Natura:Thornvines-3
rule81=0,100,Natura:Thornvines-2
rule82=0,100,BiomesOPlenty:cherryStairs-1
rule83=0,100,BiomesOPlenty:flowerVine-4
rule84=0,100,BiomesOPlenty:moss-1
rule85=0,100,BiomesOPlenty:flowerVine-12
rule86=0,100,BiomesOPlenty:flowerVine-11
rule87=0,100,BiomesOPlenty:woodenSingleSlab1-1
rule88=0,100,minecraft:vine-14
rule89=0,100,BiomesOPlenty:flowers-9
rule90=0,100,TwilightForest:tile.TFPlant-9
rule91=0,100,BiomesOPlenty:flowerVine-10
rule92=0,100,BiomesOPlenty:flowers2-4
rule93=0,100,BiomesOPlenty:moss-14
rule94=0,100,minecraft:vine-11
rule95=0,100,Natura:Thornvines-1
rule96=0,100,BiomesOPlenty:flowerVine-6
rule97=0,100,BiomesOPlenty:cherryStairs-0
rule98=0,100,BiomesOPlenty:moss-4
rule99=0,100,BiomesOPlenty:colorizedLeaves2-0
rule100=0,100,BiomesOPlenty:foliage-11
rule101=0,100,minecraft:vine-5
rule102=0,100,Natura:Thornvines-6
rule103=0,100,Natura:Thornvines-0
rule104=0,100,BiomesOPlenty:moss-3
rule105=0,100,BiomesOPlenty:moss-0
rule106=0,100,Natura:Thornvines-8
rule107=0,100,minecraft:tripwire-0
rule108=0,100,minecraft:bed-3
rule109=0,100,minecraft:bed-11
rule110=0,100,minecraft:farmland-7
rule111=0,100,minecraft:vine-10
rule112=0,100,Natura:Thornvines-12
rule113=0,100,Natura:Cloud-0

layer
0,0,0,0,1,0,0,1,1,0,1,1,0,0,0,0,0,0,0,0,0,0,0,0,0,0,0,0,0,1,0,1,0,0,0
0,1,0,1,0,0,1,0,1,0,0,0,1,1,1,0,0,0,0,0,0,0,1,0,0,0,0,0,1,0,1,0,0,1,1
1,0,0,0,1,0,0,0,3,0,3,1,1,0,1,1,1,1,0,1,1,0,0,1,2,2,2,2,0,1,1,1,0,1,1
1,0,0,0,0,0,6,5,5,0,0,0,0,1,1,0,1,1,0,1,1,1,1,4,1,1,1,1,1,1,1,1,1,1,0
0,0,0,7,7,7,7,0,0,0,0,0,1,0,0,0,1,1,1,1,1,0,1,1,0,2,2,2,2,2,2,2,0,0,1
0,0,0,3,3,3,3,7,0,0,0,0,0,0,0,0,0,1,0,1,1,1,0,2,2,2,2,2,2,2,2,2,0,1,1
1,0,0,3,3,3,3,7,0,0,0,0,0,0,0,0,0,0,0,1,1,0,0,2,2,2,2,2,2,0,2,2,0,0,1
0,0,0,0,3,3,8,10,10,10,8,10,10,9,9,8,0,0,0,0,1,1,1,2,2,2,2,2,2,0,2,2,0,0,1
0,0,0,15,7,3,11,14,13,13,14,13,13,13,12,11,8,0,0,0,0,4,0,7,2,0,0,0,0,0,0,2,0,0,1
0,0,0,20,7,3,11,12,0,0,0,0,0,0,12,11,19,8,7,8,19,18,17,0,16,2,0,0,0,0,0,2,0,0,1
0,0,0,21,5,7,11,12,0,0,4,0,0,0,12,11,8,23,23,22,18,22,21,21,21,21,2,2,2,0,0,0,0,1,1
0,21,21,21,19,3,11,12,0,0,0,0,0,0,12,9,24,25,25,24,22,24,22,21,14,21,2,3,0,0,0,0,0,1,1
21,21,21,21,21,21,21,14,0,0,14,0,0,0,14,26,8,8,23,23,24,25,24,21,14,21,8,3,3,0,0,0,0,0,1
21,21,21,21,0,0,0,13,0,0,0,0,0,0,13,14,13,13,13,23,8,23,23,21,14,21,3,3,3,0,0,0,1,0,1
21,21,21,29,0,0,0,0,0,0,4,0,0,0,28,0,0,0,0,27,21,21,21,21,14,21,3,3,3,1,0,0,1,1,0
21,21,21,21,0,0,0,13,0,0,0,0,0,0,13,14,13,13,13,13,3,3,3,21,14,21,8,3,3,0,0,0,1,1,0
21,21,21,21,21,21,21,14,0,0,14,0,0,0,14,14,3,3,3,23,23,23,3,21,14,21,3,3,0,0,0,0,0,1,0
30,21,21,21,21,3,13,12,0,0,0,0,0,0,12,9,3,3,3,3,3,3,3,21,21,21,3,7,3,0,0,0,1,0,0
30,21,21,21,21,7,13,12,0,0,0,0,0,0,12,9,3,7,7,3,3,3,3,3,21,3,3,3,3,0,0,0,1,0,0
0,0,7,5,21,0,0,0,4,0,0,0,0,0,12,13,7,7,7,7,3,3,3,7,7,7,7,0,3,0,0,0,1,0,0
0,0,0,3,0,0,0,0,13,13,14,13,13,13,14,9,7,7,7,7,7,3,7,0,0,0,0,0,0,0,0,0,0,1,0
0,0,0,0,0,0,0,0,0,12,8,12,12,12,9,3,3,7,8,7,7,3,0,0,0,0,0,0,0,0,0,0,1,0,0
0,0,0,0,0,0,0,7,0,0,0,0,7,7,7,3,3,23,8,8,7,19,7,0,0,0,0,1,0,0,0,0,0,0,1
0,0,0,0,0,0,0,0,0,0,0,0,7,7,0,0,7,7,8,7,23,7,7,0,1,1,1,0,0,0,1,0,0,0,0
0,0,0,0,0,0,0,0,0,0,0,0,7,0,0,0,7,7,7,8,0,0,0,0,1,1,1,0,0,0,0,0,0,1,0
0,0,0,0,0,0,0,0,0,0,0,0,7,0,0,0,0,7,19,0,0,0,0,0,0,0,0,0,0,0,0,0,0,3,0
2,0,0,0,0,0,0,0,0,0,0,0,0,0,0,0,0,0,0,0,0,0,0,0,0,0,0,0,0,0,1,0,0,0,0
endlayer

layer
0,0,0,0,0,0,0,0,0,1,0,0,2,0,0,0,0,0,2,2,0,0,0,0,0,0,0,0,0,0,0,0,0,31,0
0,0,0,0,0,0,0,0,0,0,0,0,0,0,0,0,0,0,0,0,0,0,0,0,0,0,0,0,0,0,0,0,0,0,0
0,0,0,0,1,0,0,0,0,0,0,0,0,0,0,0,0,0,0,0,0,0,0,0,3,0,0,3,0,0,0,0,0,0,0
0,0,0,1,0,0,5,6,6,0,0,0,0,1,0,0,1,0,0,0,0,0,0,0,0,0,0,0,0,0,0,0,0,0,0
0,0,0,33,32,6,0,5,0,0,0,0,0,0,0,0,1,0,1,0,1,0,0,0,0,0,0,0,2,2,2,2,2,0,0
0,0,0,7,3,3,7,5,5,0,0,0,0,0,0,0,0,0,0,1,0,0,0,0,0,2,2,2,2,2,2,2,2,0,0
0,0,0,7,3,3,7,5,5,0,0,12,12,12,0,0,0,0,0,0,1,0,2,2,2,2,2,2,2,2,2,2,2,0,0
0,0,0,0,3,3,8,10,12,12,8,12,12,12,9,8,0,0,0,0,0,0,0,2,2,2,2,2,2,2,2,3,2,0,0
0,0,0,15,32,19,9,14,0,0,14,0,0,0,14,11,7,8,0,0,0,0,0,0,21,0,2,0,0,31,0,2,0,0,0
0,0,0,15,5,13,13,0,0,0,0,0,0,0,0,13,13,19,32,32,32,1,0,13,13,13,2,0,0,0,0,3,0,0,0
0,0,0,34,5,5,13,0,0,0,0,0,0,0,0,13,8,8,0,0,8,0,12,0,0,0,12,2,3,0,0,3,0,0,0
0,34,34,34,5,12,13,0,0,0,0,0,0,0,0,13,13,36,35,0,0,0,12,0,0,0,12,3,3,0,0,0,0,0,0
34,34,32,5,21,21,21,14,0,0,14,0,0,0,14,26,8,23,23,0,0,0,12,0,0,0,12,3,3,37,0,0,0,0,0
34,32,32,21,0,0,0,13,0,0,0,0,0,0,13,14,13,13,13,13,13,13,14,0,0,0,14,3,3,0,0,0,0,0,0
34,32,32,0,0,0,0,0,0,0,0,0,0,0,39,0,0,0,0,0,0,0,38,0,0,0,12,7,7,0,0,0,0,0,0
34,32,5,21,0,0,0,13,0,0,0,0,0,0,13,14,13,13,13,13,13,13,14,0,0,0,14,7,3,0,0,0,0,0,0
34,32,32,5,21,21,21,14,0,0,14,0,0,0,14,14,3,3,8,0,0,0,12,0,0,0,12,19,0,0,0,0,0,0,0
34,32,32,32,15,21,13,0,0,0,0,0,0,0,0,13,3,3,23,23,23,23,12,0,0,0,12,5,3,0,0,0,0,0,0
34,32,32,15,21,5,13,0,0,0,0,0,0,0,0,13,7,41,41,7,23,8,14,14,40,14,14,7,7,0,0,0,0,0,0
34,34,34,21,21,5,13,0,0,0,0,0,0,0,0,13,0,42,5,31,23,19,7,5,0,5,5,0,7,0,0,0,0,0,0
0,0,0,3,3,3,10,14,0,0,14,0,0,0,14,9,43,42,4,0,5,19,5,0,0,0,0,5,0,0,0,0,0,0,0
0,0,0,0,0,0,8,11,12,12,8,12,12,12,9,8,7,5,5,5,5,19,5,44,0,0,0,0,0,0,0,0,0,0,0
0,0,0,0,0,0,0,0,5,5,5,5,5,5,5,7,7,5,8,5,5,5,5,44,0,0,0,0,0,0,0,0,0,0,0
0,0,0,0,0,0,0,41,5,5,5,5,5,5,5,5,5,5,5,5,5,5,45,0,0,0,0,0,0,0,0,0,0,0,0
0,0,0,0,0,0,0,0,0,0,5,5,5,5,5,5,32,32,5,5,5,0,0,0,0,0,0,0,0,0,0,0,0,0,0
0,0,0,0,0,0,0,0,0,0,5,5,5,5,5,46,0,32,5,0,0,0,0,0,0,0,0,0,0,0,0,0,0,0,0
3,0,0,0,0,0,0,0,0,0,0,0,0,0,0,0,0,0,0,0,0,0,0,0,7,7,7,7,7,7,0,0,0,0,0
endlayer

layer
0,0,0,0,0,0,0,0,0,3,0,3,0,0,0,0,0,0,0,2,2,2,2,0,2,2,2,2,2,2,2,2,2,2,2
1,0,0,0,0,0,0,0,0,0,0,0,0,0,0,0,0,0,0,2,0,0,2,0,0,2,2,0,0,2,0,2,2,2,2
0,0,1,0,0,1,0,0,0,0,0,0,0,1,0,0,1,0,0,2,0,0,0,0,0,0,0,3,2,2,0,2,2,2,2
0,0,0,0,0,0,0,5,5,6,0,1,0,0,0,0,0,0,0,0,0,0,0,0,0,0,0,2,2,2,0,2,2,2,2
0,0,0,47,0,0,5,5,5,5,0,0,0,0,0,0,0,1,0,0,0,0,0,0,0,2,2,2,2,2,3,2,2,2,2
0,0,0,33,7,7,5,5,5,5,0,42,42,0,0,0,0,0,0,0,0,0,2,2,2,2,2,2,2,2,2,3,2,2,2
0,0,0,33,3,3,5,5,5,5,0,5,0,5,8,0,0,0,0,0,0,0,3,3,2,2,2,2,2,2,3,2,2,3,3
0,0,0,15,3,3,8,9,12,12,8,12,12,12,9,8,0,8,7,0,0,0,3,0,2,2,2,2,2,2,2,3,3,0,0
0,0,0,15,15,8,9,14,0,0,14,0,0,0,14,11,49,48,48,0,0,0,7,3,31,21,2,2,2,3,0,3,0,0,0
0,0,0,0,0,13,13,0,0,0,0,0,0,0,0,13,13,52,51,51,51,0,51,14,50,14,14,2,2,3,3,3,3,0,3
0,0,0,15,5,13,13,0,0,0,0,0,0,0,0,13,8,53,51,51,8,51,14,0,0,0,14,3,3,3,3,3,3,0,3
0,0,0,15,5,5,13,0,0,0,0,0,0,0,0,13,13,19,51,51,51,31,50,0,0,0,50,3,3,3,3,3,3,0,0
0,0,0,0,21,21,21,14,0,0,14,0,0,0,14,26,8,8,23,51,51,51,50,0,0,0,50,54,8,3,23,0,0,0,0
0,0,15,21,0,0,0,13,0,0,0,0,0,0,13,10,23,13,13,13,13,13,14,0,0,0,14,23,23,8,3,0,0,0,0
0,0,15,0,0,0,0,13,37,0,0,0,0,54,13,12,23,37,0,0,0,0,39,0,0,0,50,4,0,3,19,0,0,0,0
0,0,15,21,0,0,0,13,0,0,0,0,0,0,13,9,23,13,13,13,13,13,14,0,0,0,14,5,3,3,0,0,0,0,0
0,0,0,5,21,21,21,14,0,0,14,0,0,0,14,14,19,23,23,0,5,0,50,0,0,0,50,5,0,8,0,0,0,0,0
0,0,0,0,15,21,13,0,0,0,31,0,0,0,0,13,19,19,8,0,0,8,50,0,0,0,50,5,8,8,0,0,0,0,0
0,0,0,55,21,21,13,0,0,0,0,0,0,0,0,13,5,31,5,5,8,3,14,14,39,14,14,5,5,0,0,0,0,0,0
0,0,15,21,21,5,13,0,0,0,0,0,0,0,0,13,13,5,5,5,5,8,56,5,0,5,5,5,32,0,0,0,0,0,0
0,0,15,3,3,3,10,14,0,0,14,0,0,0,14,9,5,5,0,5,5,5,0,0,44,0,0,0,0,0,0,0,0,0,0
0,0,0,0,0,0,8,11,12,12,8,12,12,12,9,26,5,4,5,5,5,5,0,57,0,0,0,0,0,0,0,0,0,0,0
0,0,0,0,0,0,0,3,5,5,5,5,5,5,5,56,5,5,5,5,5,0,0,0,0,0,0,0,0,0,0,0,0,0,0
0,0,0,0,0,0,41,41,5,5,5,5,5,5,5,5,5,0,5,5,5,37,0,0,0,0,0,0,0,0,0,0,0,0,0
0,0,0,0,0,0,0,0,58,0,5,5,5,5,0,0,0,41,0,0,0,0,0,0,0,0,0,0,0,0,0,0,0,0,0
0,0,0,0,0,0,0,0,0,0,0,0,0,0,0,59,0,0,0,0,0,0,0,0,0,0,1,0,0,0,0,0,0,0,0
0,0,0,0,0,0,0,0,0,0,0,0,0,0,0,0,0,0,0,0,0,0,0,0,63,61,61,62,61,60,0,0,0,0,0
endlayer

layer
0,0,0,0,0,0,0,0,0,3,3,0,0,0,0,0,0,0,0,0,0,0,2,0,2,2,2,2,2,0,2,2,2,2,2
0,0,0,0,1,0,0,0,0,3,3,0,0,0,0,0,0,2,2,0,0,0,0,0,0,0,3,0,2,0,0,2,2,2,2
0,0,0,0,1,0,0,0,0,0,0,1,1,0,0,0,1,0,1,0,1,0,1,0,1,0,0,3,3,0,0,2,2,2,2
1,0,0,0,0,0,0,0,0,0,0,0,0,1,1,0,0,0,1,1,0,1,0,0,0,0,0,0,2,2,3,2,2,2,2
0,0,0,0,0,0,0,0,0,0,64,0,0,0,0,0,0,0,0,0,0,0,0,0,2,2,2,2,2,3,3,3,0,2,2
0,0,0,47,67,55,5,0,66,5,0,5,5,65,7,3,3,3,0,0,0,7,0,0,2,2,2,2,2,2,3,3,3,3,0
0,0,0,47,7,3,5,5,5,3,3,5,5,5,8,3,3,3,3,8,8,3,3,3,2,2,2,2,2,2,3,3,3,3,0
0,0,0,15,3,3,8,23,23,23,8,68,68,68,68,8,23,23,56,8,8,7,7,3,3,2,2,2,3,3,3,3,3,3,3
0,0,0,15,5,8,19,14,13,13,69,13,13,13,14,69,48,48,0,51,51,51,51,7,3,2,2,2,2,3,0,3,3,3,3
0,0,0,0,0,15,69,12,0,0,12,0,0,0,12,69,52,0,51,51,51,51,51,14,13,14,2,3,3,3,3,3,3,8,19
0,0,15,15,5,15,69,12,0,0,12,0,0,0,12,69,8,52,51,51,8,51,14,0,0,0,12,3,3,3,3,3,8,19,19
0,0,0,15,42,15,69,12,0,0,12,0,0,0,12,69,70,0,51,51,51,51,12,0,0,0,12,3,23,3,3,23,23,8,19
0,0,71,0,21,3,26,68,68,68,8,13,13,13,68,8,8,8,51,51,51,51,12,0,0,0,12,8,8,8,8,19,23,8,8
0,0,15,21,21,21,21,12,0,0,69,0,0,0,12,69,8,23,8,5,72,53,14,0,0,0,14,8,8,8,8,19,23,8,8
0,0,15,21,21,21,21,12,0,0,69,0,0,0,12,69,8,23,13,13,13,13,12,37,0,54,12,8,19,19,19,19,8,0,0
0,0,15,21,21,21,21,12,0,0,69,0,0,0,12,19,8,23,8,5,5,5,14,0,0,0,14,73,19,19,8,8,0,0,0
0,0,0,15,21,5,19,68,13,13,8,13,13,13,13,8,8,8,0,0,0,0,12,0,0,0,12,5,0,32,7,0,0,0,0
0,0,0,0,15,21,19,12,0,0,19,0,0,0,12,19,8,8,8,0,0,0,12,0,0,0,12,5,32,32,7,0,0,0,0
0,0,0,15,21,21,19,12,0,0,19,0,0,0,12,19,5,5,5,0,0,8,14,13,13,13,14,5,0,0,0,0,0,0,0
0,0,15,21,21,3,19,12,0,0,19,0,0,0,12,19,57,0,5,0,5,5,0,5,5,5,5,0,0,0,0,0,0,0,0
0,0,15,21,0,3,19,14,13,13,19,13,13,13,14,19,5,5,5,0,5,0,0,0,44,0,0,0,0,0,0,0,0,0,0
0,0,0,0,3,0,8,23,23,23,26,68,68,68,68,26,5,5,5,5,0,41,0,57,0,0,0,0,0,0,0,0,0,0,0
0,0,0,0,0,0,3,3,0,5,5,5,5,5,5,5,74,0,5,5,0,0,0,0,0,0,0,0,0,0,0,0,0,0,0
0,0,0,0,0,0,41,41,5,5,5,5,5,5,5,5,5,0,41,0,0,0,0,0,0,0,0,0,0,0,0,0,0,0,0
0,0,0,0,0,0,0,0,0,0,0,0,0,0,0,0,0,41,0,0,0,0,0,0,0,0,1,0,0,0,0,0,0,0,0
0,0,0,0,0,0,0,0,0,0,0,0,0,0,0,0,0,0,0,0,0,0,0,0,0,0,0,0,0,0,0,0,0,0,0
0,0,0,0,0,0,0,0,0,0,0,0,0,0,0,0,0,0,0,0,0,0,0,0,0,0,0,0,0,0,0,0,0,0,0
endlayer

layer
0,0,0,0,0,0,7,0,0,7,3,0,0,0,0,0,0,0,0,0,0,0,0,0,2,2,0,2,2,0,2,2,2,2,2
0,0,0,0,0,0,0,0,0,0,0,0,0,0,0,0,0,0,0,0,0,0,0,0,0,2,0,0,2,0,0,2,2,2,2
0,0,0,0,0,0,0,0,0,1,0,0,0,0,0,0,0,0,0,1,0,0,0,0,0,0,0,0,3,0,0,2,2,0,0
0,0,0,0,0,0,0,0,0,0,0,0,0,0,0,0,1,0,0,1,0,0,0,0,0,0,0,0,2,2,3,7,0,0,0
0,0,0,0,0,0,0,0,0,0,0,0,0,0,0,0,3,3,3,0,1,0,0,0,0,2,2,2,2,7,3,3,0,0,0
0,0,0,0,0,0,0,55,66,7,64,0,15,0,0,3,3,3,3,3,3,0,0,0,0,2,2,2,7,3,3,7,3,7,0
0,0,0,0,32,7,3,3,3,3,7,5,5,5,8,3,8,3,8,8,23,3,3,3,3,2,2,2,3,3,3,3,3,3,0
0,0,0,5,19,3,8,76,76,76,8,76,76,76,76,19,8,8,0,8,8,75,70,3,3,2,2,2,3,3,3,3,3,19,19
0,0,0,15,19,3,76,10,10,10,76,9,9,9,10,19,19,0,0,0,0,0,0,63,3,3,2,2,3,3,0,3,3,19,8
0,0,54,5,8,3,76,10,21,21,76,21,21,21,10,8,0,0,0,51,51,51,0,5,3,3,3,3,3,3,3,23,23,5,5
0,0,15,5,19,3,76,10,21,21,76,21,21,21,10,76,8,52,0,51,8,51,77,21,21,21,3,3,3,3,3,23,23,5,5
0,42,0,15,19,7,76,10,21,21,21,21,21,21,5,5,70,0,0,51,51,78,78,21,31,21,8,8,23,8,8,19,23,5,5
0,0,5,5,23,23,26,76,76,21,21,21,21,21,76,26,8,52,0,0,78,78,72,21,0,21,8,8,8,8,8,32,32,5,5
0,71,5,23,5,5,76,9,21,21,21,21,21,21,11,76,8,8,4,52,72,53,72,21,0,21,8,8,8,8,32,32,32,5,5
0,0,5,32,21,21,21,21,21,21,21,21,21,21,11,76,8,8,8,5,5,72,72,21,0,21,8,5,5,5,32,32,32,0,0
0,0,0,32,21,21,21,21,21,21,21,21,21,21,11,76,8,8,5,5,5,5,5,21,0,21,0,5,5,5,32,32,14,5,44
0,0,0,15,21,21,8,21,21,21,21,76,76,76,76,8,3,0,0,0,0,51,51,21,55,21,0,0,0,0,32,0,5,5,0
0,0,0,0,15,21,21,21,21,21,21,21,21,21,9,76,79,8,0,51,51,51,51,21,21,21,5,41,0,0,67,41,0,0,0
0,0,0,15,21,21,21,21,21,21,21,21,21,21,10,76,44,5,5,51,51,8,51,51,5,5,5,0,0,0,0,0,0,0,0
0,0,0,32,21,3,21,21,21,21,21,21,21,21,10,76,5,0,0,0,51,51,51,44,44,0,0,0,0,0,0,0,0,0,0
0,0,0,32,21,7,76,10,10,11,76,9,9,9,10,76,5,5,5,0,0,51,0,0,44,0,0,0,0,0,0,0,0,0,0
0,0,0,0,7,7,8,76,76,76,26,76,76,76,76,26,5,5,5,0,0,41,0,57,0,0,0,0,0,0,0,0,1,0,0
0,0,0,7,0,0,7,7,7,5,5,5,5,5,5,5,74,0,0,41,0,0,0,0,0,0,0,0,0,0,1,0,0,0,0
0,0,0,0,0,0,41,41,41,0,0,0,81,81,81,15,0,0,80,44,0,0,0,0,0,0,0,0,0,0,0,0,0,0,0
0,0,0,0,0,0,0,0,0,0,0,0,0,0,0,0,0,41,0,0,0,0,0,0,0,1,0,0,0,0,0,0,0,0,0
0,0,0,0,0,0,0,0,0,0,0,0,0,0,0,0,0,0,0,0,0,0,0,0,0,0,0,0,0,0,0,0,0,0,0
0,0,0,0,0,0,0,0,0,0,0,0,0,0,0,0,0,0,0,0,0,0,0,0,0,0,0,0,0,0,0,0,0,0,0
endlayer

layer
0,0,7,0,0,0,56,0,0,0,7,0,0,0,0,0,0,2,0,0,0,0,0,0,3,3,0,0,0,0,2,2,2,2,2
0,0,0,0,0,1,0,0,0,1,0,0,0,0,0,0,0,0,0,0,0,0,0,0,0,0,0,0,0,0,2,2,2,2,3
0,0,0,0,0,0,0,0,0,0,0,0,0,0,0,0,0,0,0,0,1,1,0,1,0,0,0,0,3,3,3,3,0,0,0
0,0,0,0,0,0,0,0,0,0,0,0,0,0,0,0,0,0,0,0,0,0,0,0,0,0,0,0,0,0,7,0,0,0,0
0,0,0,0,0,0,0,0,0,0,0,0,0,20,0,0,8,8,8,0,0,0,0,0,0,2,2,2,0,0,7,0,0,0,0
0,0,0,0,0,0,0,66,66,66,0,0,15,0,5,8,8,8,8,8,0,0,0,0,0,2,2,2,0,0,7,0,3,0,0
1,0,0,0,0,0,7,7,7,7,43,15,0,5,8,8,26,8,8,8,8,8,7,3,3,2,2,2,3,3,3,3,3,7,0
0,0,0,0,5,7,7,3,3,3,7,4,5,8,8,8,8,8,23,23,23,23,23,23,3,3,2,2,3,3,3,19,23,5,5
0,0,0,0,5,7,3,3,3,3,7,21,21,21,8,8,8,23,23,23,23,23,23,23,3,3,2,3,3,3,0,19,23,5,5
0,0,0,5,8,3,3,3,3,3,3,21,21,21,21,8,23,0,0,0,51,52,0,5,23,3,3,3,3,3,8,23,5,5,0
0,0,0,5,5,7,7,3,3,3,21,82,82,21,8,23,8,0,0,51,51,51,77,5,31,5,3,3,8,8,23,8,5,5,5
0,5,5,5,5,0,7,3,7,21,31,32,32,21,5,5,0,0,0,0,51,52,0,83,50,8,19,8,8,8,5,8,0,5,5
5,5,5,23,8,5,8,3,21,32,32,32,32,21,8,8,8,52,0,0,86,72,72,85,50,0,8,8,8,8,84,31,0,0,4
0,5,5,5,5,87,21,21,32,32,32,32,32,21,8,0,8,8,5,52,0,53,72,83,50,8,8,8,8,5,84,0,0,0,0
0,0,5,5,32,21,21,88,32,32,32,32,32,21,8,8,8,8,8,5,52,0,5,0,50,8,8,5,5,0,0,0,0,0,0
0,0,0,0,32,21,32,32,32,32,32,32,32,21,21,3,8,8,5,5,5,5,5,5,50,19,5,5,0,0,0,0,14,5,44
0,0,0,0,32,21,32,32,32,32,54,21,21,21,3,3,8,0,0,5,51,51,51,51,50,5,5,0,0,0,0,0,5,6,0
0,0,0,0,15,32,32,32,32,32,32,21,0,5,7,3,19,8,5,51,51,51,51,51,5,5,0,41,0,0,0,41,0,0,0
0,0,0,0,32,21,32,32,32,32,32,21,5,5,5,7,19,5,5,51,51,8,51,51,79,0,0,0,0,0,0,0,0,0,0
0,0,0,0,32,21,32,32,32,32,32,21,5,5,4,5,5,5,5,51,51,51,51,51,44,0,0,0,0,0,0,0,0,0,0
0,0,0,0,32,87,21,21,21,21,21,5,6,5,5,4,5,5,0,0,51,51,51,51,44,0,0,0,0,0,0,0,0,0,0
0,0,0,0,32,4,7,7,5,5,5,5,5,5,5,5,0,5,0,0,0,41,0,57,0,0,0,0,0,0,0,0,0,0,0
0,0,0,0,0,0,5,5,5,5,5,5,74,5,5,5,74,0,0,41,0,0,0,0,0,0,0,0,0,0,0,0,0,0,0
0,0,0,0,0,0,41,0,31,0,0,0,0,81,0,15,0,0,80,44,0,0,0,0,0,0,0,0,0,0,0,0,0,0,0
0,0,0,0,0,0,0,0,0,0,0,0,0,0,0,0,0,41,0,0,0,0,0,0,1,0,0,0,0,0,0,0,0,0,0
0,0,0,0,0,0,0,0,0,0,0,0,0,0,0,0,0,0,0,0,0,0,0,0,0,0,0,0,0,0,0,1,0,0,0
0,0,0,0,0,0,0,0,0,0,0,0,0,0,0,0,0,0,0,0,0,0,0,0,0,0,0,0,0,0,0,1,0,0,0
endlayer

layer
0,0,75,0,0,0,0,0,0,0,56,0,0,0,0,0,0,2,0,0,0,0,0,0,0,0,0,0,0,3,2,2,2,2,3
0,0,0,0,0,0,0,0,0,0,0,0,0,0,0,0,0,0,0,0,0,0,0,0,0,0,0,0,0,0,0,3,0,3,3
0,0,0,0,0,0,0,0,0,0,0,0,0,0,0,0,1,0,0,1,0,1,0,0,0,0,0,0,0,0,0,7,0,0,0
0,1,0,0,0,0,0,0,0,0,0,1,0,1,0,0,66,1,0,0,0,0,0,0,0,0,0,0,1,0,1,0,0,0,0
0,0,0,0,0,0,0,0,0,0,0,0,0,20,0,6,6,19,6,0,0,0,0,0,2,2,3,0,0,0,0,0,7,0,0
0,0,0,0,0,0,0,0,0,0,0,0,15,0,5,6,23,8,23,0,6,7,0,0,0,2,2,3,0,0,0,0,7,0,0
0,0,0,0,0,0,33,0,89,5,0,15,5,5,54,23,8,8,8,23,5,5,5,7,3,3,2,3,3,3,3,21,7,5,5
0,0,0,0,0,56,32,7,7,7,15,5,5,32,32,32,90,0,70,70,70,91,90,70,23,8,8,8,8,8,8,21,5,5,5
0,0,0,0,0,56,7,7,3,7,5,32,32,32,32,32,32,0,0,90,0,4,52,74,23,8,8,8,8,8,0,21,5,5,5
0,0,0,0,5,8,7,7,3,3,7,32,32,32,32,32,34,34,34,34,34,34,34,34,34,8,8,8,8,19,8,5,0,5,5
0,0,0,0,15,5,5,7,7,7,5,0,0,32,8,8,5,0,0,72,52,44,52,83,5,15,8,8,8,8,57,8,0,5,5
0,0,0,0,5,5,67,3,92,5,0,0,0,32,5,19,5,5,0,0,52,52,0,83,5,5,8,8,8,8,0,48,0,0,44
5,5,5,5,5,5,8,8,84,84,0,0,0,32,8,8,8,5,0,5,53,72,72,85,5,5,8,8,8,8,44,0,0,0,0
5,5,5,0,0,0,15,8,84,0,0,0,0,54,8,0,8,8,5,5,5,53,0,83,5,8,8,8,5,48,0,0,0,0,0
0,5,5,0,0,32,4,88,0,0,0,0,0,32,8,8,8,25,23,8,5,5,52,0,5,8,5,41,0,0,0,0,0,0,0
0,0,31,0,0,32,0,15,41,0,0,0,0,32,93,8,8,19,23,5,5,5,0,5,0,5,5,0,0,0,0,5,14,5,44
0,0,0,0,0,32,0,15,0,0,0,5,5,5,7,7,19,0,0,0,5,94,0,0,41,5,0,0,0,0,0,0,5,5,0
0,0,0,0,15,0,41,0,0,0,0,5,5,5,5,8,8,8,0,0,0,51,44,41,0,31,0,41,0,1,44,41,0,0,0
0,0,0,0,0,32,41,0,0,0,0,5,5,5,5,5,8,19,0,0,51,8,51,37,73,0,41,0,0,0,0,41,0,0,0
0,0,0,0,0,4,41,41,0,0,0,5,5,0,15,0,5,5,0,0,51,51,41,4,0,0,0,0,0,0,0,0,0,0,0
0,0,0,0,0,0,6,5,6,6,5,6,6,5,95,5,0,0,0,0,0,0,41,44,0,0,0,0,0,0,0,0,0,0,0
0,0,0,0,0,0,5,5,5,0,0,0,0,81,0,5,0,0,0,0,0,0,0,44,0,0,0,0,0,0,0,0,0,0,0
0,0,0,0,0,0,31,5,31,0,4,0,0,0,0,15,74,0,0,41,0,0,0,0,0,0,0,0,0,0,0,0,0,0,0
0,0,0,0,0,0,0,0,0,0,0,0,0,0,0,15,0,0,80,44,0,0,0,0,0,0,0,0,0,0,0,0,0,0,0
0,0,0,0,0,0,0,0,0,0,0,0,0,0,0,0,0,41,0,0,0,0,0,0,0,0,0,0,0,0,0,0,0,0,0
0,0,0,1,0,0,0,0,0,0,0,0,0,0,0,0,0,0,0,0,0,0,0,0,0,0,0,0,0,0,0,0,0,0,0
0,0,0,0,0,0,0,0,0,0,0,0,0,0,0,0,0,0,0,0,0,0,0,0,0,0,0,0,0,0,0,0,0,0,0
endlayer

layer
0,0,0,0,0,0,0,0,0,0,0,0,0,0,0,0,0,0,0,0,0,0,0,0,2,0,0,0,0,0,2,2,2,3,3
0,0,0,0,0,0,0,0,0,0,0,0,0,0,0,0,0,0,0,0,0,0,0,0,0,0,0,0,0,0,0,0,0,3,3
0,0,0,0,0,0,0,0,0,0,0,0,0,1,0,0,1,0,0,0,0,0,0,0,0,0,0,0,0,0,0,0,0,7,7
0,0,0,0,0,0,0,0,0,0,0,0,0,0,66,1,66,66,0,0,0,1,0,0,0,0,0,0,0,0,0,0,0,0,0
0,0,0,0,0,0,0,0,0,0,0,0,0,20,0,66,0,6,6,6,0,0,0,0,0,2,0,0,0,0,0,0,0,0,7
0,0,0,0,0,0,0,0,0,0,0,0,15,0,6,6,8,8,8,6,6,6,0,0,0,3,2,3,0,0,21,0,5,5,5
0,0,0,0,0,0,47,0,0,0,0,15,0,5,0,5,8,8,8,5,5,5,5,5,0,8,8,8,8,21,21,21,5,5,5
0,0,0,0,0,0,0,32,4,33,15,5,0,0,0,0,31,0,70,70,70,91,96,70,0,41,41,32,32,0,0,0,21,5,5
0,0,0,0,0,0,33,92,7,5,5,5,0,0,0,0,0,0,0,52,0,52,52,70,0,70,0,0,44,0,0,0,21,5,5
0,0,0,0,0,0,56,32,7,7,5,0,0,0,0,5,5,5,5,52,52,52,20,0,83,5,5,5,5,8,97,97,5,5,5
0,0,0,0,0,66,5,32,32,32,0,0,0,0,5,8,5,5,0,72,52,44,52,0,15,0,8,8,8,8,5,8,5,0,0
0,0,0,0,15,5,5,8,84,0,0,0,0,23,23,8,8,5,5,5,52,52,0,15,0,72,5,23,23,8,5,5,5,0,44
0,5,0,0,0,5,8,8,23,84,0,0,0,5,8,8,8,5,5,5,52,72,72,72,83,83,8,8,8,8,44,0,0,0,0
0,5,0,0,0,0,15,8,84,0,0,0,0,98,8,0,8,8,5,5,5,72,0,0,83,8,8,5,48,48,0,0,0,0,0
0,0,0,0,0,0,0,20,0,0,0,0,0,0,5,8,8,0,8,8,5,5,52,0,0,5,41,0,0,0,0,0,6,0,0
0,0,0,0,0,15,0,15,41,0,0,0,0,0,98,8,8,0,8,5,5,5,0,0,0,5,0,0,0,0,0,6,14,5,44
0,0,0,0,0,15,0,15,0,0,0,5,0,78,32,5,19,0,19,5,5,57,0,0,41,0,0,0,0,0,0,6,6,5,0
0,0,0,0,15,0,41,0,0,0,0,41,0,78,15,5,8,8,19,0,0,51,0,41,0,0,0,41,0,0,44,41,0,0,0
0,0,0,0,0,0,41,0,0,41,0,15,0,0,15,5,8,8,19,0,51,51,51,43,73,0,41,0,41,0,0,41,0,0,0
0,0,0,0,0,0,41,41,81,0,0,0,0,0,15,0,5,5,19,5,5,51,5,44,0,0,0,0,41,0,0,0,0,0,0
0,0,0,0,0,0,0,0,0,0,0,0,41,81,0,15,0,5,5,0,0,0,41,44,0,0,0,0,0,0,0,0,0,0,0
0,0,0,0,0,0,0,5,0,0,0,0,0,0,0,15,0,31,0,0,0,0,0,44,0,0,0,0,0,0,0,0,0,0,0
0,0,0,0,0,0,0,0,0,0,0,0,0,0,0,15,74,0,0,41,0,0,0,0,0,0,0,0,0,0,0,0,0,0,0
0,0,0,0,0,0,0,0,0,0,0,0,0,0,0,15,0,0,80,44,0,0,0,0,0,0,0,0,0,0,0,0,0,0,0
0,0,0,0,0,0,0,0,0,0,0,0,0,0,0,0,0,41,81,0,0,0,0,0,0,0,0,0,0,0,0,0,0,0,0
0,0,0,0,0,0,0,0,0,0,0,0,0,0,0,0,0,0,0,0,0,0,0,0,0,0,0,0,0,0,0,0,0,0,0
0,0,0,0,0,0,0,0,0,0,0,0,0,0,0,0,0,0,0,0,0,0,0,0,0,0,0,0,0,0,0,0,0,0,0
endlayer

layer
0,0,0,0,0,0,0,0,0,0,0,0,0,0,0,0,2,2,0,0,0,0,2,2,2,0,0,0,0,0,2,3,3,3,3
0,0,0,0,0,0,0,0,0,0,0,0,0,0,0,0,0,0,0,0,0,0,0,0,0,0,0,0,0,0,0,3,3,3,7
0,0,0,0,0,0,0,0,0,0,0,0,0,0,0,0,0,0,0,1,1,1,0,0,0,0,0,0,0,0,0,7,7,63,56
0,0,0,0,0,0,0,0,0,0,1,0,0,0,66,0,66,66,66,66,0,0,0,0,3,1,0,1,0,1,0,0,0,0,0
0,0,0,0,0,0,0,0,0,0,0,0,0,20,0,6,0,0,0,6,0,0,0,0,0,3,0,0,0,0,66,66,0,0,0
0,0,0,0,0,0,0,0,0,0,0,0,15,0,0,0,6,8,5,0,0,0,6,6,0,3,3,3,7,0,66,0,66,0,0
0,0,0,0,0,0,0,0,0,0,0,15,0,0,0,5,8,8,8,5,6,5,5,5,5,8,8,8,8,5,5,5,5,5,0
0,0,0,0,0,0,0,0,0,47,15,0,0,0,0,0,0,8,70,70,70,91,96,70,0,31,41,41,41,0,0,0,5,5,66
0,0,0,0,0,0,47,0,4,0,66,0,0,0,0,0,0,0,0,52,0,52,52,70,0,70,0,0,44,0,0,0,5,5,0
0,0,0,0,0,0,0,0,32,4,0,0,0,0,23,23,8,5,5,5,52,52,20,0,0,85,5,5,5,5,44,0,5,5,0
0,0,0,0,0,0,0,0,5,0,0,0,0,0,5,19,19,5,6,6,52,44,52,0,15,0,8,8,8,8,97,97,14,5,44
0,0,0,0,0,55,5,8,5,0,0,5,5,5,5,19,19,5,5,6,52,52,0,15,0,72,0,0,0,8,5,5,5,0,44
0,0,0,0,0,5,8,8,8,84,0,31,6,5,0,8,8,23,5,5,5,72,72,72,83,83,8,8,8,8,0,5,5,0,0
6,6,0,0,0,5,5,8,84,0,0,0,0,98,8,0,8,8,5,5,19,5,5,0,83,8,5,41,48,5,5,5,5,0,0
31,0,0,0,0,0,5,42,6,0,0,0,0,6,5,8,5,5,5,8,23,23,5,0,0,44,0,0,0,6,5,5,6,6,0
0,0,0,0,0,15,0,15,41,0,0,0,0,0,5,5,5,5,5,6,5,5,0,0,0,44,0,0,0,0,6,6,14,6,44
0,0,0,0,0,15,0,15,41,54,5,0,0,0,0,0,5,5,5,5,5,41,0,0,41,0,0,0,0,0,0,6,6,6,0
0,0,0,0,15,0,41,0,0,0,0,41,0,0,15,5,5,19,5,23,5,44,0,41,0,0,0,41,0,0,44,41,0,0,0
0,0,0,0,0,0,41,0,0,41,0,15,0,0,15,5,5,19,23,5,5,5,44,66,73,0,41,0,41,0,0,41,0,0,0
0,0,0,0,0,0,41,41,81,0,0,0,0,0,15,0,5,8,23,23,23,5,5,44,0,41,0,41,41,0,0,0,0,0,0
0,0,0,0,0,0,0,0,0,0,0,0,41,81,0,15,0,5,8,5,5,5,5,44,0,0,0,0,0,0,0,0,0,0,0
0,0,0,0,0,0,0,0,0,0,0,0,0,0,0,15,0,0,5,5,0,5,0,44,0,0,0,0,0,0,0,0,0,0,0
0,0,0,0,0,0,0,0,0,0,0,0,0,0,0,15,74,0,0,41,0,0,0,0,0,0,0,0,0,0,0,0,0,0,0
0,0,0,0,0,0,0,0,0,0,0,0,0,0,0,15,0,0,80,44,0,0,0,0,0,0,0,41,0,0,0,0,0,0,0
0,0,0,0,0,0,0,0,0,0,0,0,0,0,0,0,0,41,81,0,0,0,0,0,0,0,0,0,0,0,0,0,0,0,0
0,0,0,0,0,0,0,0,0,0,0,0,0,0,0,0,0,0,0,0,0,0,0,0,0,0,0,0,0,0,0,0,0,0,0
0,0,0,0,0,0,0,0,0,0,0,0,0,0,0,0,0,0,0,0,0,0,0,0,0,0,0,0,0,0,0,0,0,0,0
endlayer

layer
0,0,0,0,0,0,0,0,0,0,0,0,0,0,0,0,0,0,1,0,0,0,2,0,0,0,3,0,0,0,0,3,3,3,7
0,0,0,0,0,0,0,0,0,0,99,0,0,0,0,0,1,0,0,1,0,0,0,1,0,0,0,0,0,0,0,3,7,7,75
0,0,0,0,0,0,0,0,0,0,0,0,0,0,0,0,0,0,0,0,0,0,0,0,0,0,0,0,0,0,0,56,100,0,0
0,0,0,0,0,0,0,0,0,0,0,0,0,0,66,66,66,66,66,66,0,0,0,0,0,0,0,0,1,0,1,0,0,0,0
0,0,0,0,0,0,0,0,0,0,0,0,0,20,0,42,0,5,0,0,0,0,0,0,0,3,0,0,0,0,66,66,0,0,66
0,0,0,0,0,0,0,0,0,0,0,0,15,0,0,0,0,8,5,5,0,0,0,0,0,3,3,3,5,5,66,0,66,0,0
0,0,0,0,0,0,0,0,0,0,0,15,0,0,5,5,8,8,8,5,52,0,0,83,83,6,8,19,8,5,5,66,5,0,0
0,0,0,0,0,0,0,0,0,0,15,0,0,0,5,0,19,19,70,70,66,72,83,6,5,83,5,5,5,5,5,5,5,5,66
0,0,0,0,0,0,0,0,0,0,66,0,0,5,8,23,23,5,5,52,0,52,52,70,70,70,0,0,44,0,0,0,5,0,0
0,0,0,0,0,0,0,0,15,0,0,0,0,23,23,23,19,23,5,5,0,52,20,0,0,72,5,55,5,5,44,0,5,0,0
0,0,0,0,0,0,0,0,15,0,0,0,0,5,0,5,5,5,5,5,52,44,52,0,15,5,8,8,8,8,44,0,14,5,44
0,0,0,0,0,0,55,5,0,0,5,5,5,5,5,5,5,5,19,5,52,52,0,15,0,72,0,0,0,8,97,97,14,5,44
0,0,0,0,0,15,5,8,6,6,5,5,5,23,8,8,8,8,23,5,78,72,72,72,83,23,8,8,8,48,21,21,12,5,0
6,6,0,0,0,0,5,5,6,6,5,5,5,5,8,23,8,5,5,78,5,5,5,5,44,5,41,48,48,5,21,21,12,5,0
0,0,0,0,0,0,0,5,6,6,5,0,5,5,5,8,5,5,5,6,5,5,5,5,0,44,0,0,0,5,21,21,12,6,0
0,0,0,0,0,15,0,15,41,0,0,0,0,5,5,5,5,5,5,44,0,5,5,0,0,44,0,0,0,5,13,13,14,6,44
0,0,0,0,0,15,0,15,41,15,5,0,0,0,5,5,5,5,5,44,5,0,0,0,41,0,0,0,0,0,5,5,6,6,0
0,0,0,0,15,0,41,0,0,0,0,41,0,0,15,5,15,5,5,8,5,44,0,41,0,0,0,41,0,0,44,41,0,0,0
0,0,0,0,0,0,41,0,0,41,0,15,0,0,0,41,5,5,5,5,5,5,0,66,73,0,41,0,41,0,0,41,0,0,0
0,0,0,0,0,0,41,41,81,0,0,0,0,0,15,0,5,5,8,5,8,5,5,5,0,41,0,41,41,0,0,0,0,0,0
0,0,0,0,0,0,0,0,0,0,0,0,41,81,0,15,0,5,19,5,5,19,5,31,0,0,0,0,0,0,0,0,0,0,0
0,0,0,0,0,0,0,0,0,0,0,0,0,0,0,15,5,5,19,5,5,5,5,44,0,0,0,0,0,0,0,0,0,0,0
0,0,0,0,0,0,0,0,0,0,0,0,0,0,0,15,74,5,5,41,0,0,0,0,0,0,0,0,0,0,0,0,44,0,0
0,0,0,0,0,0,0,0,0,0,0,0,0,0,0,15,0,0,80,44,0,0,0,0,0,0,0,41,41,0,0,0,0,0,0
0,0,0,0,0,0,0,0,0,0,0,0,0,0,0,0,0,41,81,0,0,0,0,0,0,0,0,0,0,0,0,0,0,0,0
0,0,0,0,0,0,0,0,0,0,0,0,0,0,0,0,0,0,0,0,0,0,0,0,0,0,0,0,0,0,0,44,0,0,0
0,0,0,0,0,0,0,0,0,0,0,0,0,0,0,0,0,0,0,0,0,0,0,0,0,0,0,0,0,0,0,0,0,0,0
endlayer

layer
0,0,99,0,0,0,0,0,0,0,0,0,0,0,0,0,0,0,0,0,0,0,0,0,0,0,0,0,0,0,0,3,3,7,56
0,0,0,1,0,0,0,0,0,0,99,0,0,0,0,0,0,0,0,0,0,0,1,0,0,0,0,0,0,0,0,7,63,100,66
0,0,0,0,0,0,0,0,0,0,0,0,0,0,0,0,0,0,0,0,0,0,0,0,0,0,0,0,0,0,0,0,0,0,0
0,0,0,0,0,99,0,0,0,0,0,0,0,0,66,66,66,66,66,66,0,66,0,0,0,0,0,0,0,0,0,66,0,0,0
0,0,0,0,0,0,0,0,0,0,0,0,0,20,5,5,5,55,5,0,0,0,0,0,0,3,0,0,0,0,66,66,0,0,66
0,0,0,0,0,0,0,0,0,0,0,0,15,5,19,5,5,5,5,5,0,0,0,0,15,7,7,7,0,66,66,0,66,0,0
0,0,0,0,0,0,0,0,0,0,0,15,5,5,19,5,0,8,5,5,52,0,0,83,83,6,8,19,8,5,44,66,66,0,0
0,0,0,0,0,0,0,0,0,0,15,0,0,5,19,0,0,5,5,70,66,72,0,83,83,5,5,19,5,5,5,5,5,0,66
0,0,0,0,0,0,0,0,0,0,66,0,5,5,8,5,5,19,5,5,5,52,52,0,70,70,0,0,44,0,5,5,5,44,0
0,0,0,0,0,0,0,0,15,0,0,0,5,5,5,5,5,5,5,5,5,52,20,0,0,0,5,8,44,5,44,0,5,0,0
0,0,0,0,0,0,0,0,15,0,5,5,5,5,0,5,5,5,5,19,5,44,52,0,83,5,8,8,8,8,84,0,5,0,44
0,0,0,0,0,0,0,6,6,0,5,5,5,8,19,5,5,5,5,23,5,52,0,15,5,23,23,8,0,8,44,0,14,5,44
0,0,0,0,0,15,5,4,0,6,5,5,5,23,23,8,5,5,8,5,0,72,72,72,0,5,8,8,8,21,44,0,5,5,0
6,6,0,0,0,0,0,6,6,6,5,5,5,5,8,3,8,5,5,0,0,5,5,5,44,0,41,48,5,29,0,0,5,5,0
0,0,0,0,0,0,0,5,6,6,5,5,5,5,5,8,5,6,6,0,101,5,5,5,5,44,0,0,5,29,0,41,6,6,0
0,0,0,0,0,15,0,15,41,0,0,0,0,5,5,19,5,6,6,101,0,0,5,5,5,44,0,0,5,13,14,5,14,6,44
0,0,0,0,0,15,0,15,41,15,5,0,0,0,5,19,5,0,5,44,15,0,15,0,41,0,0,0,0,5,5,5,6,6,0
0,0,0,0,15,0,41,0,0,0,0,41,0,0,0,5,5,5,5,5,41,102,0,41,0,0,0,41,0,0,44,41,0,0,0
0,0,0,0,0,0,41,41,0,41,0,15,0,0,0,5,5,0,5,5,0,41,41,73,73,0,41,0,41,0,0,41,1,0,0
0,0,0,0,0,0,41,41,81,0,0,0,0,0,15,31,5,5,8,5,5,0,0,0,0,41,0,41,41,0,0,41,0,0,0
0,0,0,0,0,0,0,0,0,0,0,0,41,81,0,15,5,5,5,6,6,5,37,0,0,0,0,0,0,0,0,0,0,0,0
0,0,0,0,0,0,0,0,0,0,0,0,0,0,0,15,5,5,5,6,6,0,0,0,0,0,0,0,0,0,0,0,0,0,0
0,0,0,0,0,0,0,0,0,0,0,0,0,0,0,15,5,19,5,81,0,0,0,0,0,0,0,0,0,0,0,0,44,0,0
0,0,0,0,0,0,0,0,0,0,0,0,0,0,0,15,0,6,95,44,0,0,0,0,0,0,0,41,41,0,0,0,0,0,0
0,0,0,0,0,0,0,0,0,0,0,0,0,0,0,0,0,41,81,0,0,0,0,0,0,0,0,0,0,0,0,0,0,0,0
0,0,0,0,0,0,0,0,0,0,0,0,0,0,0,0,0,0,0,0,0,0,0,0,0,0,0,0,0,0,0,44,0,0,0
0,0,0,0,0,0,0,0,0,0,0,0,0,0,0,0,0,0,0,0,0,0,0,0,0,0,0,0,0,0,0,0,0,0,0
endlayer

layer
0,0,99,0,0,0,0,0,0,0,0,0,0,0,0,0,0,0,0,0,0,0,0,0,0,0,0,0,0,0,0,3,7,100,0
0,0,0,0,0,0,0,0,0,0,99,0,0,0,0,0,0,15,0,0,0,0,0,0,0,0,0,0,0,0,0,63,31,66,66
0,0,0,0,0,0,0,0,0,0,0,0,0,0,0,0,0,0,0,0,66,0,0,0,0,0,0,0,0,1,0,0,0,0,0
0,0,0,0,0,99,0,0,0,0,0,0,0,0,66,66,66,66,0,66,0,66,0,0,0,0,0,0,0,0,0,66,1,0,0
0,0,0,0,0,0,0,0,0,0,0,0,0,66,5,5,5,5,15,0,0,0,0,0,0,3,0,0,0,0,66,66,0,0,66
0,0,0,0,0,0,0,0,0,0,0,0,15,5,5,5,5,5,5,0,0,0,0,0,0,92,0,56,0,0,66,0,66,0,0
0,0,0,0,0,0,0,0,0,0,0,15,5,23,5,5,0,8,5,5,0,0,0,83,5,5,8,8,8,5,0,0,0,0,0
0,0,0,0,0,0,0,0,0,0,15,5,5,5,5,5,5,5,5,5,52,72,0,83,5,5,8,8,44,5,5,4,66,0,66
0,0,0,0,0,0,0,0,0,0,66,5,5,5,5,0,0,8,23,5,5,5,52,0,70,5,5,19,44,42,5,5,0,44,0
0,0,0,0,0,0,0,0,15,0,0,5,5,5,19,5,5,5,5,5,5,66,20,0,5,5,8,19,8,5,5,0,0,0,0
0,0,0,0,0,0,0,0,15,0,5,5,5,5,19,5,5,5,5,5,23,5,52,0,5,23,8,8,8,8,84,0,0,0,44
0,0,0,0,0,0,0,6,0,0,5,5,5,8,19,5,5,5,5,5,5,0,0,0,4,5,8,8,0,8,84,0,5,0,44
0,0,0,0,0,0,0,6,6,5,23,23,23,23,23,8,5,5,5,5,0,0,0,0,0,5,8,8,8,57,44,0,0,44,0
6,0,0,0,0,0,0,6,6,5,5,5,5,5,5,8,8,5,5,0,0,5,5,0,0,0,41,5,29,0,0,0,0,0,0
0,0,0,0,0,0,0,15,0,5,5,5,5,5,5,5,5,6,44,0,101,5,5,5,5,44,0,5,29,66,0,41,55,0,0
0,0,0,0,0,15,0,15,41,0,6,6,6,5,0,5,6,6,44,15,0,0,0,5,5,44,0,5,13,14,5,44,6,0,44
0,0,0,0,0,15,0,15,41,15,6,0,6,5,0,5,5,5,5,15,15,0,15,0,41,0,0,0,5,5,44,0,0,0,0
0,0,0,0,15,0,41,0,0,0,0,41,71,5,5,19,5,5,5,5,41,102,0,41,0,0,0,41,0,0,44,41,0,0,0
0,0,0,0,0,0,41,41,0,41,0,15,0,5,5,19,5,0,5,5,0,41,41,73,73,0,41,0,41,41,0,41,0,0,0
0,0,0,0,0,0,41,41,81,0,0,0,0,0,15,5,5,5,8,5,5,0,0,0,0,41,0,41,41,0,0,41,0,41,41
0,0,0,0,0,0,0,0,0,0,0,0,41,81,103,15,5,5,5,5,6,0,0,0,41,0,0,0,0,0,0,0,0,0,0
0,0,0,0,0,0,0,0,0,0,0,0,0,0,0,15,5,5,6,5,44,0,0,0,0,0,0,0,0,0,0,0,0,0,0
0,0,0,0,0,0,0,0,0,0,0,0,0,0,0,15,5,5,5,81,0,0,0,0,0,0,0,0,0,0,0,0,44,0,0
0,0,0,0,0,0,0,0,0,0,0,0,0,0,0,15,6,6,6,44,0,0,0,0,0,0,0,41,41,0,0,0,0,0,0
0,0,0,0,0,0,0,0,0,0,0,0,0,0,0,0,31,41,81,0,0,0,0,0,0,0,0,0,0,0,0,0,0,0,0
0,0,0,0,0,0,0,0,0,0,0,0,0,0,0,0,0,0,0,0,0,0,0,0,0,0,0,0,0,0,0,44,0,0,0
0,0,0,0,0,0,0,0,0,0,0,0,0,0,0,0,0,0,0,0,0,0,0,0,0,0,0,0,0,0,0,0,0,0,0
endlayer

layer
0,0,99,0,0,0,0,0,0,0,0,0,0,0,0,0,0,0,0,0,0,0,0,0,0,0,0,0,0,0,0,7,56,0,0
0,0,0,0,0,0,0,0,0,0,99,0,0,0,0,0,0,15,0,0,0,0,0,0,1,0,0,0,0,0,0,0,0,66,66
0,0,0,0,0,0,0,0,0,0,0,0,0,0,0,0,0,0,0,0,66,0,0,0,0,1,0,0,0,0,0,0,66,0,0
0,0,0,0,0,99,0,0,0,0,0,0,0,0,0,66,66,0,0,66,0,66,0,0,0,3,0,0,1,0,0,66,0,0,0
0,0,0,0,0,0,0,0,0,0,0,0,0,54,5,5,5,0,15,0,0,0,0,0,0,0,0,0,0,0,66,66,0,0,66
0,1,0,0,0,0,0,0,0,0,0,0,0,66,5,5,5,5,15,0,0,0,55,5,0,0,7,0,5,5,66,0,66,0,0
0,0,0,0,0,0,0,0,0,0,0,15,5,5,5,5,5,5,5,5,5,5,5,5,5,5,8,8,8,43,0,0,0,0,0
0,0,0,0,0,0,0,0,0,0,0,0,5,5,19,5,5,5,5,5,5,5,5,5,5,8,23,8,44,0,0,0,66,0,66
0,0,0,0,0,0,0,0,0,0,66,0,5,5,19,5,5,5,5,5,5,5,5,5,5,23,8,8,8,5,5,0,0,44,0
0,0,0,0,0,0,0,0,15,5,5,5,23,23,8,5,5,5,5,5,5,5,20,0,5,23,8,8,8,8,5,5,0,0,41
0,0,0,0,0,0,0,0,15,5,5,5,5,5,0,5,5,5,5,5,5,31,0,0,5,5,8,8,8,8,0,0,0,0,44
0,0,0,0,0,0,0,15,5,5,19,5,5,5,0,51,51,5,5,5,0,0,0,0,0,5,8,8,0,8,44,0,0,0,44
0,0,0,0,0,0,0,6,5,5,8,5,5,5,51,8,0,51,5,78,0,0,0,0,0,5,8,8,8,57,44,0,0,44,0
6,0,0,0,0,0,0,15,5,99,99,99,5,5,51,8,8,51,51,0,0,0,4,0,0,0,5,29,41,0,0,0,0,0,0
0,0,0,0,0,0,0,15,99,99,5,5,5,5,51,51,51,51,51,6,101,0,0,4,4,0,5,29,66,0,0,41,0,0,0
0,0,0,0,0,15,0,15,41,0,6,6,6,99,0,51,51,51,6,15,0,0,0,0,0,0,5,13,14,0,0,44,0,0,44
0,0,0,0,0,15,0,15,41,15,6,6,6,99,99,5,5,5,0,15,15,0,15,0,41,0,0,5,5,0,44,0,0,0,0
0,0,0,0,15,15,41,0,0,0,31,41,6,99,5,5,5,5,5,6,41,102,0,41,0,0,0,41,0,0,44,41,0,0,0
0,0,0,0,0,0,41,41,0,41,0,15,6,5,5,8,23,5,5,5,0,41,41,73,73,0,41,0,41,41,41,41,44,0,0
0,0,0,0,0,0,41,41,81,0,0,54,5,5,5,19,5,5,5,5,0,0,0,41,0,41,0,41,41,0,0,41,0,41,41
0,0,0,0,0,0,0,0,0,0,0,0,41,81,5,5,5,5,6,5,0,0,0,0,41,0,0,0,0,0,0,0,0,0,0
0,0,0,0,0,0,0,0,0,0,0,0,0,0,31,6,5,6,6,5,0,0,0,0,0,0,0,0,0,0,0,0,0,0,0
0,0,0,0,0,0,0,0,0,0,0,0,0,0,0,0,5,5,5,0,0,0,0,0,0,0,0,0,0,0,0,0,44,0,0
0,0,0,0,0,0,0,0,0,0,0,0,0,0,0,15,6,5,5,95,0,0,0,0,0,0,0,41,41,0,0,0,0,0,0
0,0,0,0,0,0,0,0,0,0,0,0,0,0,0,0,0,41,81,0,0,0,0,0,0,0,0,0,0,0,0,0,0,0,0
0,0,0,0,0,0,0,0,0,0,0,0,0,0,0,0,0,0,0,0,0,0,0,0,0,0,0,0,0,0,0,44,0,0,0
0,0,0,0,0,0,0,0,0,0,0,0,0,0,0,0,0,0,0,0,0,0,0,0,0,0,0,0,0,0,0,0,0,0,0
endlayer

layer
0,0,99,99,99,99,99,99,99,99,0,0,0,0,0,0,0,0,0,0,0,0,0,0,0,0,0,0,7,0,0,100,0,0,0
0,0,0,99,99,99,99,99,99,99,99,0,0,0,0,0,0,15,0,0,0,0,0,0,0,0,0,0,0,0,0,0,0,66,66
0,0,0,99,99,99,99,99,99,0,0,0,0,0,0,0,0,0,0,0,66,1,0,0,0,0,0,0,66,66,0,0,66,0,0
0,0,0,0,0,99,0,0,0,0,0,0,0,0,0,66,55,0,0,66,0,66,0,0,0,0,0,0,0,0,0,66,0,0,66
0,0,0,0,0,0,0,0,0,0,0,0,0,0,15,5,5,0,15,0,0,0,0,0,0,0,0,0,0,0,66,66,0,0,66
0,0,0,0,0,0,0,0,0,0,0,0,0,66,6,5,5,0,15,55,0,5,5,0,0,0,56,0,0,44,66,0,66,0,0
0,0,0,0,0,0,0,0,0,0,0,15,5,5,5,5,5,5,5,5,5,5,5,5,5,8,8,8,8,43,5,0,0,0,0
0,0,0,0,0,0,0,0,0,0,0,5,5,5,5,6,5,5,5,5,5,5,23,23,23,23,8,8,8,5,0,0,66,0,66
0,0,0,0,0,0,0,0,0,0,66,5,19,5,5,5,5,5,0,5,5,5,5,5,5,8,8,8,8,8,5,5,5,44,0
0,0,0,0,0,0,0,0,15,5,5,23,5,5,5,5,5,5,0,5,5,5,20,0,5,0,8,8,8,8,5,5,0,0,41
0,0,0,0,0,0,0,0,15,5,5,5,5,5,51,51,51,5,5,5,4,0,0,0,5,5,8,8,8,8,8,0,0,0,44
0,0,0,0,0,0,0,0,0,5,5,5,5,51,51,51,51,51,5,5,0,0,0,0,0,5,23,8,23,8,44,0,0,0,44
0,0,0,0,0,0,0,15,5,5,5,5,5,51,51,8,0,51,51,0,0,0,0,0,0,5,29,82,8,104,44,0,0,44,0
4,0,0,0,0,0,0,54,5,5,5,5,5,51,51,8,8,51,51,0,0,0,0,0,0,5,29,0,48,105,0,0,0,0,0
0,0,0,0,0,0,0,15,5,99,6,6,6,51,51,51,51,51,51,44,15,0,0,0,0,5,29,66,0,0,0,41,0,0,0
0,0,0,0,0,15,0,15,41,5,6,6,6,51,51,51,51,51,44,15,0,0,0,0,0,5,13,14,0,0,0,44,0,0,44
0,0,0,0,0,15,0,15,41,15,6,6,6,6,5,5,6,0,0,15,15,0,15,0,41,5,5,5,0,0,44,0,0,0,0
0,0,0,0,15,15,41,0,0,0,80,41,6,99,5,5,0,6,6,0,41,102,0,41,0,0,0,41,0,0,44,41,0,0,0
0,0,0,0,0,0,41,41,0,41,0,0,6,5,5,5,5,5,6,6,0,41,41,73,73,0,41,0,41,41,41,41,44,0,0
0,0,0,0,0,0,41,41,81,0,0,0,15,5,5,5,5,8,5,5,0,0,0,41,0,41,0,41,41,0,0,41,0,41,41
0,0,0,0,0,0,0,0,0,0,0,0,0,41,0,6,5,5,6,6,0,0,0,0,41,0,0,0,0,0,0,0,0,0,0
0,0,0,0,0,0,0,0,0,0,0,0,0,0,54,6,5,5,5,95,0,0,0,0,0,0,0,0,0,0,0,0,0,0,0
0,0,0,0,0,0,0,0,0,0,0,0,0,0,0,0,0,5,5,0,0,0,0,0,0,0,0,0,0,0,0,0,44,0,0
0,0,0,0,0,0,0,0,0,0,0,0,0,0,0,0,15,5,95,0,0,0,0,0,0,0,0,73,41,41,0,0,0,0,0
0,0,0,0,0,0,0,0,0,0,0,0,0,0,0,0,0,41,0,0,0,0,0,0,0,0,0,0,0,0,41,0,0,0,0
0,0,0,0,0,0,0,0,0,0,0,0,0,0,0,0,0,0,0,0,0,0,0,0,0,0,0,0,0,0,0,44,0,0,0
0,0,0,0,0,0,0,0,0,0,0,0,0,0,0,0,0,0,0,0,0,0,0,0,0,0,0,0,0,0,41,0,0,0,0
endlayer

layer
0,0,99,99,99,99,99,99,99,99,0,0,0,0,0,0,0,0,0,0,0,0,0,66,0,59,0,0,56,0,66,0,0,0,0
0,0,0,99,99,99,99,99,99,99,0,0,0,0,0,0,0,15,0,0,0,0,0,0,0,66,0,66,1,0,0,0,0,66,66
0,0,0,99,99,99,99,99,99,0,0,0,0,0,0,0,0,0,0,0,66,0,0,66,66,0,0,0,66,66,0,0,66,0,0
0,0,0,0,0,99,0,0,0,0,0,0,0,0,0,0,0,0,0,66,0,66,5,0,0,0,0,0,0,0,0,66,0,0,66
0,0,0,0,0,0,0,0,0,0,0,0,0,0,0,0,0,0,15,0,0,0,5,0,0,0,0,5,5,0,66,66,0,0,66
0,0,0,0,0,0,0,0,0,0,0,0,0,0,15,5,66,0,15,41,5,5,19,0,5,0,0,5,5,44,66,0,66,0,0
0,0,0,0,0,0,0,0,0,0,0,0,4,0,6,5,5,6,0,5,5,5,19,0,5,8,8,8,8,55,5,37,0,0,0
0,0,0,0,0,0,0,0,0,0,0,0,5,5,6,6,5,5,5,5,5,5,5,5,8,0,0,8,8,8,5,0,0,5,66
0,0,0,0,0,0,0,0,0,0,0,66,5,5,6,5,5,5,0,5,5,5,5,5,5,8,5,5,8,23,23,23,5,5,5
0,0,0,0,0,0,0,0,0,15,5,5,5,5,5,5,5,5,0,5,5,5,20,0,5,0,21,19,23,8,5,5,0,0,41
0,0,0,0,0,0,0,0,54,5,5,5,5,51,51,51,51,5,5,5,31,0,0,0,5,0,0,19,8,8,8,5,5,0,44
0,0,0,0,0,0,0,0,0,5,5,5,5,51,51,51,51,51,5,15,0,0,0,5,5,8,82,82,8,8,0,0,0,0,44
0,0,0,0,0,0,0,0,20,5,5,5,5,51,51,8,0,51,51,0,0,0,0,0,5,12,0,98,8,8,44,0,0,44,0
0,0,0,0,0,0,0,15,6,6,5,5,5,51,51,8,8,51,51,0,0,0,0,0,5,12,0,0,48,5,0,0,0,0,0
0,0,0,0,0,0,0,15,6,6,99,6,6,51,51,51,51,51,101,0,15,0,0,0,5,12,66,66,0,0,0,41,0,0,0
0,0,0,0,0,15,0,15,5,5,6,6,6,6,51,51,51,51,44,15,0,0,0,0,5,12,5,5,0,0,0,44,0,0,44
0,0,0,0,0,15,0,15,41,5,6,6,6,6,5,6,6,6,0,15,15,0,15,0,41,5,0,0,0,0,44,0,0,0,0
0,0,0,0,15,15,41,0,0,31,80,81,6,5,5,6,6,6,55,0,41,102,0,41,0,0,0,41,0,0,44,41,0,0,0
0,0,0,0,0,0,41,41,0,41,0,0,0,6,41,41,6,6,6,0,0,41,41,73,73,0,41,0,41,41,41,41,44,0,0
0,0,0,0,0,0,41,41,81,0,0,0,0,0,0,0,6,8,5,6,0,0,0,41,0,41,0,41,41,0,0,41,0,41,41
0,0,0,0,0,0,0,0,0,0,0,0,0,0,0,0,6,6,5,6,0,0,0,0,41,41,0,0,0,0,0,0,0,0,0
0,0,0,0,0,0,0,0,0,0,0,0,0,0,0,4,74,5,5,95,0,0,0,0,0,0,0,0,0,0,0,0,0,0,0
0,0,0,0,0,0,0,0,0,0,0,0,0,0,0,0,0,81,81,0,0,0,0,0,0,0,0,0,0,0,0,0,44,0,0
0,0,0,0,0,0,0,0,0,0,0,0,0,0,0,0,0,0,0,0,0,0,0,0,0,0,0,73,41,41,0,0,0,0,0
0,1,0,0,0,0,0,0,0,0,0,0,0,0,0,0,0,0,0,0,0,0,0,0,0,0,0,0,0,0,41,0,44,0,0
0,0,0,0,0,0,0,0,0,0,0,0,0,0,0,0,0,0,0,0,0,0,0,0,0,0,0,0,0,0,0,44,0,0,0
0,1,0,0,0,0,0,0,0,0,0,0,0,0,0,0,0,0,0,0,0,0,0,0,0,0,0,0,41,0,41,0,0,0,0
endlayer

layer
0,0,0,99,99,99,99,99,99,0,0,0,0,0,0,0,0,15,0,0,0,0,0,66,66,66,0,66,0,0,66,0,0,0,0
0,0,0,99,99,99,99,99,99,0,0,0,0,0,0,0,15,15,0,0,0,0,0,0,66,66,0,66,0,0,0,0,0,66,66
0,0,0,0,99,99,0,99,99,0,0,0,0,0,0,0,0,0,0,0,66,0,0,66,66,0,0,0,66,66,0,0,66,0,0
0,0,0,0,0,0,0,0,0,0,0,0,0,0,0,0,15,0,0,66,0,66,66,5,5,0,5,0,0,0,0,66,0,0,66
0,0,0,0,0,0,0,0,0,0,0,0,0,0,0,55,0,0,15,0,0,5,5,5,5,5,5,5,5,0,66,66,0,0,66
0,0,0,0,0,0,0,0,0,0,0,0,0,0,15,6,66,0,15,41,0,5,5,0,5,5,5,5,5,0,0,5,66,0,0
0,0,0,0,0,0,0,0,0,0,0,0,0,54,6,6,6,44,0,73,5,5,5,0,8,8,0,8,8,8,44,5,5,5,0
0,0,0,0,0,0,0,0,0,0,0,0,0,0,6,6,6,78,0,5,5,5,5,5,8,5,5,8,8,8,0,5,5,5,5
0,0,0,0,0,0,0,0,0,0,0,55,5,5,6,6,5,5,5,5,5,0,0,0,5,8,21,21,21,23,44,8,23,23,23
0,0,0,0,0,0,0,0,0,0,15,5,5,5,5,5,5,5,5,5,0,0,20,0,0,0,21,21,19,8,0,0,5,5,0
0,0,0,0,0,0,0,0,0,55,5,5,5,5,5,5,99,5,5,31,0,0,0,0,0,0,82,82,8,19,8,0,0,5,44
0,0,0,0,0,0,0,0,0,5,5,5,5,5,6,51,51,5,6,15,0,0,0,5,5,8,15,15,8,23,23,5,5,0,44
0,0,0,0,0,0,0,0,20,5,5,5,5,5,51,8,0,51,6,0,0,0,0,0,5,0,0,0,8,8,0,0,5,44,0
0,0,0,0,0,0,0,15,6,6,5,5,5,6,51,8,51,51,73,0,0,0,0,0,5,5,0,0,19,5,0,0,0,0,0
0,0,0,0,0,0,0,15,5,6,5,5,5,6,6,51,51,6,15,0,15,0,0,0,5,5,0,0,5,5,5,41,0,0,0
0,0,0,0,0,15,0,0,5,5,6,5,5,6,6,6,6,6,0,15,0,0,0,0,5,5,5,5,0,31,0,44,0,0,44
0,0,0,0,0,15,0,15,6,5,6,6,6,6,6,6,6,6,0,15,15,0,15,0,41,0,0,0,0,0,44,0,0,0,0
0,0,0,0,15,15,41,0,0,0,80,81,81,0,0,0,0,4,0,0,41,102,0,41,0,0,0,41,0,0,44,41,0,0,0
0,0,0,0,0,0,41,41,0,41,0,0,0,0,0,0,0,4,106,0,0,41,41,73,73,0,41,0,41,41,41,41,44,0,0
0,0,0,0,0,0,41,41,81,0,0,0,0,0,0,0,0,5,5,95,0,0,0,41,0,41,0,41,41,0,0,41,0,41,41
0,0,0,0,0,0,0,0,0,0,0,0,0,0,0,0,0,5,6,6,0,0,0,0,41,41,41,0,0,41,0,0,0,0,0
0,0,0,0,0,0,0,0,0,0,0,0,0,0,0,0,0,0,0,31,0,0,0,0,0,15,0,0,0,0,0,0,0,0,0
0,0,0,0,0,0,0,0,0,0,0,0,0,0,0,0,0,0,0,0,0,0,0,0,0,0,0,0,0,0,0,0,44,0,0
0,0,0,0,0,0,0,0,0,0,0,0,0,0,0,0,0,0,0,0,0,0,0,0,0,0,0,73,41,41,0,0,0,0,0
0,0,0,0,0,0,0,0,0,0,0,0,0,0,0,0,0,0,0,0,0,0,0,0,0,0,0,0,0,0,41,0,44,0,0
0,0,0,0,0,0,0,0,0,0,0,0,0,0,0,0,0,0,0,0,0,0,0,0,0,0,0,0,0,0,0,44,0,0,0
0,0,0,0,0,0,0,0,0,0,0,0,0,0,0,0,0,0,0,0,0,0,0,0,0,0,0,0,41,0,41,0,0,0,0
endlayer

layer
0,0,0,99,99,99,99,99,99,0,0,0,0,0,0,0,0,15,0,0,0,0,0,66,66,66,0,66,0,0,66,0,0,66,0
0,0,0,0,99,99,99,99,0,0,0,0,0,0,0,0,15,15,0,0,0,0,0,0,66,66,0,66,0,0,0,0,0,66,66
0,0,0,0,99,99,0,0,0,0,0,0,0,0,0,0,0,0,0,0,66,0,0,0,66,0,0,0,66,66,0,0,66,0,0
0,0,0,0,0,0,0,0,0,0,0,0,0,0,0,0,15,0,0,66,5,66,66,20,5,0,0,0,0,0,0,66,0,0,66
0,0,0,0,0,0,0,0,0,0,0,0,0,0,0,0,0,0,15,5,5,6,5,66,5,0,5,5,5,5,66,0,0,0,66
0,0,0,0,0,0,0,0,0,0,0,0,0,0,15,6,0,0,15,41,5,5,5,5,5,0,5,0,8,5,5,66,0,0,5
0,0,0,0,0,0,0,0,0,0,0,0,0,15,6,6,6,44,0,41,73,6,5,5,8,8,0,8,8,8,44,5,5,5,5
0,0,0,0,0,0,0,0,0,0,0,0,0,0,6,6,6,0,0,4,6,15,5,5,8,0,21,21,8,23,0,5,0,5,5
0,0,0,0,0,0,0,0,0,0,0,0,0,0,0,73,41,0,0,6,0,0,0,0,5,21,0,41,27,0,0,5,0,5,5
0,0,0,0,0,0,0,0,0,0,0,15,5,66,6,44,0,6,6,0,0,0,20,0,0,23,44,44,27,19,8,5,0,5,5
0,0,0,0,0,0,0,0,0,0,66,5,5,5,5,6,6,6,6,37,0,0,0,5,8,23,41,66,8,23,23,5,5,5,0
0,0,0,0,0,0,0,0,0,5,5,5,5,5,6,51,51,6,0,15,0,0,0,73,8,0,15,15,8,23,23,23,5,0,42
0,0,0,0,0,0,0,0,20,5,5,5,5,5,51,51,51,51,15,0,0,0,0,5,5,0,0,0,8,23,5,5,5,0,0
0,0,0,0,0,0,0,0,5,6,6,6,5,6,51,51,51,0,73,0,0,0,5,5,5,5,0,0,8,23,0,5,5,0,0
0,0,0,0,0,0,0,0,5,6,6,6,6,6,6,51,0,0,15,0,15,0,0,5,5,8,0,8,23,8,44,41,0,0,0
0,0,0,0,0,15,0,6,5,6,6,6,6,6,6,0,4,0,0,15,0,0,0,0,5,5,8,5,5,5,0,44,0,0,44
0,0,0,0,0,15,0,31,5,6,6,6,6,0,0,0,0,4,0,15,15,0,15,0,41,0,5,5,0,0,44,0,0,0,0
0,0,0,0,15,15,41,0,0,6,80,81,0,0,0,0,0,0,0,0,41,102,0,41,0,0,5,41,0,0,44,41,0,0,0
0,0,0,0,0,0,41,41,0,41,0,0,0,0,0,0,0,0,106,0,0,41,41,73,73,0,41,0,41,41,41,41,44,0,0
0,0,0,0,0,0,41,41,81,0,0,0,0,0,0,0,0,6,6,95,0,0,0,41,0,41,0,41,41,0,0,41,41,41,41
0,0,0,0,0,0,0,0,0,0,0,0,0,0,0,0,0,6,6,37,0,0,0,0,41,41,41,0,0,41,0,0,0,0,0
0,0,0,0,0,0,0,0,0,0,0,0,0,0,0,0,0,0,0,0,0,0,0,0,0,15,0,0,0,0,0,41,0,0,0
0,0,0,0,0,0,0,0,0,0,0,0,0,0,0,0,0,0,0,0,0,0,0,0,0,0,81,0,0,0,41,0,44,0,0
0,0,0,0,0,0,0,0,0,0,0,0,0,0,0,0,0,0,0,0,0,0,0,0,0,0,0,73,41,41,0,0,44,0,0
0,0,0,0,0,0,0,0,0,0,0,0,0,0,0,0,0,0,0,0,0,0,0,0,0,0,0,0,0,0,41,0,44,0,0
0,0,0,0,0,0,0,0,0,0,0,0,0,0,0,0,0,0,0,0,0,0,0,0,0,0,0,0,0,0,0,44,0,0,0
0,0,0,0,0,0,0,0,0,0,0,0,0,0,0,0,0,0,0,0,0,0,0,0,0,0,0,0,41,0,41,0,0,0,0
endlayer

layer
0,0,0,0,0,0,0,0,0,0,0,0,0,0,0,0,0,15,0,0,0,0,0,66,66,66,0,66,0,0,66,0,0,66,0
0,0,0,0,0,0,0,0,0,0,0,0,0,0,0,0,15,15,0,0,0,0,0,0,66,66,0,66,0,0,0,0,0,66,66
0,0,0,0,0,0,0,0,0,0,0,0,0,0,0,0,0,66,0,0,55,0,0,0,0,0,0,0,66,66,0,0,66,0,0
0,0,0,0,0,0,0,0,0,0,0,0,0,0,0,0,15,0,0,66,5,0,66,66,66,0,5,0,5,0,0,66,0,0,66
0,0,0,0,0,0,0,0,0,0,0,0,0,0,0,0,0,0,15,5,5,6,6,5,5,5,5,5,5,0,55,5,0,0,0
0,0,0,0,0,0,0,0,0,0,0,0,0,0,15,6,0,0,15,41,41,6,5,5,5,5,5,5,8,5,5,5,0,0,0
0,0,0,0,0,0,0,0,0,0,0,0,0,15,6,6,6,44,0,41,41,31,5,5,8,23,23,8,8,8,44,5,5,5,0
0,0,0,0,0,0,0,0,0,0,0,0,0,0,41,6,41,0,0,0,0,15,5,5,8,0,5,5,8,21,0,0,0,5,5
0,0,0,0,0,0,0,0,0,0,0,0,0,0,0,73,0,0,0,0,0,0,0,0,0,0,5,41,41,27,0,0,0,0,5
0,0,0,0,0,0,0,0,0,0,0,0,55,66,4,0,41,0,0,0,0,0,20,0,8,8,44,44,0,27,23,44,0,5,5
0,0,0,0,0,0,0,0,0,0,0,4,6,6,6,4,0,4,0,0,0,0,0,19,19,8,41,66,15,19,8,0,0,5,0
0,0,0,0,0,0,0,0,0,6,6,5,6,6,6,66,0,0,0,15,0,0,0,41,8,0,15,0,8,23,5,0,23,23,5
0,0,0,0,0,0,0,0,20,6,6,6,6,6,6,0,0,15,15,0,0,5,5,5,0,0,0,0,8,23,5,5,5,5,5
0,0,0,0,0,0,0,0,5,6,6,6,6,6,6,44,4,0,73,0,0,5,5,5,0,0,5,5,8,19,5,5,5,0,0
0,0,0,0,0,0,0,0,5,6,6,6,6,6,95,0,0,0,15,0,15,0,5,5,5,8,8,8,23,8,5,5,0,0,0
0,0,0,0,0,15,0,6,5,6,6,6,6,0,0,0,0,0,0,15,0,0,5,5,5,5,8,5,5,5,5,44,0,0,44
0,0,0,0,0,15,0,6,5,6,6,6,44,0,0,0,0,0,0,15,15,0,15,5,41,0,5,0,0,5,44,0,0,0,0
0,0,0,0,15,15,41,0,6,6,95,0,0,0,0,0,0,0,0,0,41,102,0,41,0,0,5,5,5,5,44,41,0,0,0
0,0,0,0,0,0,41,41,0,81,95,0,0,0,0,0,0,0,106,0,0,41,41,73,73,0,41,0,41,41,41,41,44,0,0
0,0,0,0,0,0,41,41,81,81,0,0,0,0,0,0,0,6,6,95,0,0,0,41,0,41,0,41,41,0,0,41,41,41,41
0,0,0,0,0,0,0,0,0,0,0,0,0,0,0,0,0,6,6,95,0,0,0,0,41,41,41,0,41,41,0,0,0,0,0
0,0,0,0,0,0,0,0,0,0,0,0,0,0,0,0,0,0,31,0,0,0,0,0,0,15,0,0,0,0,0,41,0,0,0
0,0,0,0,0,0,0,0,0,0,0,0,0,0,0,0,0,0,0,0,0,0,0,0,0,0,81,0,0,0,41,0,44,0,0
0,0,0,0,0,0,0,0,0,0,0,0,0,0,0,0,0,0,0,0,0,0,0,0,0,0,0,73,41,41,0,0,44,0,0
0,0,0,0,0,0,0,0,0,0,0,0,0,0,0,0,0,0,0,0,0,0,0,0,0,0,0,0,0,0,41,0,44,0,0
0,0,0,0,0,0,0,0,0,0,0,0,0,0,0,0,0,0,0,0,0,0,0,0,0,0,0,0,0,0,0,44,0,0,0
0,0,0,0,0,0,0,0,0,0,0,0,0,0,0,0,0,0,0,0,0,0,0,0,0,0,0,0,41,0,41,0,0,0,0
endlayer

layer
0,0,0,0,0,0,0,0,0,0,0,0,0,0,0,0,0,15,0,0,0,0,0,66,66,20,0,66,0,0,66,0,0,66,0
0,0,0,0,0,0,0,0,0,0,0,0,0,0,0,0,15,15,0,0,0,0,0,0,66,66,0,66,0,0,0,0,0,66,66
0,0,0,0,0,0,0,0,0,0,0,0,0,0,0,0,0,66,0,0,66,0,0,0,0,6,0,0,0,66,0,0,66,0,0
0,0,0,0,0,0,0,0,0,0,0,0,0,0,0,0,15,0,0,0,5,0,0,0,55,5,5,0,0,0,0,0,0,0,66
0,0,0,0,0,0,0,0,0,0,0,0,0,0,0,0,41,0,0,0,5,5,0,5,5,5,66,5,66,0,0,0,0,0,0
0,0,0,0,0,0,0,0,0,0,0,0,0,0,55,6,0,0,15,5,5,5,5,5,5,5,5,5,8,0,0,4,0,0,0
0,0,0,0,0,0,0,0,0,0,0,0,0,15,6,6,6,44,0,41,41,15,5,5,8,8,5,8,8,8,0,5,5,5,0
0,0,0,0,0,0,0,0,0,0,0,0,0,0,41,41,41,0,0,0,0,0,15,5,19,5,5,5,8,5,5,5,5,0,0
0,0,0,0,0,0,0,0,0,0,0,0,0,0,0,15,0,0,0,0,0,0,0,5,19,0,5,31,41,41,27,21,5,5,0
0,0,0,0,0,0,0,0,0,0,0,0,0,0,0,0,41,0,0,0,0,0,20,19,19,5,5,44,0,0,97,21,0,0,44
0,0,0,0,0,0,0,0,0,0,0,0,0,4,0,0,0,0,0,0,0,5,5,8,8,5,41,66,15,8,8,5,5,5,0
0,0,0,0,0,0,0,0,0,0,6,66,0,0,0,66,0,0,0,15,0,0,5,5,8,8,15,8,8,8,0,0,5,5,8
0,0,0,0,0,0,0,0,20,6,6,6,6,0,0,0,0,15,15,0,6,5,5,5,8,0,5,8,8,41,5,5,5,0,5
0,0,0,0,0,0,0,54,6,6,6,6,6,4,0,0,0,0,73,0,0,5,5,5,0,0,5,5,0,8,0,0,5,5,5
0,0,0,0,0,0,0,0,5,5,6,6,0,0,0,0,0,0,15,0,15,0,5,5,5,8,8,5,8,8,8,5,0,0,31
0,0,0,0,0,15,0,6,5,5,5,6,95,0,0,0,0,0,0,15,0,0,5,5,5,5,8,5,5,8,5,5,0,0,44
0,0,0,0,0,15,0,6,5,5,5,5,44,0,0,0,0,0,0,15,15,0,5,5,5,5,5,5,5,31,0,5,0,0,0
0,0,0,0,15,15,41,6,6,5,0,0,0,0,0,0,0,0,0,0,41,102,0,5,5,5,5,5,5,44,0,41,0,0,0
0,0,0,0,0,0,41,41,0,81,95,0,0,0,0,0,0,0,0,0,0,41,41,73,73,31,41,5,5,41,41,41,44,0,0
0,0,0,0,0,0,41,41,81,81,0,0,0,0,0,0,0,0,4,0,0,0,0,41,0,41,0,41,41,0,0,41,41,41,41
0,0,0,0,0,0,0,0,0,0,0,0,0,0,0,0,0,0,6,95,0,0,0,0,41,41,41,0,41,41,0,0,0,0,0
0,0,0,0,0,0,0,0,0,0,0,0,0,0,0,0,0,0,0,0,0,0,0,0,0,15,0,0,0,0,0,41,0,0,0
0,0,0,0,0,0,0,0,0,0,0,0,0,0,0,0,0,0,0,0,0,0,0,0,0,0,81,0,0,0,41,0,44,0,0
0,0,0,0,0,0,0,0,0,0,0,0,0,0,0,0,0,0,0,0,0,0,0,0,0,0,0,73,41,41,0,0,44,0,0
0,0,0,0,0,0,0,0,0,0,0,0,0,0,0,0,0,0,0,0,0,0,0,0,0,0,0,0,0,0,41,0,44,0,0
0,0,0,0,0,0,0,0,0,0,0,0,0,0,0,0,0,0,0,0,0,0,0,0,0,0,0,0,0,0,0,44,0,0,0
0,0,0,0,0,0,0,0,0,0,0,0,0,0,0,0,0,0,0,0,0,0,0,0,0,0,0,0,41,0,41,0,0,0,0
endlayer

layer
0,0,0,0,0,0,0,0,0,0,0,0,0,0,0,0,0,15,0,0,0,0,0,66,66,20,0,66,0,0,66,0,0,66,0
0,0,0,0,0,0,0,0,0,0,0,0,0,0,0,0,15,15,0,0,0,0,0,0,66,66,0,66,0,0,0,0,0,66,66
0,0,0,0,0,0,0,0,0,0,0,0,0,0,0,0,0,66,0,0,0,0,0,0,0,0,55,0,0,66,0,0,66,0,0
0,0,0,0,0,0,0,0,0,0,0,0,0,0,0,0,15,0,0,0,0,0,0,0,66,0,5,0,0,0,0,0,0,0,66
0,0,0,0,0,0,0,0,0,0,0,0,0,0,0,0,73,0,0,0,0,0,0,66,5,5,5,5,5,0,0,5,0,0,0
0,0,0,0,0,0,0,0,0,0,0,0,0,0,0,0,0,0,0,0,0,0,0,5,19,5,5,5,8,5,5,5,0,0,0
0,0,0,0,0,0,0,0,0,0,0,0,0,0,15,6,44,0,0,0,54,5,5,5,19,5,5,8,8,8,5,0,55,0,0
0,0,0,0,0,0,0,0,0,0,0,0,0,0,0,41,0,0,0,0,0,0,15,0,19,5,5,15,8,6,6,19,5,0,0
0,0,0,0,0,0,0,0,0,0,0,0,0,0,0,15,0,0,0,0,0,5,5,19,19,5,6,6,41,0,41,73,5,5,5
0,0,0,0,0,0,0,0,0,0,0,0,0,0,0,0,41,0,0,0,5,0,20,19,19,5,0,5,0,0,0,15,5,5,44
0,0,0,0,0,0,0,0,0,0,0,0,0,0,0,0,0,0,0,0,0,0,23,8,8,0,0,5,8,8,97,97,5,0,0
0,0,0,0,0,0,0,0,0,0,6,66,0,0,0,66,0,0,0,15,6,5,5,8,8,23,15,8,8,23,23,5,0,0,8
0,0,0,0,0,0,0,0,20,6,6,6,4,0,15,0,0,15,15,0,6,5,5,5,8,5,0,41,8,5,5,5,0,0,5
0,0,0,0,0,0,0,0,6,6,6,5,6,20,0,0,0,0,73,0,0,5,5,5,5,5,5,5,5,5,5,5,0,5,0
0,0,0,0,0,0,0,0,5,5,6,6,0,0,0,0,0,0,15,0,15,5,5,5,0,0,5,5,8,8,8,5,5,5,5
0,0,0,0,0,15,0,6,5,5,5,5,37,0,0,0,0,0,0,15,0,5,5,5,5,5,8,5,0,8,5,5,5,0,44
0,0,0,0,0,15,6,6,5,5,5,5,95,0,0,0,0,0,0,15,15,5,5,5,5,5,19,5,5,5,5,5,0,0,0
0,0,0,0,15,15,41,6,6,5,0,0,0,0,0,0,0,0,0,0,41,102,5,5,5,5,5,5,5,5,5,41,0,0,0
0,0,0,0,0,0,41,41,6,31,95,0,0,0,0,0,0,0,0,0,0,41,41,73,15,5,5,5,5,41,41,41,44,0,0
0,0,0,0,0,0,41,41,81,81,0,0,0,0,0,0,0,0,55,0,0,0,0,41,0,41,31,41,41,0,0,41,41,41,41
0,0,0,0,0,0,0,0,0,0,0,0,0,0,0,0,0,0,6,0,0,0,0,0,41,41,41,0,41,41,0,0,0,0,41
0,0,0,0,0,0,0,0,0,0,0,0,0,0,0,0,0,0,31,0,0,0,0,0,0,15,0,0,0,0,0,41,0,0,0
0,0,0,0,0,0,0,0,0,0,0,0,0,0,0,0,0,0,0,0,0,0,0,0,0,0,81,0,0,0,41,0,44,0,0
0,0,0,0,0,0,0,0,0,0,0,0,0,0,0,0,0,0,0,0,0,0,0,0,0,0,0,73,41,41,0,0,44,0,0
0,0,0,0,0,0,0,0,0,0,0,0,0,0,0,0,0,0,0,0,0,0,0,0,0,0,0,0,0,0,41,0,44,0,0
0,0,0,0,0,0,0,0,0,0,0,0,0,0,0,0,0,0,0,0,0,0,0,0,0,0,0,0,0,0,0,44,0,0,0
0,0,0,0,0,0,0,0,0,0,0,0,0,0,0,0,0,0,0,0,0,0,0,0,0,0,0,0,41,0,41,0,0,0,0
endlayer

layer
0,0,0,0,0,0,0,0,0,0,0,0,0,0,0,0,0,15,0,0,0,0,0,66,66,20,0,66,0,66,66,0,0,66,0
0,0,0,0,0,0,0,0,0,0,0,0,0,0,0,0,15,15,0,0,0,0,0,0,66,66,0,66,0,0,0,0,0,66,66
0,0,0,0,0,0,0,0,0,0,0,0,0,0,0,0,0,66,0,0,0,0,0,0,0,0,0,0,0,66,0,0,66,0,0
0,0,0,0,0,0,0,0,0,0,0,0,0,0,0,0,15,0,0,0,0,0,0,55,0,0,0,0,5,5,0,0,0,0,66
0,0,0,0,0,0,0,0,0,0,0,0,0,0,0,0,73,0,0,0,0,0,0,5,5,5,5,5,5,5,5,5,5,0,0
0,0,0,0,0,0,0,0,0,0,0,0,0,0,0,0,0,0,0,0,0,5,5,5,5,0,0,0,5,5,5,5,5,0,0
0,0,0,0,0,0,0,0,0,0,0,0,0,0,15,6,44,0,0,54,5,5,5,0,5,5,5,15,8,5,5,5,5,5,37
0,0,0,0,0,0,0,0,0,0,0,0,0,0,0,0,0,0,0,0,5,0,15,8,8,44,41,0,8,6,6,8,5,0,0
0,0,0,0,0,0,0,0,0,0,0,0,0,0,0,15,0,0,0,5,5,5,0,0,4,0,6,6,6,0,41,15,5,0,0
0,0,0,0,0,0,0,0,0,0,0,0,0,0,0,0,41,0,5,5,5,5,5,0,8,0,5,5,8,0,0,0,15,5,5
0,0,0,0,0,0,0,0,0,0,0,0,0,0,0,0,0,71,0,31,0,5,8,23,8,5,5,0,19,8,44,15,0,0,0
0,0,0,0,0,0,0,0,0,0,4,0,0,0,0,66,0,0,54,6,6,5,8,8,8,5,15,5,8,8,97,97,5,0,5
0,0,0,0,0,0,0,0,66,6,6,0,0,0,15,0,0,15,15,5,5,0,5,8,8,5,0,41,41,5,5,5,5,5,5
0,0,0,0,0,0,0,0,6,6,6,5,66,20,0,0,0,0,73,6,6,5,5,5,5,5,5,5,5,5,5,5,5,5,5
0,0,0,0,0,0,54,6,5,5,6,6,6,0,0,0,0,0,15,0,15,5,5,5,5,5,5,5,5,0,8,5,5,0,0
0,0,0,0,0,15,0,6,5,5,5,5,0,0,0,0,0,0,0,15,0,5,5,0,5,5,8,5,0,8,8,5,5,5,44
0,0,0,0,0,15,6,6,5,5,5,0,0,0,0,0,0,0,0,15,5,5,5,5,5,5,8,5,5,5,5,5,0,0,0
0,0,0,0,15,15,6,6,6,5,6,0,0,0,0,0,0,0,0,0,41,102,5,5,5,5,5,5,5,5,5,5,0,0,0
0,0,0,0,0,0,41,6,6,0,95,0,0,0,0,0,0,0,0,0,0,41,41,15,5,5,5,5,5,41,41,41,44,0,0
0,0,0,0,0,0,41,41,41,81,0,0,0,0,0,0,0,0,0,0,0,0,0,41,0,41,73,0,0,0,0,41,41,41,41
0,0,0,0,0,0,0,0,0,0,0,0,0,0,0,0,0,54,6,0,0,0,0,0,41,41,41,0,41,41,0,0,0,41,41
0,0,0,0,0,0,0,0,0,0,0,0,0,0,0,0,0,0,0,0,0,0,0,0,0,15,0,0,0,0,0,41,0,0,41
0,0,0,0,0,0,0,0,0,0,0,0,0,0,0,0,0,0,0,0,0,0,0,0,0,0,81,0,0,0,41,0,44,0,0
0,0,0,0,0,0,0,0,0,0,0,0,0,0,0,0,0,0,0,0,0,0,0,0,0,0,0,73,41,41,0,0,44,0,0
0,0,0,0,0,0,0,0,0,0,0,0,0,0,0,0,0,0,0,0,0,0,0,0,0,0,0,0,0,0,41,0,44,0,0
0,0,0,0,0,0,0,0,0,0,0,0,0,0,0,0,0,0,0,0,0,0,0,0,0,0,0,0,0,0,0,44,0,0,0
0,0,0,0,0,0,0,0,0,0,0,0,0,0,0,0,0,0,0,0,0,0,0,0,0,0,0,0,41,0,41,0,0,0,0
endlayer

layer
0,0,0,0,0,0,0,0,0,0,0,0,0,0,0,0,0,15,0,0,0,0,0,66,66,20,0,66,0,66,66,0,0,66,66
0,0,0,0,0,0,0,0,0,0,0,0,0,0,0,0,15,15,0,0,0,0,0,0,66,66,55,66,0,0,0,0,0,66,66
0,0,0,0,0,0,0,0,0,0,0,0,0,0,0,0,0,66,0,0,0,0,0,0,5,5,6,5,55,66,0,0,66,0,0
0,0,0,0,0,0,0,0,0,0,0,0,0,0,0,0,15,0,0,0,0,0,55,0,6,6,6,6,6,6,0,6,0,55,66
0,0,0,0,0,0,0,0,0,0,0,0,0,0,0,0,73,0,0,0,0,0,6,6,6,6,5,5,5,0,5,5,5,5,0
0,0,0,0,0,0,0,0,0,0,0,0,0,0,0,55,0,0,0,5,5,0,6,0,6,0,5,5,5,0,5,5,5,5,5
0,0,0,0,0,0,0,0,0,0,0,0,0,0,15,6,44,54,5,5,5,5,6,0,0,0,5,5,8,5,5,5,0,0,5
0,0,0,0,0,0,0,0,0,0,0,0,0,0,0,0,0,0,0,0,5,5,23,8,8,44,41,5,8,6,6,8,8,0,5
0,0,0,0,0,0,0,0,0,0,0,0,0,0,0,15,0,6,6,6,5,23,23,0,0,0,0,41,19,0,0,0,0,0,5
0,0,0,0,0,0,0,0,0,0,0,0,0,0,0,15,41,0,0,0,6,0,19,0,0,0,0,0,5,0,0,0,0,0,5
0,0,0,0,0,0,0,0,0,0,0,0,0,0,0,0,54,6,0,6,6,23,23,19,8,5,0,5,8,8,44,15,5,5,0
0,0,0,0,0,0,0,0,0,0,0,0,0,0,0,20,0,31,0,6,6,23,8,8,8,5,5,5,8,8,0,15,5,5,0
0,0,0,0,0,0,0,0,66,6,6,0,0,0,15,0,0,15,15,5,5,5,5,8,5,0,5,5,5,5,97,97,5,5,5
0,0,0,0,0,0,0,0,6,6,5,5,0,20,15,0,0,0,73,6,6,5,5,5,5,0,0,5,5,5,5,5,5,5,5
0,0,0,0,0,0,0,6,6,6,6,6,6,0,0,0,0,0,73,6,6,5,5,5,0,0,5,5,0,5,8,5,5,5,5
0,0,0,0,0,15,6,5,6,6,5,5,31,0,0,0,0,0,0,15,6,5,5,5,0,5,8,23,0,8,8,23,5,5,44
0,0,0,0,0,15,5,5,6,5,5,0,0,0,0,0,0,0,0,15,6,5,5,5,5,5,8,5,5,5,19,5,5,5,71
0,0,0,0,15,0,6,6,5,5,5,37,0,0,0,0,0,0,0,0,41,74,6,5,6,6,31,5,5,0,5,5,0,0,0
0,0,0,0,0,54,6,6,5,5,95,0,0,0,0,0,0,0,0,0,0,41,74,6,5,6,6,6,5,5,6,6,44,0,0
0,0,0,0,0,0,41,41,41,81,0,0,0,0,0,0,0,0,0,0,0,0,0,41,6,6,15,6,6,71,71,41,41,41,41
0,0,0,0,0,0,0,0,0,0,0,0,0,0,0,0,0,54,6,0,0,0,0,0,41,41,41,31,41,41,0,0,0,41,41
0,0,0,0,0,0,0,0,0,0,0,0,0,0,0,0,0,0,0,0,0,0,0,0,0,15,0,0,0,0,0,41,0,0,41
0,0,0,0,0,0,0,0,0,0,0,0,0,0,0,0,0,0,0,0,0,0,0,0,0,0,81,0,0,0,41,0,44,0,0
0,0,0,0,0,0,0,0,0,0,0,0,0,0,0,0,0,0,0,0,0,0,0,0,0,0,0,73,41,41,0,0,44,0,0
0,0,0,0,0,0,0,0,0,0,0,0,0,0,0,0,0,0,0,0,0,0,0,0,0,0,0,0,0,0,41,0,44,0,0
0,0,0,0,0,0,0,0,0,0,0,0,0,0,0,0,0,0,0,0,0,0,0,0,0,0,0,0,0,0,0,44,0,0,0
0,0,0,0,0,0,0,0,0,0,0,0,0,0,0,0,0,0,0,0,0,0,0,0,0,0,0,0,41,0,41,0,0,0,0
endlayer

layer
0,0,0,0,0,0,0,0,0,0,0,0,0,0,0,0,0,15,0,0,0,0,0,66,66,20,0,66,0,66,66,0,0,66,66
0,0,0,0,0,0,0,0,0,0,0,0,0,0,0,0,15,15,0,0,0,0,0,0,0,66,0,66,55,0,0,0,0,66,66
0,0,0,0,0,0,0,0,0,0,0,0,0,0,0,15,0,66,0,0,0,0,0,5,5,5,6,6,5,66,0,55,66,0,0
0,0,0,0,0,0,0,0,0,0,0,0,0,0,0,0,15,0,0,55,5,5,55,6,6,6,6,6,6,0,0,6,0,0,66
0,0,0,0,0,0,0,0,0,0,0,0,0,0,0,0,73,0,0,5,6,0,6,23,6,6,0,0,5,0,5,5,5,5,5
0,0,0,0,0,0,0,0,0,0,0,0,0,0,0,15,0,0,5,5,6,23,19,19,19,0,0,5,19,5,5,5,5,5,0
0,0,0,0,0,0,0,0,0,0,0,0,0,0,15,6,37,55,5,0,0,0,8,19,19,0,0,23,19,0,5,19,5,5,5
0,0,0,0,0,0,0,0,0,0,0,0,0,0,0,0,0,6,5,6,23,23,23,23,8,23,23,23,19,23,23,8,23,23,23
0,0,0,0,0,0,0,0,0,0,0,0,0,0,0,15,0,6,6,6,8,23,23,8,19,0,0,0,19,0,0,19,5,5,5
0,0,0,0,0,0,0,0,0,0,0,0,0,0,0,15,41,6,6,0,19,8,23,23,19,0,5,5,5,5,0,0,0,5,0
0,0,0,0,0,0,0,0,0,0,0,0,0,0,0,0,15,6,6,6,19,21,0,8,8,23,5,5,0,8,44,0,0,5,0
0,0,0,0,0,0,0,0,0,55,0,0,0,0,0,20,0,73,6,6,23,23,23,8,23,5,0,0,8,8,41,15,23,5,0
0,0,0,0,0,0,0,0,66,6,5,0,0,0,15,0,0,15,0,41,6,31,5,8,5,0,0,5,5,5,0,41,5,5,0
0,0,0,0,0,0,0,0,6,5,5,5,0,20,15,0,0,41,73,6,6,5,5,19,5,0,0,0,5,21,97,97,5,5,5
0,0,0,0,0,0,0,6,5,5,5,5,5,0,0,0,41,41,73,6,6,5,5,5,0,5,19,5,5,19,19,0,0,5,5
0,0,0,0,0,0,55,5,5,6,5,5,44,0,0,0,0,0,0,15,6,6,5,5,0,0,19,8,23,19,8,23,23,23,5
0,0,0,0,0,15,5,5,6,6,5,31,0,0,0,0,0,0,0,15,6,6,6,5,5,23,8,23,23,8,8,19,5,0,5
0,0,0,0,15,0,5,5,5,5,6,0,0,0,0,0,0,0,0,0,41,6,6,6,6,6,19,5,5,19,19,5,5,5,0
0,0,0,0,0,0,5,5,5,0,0,0,0,0,0,0,0,0,0,0,0,41,31,6,6,6,6,6,5,5,5,6,6,0,0
0,0,0,0,0,0,0,0,41,0,0,0,0,0,0,0,0,0,0,0,0,0,0,41,31,6,6,6,6,5,5,41,41,41,41
0,0,0,0,0,0,0,0,0,0,0,0,0,0,0,0,0,0,4,0,0,0,0,0,0,41,41,41,41,41,0,0,0,41,41
0,0,0,0,0,0,0,0,0,0,0,0,0,0,0,0,0,0,0,0,0,0,0,0,0,15,0,0,0,0,0,41,0,0,41
0,0,0,0,0,0,0,0,0,0,0,0,0,0,0,0,0,0,0,0,0,0,0,0,0,0,81,0,0,0,41,0,44,0,0
0,0,0,0,0,0,0,0,0,0,0,0,0,0,0,0,0,0,0,0,0,0,0,0,0,0,0,73,41,41,0,0,44,0,0
0,0,0,0,0,0,0,0,0,0,0,0,0,0,0,0,0,0,0,0,0,0,0,0,0,0,0,0,0,0,41,0,44,0,0
0,0,0,0,0,0,0,0,0,0,0,0,0,0,0,0,0,0,0,0,0,0,0,0,0,0,0,0,0,0,0,44,0,0,0
0,0,0,0,0,0,0,0,0,0,0,0,0,0,0,0,0,0,0,0,0,0,0,0,0,0,0,0,41,0,41,0,0,0,0
endlayer

layer
0,0,0,0,0,0,0,0,0,0,0,0,0,0,0,0,0,15,0,0,0,0,55,66,66,20,0,66,0,66,66,0,0,66,66
0,0,0,0,0,0,0,0,0,0,0,0,0,0,0,15,15,15,0,0,5,6,6,0,0,5,5,66,43,0,0,0,0,66,66
0,0,0,0,0,0,0,0,0,0,0,0,0,0,0,15,0,66,0,5,5,5,6,5,5,5,6,6,44,66,0,0,66,0,0
0,0,0,0,0,0,0,0,0,0,0,0,0,0,0,0,15,0,5,5,5,5,5,6,5,6,6,6,0,5,5,6,6,0,0
0,0,0,0,0,0,0,0,0,0,0,0,0,0,0,0,73,0,0,6,8,23,23,19,8,5,0,5,8,5,0,5,5,5,5
0,0,0,0,0,0,0,0,0,0,0,0,0,0,0,15,0,0,5,5,19,9,9,8,9,9,23,8,8,8,23,9,9,5,0
0,0,0,0,0,0,0,0,0,0,0,0,0,0,54,6,0,0,6,6,19,9,9,9,9,9,9,9,9,9,9,9,9,5,5
0,0,0,0,0,0,0,0,0,0,0,0,0,0,0,0,0,6,5,23,8,8,9,9,9,9,9,9,9,9,9,9,9,8,5
0,0,0,0,0,0,0,0,0,0,0,0,0,0,0,15,0,6,0,6,8,9,9,21,21,21,9,9,9,9,9,9,9,5,5
0,0,0,0,0,0,0,0,0,0,0,0,0,0,0,15,41,6,6,6,6,9,21,21,3,21,21,9,9,9,21,21,9,5,5
0,0,0,0,0,0,0,0,0,0,0,0,0,0,0,0,15,6,6,0,0,21,21,3,3,3,21,9,9,8,44,0,8,5,0
0,0,0,0,0,0,0,0,0,0,0,0,0,0,0,20,0,73,6,6,8,21,3,3,3,21,21,9,8,8,41,0,8,5,0
0,0,0,0,0,0,0,0,0,0,0,0,0,0,15,0,0,15,31,6,6,21,21,3,21,21,9,9,5,6,44,41,8,5,5
0,0,0,0,0,0,0,0,66,6,5,0,0,20,15,0,0,41,73,6,6,9,9,21,21,9,9,9,9,29,0,0,9,5,5
0,0,0,0,0,0,0,20,5,5,5,5,0,0,0,0,41,41,41,15,6,9,9,9,9,9,9,9,9,97,97,97,9,5,5
0,0,0,0,0,0,55,5,5,5,5,44,0,0,0,0,0,0,0,15,6,9,9,9,9,9,9,9,9,9,9,9,9,8,5
0,0,0,0,0,0,6,5,6,6,6,37,0,0,0,0,0,0,0,15,6,9,9,9,9,9,9,9,9,9,9,9,9,5,5
0,0,0,0,15,6,5,5,5,6,41,0,0,0,0,0,0,0,0,0,0,6,6,5,0,0,8,23,8,19,23,23,5,5,5
0,0,0,0,0,0,5,5,6,0,0,0,0,0,0,0,0,0,0,0,0,0,41,41,5,5,6,5,5,8,0,6,6,5,0
0,0,0,0,0,0,0,6,41,0,0,0,0,0,0,0,0,0,0,0,0,0,0,41,41,6,5,5,6,5,5,71,41,41,41
0,0,0,0,0,0,0,31,0,0,0,0,0,0,0,0,0,0,0,0,0,0,0,0,0,41,41,41,41,41,0,0,0,41,41
0,0,0,0,0,0,0,0,0,0,0,0,0,0,0,0,0,0,0,0,0,0,0,0,0,15,0,0,0,0,0,41,0,0,41
0,0,0,0,0,0,0,0,0,0,0,0,0,0,0,0,0,0,0,0,0,0,0,0,0,0,81,0,0,0,41,0,44,0,0
0,0,0,0,0,0,0,0,0,0,0,0,0,0,0,0,0,0,0,0,0,0,0,0,0,0,0,73,41,41,0,0,44,0,0
0,0,0,0,0,0,0,0,0,0,0,0,0,0,0,0,0,0,0,0,0,0,0,0,0,0,0,0,0,0,41,0,44,0,0
0,0,0,0,0,0,0,0,0,0,0,0,0,0,0,0,0,0,0,0,0,0,0,0,0,0,0,0,0,0,0,44,0,0,0
0,0,0,0,0,0,0,0,0,0,0,0,0,0,0,0,0,0,0,0,0,0,0,0,0,0,0,0,41,0,41,0,0,0,0
endlayer

layer
0,0,0,0,0,0,0,0,0,0,0,0,0,0,0,0,0,15,0,55,6,6,0,66,66,20,0,66,0,66,66,0,0,66,66
0,0,0,0,0,0,0,0,0,0,0,0,0,0,0,15,15,15,0,5,5,6,6,6,0,5,5,5,43,0,6,55,55,66,66
0,0,0,0,0,0,0,0,0,0,0,0,0,0,0,15,0,66,0,0,5,5,6,6,6,6,6,6,6,66,5,6,6,0,0
0,0,0,0,0,0,0,0,0,0,0,0,0,0,0,0,15,0,0,0,0,5,0,6,0,6,6,6,6,6,5,5,6,6,6
0,0,0,0,0,0,0,0,0,0,0,0,0,0,0,15,73,5,5,0,0,0,0,8,8,6,6,6,8,6,6,6,5,5,6
0,0,0,0,0,0,0,0,0,0,0,0,0,0,0,15,0,6,5,5,0,0,0,8,8,9,50,50,50,50,50,9,9,6,6
0,0,0,0,0,0,0,0,0,0,0,0,0,0,0,15,0,6,6,6,0,0,0,6,8,6,6,6,6,107,6,6,9,5,0
0,0,0,0,0,0,0,0,0,0,0,0,0,0,0,0,0,6,6,8,8,0,0,6,6,6,6,32,32,32,32,6,50,5,5
0,0,0,0,0,0,0,0,0,0,0,0,0,0,0,15,6,6,6,6,8,9,8,6,7,7,32,32,32,32,108,5,50,0,5
0,0,0,0,0,0,0,0,0,0,0,0,0,0,0,15,41,6,6,6,6,9,5,7,25,7,32,32,32,32,109,5,50,0,5
0,0,0,0,0,0,0,0,0,0,0,0,0,0,0,0,15,6,6,6,6,50,7,25,25,7,32,32,6,8,21,21,8,0,0
0,0,0,0,0,0,0,0,0,0,0,0,0,0,0,20,0,73,6,6,8,50,25,25,25,7,32,32,8,8,41,41,50,5,5
0,0,0,0,0,0,0,0,0,0,0,0,0,0,15,0,0,15,15,6,0,50,25,25,25,7,32,32,5,8,44,41,8,5,5
0,0,0,0,0,0,0,0,66,0,0,0,0,20,15,0,0,41,41,6,15,50,25,25,25,110,32,32,32,41,0,0,50,5,5
0,0,0,0,0,0,0,20,5,5,5,0,0,0,0,0,41,41,41,15,15,50,3,25,25,3,3,32,90,0,0,0,50,5,5
0,0,0,0,0,0,0,5,5,5,5,0,0,15,0,0,0,0,0,15,15,5,3,3,25,25,110,3,32,66,0,90,9,5,5
0,0,0,0,0,0,5,5,5,5,5,37,0,0,0,0,0,0,0,15,6,5,5,50,50,50,50,50,50,50,50,9,9,5,5
0,0,0,0,54,5,5,6,5,5,41,0,0,0,0,0,0,0,0,54,6,6,41,5,5,6,8,5,8,8,8,5,5,5,5
0,0,0,0,0,0,5,5,5,31,0,0,0,0,0,0,0,0,0,0,0,0,0,5,5,6,6,0,6,8,0,6,6,5,5
0,0,0,0,0,0,0,5,41,0,0,0,0,0,0,0,0,0,0,0,0,0,0,41,74,6,5,6,5,5,5,5,31,41,41
0,0,0,0,0,0,0,0,0,0,0,0,0,0,0,0,0,0,0,0,0,0,0,0,0,31,41,41,0,41,5,31,0,41,41
0,0,0,0,0,0,0,0,0,0,0,0,0,0,0,0,0,0,0,0,0,0,0,0,0,15,0,95,0,0,0,41,0,0,41
0,0,0,0,0,0,0,0,0,0,0,0,0,0,0,0,0,0,0,0,0,0,0,0,0,0,81,0,0,0,41,0,44,0,41
0,0,0,0,0,0,0,0,0,0,0,0,0,0,0,0,0,0,0,0,0,0,0,0,0,0,0,73,41,41,0,0,44,0,0
0,0,0,0,0,0,0,0,0,0,0,0,0,0,0,0,0,0,0,0,0,0,0,0,0,0,0,0,0,0,41,0,44,0,0
0,0,0,0,0,0,0,0,0,0,0,0,0,0,0,0,0,0,0,0,0,0,0,0,0,0,0,0,0,0,0,44,0,0,0
0,0,0,0,0,0,0,0,0,0,0,0,0,0,0,0,0,0,0,0,0,0,0,0,0,0,0,0,41,0,41,0,0,0,0
endlayer

layer
0,0,0,0,0,0,0,0,0,0,0,0,0,0,0,0,0,15,6,6,6,6,0,66,66,15,6,0,0,66,0,0,0,66,66
0,0,0,0,0,0,0,0,0,0,0,0,0,0,0,15,15,15,5,5,5,6,6,6,6,5,5,5,44,0,66,66,66,66,66
0,0,0,0,0,0,0,0,0,0,0,0,0,0,0,15,0,66,0,0,5,5,6,6,6,6,5,5,5,6,6,6,6,6,0
0,0,0,0,0,0,0,0,0,0,0,0,0,0,0,0,15,5,0,0,0,0,0,6,0,6,6,6,6,0,6,6,6,6,6
0,0,0,0,0,0,0,0,0,0,0,0,0,0,0,15,73,5,5,0,0,0,5,8,4,6,6,6,8,0,6,0,5,6,6
0,0,0,0,0,0,0,0,0,0,0,0,0,0,0,15,0,6,5,5,0,0,0,0,8,50,50,50,50,50,23,50,9,6,6
0,0,0,0,0,0,0,0,0,0,0,0,0,0,0,15,6,0,6,6,6,0,0,0,8,6,6,6,6,6,6,6,50,0,5
0,0,0,0,0,0,0,0,0,0,0,0,0,0,0,54,6,5,5,8,8,0,0,6,6,44,44,41,41,41,31,0,50,5,5
0,0,0,0,0,0,0,0,0,0,0,0,0,0,0,15,6,6,6,6,8,9,8,6,0,0,0,0,41,0,0,0,50,0,5
0,0,0,0,0,0,0,0,0,0,0,0,0,0,0,15,0,6,0,6,6,50,6,0,0,67,0,0,66,66,66,66,50,5,5
0,0,0,0,0,0,0,0,0,0,0,0,0,0,0,74,54,6,6,6,6,50,6,0,0,0,0,15,6,8,5,5,50,5,5
0,0,0,0,0,0,0,0,0,0,0,0,0,0,0,20,0,73,6,6,6,50,0,44,0,4,0,54,8,8,21,21,8,0,5
0,0,0,0,0,0,0,0,0,0,0,0,0,0,15,0,0,15,6,6,6,50,0,44,0,0,41,15,6,8,0,41,8,5,5
0,0,0,0,0,0,0,0,55,0,0,0,0,20,15,0,0,41,41,41,15,50,0,44,0,0,0,0,0,0,0,0,50,0,5
0,0,0,0,0,0,0,20,6,6,6,0,0,0,0,0,41,41,41,20,15,50,6,44,0,67,0,0,0,0,0,0,50,5,5
0,0,0,0,0,0,0,5,6,6,6,0,0,15,0,0,0,0,0,15,15,5,6,6,44,0,0,67,0,66,0,15,50,5,5
0,0,0,0,0,0,5,5,5,6,6,0,0,0,0,0,0,0,0,15,6,5,5,50,50,50,50,50,50,50,50,50,9,5,5
0,0,0,0,0,0,5,5,5,5,0,0,0,0,0,0,0,0,0,0,6,6,41,6,6,0,8,0,8,8,23,23,5,5,5
0,0,0,0,0,0,5,5,5,41,0,0,0,0,0,0,0,0,0,0,0,0,0,4,6,6,6,0,8,19,6,6,6,6,6
0,0,0,0,0,0,0,41,41,0,0,0,0,0,0,0,0,0,0,0,0,0,0,0,6,5,0,5,5,5,5,5,41,41,41
0,0,0,0,0,0,0,0,0,0,0,0,0,0,0,0,0,0,0,0,0,0,0,0,0,15,5,5,0,41,5,5,37,41,41
0,0,0,0,0,0,0,0,0,0,0,0,0,0,0,0,0,0,0,0,0,0,0,0,0,15,5,95,103,0,5,41,0,0,41
0,0,0,0,0,0,0,0,0,0,0,0,0,0,0,0,0,0,0,0,0,0,0,0,0,0,81,0,0,0,41,0,44,0,41
0,0,0,0,0,0,0,0,0,0,0,0,0,0,0,0,0,0,0,0,0,0,0,0,0,0,0,73,41,41,0,0,44,0,0
0,0,0,0,0,0,0,0,0,0,0,0,0,0,0,0,0,0,0,0,0,0,0,0,0,0,0,0,0,0,41,0,44,0,0
0,0,0,0,0,0,0,0,0,0,0,0,0,0,0,0,0,0,0,0,0,0,0,0,0,0,0,0,0,0,0,44,0,0,0
0,0,0,0,0,0,0,0,0,0,0,0,0,0,0,0,0,0,0,0,0,0,0,0,0,0,0,0,41,0,41,0,0,0,0
endlayer

layer
0,0,0,0,0,0,0,0,0,0,0,0,0,0,0,0,0,15,6,6,6,6,0,66,6,6,5,6,0,66,0,0,0,66,66
0,0,0,0,0,0,0,0,0,0,0,0,0,0,0,15,15,15,5,5,5,6,6,6,6,5,5,5,0,0,66,66,66,66,66
0,0,0,0,0,0,0,0,0,0,0,0,0,0,0,15,0,0,5,5,5,5,6,6,6,6,5,5,0,6,6,6,6,6,6
0,0,0,0,0,0,0,0,0,0,0,0,0,0,0,0,54,5,5,0,5,5,6,6,6,6,6,6,0,6,6,6,6,5,5
0,0,0,0,0,0,0,0,0,0,0,0,0,0,0,15,73,5,5,5,5,5,8,8,6,6,0,6,8,6,6,0,5,5,6
0,0,0,0,0,0,0,0,0,0,0,0,0,0,0,15,6,6,6,5,5,0,0,0,8,9,50,50,50,8,50,9,8,8,6
0,0,0,0,0,0,0,0,0,0,0,0,0,0,0,15,6,6,6,6,8,0,0,0,8,8,5,6,6,6,15,6,9,5,5
0,0,0,0,0,0,0,0,0,0,0,0,0,0,0,15,6,6,0,4,8,19,0,0,0,6,44,0,6,41,0,0,50,5,5
0,0,0,0,0,0,0,0,0,0,0,0,0,0,0,15,6,6,6,23,8,9,8,6,0,0,0,0,41,0,0,0,50,5,5
0,0,0,0,0,0,0,0,0,0,0,0,0,0,0,15,6,6,5,6,8,9,19,6,0,0,0,0,0,66,0,0,50,5,5
0,0,0,0,0,0,0,0,0,0,0,0,0,0,0,74,15,6,5,5,5,50,19,6,0,0,0,15,6,8,6,6,50,0,5
0,0,0,0,0,0,0,0,0,0,0,0,0,0,0,20,0,74,6,5,6,50,6,44,0,0,6,6,23,8,97,97,8,0,66
0,0,0,0,0,0,0,0,0,0,0,0,0,0,15,0,0,15,0,41,15,50,6,44,0,0,41,6,6,8,0,0,50,5,5
0,0,0,0,0,0,0,0,0,0,0,0,0,20,15,0,0,41,0,41,15,50,6,44,0,0,0,0,0,0,0,0,50,5,5
0,0,0,0,0,0,0,20,6,6,0,0,66,0,0,0,41,41,41,20,15,50,5,44,0,0,0,0,0,0,0,0,50,5,5
0,0,0,0,0,0,0,5,6,6,6,0,0,15,0,41,0,0,0,15,15,5,5,5,44,0,0,0,0,66,0,15,9,5,5
0,0,0,0,0,0,55,5,5,6,6,0,0,0,41,0,0,0,0,15,6,5,5,50,50,50,50,50,50,8,0,9,9,0,5
0,0,0,0,0,0,5,5,5,5,0,0,0,0,0,0,0,0,0,0,6,6,41,41,41,6,8,23,23,8,8,0,8,5,5
0,0,0,0,0,0,41,5,0,0,0,0,0,0,0,0,0,0,0,0,0,0,0,0,0,0,6,6,23,19,6,0,6,5,6
0,0,0,0,0,0,0,0,0,0,0,0,0,0,0,0,0,0,0,0,0,0,0,0,0,15,0,6,0,19,6,6,0,0,41
0,0,0,0,0,0,0,0,0,0,0,0,0,0,0,0,0,0,0,0,0,0,0,0,0,15,0,6,5,5,6,6,44,41,41
0,0,0,0,0,0,0,0,0,0,0,0,0,0,0,0,0,0,0,0,0,0,0,0,0,0,4,0,5,5,6,41,0,0,41
0,0,0,0,0,0,0,0,0,0,0,0,0,0,0,0,0,0,0,0,0,0,0,0,0,0,15,0,0,5,5,0,44,0,41
0,0,0,0,0,0,0,0,0,0,0,0,0,0,0,0,0,0,0,0,0,0,0,0,0,0,0,73,41,41,5,0,44,0,0
0,0,0,0,0,0,0,0,0,0,0,0,0,0,0,0,0,0,0,0,0,0,0,0,0,0,0,0,0,0,41,0,44,0,0
0,0,0,0,0,0,0,0,0,0,0,0,0,0,0,0,0,0,0,0,0,0,0,0,0,0,0,0,0,0,0,44,0,0,0
0,0,0,0,0,0,0,0,0,0,0,0,0,0,0,0,0,0,0,0,0,0,0,0,0,0,0,0,41,0,41,0,0,0,0
endlayer

layer
0,0,0,0,0,0,0,0,0,0,0,0,0,0,0,0,0,0,6,6,6,43,42,6,6,5,5,5,0,66,0,0,0,66,66
0,0,0,0,0,0,0,0,0,0,0,0,0,0,0,15,15,15,6,6,6,6,42,6,6,5,5,5,5,6,66,66,66,66,66
0,0,0,0,0,0,0,0,0,0,0,0,0,0,15,15,0,0,6,6,6,6,6,6,6,6,5,5,5,0,6,5,5,5,6
0,0,0,0,0,0,0,0,0,0,0,0,0,0,0,0,0,15,5,5,0,0,19,6,6,6,6,0,6,6,6,6,6,5,5
0,0,0,0,0,0,0,0,0,0,0,0,0,0,0,15,73,6,6,5,6,6,19,8,23,23,6,6,8,6,6,6,8,5,6
0,0,0,0,0,0,0,0,0,0,0,0,0,0,0,0,15,6,6,6,6,8,19,23,23,23,23,23,23,23,23,23,8,8,6
0,0,0,0,0,0,0,0,0,0,0,0,0,0,0,15,6,6,6,23,23,19,8,23,19,23,23,8,19,9,9,8,19,5,5
0,0,0,0,0,0,0,0,0,0,0,0,0,0,0,0,4,6,6,6,8,19,19,9,9,9,9,9,19,9,9,9,19,5,5
0,0,0,0,0,0,0,0,0,0,0,0,0,0,0,15,6,6,6,6,19,23,8,23,9,9,9,9,9,9,9,9,19,5,5
0,0,0,0,0,0,0,0,0,0,0,0,0,0,0,0,41,6,5,19,19,23,19,9,9,9,9,9,9,9,9,9,19,5,5
0,0,0,0,0,0,0,0,0,0,0,0,0,0,0,74,0,31,6,5,6,9,8,23,9,9,9,9,9,8,9,9,19,0,5
0,0,0,0,0,0,0,0,0,0,0,0,0,0,0,20,0,15,6,6,6,9,19,9,9,9,9,8,23,8,23,9,8,23,5
0,0,0,0,0,0,0,0,0,0,0,0,0,0,15,0,0,15,31,6,15,9,9,9,9,9,9,9,9,8,9,9,19,5,5
0,0,0,0,0,0,0,0,0,0,0,0,0,20,15,0,0,41,0,41,15,9,9,9,9,9,9,9,9,9,9,9,19,5,5
0,0,0,0,0,0,0,66,5,0,0,0,20,0,0,0,41,41,41,20,15,9,9,9,9,9,9,9,9,9,9,9,9,5,5
0,0,0,0,0,0,0,5,5,6,0,0,0,15,41,41,0,0,15,15,15,9,9,9,9,9,9,9,9,9,9,9,5,0,5
0,0,0,0,0,0,0,5,5,5,5,37,0,0,57,0,0,0,0,15,6,9,9,9,9,9,19,9,9,19,9,9,9,5,5
0,0,0,0,0,0,15,5,5,5,0,0,41,0,0,0,0,0,0,0,6,6,41,41,41,15,8,23,8,8,8,0,8,6,6
0,0,0,0,0,0,0,41,31,0,0,0,41,0,0,0,0,0,0,0,0,0,0,0,6,6,6,6,4,8,6,6,6,6,6
0,0,0,0,0,0,0,0,0,0,0,0,0,0,0,0,0,0,0,0,0,0,0,0,0,15,6,6,6,8,5,5,31,0,6
0,0,0,0,0,0,0,0,0,0,0,0,0,0,0,0,0,0,0,0,0,0,0,0,0,15,6,5,5,19,5,6,0,41,41
0,0,0,0,0,0,0,0,0,0,0,0,0,0,0,0,0,0,0,0,0,0,0,0,0,0,41,0,5,19,6,0,0,0,41
0,0,0,0,0,0,0,0,0,0,0,0,0,0,0,0,0,0,0,0,0,0,0,0,0,0,15,5,5,19,5,6,44,0,41
0,0,0,0,0,0,0,0,0,0,0,0,0,0,0,0,0,0,0,0,0,0,0,0,0,0,0,73,41,5,5,5,44,0,0
0,0,0,0,0,0,0,0,0,0,0,0,0,0,0,0,0,0,0,0,0,0,0,0,0,0,0,0,0,0,0,0,44,0,0
0,0,0,0,0,0,0,0,0,0,0,0,0,0,0,0,0,0,0,0,0,0,0,0,0,0,0,0,0,0,0,44,0,0,0
0,0,0,0,0,0,0,0,0,0,0,0,0,0,0,0,0,0,0,0,0,0,0,0,0,0,0,0,41,0,41,0,0,0,0
endlayer

layer
0,0,0,0,0,0,0,0,0,0,0,0,0,0,0,0,0,0,0,66,43,43,6,6,6,6,6,6,55,55,0,0,0,66,66
0,0,0,0,0,0,0,0,0,0,0,0,0,0,0,15,15,0,0,6,6,6,6,6,6,6,6,6,6,6,66,66,5,5,5
0,0,0,0,0,0,0,0,0,0,0,0,0,0,15,15,0,54,6,6,6,6,6,6,6,6,6,6,6,6,6,6,5,5,5
0,0,0,0,0,0,0,0,0,0,0,0,0,0,0,0,0,15,6,6,6,6,0,6,6,6,6,6,0,6,6,6,6,6,6
0,0,0,0,0,0,0,0,0,0,0,0,0,0,0,15,73,15,6,6,6,6,19,6,6,6,6,6,6,6,6,6,6,6,6
0,0,0,0,0,0,0,0,0,0,0,0,0,0,0,0,15,6,6,6,6,8,8,8,8,23,23,23,8,6,6,6,6,6,6
0,0,0,0,0,0,0,0,0,0,0,0,0,0,0,0,54,6,6,6,23,8,8,8,23,23,5,5,5,5,5,5,8,5,5
0,0,0,0,0,0,0,0,0,0,0,0,0,0,0,0,15,6,6,6,6,8,8,8,23,6,0,5,5,5,0,0,5,5,5
0,0,0,0,0,0,0,0,0,0,0,0,0,0,0,15,6,111,6,6,6,6,19,8,0,0,0,0,5,5,0,0,5,5,5
0,0,0,0,0,0,0,0,0,0,0,0,0,0,0,0,31,15,6,5,6,6,0,0,0,0,5,5,0,0,0,0,5,5,5
0,0,0,0,0,0,0,0,0,0,0,0,0,0,0,74,0,0,6,5,6,6,8,6,6,0,5,0,23,8,8,0,5,5,5
0,0,0,0,0,0,0,0,0,0,0,0,0,0,0,20,0,15,6,6,6,6,6,0,6,6,23,8,23,8,23,23,8,5,5
0,0,0,0,0,0,0,0,0,0,0,0,0,0,15,0,0,15,41,6,6,6,6,6,0,6,0,5,8,19,8,5,5,5,0
0,0,0,0,0,0,0,0,0,0,0,0,0,20,15,0,0,41,0,41,6,6,6,6,5,5,5,5,0,5,0,5,5,5,0
0,0,0,0,0,0,0,0,106,0,0,0,20,0,0,0,41,41,41,20,31,6,6,6,6,5,5,5,0,19,5,5,5,5,5
0,0,0,0,0,0,0,66,5,106,0,0,0,15,41,41,0,0,15,15,0,32,32,6,6,5,5,5,5,19,44,5,5,5,5
0,0,0,0,0,0,54,5,5,5,0,0,0,0,57,0,0,0,0,15,0,6,32,32,6,6,8,0,0,8,6,6,0,6,6
0,0,0,0,0,0,15,6,5,4,0,0,41,0,0,0,0,0,0,0,4,6,0,0,41,6,6,6,8,19,8,6,6,6,6
0,0,0,0,0,0,0,41,81,0,0,0,41,0,0,0,0,0,0,0,0,0,0,0,54,6,6,6,6,8,6,6,6,6,6
0,0,0,0,0,0,0,0,0,0,0,0,0,0,0,0,0,0,0,0,0,0,0,0,0,15,6,6,0,6,6,6,6,6,6
0,0,0,0,0,0,0,0,0,0,0,0,0,0,0,0,0,0,0,0,0,0,0,0,0,15,31,0,0,0,5,5,5,41,41
0,0,0,0,0,0,0,0,0,0,0,0,0,0,0,0,0,0,0,0,0,0,0,0,0,0,41,5,23,5,5,0,31,0,41
0,0,0,0,0,0,0,0,0,0,0,0,0,0,0,0,0,0,0,0,0,0,0,0,0,0,15,0,5,5,5,0,0,0,41
0,0,0,0,0,0,0,0,0,0,0,0,0,0,0,0,0,0,0,0,0,0,0,0,0,0,0,15,5,8,5,6,0,0,0
0,0,0,0,0,0,0,0,0,0,0,0,0,0,0,0,0,0,0,0,0,0,0,0,0,0,0,0,6,6,6,6,44,0,0
0,0,0,0,0,0,0,0,0,0,0,0,0,0,0,0,0,0,0,0,0,0,0,0,0,0,0,0,0,6,6,44,0,0,0
0,0,0,0,0,0,0,0,0,0,0,0,0,0,0,0,0,0,0,0,0,0,0,0,0,0,0,0,41,0,41,0,0,0,0
endlayer

layer
0,0,0,0,0,0,0,0,0,0,0,0,0,0,0,0,0,0,0,66,43,43,66,6,6,6,5,5,66,66,0,0,55,66,66
0,0,0,0,0,0,0,0,0,0,0,0,0,0,0,15,15,0,0,20,6,6,6,6,5,5,5,5,6,6,66,66,6,6,6
0,0,0,0,0,0,0,0,0,0,0,0,0,0,15,15,0,0,66,6,6,6,6,6,5,5,5,5,5,6,6,6,6,6,6
0,0,0,0,0,0,0,0,0,0,0,0,0,0,0,0,15,15,6,6,6,6,0,0,5,6,6,6,0,6,6,6,6,6,6
0,0,0,0,0,0,0,0,0,0,0,0,0,0,0,15,73,15,6,6,6,6,6,0,6,6,0,6,6,6,6,6,6,6,6
0,0,0,0,0,0,0,0,0,0,0,0,0,0,0,0,0,15,6,6,6,8,8,8,6,6,6,6,8,0,0,6,6,6,6
0,0,0,0,0,0,0,0,0,0,0,0,0,0,0,0,15,6,6,6,6,8,8,8,8,0,0,0,0,0,6,0,6,6,0
0,0,0,0,0,0,0,0,0,0,0,0,0,0,0,0,0,41,6,6,6,8,8,8,8,6,0,5,5,0,0,0,0,5,0
0,0,0,0,0,0,0,0,0,0,0,0,0,0,0,0,0,66,6,6,0,6,8,8,8,0,0,0,5,5,5,0,0,5,0
0,0,0,0,0,0,0,0,0,0,0,0,0,0,0,0,15,0,6,6,6,6,6,6,6,0,0,5,0,8,5,5,0,5,44
0,0,0,0,0,0,0,0,0,0,0,0,0,0,0,74,0,0,6,6,6,6,6,6,0,0,0,0,8,8,8,5,5,5,44
0,0,0,0,0,0,0,0,0,0,0,0,0,0,0,20,0,15,6,6,6,6,6,6,0,23,23,8,8,8,8,8,5,0,44
0,0,0,0,0,0,0,0,0,0,0,0,0,0,15,0,0,15,41,5,5,6,6,5,6,6,5,8,8,8,8,5,5,55,0
0,0,0,0,0,0,0,0,0,0,0,0,0,20,15,0,0,41,0,31,6,6,6,6,6,6,5,5,0,8,5,31,5,5,0
0,0,0,0,0,0,0,0,106,0,0,0,20,0,0,0,41,41,41,20,6,41,41,6,6,6,5,5,0,19,5,5,5,5,4
0,0,0,0,0,0,0,112,6,0,0,0,0,15,41,41,0,0,15,15,0,0,0,0,31,6,5,5,5,19,44,5,5,5,55
0,0,0,0,0,0,74,5,5,6,0,0,0,0,57,0,0,0,0,15,0,6,0,0,0,6,5,5,6,19,6,6,6,6,6
0,0,0,0,0,0,0,6,6,0,0,0,41,0,0,0,0,0,0,0,41,0,0,0,0,31,6,6,23,19,23,6,6,6,6
0,0,0,0,0,0,0,0,81,0,0,0,41,0,0,0,0,0,0,0,0,0,0,0,0,15,6,6,6,19,6,6,6,6,6
0,0,0,0,0,0,0,0,0,0,0,0,0,0,0,0,0,0,0,0,0,0,0,0,0,15,6,6,0,6,6,6,6,6,6
0,0,0,0,0,0,0,0,0,0,0,0,0,0,0,0,0,0,0,0,0,0,0,0,0,15,5,8,6,6,0,4,0,0,6
0,0,0,0,0,0,0,0,0,0,0,0,0,0,0,0,0,0,0,0,0,0,0,0,0,0,41,5,5,0,0,0,0,0,41
0,0,0,0,0,0,0,0,0,0,0,0,0,0,0,0,0,0,0,0,0,0,0,0,0,0,15,5,5,0,6,0,0,0,41
0,0,0,0,0,0,0,0,0,0,0,0,0,0,0,0,0,0,0,0,0,0,0,0,0,0,0,15,5,8,6,6,0,0,0
0,0,0,0,0,0,0,0,0,0,0,0,0,0,0,0,0,0,0,0,0,0,0,0,0,0,0,0,6,6,5,6,0,0,0
0,0,0,0,0,0,0,0,0,0,0,0,0,0,0,0,0,0,0,0,0,0,0,0,0,0,0,0,6,6,6,44,0,0,0
0,0,0,0,0,0,0,0,0,0,0,0,0,0,0,0,0,0,0,0,0,0,0,0,0,0,0,0,41,31,41,0,0,0,0
endlayer

layer
0,0,0,0,0,0,0,0,0,0,0,0,0,0,0,0,0,0,0,66,43,43,66,6,0,0,6,0,0,0,0,0,0,66,55
0,0,0,0,0,0,0,0,0,0,0,0,0,0,0,15,15,0,0,20,6,6,6,6,66,66,6,55,66,0,0,0,0,6,6
0,0,0,0,0,0,0,0,0,0,0,0,0,0,15,15,0,0,55,6,6,6,6,6,42,5,5,6,5,66,66,0,6,6,6
0,0,0,0,0,0,0,0,0,0,0,0,0,0,0,0,15,15,6,6,6,6,0,6,6,6,6,6,6,6,5,5,5,6,6
0,0,0,0,0,0,0,0,0,0,0,0,0,0,0,15,73,15,6,6,5,19,0,6,0,6,0,0,6,6,5,5,5,6,0
0,0,0,0,0,0,0,0,0,0,0,0,0,0,0,0,0,15,6,6,5,8,23,8,6,6,0,0,8,6,0,5,5,0,0
0,0,0,0,0,0,0,0,0,0,0,0,0,0,0,0,0,54,6,6,6,19,8,8,8,0,0,0,6,6,6,6,6,0,0
0,0,0,0,0,0,0,0,0,0,0,0,0,0,0,0,0,0,6,6,6,8,8,8,8,0,0,0,0,0,5,5,5,5,0
0,0,0,0,0,0,0,0,0,0,0,0,0,0,0,0,0,66,6,6,6,6,8,8,8,23,0,42,5,5,5,5,5,5,37
0,0,0,0,0,0,0,0,0,0,0,0,0,0,0,0,15,6,6,6,6,6,6,0,19,0,0,42,42,66,0,5,5,5,44
0,0,0,0,0,0,0,0,0,0,0,0,0,0,0,74,0,6,6,5,6,5,5,0,19,0,8,42,8,8,8,5,5,5,44
0,0,0,0,0,0,0,0,0,0,0,0,0,0,0,20,0,6,6,6,6,6,6,6,8,23,8,23,8,8,8,5,5,0,44
0,0,0,0,0,0,0,0,0,0,0,0,0,0,15,0,0,15,5,5,5,6,6,6,6,6,5,8,23,8,5,5,5,44,0
0,0,0,0,0,0,0,0,0,0,0,0,0,20,15,0,0,41,0,0,6,6,6,6,6,6,5,0,5,19,5,5,5,44,0
0,0,0,0,0,0,0,0,106,0,0,0,20,0,0,0,41,41,41,20,73,41,41,6,6,15,5,5,0,19,5,5,5,0,0
0,0,0,0,0,0,0,74,6,0,0,0,0,15,41,41,0,0,15,15,0,0,0,0,0,15,5,5,5,5,5,5,5,0,0
0,0,0,0,0,0,0,6,6,6,0,0,0,0,57,0,0,0,0,15,0,6,0,0,0,0,6,5,6,6,6,6,6,0,0
0,0,0,0,0,0,0,74,6,31,0,0,41,41,0,0,0,0,0,0,41,0,0,0,0,0,6,6,6,6,6,6,6,0,0
0,0,0,0,0,0,0,0,81,0,0,0,41,0,0,0,0,0,0,0,0,0,0,0,0,15,6,6,6,6,6,6,0,0,0
0,0,0,0,0,0,0,0,0,0,0,0,0,0,0,0,0,0,0,0,0,0,0,0,0,15,6,6,6,6,6,0,4,0,6
0,0,0,0,0,0,0,0,0,0,0,0,0,0,0,0,0,0,0,0,0,0,0,0,0,0,6,8,6,4,0,0,0,0,6
0,0,0,0,0,0,0,0,0,0,0,0,0,0,0,0,0,0,0,0,0,0,0,0,0,0,41,31,0,0,0,0,0,0,6
0,0,0,0,0,0,0,0,0,0,0,0,0,0,0,0,0,0,0,0,0,0,0,0,0,0,0,0,0,0,0,0,0,0,41
0,0,0,0,0,0,0,0,0,0,0,0,0,0,0,0,0,0,0,0,0,0,0,0,0,0,0,0,6,6,6,0,0,0,0
0,0,0,0,0,0,0,0,0,0,0,0,0,0,0,0,0,0,0,0,0,0,0,0,0,0,0,0,6,6,6,37,0,0,0
0,0,0,0,0,0,0,0,0,0,0,0,0,0,0,0,0,0,0,0,0,0,0,0,0,0,0,0,6,6,6,0,0,0,0
0,0,0,0,0,0,0,0,0,0,0,0,0,0,0,0,0,0,0,0,0,0,0,0,0,0,0,0,41,41,0,0,0,0,0
endlayer

layer
0,0,0,0,0,0,0,0,0,0,0,0,0,0,0,0,0,0,0,66,43,44,0,0,0,0,0,0,0,0,0,0,0,0,20
0,0,0,0,0,0,0,0,0,0,0,0,0,0,0,15,15,0,0,20,0,43,0,55,66,66,0,0,0,0,0,0,0,0,6
0,0,0,0,0,0,0,0,0,0,0,0,0,0,15,15,0,0,6,6,5,0,6,6,5,5,0,4,0,0,0,0,0,6,6
0,0,0,0,0,0,0,0,0,0,0,0,0,0,0,15,15,15,6,6,6,0,5,0,6,5,5,5,55,66,66,0,0,6,6
0,0,0,0,0,0,0,0,0,0,0,0,0,0,0,15,73,15,6,5,19,19,5,6,6,5,5,5,6,6,5,55,0,0,0
0,0,0,0,0,0,0,0,0,0,0,0,0,0,0,0,0,0,15,6,23,8,0,6,0,0,6,6,6,6,5,5,0,0,0
0,0,0,0,0,0,0,0,0,0,0,0,0,0,0,0,0,0,6,6,6,6,8,8,8,23,23,23,6,6,6,6,4,0,0
0,0,0,0,0,0,0,0,0,0,0,0,0,0,0,0,0,0,6,6,6,6,8,8,23,8,6,5,5,5,6,6,0,0,0
0,0,0,0,0,0,0,0,0,0,0,0,0,0,0,0,0,106,6,6,6,6,6,19,8,23,23,23,6,6,6,6,6,44,0
0,0,0,0,0,0,0,0,0,0,0,0,0,0,0,0,106,6,6,6,6,6,6,19,19,8,23,23,5,5,6,6,6,6,44
0,0,0,0,0,0,0,0,0,0,0,0,0,0,0,74,6,6,5,5,6,6,6,0,8,19,23,23,23,8,6,6,6,6,0
0,0,0,0,0,0,0,0,0,0,0,0,0,0,0,20,6,6,6,6,6,6,6,6,8,8,8,23,8,8,8,0,6,6,44
0,0,0,0,0,0,0,0,0,0,0,0,0,0,15,54,6,6,5,5,6,6,6,6,6,6,6,8,8,8,6,6,66,95,0
0,0,0,0,0,0,0,0,0,0,0,0,0,20,15,0,0,41,5,0,31,6,6,6,6,6,6,6,6,0,6,31,6,44,0
0,0,0,0,0,0,0,0,0,0,0,0,20,0,0,0,41,41,41,20,15,0,5,5,6,15,6,5,6,6,6,6,0,0,0
0,0,0,0,0,0,0,66,6,0,0,0,0,15,41,41,0,0,15,15,0,0,0,6,0,15,6,6,6,6,5,4,0,0,0
0,0,0,0,0,0,54,6,6,6,0,0,0,0,57,0,0,0,0,15,0,6,0,31,0,54,6,6,6,6,5,0,0,0,0
0,0,0,0,0,0,0,41,6,0,0,0,41,41,0,0,0,0,0,0,41,0,0,0,0,0,6,6,6,6,5,0,0,0,0
0,0,0,0,0,0,0,0,81,0,0,0,41,0,0,0,0,0,0,0,0,0,0,0,0,15,6,6,6,6,6,0,0,0,0
0,0,0,0,0,0,0,0,0,0,0,0,0,0,0,0,0,0,0,0,0,0,0,0,0,54,6,6,31,6,0,0,0,0,0
0,0,0,0,0,0,0,0,0,0,0,0,0,0,0,0,0,0,0,0,0,0,0,0,0,0,41,6,0,31,0,0,0,0,6
0,0,0,0,0,0,0,0,0,0,0,0,0,0,0,0,0,0,0,0,0,0,0,0,0,0,0,0,0,0,0,0,0,0,4
0,0,0,0,0,0,0,0,0,0,0,0,0,0,0,0,0,0,0,0,0,0,0,0,0,0,0,0,0,0,0,0,0,0,0
0,0,0,0,0,0,0,0,0,0,0,0,0,0,0,0,0,0,0,0,0,0,0,0,0,0,0,0,0,6,0,0,0,0,0
0,0,0,0,0,0,0,0,0,0,0,0,0,0,0,0,0,0,0,0,0,0,0,0,0,0,0,0,6,6,6,0,0,0,0
0,0,0,0,0,0,0,0,0,0,0,0,0,0,0,0,0,0,0,0,0,0,0,0,0,0,0,0,0,6,0,0,0,0,0
0,0,0,0,0,0,0,0,0,0,0,0,0,0,0,0,0,0,0,0,0,0,0,0,0,0,0,0,0,0,0,0,0,0,0
endlayer

layer
0,0,0,0,0,0,0,0,0,0,0,0,0,0,0,0,0,0,0,66,43,44,0,0,0,0,0,0,0,0,0,0,0,0,20
0,0,0,0,0,0,0,0,0,0,0,0,0,0,0,15,15,0,0,20,6,43,0,66,0,0,0,0,0,0,0,0,0,0,6
0,0,0,0,0,0,0,0,0,0,0,0,0,0,15,15,0,54,6,6,6,6,44,6,66,4,0,0,0,0,0,0,0,4,6
0,0,0,0,0,0,0,0,0,0,0,0,0,0,0,15,15,0,6,6,19,0,6,6,6,66,66,66,0,0,0,0,0,0,4
0,0,0,0,0,0,0,0,0,0,0,0,0,0,0,15,73,15,6,23,8,6,6,6,6,6,5,5,6,6,44,0,0,0,0
0,0,0,0,0,0,0,0,0,0,0,0,0,0,0,0,0,0,15,6,6,6,6,6,19,6,6,6,6,6,95,0,0,0,0
0,0,0,0,0,0,0,0,0,0,0,0,0,0,0,0,0,0,41,6,6,73,6,23,23,23,6,6,6,6,95,0,0,0,0
0,0,0,0,0,0,0,0,0,0,0,0,0,0,0,0,0,0,0,5,5,5,19,23,23,19,6,6,6,6,6,4,0,0,0
0,0,0,0,0,0,0,0,0,0,0,0,0,0,0,0,0,106,0,5,5,5,6,19,19,19,8,6,0,6,6,4,0,0,0
0,0,0,0,0,0,0,0,0,0,0,0,0,0,0,0,15,6,5,5,5,5,5,19,19,19,23,8,43,6,6,6,4,0,0
0,0,0,0,0,0,0,0,0,0,0,0,0,0,0,0,6,5,5,5,5,6,5,5,6,19,8,8,8,6,6,6,4,0,0
0,0,0,0,0,0,0,0,0,0,0,0,0,0,0,20,6,6,6,6,6,6,5,5,5,5,6,8,8,23,23,6,6,37,0
0,0,0,0,0,0,0,0,0,0,0,0,0,0,15,15,6,6,6,15,6,6,5,5,5,5,6,6,19,6,6,44,0,95,0
0,0,0,0,0,0,0,0,0,0,0,0,0,20,15,0,0,6,0,0,88,5,5,5,5,5,6,6,6,6,6,0,0,44,0
0,0,0,0,0,0,0,0,0,0,0,0,20,0,0,0,41,41,0,20,15,5,5,5,5,0,0,41,6,6,0,6,0,0,0
0,0,0,0,0,0,0,66,6,0,0,0,0,15,41,41,0,0,15,15,0,31,5,5,0,0,0,0,6,6,6,6,0,0,0
0,0,0,0,0,0,74,6,6,6,0,0,0,0,57,0,0,0,0,15,0,0,31,0,0,0,4,0,6,6,44,0,0,0,0
0,0,0,0,0,0,0,81,6,31,0,41,41,41,0,0,0,0,0,0,41,0,0,0,0,0,0,15,6,5,6,0,0,0,0
0,0,0,0,0,0,0,0,0,0,0,0,41,0,0,0,0,0,0,0,0,0,0,0,0,0,4,0,41,6,44,0,0,0,0
0,0,0,0,0,0,0,0,0,0,0,0,0,0,0,0,0,0,0,0,0,0,0,0,0,0,0,0,0,0,0,0,0,0,0
0,0,0,0,0,0,0,0,0,0,0,0,0,0,0,0,0,0,0,0,0,0,0,0,0,0,0,0,0,0,0,0,0,0,6
0,0,0,0,0,0,0,0,0,0,0,0,0,0,0,0,0,0,0,0,0,0,0,0,0,0,0,0,0,0,0,0,0,0,0
0,0,0,0,0,0,0,0,0,0,0,0,0,0,0,0,0,0,0,0,0,0,0,0,0,0,0,0,0,0,0,0,0,0,0
0,0,0,0,0,0,0,0,0,0,0,0,0,0,0,0,0,0,0,0,0,0,0,0,0,0,0,0,0,6,0,0,0,0,0
0,0,0,0,0,0,0,0,0,0,0,0,0,0,0,0,0,0,0,0,0,0,0,0,0,0,0,0,6,6,6,0,0,0,0
0,0,0,0,0,0,0,0,0,0,0,0,0,0,0,0,0,0,0,0,0,0,0,0,0,0,0,0,31,6,0,0,0,0,0
0,0,0,0,0,0,0,0,0,0,0,0,0,0,0,0,0,0,0,0,0,0,0,0,0,0,0,0,0,0,0,0,0,0,0
endlayer

layer
0,0,0,0,0,0,0,0,0,0,0,0,0,0,0,0,0,0,0,66,43,44,0,0,0,0,0,0,0,0,0,0,0,0,20
0,0,0,0,0,0,0,0,0,0,0,0,0,0,0,15,15,0,6,66,6,44,0,0,0,0,0,0,0,0,0,0,0,54,6
0,0,0,0,0,0,0,0,0,0,0,0,0,0,15,15,0,66,6,6,6,44,44,0,0,0,0,0,0,0,0,0,0,15,6
0,0,0,0,0,0,0,0,0,0,0,0,0,0,0,15,15,5,6,19,6,6,0,0,0,0,0,0,0,0,0,0,0,0,0
0,0,0,0,0,0,0,0,0,0,0,0,0,0,0,15,73,0,6,23,8,6,6,6,6,0,0,4,66,66,0,0,0,0,0
0,0,0,0,0,0,0,0,0,0,0,0,0,0,0,0,0,0,6,6,6,6,6,6,6,0,66,6,6,6,95,0,0,0,0
0,0,0,0,0,0,0,0,0,0,0,0,0,0,0,0,0,0,41,0,0,41,15,6,6,6,6,6,6,6,37,0,0,0,0
0,0,0,0,0,0,0,0,0,0,0,0,0,0,0,0,0,0,0,0,0,15,6,6,6,6,66,66,6,6,0,0,0,0,0
0,0,0,0,0,0,0,0,0,0,0,0,0,0,0,0,0,0,0,0,0,0,41,6,6,8,8,6,6,6,6,0,0,0,0
0,0,0,0,0,0,0,0,0,0,0,0,0,0,0,0,0,106,4,0,0,55,6,5,6,8,8,8,43,6,6,95,0,0,0
0,0,0,0,0,0,0,0,0,0,0,0,0,0,0,0,66,6,5,0,0,6,6,5,6,6,8,8,8,0,6,0,106,0,0
0,0,0,0,0,0,0,0,0,0,0,0,0,0,0,20,5,5,6,0,15,6,6,6,5,5,6,8,8,0,6,0,6,95,0
0,0,0,0,0,0,0,0,0,0,0,0,0,0,15,6,6,5,0,0,0,0,6,6,6,5,6,6,6,6,6,44,0,95,0
0,0,0,0,0,0,0,0,0,0,0,0,0,20,15,6,6,31,0,0,20,15,5,6,6,0,6,6,6,6,6,0,0,44,0
0,0,0,0,0,0,0,0,0,0,0,0,20,0,0,0,41,0,0,20,15,5,5,5,0,0,31,0,6,6,0,0,0,0,0
0,0,0,0,0,0,0,0,0,0,0,0,0,15,41,41,0,0,15,15,0,5,5,0,0,0,0,0,6,6,0,0,0,0,0
0,0,0,0,0,0,0,15,6,4,15,0,0,0,57,0,0,0,0,15,0,0,0,0,0,0,0,54,6,6,44,0,0,0,0
0,0,0,0,0,0,0,0,41,0,0,41,41,41,0,0,0,0,0,0,41,0,0,0,0,0,0,15,6,5,6,0,0,0,0
0,0,0,0,0,0,0,0,0,0,0,0,41,0,0,0,0,0,0,0,0,0,0,0,0,0,0,0,41,6,44,0,0,0,0
0,0,0,0,0,0,0,0,0,0,0,0,0,0,0,0,0,0,0,0,0,0,0,0,0,0,0,0,0,0,0,0,0,0,0
0,0,0,0,0,0,0,0,0,0,0,0,0,0,0,0,0,0,0,0,0,0,0,0,0,0,0,0,0,0,0,0,0,0,0
0,0,0,0,0,0,0,0,0,0,0,0,0,0,0,0,0,0,0,0,0,0,0,0,0,0,0,0,0,0,0,0,0,0,54
0,0,0,0,0,0,0,0,0,0,0,0,0,0,0,0,0,0,0,0,0,0,0,0,0,0,0,0,0,0,0,0,0,0,0
0,0,0,0,0,0,0,0,0,0,0,0,0,0,0,0,0,0,0,0,0,0,0,0,0,0,0,0,0,66,0,0,0,0,0
0,0,0,0,0,0,0,0,0,0,0,0,0,0,0,0,0,0,0,0,0,0,0,0,0,0,0,0,15,6,37,0,0,0,0
0,0,0,0,0,0,0,0,0,0,0,0,0,0,0,0,0,0,0,0,0,0,0,0,0,0,0,0,0,41,0,0,0,0,0
0,0,0,0,0,0,0,0,0,0,0,0,0,0,0,0,0,0,0,0,0,0,0,0,0,0,0,0,0,0,0,0,0,0,0
endlayer

layer
0,0,0,0,0,0,0,0,0,0,0,0,0,0,0,0,0,55,0,66,44,44,0,0,0,0,0,0,0,0,0,0,0,0,15
0,0,0,0,0,0,0,0,0,0,0,0,0,0,0,15,15,6,5,6,0,0,0,0,0,0,0,0,0,0,0,0,0,15,6
0,0,0,0,0,0,0,0,0,0,0,0,0,0,15,15,0,6,19,6,6,44,44,0,0,0,0,0,0,0,0,0,0,0,6
0,0,0,0,0,0,0,0,0,0,0,0,0,0,0,15,15,5,23,8,6,44,0,0,0,0,0,0,0,0,0,0,0,0,0
0,0,0,0,0,0,0,0,0,0,0,0,0,0,0,15,73,6,6,6,44,44,0,0,0,0,0,0,66,66,0,0,0,0,0
0,0,0,0,0,0,0,0,0,0,0,0,0,0,0,0,0,0,4,0,41,0,0,6,0,0,0,66,6,6,95,0,0,0,0
0,0,0,0,0,0,0,0,0,0,0,0,0,0,0,0,0,0,41,0,0,0,0,0,0,0,0,6,6,6,44,0,0,0,0
0,0,0,0,0,0,0,0,0,0,0,0,0,0,0,0,0,0,0,0,0,0,0,6,6,6,6,6,6,81,0,0,0,0,0
0,0,0,0,0,0,0,0,0,0,0,0,0,0,0,0,0,0,0,0,0,0,54,6,6,6,8,6,6,0,0,0,0,0,0
0,0,0,0,0,0,0,0,0,0,0,0,0,0,0,0,0,0,0,0,0,0,15,5,6,8,8,8,0,6,0,0,0,0,0
0,0,0,0,0,0,0,0,0,0,0,0,0,0,0,0,66,66,0,0,0,15,6,6,6,6,8,8,8,0,0,0,0,0,0
0,0,0,0,0,0,0,0,0,0,0,0,0,0,0,20,5,5,0,0,0,15,6,6,6,5,6,8,6,0,6,0,6,95,0
0,0,0,0,0,0,0,0,0,0,0,0,0,0,15,5,5,5,0,0,0,0,0,6,6,6,6,6,0,6,6,0,6,95,0
0,0,0,0,0,0,0,0,0,0,0,0,0,20,71,6,5,0,0,0,20,5,5,6,0,0,4,0,6,6,95,0,6,44,0
0,0,0,0,0,0,0,0,0,0,0,0,20,0,0,6,41,0,0,20,15,5,5,5,0,0,0,0,0,0,0,0,0,0,0
0,0,0,0,0,0,0,0,55,0,0,20,0,15,41,41,0,0,15,15,6,6,5,6,0,0,0,0,4,0,0,0,0,0,0
0,0,0,0,0,0,0,15,6,0,15,0,0,0,57,0,0,0,0,15,31,6,0,0,0,0,0,0,0,6,44,0,0,0,0
0,0,0,0,0,0,0,0,41,0,0,41,41,41,0,0,0,0,0,0,41,0,0,0,0,0,0,0,6,5,6,37,0,0,0
0,0,0,0,0,0,0,0,0,0,0,0,41,0,0,0,0,0,0,0,0,0,0,0,0,0,0,0,41,6,44,0,0,0,0
0,0,0,0,0,0,0,0,0,0,0,0,0,0,0,0,0,0,0,0,0,0,0,0,0,0,0,0,0,0,0,0,0,0,0
0,0,0,0,0,0,0,0,0,0,0,0,0,0,0,0,0,0,0,0,0,0,0,0,0,0,0,0,0,0,0,0,0,0,0
0,0,0,0,0,0,0,0,0,0,0,0,0,0,0,0,0,0,0,0,0,0,0,0,0,0,0,0,0,0,0,0,0,0,0
0,0,0,0,0,0,0,0,0,0,0,0,0,0,0,0,0,0,0,0,0,0,0,0,0,0,0,0,0,0,0,0,0,0,0
0,0,0,0,0,0,0,0,0,0,0,0,0,0,0,0,0,0,0,0,0,0,0,0,0,0,0,0,0,66,0,0,0,0,0
0,0,0,0,0,0,0,0,0,0,0,0,0,0,0,0,0,0,0,0,0,0,0,0,0,0,0,0,15,6,44,0,0,0,0
0,0,0,0,0,0,0,0,0,0,0,0,0,0,0,0,0,0,0,0,0,0,0,0,0,0,0,0,0,41,0,0,0,0,0
0,0,0,0,0,0,0,0,0,0,0,0,0,0,0,0,0,0,0,0,0,0,0,0,0,0,0,0,0,0,0,0,0,0,0
endlayer

layer
0,0,0,0,0,0,0,0,0,0,0,0,0,0,0,0,0,20,0,66,44,44,0,0,0,0,0,0,0,0,0,0,0,0,15
0,0,0,0,0,0,0,0,0,0,0,0,0,0,0,15,15,5,5,6,0,0,0,0,0,0,0,0,0,0,0,0,0,15,6
0,0,0,0,0,0,0,0,0,0,0,0,0,0,15,15,0,5,5,6,0,44,44,0,0,0,0,0,0,0,0,0,0,0,6
0,0,0,0,0,0,0,0,0,0,0,0,0,0,0,15,15,5,5,6,44,44,0,0,0,0,0,0,0,0,0,0,0,0,0
0,0,0,0,0,0,0,0,0,0,0,0,0,0,0,15,73,5,5,44,44,44,0,0,0,0,0,0,66,55,0,0,0,0,0
0,0,0,0,0,0,0,0,0,0,0,0,0,0,0,0,54,5,41,0,41,0,0,0,0,0,0,0,6,6,95,0,0,0,0
0,0,0,0,0,0,0,0,0,0,0,0,0,0,0,0,0,31,41,0,0,0,0,0,0,0,0,6,6,6,95,0,0,0,0
0,0,0,0,0,0,0,0,0,0,0,0,0,0,0,0,0,0,0,0,0,0,0,0,0,6,6,6,6,81,0,0,0,0,0
0,0,0,0,0,0,0,0,0,0,0,0,0,0,0,0,0,0,0,0,0,0,0,0,6,6,0,6,6,0,0,0,0,0,0
0,0,0,0,0,0,0,0,0,0,0,0,0,0,0,0,0,0,0,0,0,0,15,0,6,6,8,8,6,6,0,0,0,0,0
0,0,0,0,0,0,0,0,0,0,0,0,0,0,0,0,0,0,0,0,0,0,15,6,6,6,8,8,8,8,5,0,0,0,0
0,0,0,0,0,0,0,0,0,0,0,0,0,0,0,20,6,0,0,0,0,0,15,6,6,6,6,41,41,6,6,0,0,0,0
0,0,0,0,0,0,0,0,0,0,0,0,0,0,15,5,5,6,0,0,0,0,0,0,0,0,4,6,0,6,6,0,0,0,0
0,0,0,0,0,0,0,0,0,0,0,0,0,20,6,5,5,0,0,0,66,6,0,66,0,0,81,0,0,6,6,0,0,0,0
0,0,0,0,0,0,0,0,0,0,0,0,20,0,6,6,41,0,0,20,6,6,5,5,0,0,0,0,0,6,0,0,0,0,0
0,0,0,0,0,0,0,0,66,0,0,20,0,15,41,41,0,0,15,15,6,6,5,5,0,0,0,0,0,0,0,0,0,0,0
0,0,0,0,0,0,0,15,6,0,15,0,0,0,57,0,0,0,0,15,6,6,5,0,0,0,0,0,0,6,44,0,0,0,0
0,0,0,0,0,0,0,0,6,0,0,41,41,41,0,0,0,0,0,0,41,0,0,0,0,0,0,54,6,6,6,95,0,0,0
0,0,0,0,0,0,0,0,0,0,0,0,41,0,0,0,0,0,0,0,0,0,0,0,0,0,0,0,0,6,44,0,0,0,0
0,0,0,0,0,0,0,0,0,0,0,0,0,0,0,0,0,0,0,0,0,0,0,0,0,0,0,0,0,0,0,0,0,0,0
0,0,0,0,0,0,0,0,0,0,0,0,0,0,0,0,0,0,0,0,0,0,0,0,0,0,0,0,0,0,0,0,0,0,0
0,0,0,0,0,0,0,0,0,0,0,0,0,0,0,0,0,0,0,0,0,0,0,0,0,0,0,0,0,0,0,0,0,0,0
0,0,0,0,0,0,0,0,0,0,0,0,0,0,0,0,0,0,0,0,0,0,0,0,0,0,0,0,0,0,0,0,0,0,0
0,0,0,0,0,0,0,0,0,0,0,0,0,0,0,0,0,0,0,0,0,0,0,0,0,0,0,0,0,66,0,0,0,0,0
0,0,0,0,0,0,0,0,0,0,0,0,0,0,0,0,0,0,0,0,0,0,0,0,0,0,0,0,15,6,44,0,0,0,0
0,0,0,0,0,0,0,0,0,0,0,0,0,0,0,0,0,0,0,0,0,0,0,0,0,0,0,0,0,41,0,0,0,0,0
0,0,0,0,0,0,0,0,0,0,0,0,0,0,0,0,0,0,0,0,0,0,0,0,0,0,0,0,0,0,0,0,0,0,0
endlayer

layer
0,0,0,0,0,0,0,0,0,0,0,0,0,0,0,0,0,20,6,66,44,44,0,0,0,0,0,0,0,0,0,0,0,0,15
0,0,0,0,0,0,0,0,0,0,0,0,0,0,0,15,15,6,6,6,0,0,0,0,0,0,0,0,0,0,0,0,0,15,6
0,0,0,0,0,0,0,0,0,0,0,0,0,0,15,15,6,6,5,5,5,44,44,0,0,0,0,0,0,0,0,0,0,0,0
0,0,0,0,0,0,0,0,0,0,0,0,0,0,0,15,15,6,6,5,44,44,0,0,0,0,0,0,0,0,0,0,0,0,0
0,0,0,0,0,0,0,0,0,0,0,0,0,0,0,15,41,31,5,44,44,44,0,0,0,0,0,0,66,66,0,0,0,0,0
0,0,0,0,0,0,0,0,0,0,0,0,0,0,0,0,41,0,41,0,41,0,0,0,0,0,0,0,6,6,95,0,0,0,0
0,0,0,0,0,0,0,0,0,0,0,0,0,0,0,0,0,0,41,0,0,0,0,0,0,0,0,6,6,6,44,0,0,0,0
0,0,0,0,0,0,0,0,0,0,0,0,0,0,0,0,0,0,0,0,0,0,0,0,0,6,6,6,6,81,0,0,0,0,0
0,0,0,0,0,0,0,0,0,0,0,0,0,0,0,0,0,0,0,0,0,0,0,55,6,6,0,6,6,0,0,0,0,0,0
0,0,0,0,0,0,0,0,0,0,0,0,0,0,0,0,0,0,0,0,0,0,15,6,6,6,8,8,6,0,0,0,0,0,0
0,0,0,0,0,0,0,0,0,0,0,0,0,0,0,0,0,0,0,0,0,0,15,6,6,6,8,8,23,8,5,0,0,0,0
0,0,0,0,0,0,0,0,0,0,0,0,0,0,0,66,0,0,0,0,0,0,15,6,0,6,6,41,6,103,0,0,0,0,0
0,0,0,0,0,0,0,0,0,0,0,0,0,0,15,6,6,0,0,0,0,0,0,0,0,0,31,0,0,74,0,0,0,0,0
0,0,0,0,0,0,0,0,0,0,0,0,0,20,6,6,6,0,0,0,66,6,0,0,0,0,81,0,0,6,81,0,0,0,0
0,0,0,0,0,0,0,0,0,0,0,0,20,0,6,6,31,0,0,66,6,6,5,0,0,0,0,0,0,0,0,0,0,0,0
0,0,0,0,0,0,0,0,66,0,0,20,0,15,71,41,0,0,15,6,6,6,5,6,0,0,0,0,0,0,0,0,0,0,0
0,0,0,0,0,0,0,15,6,37,15,0,0,0,57,0,0,0,0,15,6,6,5,0,0,0,0,0,0,6,44,0,0,0,0
0,0,0,0,0,0,0,0,41,0,0,41,41,41,0,0,0,0,0,0,41,6,0,0,0,0,0,0,6,6,44,0,0,0,0
0,0,0,0,0,0,0,0,0,0,0,0,41,0,0,0,0,0,0,0,0,0,0,0,0,0,0,0,0,41,0,0,0,0,0
0,0,0,0,0,0,0,0,0,0,0,0,0,0,0,0,0,0,0,0,0,0,0,0,0,0,0,0,0,0,0,0,0,0,0
0,0,0,0,0,0,0,0,0,0,0,0,0,0,0,0,0,0,0,0,0,0,0,0,0,0,0,0,0,0,0,0,0,0,0
0,0,0,0,0,0,0,0,0,0,0,0,0,0,0,0,0,0,0,0,0,0,0,0,0,0,0,0,0,0,0,0,0,0,0
0,0,0,0,0,0,0,0,0,0,0,0,0,0,0,0,0,0,0,0,0,0,0,0,0,0,0,0,0,0,0,0,0,0,0
0,0,0,0,0,0,0,0,0,0,0,0,0,0,0,0,0,0,0,0,0,0,0,0,0,0,0,0,0,0,0,0,0,0,0
0,0,0,0,0,0,0,0,0,0,0,0,0,0,0,0,0,0,0,0,0,0,0,0,0,0,0,0,0,4,0,0,0,0,0
0,0,0,0,0,0,0,0,0,0,0,0,0,0,0,0,0,0,0,0,0,0,0,0,0,0,0,0,0,0,0,0,0,0,0
0,0,0,0,0,0,0,0,0,0,0,0,0,0,0,0,0,0,0,0,0,0,0,0,0,0,0,0,0,0,0,0,0,0,0
endlayer

layer
0,0,0,0,0,0,0,0,0,0,0,0,0,0,0,0,0,15,6,66,44,44,0,0,0,0,0,0,0,0,0,0,0,0,15
0,0,0,0,0,0,0,0,0,0,0,0,0,0,0,15,15,5,5,6,0,0,0,0,0,0,0,0,0,0,0,0,0,15,6
0,0,0,0,0,0,0,0,0,0,0,0,0,0,15,15,6,5,5,5,5,44,44,0,0,0,0,0,0,0,0,0,0,0,0
0,0,0,0,0,0,0,0,0,0,0,0,0,0,0,15,0,6,6,5,0,44,0,0,0,0,0,0,0,0,0,0,0,0,0
0,0,0,0,0,0,0,0,0,0,0,0,0,0,0,15,41,41,6,0,44,44,0,0,0,0,0,0,0,66,0,0,0,0,0
0,0,0,0,0,0,0,0,0,0,0,0,0,0,0,0,41,0,41,0,41,0,0,0,0,0,0,0,6,6,95,0,0,0,0
0,0,0,0,0,0,0,0,0,0,0,0,0,0,0,0,0,0,41,0,0,0,0,0,0,0,0,55,0,6,44,0,0,0,0
0,0,0,0,0,0,0,0,0,0,0,0,0,0,0,0,0,0,0,0,0,0,0,0,0,0,6,6,0,66,0,0,0,0,0
0,0,0,0,0,0,0,0,0,0,0,0,0,0,0,0,0,0,0,0,0,0,0,0,6,6,6,6,6,0,71,0,0,0,0
0,0,0,0,0,0,0,0,0,0,0,0,0,0,0,0,0,0,0,0,0,0,15,6,6,6,6,8,6,6,55,0,0,0,0
0,0,0,0,0,0,0,0,0,0,0,0,0,0,0,0,0,0,0,0,0,0,0,6,6,6,8,8,8,8,8,5,0,0,0
0,0,0,0,0,0,0,0,0,0,0,0,0,0,0,66,0,0,0,0,0,0,15,6,6,6,6,6,0,6,5,0,0,0,0
0,0,0,0,0,0,0,0,0,0,0,0,0,0,0,6,0,0,0,0,0,0,0,0,0,31,0,0,0,74,0,0,0,0,0
0,0,0,0,0,0,0,0,0,0,0,0,0,20,6,6,6,0,0,0,66,0,0,0,0,0,81,0,0,41,81,0,0,0,0
0,0,0,0,0,0,0,0,0,0,0,0,20,6,6,6,57,0,0,66,6,6,5,0,0,0,0,0,0,0,0,0,0,0,0
0,0,0,0,0,0,0,0,0,0,0,20,0,15,6,41,0,0,15,6,6,6,5,0,0,0,0,0,0,0,0,0,0,0,0
0,0,0,0,0,0,0,0,6,44,15,0,0,0,57,0,0,0,0,31,6,6,5,0,0,0,0,0,0,66,0,0,0,0,0
0,0,0,0,0,0,0,0,41,0,0,41,41,41,0,0,0,0,0,0,41,6,31,0,0,0,0,0,6,6,44,0,0,0,0
0,0,0,0,0,0,0,0,0,0,0,0,41,0,0,0,0,0,0,0,0,0,0,0,0,0,0,0,0,0,0,0,0,0,0
0,0,0,0,0,0,0,0,0,0,0,0,0,0,0,0,0,0,0,0,0,0,0,0,0,0,0,0,0,0,0,0,0,0,0
0,0,0,0,0,0,0,0,0,0,0,0,0,0,0,0,0,0,0,0,0,0,0,0,0,0,0,0,0,0,0,0,0,0,0
0,0,0,0,0,0,0,0,0,0,0,0,0,0,0,0,0,0,0,0,0,0,0,0,0,0,0,0,0,0,0,0,0,0,0
0,0,0,0,0,0,0,0,0,0,0,0,0,0,0,0,0,0,0,0,0,0,0,0,0,0,0,0,0,0,0,0,0,0,0
0,0,0,0,0,0,0,0,0,0,0,0,0,0,0,0,0,0,0,0,0,0,0,0,0,0,0,0,0,0,0,0,0,0,0
0,0,0,0,0,0,0,0,0,0,0,0,0,0,0,0,0,0,0,0,0,0,0,0,0,0,0,0,0,0,0,0,0,0,0
0,0,0,0,0,0,0,0,0,0,0,0,0,0,0,0,0,0,0,0,0,0,0,0,0,0,0,0,0,0,0,0,0,0,0
0,0,0,0,0,0,0,0,0,0,0,0,0,0,0,0,0,0,0,0,0,0,0,0,0,0,0,0,0,0,0,0,0,0,0
endlayer

layer
0,0,0,0,0,0,0,0,0,0,0,0,0,0,0,0,55,6,6,6,44,44,0,0,0,0,0,0,0,0,0,0,0,0,15
0,0,0,0,0,0,0,0,0,0,0,0,0,0,0,15,6,6,6,6,6,37,0,0,0,0,0,0,0,0,0,0,0,0,15
0,0,0,0,0,0,0,0,0,0,0,0,0,0,15,15,6,6,6,6,5,44,44,0,0,0,0,0,0,0,0,0,0,0,0
0,0,0,0,0,0,0,0,0,0,0,0,0,0,0,15,6,6,6,5,5,44,0,0,0,0,0,0,0,0,0,0,0,0,0
0,0,0,0,0,0,0,0,0,0,0,0,0,0,0,15,41,6,6,5,44,44,0,0,0,0,0,0,0,66,0,0,0,0,0
0,0,0,0,0,0,0,0,0,0,0,0,0,0,0,0,41,31,0,0,41,0,0,0,0,0,0,0,74,6,95,0,0,0,0
0,0,0,0,0,0,0,0,0,0,0,0,0,0,0,0,0,0,41,0,0,0,0,0,0,0,0,0,0,81,0,0,0,0,0
0,0,0,0,0,0,0,0,0,0,0,0,0,0,0,0,0,0,0,0,0,0,0,0,0,0,0,6,0,66,0,0,0,0,0
0,0,0,0,0,0,0,0,0,0,0,0,0,0,0,0,0,0,0,0,0,0,0,0,55,6,6,5,6,71,6,0,0,0,0
0,0,0,0,0,0,0,0,0,0,0,0,0,0,0,0,0,0,0,0,0,0,0,0,6,6,6,8,6,0,6,42,42,0,0
0,0,0,0,0,0,0,0,0,0,0,0,0,0,0,0,0,0,0,0,0,0,0,6,6,6,8,8,6,6,8,5,42,42,0
0,0,0,0,0,0,0,0,0,0,0,0,0,0,0,0,0,0,0,0,0,0,0,0,6,6,6,6,6,6,5,5,0,0,0
0,0,0,0,0,0,0,0,0,0,0,0,0,0,0,0,0,0,0,0,0,0,0,0,0,31,0,0,0,74,0,5,0,0,0
0,0,0,0,0,0,0,0,0,0,0,0,0,66,6,6,0,0,0,0,0,0,0,0,0,0,81,0,0,41,81,31,0,0,0
0,0,0,0,0,0,0,0,0,0,0,0,20,5,6,6,44,0,0,0,66,6,55,0,0,0,0,0,0,0,0,0,0,0,0
0,0,0,0,0,0,0,0,55,0,0,20,0,5,6,41,0,0,0,0,6,6,5,0,0,0,0,0,0,0,0,0,0,0,0
0,0,0,0,0,0,0,0,6,44,15,0,0,31,57,0,0,0,0,15,6,6,31,0,0,0,0,0,0,0,0,0,0,0,0
0,0,0,0,0,0,0,0,41,0,0,41,41,41,0,0,0,0,0,0,41,41,0,0,0,0,0,0,0,6,0,0,0,0,0
0,0,0,0,0,0,0,0,0,0,0,0,41,0,0,0,0,0,0,0,0,0,0,0,0,0,0,0,0,0,0,0,0,0,0
0,0,0,0,0,0,0,0,0,0,0,0,0,0,0,0,0,0,0,0,0,0,0,0,0,0,0,0,0,0,0,0,0,0,0
0,0,0,0,0,0,0,0,0,0,0,0,0,0,0,0,0,0,0,0,0,0,0,0,0,0,0,0,0,0,0,0,0,0,0
0,0,0,0,0,0,0,0,0,0,0,0,0,0,0,0,0,0,0,0,0,0,0,0,0,0,0,0,0,0,0,0,0,0,0
0,0,0,0,0,0,0,0,0,0,0,0,0,0,0,0,0,0,0,0,0,0,0,0,0,0,0,0,0,0,0,0,0,0,0
0,0,0,0,0,0,0,0,0,0,0,0,0,0,0,0,0,0,0,0,0,0,0,0,0,0,0,0,0,0,0,0,0,0,0
0,0,0,0,0,0,0,0,0,0,0,0,0,0,0,0,0,0,0,0,0,0,0,0,0,0,0,0,0,0,0,0,0,0,0
0,0,0,0,0,0,0,0,0,0,0,0,0,0,0,0,0,0,0,0,0,0,0,0,0,0,0,0,0,0,0,0,0,0,0
0,0,0,0,0,0,0,0,0,0,0,0,0,0,0,0,0,0,0,0,0,0,0,0,0,0,0,0,0,0,0,0,0,0,0
endlayer

layer
0,0,0,0,0,0,0,0,0,0,0,0,0,0,0,0,71,6,6,6,0,44,0,0,0,0,0,0,0,0,0,0,0,0,0
0,0,0,0,0,0,0,0,0,0,0,0,0,0,0,15,6,6,6,6,6,0,0,0,0,0,0,0,0,0,0,0,0,0,0
0,0,0,0,0,0,0,0,0,0,0,0,0,0,15,6,6,6,6,6,6,6,44,0,0,0,0,0,0,0,0,0,0,0,0
0,0,0,0,0,0,0,0,0,0,0,0,0,0,0,15,6,6,6,6,6,44,0,0,0,0,0,0,0,0,0,0,0,0,0
0,0,0,0,0,0,0,0,0,0,0,0,0,0,0,15,0,6,6,6,0,44,0,0,0,0,0,0,0,66,0,0,0,0,0
0,0,0,0,0,0,0,0,0,0,0,0,0,0,0,0,41,31,6,0,41,0,0,0,0,0,0,0,74,6,44,0,0,0,0
0,0,0,0,0,0,0,0,0,0,0,0,0,0,0,0,0,0,41,0,0,0,0,0,0,0,0,55,0,81,0,0,0,0,0
0,0,0,0,0,0,0,0,0,0,0,0,0,0,0,0,0,0,0,0,0,0,0,0,0,0,0,6,0,66,0,0,0,0,0
0,0,0,0,0,0,0,0,0,0,0,0,0,0,0,0,0,0,0,0,0,0,0,0,0,0,6,5,6,6,6,0,55,0,0
0,0,0,0,0,0,0,0,0,0,0,0,0,0,0,0,0,0,0,0,0,0,0,0,0,6,6,8,5,5,6,6,5,0,0
0,0,0,0,0,0,0,0,0,0,0,0,0,0,0,0,0,0,0,0,0,0,0,0,15,6,6,8,0,6,8,8,5,5,0
0,0,0,0,0,0,0,0,0,0,0,0,0,0,0,0,0,0,0,0,0,0,0,0,74,0,6,6,0,6,6,0,0,0,0
0,0,0,0,0,0,0,0,0,0,0,0,0,0,0,0,0,0,0,0,0,0,0,0,0,81,0,0,0,74,6,95,0,0,0
0,0,0,0,0,0,0,0,0,0,0,0,0,66,6,0,0,0,0,0,0,0,0,0,0,0,81,0,0,41,81,0,0,0,0
0,0,0,0,0,0,0,0,0,0,0,0,20,5,6,6,44,0,0,0,66,6,0,0,0,0,0,0,0,0,0,0,0,0,0
0,0,0,0,0,0,0,0,0,0,0,20,5,5,5,41,0,0,0,0,6,6,6,0,0,0,0,0,0,0,0,0,0,0,0
0,0,0,0,0,0,0,0,0,0,15,0,0,5,57,0,0,0,0,15,6,6,44,0,0,0,0,0,0,0,0,0,0,0,0
0,0,0,0,0,0,0,0,0,0,0,41,41,41,0,0,0,0,0,0,31,41,0,0,0,0,0,0,0,6,37,0,0,0,0
0,0,0,0,0,0,0,0,0,0,0,0,41,0,0,0,0,0,0,0,0,0,0,0,0,0,0,0,0,0,0,0,0,0,0
0,0,0,0,0,0,0,0,0,0,0,0,0,0,0,0,0,0,0,0,0,0,0,0,0,0,0,0,0,0,0,0,0,0,0
0,0,0,0,0,0,0,0,0,0,0,0,0,0,0,0,0,0,0,0,0,0,0,0,0,0,0,0,0,0,0,0,0,0,0
0,0,0,0,0,0,0,0,0,0,0,0,0,0,0,0,0,0,0,0,0,0,0,0,0,0,0,0,0,0,0,0,0,0,0
0,0,0,0,0,0,0,0,0,0,0,0,0,0,0,0,0,0,0,0,0,0,0,0,0,0,0,0,0,0,0,0,0,0,0
0,0,0,0,0,0,0,0,0,0,0,0,0,0,0,0,0,0,0,0,0,0,0,0,0,0,0,0,0,0,0,0,0,0,0
0,0,0,0,0,0,0,0,0,0,0,0,0,0,0,0,0,0,0,0,0,0,0,0,0,0,0,0,0,0,0,0,0,0,0
0,0,0,0,0,0,0,0,0,0,0,0,0,0,0,0,0,0,0,0,0,0,0,0,0,0,0,0,0,0,0,0,0,0,0
0,0,0,0,0,0,0,0,0,0,0,0,0,0,0,0,0,0,0,0,0,0,0,0,0,0,0,0,0,0,0,0,0,0,0
endlayer

layer
0,0,0,0,0,0,0,0,0,0,0,0,0,0,0,0,6,6,6,6,6,44,0,0,0,0,0,0,0,0,0,0,0,0,0
0,0,0,0,0,0,0,0,0,0,0,0,0,0,0,15,6,6,6,6,6,44,0,0,0,0,0,0,0,0,0,0,0,0,0
0,0,0,0,0,0,0,0,0,0,0,0,0,0,15,6,6,6,6,6,6,6,44,0,0,0,0,0,0,0,0,0,0,0,0
0,0,0,0,0,0,0,0,0,0,0,0,0,0,0,15,6,6,6,6,6,44,0,0,0,0,0,0,0,0,0,0,0,0,0
0,0,0,0,0,0,0,0,0,0,0,0,0,0,0,15,6,6,6,6,6,44,0,0,0,0,0,0,0,106,0,0,0,0,0
0,0,0,0,0,0,0,0,0,0,0,0,0,0,0,0,41,31,6,0,41,0,0,0,0,0,0,0,74,6,95,0,0,0,0
0,0,0,0,0,0,0,0,0,0,0,0,0,0,0,0,0,0,41,0,0,0,0,0,0,0,0,55,0,81,0,0,0,0,0
0,0,0,0,0,0,0,0,0,0,0,0,0,0,0,0,0,0,0,0,0,0,0,0,0,0,0,6,0,0,0,0,0,0,0
0,0,0,0,0,0,0,0,0,0,0,0,0,0,0,0,0,0,0,0,0,0,0,0,0,54,6,5,6,0,66,0,66,0,0
0,0,0,0,0,0,0,0,0,0,0,0,0,0,0,0,0,0,0,0,0,0,0,0,0,15,6,0,5,5,6,6,5,6,55
0,0,0,0,0,0,0,0,0,0,0,0,0,0,0,0,0,0,0,0,0,0,0,0,0,20,6,8,6,6,6,23,23,5,6
0,0,0,0,0,0,0,0,0,0,0,0,0,0,0,0,0,0,0,0,0,0,0,0,74,0,5,5,0,6,6,6,6,6,6
0,0,0,0,0,0,0,0,0,0,0,0,0,0,0,0,0,0,0,0,0,0,0,0,0,81,0,0,0,0,6,95,0,31,31
0,0,0,0,0,0,0,0,0,0,0,0,0,66,0,0,0,0,0,0,0,0,0,0,0,0,81,0,0,41,81,0,0,0,0
0,0,0,0,0,0,0,0,0,0,0,0,20,5,5,0,0,0,0,0,66,4,0,0,0,0,0,0,0,0,0,0,0,0,0
0,0,0,0,0,0,0,0,0,0,0,20,5,5,5,0,0,0,0,0,6,6,44,0,0,0,0,0,0,0,0,0,0,0,0
0,0,0,0,0,0,0,0,0,0,15,0,0,5,44,0,0,0,0,15,6,6,44,0,0,0,0,0,0,0,0,0,0,0,0
0,0,0,0,0,0,0,0,0,0,0,41,41,41,0,0,0,0,0,0,41,41,0,0,0,0,0,0,0,4,0,0,0,0,0
0,0,0,0,0,0,0,0,0,0,0,0,41,0,0,0,0,0,0,0,0,0,0,0,0,0,0,0,0,0,0,0,0,0,0
0,0,0,0,0,0,0,0,0,0,0,0,0,0,0,0,0,0,0,0,0,0,0,0,0,0,0,0,0,0,0,0,0,0,0
0,0,0,0,0,0,0,0,0,0,0,0,0,0,0,0,0,0,0,0,0,0,0,0,0,0,0,0,0,0,0,0,0,0,0
0,0,0,0,0,0,0,0,0,0,0,0,0,0,0,0,0,0,0,0,0,0,0,0,0,0,0,0,0,0,0,0,0,0,0
0,0,0,0,0,0,0,0,0,0,0,0,0,0,0,0,0,0,0,0,0,0,0,0,0,0,0,0,0,0,0,0,0,0,0
0,0,0,0,0,0,0,0,0,0,0,0,0,0,0,0,0,0,0,0,0,0,0,0,0,0,0,0,0,0,0,0,0,0,0
0,0,0,0,0,0,0,0,0,0,0,0,0,0,0,0,0,0,0,0,0,0,0,0,0,0,0,0,0,0,0,0,0,0,0
0,0,0,0,0,0,0,0,0,0,0,0,0,0,0,0,0,0,0,0,0,0,0,0,0,0,0,0,0,0,0,0,0,0,0
0,0,0,0,0,0,0,0,0,0,0,0,0,0,0,0,0,0,0,0,0,0,0,0,0,0,0,0,0,0,0,0,0,0,0
endlayer

layer
0,0,0,0,0,0,0,0,0,0,0,0,0,0,0,0,55,6,6,6,66,0,0,0,0,0,0,0,0,0,0,0,0,0,0
0,0,0,0,0,0,0,0,0,0,0,0,0,0,0,0,6,6,6,6,6,44,0,0,0,0,0,0,0,0,0,0,0,0,0
0,0,0,0,0,0,0,0,0,0,0,0,0,0,0,6,6,6,6,5,5,5,44,0,0,0,0,0,0,0,0,0,0,0,0
0,0,0,0,0,0,0,0,0,0,0,0,0,0,0,15,6,6,6,5,5,44,0,0,0,0,0,0,0,0,0,0,0,0,0
0,0,0,0,0,0,0,0,0,0,0,0,0,0,0,0,0,6,6,5,4,0,0,0,0,0,0,0,0,0,0,0,0,0,0
0,0,0,0,0,0,0,0,0,0,0,0,0,0,0,0,0,31,6,0,0,0,0,0,0,0,0,0,0,0,0,0,0,0,0
0,0,0,0,0,0,0,0,0,0,0,0,0,0,0,0,0,0,0,0,0,0,0,0,0,0,0,0,0,0,0,0,0,0,0
0,0,0,0,0,0,0,0,0,0,0,0,0,0,0,0,0,0,0,0,0,0,0,0,0,0,0,55,0,0,0,0,0,0,0
0,0,0,0,0,0,0,0,0,0,0,0,0,0,0,0,0,0,0,0,0,0,0,0,0,0,0,6,6,0,0,0,66,5,0
0,0,0,0,0,0,0,0,0,0,0,0,0,0,0,0,0,0,0,0,0,0,0,0,0,15,6,6,6,6,0,0,5,5,5
0,0,0,0,0,0,0,0,0,0,0,0,0,0,0,0,0,0,0,0,0,0,0,0,0,20,6,8,6,6,6,6,5,23,5
0,0,0,0,0,0,0,0,0,0,0,0,0,0,0,0,0,0,0,0,0,0,0,0,74,0,5,5,5,6,6,0,6,5,5
0,0,0,0,0,0,0,0,0,0,0,0,0,0,0,0,0,0,0,0,0,0,0,0,0,81,31,0,5,6,44,0,0,5,31
0,0,0,0,0,0,0,0,0,0,0,0,0,66,0,0,0,0,0,0,0,0,0,0,0,0,81,0,0,41,0,0,0,0,0
0,0,0,0,0,0,0,0,0,0,0,0,66,5,0,0,0,0,0,0,0,66,0,0,0,0,0,0,0,0,0,0,0,0,0
0,0,0,0,0,0,0,0,0,0,0,20,5,5,5,0,0,0,0,0,6,6,44,0,0,0,0,0,0,0,0,0,0,0,0
0,0,0,0,0,0,0,0,0,0,15,0,5,5,31,0,0,0,0,0,41,6,44,0,0,0,0,0,0,0,0,0,0,0,0
0,0,0,0,0,0,0,0,0,0,0,41,41,0,0,0,0,0,0,0,0,41,0,0,0,0,0,0,0,0,0,0,0,0,0
0,0,0,0,0,0,0,0,0,0,0,0,41,0,0,0,0,0,0,0,0,0,0,0,0,0,0,0,0,0,0,0,0,0,0
0,0,0,0,0,0,0,0,0,0,0,0,0,0,0,0,0,0,0,0,0,0,0,0,0,0,0,0,0,0,0,0,0,0,0
0,0,0,0,0,0,0,0,0,0,0,0,0,0,0,0,0,0,0,0,0,0,0,0,0,0,0,0,0,0,0,0,0,0,0
0,0,0,0,0,0,0,0,0,0,0,0,0,0,0,0,0,0,0,0,0,0,0,0,0,0,0,0,0,0,0,0,0,0,0
0,0,0,0,0,0,0,0,0,0,0,0,0,0,0,0,0,0,0,0,0,0,0,0,0,0,0,0,0,0,0,0,0,0,0
0,0,0,0,0,0,0,0,0,0,0,0,0,0,0,0,0,0,0,0,0,0,0,0,0,0,0,0,0,0,0,0,0,0,0
0,0,0,0,0,0,0,0,0,0,0,0,0,0,0,0,0,0,0,0,0,0,0,0,0,0,0,0,0,0,0,0,0,0,0
0,0,0,0,0,0,0,0,0,0,0,0,0,0,0,0,0,0,0,0,0,0,0,0,0,0,0,0,0,0,0,0,0,0,0
0,0,0,0,0,0,0,0,0,0,0,0,0,0,0,0,0,0,0,0,0,0,0,0,0,0,0,0,0,0,0,0,0,0,0
endlayer

layer
0,0,0,0,0,0,0,0,0,0,0,0,0,0,0,0,55,6,6,6,66,0,0,0,0,0,0,0,0,0,0,0,0,0,0
0,0,0,0,0,0,0,0,0,0,0,0,0,0,0,0,6,6,6,6,6,0,0,0,0,0,0,0,0,0,0,0,0,0,0
0,0,0,0,0,0,0,0,0,0,0,0,0,0,0,0,6,6,6,6,6,37,0,0,0,0,0,0,0,0,0,0,0,0,0
0,0,0,0,0,0,0,0,0,0,0,0,0,0,0,15,6,6,6,6,6,44,0,0,0,0,0,0,0,0,0,0,0,0,0
0,0,0,0,0,0,0,0,0,0,0,0,0,0,0,0,0,6,6,6,0,0,0,0,0,0,0,0,0,0,0,0,0,0,0
0,0,0,0,0,0,0,0,0,0,0,0,0,0,0,0,0,31,0,0,0,0,0,0,0,0,0,0,0,0,0,0,0,0,0
0,0,0,0,0,0,0,0,0,0,0,0,0,0,0,0,0,0,0,0,0,0,0,0,0,0,0,0,0,0,0,0,0,0,0
0,0,0,0,0,0,0,0,0,0,0,0,0,0,0,0,0,0,0,0,0,0,0,0,0,0,0,0,0,0,0,0,0,0,0
0,0,0,0,0,0,0,0,0,0,0,0,0,0,0,0,0,0,0,0,0,0,0,0,0,0,55,0,0,0,0,0,0,66,0
0,0,0,0,0,0,0,0,0,0,0,0,0,0,0,0,0,0,0,0,0,0,0,0,0,15,6,6,6,0,0,0,0,5,43
0,0,0,0,0,0,0,0,0,0,0,0,0,0,0,0,0,0,0,0,0,0,0,0,0,20,6,8,6,6,0,0,5,5,5
0,0,0,0,0,0,0,0,0,0,0,0,0,0,0,0,0,0,0,0,0,0,0,0,74,5,5,5,5,6,95,0,0,5,31
0,0,0,0,0,0,0,0,0,0,0,0,0,0,0,0,0,0,0,0,0,0,0,0,0,81,5,5,5,6,95,0,0,41,0
0,0,0,0,0,0,0,0,0,0,0,0,0,0,0,0,0,0,0,0,0,0,0,0,0,0,81,0,0,41,0,0,0,0,0
0,0,0,0,0,0,0,0,0,0,0,0,66,0,0,0,0,0,0,0,0,66,0,0,0,0,0,0,0,0,0,0,0,0,0
0,0,0,0,0,0,0,0,0,0,0,20,5,5,0,0,0,0,0,0,15,6,37,0,0,0,0,0,0,0,0,0,0,0,0
0,0,0,0,0,0,0,0,0,0,15,54,5,6,44,0,0,0,0,0,0,41,0,0,0,0,0,0,0,0,0,0,0,0,0
0,0,0,0,0,0,0,0,0,0,0,41,41,31,0,0,0,0,0,0,0,0,0,0,0,0,0,0,0,0,0,0,0,0,0
0,0,0,0,0,0,0,0,0,0,0,0,41,0,0,0,0,0,0,0,0,0,0,0,0,0,0,0,0,0,0,0,0,0,0
0,0,0,0,0,0,0,0,0,0,0,0,0,0,0,0,0,0,0,0,0,0,0,0,0,0,0,0,0,0,0,0,0,0,0
0,0,0,0,0,0,0,0,0,0,0,0,0,0,0,0,0,0,0,0,0,0,0,0,0,0,0,0,0,0,0,0,0,0,0
0,0,0,0,0,0,0,0,0,0,0,0,0,0,0,0,0,0,0,0,0,0,0,0,0,0,0,0,0,0,0,0,0,0,0
0,0,0,0,0,0,0,0,0,0,0,0,0,0,0,0,0,0,0,0,0,0,0,0,0,0,0,0,0,0,0,0,0,0,0
0,0,0,0,0,0,0,0,0,0,0,0,0,0,0,0,0,0,0,0,0,0,0,0,0,0,0,0,0,0,0,0,0,0,0
0,0,0,0,0,0,0,0,0,0,0,0,0,0,0,0,0,0,0,0,0,0,0,0,0,0,0,0,0,0,0,0,0,0,0
0,0,0,0,0,0,0,0,0,0,0,0,0,0,0,0,0,0,0,0,0,0,0,0,0,0,0,0,0,0,0,0,0,0,0
0,0,0,0,0,0,0,0,0,0,0,0,0,0,0,0,0,0,0,0,0,0,0,0,0,0,0,0,0,0,0,0,0,0,0
endlayer

layer
0,0,0,0,0,0,0,0,0,0,0,0,0,0,0,0,0,66,6,66,0,0,0,0,0,0,0,0,0,0,0,0,0,0,0
0,0,0,0,0,0,0,0,0,0,0,0,0,0,0,0,55,6,6,6,44,0,0,0,0,0,0,0,0,0,0,0,0,0,0
0,0,0,0,0,0,0,0,0,0,0,0,0,0,0,0,6,6,6,6,6,44,0,0,0,0,0,0,0,0,0,0,0,0,0
0,0,0,0,0,0,0,0,0,0,0,0,0,0,0,0,15,6,6,6,44,0,0,0,0,0,0,0,0,0,0,0,0,0,0
0,0,0,0,0,0,0,0,0,0,0,0,0,0,0,0,0,31,6,41,0,0,0,0,0,0,0,0,0,0,0,0,0,0,0
0,0,0,0,0,0,0,0,0,0,0,0,0,0,0,0,0,0,0,0,0,0,0,0,0,0,0,0,0,0,0,0,0,0,0
0,0,0,0,0,0,0,0,0,0,0,0,0,0,0,0,0,0,0,0,0,0,0,0,0,0,0,0,0,0,0,0,0,0,0
0,0,0,0,0,0,0,0,0,0,0,0,0,0,0,0,0,0,0,0,0,0,0,0,0,0,0,0,0,0,0,0,0,0,0
0,0,0,0,0,0,0,0,0,0,0,0,0,0,0,0,0,0,0,0,0,0,0,0,0,0,0,0,0,0,0,0,0,0,0
0,0,0,0,0,0,0,0,0,0,0,0,0,0,0,0,0,0,0,0,0,0,0,0,0,0,4,6,0,0,0,0,0,6,66
0,0,0,0,0,0,0,0,0,0,0,0,0,0,0,0,0,0,0,0,0,0,0,0,0,20,6,6,6,66,0,0,6,5,6
0,0,0,0,0,0,0,0,0,0,0,0,0,0,0,0,0,0,0,0,0,0,0,0,74,5,5,5,6,6,95,0,0,6,31
0,0,0,0,0,0,0,0,0,0,0,0,0,0,0,0,0,0,0,0,0,0,0,0,0,81,6,5,6,6,95,0,0,41,0
0,0,0,0,0,0,0,0,0,0,0,0,0,0,0,0,0,0,0,0,0,0,0,0,0,0,81,0,0,0,0,0,0,0,0
0,0,0,0,0,0,0,0,0,0,0,0,66,0,0,0,0,0,0,0,0,66,0,0,0,0,0,0,0,0,0,0,0,0,0
0,0,0,0,0,0,0,0,0,0,0,20,5,0,0,0,0,0,0,0,15,6,44,0,0,0,0,0,0,0,0,0,0,0,0
0,0,0,0,0,0,0,0,0,0,15,5,5,6,44,0,0,0,0,0,0,41,0,0,0,0,0,0,0,0,0,0,0,0,0
0,0,0,0,0,0,0,0,0,0,0,41,5,57,0,0,0,0,0,0,0,0,0,0,0,0,0,0,0,0,0,0,0,0,0
0,0,0,0,0,0,0,0,0,0,0,0,41,0,0,0,0,0,0,0,0,0,0,0,0,0,0,0,0,0,0,0,0,0,0
0,0,0,0,0,0,0,0,0,0,0,0,0,0,0,0,0,0,0,0,0,0,0,0,0,0,0,0,0,0,0,0,0,0,0
0,0,0,0,0,0,0,0,0,0,0,0,0,0,0,0,0,0,0,0,0,0,0,0,0,0,0,0,0,0,0,0,0,0,0
0,0,0,0,0,0,0,0,0,0,0,0,0,0,0,0,0,0,0,0,0,0,0,0,0,0,0,0,0,0,0,0,0,0,0
0,0,0,0,0,0,0,0,0,0,0,0,0,0,0,0,0,0,0,0,0,0,0,0,0,0,0,0,0,0,0,0,0,0,0
0,0,0,0,0,0,0,0,0,0,0,0,0,0,0,0,0,0,0,0,0,0,0,0,0,0,0,0,0,0,0,0,0,0,0
0,0,0,0,0,0,0,0,0,0,0,0,0,0,0,0,0,0,0,0,0,0,0,0,0,0,0,0,0,0,0,0,0,0,0
0,0,0,0,0,0,0,0,0,0,0,0,0,0,0,0,0,0,0,0,0,0,0,0,0,0,0,0,0,0,0,0,0,0,0
0,0,0,0,0,0,0,0,0,0,0,0,0,0,0,0,0,0,0,0,0,0,0,0,0,0,0,0,0,0,0,0,0,0,0
endlayer

layer
0,0,0,0,0,0,0,0,0,0,0,0,0,0,0,0,0,66,66,66,0,0,0,0,0,0,0,0,0,0,0,0,0,0,0
0,0,0,0,0,0,0,0,0,0,0,0,0,0,0,0,54,6,6,6,44,0,0,0,0,0,0,0,0,0,0,0,0,0,0
0,0,0,0,0,0,0,0,0,0,0,0,0,0,0,0,15,5,5,6,44,0,0,0,0,0,0,0,0,0,0,0,0,0,0
0,0,0,0,0,0,0,0,0,0,0,0,0,0,0,0,15,5,5,6,44,0,0,0,0,0,0,0,0,0,0,0,0,0,0
0,0,0,0,0,0,0,0,0,0,0,0,0,0,0,0,0,31,0,41,0,0,0,0,0,0,0,0,0,0,0,0,0,0,0
0,0,0,0,0,0,0,0,0,0,0,0,0,0,0,0,0,0,0,0,0,0,0,0,0,0,0,0,0,0,0,0,0,0,0
0,0,0,0,0,0,0,0,0,0,0,0,0,0,0,0,0,0,0,0,0,0,0,0,0,0,0,0,0,0,0,0,0,0,0
0,0,0,0,0,0,0,0,0,0,0,0,0,0,0,0,0,0,0,0,0,0,0,0,0,0,0,0,0,0,0,0,0,0,0
0,0,0,0,0,0,0,0,0,0,0,0,0,0,0,0,0,0,0,0,0,0,0,0,0,0,0,0,0,0,0,0,0,0,0
0,0,0,0,0,0,0,0,0,0,0,0,0,0,0,0,0,0,0,0,0,0,0,0,0,0,0,6,0,0,0,0,0,0,0
0,0,0,0,0,0,0,0,0,0,0,0,0,0,0,0,0,0,0,0,0,0,0,0,0,20,6,6,6,66,0,0,0,6,37
0,0,0,0,0,0,0,0,0,0,0,0,0,0,0,0,0,0,0,0,0,0,0,0,74,5,5,5,6,6,95,0,0,6,44
0,0,0,0,0,0,0,0,0,0,0,0,0,0,0,0,0,0,0,0,0,0,0,0,0,81,5,5,6,81,0,0,0,41,0
0,0,0,0,0,0,0,0,0,0,0,0,0,0,0,0,0,0,0,0,0,0,0,0,0,0,0,5,0,0,0,0,0,0,0
0,0,0,0,0,0,0,0,0,0,0,0,66,0,0,0,0,0,0,0,0,66,0,0,0,0,0,0,0,0,0,0,0,0,0
0,0,0,0,0,0,0,0,0,0,0,20,6,0,0,0,0,0,0,0,15,6,44,0,0,0,0,0,0,0,0,0,0,0,0
0,0,0,0,0,0,0,0,0,0,15,5,5,6,0,0,0,0,0,0,0,41,0,0,0,0,0,0,0,0,0,0,0,0,0
0,0,0,0,0,0,0,0,0,0,0,41,5,41,0,0,0,0,0,0,0,0,0,0,0,0,0,0,0,0,0,0,0,0,0
0,0,0,0,0,0,0,0,0,0,0,0,41,0,0,0,0,0,0,0,0,0,0,0,0,0,0,0,0,0,0,0,0,0,0
0,0,0,0,0,0,0,0,0,0,0,0,0,0,0,0,0,0,0,0,0,0,0,0,0,0,0,0,0,0,0,0,0,0,0
0,0,0,0,0,0,0,0,0,0,0,0,0,0,0,0,0,0,0,0,0,0,0,0,0,0,0,0,0,0,0,0,0,0,0
0,0,0,0,0,0,0,0,0,0,0,0,0,0,0,0,0,0,0,0,0,0,0,0,0,0,0,0,0,0,0,0,0,0,0
0,0,0,0,0,0,0,0,0,0,0,0,0,0,0,0,0,0,0,0,0,0,0,0,0,0,0,0,0,0,0,0,0,0,0
0,0,0,0,0,0,0,0,0,0,0,0,0,0,0,0,0,0,0,0,0,0,0,0,0,0,0,0,0,0,0,0,0,0,0
0,0,0,0,0,0,0,0,0,0,0,0,0,0,0,0,0,0,0,0,0,0,0,0,0,0,0,0,0,0,0,0,0,0,0
0,0,0,0,0,0,0,0,0,0,0,0,0,0,0,0,0,0,0,0,0,0,0,0,0,0,0,0,0,0,0,0,0,0,0
0,0,0,0,0,0,0,0,0,0,0,0,0,0,0,0,0,0,0,0,0,0,0,0,0,0,0,0,0,0,0,0,0,0,0
endlayer

layer
0,0,0,0,0,0,0,0,0,0,0,0,0,0,0,0,0,66,66,66,0,0,0,0,0,0,0,0,0,0,0,0,0,0,0
0,0,0,0,0,0,0,0,0,0,0,0,0,0,0,0,0,0,6,0,44,0,0,0,0,0,0,0,0,0,0,0,0,0,0
0,0,0,0,0,0,0,0,0,0,0,0,0,0,0,0,15,5,6,6,44,0,0,0,0,0,0,0,0,0,0,0,0,0,0
0,0,0,0,0,0,0,0,0,0,0,0,0,0,0,0,0,31,6,0,44,0,0,0,0,0,0,0,0,0,0,0,0,0,0
0,0,0,0,0,0,0,0,0,0,0,0,0,0,0,0,0,0,0,41,0,0,0,0,0,0,0,0,0,0,0,0,0,0,0
0,0,0,0,0,0,0,0,0,0,0,0,0,0,0,0,0,0,0,0,0,0,0,0,0,0,0,0,0,0,0,0,0,0,0
0,0,0,0,0,0,0,0,0,0,0,0,0,0,0,0,0,0,0,0,0,0,0,0,0,0,0,0,0,0,0,0,0,0,0
0,0,0,0,0,0,0,0,0,0,0,0,0,0,0,0,0,0,0,0,0,0,0,0,0,0,0,0,0,0,0,0,0,0,0
0,0,0,0,0,0,0,0,0,0,0,0,0,0,0,0,0,0,0,0,0,0,0,0,0,0,0,0,0,0,0,0,0,0,0
0,0,0,0,0,0,0,0,0,0,0,0,0,0,0,0,0,0,0,0,0,0,0,0,0,0,0,6,0,0,0,0,0,0,0
0,0,0,0,0,0,0,0,0,0,0,0,0,0,0,0,0,0,0,0,0,0,0,0,0,15,5,6,6,66,0,0,0,6,37
0,0,0,0,0,0,0,0,0,0,0,0,0,0,0,0,0,0,0,0,0,0,0,0,74,6,5,6,6,6,95,0,0,0,0
0,0,0,0,0,0,0,0,0,0,0,0,0,0,0,0,0,0,0,0,0,0,0,0,0,81,5,6,6,81,0,0,0,0,0
0,0,0,0,0,0,0,0,0,0,0,0,0,0,0,0,0,0,0,0,0,0,0,0,0,0,31,6,0,0,0,0,0,0,0
0,0,0,0,0,0,0,0,0,0,0,0,0,0,0,0,0,0,0,0,0,66,0,0,0,0,0,0,0,0,0,0,0,0,0
0,0,0,0,0,0,0,0,0,0,0,66,66,0,0,0,0,0,0,0,15,6,44,0,0,0,0,0,0,0,0,0,0,0,0
0,0,0,0,0,0,0,0,0,0,15,5,5,0,0,0,0,0,0,0,0,41,0,0,0,0,0,0,0,0,0,0,0,0,0
0,0,0,0,0,0,0,0,0,0,0,31,5,37,0,0,0,0,0,0,0,0,0,0,0,0,0,0,0,0,0,0,0,0,0
0,0,0,0,0,0,0,0,0,0,0,0,41,0,0,0,0,0,0,0,0,0,0,0,0,0,0,0,0,0,0,0,0,0,0
0,0,0,0,0,0,0,0,0,0,0,0,0,0,0,0,0,0,0,0,0,0,0,0,0,0,0,0,0,0,0,0,0,0,0
0,0,0,0,0,0,0,0,0,0,0,0,0,0,0,0,0,0,0,0,0,0,0,0,0,0,0,0,0,0,0,0,0,0,0
0,0,0,0,0,0,0,0,0,0,0,0,0,0,0,0,0,0,0,0,0,0,0,0,0,0,0,0,0,0,0,0,0,0,0
0,0,0,0,0,0,0,0,0,0,0,0,0,0,0,0,0,0,0,0,0,0,0,0,0,0,0,0,0,0,0,0,0,0,0
0,0,0,0,0,0,0,0,0,0,0,0,0,0,0,0,0,0,0,0,0,0,0,0,0,0,0,0,0,0,0,0,0,0,0
0,0,0,0,0,0,0,0,0,0,0,0,0,0,0,0,0,0,0,0,0,0,0,0,0,0,0,0,0,0,0,0,0,0,0
0,0,0,0,0,0,0,0,0,0,0,0,0,0,0,0,0,0,0,0,0,0,0,0,0,0,0,0,0,0,0,0,0,0,0
0,0,0,0,0,0,0,0,0,0,0,0,0,0,0,0,0,0,0,0,0,0,0,0,0,0,0,0,0,0,0,0,0,0,0
endlayer

layer
0,0,0,0,0,0,0,0,0,0,0,0,0,0,0,0,0,66,66,66,0,0,0,0,0,0,0,0,0,0,0,0,0,0,0
0,0,0,0,0,0,0,0,0,0,0,0,0,0,0,0,0,55,6,0,44,0,0,0,0,0,0,0,0,0,0,0,0,0,0
0,0,0,0,0,0,0,0,0,0,0,0,0,0,0,0,15,6,6,6,44,0,0,0,0,0,0,0,0,0,0,0,0,0,0
0,0,0,0,0,0,0,0,0,0,0,0,0,0,0,0,0,31,6,0,44,0,0,0,0,0,0,0,0,0,0,0,0,0,0
0,0,0,0,0,0,0,0,0,0,0,0,0,0,0,0,0,0,0,41,0,0,0,0,0,0,0,0,0,0,0,0,0,0,0
0,0,0,0,0,0,0,0,0,0,0,0,0,0,0,0,0,0,0,0,0,0,0,0,0,0,0,0,0,0,0,0,0,0,0
0,0,0,0,0,0,0,0,0,0,0,0,0,0,0,0,0,0,0,0,0,0,0,0,0,0,0,0,0,0,0,0,0,0,0
0,0,0,0,0,0,0,0,0,0,0,0,0,0,0,0,0,0,0,0,0,0,0,0,0,0,0,0,0,0,0,0,0,0,0
0,0,0,0,0,0,0,0,0,0,0,0,0,0,0,0,0,0,0,0,0,0,0,0,0,0,0,0,0,0,0,0,0,0,0
0,0,0,0,0,0,0,0,0,0,0,0,0,0,0,0,0,0,0,0,0,0,0,0,0,0,55,0,0,0,0,0,0,0,0
0,0,0,0,0,0,0,0,0,0,0,0,0,0,0,0,0,0,0,0,0,0,0,0,0,15,5,6,6,0,0,0,0,6,37
0,0,0,0,0,0,0,0,0,0,0,0,0,0,0,0,0,0,0,0,0,0,0,0,0,4,5,6,6,6,44,0,0,0,0
0,0,0,0,0,0,0,0,0,0,0,0,0,0,0,0,0,0,0,0,0,0,0,0,0,0,5,6,6,41,0,0,0,0,0
0,0,0,0,0,0,0,0,0,0,0,0,0,0,0,0,0,0,0,0,0,0,0,0,0,0,0,6,0,0,0,0,0,0,0
0,0,0,0,0,0,0,0,0,0,0,0,0,0,0,0,0,0,0,0,0,66,0,0,0,0,0,0,0,0,0,0,0,0,0
0,0,0,0,0,0,0,0,0,0,0,66,66,0,0,0,0,0,0,0,15,6,44,0,0,0,0,0,0,0,0,0,0,0,0
0,0,0,0,0,0,0,0,0,0,15,5,5,0,0,0,0,0,0,0,0,41,0,0,0,0,0,0,0,0,0,0,0,0,0
0,0,0,0,0,0,0,0,0,0,0,5,5,44,0,0,0,0,0,0,0,0,0,0,0,0,0,0,0,0,0,0,0,0,0
0,0,0,0,0,0,0,0,0,0,0,0,41,0,0,0,0,0,0,0,0,0,0,0,0,0,0,0,0,0,0,0,0,0,0
0,0,0,0,0,0,0,0,0,0,0,0,0,0,0,0,0,0,0,0,0,0,0,0,0,0,0,0,0,0,0,0,0,0,0
0,0,0,0,0,0,0,0,0,0,0,0,0,0,0,0,0,0,0,0,0,0,0,0,0,0,0,0,0,0,0,0,0,0,0
0,0,0,0,0,0,0,0,0,0,0,0,0,0,0,0,0,0,0,0,0,0,0,0,0,0,0,0,0,0,0,0,0,0,0
0,0,0,0,0,0,0,0,0,0,0,0,0,0,0,0,0,0,0,0,0,0,0,0,0,0,0,0,0,0,0,0,0,0,0
0,0,0,0,0,0,0,0,0,0,0,0,0,0,0,0,0,0,0,0,0,0,0,0,0,0,0,0,0,0,0,0,0,0,0
0,0,0,0,0,0,0,0,0,0,0,0,0,0,0,0,0,0,0,0,0,0,0,0,0,0,0,0,0,0,0,0,0,0,0
0,0,0,0,0,0,0,0,0,0,0,0,0,0,0,0,0,0,0,0,0,0,0,0,0,0,0,0,0,0,0,0,0,0,0
0,0,0,0,0,0,0,0,0,0,0,0,0,0,0,0,0,0,0,0,0,0,0,0,0,0,0,0,0,0,0,0,0,0,0
endlayer

layer
0,0,0,0,0,0,0,0,0,0,0,0,0,0,0,0,0,66,66,66,0,0,0,0,0,0,0,0,0,0,0,0,0,0,0
0,0,0,0,0,0,0,0,0,0,0,0,0,0,0,0,0,55,0,0,44,0,0,0,0,0,0,0,0,0,0,0,0,0,0
0,0,0,0,0,0,0,0,0,0,0,0,0,0,0,0,15,5,5,5,44,0,0,0,0,0,0,0,0,0,0,0,0,0,0
0,0,0,0,0,0,0,0,0,0,0,0,0,0,0,0,0,31,6,0,44,0,0,0,0,0,0,0,0,0,0,0,0,0,0
0,0,0,0,0,0,0,0,0,0,0,0,0,0,0,0,0,0,0,41,0,0,0,0,0,0,0,0,0,0,0,0,0,0,0
