
# Created by Ruins mod version 14.6 Ingame Parser
# authoring Player: ArchNihil

weight=1
embed_into_distance=0
acceptable_target_blocks=
unacceptable_target_blocks=flowing_water,water,flowing_lava,lava
dimensions=18,16,16
allowable_overhang=0
max_leveling=2
leveling_buffer=0
preserve_water=0
preserve_lava=0

rule1=0,100,Railcraft:tile.railcraft.residual.heat-0
rule2=0,100,minecraft:stonebrick-2
rule3=0,100,minecraft:stonebrick-0
rule4=0,100,minecraft:cobblestone-0
rule5=0,100,minecraft:web-0
rule6=0,100,ForgeMultipart:block-0
rule7=0,100,minecraft:monster_egg-2
rule8=0,100,minecraft:vine-4
rule9=0,100,minecraft:vine-2
rule10=0,100,minecraft:vine-1
rule11=0,100,minecraft:iron_bars-0
rule12=0,100,minecraft:vine-6
rule13=0,100,minecraft:monster_egg-4
rule14=0,100,minecraft:vine-9
rule15=0,100,minecraft:vine-8
rule16=0,100,minecraft:monster_egg-1
rule17=0,100,minecraft:monster_egg-3

layer
0,0,1,0,0,0,0,1,1,2,0,0,1,1,0,0
1,1,0,0,0,0,0,1,1,0,0,0,1,0,0,1
0,0,0,0,0,0,0,2,0,0,2,2,0,0,0,0
1,0,0,4,3,0,0,3,1,0,0,0,3,0,1,1
0,0,2,0,2,0,0,1,1,0,0,0,0,2,0,0
0,0,2,0,0,0,0,1,1,1,0,0,0,3,0,0
0,2,0,0,1,1,0,1,1,1,1,1,0,5,3,0
0,4,5,0,0,1,0,0,0,0,1,0,0,5,2,0
0,0,0,1,1,1,0,0,0,0,1,0,0,0,2,0
0,4,0,0,1,1,1,0,1,1,1,0,0,0,0,0
0,0,2,0,0,0,0,0,1,1,0,0,0,0,0,0
0,0,2,0,0,0,1,1,1,0,0,0,5,0,0,0
0,0,0,2,0,0,0,1,1,0,0,5,2,0,1,0
0,0,0,0,2,2,0,0,0,0,4,2,0,1,0,1
0,0,1,0,1,0,2,2,2,3,0,0,1,0,1,1
0,0,0,0,0,0,1,0,0,0,0,1,1,0,0,0
endlayer

layer
0,0,1,0,0,0,0,0,0,0,0,0,0,0,0,0
0,0,0,0,0,0,0,0,0,0,0,0,0,0,0,0
0,0,0,0,0,0,0,0,0,0,0,0,0,0,0,0
0,0,0,0,0,0,3,1,0,0,3,3,0,0,0,0
0,0,0,7,0,0,0,0,0,0,0,0,3,6,0,0
0,0,0,0,0,0,0,1,0,0,0,0,3,6,0,0
0,0,3,0,1,1,0,1,0,0,0,0,0,3,0,0
0,0,7,0,0,1,0,0,0,0,0,0,0,3,0,0
0,0,0,0,0,0,0,0,0,0,0,0,0,3,0,1
0,0,3,0,0,0,0,0,1,0,0,0,0,4,0,0
0,0,0,3,0,0,0,0,0,0,0,0,3,0,0,0
0,0,8,3,0,0,0,0,0,0,0,0,3,0,0,0
0,0,0,3,3,3,0,0,0,0,3,3,0,0,0,0
0,0,0,0,0,0,3,3,3,3,0,0,0,0,0,0
0,1,0,0,0,0,0,9,9,0,0,0,0,0,0,0
0,1,0,0,0,0,0,0,0,0,0,0,0,0,0,0
endlayer

layer
0,0,0,0,0,0,0,0,0,0,0,0,0,0,0,0
0,0,0,0,0,0,0,0,0,0,0,0,0,0,0,0
0,0,0,0,0,0,0,0,0,0,0,0,0,0,0,0
0,0,0,0,0,0,0,0,0,0,0,3,0,0,0,0
0,0,0,0,0,0,0,0,0,0,0,0,3,0,0,0
0,0,0,3,0,0,0,0,0,0,0,0,3,0,0,0
0,0,3,1,0,1,0,0,0,0,0,0,0,3,0,0
0,0,0,0,1,1,0,0,0,0,0,0,0,3,0,0
0,0,0,0,0,0,0,0,0,0,0,0,0,3,0,0
0,0,3,0,0,0,0,0,0,0,1,0,0,4,0,0
0,0,0,3,0,0,0,0,0,0,0,0,3,0,0,0
0,0,8,3,0,0,0,0,0,0,0,0,3,0,0,0
0,0,0,0,3,3,0,0,0,0,3,3,0,0,0,0
1,0,0,0,0,0,3,3,3,3,0,9,0,0,0,0
0,0,0,0,0,0,0,9,0,0,0,0,0,0,0,0
0,0,0,0,0,0,0,0,0,0,0,0,0,0,0,0
endlayer

layer
0,0,1,0,0,0,0,1,0,0,0,0,0,0,0,0
0,0,0,0,0,0,0,0,0,0,0,0,0,0,0,0
0,0,0,0,0,0,0,0,0,0,0,0,0,0,0,0
0,0,0,0,0,0,0,0,0,0,0,3,0,0,0,0
0,1,0,0,0,0,0,0,0,0,1,0,3,0,0,0
0,0,0,0,0,0,0,1,0,0,0,0,3,0,0,0
0,0,0,0,0,1,0,0,0,1,0,0,0,3,0,0
0,0,0,0,0,0,0,0,0,0,0,0,0,3,10,0
0,0,0,0,0,0,0,0,0,0,0,0,0,3,0,0
0,0,3,0,0,0,0,0,0,0,1,0,0,0,0,0
0,0,0,3,0,0,0,1,0,0,0,0,3,0,0,0
0,0,0,3,5,0,0,0,1,0,0,0,3,0,0,0
0,0,0,0,0,3,5,0,0,0,3,3,10,0,0,0
0,0,0,0,0,0,3,3,3,0,0,9,0,0,0,0
0,0,0,0,0,0,0,9,0,0,0,0,0,0,0,0
0,0,0,0,0,0,0,0,0,0,0,0,0,0,0,0
endlayer

layer
0,0,0,0,0,0,0,0,0,0,0,0,0,0,0,0
0,0,0,0,0,0,0,0,0,0,0,0,0,0,0,0
0,0,0,0,0,0,0,0,0,0,0,0,0,0,0,0
0,0,0,0,0,0,0,0,0,0,0,0,0,0,0,0
0,0,0,0,0,0,0,0,0,0,0,3,0,0,0,0
0,0,0,0,0,0,0,1,0,0,0,0,0,0,0,0
0,0,0,0,0,0,0,0,1,1,0,0,3,0,0,0
0,0,0,2,1,1,1,0,0,0,0,0,3,0,0,0
0,0,0,0,0,0,0,0,0,0,0,0,3,0,0,0
0,0,0,3,0,0,0,0,0,0,0,0,3,0,0,0
0,0,0,0,3,0,0,0,0,0,0,3,0,0,0,0
0,0,0,8,3,7,0,0,1,2,3,3,0,0,0,0
0,0,0,0,0,0,3,3,3,3,0,0,0,0,0,0
0,0,0,0,0,0,0,0,0,0,0,0,0,0,1,0
0,0,0,0,0,0,0,0,0,0,0,0,0,0,0,0
0,0,0,0,0,0,0,0,0,0,0,0,0,0,0,0
endlayer

layer
0,0,0,0,0,0,0,0,0,0,0,0,0,0,0,0
0,0,0,0,0,0,0,0,0,0,0,0,0,0,0,0
0,0,0,0,0,0,0,0,0,0,0,0,0,0,0,0
0,0,0,0,0,0,0,0,0,0,0,0,0,0,0,0
0,0,0,0,0,0,0,0,0,0,0,3,10,0,0,0
0,0,0,0,0,0,0,1,1,1,0,3,0,0,0,0
0,0,0,2,0,0,0,0,0,0,0,0,3,0,0,0
0,0,0,11,0,0,1,0,0,0,1,0,11,0,0,0
0,0,0,11,0,0,1,1,0,1,0,0,11,0,0,0
0,0,0,3,0,0,0,1,0,0,0,2,3,0,0,0
0,0,0,12,3,0,0,0,0,0,0,3,0,0,0,0
0,0,0,8,3,0,0,0,0,3,3,4,0,0,0,0
0,0,0,0,0,0,3,11,11,3,0,0,0,0,0,0
0,0,0,0,0,0,0,0,0,0,0,0,1,0,1,0
0,0,0,0,0,0,0,0,0,0,0,0,0,0,0,0
0,0,0,0,0,0,0,0,0,0,0,0,0,0,0,0
endlayer

layer
0,0,0,0,0,0,0,0,0,0,0,0,0,0,0,0
0,0,0,0,0,0,0,0,0,0,0,0,0,0,0,0
0,0,1,0,0,0,0,0,0,0,0,0,0,0,0,0
0,0,0,0,0,0,0,0,0,0,0,0,0,0,0,0
0,0,0,0,0,0,0,0,0,0,0,3,10,0,0,0
0,0,0,0,0,1,0,0,0,0,0,3,0,0,0,0
0,0,8,3,0,0,0,1,1,0,0,2,3,10,0,0
0,0,0,11,1,1,1,0,0,0,1,0,11,0,0,0
0,0,0,0,0,0,1,1,0,1,0,0,11,0,0,0
0,0,0,2,0,0,0,0,0,1,0,3,3,0,0,0
0,0,0,0,3,0,0,1,0,0,0,3,0,0,0,0
0,0,0,0,13,0,2,0,0,2,3,4,0,0,0,0
0,0,0,0,0,0,3,11,11,3,0,0,0,0,0,0
0,0,0,0,0,0,0,0,0,0,0,0,0,0,0,0
0,0,0,0,0,0,0,0,0,0,0,0,0,0,0,0
0,0,0,0,0,0,0,0,0,0,0,0,0,0,0,0
endlayer

layer
0,0,0,0,0,0,0,0,0,0,0,0,0,0,0,0
0,0,0,0,0,0,0,0,0,0,0,0,0,0,0,0
0,0,0,0,0,0,0,0,0,0,0,0,0,0,0,0
0,0,0,0,0,0,0,0,0,0,0,0,0,0,0,0
1,0,0,0,0,0,0,0,0,0,3,3,0,0,0,0
0,0,0,0,0,0,0,1,0,0,0,3,0,0,0,0
1,0,0,3,0,0,0,0,0,0,0,3,3,0,0,0
0,0,0,11,0,1,0,0,0,0,0,0,11,0,0,0
1,0,0,0,0,1,0,0,0,0,1,5,11,0,0,0
0,0,0,2,2,0,0,1,1,0,1,2,3,0,0,0
0,0,0,0,3,0,0,1,0,2,5,3,0,0,0,0
0,0,0,0,13,3,7,0,0,3,4,4,0,0,0,0
0,0,0,0,0,0,3,11,11,3,0,0,0,0,0,0
0,0,0,0,0,0,0,0,0,0,0,0,0,0,0,0
0,0,0,0,0,0,0,0,0,0,0,0,0,0,0,0
0,1,0,0,0,0,0,0,0,0,0,0,0,0,0,0
endlayer

layer
0,0,0,0,0,0,0,0,0,0,0,0,0,0,0,0
0,0,0,0,0,0,0,0,0,0,0,0,0,0,0,0
0,0,0,0,0,0,0,0,0,0,0,0,0,0,0,0
0,0,0,0,0,0,0,0,0,3,0,0,14,0,0,0
1,0,0,0,0,0,0,0,0,0,3,3,0,0,0,0
0,0,0,0,0,0,0,0,0,0,0,3,0,0,0,0
0,0,0,3,0,0,0,0,0,0,3,2,3,0,0,0
0,0,0,2,0,0,0,0,0,0,3,0,3,0,0,0
0,0,0,3,0,0,0,0,0,2,0,2,3,0,0,0
0,0,0,2,3,0,0,0,0,3,1,2,3,0,0,0
0,0,0,0,3,0,0,0,0,0,3,3,0,0,0,0
0,0,0,0,0,0,0,0,0,0,0,3,0,0,0,0
0,0,0,0,0,0,0,0,0,3,0,0,0,0,0,0
0,0,0,0,0,0,0,0,0,0,0,0,0,0,0,0
0,0,0,0,0,0,0,0,0,0,0,0,0,0,0,0
0,0,0,0,0,0,0,0,0,0,0,0,0,0,0,0
endlayer

layer
0,0,0,0,0,0,0,0,0,0,0,0,0,0,0,0
0,0,0,0,0,0,0,0,0,0,0,0,0,0,0,0
0,0,0,0,0,0,0,0,0,2,0,0,0,0,0,0
0,0,0,0,0,0,0,0,1,0,4,4,14,0,0,0
0,0,0,2,0,0,1,1,1,0,0,0,3,10,0,0
0,0,0,3,0,0,0,0,1,0,0,0,7,0,0,0
0,0,3,0,0,1,1,0,0,1,1,1,0,3,0,0
0,0,3,0,1,1,0,0,0,1,1,1,0,3,0,0
0,0,3,0,1,0,1,0,0,0,1,1,0,3,0,0
0,8,3,5,1,1,1,0,1,1,1,0,0,3,0,0
0,0,0,7,1,1,1,0,1,1,0,0,3,10,0,0
0,0,8,7,0,1,1,1,0,1,1,0,4,10,0,0
0,0,0,0,0,0,1,0,0,1,0,3,0,0,0,0
0,0,0,0,0,0,0,0,0,0,0,0,0,0,0,0
0,0,0,0,0,0,0,0,0,0,0,0,0,0,0,0
0,0,0,0,0,0,0,0,0,0,0,0,0,0,0,0
endlayer

layer
0,0,0,0,0,0,0,0,0,0,0,0,0,1,0,0
0,0,0,0,0,0,0,0,0,0,0,0,0,0,0,0
0,0,0,0,0,0,0,1,0,0,0,0,0,0,0,0
1,0,0,0,0,0,0,0,0,0,0,4,15,0,0,0
0,0,0,2,0,0,0,0,0,0,0,5,3,10,0,0
0,0,0,2,0,0,0,1,0,0,0,0,3,0,0,0
0,0,7,0,0,1,1,0,0,0,0,0,0,3,0,0
0,0,0,0,0,0,0,0,0,0,0,0,0,0,0,0
0,0,2,0,0,0,0,0,0,1,0,0,0,16,0,0
0,8,3,0,0,0,0,1,0,0,1,0,0,0,0,0
0,0,0,3,0,0,0,0,1,0,0,0,3,10,0,0
0,0,8,3,0,1,0,0,0,1,0,0,3,10,0,0
0,0,0,0,3,0,0,0,0,0,0,3,0,0,0,0
0,1,0,0,0,0,0,0,0,0,0,0,0,0,0,0
0,0,0,0,0,0,0,0,0,0,0,0,0,0,0,0
0,0,0,0,0,0,0,0,0,0,0,0,0,0,0,0
endlayer

layer
0,0,0,0,0,0,0,0,0,0,1,0,0,0,0,0
0,0,0,0,0,0,0,0,0,0,0,0,0,0,0,0
0,0,0,0,15,0,0,0,0,0,0,0,0,0,0,0
0,0,0,0,3,0,0,0,0,0,0,2,0,0,0,0
0,0,0,2,0,0,0,0,1,0,0,0,3,0,0,0
0,0,0,0,0,0,0,0,0,0,0,0,3,0,0,0
0,0,3,0,0,0,0,0,0,0,0,0,0,4,0,0
0,0,7,0,0,0,0,1,0,0,0,0,0,7,0,0
0,8,2,0,0,0,0,0,0,0,0,0,0,17,0,0
0,8,3,0,0,0,0,0,0,0,0,0,0,3,0,0
0,0,0,0,0,1,0,1,0,0,0,0,3,0,0,0
0,0,0,3,0,0,0,0,0,0,0,0,3,0,0,0
0,0,0,0,3,0,0,0,0,0,0,0,0,0,0,0
0,0,0,0,0,0,0,0,0,0,0,0,0,0,0,0
0,0,0,0,0,0,0,0,0,0,0,0,0,0,0,0
0,0,0,0,0,0,0,0,0,0,0,0,0,0,0,0
endlayer

layer
0,0,0,0,0,0,0,0,0,0,0,0,0,0,0,0
0,0,0,0,0,0,0,0,0,0,1,0,0,0,0,0
0,0,0,0,0,0,0,0,0,0,0,0,0,0,0,0
1,0,0,0,3,0,0,0,0,0,0,2,0,0,0,0
0,0,0,2,0,0,0,1,0,0,0,5,3,0,0,0
0,0,0,0,0,0,0,0,0,0,0,0,0,0,0,0
0,0,3,0,1,0,0,0,0,0,0,0,0,2,0,0
0,0,0,0,1,0,0,0,0,0,1,0,0,0,0,0
0,0,0,0,0,0,0,0,0,0,1,0,0,0,0,0
0,0,2,0,0,0,0,0,0,0,0,0,0,0,0,0
0,1,0,0,0,0,0,0,0,0,0,0,0,0,0,0
0,0,0,3,0,0,0,0,0,0,0,0,2,0,0,0
0,0,0,0,2,0,0,0,0,0,0,0,0,0,1,0
0,0,0,0,0,0,0,0,0,0,0,0,0,0,0,0
0,0,0,0,0,0,0,0,0,0,0,0,0,0,0,0
0,0,0,0,0,0,0,0,0,0,0,0,0,0,0,0
endlayer

layer
0,0,0,0,0,0,0,0,1,0,1,0,0,0,0,0
0,0,0,0,0,0,0,0,0,0,0,0,0,0,1,0
0,0,0,0,0,0,0,0,0,0,0,0,0,0,0,0
0,0,0,0,0,0,0,0,0,0,0,0,0,0,0,0
0,0,0,0,0,0,0,0,0,0,0,0,0,0,0,0
0,0,0,0,0,0,0,0,0,0,0,0,0,0,0,0
0,0,0,0,0,0,0,0,0,0,1,0,0,0,0,0
0,0,0,0,0,0,0,0,0,0,0,0,0,0,0,0
0,0,0,0,0,0,0,0,0,0,0,0,0,0,0,0
0,0,0,0,0,0,0,0,0,0,0,0,0,0,0,0
0,0,0,0,0,0,0,0,0,0,0,0,0,0,0,0
0,0,0,0,0,0,1,0,0,0,0,0,0,0,0,0
0,0,0,0,0,0,0,0,0,0,0,0,0,0,0,0
0,0,0,0,0,0,0,0,0,0,0,0,0,0,0,0
0,0,0,0,0,0,0,0,0,0,0,0,0,1,0,0
0,0,0,0,0,1,0,0,0,0,1,0,0,0,0,0
endlayer

layer
0,0,0,0,0,0,0,0,0,0,0,0,0,0,0,0
0,0,0,0,0,0,0,0,0,0,0,0,0,0,0,0
0,0,0,0,0,0,0,0,0,0,0,0,0,0,0,0
0,0,0,0,0,0,0,0,0,0,0,0,0,0,0,0
0,0,0,0,0,0,0,0,0,0,0,0,0,0,0,0
0,0,0,0,0,0,0,0,0,0,0,0,0,0,0,0
0,0,0,0,0,0,0,0,0,0,0,0,0,0,0,0
0,0,0,0,0,0,0,0,0,0,0,0,0,0,0,0
0,0,0,0,0,0,0,0,0,0,0,0,0,0,0,0
0,0,0,0,0,0,1,0,0,0,0,0,0,0,0,0
0,0,0,0,0,0,0,0,0,0,0,0,0,0,0,0
0,0,0,0,0,0,0,0,0,0,0,0,0,0,0,0
0,0,0,0,0,0,0,0,0,0,0,0,0,0,0,0
0,0,0,0,0,0,0,0,0,0,0,0,0,0,0,0
0,0,0,0,0,0,0,0,0,0,0,0,0,0,0,0
0,0,0,0,0,0,0,0,0,0,0,0,0,0,0,0
endlayer

layer
0,0,0,0,0,0,0,0,0,0,0,0,0,0,0,0
0,0,0,0,0,0,0,0,0,0,0,0,0,0,0,0
0,0,0,0,0,0,0,0,0,0,0,0,0,0,0,0
0,0,0,0,0,0,0,0,0,0,0,0,0,0,0,0
0,0,0,0,0,0,0,0,0,0,0,0,0,0,0,0
0,0,0,0,0,0,0,0,0,0,0,0,0,0,0,0
0,0,0,1,0,0,0,0,0,0,0,0,0,0,0,0
0,0,0,0,0,0,0,0,0,0,0,0,0,0,0,0
0,0,0,0,0,0,0,0,0,0,0,0,0,0,0,0
0,0,0,0,0,0,0,0,0,0,0,0,0,0,0,0
0,0,0,0,0,0,0,0,0,0,0,0,0,0,0,0
0,0,0,0,0,0,0,0,0,0,0,0,0,0,0,0
0,0,0,0,0,0,0,0,0,0,0,0,0,0,0,0
0,0,0,0,0,0,0,0,0,0,0,0,0,0,0,0
0,0,0,0,0,0,0,0,0,0,0,0,0,0,0,0
0,0,0,0,0,0,0,0,0,0,0,0,0,0,0,0
endlayer

layer
0,0,0,0,0,0,0,0,0,0,0,0,0,0,0,0
0,0,0,0,0,0,0,0,0,0,0,0,0,0,0,0
0,0,0,0,0,0,0,0,0,0,0,0,0,0,0,0
0,0,0,0,0,0,0,0,0,0,0,0,0,0,0,0
0,0,0,0,0,0,0,0,0,0,0,0,0,0,0,0
0,0,0,0,0,0,0,0,0,0,0,0,0,0,0,0
0,0,0,0,0,0,0,0,0,0,0,0,0,0,0,0
0,0,0,0,0,0,0,0,0,0,0,0,0,0,0,0
0,0,0,0,0,0,0,0,0,0,0,0,0,0,0,0
0,0,0,0,0,0,0,0,0,0,0,0,0,0,0,0
0,0,0,0,0,0,0,0,0,0,0,0,0,0,0,0
0,0,0,0,0,0,0,0,0,0,0,0,0,0,0,0
0,0,0,0,0,0,0,0,0,0,0,0,0,0,0,0
0,0,0,0,0,0,0,0,0,0,0,0,0,0,0,0
0,0,0,0,0,0,0,0,0,0,0,0,0,0,0,0
0,0,0,0,0,0,0,0,0,0,0,0,0,0,0,0
endlayer

layer
0,0,0,0,0,0,0,0,0,0,0,0,0,0,0,0
0,0,0,0,0,0,0,0,0,0,0,0,0,0,0,0
0,0,0,0,0,0,0,0,0,0,0,0,0,0,0,0
0,0,0,0,0,0,0,0,0,0,0,0,0,0,0,0
0,0,0,0,0,0,0,0,0,0,0,0,0,0,0,0
0,0,0,0,0,0,0,0,0,0,0,0,0,0,0,0
0,0,0,0,0,0,0,0,0,0,0,0,0,0,0,0
0,0,0,0,1,1,0,0,0,0,0,0,0,0,0,0
0,0,0,0,0,0,0,0,0,0,0,0,0,0,0,0
0,0,0,0,0,0,0,0,0,0,0,0,0,0,0,0
0,0,0,0,0,0,0,0,0,0,0,0,0,0,0,0
0,0,0,0,0,0,0,0,0,0,0,0,0,0,0,0
0,0,0,0,0,0,0,0,0,0,0,0,0,0,0,0
0,0,0,0,0,0,0,0,0,0,0,0,0,0,0,0
0,0,0,0,0,0,0,0,0,0,0,0,0,0,0,0
0,0,0,0,0,0,0,0,0,0,0,0,0,0,0,0
endlayer

