
# Created by Ruins mod version 14.6 Ingame Parser
# authoring Player: ArchNihil

weight=1
embed_into_distance=0
acceptable_target_blocks=
unacceptable_target_blocks=flowing_water,water,flowing_lava,lava
dimensions=169,31,39
allowable_overhang=0
max_leveling=2
leveling_buffer=0
preserve_water=0
preserve_lava=0

rule1=0,100,Railcraft:tile.railcraft.residual.heat-0
rule2=0,100,UndergroundBiomes:igneousStone-7
rule3=0,100,TwilightForest:tile.TFFirefly-5
rule4=0,100,minecraft:leaves-5
rule5=0,100,minecraft:leaves-13
rule6=0,100,minecraft:log-0
rule7=0,100,BiomesOPlenty:planks-9
rule8=0,100,ExtraUtilities:colorWoodPlanks-13
rule9=0,100,minecraft:vine-4
rule10=0,100,ExtraUtilities:colorWoodPlanks-5
rule11=0,100,BiomesOPlenty:logs1-5
rule12=0,100,BiomesOPlenty:logs1-9
rule13=0,100,BiomesOPlenty:logs1-1
rule14=0,100,minecraft:log-4
rule15=0,100,minecraft:grass-0
rule16=0,100,minecraft:vine-12
rule17=0,100,BiomesOPlenty:planks-1
rule18=0,100,minecraft:water-2
rule19=0,100,minecraft:water-3
rule20=0,100,minecraft:log-8
rule21=0,100,minecraft:leaves-12
rule22=0,100,minecraft:water-1
rule23=0,100,minecraft:water-0
rule24=0,100,minecraft:dirt-0
rule25=0,100,BiomesOPlenty:logs3-1
rule26=0,100,BiomesOPlenty:cherryStairs-3
rule27=0,100,minecraft:wooden_door-3
rule28=0,100,BiomesOPlenty:cherryStairs-2
rule29=0,100,BiomesOPlenty:woodenDoubleSlab1-1
rule30=0,100,minecraft:leaves-6
rule31=0,100,TwilightForest:tile.TFPlant-3
rule32=0,100,BiomesOPlenty:moss-0
rule33=0,100,minecraft:fence-0
rule34=0,100,BiomesOPlenty:moss-8
rule35=0,100,BiomesOPlenty:moss-11
rule36=0,100,minecraft:wooden_door-1
rule37=0,100,minecraft:wooden_door-8
rule38=0,100,minecraft:vine-1
rule39=0,100,minecraft:vine-2
rule40=0,100,minecraft:wooden_door-2
rule41=0,100,TwilightForest:tile.TFFirefly-1
rule42=0,100,minecraft:vine-0
rule43=0,100,minecraft:vine-9
rule44=0,100,Natura:BerryBush-8
rule45=0,100,minecraft:vine-8
rule46=0,100,BiomesOPlenty:moss-2
rule47=0,100,BiomesOPlenty:moss-10
rule48=0,100,TConstruct:GlassBlock-0
rule49=0,100,minecraft:leaves-0
rule50=0,100,BiomesOPlenty:flowerVine-1
rule51=0,100,BiomesOPlenty:flowerVine-9
rule52=0,100,TwilightForest:tile.TFFirefly-3
rule53=0,100,TwilightForest:tile.TFFirefly-4
rule54=0,100,TwilightForest:tile.TFFirefly-2
rule55=0,100,minecraft:tallgrass-1
rule56=0,100,Natura:BerryBush-9
rule57=0,100,Natura:BerryBush-0
rule58=0,100,Natura:BerryBush-14
rule59=0,100,BiomesOPlenty:moss-1
rule60=0,100,BiomesOPlenty:logs3-9
rule61=0,100,BiomesOPlenty:logs3-5
rule62=0,100,BiomesOPlenty:flowerVine-2
rule63=0,100,TwilightForest:tile.TFFirefly-6
rule64=0,100,BiomesOPlenty:flowerVine-8
rule65=0,100,minecraft:vine-6
rule66=0,100,minecraft:vine-3
rule67=0,100,minecraft:planks-0
rule68=0,100,BiomesOPlenty:flowerVine-5
rule69=0,100,minecraft:brown_mushroom-0
rule70=0,100,minecraft:vine-7
rule71=0,100,Natura:Thornvines-4
rule72=0,100,Natura:Thornvines-3
rule73=0,100,Natura:Thornvines-2
rule74=0,100,BiomesOPlenty:cherryStairs-1
rule75=0,100,BiomesOPlenty:flowerVine-4
rule76=0,100,BiomesOPlenty:flowerVine-12
rule77=0,100,BiomesOPlenty:flowerVine-11
rule78=0,100,BiomesOPlenty:woodenSingleSlab1-1
rule79=0,100,minecraft:vine-14
rule80=0,100,minecraft:leaves-4
rule81=0,100,TwilightForest:tile.TFPlant-9
rule82=0,100,BiomesOPlenty:flowerVine-10
rule83=0,100,BiomesOPlenty:flowers2-4
rule84=0,100,minecraft:yellow_flower-0
rule85=0,100,BiomesOPlenty:moss-14
rule86=0,100,minecraft:vine-11
rule87=0,100,Natura:Thornvines-1
rule88=0,100,BiomesOPlenty:flowerVine-6
rule89=0,100,minecraft:double_plant-2
rule90=0,100,BiomesOPlenty:cherryStairs-0
rule91=0,100,BiomesOPlenty:moss-4
rule92=0,100,minecraft:vine-15
rule93=0,100,minecraft:double_plant-8
rule94=0,100,minecraft:vine-5
rule95=0,100,Natura:Thornvines-6
rule96=0,100,Natura:Thornvines-0
rule97=0,100,BiomesOPlenty:colorizedLeaves2-0
rule98=0,100,BiomesOPlenty:moss-3
rule99=0,100,Natura:Thornvines-8
rule100=0,100,minecraft:tripwire-0
rule101=0,100,minecraft:bed-3
rule102=0,100,minecraft:bed-11
rule103=0,100,minecraft:farmland-7
rule104=0,100,minecraft:vine-10
rule105=0,100,Natura:Thornvines-12
rule106=0,100,minecraft:leaves-14
rule107=0,100,Natura:Cloud-0

layer
0,0,0,0,0,0,0,0,0,0,0,0,0,0,0,0,0,0,0,0,1,0,0,0,0,1,0,0,0,0,0,0,0,0,0,0,0,0,0
0,0,0,0,0,0,0,0,0,0,0,0,0,1,0,0,0,0,0,0,0,0,0,0,0,0,0,0,0,0,0,1,0,0,0,0,0,0,0
0,0,0,0,0,0,0,0,0,0,0,0,0,0,0,0,0,0,0,0,0,0,0,0,0,0,0,0,0,2,0,0,0,0,0,0,0,0,0
0,0,0,0,0,1,0,0,1,1,0,0,0,0,0,1,1,1,0,1,1,0,0,0,0,0,0,0,0,0,0,0,0,1,0,0,0,0,0
0,0,0,0,0,1,0,1,0,0,1,0,1,0,1,0,1,0,0,0,0,1,0,1,1,0,0,0,0,1,1,0,3,0,0,0,0,0,0
0,0,0,0,0,0,0,0,0,0,0,0,0,0,1,0,0,4,1,1,1,1,0,0,0,0,0,1,0,0,0,0,3,0,1,0,0,0,0
0,0,1,0,0,0,5,4,5,0,0,0,1,0,1,0,4,4,4,0,1,0,1,3,0,1,0,1,0,0,0,0,1,0,0,0,0,1,0
0,0,1,1,0,5,5,4,5,5,5,5,5,4,4,4,5,4,4,4,4,0,0,4,4,4,4,4,4,1,0,0,0,0,0,0,0,0,0
0,0,1,1,1,4,4,4,4,4,5,5,4,4,4,4,5,5,4,4,4,4,4,4,4,4,4,4,4,4,0,1,0,0,0,0,0,0,0
0,0,1,0,4,4,4,4,4,4,4,4,4,4,4,3,4,4,4,4,4,4,4,4,4,4,4,4,4,4,4,4,0,1,1,0,0,0,0
0,0,1,9,4,4,6,8,8,8,6,8,8,7,7,6,5,5,5,4,4,4,4,4,4,4,4,4,4,4,4,4,4,1,1,0,0,0,0
0,0,0,0,4,4,10,13,12,12,13,12,12,12,11,10,6,5,5,5,5,5,5,5,5,4,5,5,4,4,4,4,5,4,1,1,0,0,0
0,0,0,16,0,4,10,11,0,0,0,0,0,0,11,10,14,6,15,6,14,5,5,5,5,4,3,5,5,5,5,4,5,5,1,1,0,0,0
0,0,9,17,21,15,10,11,0,0,3,0,0,0,11,10,6,20,20,18,19,18,17,17,17,17,5,5,5,5,5,4,4,4,0,0,0,0,0
0,17,17,17,14,24,10,11,0,0,0,0,0,0,11,7,22,23,23,22,18,22,18,17,13,17,0,5,5,5,5,5,4,4,0,0,0,0,0
17,17,17,17,17,17,17,13,0,0,13,0,0,0,13,25,6,6,20,20,22,23,22,17,13,17,6,5,5,5,5,5,4,4,0,0,0,1,0
17,17,17,17,0,0,0,12,0,0,0,0,0,0,12,13,12,12,12,20,6,20,20,17,13,17,5,5,5,0,3,5,4,4,1,1,1,0,0
17,17,17,28,0,0,0,0,0,0,3,0,0,0,27,0,0,0,0,26,17,17,17,17,13,17,5,5,5,5,5,5,4,4,1,0,0,0,0
17,17,17,17,0,0,0,12,0,0,0,0,0,0,12,13,12,12,12,12,24,24,24,17,13,17,6,5,5,5,5,4,4,1,0,1,0,0,0
17,17,17,17,17,17,17,13,0,0,13,0,0,0,13,13,24,24,24,20,20,20,24,17,13,17,5,5,5,5,4,4,4,1,0,1,0,0,0
29,17,17,17,17,24,12,11,0,0,0,0,0,0,11,7,24,24,24,24,24,24,0,17,17,17,5,5,4,4,4,4,0,0,1,0,0,0,0
29,17,17,17,17,15,12,11,0,0,0,0,0,0,11,7,24,15,15,24,24,0,4,4,17,5,5,5,4,4,4,0,0,1,0,1,1,0,0
4,4,4,4,17,0,0,0,3,0,0,0,0,0,11,12,15,15,15,15,0,0,4,4,4,5,5,5,4,4,0,1,0,0,0,0,0,0,0
4,4,4,4,4,0,4,4,12,12,13,12,12,12,13,7,15,15,15,15,0,4,4,4,4,5,5,5,5,0,0,1,1,0,0,0,0,0,0
30,4,4,4,4,4,4,4,0,11,6,11,11,11,7,24,24,15,6,15,0,4,4,4,4,5,5,5,0,3,0,0,0,3,0,0,0,0,0
0,1,30,4,4,4,4,5,4,4,0,0,15,15,15,24,24,20,6,6,15,14,4,4,4,4,4,0,0,0,0,0,0,0,0,0,0,0,0
0,0,0,30,4,4,4,4,4,4,4,4,15,15,0,0,4,0,6,15,20,4,4,4,4,4,0,0,0,0,0,0,0,0,0,0,0,0,0
0,0,0,0,30,4,4,4,4,4,4,4,15,0,4,4,4,4,4,6,4,4,4,4,4,0,0,0,0,0,0,0,0,0,0,3,0,0,0
0,0,0,0,1,30,30,4,4,4,4,4,4,4,0,0,4,4,14,4,4,4,0,0,0,0,0,0,0,0,0,0,0,0,0,0,0,0,0
0,0,0,1,0,0,1,30,4,4,4,4,4,0,0,0,0,4,4,4,0,0,0,0,0,0,0,0,0,0,0,0,0,0,0,0,0,0,0
0,0,0,0,0,0,1,1,1,1,1,0,1,0,0,1,1,0,1,0,1,0,0,0,0,0,0,0,0,0,0,0,0,0,0,0,0,0,0
endlayer

layer
0,0,0,0,0,0,0,0,0,0,0,0,0,0,0,0,0,0,0,0,0,0,0,0,0,0,0,0,0,0,0,0,0,0,0,0,0,0,0
0,0,0,0,0,0,0,0,0,0,0,0,0,0,0,0,0,0,0,0,0,0,0,0,0,0,0,0,0,0,2,0,0,0,0,0,0,0,0
0,0,0,0,0,0,0,0,0,0,0,0,0,0,0,0,0,0,0,0,0,0,0,0,0,0,0,0,0,0,0,0,0,0,0,0,0,0,0
0,0,0,0,0,0,0,0,0,0,0,0,0,0,0,0,0,0,0,0,0,0,0,0,0,0,0,1,0,0,0,0,0,0,0,0,0,0,0
0,0,0,0,0,0,0,0,0,0,0,0,0,0,0,0,0,0,0,0,0,0,0,0,0,0,0,0,0,0,0,0,0,0,0,0,0,0,0
0,0,0,0,0,0,0,0,0,0,0,0,0,0,0,0,0,0,1,0,0,0,0,0,0,0,0,0,0,0,0,1,0,0,0,0,0,0,0
0,0,0,0,0,0,21,21,21,0,0,0,0,0,0,0,0,4,0,0,0,0,0,1,0,0,0,0,0,0,0,0,0,1,0,0,0,0,0
0,0,0,0,0,0,5,21,0,0,0,0,0,0,0,0,4,4,4,1,1,0,0,0,1,0,1,0,0,0,0,0,0,0,0,0,0,0,0
0,0,0,0,0,4,4,21,21,0,5,5,5,4,0,0,4,4,4,0,0,3,0,0,4,4,4,4,4,0,1,0,0,1,0,0,0,0,0
0,0,0,0,0,4,4,21,21,4,4,11,11,11,4,4,4,4,4,4,4,4,5,4,4,4,4,4,4,4,0,0,0,0,0,1,0,0,0
0,0,0,9,0,4,6,8,11,11,6,11,11,11,7,6,5,5,5,4,4,5,4,4,4,4,4,4,4,4,4,1,0,0,0,0,0,0,0
0,0,0,9,4,14,7,13,0,0,13,0,0,0,13,10,15,6,5,5,5,5,5,5,5,4,5,5,4,4,4,4,1,0,0,0,0,0,0
0,0,0,9,21,12,12,0,0,0,0,0,0,0,0,12,12,14,31,31,31,5,5,12,12,12,5,5,4,4,4,4,4,1,0,0,0,0,0
0,0,9,33,21,21,12,0,0,0,0,0,0,0,0,12,6,6,32,0,6,0,11,0,0,0,11,5,4,5,5,4,4,0,1,0,0,0,0
0,33,33,33,21,11,12,0,0,0,0,0,0,0,0,12,12,35,34,0,0,0,11,0,0,0,11,5,4,5,5,4,4,0,0,0,0,0,0
33,33,31,21,17,17,17,13,0,0,13,0,0,0,13,25,6,20,20,0,0,0,11,0,0,0,11,5,5,5,5,5,0,0,0,0,0,0,0
33,31,31,17,0,0,0,12,0,0,0,0,0,0,12,13,12,12,12,12,12,12,13,0,0,0,13,5,5,5,5,5,0,0,0,0,0,0,0
33,31,31,0,0,0,0,0,0,0,0,0,0,0,37,0,0,0,0,0,0,0,36,0,0,0,11,5,5,5,5,5,0,0,0,0,0,0,0
33,31,21,17,0,0,0,12,0,0,0,0,0,0,12,13,12,12,12,12,12,12,13,0,0,0,13,5,5,5,5,4,0,0,38,0,0,0,0
33,31,31,21,17,17,17,13,0,0,13,0,0,0,13,13,24,24,6,0,0,0,11,0,0,0,11,14,5,5,5,4,38,1,0,0,0,0,0
33,31,31,31,9,17,12,0,0,0,0,0,0,0,0,12,24,24,20,20,20,20,11,0,0,0,11,21,4,4,4,39,0,0,0,0,0,0,0
33,31,31,9,17,21,12,0,0,0,0,0,0,0,0,12,15,39,39,15,20,6,13,13,40,13,13,4,4,4,0,0,0,1,0,0,0,0,0
33,33,33,17,17,21,12,0,0,0,0,0,0,0,0,12,0,42,21,41,20,14,4,21,0,21,21,4,4,0,0,0,0,0,0,0,0,0,0
0,0,5,5,4,4,8,13,0,0,13,0,0,0,13,7,43,42,3,0,21,14,21,0,38,5,0,0,0,0,0,0,0,0,0,0,0,0,0
0,0,0,5,4,4,6,10,11,11,6,11,11,11,7,6,15,21,21,21,21,14,21,4,38,5,0,0,0,0,0,0,0,0,0,0,0,0,0
0,0,0,41,4,4,4,0,21,21,21,21,21,21,21,15,15,21,6,21,21,21,21,4,38,0,0,0,0,0,0,0,0,0,0,0,0,0,0
0,0,0,0,0,41,4,4,0,21,21,21,21,21,21,21,21,21,21,21,21,21,44,4,38,0,0,0,0,0,0,0,0,0,0,0,0,0,0
0,1,0,0,0,30,30,4,4,4,21,21,21,21,21,21,4,4,21,21,21,4,4,4,0,0,0,0,0,0,0,0,0,0,0,0,0,0,0
0,0,0,0,0,0,0,30,4,4,21,21,21,21,0,0,0,4,21,4,0,0,0,0,0,0,0,0,0,0,0,0,0,0,0,0,0,0,0
0,0,0,0,0,0,0,0,0,0,0,0,0,0,0,0,0,0,0,0,0,0,0,0,0,0,0,0,0,0,0,0,0,0,0,0,0,0,0
0,0,0,0,1,1,0,0,1,0,0,0,0,0,0,0,1,1,1,0,0,0,0,0,0,0,0,0,0,0,0,0,0,0,0,0,0,0,2
endlayer

layer
2,2,0,0,0,0,0,0,0,0,0,0,0,0,0,0,0,0,0,0,0,0,1,0,0,0,0,0,0,0,0,0,0,0,0,0,0,0,0
0,0,0,0,0,0,0,0,0,0,0,0,0,0,0,0,0,0,0,0,0,0,0,0,0,0,0,0,0,0,0,0,0,0,0,0,0,0,0
0,0,0,0,0,0,0,0,0,0,0,0,0,0,0,0,0,0,0,0,0,0,0,0,0,0,1,0,0,0,0,0,0,0,0,0,0,0,0
0,0,0,0,0,0,0,0,0,0,0,0,0,0,0,0,0,0,0,0,0,0,0,0,0,0,0,0,0,0,0,0,0,0,0,0,0,0,0
0,0,0,0,0,0,0,0,0,0,0,0,0,0,0,0,0,0,0,1,0,0,0,0,0,0,1,0,0,0,0,0,0,0,0,0,0,0,0
0,0,0,0,0,0,0,0,0,0,0,0,0,0,0,0,0,0,0,0,0,0,0,0,0,0,0,1,0,0,0,0,0,0,0,0,0,0,0
0,0,0,0,0,0,0,21,21,21,0,0,0,0,0,0,45,0,0,0,0,0,0,0,0,0,0,1,0,1,0,0,0,1,0,0,0,0,0
0,0,0,0,0,0,21,21,21,21,0,0,0,4,0,0,0,4,0,0,1,0,0,0,0,0,0,0,1,0,0,0,0,0,0,0,0,0,0
0,0,0,0,0,0,21,21,21,21,5,5,5,0,0,0,4,4,4,0,0,0,0,0,0,0,0,0,0,0,0,0,0,1,0,0,1,0,0
0,0,0,0,0,4,21,21,21,21,4,21,4,21,6,4,4,5,5,4,4,5,5,4,4,4,4,4,4,4,0,0,1,0,0,0,0,0,0
0,0,0,9,0,4,6,7,11,11,6,11,11,11,7,6,4,6,0,5,5,4,4,5,4,4,5,4,4,4,4,0,0,0,0,0,0,0,0
0,0,0,9,4,6,7,13,0,0,13,0,0,0,13,10,47,46,0,5,5,5,4,5,5,17,5,5,5,5,4,4,0,0,0,0,0,0,0
0,0,0,0,0,12,12,0,0,0,0,0,0,0,0,12,12,50,49,49,49,0,49,13,48,13,13,5,5,5,4,4,4,0,0,0,0,0,0
0,0,9,9,21,12,12,0,0,0,0,0,0,0,0,12,6,51,49,49,6,49,13,0,0,0,13,24,4,0,5,5,4,0,0,0,0,0,0
0,0,0,9,21,21,12,0,0,0,0,0,0,0,0,12,12,14,49,49,49,41,48,0,0,0,48,24,0,5,0,5,4,0,0,0,0,0,0
0,0,0,0,17,17,17,13,0,0,13,0,0,0,13,25,6,6,20,49,49,49,48,0,0,0,48,52,6,5,5,5,5,0,0,0,0,1,0
0,0,9,17,0,0,0,12,0,0,0,0,0,0,12,8,20,12,12,12,12,12,13,0,0,0,13,20,20,6,5,5,5,5,0,0,0,0,0
0,0,9,0,0,0,0,12,53,0,0,0,0,52,12,11,20,53,0,0,0,0,37,0,0,0,48,0,0,0,14,5,5,5,0,0,0,0,0
0,0,9,17,0,0,0,12,0,0,0,0,0,0,12,7,20,12,12,12,12,12,13,0,0,0,13,21,24,5,5,5,0,0,38,0,0,1,0
0,0,0,21,17,17,17,13,0,0,13,0,0,0,13,13,14,20,20,0,21,0,48,0,0,0,48,21,5,5,5,0,0,0,0,1,0,0,0
0,0,0,0,9,17,12,0,0,0,41,0,0,0,0,12,14,14,6,0,0,6,48,0,0,0,48,21,6,4,0,39,0,0,0,1,0,0,0
0,0,0,54,17,17,12,0,0,0,0,0,0,0,0,12,21,41,21,21,6,24,13,13,37,13,13,21,21,0,0,0,0,0,1,0,0,0,0
0,0,9,17,17,21,12,0,0,0,0,0,0,0,0,12,12,21,21,21,21,6,4,21,0,21,21,21,41,0,0,0,0,0,0,0,0,0,0
0,0,9,5,4,4,8,13,0,0,13,0,0,0,13,7,21,21,0,21,21,21,4,0,42,5,0,0,0,0,0,0,0,0,0,0,0,0,0
0,0,0,4,4,4,6,10,11,11,6,11,11,11,7,25,21,3,21,21,21,21,4,4,0,3,0,0,0,1,0,0,0,0,0,0,0,0,0
0,0,0,0,0,4,4,4,21,21,21,21,21,21,21,55,21,21,21,21,21,4,4,0,0,0,0,0,0,0,0,0,0,0,0,0,0,0,0
0,1,0,1,1,0,4,4,21,21,21,21,21,21,21,21,21,0,21,21,21,53,0,0,0,0,0,0,0,0,0,0,0,1,0,0,0,0,0
0,0,0,0,0,0,0,0,56,4,21,21,21,21,0,0,0,5,4,4,0,3,0,0,0,0,0,0,0,0,0,0,0,0,0,0,0,0,0
0,0,0,1,0,0,0,0,0,0,4,4,4,0,0,57,0,0,5,0,0,0,0,0,0,0,0,0,0,0,0,1,0,0,0,0,0,0,0
0,0,0,0,0,0,0,0,0,0,0,0,0,0,0,0,0,0,0,0,0,0,0,0,0,0,0,0,0,0,0,0,0,0,0,0,0,0,0
0,0,0,0,0,0,0,0,0,0,0,0,0,0,1,0,0,0,0,0,0,0,0,0,0,0,0,0,0,0,0,0,0,0,0,0,0,0,0
endlayer

layer
2,0,0,0,0,0,0,0,0,0,0,0,0,0,0,0,0,0,0,0,0,0,0,0,0,0,0,0,0,0,0,0,0,0,0,0,0,0,0
0,0,0,0,0,0,0,0,0,0,0,0,0,0,0,0,0,0,0,0,0,0,0,0,0,0,0,0,0,0,0,0,0,0,0,0,0,0,0
0,0,0,0,0,0,0,0,0,0,0,0,0,0,0,0,0,0,0,0,0,0,0,0,0,0,0,0,0,0,0,0,0,0,0,0,0,0,0
0,0,0,0,0,0,0,0,0,0,0,0,0,0,1,0,0,0,0,0,0,0,0,0,0,0,0,0,0,0,0,0,0,0,0,0,0,0,0
0,0,0,0,0,0,0,0,0,0,0,0,0,0,0,0,0,0,0,0,0,0,0,0,0,0,0,0,0,0,0,0,0,0,0,0,0,0,0
0,0,0,0,0,0,0,0,0,0,0,0,0,0,1,0,0,0,0,0,0,0,0,1,0,0,0,1,0,1,1,0,0,0,0,0,0,0,0
0,0,0,0,0,0,0,0,0,0,0,0,0,0,0,45,45,0,45,45,0,1,0,0,0,0,0,0,0,1,1,0,1,0,0,0,0,0,0
0,0,0,0,0,0,0,0,0,3,58,0,54,16,0,0,0,4,0,0,1,0,1,0,0,1,0,1,1,0,1,1,0,1,0,0,0,0,0
0,0,0,0,0,52,21,45,45,21,0,21,21,44,15,4,4,4,4,0,5,0,0,0,0,0,0,0,0,0,1,0,0,0,0,0,0,0,0
0,0,0,0,0,0,21,21,21,15,15,21,21,21,6,4,4,5,5,5,5,4,5,4,4,4,4,4,4,4,0,0,0,0,0,0,0,0,0
0,0,0,42,0,4,6,20,20,20,6,60,60,60,60,6,20,20,59,5,6,5,5,5,4,4,5,5,4,4,4,54,0,0,0,0,0,38,0
0,0,0,9,21,6,14,13,12,12,61,12,12,12,13,61,46,46,0,49,49,49,49,5,4,4,5,5,4,5,4,5,4,0,0,0,0,0,0
0,0,0,0,0,9,61,11,0,0,11,0,0,0,11,61,50,0,49,49,49,49,49,13,12,13,5,24,5,0,5,5,5,54,0,0,0,0,0
0,0,9,9,21,9,61,11,0,0,11,0,0,0,11,61,6,50,49,49,6,49,13,0,0,0,11,24,24,5,5,0,5,5,0,0,0,1,0
0,0,0,9,42,9,61,11,0,0,11,0,0,0,11,61,62,0,49,49,49,49,11,0,0,0,11,24,20,5,5,20,5,5,0,0,0,0,0
0,0,63,0,17,24,25,60,60,60,6,12,12,12,60,6,6,6,49,49,49,49,11,0,0,0,11,6,6,6,6,14,20,5,0,0,0,0,0
0,0,9,17,17,17,17,11,0,0,61,0,0,0,11,61,6,20,6,21,64,51,13,0,0,0,13,6,6,6,6,14,20,6,5,0,0,0,0
0,0,9,17,17,17,17,11,0,0,61,0,0,0,11,61,6,20,12,12,12,12,11,53,0,52,11,6,14,14,14,14,6,5,0,38,0,0,0
0,0,9,17,17,17,17,11,0,0,61,0,0,0,11,14,6,20,6,21,21,21,13,0,0,0,13,65,14,14,6,6,5,0,42,0,0,0,0
0,0,0,9,17,21,14,60,12,12,6,12,12,12,12,6,6,6,0,0,0,0,11,0,0,0,11,21,4,4,4,0,0,0,0,0,0,0,0
0,0,0,0,9,17,14,11,0,0,14,0,0,0,11,14,6,6,6,0,0,0,11,0,0,0,11,21,31,0,0,39,0,0,0,0,0,0,0
0,0,0,9,17,17,14,11,0,0,14,0,0,0,11,14,21,21,21,0,0,6,13,12,12,12,13,21,0,0,0,0,0,0,0,0,0,0,0
0,0,9,17,17,24,14,11,0,0,14,0,0,0,11,14,66,0,21,0,21,21,4,21,21,21,21,0,0,0,0,0,0,0,0,0,0,0,0
0,0,9,17,4,4,14,13,12,12,14,12,12,12,13,14,21,21,21,4,21,0,4,0,4,0,0,0,0,0,0,0,0,1,0,0,0,0,0
0,0,0,0,4,4,6,20,20,20,25,60,60,60,60,25,21,21,21,21,4,4,4,66,0,0,0,0,0,0,0,0,0,0,0,0,0,0,0
0,0,0,0,0,0,4,0,0,21,21,21,21,21,21,21,4,0,21,21,4,0,1,0,0,0,0,0,0,0,0,0,0,0,0,0,0,0,0
0,0,0,0,0,0,39,0,21,21,21,21,21,21,21,21,21,0,39,4,0,0,0,0,0,0,0,0,0,0,0,0,0,0,0,0,0,0,0
0,0,0,1,1,0,0,0,4,0,4,4,4,4,0,0,0,39,0,0,0,0,0,0,1,0,0,0,0,0,0,0,0,0,0,0,0,0,0
0,0,0,0,0,0,0,0,0,0,0,0,0,0,0,0,0,0,0,0,0,0,0,0,0,0,0,0,0,0,0,0,0,0,0,0,0,0,0
0,0,0,0,0,0,1,1,0,0,0,0,0,0,0,0,0,0,0,0,0,0,0,0,0,0,0,0,0,0,0,0,0,0,0,0,0,0,0
0,0,0,0,0,0,0,0,0,0,0,0,1,0,0,0,0,0,0,0,0,0,0,0,0,0,0,0,0,0,0,0,0,0,0,0,0,0,0
endlayer

layer
0,0,0,0,0,0,0,0,0,0,0,0,0,0,0,0,0,0,0,0,2,2,0,0,0,0,0,0,0,0,0,0,0,0,1,0,0,0,0
0,0,0,0,0,0,0,0,0,0,0,0,0,0,0,0,0,0,0,0,0,0,0,0,0,0,0,0,0,0,0,0,0,0,0,0,0,0,0
0,0,0,0,0,0,0,0,0,0,0,0,0,0,0,0,0,0,0,0,0,0,0,0,0,0,0,0,0,0,0,0,0,0,0,0,0,0,0
0,0,0,0,0,0,0,0,0,0,0,0,0,0,0,0,0,0,0,0,0,0,0,0,0,0,0,0,0,0,0,0,0,0,0,0,0,0,0
0,0,0,0,0,0,0,0,0,0,0,0,0,0,0,0,0,0,0,0,0,0,0,0,0,0,0,0,0,0,0,1,0,0,0,0,0,0,0
0,0,0,0,0,0,0,0,0,0,0,0,0,0,0,0,0,0,0,0,0,0,0,0,0,0,0,0,0,1,0,0,0,0,0,0,0,0,0
0,0,0,0,0,0,0,0,0,0,0,0,0,0,0,45,45,0,45,45,0,0,0,0,0,0,0,0,0,1,0,0,0,0,0,0,0,0,0
0,0,0,0,0,0,0,0,0,0,0,0,0,16,0,0,0,5,0,0,0,0,0,0,1,0,0,1,0,0,0,0,0,0,0,0,0,0,0
0,0,0,0,0,0,0,0,0,0,58,0,9,0,0,4,4,4,4,5,0,4,4,0,0,0,0,0,0,0,0,0,0,0,0,0,0,0,0
0,0,0,0,0,0,4,4,4,4,45,21,21,21,6,4,6,5,6,6,20,5,4,4,4,0,4,4,5,5,5,5,0,0,0,0,0,0,0
0,0,0,21,14,4,6,67,67,67,6,67,67,67,67,14,6,6,0,6,6,0,5,4,4,4,4,5,5,5,4,4,4,0,0,0,0,38,0
0,0,0,9,14,24,67,8,8,8,67,7,7,7,8,14,14,0,0,0,0,0,0,5,0,4,4,0,24,5,5,0,5,4,0,0,0,0,0
0,0,52,21,6,24,67,8,17,17,67,17,17,17,8,6,0,0,0,49,49,49,0,21,24,24,24,24,24,24,5,20,20,5,0,0,0,0,0
0,0,9,21,14,24,67,8,17,17,67,17,17,17,8,67,6,50,0,49,6,49,68,17,17,17,24,24,24,24,24,20,20,5,0,0,0,0,0
0,42,0,9,14,15,67,8,17,17,17,17,17,17,21,21,62,0,0,49,49,69,69,17,41,17,6,6,20,6,6,14,20,21,0,0,0,0,0
0,0,21,21,20,20,25,67,67,17,17,17,17,17,67,25,6,50,0,0,69,69,64,17,0,17,6,6,6,6,6,31,31,21,4,0,0,0,0
0,63,21,20,21,21,67,7,17,17,17,17,17,17,10,67,6,6,3,50,64,51,64,17,0,17,6,6,6,6,31,31,31,21,21,0,0,0,0
0,0,21,31,17,17,17,17,17,17,17,17,17,17,10,67,6,6,6,21,21,64,64,17,0,17,6,21,21,21,31,31,31,4,4,38,0,0,0
0,0,0,31,17,17,17,17,17,17,17,17,17,17,10,67,6,6,21,21,21,21,21,17,0,17,0,21,21,21,31,31,13,21,4,0,0,0,0
0,0,0,9,17,17,6,17,17,17,17,67,67,67,67,6,24,0,0,0,0,49,49,17,54,17,0,0,0,0,0,0,21,21,0,1,0,0,0
0,0,0,0,9,17,17,17,17,17,17,17,17,17,7,67,70,6,0,49,49,49,49,17,17,17,21,39,0,0,0,39,0,0,0,0,0,0,0
0,0,0,9,17,17,17,17,17,17,17,17,17,17,8,67,38,21,21,49,49,6,49,49,21,21,21,0,0,0,0,0,0,0,0,0,0,0,0
0,0,0,31,17,24,17,17,17,17,17,17,17,17,8,67,21,0,0,0,49,49,49,38,38,0,0,0,0,0,0,0,0,0,0,0,0,0,0
1,0,0,31,17,4,67,8,8,10,67,7,7,7,8,67,21,21,21,4,4,49,0,0,38,0,0,0,0,0,0,0,0,0,0,0,0,0,0
0,0,0,0,0,4,6,67,67,67,25,67,67,67,67,25,21,21,21,4,0,39,0,66,0,0,0,0,0,0,0,0,0,0,0,0,0,0,0
0,0,0,0,0,0,4,4,15,21,21,21,21,21,21,21,71,0,4,4,1,0,1,0,0,0,0,0,0,0,0,0,0,0,0,1,0,0,0
0,0,0,0,1,0,39,0,39,39,4,4,73,73,73,9,3,0,72,38,0,0,1,0,0,0,0,0,0,0,0,0,0,0,0,0,0,0,0
0,0,0,1,0,0,0,0,0,0,0,0,0,0,0,0,0,39,0,0,0,0,0,0,0,0,0,0,0,0,0,0,0,0,0,0,0,0,0
0,0,0,0,0,0,0,0,0,0,0,0,0,0,0,0,0,0,0,0,0,0,0,1,0,0,0,0,0,0,0,0,0,0,0,0,0,0,0
0,0,0,0,0,0,1,0,0,0,1,0,0,0,0,0,0,0,0,0,0,0,1,0,0,0,0,0,0,0,0,0,0,0,0,0,0,0,0
0,0,1,0,0,0,0,0,0,0,0,0,0,0,0,0,0,0,0,0,0,0,0,0,0,0,0,0,0,0,0,0,0,0,0,0,0,0,0
endlayer

layer
0,0,0,0,24,0,24,0,0,0,0,0,0,0,0,0,0,0,0,0,2,2,0,0,0,0,0,0,0,0,0,0,0,0,0,0,0,0,0
0,0,0,0,0,0,0,0,0,0,0,0,0,0,0,0,0,0,0,0,0,0,0,0,0,0,0,0,0,0,0,0,0,0,0,0,0,0,0
0,0,0,0,0,0,0,0,0,0,0,0,0,0,0,0,0,0,0,0,0,0,0,0,0,0,0,0,0,0,0,0,0,0,0,0,0,1,0
0,0,0,0,0,0,0,0,0,0,0,0,0,0,0,0,0,0,0,0,0,0,0,0,0,0,0,0,0,0,0,0,0,0,0,0,0,0,0
0,0,0,0,0,0,0,0,0,0,0,0,0,0,0,0,0,0,0,0,0,0,1,0,0,0,0,0,0,0,0,0,0,0,0,0,0,0,0
0,0,0,0,0,0,1,0,0,0,0,0,0,0,0,0,0,0,0,1,0,0,0,1,0,0,0,0,0,0,1,0,0,0,0,0,0,0,0
0,0,1,0,1,0,0,0,0,0,0,0,0,0,45,45,45,0,45,45,0,0,0,0,0,0,0,0,0,0,0,0,0,0,0,0,0,0,0
0,0,0,0,0,0,0,0,0,0,0,0,0,16,0,0,6,6,6,4,4,0,0,0,0,0,0,0,0,0,0,0,0,0,0,0,0,0,0
0,0,0,1,0,0,0,0,0,0,0,0,9,0,21,6,6,6,6,6,4,5,4,5,0,0,63,0,0,5,5,4,0,0,0,0,0,1,0
0,0,0,0,0,0,0,0,0,0,45,9,0,21,6,6,25,6,6,6,6,6,5,5,0,0,4,4,4,5,5,5,5,0,0,0,0,0,0
0,0,0,0,21,15,4,4,4,4,15,3,21,6,6,6,6,6,20,20,20,20,20,20,4,4,4,4,5,5,5,14,20,4,0,0,0,38,0
0,0,0,0,21,15,24,4,4,5,15,17,17,17,6,6,6,20,20,20,20,20,20,20,24,24,4,24,5,5,5,14,20,21,0,0,0,0,0
0,0,0,21,6,24,24,4,4,5,24,17,17,17,17,6,20,0,0,0,49,50,0,21,20,24,24,24,24,24,6,20,21,21,0,0,0,0,0
0,0,0,21,21,15,15,4,0,5,17,74,74,17,6,20,6,0,0,49,49,49,68,21,41,21,24,24,6,6,20,6,21,21,21,0,0,1,0
0,21,21,21,21,0,15,24,15,17,41,31,31,17,21,21,0,0,0,0,49,50,0,75,48,6,14,6,6,6,21,6,0,21,21,0,0,0,0
21,21,21,20,6,21,6,24,17,31,31,31,31,17,6,6,6,50,0,0,77,64,64,76,48,0,6,6,6,6,59,41,0,0,4,0,1,0,0
0,21,21,21,21,78,17,17,31,31,31,31,31,17,6,0,6,6,21,50,0,51,64,75,48,6,6,6,6,21,59,0,0,0,4,0,0,0,0
0,0,21,21,31,17,17,79,31,31,31,31,31,17,6,6,6,6,6,21,50,0,21,0,48,6,6,21,21,46,0,0,0,0,4,38,0,0,0
0,0,0,0,31,17,31,31,31,31,31,31,31,17,17,24,6,6,21,21,21,21,21,21,48,14,21,21,0,0,0,0,13,21,38,38,0,0,0
0,0,0,0,31,17,31,31,31,31,52,17,17,17,24,24,6,0,0,21,49,49,49,49,48,21,21,0,0,0,0,0,21,21,0,0,0,0,0
0,0,0,0,9,31,31,31,31,31,31,17,0,21,15,24,14,6,21,49,49,49,49,49,21,21,0,39,0,0,38,39,0,0,0,0,0,0,0
0,0,0,0,31,17,31,31,31,31,31,17,21,21,21,15,14,21,21,49,49,6,49,49,70,0,0,0,0,1,1,39,0,0,0,0,1,0,0
0,0,0,0,31,17,31,31,31,31,31,17,21,21,3,21,21,21,21,49,49,49,49,49,38,0,0,39,39,0,1,0,0,0,0,0,0,0,0
0,0,0,0,31,78,17,17,17,17,17,21,80,21,21,3,21,21,4,4,49,49,49,49,38,0,0,0,0,0,0,0,0,0,0,0,0,0,0
0,0,0,0,0,0,4,15,21,21,21,21,21,21,21,21,4,21,4,4,1,39,0,66,0,0,0,0,0,1,0,0,0,0,0,0,0,0,0
0,0,0,0,0,0,21,21,21,21,21,21,71,21,21,21,71,0,1,39,1,0,1,0,0,0,0,0,0,0,0,0,0,0,0,0,0,0,0
0,0,0,1,0,0,39,0,41,0,0,0,0,73,0,9,0,0,72,38,0,0,1,0,0,0,0,0,0,0,0,0,0,0,0,0,0,0,0
0,0,0,1,0,0,0,0,0,0,0,0,0,0,0,0,0,39,73,0,0,0,0,1,0,0,0,0,0,0,0,0,0,0,0,0,0,0,0
0,0,0,1,0,0,0,0,0,0,0,0,0,0,0,0,0,0,0,0,1,0,1,0,0,0,0,0,0,0,0,0,0,0,0,0,0,0,0
0,0,0,0,0,0,0,0,0,0,0,1,0,0,0,0,0,0,0,0,0,1,0,0,0,0,0,0,0,0,0,0,0,0,0,0,0,0,0
0,0,0,0,0,0,0,0,0,0,0,0,0,0,0,0,0,0,0,0,0,0,0,0,0,0,0,0,0,0,0,0,0,0,0,0,0,0,0
endlayer

layer
0,0,0,0,0,24,0,0,0,0,0,0,0,0,0,0,0,0,0,0,0,0,0,0,2,2,0,0,0,0,0,0,0,0,0,0,0,0,0
0,0,0,0,0,0,0,0,0,0,0,0,0,0,0,0,0,0,0,0,0,0,0,0,0,0,0,0,0,0,0,0,0,0,0,0,0,0,0
0,0,0,0,0,0,0,0,0,0,0,0,0,0,0,0,0,0,0,0,0,0,0,0,0,0,0,0,0,0,0,0,0,0,0,0,0,0,0
0,0,0,0,0,0,0,0,0,0,0,0,0,0,0,0,0,0,0,0,0,0,0,0,0,0,0,0,0,0,1,0,0,0,0,0,0,0,0
0,1,0,0,0,0,0,0,0,0,0,0,0,0,0,0,0,0,0,0,0,0,0,0,0,0,0,0,0,0,0,0,0,0,0,0,0,0,0
0,0,0,0,0,0,0,0,0,0,0,0,0,0,0,0,0,0,0,0,0,0,0,0,1,0,0,0,0,0,0,0,0,0,0,0,0,0,0
0,0,0,0,0,0,0,0,1,0,0,0,0,0,45,45,45,45,45,45,0,0,0,0,0,0,0,0,0,0,0,45,0,0,0,0,0,0,0
0,0,0,0,0,0,0,0,0,0,0,0,0,16,0,21,21,14,21,4,4,4,0,0,0,0,0,0,0,0,45,0,0,0,0,0,0,0,0
0,0,0,0,0,0,0,0,0,0,0,0,9,0,21,21,20,6,20,4,21,15,5,5,5,0,4,0,0,4,4,4,5,0,0,0,0,0,0
0,0,0,0,0,0,1,1,0,21,0,9,21,21,52,20,6,6,6,20,21,21,21,15,15,4,4,4,4,4,24,17,5,21,54,0,0,0,0
0,0,0,0,0,55,1,0,0,0,9,21,21,31,31,31,81,0,62,62,62,82,81,62,20,6,6,6,6,6,6,17,21,21,21,0,38,38,0
0,0,0,0,0,55,15,0,0,0,21,31,31,31,31,31,31,0,0,81,0,3,50,71,20,6,6,6,6,6,0,17,21,21,21,0,0,0,0
0,0,0,0,21,6,15,0,0,0,15,31,31,31,31,31,33,33,33,33,33,33,33,33,33,6,6,6,6,14,6,21,0,21,21,0,0,0,0
0,0,0,0,9,21,21,0,0,0,21,0,0,31,6,6,21,0,0,64,50,38,50,75,21,9,6,6,6,6,66,6,0,21,21,0,0,0,0
0,0,0,0,21,21,84,24,83,21,0,0,0,31,21,14,21,21,0,0,50,50,0,75,21,21,6,6,6,6,0,46,0,0,38,0,1,0,0
21,21,21,21,21,21,6,6,59,59,0,0,0,31,6,6,6,21,0,21,51,64,64,76,21,21,6,6,6,6,38,0,0,0,0,0,0,1,0
21,21,21,0,0,0,9,6,59,0,0,0,0,52,6,0,6,6,21,21,21,51,0,75,21,6,6,6,21,46,0,0,0,0,0,0,0,0,0
0,21,21,0,0,31,3,79,0,0,0,0,0,31,6,6,6,23,20,6,21,21,50,0,21,6,21,39,0,0,0,0,0,0,0,38,0,0,0
0,0,41,0,0,31,0,9,39,0,0,0,0,31,85,6,6,14,20,21,21,21,0,21,0,21,21,0,0,0,0,21,13,21,38,38,0,0,0
0,0,0,0,0,31,0,9,39,0,0,21,21,21,15,15,14,0,0,0,21,86,0,0,39,21,0,0,0,0,0,0,21,21,1,0,0,0,0
0,0,0,0,9,0,39,0,0,0,0,21,21,21,21,6,6,6,0,0,0,49,38,39,0,41,0,39,0,0,38,39,0,0,0,0,0,0,0
0,0,0,0,0,31,39,0,0,39,0,21,21,21,21,21,6,14,0,0,49,6,49,53,65,0,39,0,39,0,0,39,0,0,1,0,0,0,0
0,0,0,0,0,3,39,39,73,0,0,21,21,0,9,0,21,21,0,0,49,49,39,3,0,39,0,39,39,0,0,39,0,0,0,0,0,0,0
0,0,0,0,0,0,80,21,80,80,21,80,80,21,87,21,4,4,4,0,0,0,39,38,39,0,0,0,0,0,0,0,0,0,0,0,0,0,0
0,0,0,0,0,0,21,21,21,30,30,30,0,73,0,21,4,0,1,0,0,0,0,38,0,0,0,0,0,0,0,0,0,0,0,0,0,0,0
0,0,0,0,0,0,41,21,41,0,3,0,0,0,0,9,71,1,0,39,0,0,0,0,0,0,0,0,0,0,0,0,0,0,0,0,0,0,0
0,0,0,0,1,0,0,0,0,0,0,0,0,0,0,9,0,0,72,38,0,0,0,0,0,0,0,0,0,0,0,0,0,0,0,0,0,0,0
0,0,0,0,0,0,0,0,0,0,0,0,0,0,0,0,0,39,73,0,0,0,0,0,0,0,0,1,0,0,0,0,0,0,0,0,0,0,0
0,0,0,0,0,0,0,0,0,0,0,0,0,0,0,0,0,1,0,0,0,0,0,0,0,0,0,0,0,0,0,0,0,0,0,0,0,0,0
0,0,0,0,0,0,0,0,0,0,0,0,0,0,0,0,0,0,0,0,0,0,0,0,0,0,0,0,0,0,0,0,0,0,0,0,0,0,0
0,0,0,0,0,1,1,0,0,0,0,0,0,0,0,0,0,0,0,0,0,0,0,0,0,0,0,0,0,0,0,0,0,0,0,0,0,0,0
endlayer

layer
0,0,0,0,0,0,0,0,0,0,0,0,0,0,0,0,0,0,0,0,0,0,0,0,1,0,0,0,0,0,0,0,0,0,0,0,0,0,0
0,0,0,0,0,0,0,0,0,0,0,0,0,0,0,0,0,0,0,0,0,0,0,0,0,0,0,0,0,0,0,1,0,0,0,0,0,0,0
0,0,0,0,0,0,0,0,0,0,0,0,0,0,0,0,0,0,0,0,0,0,0,0,0,0,0,0,0,0,1,0,0,0,0,0,0,0,0
0,0,0,0,0,0,0,0,0,0,0,0,0,0,0,0,0,0,0,0,0,0,0,0,0,0,0,0,0,0,0,0,0,0,0,0,0,0,0
0,0,0,0,0,0,0,0,0,0,0,0,0,0,0,0,0,0,0,0,0,0,0,0,0,0,0,0,0,0,0,0,0,0,0,0,0,0,0
0,0,0,0,0,0,0,0,0,0,0,0,0,0,0,0,0,0,0,0,0,0,0,0,0,0,0,0,0,0,0,0,0,0,0,0,0,0,0
0,0,0,0,0,0,0,0,0,0,0,0,0,0,45,45,45,45,45,45,0,45,0,0,0,0,0,0,0,0,0,45,0,0,0,0,0,0,0
0,0,0,0,0,0,0,0,0,0,0,0,0,16,0,45,0,21,21,21,0,0,0,0,0,0,0,0,0,54,4,42,54,0,45,0,0,0,0
0,0,0,0,0,0,0,0,0,0,0,0,9,0,80,21,6,6,6,21,21,21,0,0,5,5,4,4,4,4,17,0,21,0,0,0,0,45,0
0,0,0,0,0,0,1,0,0,0,0,9,0,21,0,21,6,6,6,21,21,21,21,21,0,6,6,6,6,17,17,17,21,21,0,0,0,38,0
0,0,0,0,0,0,0,0,0,0,9,21,0,0,0,0,41,0,62,62,62,82,88,62,0,39,39,31,31,0,0,0,17,21,21,0,38,38,0
0,0,0,0,0,0,89,0,0,21,21,21,0,0,0,0,0,0,0,50,0,50,50,62,62,62,0,0,38,0,0,0,17,21,21,38,0,0,0
0,0,0,0,0,0,55,0,9,15,21,0,0,0,0,21,21,21,21,50,50,50,16,0,75,21,21,21,21,6,90,90,21,21,21,0,38,0,0
0,0,0,0,0,45,21,0,0,0,0,0,0,0,21,6,21,21,0,64,50,38,50,0,9,0,6,6,6,6,21,6,21,0,38,0,39,0,0
0,0,0,0,9,21,21,6,59,0,0,0,0,20,20,6,6,21,21,21,50,50,0,9,0,64,21,20,20,6,21,21,21,0,38,0,0,0,0
0,21,0,0,0,21,6,6,20,59,0,0,0,21,6,6,6,21,21,21,50,64,64,64,75,75,6,6,6,6,38,0,0,0,0,0,0,0,0
0,21,0,0,0,0,9,6,59,0,0,0,0,91,6,0,6,6,21,21,21,64,0,0,75,6,6,21,46,46,0,0,0,0,0,0,0,0,0
0,0,0,0,0,0,0,16,0,0,0,0,0,0,21,6,6,0,6,6,21,21,50,0,0,21,39,0,0,0,1,0,21,0,0,38,0,0,0
0,0,0,0,0,9,0,9,39,0,0,0,0,0,91,6,6,0,6,21,21,21,0,0,0,21,0,0,0,0,0,21,13,21,38,38,0,0,0
0,0,0,0,0,9,0,9,39,0,0,21,0,69,31,21,14,0,14,21,21,66,0,0,39,0,0,0,0,0,0,21,21,21,0,0,0,0,0
0,0,0,0,9,0,39,0,0,0,0,39,0,69,9,21,6,6,14,0,0,49,0,39,0,0,0,39,0,0,38,39,0,0,0,0,0,0,0
0,0,0,0,0,0,39,0,0,39,0,9,0,0,9,21,6,6,14,0,49,49,49,92,65,0,39,0,39,0,0,39,38,0,0,0,0,0,0
0,0,0,0,0,0,39,39,73,0,0,0,0,0,9,0,21,21,14,21,21,49,21,38,0,39,0,39,39,0,0,39,0,0,0,0,0,0,0
0,0,0,0,0,0,0,0,30,30,30,30,39,73,0,9,0,21,21,0,0,0,39,38,39,0,0,0,0,0,0,0,0,0,0,0,0,0,0
0,0,0,0,0,0,0,21,30,0,0,0,0,0,0,9,0,41,0,0,0,0,0,38,0,0,0,0,0,0,0,0,0,0,0,0,0,0,0
0,0,0,0,0,0,0,0,0,0,1,0,0,0,0,9,71,0,0,39,0,0,0,0,0,0,0,0,0,0,0,0,0,0,0,0,0,0,0
0,1,0,0,0,0,0,0,0,0,0,0,0,0,0,9,0,0,72,38,0,0,0,0,0,0,0,0,0,0,0,0,0,0,0,0,0,0,0
0,1,0,0,0,0,0,0,0,0,0,0,0,0,0,0,0,39,73,0,0,0,0,0,0,0,0,0,0,0,0,0,0,0,0,0,0,0,0
0,0,0,0,0,0,0,0,0,0,0,0,0,0,0,0,0,0,0,0,0,0,0,0,0,0,0,0,0,0,0,0,0,0,0,0,0,0,0
0,0,0,0,0,0,0,0,0,0,0,0,0,0,1,0,0,0,0,0,0,0,0,0,0,0,0,0,0,0,0,0,0,0,0,0,0,0,0
0,0,0,0,0,0,0,0,0,0,0,0,0,0,0,0,0,0,0,0,0,0,0,0,0,0,0,0,0,0,0,0,0,0,0,0,0,0,0
endlayer

layer
0,0,0,0,0,0,0,0,0,0,15,15,0,0,0,0,0,0,0,0,0,0,0,0,0,0,0,0,0,0,0,15,0,0,0,0,0,0,0
0,0,0,0,0,0,0,0,0,0,0,0,0,0,0,0,0,0,0,0,0,0,0,0,0,0,0,0,0,0,0,0,0,0,0,0,0,0,0
0,0,0,0,0,0,0,0,0,0,0,0,0,0,0,0,0,0,0,0,0,0,0,0,0,0,0,0,0,0,0,0,0,0,0,0,0,0,0
0,0,0,0,0,0,0,0,0,0,0,0,0,0,0,0,0,0,0,0,0,0,0,0,0,0,0,0,0,0,0,0,0,0,0,0,0,0,0
0,0,0,0,0,0,0,0,0,0,0,0,0,0,0,0,0,0,0,0,0,0,0,0,0,0,0,0,0,0,0,1,0,0,0,0,0,0,0
0,0,0,0,0,0,0,0,0,0,0,0,0,0,0,0,0,0,0,0,0,0,0,0,0,0,0,0,0,0,0,0,0,1,1,0,0,0,0
0,0,0,0,0,0,0,0,0,0,0,0,0,0,45,45,45,45,45,45,0,45,0,0,0,0,0,0,0,0,0,45,0,0,1,0,0,1,0
0,0,0,0,0,0,0,0,0,0,0,0,0,16,0,80,0,0,0,80,0,0,0,0,0,0,0,0,0,0,4,4,0,0,45,0,0,0,0
0,0,0,0,0,0,1,0,0,0,0,0,9,0,0,0,80,6,21,0,0,0,80,80,4,4,4,4,0,4,45,4,4,0,0,0,1,45,0
0,0,0,0,0,0,0,0,0,0,0,9,0,0,0,21,6,6,6,21,80,21,21,21,21,6,6,6,6,21,21,21,21,21,0,0,0,38,0
0,0,0,0,0,0,0,0,0,0,9,0,0,0,0,0,0,6,62,62,62,82,88,62,0,41,39,39,39,0,0,0,21,21,45,0,38,38,0
0,0,0,0,0,0,93,0,0,0,45,0,0,0,0,0,0,0,0,50,0,50,50,62,62,62,0,0,38,0,0,0,21,21,0,38,0,0,0
0,0,0,0,0,0,0,0,9,3,0,0,0,0,20,20,6,21,21,21,50,50,16,0,0,76,21,21,21,21,38,0,21,21,0,0,38,38,0
0,0,0,0,0,0,0,0,21,0,0,0,0,0,21,14,14,21,80,80,50,38,50,0,9,0,6,6,6,6,90,90,13,21,38,0,39,0,0
0,0,0,0,0,54,21,6,21,0,0,21,21,21,21,14,14,21,21,80,50,50,0,9,0,64,0,0,0,6,21,21,21,0,38,0,0,0,0
0,0,0,0,0,21,6,6,6,59,0,41,80,21,0,6,6,20,21,21,21,64,64,64,75,75,6,6,6,6,0,21,21,0,0,0,0,0,0
80,80,0,0,0,21,21,6,59,0,0,0,0,91,6,0,6,6,21,21,14,21,21,0,75,6,21,39,46,21,21,21,21,0,0,0,0,1,0
41,0,0,0,0,0,21,42,80,0,0,0,0,80,21,6,21,21,21,6,20,20,21,0,0,38,0,0,0,80,21,21,80,80,0,38,0,0,0
0,0,0,0,0,9,0,9,39,0,0,0,0,0,21,21,21,21,21,80,21,21,0,0,0,38,0,0,0,0,80,80,13,80,38,38,0,0,0
0,0,0,0,0,9,0,9,39,52,21,0,0,0,0,0,21,21,21,21,21,39,0,0,39,0,0,0,0,0,0,80,80,80,0,0,0,0,0
0,0,0,0,9,0,39,0,0,0,0,39,0,0,9,21,21,14,21,20,21,38,0,39,0,0,0,39,0,0,38,39,0,0,0,0,0,0,0
0,0,0,0,0,0,39,39,0,39,0,9,0,0,9,21,21,14,20,21,21,21,66,79,65,0,39,0,39,0,39,39,38,0,0,0,0,0,0
0,0,0,0,0,0,39,39,73,0,0,0,0,0,9,0,21,6,20,20,20,21,21,38,0,39,0,39,39,0,0,39,0,0,0,0,0,0,0
0,0,0,0,0,0,0,0,0,0,0,0,39,73,0,9,0,21,6,21,21,21,21,38,39,0,0,0,0,39,0,0,0,0,0,0,0,0,0
0,0,0,0,0,0,0,0,0,0,0,0,0,0,0,9,0,0,21,21,0,21,0,38,0,0,0,0,0,0,0,0,0,0,0,0,0,0,0
0,0,0,0,0,0,0,0,0,0,0,0,0,0,0,9,71,0,0,39,0,0,0,0,0,0,0,0,0,0,0,0,0,0,0,0,0,0,0
0,0,0,0,1,0,0,0,0,0,0,0,0,0,0,9,0,0,72,38,0,0,0,0,0,0,0,0,0,0,0,0,0,0,0,0,0,0,0
0,0,1,0,0,0,0,0,0,0,0,0,0,0,0,0,0,39,73,0,0,0,0,0,0,0,0,0,0,0,0,0,0,0,0,0,0,0,0
1,0,0,0,0,0,0,0,0,0,0,0,0,0,0,0,0,0,0,0,0,0,0,0,0,0,0,0,0,0,0,0,0,0,0,0,0,0,0
0,0,0,0,0,0,0,0,0,0,0,0,0,0,0,0,0,0,0,0,0,0,0,0,0,0,0,0,0,0,0,0,0,0,0,0,0,0,0
0,0,0,0,0,0,0,0,0,0,0,0,0,0,0,0,0,0,0,0,0,0,0,0,0,0,0,0,0,0,0,0,0,0,0,0,0,0,0
endlayer

layer
0,0,0,0,0,0,0,0,0,0,0,0,0,0,0,0,0,0,0,0,0,0,0,0,0,0,0,0,0,0,0,0,0,0,0,0,0,0,0
0,0,0,0,0,0,0,0,0,0,0,0,0,0,0,0,0,0,0,0,0,0,0,0,0,0,0,0,0,0,0,0,0,0,0,0,0,0,0
0,0,0,0,0,0,0,0,0,0,0,0,0,0,0,0,0,0,0,0,0,0,0,0,0,0,0,0,0,0,0,0,0,0,0,0,0,0,0
0,0,0,0,0,0,0,0,0,0,0,0,0,0,0,0,0,0,0,0,0,0,0,0,0,0,0,0,0,0,45,0,0,0,0,0,0,0,0
0,0,0,0,0,0,0,0,0,0,0,0,0,0,0,0,0,0,0,0,0,0,0,0,0,0,0,0,0,1,0,0,0,0,0,0,0,0,0
0,0,0,0,0,0,0,0,0,0,0,0,0,0,0,0,0,0,0,0,45,0,0,0,0,0,0,0,0,0,0,0,0,0,0,1,0,0,0
0,0,0,0,0,0,0,0,0,0,0,0,0,0,45,45,45,45,45,45,0,45,0,0,1,0,0,0,0,0,0,45,0,0,0,1,0,0,0
0,0,0,0,0,0,0,0,0,0,0,0,0,16,0,42,0,21,0,0,0,0,0,0,0,0,0,0,0,0,4,45,0,0,45,0,0,0,0
0,0,0,0,0,0,0,0,0,0,0,0,9,0,0,0,0,6,21,21,0,0,0,0,0,4,4,4,21,21,4,4,45,0,0,0,0,45,0
0,0,0,0,0,0,0,0,0,0,0,9,0,0,21,21,6,6,6,21,50,0,0,75,75,80,6,14,6,21,21,4,21,0,0,0,0,38,0
0,0,0,0,0,0,0,0,0,0,9,0,0,0,21,0,14,14,62,62,45,64,75,80,21,75,21,21,21,21,21,21,21,21,45,0,38,38,0
0,0,0,0,0,0,0,0,0,0,45,0,0,21,6,20,20,21,21,50,0,50,50,62,62,62,0,0,38,0,0,0,21,38,0,38,0,0,0
0,0,0,0,0,0,0,0,9,0,0,0,0,20,20,20,14,20,21,21,0,50,16,0,0,64,21,54,21,21,38,0,21,0,0,0,38,38,0
0,0,0,0,0,0,0,0,9,0,0,0,0,21,0,21,21,21,21,21,50,38,50,0,9,21,6,6,6,6,38,0,13,21,38,0,39,0,0
0,0,0,0,0,0,54,21,0,0,21,21,21,21,21,21,21,21,14,21,50,50,0,9,0,64,0,0,0,6,90,90,13,21,38,0,0,0,0
0,0,0,0,0,9,21,6,80,80,21,21,21,20,6,6,6,6,20,21,69,64,64,64,75,20,6,6,6,46,17,17,11,21,0,0,0,0,0
80,80,0,0,0,0,21,21,80,80,21,21,21,21,6,20,6,21,21,69,21,21,21,21,38,21,39,46,46,21,17,17,11,21,0,0,0,0,0
0,0,0,0,0,0,0,21,80,80,21,0,21,21,21,6,21,21,21,80,21,21,21,21,0,38,0,0,0,21,17,17,11,80,0,38,0,0,0
0,0,0,0,0,9,0,9,39,0,0,0,0,21,21,21,21,21,21,94,0,21,21,0,0,38,0,0,0,21,12,12,13,80,38,38,0,0,0
0,0,0,0,0,9,0,9,39,9,21,0,0,0,21,21,21,21,21,38,21,0,9,0,39,0,0,0,0,0,21,21,80,80,0,0,0,0,0
0,0,0,0,9,9,39,0,0,0,0,39,0,0,9,21,9,21,21,6,21,38,0,39,0,0,0,39,0,0,38,39,0,0,0,0,0,0,0
0,0,0,0,0,0,39,39,0,39,0,9,0,0,0,39,21,21,21,21,21,21,39,79,65,0,39,0,39,39,39,39,38,0,0,0,0,0,0
0,0,0,0,0,0,39,39,73,0,0,0,0,0,9,0,21,21,6,21,6,21,21,21,0,39,0,39,39,0,0,39,0,0,0,0,0,0,0
0,0,0,1,0,1,0,0,0,0,0,0,39,73,0,9,0,21,14,21,21,14,21,41,39,0,0,0,0,39,0,0,0,0,0,0,0,0,0
0,0,0,0,0,0,0,0,0,0,0,0,0,0,0,9,21,21,14,21,21,21,21,38,0,0,0,0,0,0,0,0,0,0,0,0,0,0,0
0,0,0,0,0,0,0,0,0,0,0,1,0,0,0,9,71,21,21,39,0,0,0,0,0,0,0,0,0,0,0,0,0,0,0,0,0,0,0
0,0,0,0,0,0,0,0,1,0,0,0,0,0,0,9,0,0,72,38,0,0,0,0,0,0,0,0,0,0,0,0,0,0,0,0,0,0,0
0,0,0,0,0,0,0,0,0,0,0,0,0,0,0,0,0,39,73,0,0,0,0,0,0,0,0,0,0,0,0,1,0,0,0,0,0,0,0
0,0,0,0,0,0,0,0,0,0,0,0,0,0,0,0,0,0,0,0,0,0,0,0,0,0,0,0,0,0,0,0,0,0,0,0,0,0,0
0,0,0,0,0,0,0,0,0,0,0,0,0,0,0,0,0,0,0,0,0,0,0,0,0,0,0,0,0,0,0,0,0,0,0,0,0,0,0
0,0,0,0,0,0,0,0,0,0,0,0,0,0,0,0,0,0,0,0,0,0,0,0,0,0,0,0,0,0,0,0,0,0,0,0,0,0,0
endlayer

layer
0,0,0,0,0,0,0,0,0,0,0,0,0,0,0,0,0,0,0,0,0,0,0,0,0,0,0,0,15,0,0,0,0,0,0,0,0,0,0
0,0,0,0,0,0,0,0,0,0,0,0,0,0,0,0,0,0,0,0,0,0,0,0,0,0,0,0,0,0,0,0,0,0,0,0,0,0,0
0,0,0,0,0,0,0,0,0,0,0,0,0,0,0,0,0,0,0,0,0,0,0,0,0,0,0,0,0,0,0,0,0,0,0,0,0,0,0
0,0,0,0,0,0,0,0,0,0,1,0,0,0,0,0,0,0,0,0,0,0,0,0,0,0,0,0,0,0,45,0,0,0,0,0,0,0,0
0,0,0,0,0,0,0,0,0,0,0,0,0,0,0,0,0,0,0,0,0,0,0,0,0,0,0,0,0,0,0,0,0,0,0,0,0,0,0
0,0,0,0,0,0,0,0,0,0,0,0,0,0,0,0,0,0,0,0,45,0,0,0,0,1,0,1,45,0,0,0,45,0,0,0,0,0,0
0,0,0,0,0,0,0,0,0,0,0,0,0,0,45,45,45,45,45,45,0,45,0,0,1,0,1,0,0,1,0,45,0,0,45,0,0,0,0
0,0,0,0,0,0,0,0,0,0,0,0,0,16,21,21,21,54,21,0,0,0,0,0,0,0,0,0,0,0,45,45,0,0,45,0,0,0,0
0,0,0,0,0,0,0,0,0,0,0,0,9,21,14,21,21,21,21,21,0,0,0,0,0,4,4,4,4,45,45,0,45,0,0,0,0,45,0
0,0,0,0,0,0,0,0,0,0,0,9,21,21,14,21,0,6,21,21,50,0,0,75,75,80,6,14,6,21,38,45,45,0,0,0,0,38,0
0,0,0,0,0,0,0,0,0,0,9,0,0,21,14,0,0,21,21,62,45,64,0,75,75,21,21,14,21,21,21,21,21,0,45,0,38,38,0
0,0,0,0,0,0,0,0,0,0,45,0,21,21,6,21,21,14,21,21,21,50,50,0,62,62,0,0,38,0,21,21,21,38,0,38,0,0,0
0,0,0,0,0,0,0,0,9,0,0,0,21,21,21,21,21,21,21,21,21,50,16,0,0,0,21,6,38,21,38,0,21,0,39,0,38,38,0
0,0,0,0,0,0,0,0,9,0,21,21,21,21,0,21,21,21,21,14,21,38,50,0,75,21,6,6,6,6,59,0,21,0,38,0,39,0,0
0,0,0,0,0,0,0,80,80,0,21,21,21,6,14,21,21,21,21,20,21,50,0,9,21,20,20,6,0,6,38,0,13,21,38,0,0,0,0
0,0,0,0,0,9,21,3,0,80,21,21,21,20,20,6,21,21,6,21,0,64,64,64,0,21,6,6,6,17,38,0,21,21,0,0,0,0,0
80,80,0,0,0,0,0,80,80,80,21,21,21,21,6,24,6,21,21,0,0,21,21,21,38,0,39,46,21,28,0,0,21,21,0,0,0,0,0
0,0,0,0,0,0,0,21,80,80,21,21,21,21,21,6,21,80,80,0,94,21,21,21,21,38,0,0,21,28,0,39,80,80,0,38,0,0,0
0,0,0,0,0,9,0,9,39,0,0,0,0,21,21,14,21,80,80,94,0,0,21,21,21,38,0,0,21,12,13,21,13,80,38,38,0,0,0
0,0,0,0,0,9,0,9,39,9,21,0,0,0,21,14,21,0,21,94,9,0,9,0,39,0,0,0,0,21,21,21,80,80,0,0,0,0,0
0,0,0,0,9,9,39,0,0,0,0,39,0,0,0,21,21,21,21,21,39,95,0,39,0,0,0,39,0,0,38,39,0,0,0,0,0,0,0
0,0,0,0,0,0,39,39,0,39,0,9,0,0,0,21,21,0,21,21,4,39,39,65,65,0,39,0,39,39,39,39,38,0,0,0,0,0,0
0,0,0,0,0,0,39,39,73,0,0,0,0,0,9,41,21,21,6,21,21,4,0,39,0,39,0,39,39,0,0,39,0,0,0,0,0,0,0
0,0,0,0,0,0,0,0,0,0,0,0,39,73,0,9,21,21,21,80,80,21,53,0,39,0,0,0,0,39,0,0,0,0,0,0,0,0,0
0,0,0,0,0,0,0,0,0,0,0,0,0,0,0,9,21,21,21,80,80,0,0,0,0,0,0,0,0,0,0,0,0,0,0,0,0,0,0
0,0,0,0,0,0,0,0,0,0,0,0,0,0,0,9,21,14,21,73,0,0,0,0,0,0,0,0,0,0,0,0,0,0,0,0,0,0,0
0,0,0,0,0,0,0,0,0,0,0,0,0,0,0,9,0,80,87,38,0,0,0,0,0,0,0,0,0,0,0,0,0,0,0,0,0,0,0
0,0,0,0,0,0,0,0,0,0,0,0,0,0,0,0,0,39,73,0,0,0,0,0,0,0,0,0,0,0,0,0,0,0,0,0,0,0,0
0,0,0,0,0,0,0,0,0,0,0,0,0,0,0,0,0,0,0,0,0,0,0,0,0,0,0,0,0,0,0,0,0,0,0,0,0,0,0
0,0,0,0,0,0,0,0,0,0,0,0,0,0,0,0,0,0,0,0,0,0,0,0,0,0,0,0,0,0,0,0,0,0,0,0,0,0,0
0,0,0,0,0,0,0,0,0,0,0,0,0,0,0,0,0,0,0,0,0,0,0,0,0,0,0,0,0,0,0,0,0,0,0,0,0,0,0
endlayer

layer
0,0,0,0,0,0,0,0,0,0,0,0,0,0,0,0,0,0,0,0,0,0,0,0,0,0,0,0,0,0,0,0,0,0,0,0,0,0,0
0,0,0,0,0,0,0,0,0,0,0,0,0,0,0,0,0,0,0,0,0,0,0,0,0,0,0,0,0,0,0,0,0,0,0,0,0,0,0
0,0,0,0,0,0,0,0,0,0,0,0,0,0,0,0,0,0,0,0,0,0,0,0,0,0,0,0,0,0,0,0,0,0,0,0,0,0,0
0,0,0,0,0,0,0,0,0,0,0,0,0,0,0,0,0,0,0,0,0,0,0,0,0,0,0,0,0,0,45,0,0,0,0,0,0,0,0
0,0,0,0,0,0,0,0,0,0,0,0,0,0,0,0,0,0,0,0,0,0,0,0,0,0,0,0,0,0,0,0,0,0,0,0,0,0,0
0,0,0,0,0,0,0,0,0,0,0,0,0,0,0,0,0,0,0,0,45,0,0,45,0,0,0,0,45,0,0,0,45,0,0,38,0,0,0
0,0,0,0,0,0,0,0,0,0,0,0,0,0,45,45,45,45,0,45,0,45,0,0,1,0,0,0,0,0,0,45,0,0,45,0,0,0,0
0,0,0,0,0,0,0,0,0,0,0,0,0,45,21,21,21,21,9,0,0,0,0,0,0,0,0,0,1,0,45,45,0,0,45,0,0,0,0
0,0,0,0,0,0,0,0,0,0,0,0,9,21,21,21,21,21,21,0,0,0,0,0,0,4,4,4,4,0,45,0,45,0,0,0,0,45,0
0,0,0,0,0,0,0,0,0,0,0,9,21,20,21,21,0,6,21,21,0,0,0,75,21,21,6,6,6,21,0,0,0,0,0,0,0,38,0
0,0,0,0,0,0,0,0,0,0,9,21,21,21,21,21,21,21,21,21,50,64,0,75,21,21,6,6,38,21,21,3,45,0,45,0,38,38,0
0,0,0,0,0,0,0,0,0,0,45,21,21,21,21,0,0,6,20,21,21,21,50,0,62,21,21,14,38,42,21,21,0,38,0,38,0,0,0
0,0,0,0,0,0,0,0,9,0,0,21,21,21,14,21,21,21,21,21,21,45,16,0,21,21,6,14,6,21,21,0,0,0,39,0,38,38,0
0,0,0,0,0,0,0,0,9,0,21,21,21,21,14,21,21,21,21,21,20,21,50,0,21,20,6,6,6,6,59,0,0,0,38,0,39,0,0
0,0,0,0,0,0,0,80,0,0,21,21,21,6,14,21,21,21,21,21,21,0,0,0,3,21,6,6,0,6,59,0,21,0,38,0,0,0,0
0,0,0,0,0,0,0,80,80,21,20,20,20,20,20,6,21,21,21,21,0,0,0,0,0,21,6,6,6,66,38,0,0,38,0,0,0,0,0
80,0,0,0,0,0,0,80,80,21,21,21,21,21,21,6,6,21,21,0,0,21,21,0,0,0,39,21,28,0,0,0,0,0,0,0,0,0,0
0,0,0,0,0,0,0,9,0,21,21,21,21,21,21,21,21,80,38,0,94,21,21,21,21,38,0,21,28,45,0,39,54,0,0,38,0,0,0
0,0,0,0,0,9,0,9,39,0,80,80,80,21,0,21,80,80,38,9,0,0,0,21,21,38,0,21,12,13,21,38,80,0,38,38,0,0,0
0,0,0,0,0,9,0,9,39,9,80,0,80,21,0,21,21,21,21,9,9,0,9,0,39,0,0,0,21,21,38,0,0,0,0,0,0,0,0
0,0,0,0,9,9,39,0,0,0,0,39,63,21,21,14,21,21,21,21,39,95,0,39,0,0,0,39,0,0,38,39,0,0,0,0,0,0,0
0,0,0,0,0,0,39,39,0,39,0,9,0,21,21,14,21,0,21,21,0,39,39,65,65,0,39,0,39,39,39,39,38,0,0,0,0,0,0
0,0,0,0,0,0,39,39,73,0,0,0,0,0,9,21,21,21,6,21,21,0,0,39,0,39,0,39,39,0,0,39,0,0,0,0,0,0,0
0,1,0,0,0,0,0,0,0,0,0,0,39,73,96,9,21,21,21,21,80,0,0,0,39,0,0,0,0,39,0,0,0,0,0,0,0,0,0
0,0,0,0,0,0,0,0,0,0,0,0,0,0,0,9,21,21,21,21,38,0,0,0,0,0,0,0,0,0,0,0,0,0,0,0,0,0,0
0,0,0,0,0,0,0,0,0,0,0,0,0,0,0,9,21,21,21,73,0,0,0,0,0,0,0,0,0,0,0,0,0,0,0,0,0,0,0
0,0,0,0,0,0,0,0,0,0,0,0,0,0,0,9,80,80,21,38,0,0,0,0,0,0,0,0,0,0,0,0,0,0,0,0,0,0,0
0,0,0,0,0,0,0,0,0,0,0,0,0,0,0,0,41,39,73,0,0,0,0,0,0,0,0,0,0,0,39,0,0,0,0,0,0,0,0
0,0,0,0,0,0,0,0,0,0,0,0,0,0,0,0,0,0,0,0,0,0,0,0,0,0,0,0,0,0,0,0,0,0,0,0,0,0,0
0,0,0,0,0,0,0,0,0,0,0,0,0,0,0,0,0,0,0,0,0,0,0,0,0,0,0,0,0,0,0,0,0,0,0,0,0,0,0
0,0,0,0,0,0,0,0,0,0,0,0,0,0,0,0,0,0,0,0,0,0,0,0,0,0,0,0,0,0,0,0,0,0,0,0,0,0,0
endlayer

layer
0,0,0,0,0,0,0,0,0,0,0,0,0,0,0,0,0,0,0,0,0,0,0,0,0,0,0,0,0,0,0,0,0,0,0,0,0,0,0
0,0,0,0,0,0,0,0,0,0,0,0,0,0,0,0,0,0,0,0,0,0,0,0,0,0,0,0,0,0,0,0,0,0,0,0,0,0,0
0,0,0,0,0,0,0,0,0,0,0,0,0,0,0,0,0,0,0,0,0,0,0,0,0,0,0,0,0,0,0,0,0,0,0,0,0,0,0
0,0,0,0,0,0,0,0,0,0,0,0,0,0,0,0,0,0,0,0,0,0,0,0,0,0,0,0,0,0,45,0,0,45,0,0,0,0,0
0,0,0,0,0,0,0,0,0,0,0,0,0,0,0,0,0,0,0,0,0,0,0,0,0,0,0,45,0,0,0,0,0,0,0,0,0,0,0
0,0,0,0,0,0,0,0,0,0,0,0,0,0,0,0,0,0,0,0,45,0,0,45,45,0,0,0,45,0,0,0,45,0,0,38,0,0,0
0,0,0,0,0,0,0,0,0,0,0,0,0,0,0,45,45,0,0,45,0,45,0,0,0,0,0,0,0,0,0,45,0,0,45,0,0,0,0
0,0,0,0,0,0,0,0,0,0,0,0,0,52,21,21,21,0,9,0,0,0,0,0,0,0,0,0,0,0,45,45,0,0,45,0,0,0,0
0,0,0,0,0,0,0,0,0,0,0,0,0,45,21,21,21,21,9,0,0,0,54,21,0,4,5,4,21,21,45,0,45,0,0,0,0,45,0
0,0,0,0,0,0,0,0,0,0,0,9,21,21,21,21,21,21,21,21,21,21,21,21,21,21,6,6,6,43,0,0,0,0,0,0,0,38,0
0,0,0,0,0,0,0,0,0,0,0,0,21,21,14,21,21,21,21,21,21,21,21,21,21,6,20,6,38,0,0,0,45,0,45,0,38,38,0
0,0,0,0,0,0,0,0,0,0,45,0,21,21,14,21,21,21,21,21,21,21,21,21,21,20,6,6,6,21,21,0,0,38,0,38,0,0,0
0,0,0,0,0,0,0,0,9,21,21,21,20,20,6,21,21,21,21,21,21,21,16,0,21,20,6,6,6,6,21,21,0,0,39,0,38,38,0
0,0,0,0,0,0,0,0,9,21,21,21,21,21,0,21,21,21,21,21,21,41,0,0,21,21,6,6,6,6,59,0,0,0,38,0,39,0,0
0,0,0,0,0,0,0,9,21,21,14,21,21,21,0,49,49,21,21,21,0,0,0,0,0,21,6,6,0,6,38,0,0,0,38,0,0,0,0
0,0,0,0,0,0,0,80,21,21,6,21,21,21,49,6,0,49,21,69,0,0,0,0,0,21,6,6,6,66,38,0,0,38,0,0,0,0,0
80,0,0,0,0,0,0,9,21,97,97,97,21,21,49,6,6,49,49,0,0,0,3,0,0,0,21,28,39,0,0,0,0,0,0,0,0,0,0
0,0,0,0,0,0,0,9,97,97,21,21,21,21,49,49,49,49,49,80,94,0,0,3,3,0,21,28,45,0,0,39,0,0,0,38,0,0,0
0,0,0,0,0,9,0,9,39,0,80,80,80,97,0,49,49,49,80,9,0,0,0,0,0,0,21,12,13,0,0,38,0,0,38,38,0,0,0
0,0,0,0,0,9,0,9,39,9,80,80,80,97,97,21,21,21,0,9,9,0,9,0,39,0,0,21,21,0,38,0,0,0,0,0,0,0,0
0,0,0,0,9,9,39,0,0,0,41,39,80,97,21,21,21,21,21,80,39,95,0,39,0,0,0,39,0,0,38,39,0,0,0,0,0,0,0
0,0,0,0,0,0,39,39,0,39,0,9,80,21,21,6,20,21,21,21,0,39,39,65,65,0,39,0,39,39,39,39,38,0,0,0,0,0,0
0,0,0,0,0,0,39,39,73,0,0,52,21,21,21,14,21,21,21,21,0,0,1,39,0,39,0,39,39,0,0,39,0,0,0,0,0,0,0
0,0,0,0,0,0,0,0,0,0,0,0,39,73,21,21,21,21,80,21,0,0,0,0,39,0,39,0,0,39,0,0,0,0,0,0,0,0,0
0,0,0,0,0,0,0,0,0,0,0,0,0,0,41,80,21,80,21,21,0,0,0,0,0,0,0,0,0,0,0,0,0,0,0,0,0,0,0
0,0,0,0,0,0,0,0,0,0,0,0,0,0,0,0,21,21,21,0,0,0,0,0,0,0,0,0,0,0,0,0,0,0,0,0,0,0,0
0,0,0,0,0,0,0,0,0,0,0,0,0,0,0,9,80,21,21,87,0,1,0,0,0,0,0,0,0,0,0,0,0,0,0,0,0,0,0
0,0,0,0,0,0,0,0,0,0,0,0,0,0,0,0,0,39,73,0,0,0,0,0,0,0,0,0,0,0,39,0,0,0,0,0,0,0,0
0,0,0,0,0,0,0,0,0,0,0,0,0,0,0,0,0,0,0,0,0,0,0,0,0,0,0,0,0,0,0,0,0,0,0,0,0,0,0
0,0,0,0,0,0,0,0,0,0,0,0,0,0,0,0,0,0,0,0,0,0,0,0,0,0,0,0,0,0,0,0,0,0,0,0,0,0,0
0,0,0,0,0,0,0,0,0,0,0,0,0,0,0,0,0,0,0,0,0,0,0,0,0,0,0,0,0,0,0,0,0,0,0,0,0,0,0
endlayer

layer
0,0,0,0,0,0,0,0,0,0,0,0,0,0,0,0,0,0,0,0,0,0,0,0,0,0,0,0,0,0,0,0,0,0,0,0,0,0,0
0,0,0,0,0,0,0,0,0,0,0,0,0,0,0,0,0,0,0,0,0,0,0,0,0,0,0,0,0,0,0,0,0,0,0,0,0,0,0
0,0,0,0,0,0,0,0,0,0,0,0,0,0,0,0,0,0,0,0,0,0,0,0,0,0,0,0,0,0,0,0,0,0,0,0,0,0,0
0,0,0,0,0,0,0,0,0,0,0,0,0,0,0,0,0,0,0,0,0,0,0,0,0,0,0,0,0,0,45,0,0,45,0,0,0,0,0
0,0,0,0,0,0,0,0,0,0,0,0,0,0,0,0,0,0,0,0,0,0,0,0,45,0,0,45,0,0,0,0,0,0,0,0,38,0,0
0,0,0,0,0,0,0,0,0,0,0,0,0,0,0,0,0,45,0,0,45,0,0,45,45,0,0,0,45,0,0,0,45,0,0,38,0,0,0
0,0,0,0,0,0,0,0,0,0,0,0,0,0,0,45,54,0,0,45,0,45,0,0,1,0,1,1,0,0,0,45,0,0,45,0,0,0,0
0,0,0,0,0,0,0,0,0,0,0,0,0,0,9,21,21,0,9,0,0,0,0,0,0,0,0,4,0,0,45,45,0,0,45,0,0,0,0
0,0,0,0,0,0,0,0,0,0,0,0,0,45,80,21,21,0,9,54,0,21,21,4,4,5,5,4,0,38,45,0,45,0,0,0,0,45,0
0,0,0,0,0,0,0,0,0,0,0,9,21,21,21,21,21,21,21,21,21,21,21,21,21,6,6,6,6,43,21,0,0,0,0,0,0,38,0
0,0,0,0,0,0,0,0,0,0,0,21,21,21,21,80,21,21,21,21,21,21,20,20,20,20,6,6,6,21,0,0,45,0,45,0,38,38,0
0,0,0,0,0,0,0,0,0,0,45,21,14,21,21,21,21,21,0,21,21,21,21,21,21,6,6,6,6,6,21,21,21,38,0,38,0,0,0
0,0,0,0,0,0,0,0,9,21,21,20,21,21,21,21,21,21,0,21,21,21,16,0,21,0,6,6,6,6,21,21,0,0,39,0,38,38,0
0,0,0,0,0,0,0,0,9,21,21,21,21,21,49,49,49,21,21,21,3,0,0,0,21,21,6,6,6,6,6,0,0,0,38,0,39,0,0
0,0,0,0,0,0,0,0,0,21,21,21,21,49,49,49,49,49,21,21,0,0,0,0,0,21,20,6,20,6,38,0,0,0,38,0,0,0,0
0,0,0,0,0,0,0,9,21,21,21,21,21,49,49,6,0,49,49,0,0,0,0,0,0,21,28,74,6,98,38,0,0,38,0,0,0,0,0
3,0,0,0,0,0,0,52,21,21,21,21,21,49,49,6,6,49,49,0,0,0,0,0,0,21,28,0,46,32,0,0,0,0,0,0,0,0,0
0,0,0,0,0,0,0,9,21,97,80,80,80,49,49,49,49,49,49,38,9,0,0,0,0,21,28,45,0,0,0,39,0,0,0,38,0,0,0
0,0,0,0,0,9,0,9,39,21,80,80,80,49,49,49,49,49,38,9,0,0,0,0,0,21,12,13,0,0,0,38,0,0,38,38,0,0,0
0,0,0,0,0,9,0,9,39,9,80,80,80,80,21,21,80,0,0,9,9,0,9,0,39,21,21,21,0,0,38,0,0,0,0,0,0,0,0
0,0,0,0,9,9,39,0,0,0,72,39,80,97,21,21,0,80,80,0,39,95,0,39,0,0,0,39,0,0,38,39,0,0,0,0,0,0,0
0,0,0,0,0,0,39,39,0,39,87,0,80,21,21,21,21,21,80,80,0,39,39,65,65,0,39,0,39,39,39,39,38,0,0,0,0,0,0
0,0,0,0,0,0,39,39,73,0,0,0,9,21,21,21,21,6,21,21,0,0,0,39,0,39,0,39,39,0,0,39,0,0,0,0,0,0,0
0,0,0,0,0,0,0,0,0,0,0,0,0,39,0,80,21,21,80,80,0,0,0,1,39,39,39,0,0,39,0,0,0,0,0,0,0,0,0
0,0,0,0,0,0,0,0,0,0,0,0,0,0,52,80,21,21,21,4,0,0,0,0,0,0,0,0,0,0,0,0,0,0,0,0,0,0,0
0,0,0,0,0,0,0,0,0,0,0,0,0,0,0,0,0,21,21,0,0,0,0,0,0,0,73,0,0,0,0,0,0,0,0,0,0,0,0
0,0,0,0,0,0,0,0,0,0,0,0,0,0,0,0,9,21,87,0,0,0,0,0,0,0,0,0,0,0,0,0,0,0,0,0,0,0,0
0,0,0,0,0,0,0,0,0,0,0,0,0,0,0,0,0,39,0,0,1,0,0,0,0,0,0,0,0,0,39,0,38,0,0,0,0,0,0
0,0,0,0,0,0,0,0,0,0,0,0,0,0,0,0,0,0,0,0,0,1,1,0,0,0,0,0,0,0,0,38,0,0,0,0,0,0,0
0,0,0,0,0,0,0,0,0,0,0,0,0,0,0,0,0,0,0,0,0,0,0,0,0,0,0,1,0,0,0,0,0,0,0,0,0,0,0
0,0,0,0,0,0,0,0,0,0,0,0,0,0,0,0,0,0,0,0,0,0,0,0,0,0,0,0,0,0,0,0,0,0,0,0,0,0,0
endlayer

layer
0,0,0,0,0,0,0,0,0,0,0,0,0,0,0,0,0,0,0,0,0,0,0,0,0,0,0,0,0,0,0,0,0,0,0,0,0,0,0
0,0,0,0,0,0,0,0,0,0,0,0,0,0,0,0,0,0,0,0,0,0,0,0,0,0,0,0,0,0,0,0,0,0,0,0,0,0,0
0,0,0,0,0,0,0,0,0,0,0,0,0,0,0,0,0,0,0,0,0,0,0,0,0,0,0,0,0,0,0,0,0,0,0,0,0,0,0
0,0,0,0,0,0,0,0,0,0,0,0,0,0,0,0,0,0,0,0,0,0,0,0,0,0,0,0,0,0,45,0,0,45,0,0,0,0,0
0,0,0,0,0,0,0,0,0,0,0,0,0,0,0,0,0,0,0,0,0,0,0,0,45,45,0,45,0,0,0,0,0,0,0,0,38,0,0
0,0,0,0,0,0,0,0,0,0,0,0,0,0,0,0,0,45,0,0,45,0,0,45,45,0,0,0,45,45,0,0,45,0,0,38,0,0,0
0,0,0,0,0,0,0,0,0,0,0,0,0,0,0,0,9,0,0,45,0,45,21,0,0,0,0,0,0,0,0,45,0,0,45,0,0,0,0
0,0,0,0,0,0,0,0,0,0,0,0,0,0,0,0,0,0,9,0,0,0,21,0,0,0,0,21,21,0,45,45,0,0,45,0,0,0,0
0,0,0,0,0,0,0,0,0,0,0,0,0,0,9,21,45,0,9,39,21,21,14,4,21,4,5,21,21,38,45,0,45,0,0,0,0,45,0
0,0,0,0,0,0,0,0,0,0,0,0,3,0,80,21,21,80,0,21,21,21,14,4,21,6,6,6,6,54,21,53,0,0,0,0,0,38,0
0,0,0,0,0,0,0,0,0,0,0,0,21,21,80,80,21,21,21,21,21,21,21,21,6,0,0,6,6,6,21,0,0,21,45,0,38,38,0
0,0,0,0,0,0,0,0,0,0,0,45,21,21,80,21,21,21,0,21,21,21,21,21,21,6,21,21,6,20,20,20,21,21,21,38,0,0,0
0,0,0,0,0,0,0,0,0,9,21,21,21,21,21,21,21,21,0,21,21,21,16,0,21,0,17,14,20,6,21,21,0,0,39,0,38,38,0
0,0,0,0,0,0,0,0,52,21,21,21,21,49,49,49,49,21,21,21,41,0,0,0,21,0,0,14,6,6,6,21,21,0,38,0,39,0,39
0,0,0,0,0,0,0,0,0,21,21,21,21,49,49,49,49,49,21,9,0,0,0,21,21,6,74,74,6,6,0,0,0,0,38,0,0,0,0
0,0,0,0,0,0,0,0,16,21,21,21,21,49,49,6,0,49,49,0,0,0,0,0,21,11,0,91,6,6,38,0,0,38,0,0,0,0,0
0,0,0,0,0,0,0,9,80,80,21,21,21,49,49,6,6,49,49,0,0,0,0,0,21,11,0,0,46,21,0,0,0,0,0,0,0,0,0
0,0,0,0,0,0,0,9,80,80,97,80,80,49,49,49,49,49,94,0,9,0,0,0,21,11,45,45,0,0,0,39,0,0,0,38,0,0,0
0,0,0,0,0,9,0,9,21,21,80,80,80,80,49,49,49,49,38,9,0,0,0,0,21,11,21,21,0,0,0,38,0,0,38,38,0,0,0
0,0,0,0,0,9,0,9,39,21,80,80,80,80,21,80,80,80,0,9,9,0,9,0,39,21,0,0,0,0,38,0,0,0,0,0,0,0,0
0,0,0,0,9,9,39,0,0,41,72,73,80,21,21,80,80,80,54,0,39,95,0,39,0,0,0,39,0,0,38,39,0,0,0,0,0,0,0
0,0,0,0,0,0,39,39,0,39,87,0,0,80,39,39,80,80,80,0,0,39,39,65,65,0,39,0,39,39,39,39,38,0,0,0,0,0,0
0,0,0,0,0,0,39,39,73,0,0,0,0,0,0,0,80,6,21,80,0,0,0,39,0,39,0,39,39,0,0,39,0,0,0,0,0,0,0
0,0,0,0,0,0,0,0,0,0,0,0,0,0,0,0,80,80,21,80,0,0,0,0,39,39,39,0,39,39,0,0,0,0,0,0,0,0,0
0,0,0,0,0,0,0,0,0,0,0,0,0,0,0,3,71,21,21,87,0,0,0,0,1,0,1,0,0,0,0,0,0,0,0,0,0,0,0
0,0,0,0,0,0,0,0,0,0,0,0,0,0,0,0,0,73,73,0,0,0,0,0,0,0,73,0,0,0,0,0,0,0,0,0,0,0,0
0,0,0,0,0,0,0,0,0,0,0,0,0,0,0,0,0,0,0,0,0,0,0,0,0,0,0,0,0,0,0,0,0,0,0,0,0,0,0
0,0,0,0,0,0,0,0,0,0,0,0,0,0,0,0,0,0,0,0,0,0,0,0,0,0,0,0,0,0,39,0,38,0,0,0,0,0,0
0,0,0,0,0,0,0,0,0,0,0,0,0,0,0,0,0,0,0,0,0,0,0,0,0,0,0,0,0,0,0,38,0,0,0,0,0,0,0
0,0,0,0,0,0,0,0,0,0,0,0,0,0,0,0,0,0,0,0,0,0,0,0,0,0,0,0,39,0,39,0,0,0,0,0,0,0,0
0,0,0,0,0,0,0,0,0,0,0,0,0,0,0,0,0,0,0,0,0,0,0,0,0,0,0,0,0,0,0,0,0,0,0,0,0,0,0
endlayer

layer
0,0,0,0,0,0,0,0,0,0,0,0,0,0,0,0,0,0,0,0,0,0,0,0,0,0,0,0,0,0,0,0,0,0,0,0,0,0,0
0,0,0,0,0,0,0,0,0,0,0,0,0,0,0,0,0,0,0,0,0,0,0,0,0,0,0,0,0,0,0,0,0,0,0,0,0,0,0
0,0,0,0,0,0,0,0,0,0,0,0,0,0,0,0,0,0,0,0,0,0,0,0,0,0,0,0,0,0,0,0,0,0,0,0,0,0,0
0,0,0,0,0,0,0,0,0,0,0,0,0,0,0,0,0,0,0,0,0,0,0,0,0,0,0,0,0,0,45,0,0,45,0,0,0,0,0
0,0,0,0,0,0,0,0,0,0,0,0,0,0,0,0,0,0,0,0,0,0,0,0,45,45,0,45,0,0,0,0,0,0,0,0,38,0,0
0,0,0,0,0,0,0,0,0,0,0,0,0,0,0,0,0,45,0,0,45,0,0,45,45,0,0,0,45,45,0,0,45,0,0,38,0,0,0
0,0,0,0,0,0,0,0,0,0,0,0,0,0,0,0,9,0,0,45,0,45,45,21,21,0,21,0,0,0,0,45,0,0,45,0,0,0,0
0,0,0,0,0,0,0,0,0,0,0,0,0,0,0,54,65,0,9,0,0,21,21,21,21,21,21,21,21,0,45,45,0,0,45,0,0,0,0
0,0,0,0,0,0,0,0,0,0,0,0,0,0,9,80,45,0,9,39,0,21,21,4,21,21,21,21,21,0,0,21,45,0,0,0,0,45,0
0,0,0,0,0,0,0,0,0,0,0,0,0,52,80,80,80,38,0,65,21,21,21,0,6,6,0,6,6,6,38,21,21,21,0,54,0,38,0
0,0,0,0,0,0,0,0,0,0,0,0,0,0,80,80,80,69,0,21,21,21,21,21,6,21,21,6,6,6,0,21,21,21,21,21,38,38,0
0,0,0,0,0,0,0,0,0,0,0,54,21,21,80,80,21,21,21,21,21,0,0,0,21,6,17,17,17,20,38,6,20,20,20,21,80,0,0
0,0,0,0,0,0,0,0,0,0,9,21,21,21,21,21,21,21,21,21,0,0,16,0,0,0,17,17,14,6,0,0,21,21,0,0,38,38,0
0,0,0,0,0,0,0,0,0,54,21,21,21,21,21,21,97,21,21,41,0,0,0,0,0,0,74,74,6,14,6,0,0,21,38,0,39,0,39
0,0,0,0,0,0,0,0,0,21,21,21,21,21,80,49,49,21,80,9,0,0,0,21,21,6,9,9,6,20,20,21,21,0,38,0,0,0,0
0,0,0,0,0,0,0,0,16,21,21,21,21,21,49,6,0,49,80,0,0,0,0,0,21,0,0,0,6,6,0,0,21,38,0,0,0,0,0
0,0,0,0,0,0,0,9,80,80,21,21,21,80,49,6,49,49,65,0,0,0,0,0,21,21,0,0,14,21,0,0,0,0,0,0,0,0,0
0,0,0,0,0,0,0,9,21,80,21,21,21,80,80,49,49,80,9,0,9,0,0,0,21,21,0,0,21,21,21,39,0,0,0,38,0,0,0
0,0,0,0,0,9,0,0,21,21,80,21,21,80,80,80,80,80,0,9,0,0,0,0,21,21,21,21,0,41,0,38,0,0,38,38,0,0,0
0,0,0,0,0,9,0,9,80,21,80,80,80,80,80,80,80,80,0,9,9,0,9,0,39,0,0,0,0,0,38,0,0,0,0,0,0,0,0
0,0,0,0,9,9,39,0,0,0,72,73,73,0,0,0,0,3,0,0,39,95,0,39,0,0,0,39,0,0,38,39,0,0,0,0,0,0,0
0,0,0,0,0,0,39,39,0,39,87,0,0,0,0,0,0,3,99,0,0,39,39,65,65,0,39,0,39,39,39,39,38,0,0,0,0,0,0
0,0,0,0,0,0,39,39,73,0,0,0,0,0,0,0,0,21,21,87,0,0,0,39,0,39,0,39,39,0,0,39,1,0,0,0,0,0,0
0,0,0,0,0,0,0,0,0,0,0,0,0,0,0,0,0,21,80,80,0,0,0,0,39,39,39,0,39,39,0,0,0,0,0,0,0,0,0
0,0,0,0,0,0,0,0,0,0,0,0,0,0,0,0,0,0,0,41,0,0,0,0,0,0,0,0,0,0,0,0,0,0,0,0,0,0,0
0,0,0,0,0,0,0,0,0,0,0,0,0,0,0,0,0,0,0,0,0,0,0,0,0,0,73,0,0,0,0,0,0,0,0,0,0,0,0
0,0,0,0,0,0,0,0,0,0,0,0,0,0,0,0,0,0,0,0,0,0,0,0,0,0,0,39,0,0,0,0,38,0,0,0,0,0,0
0,0,0,0,0,1,0,0,0,0,0,0,0,0,0,0,0,0,0,0,0,0,0,0,0,0,0,0,0,0,39,0,38,0,0,0,0,0,0
0,0,0,0,0,0,0,0,0,0,0,0,0,0,0,0,0,0,0,0,0,0,0,0,0,0,0,0,0,0,0,38,0,0,0,0,0,0,0
0,0,0,0,0,0,0,0,0,0,0,0,0,0,0,0,0,0,0,0,0,0,0,0,0,0,0,0,39,0,39,0,0,0,0,0,0,0,0
0,0,0,0,0,0,0,0,0,0,0,0,0,0,0,0,0,0,0,0,0,0,0,0,0,0,0,0,0,0,0,0,0,0,0,0,0,0,0
endlayer

layer
0,0,0,0,0,0,0,0,0,0,0,0,0,0,0,0,0,0,0,0,0,0,0,0,0,0,0,0,0,0,0,0,0,0,0,0,0,0,0
0,0,0,0,0,0,0,0,0,0,0,0,0,0,0,0,0,0,0,0,0,0,0,0,0,0,0,0,0,0,0,0,0,0,0,0,0,0,0
0,0,0,0,0,0,0,0,0,0,0,0,0,0,0,0,0,0,0,0,0,0,0,0,0,0,0,0,0,0,0,0,0,0,0,0,0,0,0
0,0,0,0,0,0,0,0,0,0,0,0,0,0,0,0,0,0,0,0,0,0,0,0,0,0,0,0,0,0,45,0,0,45,0,0,0,0,0
0,0,0,0,0,0,0,0,0,0,0,0,0,0,0,0,0,0,0,0,0,0,0,0,45,45,0,45,0,0,0,0,0,0,0,0,38,0,0
0,0,0,0,0,0,0,0,0,0,0,0,0,0,0,0,0,45,0,0,45,0,0,0,45,0,0,0,45,45,0,0,45,0,0,38,0,0,0
0,0,0,0,0,0,0,0,0,0,0,0,0,0,0,0,9,0,0,45,21,45,45,16,21,0,0,0,0,0,0,45,0,0,45,0,0,0,0
0,0,0,0,0,0,0,0,0,0,0,0,0,0,0,0,65,0,9,21,21,80,21,45,21,0,21,21,21,21,45,0,0,0,45,0,0,0,0
0,0,0,0,0,0,0,0,0,0,0,0,0,0,9,80,0,0,9,39,21,21,21,21,21,0,21,0,6,21,21,45,0,0,21,0,0,45,0
0,0,0,0,0,0,0,0,0,0,0,0,0,9,80,80,80,38,0,39,65,80,21,21,6,6,0,6,6,6,38,21,21,21,21,54,0,38,0
0,0,0,0,0,0,0,0,0,0,0,0,0,0,80,80,80,0,0,3,80,9,21,21,6,0,17,17,6,20,0,21,0,21,21,21,38,38,0
0,0,0,0,0,0,0,0,0,0,0,0,0,0,0,65,39,0,0,80,0,0,0,0,21,17,0,39,26,0,0,21,0,21,21,21,38,0,0
0,0,0,0,0,0,0,0,0,0,0,9,21,45,80,38,39,80,80,0,0,0,16,0,0,20,38,38,26,14,6,21,0,21,21,21,38,38,0
0,0,0,0,0,0,0,0,0,0,45,21,21,21,21,80,80,80,80,53,0,0,0,21,6,20,39,45,6,20,20,21,21,21,0,0,39,0,39
0,0,0,0,0,0,0,0,0,21,21,21,21,21,80,49,49,80,0,9,0,0,0,65,6,0,9,9,6,20,20,20,21,0,42,0,0,0,0
0,0,0,0,0,0,0,0,16,21,21,21,21,21,49,49,49,49,9,0,0,0,0,21,21,0,0,0,6,20,21,21,21,0,0,0,0,0,0
0,0,0,0,0,0,0,0,21,80,80,80,21,80,49,49,49,39,65,0,0,0,21,21,21,21,0,0,6,20,0,21,21,0,0,0,0,0,0
0,0,0,0,0,0,0,0,21,80,80,80,80,80,80,49,0,0,9,0,9,0,0,21,21,6,0,6,20,6,38,39,0,0,0,38,0,0,0
0,0,0,0,0,9,0,80,21,80,80,80,80,80,80,0,3,0,0,9,0,0,0,0,21,21,6,21,21,21,0,38,0,0,38,38,0,0,0
0,0,0,0,0,9,0,41,21,80,80,80,80,0,0,0,0,3,0,9,9,0,9,0,39,0,21,21,0,0,38,0,0,0,0,0,0,0,0
0,0,0,0,9,9,39,0,0,80,72,73,0,0,0,0,0,0,0,0,39,95,0,39,0,0,21,39,0,0,38,39,0,0,0,0,0,0,0
0,0,0,0,0,0,39,39,0,39,87,0,0,0,0,0,0,0,99,0,0,39,39,65,65,0,39,0,39,39,39,39,38,0,0,38,0,0,0
0,0,0,0,0,0,39,39,73,0,0,0,0,0,0,0,0,80,80,87,0,0,0,39,0,39,0,39,39,0,0,39,39,0,0,0,0,0,0
0,0,0,0,0,0,0,0,0,0,0,0,0,0,0,0,0,80,80,53,0,0,0,0,39,39,39,0,39,39,0,0,0,0,0,0,0,0,0
0,0,0,0,0,0,0,0,0,0,0,0,0,0,0,0,0,0,0,0,0,0,0,0,0,9,0,0,0,0,0,0,0,0,0,39,0,0,0
0,0,0,0,0,0,0,0,0,0,0,0,0,0,0,0,0,0,0,0,0,0,0,0,0,0,73,0,0,0,39,0,38,0,0,0,0,0,0
0,0,0,0,0,0,0,0,0,0,0,0,0,0,0,0,0,0,0,0,0,0,0,0,0,0,0,65,39,39,0,0,38,0,0,0,0,0,0
0,0,0,0,0,0,0,0,0,0,0,0,0,0,0,0,0,0,0,0,1,0,0,0,0,0,0,0,0,0,39,0,38,0,0,0,0,0,0
0,0,0,0,0,0,0,0,0,0,0,0,0,0,0,0,0,0,0,0,0,0,0,0,0,0,0,0,0,0,0,38,0,0,0,0,0,0,0
0,0,0,0,0,0,0,0,0,0,0,0,0,0,0,0,0,0,0,0,0,0,0,0,0,0,0,0,39,0,39,0,0,0,0,0,0,0,0
0,0,0,0,0,0,0,0,0,0,0,0,0,0,0,0,0,0,0,0,0,0,0,0,0,0,0,0,0,0,0,0,0,0,0,0,0,0,0
endlayer

layer
0,0,0,0,0,0,0,0,0,0,0,0,0,0,0,0,0,0,0,0,0,0,0,0,1,0,0,0,0,0,0,0,0,0,0,0,0,0,0
0,0,0,0,0,0,0,0,0,0,0,0,0,0,0,0,0,0,0,0,0,0,0,0,0,0,0,0,0,0,0,0,0,0,0,0,0,0,0
0,0,0,0,0,0,0,0,0,0,0,0,0,0,0,0,0,0,0,0,0,0,0,0,0,0,0,0,0,0,0,0,0,0,0,0,0,0,0
0,0,0,0,0,0,0,0,0,0,0,0,0,0,0,1,0,0,1,0,0,1,1,0,45,0,0,0,0,45,45,0,0,45,0,0,0,0,0
0,0,0,0,0,0,0,0,0,0,0,0,0,0,0,0,0,0,0,0,0,0,0,0,45,45,0,45,0,0,0,0,0,0,0,0,38,0,0
0,0,0,0,0,0,0,0,0,0,0,0,0,0,0,0,0,45,0,0,54,0,0,0,0,0,0,0,45,45,0,0,45,0,0,38,0,0,0
0,0,0,0,0,0,0,0,0,0,0,0,0,0,0,0,9,0,0,45,21,0,45,45,45,0,21,0,21,0,0,45,0,0,45,0,38,0,0
0,0,0,0,0,0,0,0,0,0,0,0,0,0,0,0,65,0,9,21,21,80,80,21,21,21,21,21,21,0,54,21,0,0,0,0,0,0,0
0,0,0,0,0,0,0,0,0,0,0,0,0,0,9,80,0,0,9,39,39,80,21,21,21,21,21,21,6,21,21,21,0,0,0,0,0,45,0
0,0,0,0,0,0,0,0,0,0,0,0,0,9,80,80,80,38,0,39,39,41,21,21,6,20,20,6,6,6,38,21,21,21,0,38,0,38,0
0,0,0,0,0,0,0,0,0,0,0,0,0,0,39,80,39,0,0,0,0,9,21,21,6,0,21,21,6,17,0,0,0,21,21,53,38,38,0
0,0,0,0,0,0,0,0,0,0,0,0,0,0,0,65,0,0,0,0,0,0,0,0,0,0,21,39,39,26,0,0,0,0,21,0,38,0,0
0,0,0,0,0,0,0,0,0,0,0,0,54,45,3,0,39,0,0,0,0,0,16,0,6,6,38,38,0,26,20,38,0,21,21,39,0,38,0
0,0,0,0,0,0,0,0,0,0,0,3,80,80,80,3,0,3,0,0,0,0,0,14,14,6,39,45,9,14,6,0,0,21,0,0,39,0,39
0,0,0,0,0,0,0,0,0,80,80,21,80,80,80,45,0,0,0,9,0,0,0,39,6,0,9,0,6,20,21,0,20,20,21,0,0,0,0
0,0,0,0,0,0,0,0,16,80,80,80,80,80,80,0,0,9,9,0,0,21,21,21,0,0,0,0,6,20,21,21,21,21,21,0,0,0,0
0,0,0,0,0,0,0,0,21,80,80,80,80,80,80,38,3,39,65,0,0,21,21,21,0,0,21,21,6,14,21,21,21,0,0,0,0,0,0
0,0,0,0,0,0,0,0,21,80,80,80,80,80,87,0,0,0,9,0,9,0,21,21,21,6,6,6,20,6,21,21,0,0,0,38,0,0,0
0,0,0,0,0,9,0,80,21,80,80,80,80,0,0,0,0,0,0,9,0,0,21,21,21,21,6,21,21,21,21,38,0,0,38,38,0,0,0
0,0,0,0,0,9,0,80,21,80,80,80,38,0,0,0,0,0,0,9,9,0,9,21,39,0,21,0,0,21,38,0,0,0,0,1,0,0,0
0,0,0,0,9,9,39,0,80,80,87,0,0,0,0,0,0,0,0,0,39,95,0,39,0,0,21,21,21,21,38,39,0,0,0,0,0,0,0
0,0,0,0,0,0,39,39,0,73,87,0,0,0,0,0,0,0,99,0,0,39,39,65,65,0,39,0,39,39,39,39,38,0,0,38,0,0,0
0,0,0,0,0,0,39,39,73,73,0,0,0,0,0,0,0,80,80,87,0,0,0,39,0,39,0,39,39,0,0,39,39,39,0,0,0,45,0
0,0,0,0,0,0,0,0,0,0,0,0,0,0,0,0,0,80,80,87,0,0,0,0,39,39,39,0,39,39,0,0,0,0,0,0,38,0,0
0,0,0,0,0,0,0,0,0,0,0,0,0,0,0,0,0,0,41,0,0,0,0,0,0,9,0,0,0,0,0,39,0,0,0,39,0,0,0
0,0,0,0,0,0,0,0,0,0,0,0,0,0,0,0,0,0,0,0,0,0,0,0,0,0,73,0,0,0,39,0,38,0,0,0,0,0,0
0,0,0,0,0,0,0,0,0,0,0,0,0,0,0,0,0,0,0,0,0,0,0,0,0,0,0,65,39,39,0,0,38,0,0,0,0,0,0
0,0,0,0,0,0,0,0,0,0,0,0,0,0,0,0,0,0,0,0,0,0,0,0,0,0,0,0,0,0,39,0,38,0,0,0,0,0,0
0,0,0,0,0,0,0,0,0,0,0,0,0,0,0,0,0,0,0,0,0,0,0,0,0,0,0,0,0,0,0,38,0,0,0,0,0,0,0
0,0,0,0,0,0,0,0,0,0,0,0,0,0,0,0,0,0,0,0,0,0,0,0,0,0,0,0,39,0,39,0,0,0,0,0,0,0,0
0,0,0,0,0,0,0,0,0,0,0,0,0,0,0,0,0,0,0,0,0,0,0,0,0,0,0,0,0,0,0,0,0,0,0,0,0,0,0
endlayer

layer
0,0,0,0,0,0,0,0,0,0,0,0,0,0,0,0,0,0,0,0,0,0,0,0,0,0,0,0,0,0,0,0,0,0,0,0,0,0,0
0,0,0,0,0,0,0,0,0,0,0,0,0,0,0,0,0,0,0,0,0,0,0,0,0,0,0,0,0,0,0,0,0,0,0,0,0,0,0
0,0,0,0,0,0,0,0,0,0,0,0,0,0,0,0,0,0,0,0,0,0,0,0,0,0,45,0,0,0,0,0,0,0,0,0,0,0,0
0,0,0,0,0,0,0,0,0,0,0,0,0,0,0,0,0,9,0,0,0,0,0,45,45,16,0,45,0,45,45,0,0,45,0,0,0,0,0
0,0,0,0,0,0,0,0,0,0,0,0,0,0,0,0,9,9,0,0,0,0,0,0,45,45,0,45,0,0,0,0,0,0,0,0,38,0,0
0,0,0,0,0,0,0,0,0,0,0,0,0,0,0,0,0,45,0,0,45,0,0,0,0,80,0,0,0,45,0,0,45,0,0,38,0,0,0
0,0,0,0,0,0,0,0,0,0,0,0,0,0,0,0,9,0,0,0,21,0,0,0,54,21,21,0,0,0,0,0,0,0,45,0,38,0,1
0,0,0,0,0,0,0,0,0,0,0,0,0,0,0,0,65,0,0,0,21,21,0,21,21,21,45,21,45,0,0,0,0,0,0,0,0,0,0
0,0,0,0,0,0,0,0,0,0,0,0,0,0,54,80,0,0,9,21,21,21,21,21,21,21,21,21,6,0,0,3,0,0,0,0,0,45,0
0,0,0,0,0,0,0,0,0,0,0,0,0,9,80,80,80,38,0,39,39,9,21,21,6,6,21,6,6,6,0,21,21,21,0,38,0,38,0
0,0,0,0,0,0,0,0,0,0,0,0,0,0,39,39,39,0,0,0,0,0,9,21,14,21,21,21,6,21,21,21,21,0,0,0,38,38,0
0,0,0,0,0,0,0,0,0,0,0,0,0,0,0,9,0,0,0,0,0,0,0,21,14,0,21,41,39,39,26,17,21,21,0,0,38,0,0
0,0,0,0,0,0,0,0,0,0,0,0,0,0,0,0,39,0,0,0,0,0,16,14,14,21,21,38,0,0,90,17,0,0,38,39,0,38,0
0,0,0,0,0,0,0,0,0,0,0,0,0,3,0,0,0,0,0,0,0,21,21,6,6,21,39,45,9,6,6,21,21,21,0,0,39,0,39
0,0,0,0,0,0,0,0,0,0,80,45,0,0,0,45,0,0,0,9,0,0,21,21,6,6,9,6,6,6,0,0,21,21,6,21,0,0,1
0,0,0,0,0,0,0,0,16,80,80,80,80,0,9,0,0,9,9,0,80,21,21,21,6,0,21,6,6,39,21,21,21,0,21,0,0,0,0
0,0,0,0,0,0,0,52,80,80,80,80,80,3,0,0,0,39,65,0,0,21,21,21,0,0,21,21,0,6,0,0,21,21,21,0,0,0,0
0,0,0,0,0,0,0,0,21,21,80,80,0,0,0,0,0,0,9,0,9,0,21,21,21,6,6,21,6,6,6,21,0,0,41,38,0,0,0
0,0,0,0,0,9,0,80,21,21,21,80,87,0,0,0,0,0,0,9,0,0,21,21,21,21,6,21,21,6,21,21,0,0,38,38,0,0,0
0,0,0,0,0,9,0,80,21,21,21,21,38,0,0,0,0,0,0,9,9,0,21,21,21,21,21,21,21,41,0,21,0,0,0,0,0,0,0
0,0,0,0,9,9,39,80,80,21,0,0,0,0,0,0,0,0,0,0,39,95,0,21,21,21,21,21,21,38,0,39,0,0,0,38,0,0,0
0,0,0,0,0,0,39,39,0,73,87,0,0,0,0,0,0,0,0,0,0,39,39,65,65,41,39,21,21,39,39,39,38,0,0,38,0,0,0
0,0,0,0,0,0,39,39,73,73,0,0,0,0,0,0,0,0,3,0,0,0,0,39,0,39,0,39,39,0,0,39,39,39,39,0,0,45,0
0,0,0,0,0,0,0,0,0,0,0,0,0,0,0,0,0,0,80,87,0,0,0,0,39,39,39,0,39,39,0,0,0,0,39,0,38,0,0
0,0,0,0,0,0,0,0,0,0,0,0,0,0,0,0,0,0,0,0,0,0,0,0,0,9,0,0,0,0,0,39,0,0,0,39,0,0,38
0,0,0,0,0,0,0,0,0,0,0,0,0,0,0,0,0,0,0,0,0,0,0,0,0,0,73,0,0,0,39,0,38,0,0,0,0,0,0
0,0,0,0,0,0,0,0,0,0,0,0,0,0,0,0,0,0,0,0,0,0,0,0,0,0,0,65,39,39,0,0,38,0,0,0,0,0,0
0,0,0,0,0,0,0,0,0,0,0,0,0,0,0,0,0,0,0,0,0,0,0,0,0,0,0,0,0,0,39,0,38,0,0,0,39,0,0
0,0,0,0,0,0,0,0,0,0,0,0,0,0,0,0,0,0,0,0,0,0,0,0,0,0,0,0,0,0,0,38,0,0,0,0,0,0,0
0,0,0,0,0,0,0,0,0,0,0,0,0,0,0,0,0,0,0,0,0,0,0,0,0,0,0,0,39,0,39,0,0,0,0,0,0,0,0
0,0,0,0,0,0,0,0,0,0,0,0,0,0,0,0,0,0,0,0,0,0,0,0,0,0,0,0,0,0,0,0,0,0,0,0,0,0,0
endlayer

layer
0,0,0,0,0,0,0,0,0,0,0,0,0,0,0,0,0,0,0,0,0,0,0,0,0,0,0,0,0,0,0,0,0,0,0,0,0,0,0
0,0,0,0,0,0,0,0,0,0,0,0,0,0,0,0,0,0,0,0,0,0,0,0,0,0,0,0,0,0,0,0,0,0,0,0,0,0,0
0,0,0,0,0,0,0,0,0,0,0,0,0,0,0,0,0,0,0,0,0,0,0,0,0,0,45,0,0,0,0,0,0,0,0,0,0,0,0
0,0,0,0,0,0,0,0,0,0,0,0,0,0,0,0,0,9,0,0,0,0,0,45,45,16,0,45,0,45,45,0,0,45,0,0,0,0,0
0,0,0,0,0,0,0,0,0,0,0,0,0,0,0,0,9,9,0,0,0,0,0,0,45,45,0,45,0,0,0,0,0,0,0,0,38,38,0
0,0,0,0,0,0,0,0,0,0,0,0,0,0,0,9,0,45,0,0,0,0,0,0,0,0,54,0,0,45,0,0,45,0,0,38,0,0,0
0,0,0,0,0,0,0,0,0,0,0,0,0,0,0,0,9,0,0,0,0,0,0,0,45,0,21,0,0,0,0,0,0,0,45,0,38,0,0
0,0,0,0,0,0,0,0,0,0,0,0,0,0,0,0,65,0,0,0,0,0,0,45,21,21,21,21,21,0,0,21,0,0,0,0,0,0,0
0,0,0,0,0,0,0,0,0,0,0,0,0,0,0,0,0,0,0,0,0,0,0,21,14,21,21,21,6,21,21,21,0,0,0,0,0,45,0
0,0,0,0,0,0,0,0,0,0,0,0,0,0,9,80,38,0,0,0,52,21,21,21,14,21,21,6,6,6,21,0,54,0,0,38,0,38,0
0,0,0,0,0,0,0,0,0,0,0,0,0,0,0,39,0,0,0,0,0,0,9,0,14,21,21,9,6,80,80,14,21,0,0,0,38,38,0
0,0,0,0,0,0,0,0,0,0,0,0,0,0,0,9,0,0,0,0,0,21,21,14,14,21,80,80,39,0,39,65,21,21,21,21,38,0,0
0,0,0,0,0,0,0,0,0,0,0,0,0,0,0,0,39,0,0,0,21,0,16,14,14,21,0,21,0,0,0,9,21,21,38,39,0,38,0
0,0,0,0,0,0,0,0,0,0,0,0,0,0,0,0,0,0,0,0,0,0,20,6,6,0,0,21,6,6,90,90,21,0,0,21,39,0,39
0,0,0,0,0,0,0,0,0,0,80,45,0,0,0,16,0,0,0,9,80,21,21,6,6,20,9,6,6,20,20,21,0,0,6,21,0,0,0
0,0,0,0,0,0,0,0,16,80,80,80,3,0,9,0,0,9,9,0,80,21,21,21,6,21,0,39,6,21,21,21,0,0,21,21,0,0,0
0,0,0,0,0,0,0,0,80,80,80,21,80,16,0,0,0,39,65,0,0,21,21,21,21,21,21,21,21,21,21,21,0,21,0,21,0,0,0
0,0,0,0,0,0,0,0,21,21,80,80,0,0,0,0,0,0,65,0,9,21,21,21,0,0,21,21,6,6,6,21,21,21,21,38,0,0,0
0,0,0,0,0,9,0,80,21,21,21,21,53,0,0,0,0,0,0,9,0,21,21,21,21,21,6,21,0,6,21,21,21,0,38,38,0,0,0
0,0,0,0,0,9,80,80,21,21,21,21,87,0,0,0,0,0,0,9,9,21,21,21,21,21,14,21,21,21,21,21,0,0,0,0,0,0,0
0,0,0,0,9,9,39,80,80,21,0,0,0,0,0,0,0,0,0,0,39,95,21,21,21,21,21,21,21,21,21,39,0,0,0,38,0,38,0
0,0,0,0,0,0,39,39,80,41,87,0,0,0,0,0,0,0,0,0,0,39,39,65,9,21,21,21,21,39,39,39,38,0,0,38,0,0,0
0,0,0,0,0,0,39,39,73,73,0,0,0,0,0,0,0,0,54,0,0,0,0,39,0,39,41,39,39,0,0,39,39,39,39,0,0,45,0
0,0,0,0,0,0,0,0,0,0,0,0,0,0,0,0,0,0,80,0,0,0,0,0,39,39,39,0,39,39,0,0,0,39,39,0,38,0,0
0,0,0,0,0,0,0,0,0,0,0,0,0,0,0,0,0,0,41,0,0,0,0,0,0,9,0,0,0,0,0,39,0,0,0,39,0,0,38
0,0,0,0,0,0,0,0,0,0,0,0,0,0,0,0,0,0,0,0,0,0,0,0,0,0,73,0,0,0,39,0,38,0,0,0,0,0,0
0,0,0,0,0,0,0,0,0,0,0,0,0,0,0,0,0,0,0,0,0,0,0,0,0,0,0,65,39,39,0,0,38,0,0,0,0,0,0
0,0,0,0,0,0,0,0,0,0,0,0,0,0,0,0,0,0,0,0,0,0,0,0,0,0,0,0,0,0,39,0,38,0,0,0,39,0,0
0,0,0,0,0,0,0,0,0,0,0,0,0,0,0,0,0,0,0,0,0,0,0,0,0,0,0,0,0,0,0,38,0,0,0,0,0,0,0
0,0,0,0,0,0,0,0,0,0,0,0,0,0,0,0,0,0,0,0,0,0,0,0,0,0,0,0,39,0,39,0,0,0,0,0,0,0,0
0,0,0,0,0,0,0,0,0,0,0,0,0,0,0,0,0,0,0,0,0,0,0,0,0,0,0,0,0,0,0,0,0,0,0,0,0,0,0
endlayer

layer
0,0,0,0,0,0,0,0,0,0,0,0,0,0,0,0,0,0,0,0,0,0,0,0,0,0,0,0,0,0,0,0,0,0,0,0,0,0,0
0,0,0,0,0,0,0,0,0,0,0,0,0,0,0,0,0,0,0,0,0,0,0,0,0,0,0,0,0,0,0,0,0,0,0,0,0,0,0
0,0,0,0,0,0,0,0,0,0,0,0,0,0,0,0,0,0,0,0,0,0,0,0,0,0,45,0,0,0,0,0,0,0,0,0,0,0,0
0,0,0,0,0,0,0,0,0,0,0,0,0,0,0,0,0,9,0,0,0,0,0,45,45,16,0,45,0,45,45,0,0,45,0,0,0,0,0
0,0,0,0,0,0,0,0,0,0,0,0,0,0,0,0,9,9,0,0,0,0,0,0,45,45,0,45,0,0,0,0,0,45,45,0,38,38,0
0,0,0,0,0,0,0,0,0,0,0,0,0,0,0,9,0,45,0,0,0,0,0,0,0,0,0,0,0,45,0,0,45,0,0,38,66,0,0
0,0,0,0,0,0,0,0,0,0,0,0,0,0,0,0,9,0,0,0,0,0,0,54,0,0,0,0,21,21,0,0,0,0,45,0,38,0,0
0,0,0,0,0,0,0,0,0,0,0,0,0,0,0,9,65,0,0,0,0,0,0,21,21,21,21,21,21,21,21,21,21,0,0,0,0,0,0
0,0,0,0,0,0,0,0,0,0,0,0,0,0,0,0,0,0,0,0,0,21,21,21,21,0,0,0,21,21,21,21,21,0,0,0,0,45,0
0,0,0,0,0,0,0,0,0,0,0,0,0,0,9,80,38,0,0,52,21,21,21,0,21,21,21,9,6,21,21,21,21,21,53,38,0,38,0
0,0,0,0,0,0,0,0,0,0,0,0,0,0,0,0,0,0,0,0,21,0,9,6,6,38,39,0,6,80,80,6,21,0,0,0,38,38,1
0,0,0,0,0,0,0,0,0,0,0,0,0,0,0,9,0,0,0,21,21,21,0,0,3,0,80,80,80,0,39,9,21,0,0,21,38,0,0
0,0,0,0,0,0,0,0,0,0,0,0,0,0,0,9,39,0,21,21,21,21,21,0,6,0,21,21,6,0,0,0,9,21,21,21,0,38,0
0,0,0,0,0,0,0,0,0,0,0,0,0,0,0,0,0,63,0,41,0,21,6,20,6,21,21,0,14,6,38,9,0,0,0,38,39,0,39
0,0,0,0,0,0,0,0,0,0,3,0,0,0,0,16,0,0,52,80,80,21,6,6,6,21,9,21,6,6,90,90,21,0,21,21,0,0,0
0,0,0,0,0,0,0,0,45,80,80,0,0,0,9,0,0,9,9,21,21,0,21,6,6,21,0,39,39,21,21,21,21,21,21,0,0,0,0
0,0,0,0,0,0,0,0,80,80,80,21,45,16,9,0,0,39,65,80,80,21,21,21,21,21,21,21,21,21,21,21,21,21,21,0,0,0,0
0,0,0,0,0,0,52,80,21,21,80,80,80,0,0,0,39,0,65,0,9,21,21,21,21,21,21,21,21,0,6,21,21,0,0,38,0,0,0
0,0,0,0,0,9,0,80,21,21,21,21,0,0,0,0,0,0,0,9,0,21,21,0,21,21,6,21,0,6,6,21,21,21,38,38,0,0,0
0,0,0,0,0,9,80,80,21,21,21,0,0,0,0,0,0,0,0,9,21,21,21,21,21,21,6,21,21,21,21,21,0,0,1,0,0,0,0
0,0,0,0,9,9,80,80,80,21,80,0,0,0,0,0,0,0,0,0,39,95,21,21,21,21,21,21,21,21,21,21,0,0,0,38,0,38,0
0,0,0,0,0,0,39,80,80,0,87,0,0,0,0,0,0,0,0,0,0,39,39,9,21,21,21,21,21,39,39,39,38,0,0,38,0,0,0
0,0,0,0,0,0,39,39,39,73,0,0,0,0,0,0,0,0,0,0,0,0,0,39,0,39,65,0,0,0,0,39,39,39,39,0,0,45,0
0,0,0,0,0,0,0,0,0,0,0,0,0,0,0,0,0,52,80,0,0,0,0,0,39,39,39,0,39,39,0,0,0,39,39,0,38,0,0
0,0,0,0,0,0,0,0,0,0,0,0,0,0,0,0,0,0,0,0,0,0,0,0,0,9,0,0,0,0,0,39,0,0,39,39,0,0,38
0,0,0,0,0,0,0,0,0,0,0,0,0,0,0,0,0,0,0,0,0,0,0,0,0,0,73,0,0,0,39,0,38,0,0,0,0,0,0
0,0,0,0,0,0,0,0,0,0,0,0,0,0,0,0,0,0,0,0,0,0,0,0,0,0,0,65,39,39,0,0,38,0,0,0,0,0,0
0,0,0,0,0,0,0,0,0,0,0,0,0,0,0,0,0,0,0,0,0,0,0,0,0,0,0,0,0,0,39,0,38,0,0,0,39,0,0
0,0,0,0,0,0,0,0,0,0,0,0,0,0,0,0,0,0,0,0,0,0,0,0,0,0,0,0,0,0,0,38,0,0,0,0,0,0,0
0,0,0,0,0,0,0,0,0,0,0,0,0,0,0,0,0,0,0,0,0,0,0,0,0,0,0,0,39,0,39,0,0,0,0,0,0,0,0
0,0,0,0,0,0,0,0,0,0,0,0,0,0,0,0,0,0,0,0,0,0,0,0,0,0,0,0,0,0,0,0,0,0,0,0,0,0,0
endlayer

layer
0,0,0,0,0,0,0,0,0,0,0,0,0,0,0,0,0,0,0,0,0,0,0,0,0,0,1,0,0,0,0,0,0,0,0,0,0,0,0
0,0,0,0,0,0,0,0,0,0,0,0,0,0,0,0,0,0,0,0,0,0,0,0,0,0,0,0,0,0,0,0,0,0,1,1,0,0,0
0,0,0,0,0,0,0,0,0,0,0,0,0,0,0,0,0,45,0,0,0,0,0,0,0,0,45,0,0,0,0,0,0,0,0,0,0,0,0
0,0,0,0,0,0,0,0,0,0,0,0,0,0,0,0,0,9,0,0,0,0,0,45,45,16,0,45,0,45,45,0,0,45,0,0,0,0,0
0,0,0,0,0,0,0,0,0,0,0,0,0,0,0,0,9,9,0,0,0,0,0,0,45,45,54,45,0,0,0,0,0,45,45,45,38,38,0
0,0,0,0,0,0,0,0,0,0,0,0,0,0,0,9,0,45,0,0,0,0,0,0,21,21,80,21,54,45,0,0,45,0,0,38,66,0,0
0,0,0,0,0,0,0,0,0,0,0,0,0,0,0,0,9,0,0,0,0,0,54,0,80,80,80,80,80,80,0,80,0,54,45,0,38,0,0
0,0,0,0,0,0,0,0,0,0,0,0,0,0,0,9,65,0,0,0,0,0,80,80,80,80,21,21,21,0,21,21,21,21,0,0,0,0,0
0,0,0,0,0,0,0,0,0,0,0,0,0,0,0,54,0,0,0,21,21,0,80,0,80,0,21,21,21,0,21,21,21,21,21,0,0,45,0
0,0,0,0,0,0,0,0,0,0,0,0,0,0,9,80,38,52,21,21,21,21,80,0,0,0,21,21,6,21,21,21,0,0,21,38,0,38,0
0,0,0,0,0,0,0,0,0,0,0,0,0,0,0,0,0,0,0,0,21,21,20,6,6,38,39,21,6,80,80,6,6,0,21,21,38,38,0
0,0,0,0,0,0,0,0,0,0,0,0,0,0,0,9,0,80,80,80,21,20,20,0,0,0,0,39,14,0,0,0,0,0,21,21,38,0,0
0,0,0,0,0,0,0,0,0,0,0,0,0,0,0,9,39,0,0,0,80,0,14,0,0,0,0,0,21,0,0,0,0,0,21,0,0,38,0
0,0,0,0,0,0,0,0,0,0,0,0,0,0,0,0,52,80,0,80,80,20,20,14,6,21,0,21,6,6,38,9,21,21,0,38,39,0,39
0,0,0,0,0,0,0,0,0,0,0,0,0,0,0,16,0,41,0,80,80,20,6,6,6,21,21,21,6,6,39,65,21,21,0,38,0,0,0
0,0,0,0,0,0,0,0,45,80,80,0,0,0,9,0,0,9,9,21,21,21,21,6,21,0,21,21,21,21,90,90,21,21,21,0,0,0,0
0,0,0,0,0,0,0,0,80,80,21,21,0,16,9,0,0,39,65,80,80,21,21,21,21,0,0,21,21,21,21,21,21,21,21,53,0,0,0
0,0,0,0,0,0,0,80,80,80,80,80,80,0,0,0,39,39,65,80,80,21,21,21,0,0,21,21,0,21,6,21,21,21,21,38,0,0,0
0,0,0,0,0,9,80,21,80,80,21,21,41,9,0,0,0,0,0,9,80,21,21,21,0,21,6,20,0,6,6,20,21,21,38,38,0,0,0
0,0,0,0,0,9,21,21,80,21,21,0,0,0,66,0,0,0,0,9,80,21,21,21,21,21,6,21,21,21,14,21,21,21,63,0,0,0,0
0,0,0,0,9,0,80,80,21,21,21,53,0,0,0,0,0,0,0,0,39,71,80,21,80,80,41,21,21,0,21,21,0,0,0,38,0,38,0
0,0,0,0,0,52,80,80,21,21,87,0,0,0,0,0,0,0,0,0,0,39,71,80,21,80,80,80,21,21,80,80,38,0,0,38,0,0,0
0,0,0,0,0,0,39,39,39,73,0,0,0,0,0,0,0,0,0,0,0,0,0,39,80,80,9,80,80,63,63,39,39,39,39,0,0,45,0
0,0,0,0,0,0,0,0,0,0,0,0,0,0,0,0,0,52,80,0,0,0,0,0,39,39,39,41,39,39,0,0,0,39,39,0,38,0,0
0,0,0,0,0,0,0,0,0,0,0,0,0,0,0,0,0,0,0,0,0,0,0,0,0,9,0,87,0,0,0,39,0,0,39,39,0,0,38
0,0,0,0,0,0,0,0,0,0,0,0,0,0,0,0,0,0,0,0,0,0,0,0,0,0,73,0,0,0,39,0,38,0,0,39,0,0,0
0,0,0,0,0,0,0,0,0,0,0,0,0,0,0,0,0,0,0,0,0,0,0,0,0,0,0,65,39,39,0,0,38,0,0,0,0,0,0
0,0,0,0,0,0,0,0,0,0,0,0,0,0,0,0,0,0,0,0,0,0,0,0,0,0,0,0,0,0,39,0,38,0,0,0,39,0,0
0,0,0,0,0,0,0,0,0,0,0,0,0,0,0,0,0,0,0,0,0,0,0,0,0,0,0,0,0,0,0,38,0,0,0,0,0,0,0
0,0,0,0,0,0,0,0,0,0,0,0,0,0,0,0,0,0,0,0,0,0,0,0,0,0,0,0,39,0,39,0,0,0,0,0,0,0,0
0,0,0,0,0,0,0,0,0,0,0,0,0,0,0,0,0,0,0,0,0,0,0,0,0,0,0,0,0,0,0,0,0,0,0,0,0,0,0
endlayer

layer
0,0,0,0,0,0,0,0,0,0,0,0,0,0,0,0,0,0,0,0,0,0,0,0,0,0,0,0,38,0,0,0,0,0,0,0,0,0,0
0,0,0,0,0,0,0,0,0,0,0,0,0,0,0,0,0,0,0,0,0,0,0,0,0,0,45,0,0,0,0,0,0,0,0,0,0,0,0
0,0,0,0,0,0,0,0,0,0,0,0,0,0,0,0,0,45,0,0,0,0,0,0,0,0,45,0,0,0,0,0,0,0,0,45,0,0,0
0,0,0,0,0,0,0,0,0,0,0,0,0,0,0,0,0,9,0,0,0,0,0,45,45,16,0,45,0,45,45,0,0,45,45,0,0,0,0
0,0,0,0,0,0,0,0,0,0,0,0,0,0,0,9,9,9,0,0,0,0,0,0,0,45,0,45,54,0,0,0,0,45,45,45,38,38,0
0,0,0,0,0,0,0,0,0,0,0,0,0,0,0,9,0,45,0,0,0,0,0,21,21,21,80,80,21,45,0,54,45,0,0,38,66,0,0
0,0,0,0,0,0,0,0,0,0,0,0,0,0,0,0,9,0,0,54,21,21,54,80,80,80,80,80,80,0,0,80,0,0,45,0,38,0,0
0,0,0,0,0,0,0,0,0,0,0,0,0,0,0,9,65,0,0,21,80,0,80,20,80,80,0,0,21,0,21,21,21,21,21,54,0,0,0
0,0,0,0,0,0,0,0,0,0,0,0,0,0,0,9,0,0,21,21,80,20,14,14,14,0,0,21,14,21,21,21,21,21,0,21,0,45,0
0,0,0,0,0,0,0,0,0,0,0,0,0,0,9,80,53,54,21,0,0,0,6,14,14,0,0,20,14,0,21,14,21,21,21,21,80,38,0
0,0,0,0,0,0,0,0,0,0,0,0,0,0,0,0,0,80,21,80,20,20,20,20,6,20,20,20,14,20,20,6,20,20,20,20,21,38,0
0,0,0,0,0,0,0,0,0,0,0,0,0,0,0,9,0,80,80,80,6,20,20,6,14,0,0,0,14,0,0,14,21,21,21,38,0,0,0
0,0,0,0,0,0,0,0,0,0,0,0,0,0,0,9,39,80,80,0,14,6,20,20,14,0,21,21,21,21,0,0,0,21,0,0,0,38,0
0,0,0,0,0,0,0,0,0,0,0,0,0,0,0,0,9,80,80,80,14,17,0,6,6,20,21,21,0,6,38,0,0,21,0,38,39,0,39
0,0,0,0,0,0,0,0,0,54,0,0,0,0,0,16,0,65,80,80,20,20,20,6,20,21,0,0,6,6,39,65,20,21,0,38,0,0,0
0,0,0,0,0,0,0,0,45,80,21,0,0,0,9,0,0,9,0,39,80,41,21,6,21,0,0,21,21,21,38,39,21,21,0,0,0,0,0
0,0,0,0,0,0,0,0,80,21,21,21,0,16,9,0,0,39,65,80,80,21,21,14,21,0,0,0,21,17,90,90,21,21,21,0,0,0,0
0,0,0,0,0,0,0,80,21,21,21,21,21,0,0,0,39,39,65,80,80,21,21,21,0,21,14,21,21,14,14,0,0,21,21,38,0,0,0
0,0,0,0,0,0,54,21,21,80,21,21,38,9,0,0,0,0,0,9,80,80,21,21,0,0,14,6,20,14,6,20,20,20,21,38,0,0,0
0,0,0,0,0,9,21,21,80,80,21,41,0,0,66,0,0,0,0,9,80,80,80,21,21,20,6,20,20,6,6,14,21,0,21,0,0,0,0
0,0,0,0,9,0,21,21,21,21,80,0,0,0,0,0,0,0,0,0,39,80,80,80,80,80,14,21,21,14,14,21,21,21,0,38,0,38,0
0,0,0,0,0,0,21,21,21,0,0,0,0,0,0,0,0,0,0,0,0,39,41,80,80,80,80,80,21,21,21,80,80,0,0,38,0,0,0
0,0,0,0,0,0,0,0,39,0,0,0,0,0,0,0,0,0,0,0,0,0,0,39,41,80,80,80,80,21,21,39,39,39,39,0,0,45,0
0,0,0,0,0,0,0,0,0,0,0,0,0,0,0,0,0,0,3,0,0,0,0,0,0,39,39,39,39,39,0,0,0,39,39,0,38,0,87
0,0,0,0,0,0,0,0,0,0,0,0,0,0,0,0,0,0,0,0,0,0,0,0,0,9,0,87,0,0,0,39,0,0,39,39,0,0,38
0,0,0,0,0,0,0,0,0,0,0,0,0,0,0,0,0,0,0,0,0,0,0,0,0,0,73,0,0,0,39,0,38,0,0,39,0,0,0
0,0,0,0,0,0,0,0,0,0,0,0,0,0,0,0,0,0,0,0,0,0,0,0,0,0,0,65,39,39,0,0,38,0,0,0,0,0,0
0,0,0,0,0,0,0,0,0,0,0,0,0,0,0,0,0,0,0,0,0,0,0,0,0,0,0,0,0,0,39,0,38,0,0,0,39,0,0
0,0,0,0,0,0,0,0,0,0,0,0,0,0,0,0,0,0,0,0,0,0,0,0,0,0,0,0,0,0,0,38,0,0,0,0,0,0,0
0,0,0,0,0,0,0,0,0,0,0,0,0,0,0,0,0,0,0,0,0,0,0,0,0,0,0,0,39,0,39,0,0,0,0,0,0,0,0
0,0,0,0,0,0,0,0,0,0,0,0,0,0,0,0,0,0,0,0,0,0,0,0,0,0,0,0,0,0,0,0,0,0,0,0,0,0,0
endlayer

layer
0,0,0,0,0,0,0,0,0,0,0,0,0,0,0,0,0,0,0,0,0,0,0,0,0,0,0,0,38,0,0,0,0,0,0,0,0,0,0
0,0,0,0,0,0,0,0,0,0,0,0,0,0,0,0,0,0,0,0,0,0,0,0,0,0,45,0,0,0,0,0,0,0,0,0,0,0,0
0,0,0,0,0,0,0,0,0,0,0,0,0,0,0,0,0,45,0,0,0,0,0,0,0,0,45,0,0,0,0,0,0,0,0,45,0,0,0
0,0,0,0,0,0,0,0,0,0,0,0,0,0,0,0,0,9,0,0,0,0,54,45,45,16,0,45,0,45,45,0,0,45,45,45,0,38,0
0,0,0,0,0,0,0,0,0,0,0,0,0,0,0,9,9,9,0,0,21,80,80,0,0,21,21,45,43,0,0,0,0,45,45,45,38,38,0
0,0,0,0,0,0,0,0,0,0,0,0,0,0,0,9,0,45,0,21,21,21,80,21,21,21,80,80,38,45,0,0,45,0,0,38,66,0,0
0,0,0,0,0,0,0,0,0,0,0,0,0,0,0,0,9,0,21,21,21,21,21,80,21,80,80,80,0,21,21,80,80,0,0,0,38,0,0
0,0,0,0,0,0,0,0,0,0,0,0,0,0,0,9,65,0,0,80,6,20,20,14,6,21,0,21,6,21,0,21,21,21,21,54,0,0,0
0,0,0,0,0,0,0,0,0,0,0,0,0,0,0,9,0,0,21,21,14,7,7,6,7,7,20,6,6,6,20,7,7,21,0,21,80,45,54
0,0,0,0,0,0,0,0,0,0,0,0,0,0,52,80,0,0,80,80,14,7,7,7,7,7,7,7,7,7,7,7,7,21,21,21,80,80,80
0,0,0,0,0,0,0,0,0,0,0,0,0,0,0,0,0,80,21,20,6,6,7,7,7,7,7,7,7,7,7,7,7,6,21,21,80,21,21
0,0,0,0,0,0,0,0,0,0,0,0,0,0,0,9,0,80,0,80,6,7,7,17,17,17,7,7,7,7,7,7,7,21,21,21,80,21,0
0,0,0,0,0,0,0,0,0,0,0,0,0,0,0,9,39,80,80,80,80,7,17,17,24,17,17,7,7,7,17,17,7,21,21,21,80,38,0
0,0,0,0,0,0,0,0,0,0,0,0,0,0,0,0,9,80,80,0,0,17,17,24,24,24,17,7,7,6,38,0,6,21,0,38,39,0,39
0,0,0,0,0,0,0,0,0,0,0,0,0,0,0,16,0,65,80,80,6,17,24,24,24,17,17,7,6,6,39,39,6,21,0,38,0,0,0
0,0,0,0,0,0,0,0,0,0,0,0,0,0,9,0,0,9,41,80,80,17,17,24,17,17,7,7,21,80,38,39,6,21,21,0,0,0,0
0,0,0,0,0,0,0,0,45,80,21,0,0,16,9,0,0,39,65,80,80,7,7,17,17,7,7,7,7,28,0,0,7,21,21,0,0,0,0
0,0,0,0,0,0,0,16,21,21,21,21,16,0,0,0,39,39,39,16,80,7,7,7,7,7,7,7,7,90,90,90,7,21,21,21,0,0,0
0,0,0,0,0,0,54,21,21,21,21,38,0,9,39,0,0,0,0,9,80,7,7,7,7,7,7,7,7,7,7,7,7,6,21,38,0,0,0
0,0,0,0,0,0,80,21,80,80,80,53,0,0,66,0,0,0,0,9,80,7,7,7,7,7,7,7,7,7,7,7,7,21,21,53,0,0,0
0,0,0,0,9,80,21,21,21,80,39,0,0,0,0,0,0,0,0,0,0,80,80,21,0,0,6,20,6,14,20,20,21,21,21,38,0,38,0
0,0,0,0,0,0,21,21,80,0,0,0,0,0,0,0,0,0,0,0,0,0,39,39,21,21,80,21,21,6,0,80,80,21,0,38,0,0,0
0,0,0,0,0,0,0,80,39,0,0,0,0,0,0,0,0,0,0,0,0,0,0,39,39,80,21,21,80,21,21,63,39,39,39,0,0,45,0
0,0,0,0,0,0,0,41,0,0,0,0,0,0,0,0,0,0,0,0,0,0,0,0,0,39,39,39,39,39,0,0,0,39,39,0,38,0,87
0,0,0,0,0,0,0,0,0,0,0,0,0,0,0,0,0,0,0,0,0,0,0,0,0,9,0,87,0,0,0,39,0,0,39,39,0,0,38
0,0,0,0,0,0,0,0,0,0,0,0,0,0,0,0,0,0,0,0,0,0,0,0,0,0,73,0,0,0,39,0,38,0,39,39,0,0,0
0,0,0,0,0,0,0,0,0,0,0,0,0,0,0,0,0,0,0,0,0,0,0,0,0,0,0,65,39,39,0,0,38,0,0,0,0,0,0
0,0,0,0,0,0,0,0,0,0,0,0,0,0,0,0,0,0,0,0,0,0,0,0,0,0,0,0,0,0,39,0,38,0,0,0,39,0,0
0,0,0,0,0,0,0,0,0,0,0,0,0,0,0,0,0,0,0,0,0,0,0,0,0,0,0,0,0,0,0,38,0,0,0,0,0,0,0
0,0,0,0,0,0,0,0,0,0,0,0,0,0,0,0,0,0,0,0,0,0,0,0,0,0,0,0,39,0,39,0,0,0,0,0,0,0,0
0,0,0,0,0,0,0,0,0,0,0,0,0,0,0,0,0,0,0,0,0,0,0,0,0,0,0,0,0,0,0,0,0,0,0,0,0,0,0
endlayer

layer
0,0,0,0,0,0,0,0,0,0,0,0,0,0,0,0,0,0,0,0,0,0,0,0,0,0,0,0,38,0,0,0,0,0,0,0,0,0,0
0,0,0,0,0,0,0,0,0,0,0,0,0,0,0,0,0,0,0,0,0,0,0,0,0,0,45,0,0,0,0,0,0,0,0,0,0,0,0
0,0,0,0,0,0,0,0,0,0,0,0,0,0,0,0,0,45,0,0,0,0,0,0,0,0,45,0,0,0,0,0,0,0,0,45,45,0,0
0,0,0,0,0,0,0,0,0,0,0,0,0,0,0,0,0,9,0,54,80,80,0,45,45,16,0,45,0,45,45,0,0,45,45,45,0,38,0
0,0,0,0,0,0,0,0,0,0,0,0,0,0,0,9,9,9,0,21,21,80,80,80,0,21,21,21,43,0,80,54,54,45,45,45,38,38,0
0,0,0,0,0,0,0,0,0,0,0,0,0,0,0,9,0,45,0,0,21,21,80,80,80,80,80,80,80,45,21,80,80,0,0,38,66,0,0
0,0,0,0,0,0,0,0,0,0,0,0,0,0,0,0,9,0,0,0,0,21,0,80,0,80,80,80,80,80,21,21,80,80,80,0,38,0,0
0,0,0,0,0,0,0,0,0,0,0,0,0,0,0,9,65,21,21,0,0,0,0,6,6,80,80,80,6,80,80,80,21,21,80,0,0,0,0
0,0,0,0,0,0,0,0,0,0,0,0,0,0,0,9,0,80,21,21,0,0,0,6,6,7,48,48,48,48,48,7,7,80,80,0,0,0,0
0,0,0,0,0,0,0,0,0,0,0,0,0,0,0,9,0,80,80,80,0,0,0,80,6,80,80,80,80,100,80,80,7,21,0,80,80,80,45
0,0,0,0,0,0,0,0,0,0,0,0,0,0,0,0,0,80,80,6,6,0,0,80,80,80,80,31,31,31,31,80,48,21,21,21,80,21,21
0,0,0,0,0,0,0,0,0,0,0,0,0,0,0,9,80,80,80,80,6,7,6,80,15,15,31,31,31,31,101,21,48,0,21,21,80,21,21
0,0,0,0,0,0,0,0,0,0,0,0,0,0,0,9,39,80,80,80,80,7,21,15,23,15,31,31,31,31,102,21,48,0,21,21,80,21,0
0,0,0,0,0,0,0,0,0,0,0,0,0,0,0,71,9,80,80,80,80,48,15,23,23,15,31,31,80,6,17,17,6,0,0,38,80,0,39
0,0,0,0,0,0,0,0,0,0,0,0,0,0,0,16,0,65,80,80,6,48,23,23,23,15,31,31,6,6,39,39,48,21,21,38,0,0,0
0,0,0,0,0,0,0,0,0,0,0,0,0,0,9,0,0,9,9,80,0,48,23,23,23,15,31,31,21,6,38,39,6,21,21,0,0,0,0
0,0,0,0,0,0,0,0,45,0,0,0,0,16,9,0,0,39,39,80,9,48,23,23,23,103,31,31,31,39,0,0,48,21,21,21,0,0,0
0,0,0,0,0,0,0,16,21,21,21,0,16,0,0,0,39,39,39,16,9,48,24,23,23,24,24,31,81,0,0,0,48,21,21,21,0,0,0
0,0,0,0,0,0,0,21,21,21,21,0,0,9,39,39,0,0,0,9,9,21,24,24,23,23,103,24,31,45,0,81,7,21,21,38,0,0,0
0,0,0,0,0,0,21,21,21,21,21,53,0,0,66,0,0,0,0,9,80,21,21,48,48,48,48,48,48,48,48,7,7,21,21,38,0,0,0
0,0,0,0,52,21,21,80,21,21,39,0,0,0,0,0,0,1,0,52,80,80,39,21,21,80,6,21,6,6,6,21,21,21,21,38,0,38,0
0,0,0,0,0,0,21,21,21,41,0,0,39,0,0,0,0,0,0,0,0,0,0,21,21,80,80,0,80,6,0,80,80,21,21,38,0,0,0
0,0,0,0,0,0,0,21,39,0,0,0,0,0,0,0,0,0,0,0,0,0,0,39,71,80,21,80,21,21,21,21,41,39,39,0,0,45,0
0,0,0,0,0,0,0,0,0,0,0,0,0,0,0,0,0,0,0,0,0,0,0,0,0,41,39,39,0,39,21,41,0,39,39,0,38,0,87
0,0,0,0,0,0,0,0,0,0,0,0,0,0,0,0,0,0,0,0,0,0,0,0,0,9,0,87,0,0,0,39,0,0,39,39,0,0,38
0,0,0,0,0,0,0,0,0,0,0,0,0,0,0,0,0,0,0,0,0,0,0,0,0,0,73,0,0,0,39,0,38,0,39,39,0,0,0
0,0,0,0,0,0,0,0,0,0,0,0,0,0,0,0,0,0,0,0,0,0,0,0,0,0,0,65,39,39,0,0,38,0,0,0,39,0,0
0,0,0,0,0,0,0,0,0,0,0,0,0,0,0,0,0,0,0,0,0,0,0,0,0,0,0,0,0,0,39,0,38,0,0,0,39,0,0
0,0,0,0,0,0,0,0,0,0,0,0,0,0,0,0,0,0,0,0,0,0,0,0,0,0,0,0,0,0,0,38,0,0,0,0,0,0,0
0,0,0,0,0,0,0,0,0,0,0,0,0,0,0,0,0,0,0,0,0,1,0,0,0,0,0,0,39,0,39,0,0,0,0,0,0,0,0
0,0,0,0,0,0,0,0,0,0,0,0,0,0,0,0,0,0,0,0,0,0,0,0,0,0,0,0,0,0,0,0,0,0,0,0,0,0,0
endlayer

layer
0,0,0,0,0,0,0,0,0,0,0,0,0,0,0,0,0,0,0,0,0,0,0,0,0,0,0,0,38,0,0,0,0,0,0,0,0,0,0
0,0,0,0,0,0,0,0,0,0,0,0,0,0,0,0,0,0,0,0,0,0,0,0,0,0,45,0,0,0,0,0,0,0,0,0,0,0,0
0,0,0,0,0,0,0,0,0,0,0,0,0,0,0,0,0,45,0,80,80,0,0,0,0,0,45,0,0,0,0,0,0,0,0,45,45,0,0
0,0,0,0,0,0,0,0,0,0,0,0,0,0,0,0,0,9,80,80,80,80,0,45,45,9,80,0,0,45,0,0,0,45,45,45,38,38,0
0,0,0,0,0,0,0,0,0,0,0,0,0,0,0,9,9,9,21,21,21,80,80,80,80,21,21,21,38,0,45,45,45,45,45,45,38,38,0
0,0,0,0,0,0,0,0,0,0,0,0,0,0,9,9,0,45,0,0,21,21,80,80,80,80,21,21,21,80,80,80,80,80,0,38,66,0,0
0,0,0,0,0,0,0,0,0,0,0,0,0,0,0,0,9,21,0,0,0,0,0,80,0,80,80,80,80,0,80,80,80,80,80,53,38,0,0
0,0,0,0,0,0,0,0,0,0,0,0,0,1,0,9,65,21,21,0,0,0,21,6,3,80,80,80,6,0,80,0,21,80,80,0,0,0,0
0,0,0,0,0,0,0,0,0,0,0,0,0,0,0,9,0,80,21,21,0,0,0,0,6,48,48,48,48,48,20,48,7,80,80,80,0,0,0
0,0,0,0,0,0,0,0,0,0,0,0,0,0,0,9,80,0,80,80,80,0,0,0,6,80,80,80,80,80,80,80,48,0,21,80,80,45,45
0,0,0,0,0,0,0,0,0,0,0,0,0,0,0,52,80,21,21,6,6,0,0,80,80,38,38,39,39,39,41,0,48,21,21,21,80,80,21
0,0,0,0,0,0,0,0,0,0,0,0,0,0,0,9,80,80,80,80,6,7,6,80,0,0,0,0,39,0,0,0,48,0,21,21,80,21,21
0,0,0,0,0,0,0,0,0,0,0,0,0,0,0,9,0,80,0,80,80,48,80,0,0,84,0,0,45,45,45,45,48,21,21,21,80,21,0
0,0,0,0,0,0,0,0,0,0,0,0,0,0,0,71,52,80,80,80,80,48,80,0,0,0,0,9,80,6,21,21,48,21,21,38,80,41,39
0,0,0,0,0,0,0,0,0,0,0,0,0,0,0,16,0,65,80,80,80,48,0,38,0,3,0,52,6,6,17,17,6,0,21,38,0,0,0
0,0,0,0,0,0,0,0,0,0,0,0,0,0,9,0,0,9,80,80,80,48,0,38,0,0,39,9,80,6,0,39,6,21,21,21,53,0,0
0,0,0,0,0,0,0,0,54,0,0,0,0,16,9,0,0,39,39,39,9,48,0,38,0,0,0,0,0,0,0,0,48,0,21,21,0,0,0
0,0,0,0,0,0,0,16,80,80,80,0,16,0,0,0,39,39,39,16,9,48,80,38,0,84,0,0,0,0,0,0,48,21,21,21,0,0,0
0,0,0,0,0,0,0,21,80,80,80,0,0,9,39,39,0,0,0,9,9,21,80,80,38,0,0,84,0,45,0,9,48,21,21,21,0,0,0
0,0,0,0,0,0,21,21,21,80,80,0,0,0,66,0,0,0,0,9,80,21,21,48,48,48,48,48,48,48,48,48,7,21,21,41,0,0,0
0,0,0,0,0,0,21,21,21,21,0,0,0,0,0,0,0,0,0,0,80,80,39,80,80,0,6,0,6,6,20,20,21,21,21,38,0,38,0
0,0,0,0,0,0,21,21,21,39,0,0,39,0,0,0,0,0,0,0,0,0,0,3,80,80,80,0,6,14,80,80,80,80,80,38,0,0,0
0,0,0,0,0,0,0,39,39,0,0,0,0,0,0,0,0,0,0,0,0,0,0,0,80,21,0,21,21,21,21,21,39,39,39,0,0,45,0
0,0,0,0,0,0,0,0,0,0,0,0,0,0,0,0,0,0,0,0,0,0,0,0,0,9,21,21,0,39,21,21,53,39,39,0,38,0,87
0,0,0,0,0,0,0,0,0,0,0,0,0,0,0,0,0,0,0,0,0,0,0,0,0,9,21,87,96,0,21,39,0,0,39,39,0,0,38
0,0,0,0,0,0,0,0,0,0,0,0,0,0,0,0,0,0,0,0,0,0,0,0,0,0,73,0,0,0,39,0,38,0,39,39,0,0,0
0,0,0,0,0,0,0,0,0,0,0,0,0,0,0,0,0,0,0,0,0,0,0,0,0,0,0,65,39,39,0,0,38,0,0,0,39,0,0
0,0,0,0,0,0,0,0,0,0,0,0,0,0,0,0,0,0,0,0,0,0,0,0,0,0,0,0,0,0,39,0,38,0,0,0,39,0,0
0,0,0,0,0,0,0,0,0,0,0,0,0,0,0,0,0,0,0,0,0,0,0,0,0,0,0,0,0,0,0,38,0,0,0,0,0,0,0
0,0,0,0,0,0,0,0,0,0,0,0,0,0,0,0,0,0,0,0,0,0,0,0,0,0,0,0,39,0,39,0,0,0,0,0,0,0,0
0,0,0,0,0,0,0,0,0,0,0,0,0,0,0,0,0,0,0,0,0,0,0,0,0,0,0,0,0,0,0,0,0,0,0,0,0,0,0
endlayer

layer
0,0,0,0,0,0,0,0,0,0,0,0,0,0,0,0,0,0,0,0,0,0,0,0,0,0,0,0,38,0,0,0,0,0,0,0,0,0,0
0,0,0,0,0,0,0,0,0,0,0,0,0,0,0,0,0,0,0,0,0,0,0,0,0,54,45,0,0,0,0,0,0,0,0,0,0,0,0
0,0,0,0,0,0,0,0,0,0,0,0,0,0,0,0,45,45,0,80,80,0,0,0,0,80,80,0,0,0,0,0,0,0,0,45,45,0,0
0,0,0,0,0,0,0,0,0,0,0,0,0,0,0,0,0,9,80,80,80,80,0,45,80,80,21,80,0,45,0,0,0,45,45,45,38,38,0
0,0,0,0,0,0,0,0,0,0,0,0,0,0,0,9,9,9,21,21,21,80,80,80,80,21,21,21,0,0,45,45,45,45,45,45,38,38,0
0,0,0,0,0,0,0,0,0,0,0,0,0,0,9,9,0,0,21,21,21,21,80,80,80,80,21,21,0,80,80,80,80,80,80,38,66,0,0
0,0,0,0,0,0,0,0,0,0,0,0,0,0,0,0,52,21,21,0,21,21,80,80,80,80,80,80,0,80,80,80,80,21,21,54,38,0,0
0,0,0,0,0,0,0,0,0,0,0,0,0,0,0,9,65,21,21,21,21,21,6,6,80,80,0,80,6,80,80,0,21,21,80,80,0,0,0
0,0,0,0,0,0,0,0,0,0,0,0,0,0,0,9,80,80,80,21,21,0,0,0,6,7,48,48,48,6,48,7,6,6,80,80,54,0,0
0,0,0,0,0,0,0,0,0,0,0,0,0,0,0,9,80,80,80,80,6,0,0,0,6,6,21,80,80,80,9,80,7,21,21,80,80,80,45
0,0,0,0,0,0,0,0,0,0,0,0,0,0,0,9,80,80,0,3,6,14,0,0,0,80,38,0,80,39,0,0,48,21,21,21,21,21,80
0,0,0,0,0,0,0,0,0,0,0,0,0,0,0,9,80,80,80,20,6,7,6,80,0,0,0,0,39,0,0,0,48,21,21,21,21,21,21
0,0,0,0,0,0,0,0,0,0,0,0,0,0,0,9,80,80,21,80,6,7,14,80,0,0,0,0,0,45,0,0,48,21,21,21,21,21,80
0,0,0,0,0,0,0,0,0,0,0,0,0,0,0,71,9,80,21,21,21,48,14,80,0,0,0,9,80,6,80,80,48,0,21,38,0,41,39
0,0,0,0,0,0,0,0,0,0,0,0,0,0,0,16,0,71,80,21,80,48,80,38,0,0,80,80,20,6,90,90,6,0,45,38,0,0,0
0,0,0,0,0,0,0,0,0,0,0,0,0,0,9,0,0,9,0,39,9,48,80,38,0,0,39,80,80,6,0,0,48,21,21,38,0,0,0
0,0,0,0,0,0,0,0,0,0,0,0,0,16,9,0,0,39,0,39,9,48,80,38,0,0,0,0,0,0,0,0,48,21,21,21,0,0,0
0,0,0,0,0,0,0,16,80,80,0,0,16,0,0,0,39,39,39,16,9,48,21,38,0,0,0,0,0,0,0,0,48,21,21,21,0,0,0
0,0,0,0,0,0,0,21,80,80,80,0,0,9,39,39,0,0,0,9,9,21,21,21,38,0,0,0,0,45,0,9,7,21,21,0,0,0,0
0,0,0,0,0,0,54,21,21,80,80,0,0,0,66,0,0,0,0,9,80,21,21,48,48,48,48,48,48,6,0,7,7,0,21,0,0,0,1
0,0,0,0,0,0,21,21,21,21,0,0,39,0,0,0,0,0,0,0,80,80,39,39,39,80,6,20,20,6,6,0,6,21,21,38,0,38,0
0,0,0,0,0,0,39,21,0,0,0,0,39,0,0,0,0,0,0,0,0,0,0,0,0,0,80,80,20,14,80,0,80,21,80,38,0,0,0
0,0,0,0,0,0,0,0,0,0,0,0,0,0,0,0,0,0,0,0,0,0,0,0,0,9,0,80,0,14,80,80,0,0,39,0,0,45,0
0,0,0,0,0,0,0,0,0,0,0,0,0,0,0,0,0,0,0,0,0,0,0,0,0,9,0,80,21,21,80,80,38,39,39,0,38,0,87
0,0,0,0,0,0,0,0,0,0,0,0,0,0,0,0,0,0,0,0,0,0,0,0,0,0,3,0,21,21,80,39,0,0,39,39,0,0,38
0,0,0,0,0,0,0,0,0,0,0,0,0,0,0,0,0,0,0,0,0,0,0,0,0,0,9,0,0,21,21,0,38,0,39,39,0,0,0
0,0,0,0,0,0,0,0,0,0,0,0,0,0,0,0,0,0,0,0,0,0,0,0,0,0,0,65,39,39,21,0,38,0,0,0,39,0,0
0,0,0,0,0,0,0,0,0,0,0,0,0,0,0,0,0,0,0,0,0,0,0,0,0,0,0,0,0,0,39,0,38,0,0,0,39,0,0
0,0,0,0,0,0,0,0,0,0,0,0,0,0,0,0,0,0,0,0,0,0,0,0,0,0,0,0,0,0,0,38,0,0,0,0,0,0,0
0,0,0,0,0,0,0,0,0,0,0,0,0,0,0,0,0,0,0,0,0,0,0,0,0,0,0,0,39,0,39,0,0,0,0,0,0,0,0
0,0,0,0,0,0,0,0,0,0,0,0,0,0,0,0,0,0,0,0,0,0,0,0,0,0,0,0,0,0,0,0,0,0,0,0,0,0,0
endlayer

layer
0,0,0,0,0,0,0,0,0,0,0,0,0,0,0,0,0,0,0,0,0,0,0,0,0,54,63,0,38,0,0,0,0,0,0,0,0,0,0
0,0,0,0,0,0,0,0,0,0,0,0,0,0,0,0,0,0,0,0,0,0,0,0,63,80,21,54,0,0,0,0,0,0,0,0,0,0,0
0,0,0,0,0,0,0,0,0,0,0,0,0,0,0,0,45,45,54,43,45,0,0,0,80,80,80,80,0,0,0,0,0,0,0,45,45,0,0
0,0,0,0,0,0,0,0,0,0,0,0,0,0,0,0,0,0,80,80,80,43,42,80,80,21,21,21,0,45,0,0,0,45,45,45,38,38,0
0,0,0,0,0,0,0,0,0,0,0,0,0,0,0,9,9,9,80,80,80,80,42,80,80,21,21,21,21,80,45,45,45,45,45,45,38,38,0
0,0,0,0,0,0,0,0,0,0,0,0,0,0,9,9,0,0,80,80,80,80,80,80,80,80,21,21,21,0,80,21,21,21,80,38,66,0,0
0,0,0,0,0,0,0,0,0,0,0,0,0,0,0,0,9,9,21,21,0,0,14,80,80,80,80,0,80,80,80,80,80,21,21,80,38,0,0
0,0,0,0,0,0,0,0,0,0,0,0,0,0,0,9,65,80,80,21,80,80,14,6,20,20,80,80,6,80,80,80,6,21,80,80,0,0,0
0,0,0,0,0,0,0,0,0,0,0,0,0,0,0,0,9,80,80,80,80,6,14,20,20,20,20,20,20,20,20,20,6,6,80,38,0,0,0
0,0,0,0,0,0,0,0,0,0,0,0,0,0,0,9,80,80,80,20,20,14,6,20,14,20,20,6,14,7,7,6,14,21,21,0,0,0,45
0,0,0,0,0,0,0,0,0,0,0,0,0,0,0,0,3,80,80,80,6,14,14,7,7,7,7,7,14,7,7,7,14,21,21,80,80,21,80
0,0,0,0,0,0,0,0,0,0,0,0,0,0,0,9,80,80,80,80,14,20,6,20,7,7,7,7,7,7,7,7,14,21,21,21,21,21,21
0,0,0,0,0,0,0,0,0,0,0,0,0,0,0,0,39,80,21,14,14,20,14,7,7,7,7,7,7,7,7,7,14,21,21,0,80,21,80
0,0,0,0,0,0,0,0,0,0,0,0,0,0,0,71,0,41,80,21,80,7,6,20,7,7,7,7,7,6,7,7,14,0,21,0,0,0,39
0,0,0,0,0,0,0,0,0,0,0,0,0,0,0,16,0,9,80,80,80,7,14,7,7,7,7,6,20,6,20,7,6,20,21,38,0,0,0
0,0,0,0,0,0,0,0,0,0,0,0,0,0,9,0,0,9,41,80,9,7,7,7,7,7,7,7,7,6,7,7,14,21,21,38,0,0,0
0,0,0,0,0,0,0,0,0,0,0,0,0,16,9,0,0,39,0,39,9,7,7,7,7,7,7,7,7,7,7,7,14,21,21,0,0,0,0
0,0,0,0,0,0,0,45,21,0,0,0,16,0,0,0,39,39,39,16,9,7,7,7,7,7,7,7,7,7,7,7,7,21,21,0,0,0,0
0,0,0,0,0,0,0,21,21,80,0,0,0,9,39,39,0,0,9,9,9,7,7,7,7,7,7,7,7,7,7,7,21,0,21,0,0,0,0
0,0,0,0,0,0,0,21,21,21,21,53,0,0,66,0,0,0,0,9,80,7,7,7,7,7,14,7,7,14,7,7,7,21,21,21,0,0,0
0,0,0,0,0,0,9,21,21,21,0,0,39,0,0,0,0,0,0,0,80,80,39,39,39,9,6,20,6,6,6,0,6,80,80,41,63,38,0
0,0,0,0,0,0,0,39,41,0,0,0,39,0,0,0,0,0,0,0,0,0,0,0,80,80,80,80,3,6,80,80,80,80,80,80,0,0,0
0,0,0,0,0,0,0,0,0,0,0,0,0,0,0,0,0,0,0,0,0,0,0,0,0,9,80,80,80,6,21,21,41,0,80,0,0,45,0
0,0,0,0,0,0,0,0,0,0,0,0,0,0,0,0,0,0,0,0,0,0,0,0,0,9,80,21,21,14,21,80,0,39,39,0,38,0,87
0,0,0,0,0,0,0,0,0,0,0,0,0,0,0,0,0,0,0,0,0,0,0,0,0,0,39,0,21,14,80,0,0,0,39,39,0,0,38
0,0,0,0,0,0,0,0,0,0,0,0,0,0,0,0,0,0,0,0,0,0,0,0,0,0,9,21,21,14,21,80,38,0,39,39,0,0,0
0,0,0,0,0,0,0,0,0,0,0,0,0,0,0,0,0,0,0,0,0,0,0,0,0,0,0,65,39,21,21,21,38,0,0,0,39,0,0
0,0,0,0,0,0,0,0,0,0,0,0,0,0,0,0,0,0,0,0,0,0,0,0,0,0,0,0,0,0,0,0,38,0,0,0,39,0,0
0,0,0,0,0,0,0,0,0,0,0,0,0,0,0,0,0,0,0,0,0,0,0,0,0,0,0,0,0,0,0,38,0,0,0,0,0,0,0
0,0,0,0,0,0,0,0,0,0,0,0,0,0,0,0,0,0,0,0,0,0,0,0,0,0,0,0,39,0,39,0,0,0,0,0,0,0,0
0,0,0,0,0,0,0,0,0,0,0,0,0,0,0,0,0,0,0,0,0,0,0,0,0,0,0,0,0,0,0,0,0,0,0,0,0,0,0
endlayer

layer
0,0,0,0,0,0,0,0,0,0,0,0,0,0,0,0,0,0,0,0,0,0,0,0,0,80,21,0,38,0,0,0,0,0,0,0,0,0,0
0,0,0,0,0,0,0,0,0,0,0,0,0,0,0,0,0,0,45,0,0,0,0,54,80,80,21,21,0,0,0,0,0,0,0,0,0,0,0
0,0,0,0,0,0,0,0,0,0,0,0,0,0,0,0,45,45,45,43,45,0,54,80,80,21,21,21,0,0,0,0,0,0,0,45,45,0,0
0,0,0,0,0,0,0,0,0,0,0,0,0,0,0,0,0,0,0,45,43,43,80,80,80,80,80,80,54,54,0,0,0,45,45,45,38,38,0
0,0,0,0,0,0,0,0,0,0,0,0,0,0,0,9,9,0,0,80,80,80,80,80,80,80,80,80,80,80,45,45,21,21,21,45,38,38,0
0,0,0,0,0,0,0,0,0,0,0,0,0,0,9,9,0,52,80,80,80,80,80,80,80,80,80,80,80,80,80,80,21,21,21,80,66,0,0
0,0,0,0,0,0,0,0,0,0,0,0,0,0,0,0,9,9,80,80,80,80,0,80,80,80,80,80,0,80,80,80,80,80,80,80,38,0,0
0,0,0,0,0,0,0,0,0,0,0,0,0,0,0,9,65,9,80,80,80,80,14,80,80,80,80,80,80,80,80,80,80,80,80,80,0,0,0
0,0,0,0,0,0,0,0,0,0,0,0,0,0,0,0,9,80,80,80,80,6,6,6,6,20,20,20,6,80,80,80,80,80,80,0,0,0,0
0,0,0,0,0,0,0,0,0,0,0,0,0,0,0,0,52,80,80,80,20,6,6,6,20,20,21,21,21,21,21,21,6,21,21,0,0,0,45
0,0,0,0,0,0,0,0,0,0,0,0,0,0,0,0,9,80,80,80,80,6,6,6,20,80,0,21,21,21,0,0,21,21,21,0,0,80,80
0,0,0,0,0,0,0,0,0,0,0,0,0,0,0,9,80,104,80,80,80,80,14,6,0,0,0,0,21,21,0,0,21,21,21,53,0,21,80
0,0,0,0,0,0,0,0,0,0,0,0,0,0,0,0,41,9,80,21,80,80,0,0,0,0,21,21,0,0,0,0,21,21,21,0,0,80,80
0,0,0,0,0,0,0,0,0,0,0,0,0,0,0,71,0,0,80,21,80,80,6,80,80,0,21,0,20,6,6,0,21,21,21,0,0,0,39
0,0,0,0,0,0,0,0,0,0,0,0,0,0,0,16,0,9,80,80,80,80,80,0,80,80,20,6,20,6,20,20,6,21,21,38,0,0,0
0,0,0,0,0,0,0,0,0,0,0,0,0,0,9,0,0,9,39,80,80,80,80,80,0,80,0,21,6,14,6,21,21,21,0,0,0,0,0
0,0,0,0,0,0,0,0,0,0,0,0,0,16,9,0,0,39,0,39,80,80,80,80,21,21,21,21,0,21,0,21,21,21,0,0,0,0,0
0,0,0,0,0,0,0,0,99,0,0,0,16,0,0,0,39,39,39,16,41,80,80,80,80,21,21,21,0,14,21,21,21,21,21,0,0,0,0
0,0,0,0,0,0,0,45,21,99,0,0,0,9,39,39,0,0,9,9,0,31,31,80,80,21,21,21,21,14,38,21,21,21,21,0,0,0,0
0,0,0,0,0,0,52,21,21,21,0,0,0,0,66,0,0,0,0,9,0,80,31,31,80,80,6,0,0,6,80,80,0,80,80,0,0,0,0
0,0,0,0,0,0,9,80,21,3,0,0,39,0,0,0,0,0,0,0,3,80,0,0,39,80,80,80,6,14,6,80,80,80,80,80,80,38,0
0,0,0,0,0,0,0,39,73,0,0,0,39,0,0,0,0,0,0,0,0,0,0,0,52,80,80,80,80,6,80,80,80,80,80,80,80,53,0
0,0,0,0,0,0,0,0,0,0,0,0,0,0,0,0,0,0,0,0,0,0,0,0,0,9,80,80,0,80,80,80,80,80,80,80,80,45,0
0,0,0,0,0,0,0,0,0,0,0,0,0,0,0,0,0,0,0,0,0,0,0,0,0,9,41,0,0,0,21,21,21,39,39,80,38,0,87
0,0,0,0,0,0,0,0,0,0,0,0,0,0,0,0,0,0,0,0,0,0,0,0,0,0,39,21,20,21,21,0,41,0,39,39,0,0,38
0,0,0,0,0,0,0,0,0,0,0,0,0,0,0,0,0,0,0,0,0,0,0,0,0,0,9,0,21,21,21,0,0,0,39,39,0,0,0
0,0,0,0,0,0,0,0,0,0,0,0,0,0,0,0,0,0,0,0,0,0,0,0,0,0,0,9,21,6,21,80,0,0,0,0,39,0,0
0,0,0,0,0,0,0,0,0,0,0,0,0,0,0,0,0,0,0,0,0,0,0,0,0,0,0,0,80,80,80,80,38,0,0,0,39,0,0
0,0,0,0,0,0,0,0,0,0,0,0,0,0,0,0,0,0,0,0,0,0,0,0,0,0,0,0,0,80,80,38,0,0,0,0,0,0,0
0,0,0,0,0,0,0,0,0,0,0,0,0,0,0,0,0,0,0,0,0,0,0,0,0,0,0,0,39,0,39,0,0,0,0,0,0,0,0
0,0,0,0,0,0,0,0,0,0,0,0,0,0,0,0,0,0,0,0,0,0,0,0,0,0,0,0,0,0,0,0,0,0,0,0,0,0,0
endlayer

layer
0,0,0,0,0,0,0,0,0,0,0,0,0,0,0,0,0,0,0,0,0,0,0,0,0,21,21,21,38,0,0,0,0,0,0,0,0,0,0
0,0,0,0,0,0,0,0,0,0,0,0,0,0,0,0,0,0,45,0,0,0,0,0,0,80,21,80,0,0,0,0,0,0,0,0,0,0,0
0,0,0,0,0,0,0,0,0,0,0,0,0,0,0,0,45,45,45,43,45,0,0,0,0,80,80,80,0,0,0,0,0,0,0,45,45,0,0
0,0,0,0,0,0,0,0,0,0,0,0,0,0,0,0,0,0,0,45,43,43,45,80,80,80,21,21,45,45,0,0,54,45,45,45,38,38,0
0,0,0,0,0,0,0,0,0,0,0,0,0,0,0,9,9,0,0,16,80,80,80,80,21,21,21,21,80,80,45,45,80,80,80,80,38,38,0
0,0,0,0,0,0,0,0,0,0,0,0,0,0,9,9,0,0,45,80,80,80,80,80,21,21,21,21,21,80,80,80,80,80,80,80,66,0,0
0,0,0,0,0,0,0,0,0,0,0,0,0,0,0,0,9,9,80,80,80,80,0,0,21,80,80,80,0,80,80,80,80,80,80,80,38,0,0
0,0,0,0,0,0,0,0,0,0,0,0,0,0,0,9,65,9,80,80,80,80,80,0,80,80,0,80,80,80,80,80,80,80,80,0,0,0,0
0,0,0,0,0,0,0,0,0,0,0,0,0,0,0,0,0,9,80,80,80,6,6,6,80,80,80,80,6,0,0,80,80,80,80,53,0,0,0
0,0,0,0,0,0,0,0,0,0,0,0,0,0,0,0,9,80,80,80,80,6,6,6,6,0,0,0,0,0,80,0,80,80,0,0,0,0,45
0,0,0,0,0,0,0,0,0,0,0,0,0,0,0,0,0,39,80,80,80,6,6,6,6,80,0,21,21,0,0,0,0,21,0,0,0,54,80
0,0,0,0,0,0,0,0,0,0,0,0,0,0,0,0,0,45,80,80,0,80,6,6,6,0,0,0,21,21,21,0,0,21,0,0,0,80,80
0,0,0,0,0,0,0,0,0,0,0,0,0,0,0,0,9,0,80,80,80,80,80,80,80,0,0,21,0,6,21,21,0,21,38,0,0,0,80
0,0,0,0,0,0,0,0,0,0,0,0,0,0,0,71,0,0,80,80,80,80,80,80,0,0,0,0,6,6,6,21,21,21,38,0,0,0,39
0,0,0,0,0,0,0,0,0,0,0,0,0,0,0,16,0,9,80,80,80,80,80,80,0,20,20,6,6,6,6,6,21,0,38,0,0,0,0
0,0,0,0,0,0,0,0,0,0,0,0,0,0,9,0,0,9,39,21,21,80,80,21,80,80,21,6,6,6,6,21,21,54,0,0,0,0,0
0,0,0,0,0,0,0,0,0,0,0,0,0,16,9,0,0,39,0,41,80,80,80,80,80,80,21,21,0,6,21,41,21,21,0,0,0,0,0
0,0,0,0,0,0,0,0,99,0,0,0,16,0,0,0,39,39,39,16,80,39,39,80,80,80,21,21,0,14,21,21,21,21,3,0,0,0,0
0,0,0,0,0,0,0,105,80,0,0,0,0,9,39,39,0,0,9,9,0,0,0,0,41,80,21,21,21,14,38,21,21,21,54,0,0,0,0
0,0,0,0,0,0,71,21,21,80,0,0,0,0,66,0,0,0,0,9,0,80,0,0,0,80,21,21,80,14,80,80,80,80,80,0,0,0,0
0,0,0,0,0,0,0,80,80,0,0,0,39,39,0,0,0,0,0,0,39,0,0,0,0,41,80,80,20,14,20,80,80,80,80,80,54,0,0
0,0,0,0,0,0,0,0,73,0,0,0,39,0,0,0,0,0,0,0,0,0,0,0,0,9,80,80,80,14,80,80,80,80,80,80,80,0,0
0,0,0,0,0,0,0,0,0,0,0,0,0,0,0,0,0,0,0,0,0,0,0,0,0,9,80,80,0,80,80,80,80,80,80,80,21,45,0
0,0,0,0,0,0,0,0,0,0,0,0,0,0,0,0,0,0,0,0,0,0,0,0,0,9,21,6,80,80,0,3,0,0,80,80,21,21,87
0,0,0,0,0,0,0,0,0,0,0,0,0,0,0,0,0,0,0,0,0,0,0,0,0,0,39,21,21,0,0,0,0,0,39,80,0,41,38
0,0,0,0,0,0,0,0,0,0,0,0,0,0,0,0,0,0,0,0,0,0,0,0,0,0,9,21,21,0,80,0,0,0,39,39,0,0,0
0,0,0,0,0,0,0,0,0,0,0,0,0,0,0,0,0,0,0,0,0,0,0,0,0,0,0,9,21,6,80,80,0,0,0,0,39,0,0
0,0,0,0,0,0,0,0,0,0,0,0,0,0,0,0,0,0,0,0,0,0,0,0,0,0,0,0,80,80,21,80,0,0,0,0,39,0,0
0,0,0,0,0,0,0,0,0,0,0,0,0,0,0,0,0,0,0,0,0,0,0,0,0,0,0,0,80,80,80,38,0,0,0,0,0,0,0
0,0,0,0,0,0,0,0,0,0,0,0,0,0,0,0,0,0,0,0,0,0,0,0,0,0,0,0,39,41,39,0,0,0,0,0,0,0,0
0,0,0,0,0,0,0,0,0,0,0,0,0,0,0,0,0,0,0,0,0,0,0,0,0,0,0,0,0,0,0,0,0,0,0,0,0,0,0
endlayer

layer
0,0,0,0,0,0,0,0,0,0,0,0,0,0,0,0,0,0,0,0,0,0,0,0,0,21,21,21,38,0,0,0,0,0,0,0,0,0,0
0,0,0,0,0,0,0,0,0,0,0,0,0,0,0,0,0,0,45,0,0,0,0,0,0,80,21,21,0,0,0,0,0,0,0,0,0,0,0
0,0,0,0,0,0,0,0,0,0,0,0,0,0,0,0,45,45,45,43,45,0,0,0,0,80,80,80,0,0,0,0,0,0,0,45,45,0,0
0,0,0,0,0,0,0,0,0,0,0,0,0,0,0,0,0,0,0,45,43,43,45,80,0,0,80,0,0,0,0,0,0,45,54,54,38,38,0
0,0,0,0,0,0,0,0,0,0,0,0,0,0,0,9,9,0,0,16,80,80,80,80,45,45,80,54,45,0,0,0,0,80,80,80,53,38,0
0,0,0,0,0,0,0,0,0,0,0,0,0,0,9,9,0,0,54,80,80,80,80,80,42,21,21,80,21,45,45,0,80,80,80,80,66,0,0
0,0,0,0,0,0,0,0,0,0,0,0,0,0,0,9,9,9,80,80,80,80,0,80,80,80,80,80,80,80,21,21,21,80,80,80,38,0,0
0,0,0,0,0,0,0,0,0,0,0,0,0,0,0,9,65,9,80,80,21,14,0,80,0,80,0,0,80,80,21,21,21,80,0,0,0,0,0
0,0,0,0,0,0,0,0,0,0,0,0,0,0,0,0,0,9,80,80,21,6,20,6,80,80,0,0,6,80,0,21,21,0,0,0,0,0,0
0,0,0,0,0,0,0,0,0,0,0,0,0,0,0,0,0,52,80,80,80,14,6,6,6,0,0,0,80,80,80,80,80,0,0,0,0,0,0
0,0,0,0,0,0,0,0,0,0,0,0,0,0,0,0,0,0,80,80,80,6,6,6,6,0,0,0,0,0,21,21,21,21,0,0,0,0,3
0,0,0,0,0,0,0,0,0,0,0,0,0,0,0,0,0,45,80,80,80,80,6,6,6,20,0,42,21,21,21,21,21,21,53,0,0,9,21
0,0,0,0,0,0,0,0,0,0,0,0,0,0,0,0,9,80,80,80,80,80,80,0,14,0,0,42,42,45,0,21,21,21,38,0,0,0,21
0,0,0,0,0,0,0,0,0,0,0,0,0,0,0,71,0,80,80,21,80,21,21,0,14,0,6,42,6,6,6,21,21,21,38,0,0,0,39
0,0,0,0,0,0,0,0,0,0,0,0,0,0,0,16,0,80,80,80,80,80,80,80,6,20,6,20,6,6,6,21,21,0,38,0,0,0,0
0,0,0,0,0,0,0,0,0,0,0,0,0,0,9,0,0,9,21,21,21,80,80,80,80,80,21,6,20,6,21,21,21,38,0,0,0,0,0
0,0,0,0,0,0,0,0,0,0,0,0,0,16,9,0,0,39,0,0,80,80,80,80,80,80,21,0,21,14,21,21,21,38,0,0,0,0,0
0,0,0,0,0,0,0,0,99,0,0,0,16,0,0,0,39,39,39,16,65,39,39,80,80,9,21,21,0,14,21,21,21,0,0,0,0,0,0
0,0,0,0,0,0,0,71,80,0,0,0,0,9,39,39,0,0,9,9,0,0,0,0,0,9,21,21,21,21,21,21,21,0,0,0,0,0,0
0,0,0,0,0,0,0,80,80,80,9,0,0,0,66,0,0,0,0,9,0,80,0,0,0,0,80,21,80,80,80,80,80,0,0,0,0,0,0
0,0,0,0,0,0,0,71,80,41,0,0,39,39,0,0,0,0,0,0,39,0,0,0,0,0,80,80,80,80,80,80,80,0,0,0,0,0,0
0,0,0,0,0,0,0,0,73,0,0,0,39,0,0,0,0,0,0,0,0,0,0,0,0,9,80,80,80,80,80,80,0,0,0,45,0,0,0
0,0,0,0,0,0,0,0,0,0,0,0,0,0,0,0,0,0,0,0,0,0,0,0,0,9,80,80,80,80,80,0,3,0,80,80,21,45,0
0,0,0,0,0,0,0,0,0,0,0,0,0,0,0,0,0,0,0,0,0,0,0,0,0,0,80,6,80,3,0,0,0,0,80,80,21,53,38
0,0,0,0,0,0,0,0,0,0,0,0,0,0,0,0,0,0,0,0,0,0,0,0,0,0,39,41,0,0,0,0,0,0,80,80,21,0,38
0,0,0,0,0,0,0,0,0,0,0,0,0,0,0,0,0,0,0,0,0,0,0,0,0,0,0,0,0,0,0,0,0,0,39,39,0,0,0
0,0,0,0,0,0,0,0,0,0,0,0,0,0,0,0,0,0,0,0,0,0,0,0,0,0,0,0,80,80,80,0,0,0,0,0,39,0,0
0,0,0,0,0,0,0,0,0,0,0,0,0,0,0,0,0,0,0,0,0,0,0,0,0,0,0,0,80,80,80,53,0,0,0,0,39,0,0
0,0,0,0,0,0,0,0,0,0,0,0,0,0,0,0,0,0,0,0,0,0,0,0,0,0,0,0,80,80,80,0,0,0,0,0,0,0,0
0,0,0,0,0,0,0,0,0,0,0,0,0,0,0,0,0,0,0,0,0,0,0,0,0,0,0,0,39,39,0,0,0,0,0,0,0,0,0
0,0,0,0,0,0,0,0,0,0,0,0,0,0,0,0,0,0,0,0,0,0,0,0,0,0,0,0,0,0,0,0,0,0,0,0,0,0,0
endlayer

layer
0,0,0,0,0,0,0,0,0,0,0,0,0,0,0,0,0,0,0,0,0,0,0,0,0,16,21,0,0,0,0,0,0,0,0,0,0,0,0
0,0,0,0,0,0,0,0,0,0,0,0,0,0,0,0,0,0,45,0,0,0,0,0,0,80,21,21,0,0,0,0,0,0,0,0,0,0,0
0,0,0,0,0,0,0,0,0,0,0,0,0,0,0,0,45,45,45,43,45,0,0,0,0,9,80,0,0,0,0,0,0,0,0,45,45,0,0
0,0,0,0,0,0,0,0,0,0,0,0,0,0,0,0,0,0,0,45,43,38,0,0,0,0,0,0,0,0,0,0,0,0,16,0,38,38,0
0,0,0,0,0,0,0,0,0,0,0,0,0,0,0,9,9,0,0,16,0,43,0,54,45,45,0,0,0,0,0,0,0,0,80,80,38,38,0
0,0,0,0,0,0,0,0,0,0,0,0,0,0,9,9,0,0,80,80,21,0,80,80,21,21,0,3,0,0,0,0,0,80,80,80,66,0,0
0,0,0,0,0,0,0,0,0,0,0,0,0,0,0,9,9,9,80,80,80,0,21,0,80,21,21,21,54,45,45,0,0,80,80,38,0,0,0
0,0,0,0,0,0,0,0,0,0,0,0,0,0,0,9,65,9,80,21,14,14,21,80,80,21,21,21,80,80,21,54,0,0,0,0,0,0,0
0,0,0,0,0,0,0,0,0,0,0,0,0,0,0,0,0,0,9,80,20,6,0,80,0,0,80,80,80,80,21,21,0,0,0,0,0,0,0
0,0,0,0,0,0,0,0,0,0,0,0,0,0,0,0,0,0,80,80,80,80,6,6,6,20,20,20,80,80,80,80,3,0,0,0,0,0,0
0,0,0,0,0,0,0,0,0,0,0,0,0,0,0,0,0,0,80,80,80,80,6,6,20,6,80,21,21,21,80,80,0,0,0,0,0,0,0
0,0,0,0,0,0,0,0,0,0,0,0,0,0,0,0,0,99,80,80,80,80,80,14,6,20,20,20,80,80,80,80,80,38,0,0,0,9,21
0,0,0,0,0,0,0,0,0,0,0,0,0,0,0,0,99,80,80,80,80,80,80,14,14,6,20,20,21,21,80,80,80,80,38,0,0,0,39
0,0,0,0,0,0,0,0,0,0,0,0,0,0,0,71,80,80,21,21,80,80,80,0,6,14,20,20,20,6,80,80,80,80,0,0,0,0,0
0,0,0,0,0,0,0,0,0,0,0,0,0,0,0,16,80,80,80,80,80,80,80,80,6,6,6,20,6,6,6,0,80,80,38,0,0,0,0
0,0,0,0,0,0,0,0,0,0,0,0,0,0,9,52,80,80,21,21,80,80,80,80,80,80,80,6,6,6,80,80,45,87,0,0,0,0,0
0,0,0,0,0,0,0,0,0,0,0,0,0,16,9,0,0,39,21,0,41,80,80,80,80,80,80,80,80,0,80,41,80,38,0,0,0,0,0
0,0,0,0,0,0,0,0,0,0,0,0,16,0,0,0,39,39,39,16,9,0,21,21,80,9,80,21,80,80,80,80,0,0,0,0,0,0,0
0,0,0,0,0,0,0,45,80,0,0,9,0,9,39,39,0,0,9,9,0,0,0,80,0,9,80,80,80,80,21,3,0,0,0,0,0,0,0
0,0,0,0,0,0,52,80,80,80,9,0,0,0,66,0,0,0,0,9,0,80,0,41,0,52,80,80,80,80,21,0,0,0,0,0,0,0,0
0,0,0,0,0,0,0,39,80,0,0,39,39,39,0,0,0,0,0,0,39,0,0,0,0,0,80,80,80,80,21,0,0,0,0,0,0,0,0
0,0,0,0,0,0,0,0,73,0,0,0,39,0,0,0,0,0,0,0,0,0,0,0,0,9,80,80,80,80,80,0,0,0,0,0,0,0,0
0,0,0,0,0,0,0,0,0,0,0,0,0,0,0,0,0,0,0,0,0,0,0,0,0,52,80,80,41,80,0,0,0,0,0,80,45,45,0
0,0,0,0,0,0,0,0,0,0,0,0,0,0,0,0,0,0,0,0,0,0,0,0,0,0,39,80,0,41,0,0,0,0,80,80,21,38,38
0,0,0,0,0,0,0,0,0,0,0,0,0,0,0,0,0,0,0,0,0,0,0,0,0,0,0,0,0,0,0,0,0,0,3,80,80,53,38
0,0,0,0,0,0,0,0,0,0,0,0,0,0,0,0,0,0,0,0,0,0,0,0,0,0,0,0,0,0,0,0,0,0,0,39,0,0,0
0,0,0,0,0,0,0,0,0,0,0,0,0,0,0,0,0,0,0,0,0,0,0,0,0,0,0,0,0,80,0,0,0,0,0,0,39,0,0
0,0,0,0,0,0,0,0,0,0,0,0,0,0,0,0,0,0,0,0,0,0,0,0,0,0,0,0,80,80,80,0,0,0,0,0,39,0,0
0,0,0,0,0,0,0,0,0,0,0,0,0,0,0,0,0,0,0,0,0,0,0,0,0,0,0,0,0,80,0,0,0,0,0,0,0,0,0
0,0,0,0,0,0,0,0,0,0,0,0,0,0,0,0,0,0,0,0,0,0,0,0,0,0,0,0,0,0,0,0,0,0,0,0,0,0,0
0,0,0,0,0,0,0,0,0,0,0,0,0,0,0,0,0,0,0,0,0,0,0,0,0,0,0,0,0,0,0,0,0,0,0,0,0,0,0
endlayer

layer
0,0,0,0,0,0,0,0,0,0,0,0,0,0,0,0,0,0,0,0,0,0,0,0,0,16,21,0,0,0,0,0,0,0,0,0,0,0,0
0,0,0,0,0,0,0,0,0,0,0,0,0,0,0,0,0,0,45,0,0,0,0,0,0,80,21,80,0,0,0,0,0,0,0,0,0,0,0
0,0,0,0,0,0,0,0,0,0,0,0,0,0,0,0,45,45,45,43,45,0,0,0,0,9,80,0,0,0,0,0,0,0,0,45,45,0,0
0,0,0,0,0,0,0,0,0,0,0,0,0,0,0,0,0,0,0,45,43,38,0,0,0,0,0,0,0,0,0,0,0,0,16,0,38,38,0
0,0,0,0,0,0,0,0,0,0,0,0,0,0,0,9,9,0,0,16,80,43,0,45,0,0,0,0,0,0,0,0,0,0,80,80,38,38,0
0,0,0,0,0,0,0,0,0,0,0,0,0,0,9,9,0,52,80,80,80,80,38,80,45,3,0,0,0,0,0,0,0,3,80,80,66,0,0
0,0,0,0,0,0,0,0,0,0,0,0,0,0,0,9,9,0,80,80,14,0,80,80,80,45,45,45,0,0,0,0,0,0,3,0,0,0,0
0,0,0,0,0,0,0,0,0,0,0,0,0,0,0,9,65,9,80,20,6,80,80,80,80,80,21,21,80,80,38,0,0,0,0,0,0,0,0
0,0,0,0,0,0,0,0,0,0,0,0,0,0,0,0,0,0,9,80,80,80,80,80,14,80,80,80,80,80,87,0,0,0,0,0,0,0,0
0,0,0,0,0,0,0,0,0,0,0,0,0,0,0,0,0,0,39,80,80,65,80,20,20,20,80,80,80,80,87,0,0,0,0,0,0,0,0
0,0,0,0,0,0,0,0,0,0,0,0,0,0,0,0,0,0,0,21,21,21,14,20,20,14,80,80,80,80,80,3,0,0,0,0,0,0,0
0,0,0,0,0,0,0,0,0,0,0,0,0,0,0,0,0,99,0,21,21,21,80,14,14,14,6,80,0,80,80,3,0,0,0,0,0,9,21
0,0,0,0,0,0,0,0,0,0,0,0,0,0,0,0,9,80,21,21,21,21,21,14,14,14,20,6,43,80,80,80,3,0,0,0,0,0,39
0,0,0,0,0,0,0,0,0,0,0,0,0,0,0,0,80,21,21,21,21,80,21,21,80,14,6,6,6,80,80,80,3,0,0,0,0,0,0
0,0,0,0,0,0,0,0,0,0,0,0,0,0,0,16,80,80,80,80,80,80,21,21,21,21,80,6,6,20,20,80,80,53,0,0,0,0,0
0,0,0,0,0,0,0,0,0,0,0,0,0,0,9,9,80,80,80,9,80,80,21,21,21,21,80,80,14,80,80,38,0,87,0,0,0,0,0
0,0,0,0,0,0,0,0,0,0,0,0,0,16,9,0,0,80,0,0,79,21,21,21,21,21,80,80,80,80,80,0,0,38,0,0,0,0,0
0,0,0,0,0,0,0,0,0,0,0,0,16,0,0,0,39,39,0,16,9,21,21,21,21,0,0,106,21,80,0,80,0,0,0,0,0,0,0
0,0,0,0,0,0,0,45,80,0,0,16,0,9,39,39,0,0,9,9,0,41,21,21,0,0,0,106,21,80,80,80,0,0,0,0,0,0,0
0,0,0,0,0,0,71,80,80,80,9,0,0,0,66,0,0,0,0,9,0,0,41,0,0,0,3,106,21,80,38,0,0,0,0,0,0,0,0
0,0,0,0,0,0,0,73,80,41,0,39,39,39,0,0,0,0,0,0,39,0,0,0,0,0,0,30,80,21,80,0,0,0,0,0,0,0,0
0,0,0,0,0,0,0,0,0,0,0,0,39,0,0,0,0,0,0,0,0,0,1,0,0,0,3,0,39,80,38,0,0,0,0,0,0,0,0
0,0,0,0,0,0,0,0,0,0,0,0,0,0,0,0,0,0,0,0,0,0,0,0,0,0,0,0,0,0,0,0,0,0,0,80,0,45,0
0,0,0,0,0,0,0,0,0,0,0,0,0,0,0,0,0,0,0,0,0,0,0,0,0,0,0,0,0,0,0,0,0,0,80,80,80,38,38
0,0,0,0,0,0,0,0,0,0,0,0,0,0,0,0,0,0,0,0,0,0,0,0,0,0,0,0,0,0,0,0,0,0,0,80,80,80,38
0,0,0,0,0,0,0,0,0,0,0,0,0,0,0,0,0,0,0,0,0,0,0,0,0,0,0,0,0,0,0,0,0,0,0,0,80,0,0
0,0,0,0,0,0,0,0,0,0,0,0,0,0,0,0,0,0,0,0,0,0,0,0,0,0,0,0,0,80,0,0,0,0,0,0,39,0,0
0,0,0,0,0,0,0,0,0,0,0,0,0,0,0,0,0,0,0,0,0,0,0,0,0,0,0,0,80,80,80,0,0,0,0,0,39,0,0
0,0,0,0,0,0,0,0,0,0,0,0,0,0,0,0,0,0,0,0,0,0,0,0,0,0,0,0,41,80,0,0,0,0,0,0,0,0,0
0,0,0,0,0,0,0,0,0,0,0,0,0,0,0,0,0,0,0,0,0,0,0,0,0,0,0,0,0,0,0,0,0,0,0,0,0,0,0
0,0,0,0,0,0,0,0,0,0,0,0,0,0,0,0,0,0,0,0,0,0,0,0,0,0,0,0,0,0,0,0,0,0,0,0,0,0,0
endlayer

layer
0,0,0,0,0,0,0,0,0,0,0,0,0,0,0,0,0,0,0,0,0,0,0,0,0,9,80,0,0,0,0,0,0,0,0,0,0,0,0
0,0,0,0,0,0,0,0,0,0,0,0,0,0,0,0,0,0,45,0,0,0,0,0,0,9,80,53,0,0,0,0,0,0,0,0,0,0,0
0,0,0,0,0,0,0,0,0,0,0,0,0,0,0,0,45,45,45,43,45,0,0,0,0,9,80,0,0,0,0,0,0,0,0,45,45,0,0
0,0,0,0,0,0,0,0,0,0,0,0,0,0,0,0,0,0,0,45,43,38,0,0,0,0,0,0,0,0,0,0,0,0,16,80,38,38,0
0,0,0,0,0,0,0,0,0,0,0,0,0,0,0,9,9,0,80,45,80,38,0,0,0,0,0,0,0,0,0,0,0,52,80,80,80,38,0
0,0,0,0,0,0,0,0,0,0,0,0,0,0,9,9,0,45,80,80,80,38,38,0,0,0,0,0,0,0,0,0,0,9,80,80,39,0,0
0,0,0,0,0,0,0,0,0,0,0,0,0,0,0,9,9,21,80,14,80,80,0,0,0,0,0,0,0,0,0,0,0,0,0,0,0,0,0
0,0,0,0,0,0,0,0,0,0,0,0,0,0,0,9,65,0,80,20,6,80,80,80,80,0,0,3,45,45,0,0,0,0,0,0,0,0,0
0,0,0,0,0,0,0,0,0,0,0,0,0,0,0,0,0,0,80,80,80,80,80,80,80,0,45,80,80,80,87,0,0,0,0,0,0,0,0
0,0,0,0,0,0,0,0,0,0,0,0,0,0,0,0,0,0,39,0,0,39,9,80,80,80,80,80,80,80,53,0,0,0,0,0,0,0,0
0,0,0,0,0,0,0,0,0,0,0,0,0,0,0,0,0,0,0,0,0,9,80,80,80,80,45,45,80,80,0,0,0,0,0,0,0,0,0
0,0,0,0,0,0,0,0,0,0,0,0,0,0,0,0,0,0,0,0,0,0,39,80,80,6,6,80,80,80,80,0,0,0,0,0,0,9,80
0,0,0,0,0,0,0,0,0,0,0,0,0,0,0,0,0,99,3,0,0,54,80,21,80,6,6,6,43,80,80,87,0,0,0,0,0,0,39
0,0,0,0,0,0,0,0,0,0,0,0,0,0,0,0,45,80,21,0,0,80,80,21,80,80,6,6,6,0,80,0,99,0,0,0,0,0,0
0,0,0,0,0,0,0,0,0,0,0,0,0,0,0,16,21,21,80,0,9,80,80,80,21,21,80,6,6,0,80,0,80,87,0,0,0,0,0
0,0,0,0,0,0,0,0,0,0,0,0,0,0,9,80,80,21,0,0,0,0,80,80,80,21,80,80,80,80,80,38,0,87,0,0,0,0,0
0,0,0,0,0,0,0,0,0,0,0,0,0,16,9,80,80,41,0,0,16,9,21,80,80,0,80,80,80,80,80,0,0,38,0,0,0,0,0
0,0,0,0,0,0,0,0,0,0,0,0,16,0,0,0,39,0,0,16,9,21,21,21,0,0,41,0,21,80,0,0,0,0,0,0,0,0,0
0,0,0,0,0,0,0,0,0,0,0,16,0,9,39,39,0,0,9,9,0,21,21,0,0,0,0,0,21,80,0,0,0,0,0,0,0,0,0
0,0,0,0,0,0,0,9,80,3,9,0,0,0,66,0,0,0,0,9,0,0,0,0,0,0,0,52,21,80,38,0,0,0,0,0,0,0,0
0,0,0,0,0,0,0,0,39,0,0,39,39,39,0,0,0,0,0,0,39,0,0,0,0,0,0,9,80,21,80,0,0,0,0,0,0,0,0
0,0,0,0,0,0,0,0,0,0,0,0,39,0,0,0,0,0,0,0,0,0,1,0,0,0,0,0,39,80,38,0,0,0,0,0,0,0,0
0,0,0,0,0,0,0,0,0,0,0,0,0,0,0,0,0,0,0,0,0,0,0,0,0,0,0,0,0,0,0,0,0,0,0,0,0,45,0
0,0,0,0,0,0,0,0,0,0,0,0,0,0,0,0,0,0,0,0,0,0,0,0,0,0,0,0,0,0,0,0,0,0,0,80,80,80,38
0,0,0,0,0,0,0,0,0,0,0,0,0,0,0,0,0,0,0,0,0,0,0,0,0,0,0,0,0,0,0,0,0,0,52,21,21,80,38
0,0,0,0,0,0,0,0,0,0,0,0,0,0,0,0,0,0,0,0,0,0,0,0,0,0,0,0,0,0,0,0,0,0,0,80,21,80,0
0,0,0,0,0,0,0,0,0,0,0,0,0,0,0,0,0,0,0,0,0,0,0,0,0,0,0,0,0,45,0,0,0,0,0,41,0,0,0
0,0,0,0,0,0,0,0,0,0,0,0,0,0,0,0,0,0,0,0,0,0,0,0,0,0,0,0,9,80,53,0,0,0,0,0,39,0,0
0,0,0,0,0,0,0,0,0,0,0,0,0,0,0,0,0,0,0,0,0,0,0,0,0,0,0,0,0,39,0,0,0,0,0,0,0,0,0
0,0,0,0,0,0,0,0,0,0,0,0,0,0,0,0,0,0,0,0,0,0,0,0,0,0,0,0,0,0,0,0,0,0,0,0,0,0,0
0,0,0,0,0,0,0,0,0,0,0,0,0,0,0,0,0,0,0,0,0,0,0,0,0,0,0,0,0,0,0,0,0,0,0,0,0,0,0
endlayer

layer
0,0,0,0,0,0,0,0,0,0,0,0,0,0,0,0,0,0,0,0,0,0,0,0,0,0,45,0,0,0,0,0,0,0,0,0,0,0,0
0,0,0,0,0,0,0,0,0,0,0,0,0,0,0,0,0,0,45,0,0,0,0,0,0,9,80,38,0,0,0,0,0,0,0,0,0,0,0
0,0,0,0,0,0,0,0,0,0,0,0,0,0,0,0,45,45,45,43,45,0,0,0,0,9,80,0,0,0,0,0,0,0,0,45,45,0,0
0,0,0,0,0,0,0,0,0,0,0,0,0,0,0,0,0,54,0,45,38,38,0,0,0,0,0,0,0,0,0,0,0,0,9,80,38,38,0
0,0,0,0,0,0,0,0,0,0,0,0,0,0,0,9,9,80,21,80,0,0,0,0,0,0,0,0,0,0,0,0,0,9,80,80,80,38,0
0,0,0,0,0,0,0,0,0,0,0,0,0,0,9,9,0,80,14,80,80,38,38,0,0,0,0,0,0,0,0,0,0,0,80,80,0,0,0
0,0,0,0,0,0,0,0,0,0,0,0,0,0,0,9,9,21,20,6,80,38,0,0,0,0,0,0,0,0,0,0,0,0,0,41,0,0,0
0,0,0,0,0,0,0,0,0,0,0,0,0,0,0,9,65,80,80,80,38,38,0,0,0,0,0,0,45,45,0,0,0,0,0,0,0,0,0
0,0,0,0,0,0,0,0,0,0,0,0,0,0,0,0,0,0,3,0,39,0,0,80,0,0,0,45,80,80,87,0,0,0,0,0,0,0,0
0,0,0,0,0,0,0,0,0,0,0,0,0,0,0,0,0,0,39,0,0,0,0,0,0,0,0,80,80,80,38,0,0,0,0,0,0,0,0
0,0,0,0,0,0,0,0,0,0,0,0,0,0,0,0,0,0,0,0,0,0,0,80,80,80,80,80,80,73,0,0,0,0,0,0,0,0,0
0,0,0,0,0,0,0,0,0,0,0,0,0,0,0,0,0,0,0,0,0,0,52,80,80,80,6,80,80,0,0,0,0,0,0,0,0,9,80
0,0,0,0,0,0,0,0,0,0,0,0,0,0,0,0,0,0,0,0,0,0,9,21,80,6,6,6,0,80,0,0,0,0,0,0,0,0,39
0,0,0,0,0,0,0,0,0,0,0,0,0,0,0,0,45,45,0,0,0,9,80,80,80,80,6,6,6,0,0,0,0,0,0,0,0,0,0
0,0,0,0,0,0,0,0,0,0,0,0,0,0,0,16,21,21,0,0,0,9,80,80,80,21,80,6,80,0,80,0,80,87,0,0,0,0,0
0,0,0,0,0,0,0,0,0,0,0,0,0,0,9,21,21,21,0,0,0,0,0,80,80,80,80,80,0,80,80,0,80,87,0,0,0,0,0
0,0,0,0,0,0,0,0,0,0,0,0,0,16,63,80,21,0,0,0,16,21,21,80,0,0,3,0,80,80,87,0,80,38,0,0,0,0,0
0,0,0,0,0,0,0,0,0,0,0,0,16,0,0,80,39,0,0,16,9,21,21,21,0,0,0,0,0,0,0,0,0,0,0,0,0,0,0
0,0,0,0,0,0,0,0,54,0,0,16,0,9,39,39,0,0,9,9,80,80,21,80,0,1,0,0,3,0,0,0,0,0,0,0,0,0,0
0,0,0,0,0,0,0,9,80,0,9,0,0,0,66,0,0,0,0,9,41,80,0,0,0,0,0,0,0,80,38,0,0,0,0,0,0,0,0
0,0,0,0,0,0,0,0,39,0,0,39,39,39,0,0,0,0,0,0,39,0,0,0,0,1,0,0,80,21,80,53,0,0,0,0,0,0,0
0,0,0,0,0,0,0,0,0,0,0,0,39,0,0,0,0,0,0,0,0,0,0,0,0,0,0,0,39,80,38,0,0,0,0,0,0,0,0
0,0,0,0,0,0,0,0,0,0,0,0,0,0,0,0,0,0,0,0,0,0,0,0,0,0,0,0,0,0,0,0,0,0,0,0,54,45,0
0,0,0,0,0,0,0,0,0,0,0,0,0,0,0,0,0,0,0,0,0,0,0,0,0,0,0,0,0,0,0,0,0,0,0,80,80,80,38
0,0,0,0,0,0,0,0,0,0,0,0,0,0,0,0,0,0,0,0,0,0,0,0,0,0,0,0,0,0,0,0,0,0,0,21,21,80,80
0,0,0,0,0,0,0,0,0,0,0,0,0,0,0,0,0,0,0,0,0,0,0,0,0,0,0,0,0,0,0,0,0,0,0,80,21,80,41
0,0,0,0,0,0,0,0,0,0,0,0,0,0,0,0,0,0,0,0,0,0,0,0,0,0,0,0,0,45,0,0,0,0,0,0,80,0,0
0,0,0,0,0,0,0,0,0,0,0,0,0,0,0,0,0,0,0,0,0,0,0,0,0,0,0,0,9,80,38,0,0,0,0,0,39,0,0
0,0,0,0,0,0,0,0,0,0,0,0,0,0,0,0,0,0,0,0,0,0,0,0,0,0,0,0,0,39,0,0,0,0,0,0,0,0,0
0,0,0,0,0,0,0,0,0,0,0,0,0,0,0,0,0,0,0,0,0,1,0,0,0,0,0,0,0,0,0,0,0,0,0,0,0,0,0
0,0,0,0,0,0,0,0,0,0,0,0,0,0,0,0,0,0,0,0,0,0,0,0,0,0,0,0,0,0,0,0,0,0,0,0,0,0,0
endlayer

layer
0,0,0,0,0,0,0,0,0,0,0,0,0,0,0,0,0,0,0,0,0,0,0,0,0,0,45,0,0,0,0,0,0,0,0,0,0,0,0
0,0,0,0,0,0,0,0,0,0,0,0,0,0,0,0,0,0,45,0,0,0,0,0,0,9,80,38,0,0,0,0,0,0,0,0,0,0,0
0,0,0,0,0,0,0,0,0,0,0,0,0,0,0,0,45,45,45,43,45,0,0,0,0,9,80,0,0,0,0,0,0,0,0,54,45,0,0
0,0,0,0,0,0,0,0,0,0,0,0,0,0,0,0,0,16,0,45,38,38,0,0,0,0,0,0,0,0,0,0,0,0,9,80,80,38,0
0,0,0,0,0,0,0,0,0,0,0,0,0,0,0,9,9,21,21,80,0,0,0,0,0,0,0,0,0,0,0,0,0,9,80,80,80,38,0
0,0,0,0,0,0,0,0,0,0,0,0,0,0,9,9,0,21,21,80,0,38,38,0,0,0,0,0,0,0,0,0,0,0,80,80,41,0,0
0,0,0,0,0,0,0,0,0,0,0,0,0,0,0,9,9,21,21,80,38,38,0,0,0,0,0,0,0,0,0,0,0,0,0,0,0,0,0
