
# Created by Ruins mod version 14.6 Ingame Parser
# authoring Player: ArchNihil

weight=1
embed_into_distance=0
acceptable_target_blocks=
unacceptable_target_blocks=flowing_water,water,flowing_lava,lava
dimensions=169,31,39
allowable_overhang=0
max_leveling=2
leveling_buffer=0
preserve_water=0
preserve_lava=0

rule1=0,100,Railcraft:tile.railcraft.residual.heat-0
rule2=0,100,UndergroundBiomes:igneousStone-7
rule3=0,100,TwilightForest:tile.TFFirefly-5
rule4=0,100,minecraft:leaves-5
rule5=0,100,minecraft:leaves-13
rule6=0,100,minecraft:log-0
rule7=0,100,BiomesOPlenty:planks-9
rule8=0,100,ExtraUtilities:colorWoodPlanks-13
rule9=0,100,minecraft:vine-4
rule10=0,100,ExtraUtilities:colorWoodPlanks-5
rule11=0,100,BiomesOPlenty:logs1-5
rule12=0,100,BiomesOPlenty:logs1-9
rule13=0,100,BiomesOPlenty:logs1-1
rule14=0,100,minecraft:log-4
rule15=0,100,minecraft:grass-0
rule16=0,100,minecraft:vine-12
rule17=0,100,BiomesOPlenty:planks-1
rule18=0,100,minecraft:water-2
rule19=0,100,minecraft:water-3
rule20=0,100,minecraft:log-8
rule21=0,100,minecraft:leaves-12
rule22=0,100,minecraft:water-1
rule23=0,100,minecraft:water-0
rule24=0,100,minecraft:dirt-0
rule25=0,100,BiomesOPlenty:logs3-1
rule26=0,100,BiomesOPlenty:cherryStairs-3
rule27=0,100,minecraft:wooden_door-3
rule28=0,100,BiomesOPlenty:cherryStairs-2
rule29=0,100,BiomesOPlenty:woodenDoubleSlab1-1
rule30=0,100,minecraft:leaves-6
rule31=0,100,minecraft:vine-8
rule32=0,100,minecraft:vine-1
rule33=0,100,TwilightForest:tile.TFPlant-3
rule34=0,100,BiomesOPlenty:moss-0
rule35=0,100,minecraft:fence-0
rule36=0,100,BiomesOPlenty:moss-8
rule37=0,100,BiomesOPlenty:moss-11
rule38=0,100,minecraft:wooden_door-1
rule39=0,100,minecraft:wooden_door-8
rule40=0,100,minecraft:vine-2
rule41=0,100,minecraft:wooden_door-2
rule42=0,100,TwilightForest:tile.TFFirefly-1
rule43=0,100,minecraft:vine-0
rule44=0,100,minecraft:vine-9
rule45=0,100,Natura:BerryBush-8
rule46=0,100,BiomesOPlenty:moss-1
rule47=0,100,TConstruct:GlassBlock-0
rule48=0,100,minecraft:leaves-0
rule49=0,100,minecraft:leaves-8
rule50=0,100,BiomesOPlenty:flowerVine-1
rule51=0,100,TwilightForest:tile.TFFirefly-3
rule52=0,100,TwilightForest:tile.TFFirefly-4
rule53=0,100,TwilightForest:tile.TFFirefly-2
rule54=0,100,minecraft:tallgrass-1
rule55=0,100,Natura:BerryBush-9
rule56=0,100,Natura:BerryBush-4
rule57=0,100,Natura:BerryBush-14
rule58=0,100,BiomesOPlenty:logs3-9
rule59=0,100,BiomesOPlenty:moss-2
rule60=0,100,BiomesOPlenty:logs3-5
rule61=0,100,TwilightForest:tile.TFFirefly-6
rule62=0,100,minecraft:vine-6
rule63=0,100,minecraft:vine-3
rule64=0,100,minecraft:planks-0
rule65=0,100,BiomesOPlenty:flowerVine-5
rule66=0,100,minecraft:brown_mushroom-0
rule67=0,100,BiomesOPlenty:flowerVine-2
rule68=0,100,BiomesOPlenty:flowerVine-8
rule69=0,100,minecraft:vine-7
rule70=0,100,Natura:Thornvines-4
rule71=0,100,Natura:Thornvines-3
rule72=0,100,Natura:Thornvines-2
rule73=0,100,BiomesOPlenty:cherryStairs-1
rule74=0,100,BiomesOPlenty:flowerVine-11
rule75=0,100,BiomesOPlenty:flowerVine-4
rule76=0,100,BiomesOPlenty:flowerVine-9
rule77=0,100,BiomesOPlenty:woodenSingleSlab1-1
rule78=0,100,minecraft:vine-14
rule79=0,100,minecraft:leaves-4
rule80=0,100,TwilightForest:tile.TFPlant-9
rule81=0,100,BiomesOPlenty:flowerVine-10
rule82=0,100,BiomesOPlenty:flowers2-4
rule83=0,100,minecraft:yellow_flower-0
rule84=0,100,BiomesOPlenty:moss-14
rule85=0,100,minecraft:vine-11
rule86=0,100,Natura:Thornvines-1
rule87=0,100,BiomesOPlenty:flowerVine-6
rule88=0,100,minecraft:double_plant-2
rule89=0,100,BiomesOPlenty:cherryStairs-0
rule90=0,100,BiomesOPlenty:moss-4
rule91=0,100,minecraft:vine-15
rule92=0,100,minecraft:double_plant-8
rule93=0,100,BiomesOPlenty:flowerVine-12
rule94=0,100,minecraft:vine-5
rule95=0,100,Natura:Thornvines-6
rule96=0,100,Natura:Thornvines-0
rule97=0,100,BiomesOPlenty:colorizedLeaves2-0
rule98=0,100,BiomesOPlenty:moss-3
rule99=0,100,Natura:Thornvines-8
rule100=0,100,gregtech:gt.blockores-6
rule101=0,100,gregtech:gt.blockores-5
rule102=0,100,gregtech:gt.blockores-4
rule103=0,100,BiomesOPlenty:hell_blood-0
rule104=0,100,BiomesOPlenty:hell_blood-1
rule105=0,100,minecraft:vine-10
rule106=0,100,Natura:Thornvines-12
rule107=0,100,minecraft:leaves-14
rule108=0,100,Natura:Cloud-0

layer
0,0,0,0,0,0,0,0,0,0,0,0,0,0,0,0,0,0,0,0,0,0,0,0,0,0,0,1,0,0,0,0,0,0,0,0,0,0,0
0,0,0,0,0,0,0,0,0,0,0,0,0,0,0,0,0,0,0,0,0,0,0,0,0,0,0,0,0,0,0,0,0,0,0,0,0,0,0
0,0,0,0,0,0,0,0,0,0,0,0,0,0,0,0,0,0,0,0,0,0,0,0,0,0,0,0,0,2,0,0,0,0,0,0,0,0,0
0,0,0,0,0,0,0,0,0,0,0,0,0,0,0,0,0,0,0,0,0,0,0,0,0,0,0,0,0,0,0,0,0,0,0,0,0,0,0
0,0,0,0,0,0,0,0,0,0,0,0,0,0,0,0,0,0,0,0,0,0,0,0,0,0,0,0,0,0,0,0,3,0,0,0,0,0,0
0,0,0,0,0,0,0,0,0,0,0,0,0,0,0,0,0,4,0,0,0,0,0,0,0,0,1,0,0,0,0,0,3,0,0,0,0,0,0
0,0,0,0,0,0,5,4,5,0,0,0,0,0,0,0,4,4,4,0,0,0,0,3,0,0,0,0,0,0,0,0,0,0,0,0,0,0,0
0,0,0,0,0,5,5,4,5,5,5,5,5,4,4,4,5,4,4,4,4,0,0,4,4,4,4,4,4,0,0,0,0,0,0,0,0,0,0
0,0,0,0,0,4,4,4,4,4,5,5,4,4,4,4,5,5,4,4,4,4,4,4,4,4,4,4,4,4,0,0,0,0,0,0,0,0,0
0,0,0,0,4,4,4,4,4,4,4,4,4,4,4,3,4,4,4,4,4,4,4,4,4,4,4,4,4,4,4,4,0,0,0,0,0,0,0
0,0,0,9,4,4,6,8,8,8,6,8,8,7,7,6,5,5,5,4,4,4,4,4,4,4,4,4,4,4,4,4,4,0,0,0,0,0,0
0,0,0,9,4,4,10,13,12,12,13,12,12,12,11,10,6,5,5,5,5,5,5,5,5,4,5,5,4,4,4,4,5,4,0,0,0,0,0
0,0,0,16,0,4,10,11,0,0,0,0,0,0,11,10,14,6,15,6,14,5,5,5,5,4,3,5,5,5,5,4,5,5,0,0,0,0,0
0,0,9,17,21,15,10,11,0,0,3,0,0,0,11,10,6,20,20,18,19,18,17,17,17,17,5,5,5,5,5,4,4,4,0,0,0,0,0
0,17,17,17,14,24,10,11,0,0,0,0,0,0,11,7,22,23,23,22,18,22,18,17,13,17,0,5,5,5,5,5,4,4,0,0,0,0,0
17,17,17,17,17,17,17,13,0,0,13,0,0,0,13,25,6,6,20,20,22,23,22,17,13,17,6,5,5,5,5,5,4,4,0,0,0,0,0
17,17,17,17,0,0,0,12,0,0,0,0,0,0,12,13,12,12,12,20,6,20,20,17,13,17,5,5,5,0,3,5,4,4,0,0,0,0,0
17,17,17,28,0,0,0,0,0,0,3,0,0,0,27,0,0,0,0,26,17,17,17,17,13,17,5,5,5,5,5,5,4,4,0,0,0,0,0
17,17,17,17,0,0,0,12,0,0,0,0,0,0,12,13,12,12,12,12,24,24,24,17,13,17,6,5,5,5,5,4,4,0,0,0,0,0,0
17,17,17,17,17,17,17,13,0,0,13,0,0,0,13,13,24,24,24,20,20,20,24,17,13,17,5,5,5,5,4,4,4,0,0,0,0,0,0
29,17,17,17,17,24,12,11,0,0,0,0,0,0,11,7,24,24,24,24,24,24,0,17,17,17,5,5,4,4,4,4,0,0,0,0,0,0,0
29,17,17,17,17,15,12,11,0,0,0,0,0,0,11,7,24,15,15,24,24,0,4,4,17,5,5,5,4,4,4,0,0,0,0,0,0,0,0
4,4,4,4,17,0,0,0,3,0,0,0,0,0,11,12,15,15,15,15,0,0,4,4,4,5,5,5,4,4,0,0,0,0,0,0,0,0,0
4,4,4,4,4,0,4,4,12,12,13,12,12,12,13,7,15,15,15,15,0,4,4,4,4,5,5,5,5,0,0,0,0,0,0,0,0,0,0
30,4,4,4,4,4,4,4,0,11,6,11,11,11,7,24,24,15,6,15,0,4,4,4,4,5,5,5,0,3,0,0,0,3,0,0,0,0,0
0,0,30,4,4,4,4,5,4,4,0,0,15,15,15,24,24,20,6,6,15,14,4,4,4,4,4,0,0,0,0,0,0,0,0,0,0,0,0
0,0,0,30,4,4,4,4,4,4,4,4,15,15,0,0,4,0,6,15,20,4,4,4,4,4,0,0,0,0,0,0,0,0,0,0,0,0,0
0,0,0,0,30,4,4,4,4,4,4,4,15,0,4,4,4,4,4,6,4,4,4,4,4,0,0,0,0,0,0,0,0,0,0,3,0,0,0
0,0,0,0,0,30,30,4,4,4,4,4,4,4,0,0,4,4,14,4,4,4,0,0,0,0,0,0,0,0,0,0,0,0,0,0,0,0,0
0,0,0,0,0,0,0,30,4,4,4,4,4,0,0,0,0,4,4,4,0,0,0,0,0,0,0,0,0,0,0,0,0,0,0,0,0,0,0
0,0,0,0,0,0,0,0,0,0,0,0,0,0,0,0,0,0,0,0,0,0,0,0,0,0,0,0,0,0,0,0,0,0,0,0,0,0,0
endlayer

layer
0,0,0,0,0,0,0,0,0,0,0,0,0,0,0,0,0,0,0,0,0,0,0,0,0,0,0,0,0,0,0,0,0,0,0,0,0,0,0
0,0,0,0,0,0,0,0,0,0,0,0,0,0,0,0,0,0,0,0,0,0,0,0,0,0,0,0,0,0,2,0,0,0,0,0,0,0,0
0,0,0,0,0,0,0,0,0,0,0,0,0,0,0,0,0,0,0,0,0,0,0,0,0,0,0,0,0,0,0,0,0,0,0,0,0,0,0
0,0,0,0,0,0,0,0,0,0,0,0,0,0,0,0,0,0,0,0,0,0,0,0,0,0,0,0,0,0,0,0,0,0,0,0,0,0,0
0,0,0,0,0,0,0,0,0,0,0,0,0,0,0,0,0,0,0,0,0,0,0,0,0,0,0,0,0,0,0,0,0,0,0,0,0,0,0
0,0,0,0,0,0,0,0,0,0,0,0,0,0,0,0,0,0,0,0,0,0,0,0,0,0,0,0,0,0,0,0,0,0,0,0,0,0,0
0,0,0,0,0,0,21,21,21,0,0,0,0,0,0,0,31,4,31,0,0,0,0,0,0,0,0,0,0,0,0,0,0,0,0,0,0,0,0
0,0,0,0,0,0,5,21,0,0,0,0,0,0,0,0,4,4,5,32,0,0,0,0,0,0,0,0,0,0,0,0,0,0,0,0,0,0,0
0,0,0,0,0,4,4,21,21,0,5,5,5,4,0,0,4,4,5,0,0,3,0,0,5,5,5,4,4,0,0,0,0,0,0,0,0,0,0
0,0,0,0,0,4,4,21,21,4,4,11,11,11,4,4,4,4,5,5,5,5,5,5,5,5,5,4,4,4,0,0,0,0,0,0,0,0,0
0,0,0,9,0,4,6,8,11,11,6,11,11,11,7,6,5,5,5,5,5,5,5,5,5,5,5,4,4,4,4,0,0,0,0,0,0,32,0
0,0,0,9,4,14,7,13,0,0,13,0,0,0,13,10,15,6,5,5,5,5,5,5,5,5,5,5,4,4,4,4,0,0,0,0,0,0,0
0,0,0,9,21,12,12,0,0,0,0,0,0,0,0,12,12,14,33,33,33,5,5,12,12,12,5,5,4,4,4,4,4,0,0,0,0,0,0
0,0,9,35,21,21,12,0,0,0,0,0,0,0,0,12,6,6,34,0,6,0,11,0,0,0,11,5,4,5,5,4,4,0,0,0,0,0,0
0,35,35,35,21,11,12,0,0,0,0,0,0,0,0,12,12,37,36,0,0,0,11,0,0,0,11,5,4,5,5,4,4,0,0,0,0,0,0
35,35,33,21,17,17,17,13,0,0,13,0,0,0,13,25,6,20,20,0,0,0,11,0,0,0,11,5,5,5,5,5,0,0,0,0,0,0,0
35,33,33,17,0,0,0,12,0,0,0,0,0,0,12,13,12,12,12,12,12,12,13,0,0,0,13,5,5,5,5,5,0,0,0,0,0,0,0
35,33,33,0,0,0,0,0,0,0,0,0,0,0,39,0,0,0,0,0,0,0,38,0,0,0,11,5,5,5,5,5,0,0,0,0,0,0,0
35,33,21,17,0,0,0,12,0,0,0,0,0,0,12,13,12,12,12,12,12,12,13,0,0,0,13,5,5,5,5,4,0,0,32,0,0,0,0
35,33,33,21,17,17,17,13,0,0,13,0,0,0,13,13,24,24,6,0,0,0,11,0,0,0,11,14,5,5,5,4,32,0,0,0,0,0,0
35,33,33,33,9,17,12,0,0,0,0,0,0,0,0,12,24,24,20,20,20,20,11,0,0,0,11,21,4,4,4,40,0,0,0,0,0,0,0
35,33,33,9,17,21,12,0,0,0,0,0,0,0,0,12,15,40,40,15,20,6,13,13,41,13,13,4,4,4,0,0,0,0,0,0,0,0,0
35,35,35,17,17,21,12,0,0,0,0,0,0,0,0,12,0,43,21,42,20,14,4,21,0,21,21,4,4,0,0,0,0,0,0,0,0,0,0
0,0,5,5,4,4,8,13,0,0,13,0,0,0,13,7,44,43,3,0,21,14,21,0,32,5,0,0,0,0,0,0,0,0,0,0,0,0,0
0,0,0,5,4,4,6,10,11,11,6,11,11,11,7,6,15,21,21,21,21,14,21,4,32,5,0,0,0,0,0,0,0,0,0,0,0,0,0
0,0,0,42,4,4,4,0,21,21,21,21,21,21,21,15,15,21,6,21,21,21,21,4,32,0,0,0,0,0,0,0,0,0,0,0,0,0,0
0,0,0,0,0,42,4,4,0,21,21,21,21,21,21,21,21,21,21,21,21,21,45,4,32,0,0,0,0,0,0,0,0,0,0,0,0,0,0
0,0,0,0,0,30,30,4,4,4,21,21,21,21,21,21,4,4,21,21,21,4,4,4,0,0,0,0,0,0,0,0,0,0,0,0,0,0,0
0,0,0,0,0,0,0,30,4,4,21,21,21,21,0,0,0,4,21,4,0,0,0,0,0,0,0,0,0,0,0,0,0,0,0,0,0,0,0
0,0,0,0,0,0,0,0,0,0,0,0,0,0,0,0,0,0,0,0,0,0,0,0,0,0,0,0,0,0,0,0,0,0,0,0,0,0,0
0,0,0,0,0,0,0,0,0,0,0,0,0,0,0,0,0,0,0,0,0,0,0,0,0,0,0,0,0,0,0,0,0,0,0,0,0,0,2
endlayer

layer
2,2,0,0,0,0,0,0,0,0,0,0,0,0,0,0,0,0,0,0,0,0,0,0,0,0,0,0,0,0,0,0,0,0,0,0,0,0,0
0,0,0,0,0,0,0,0,0,0,0,0,0,0,0,0,0,0,0,0,0,0,0,0,0,0,0,0,0,0,0,0,0,0,0,0,0,0,0
0,0,0,0,0,0,0,0,0,0,0,0,0,0,0,0,0,0,0,0,0,0,0,0,0,0,0,0,0,0,0,0,0,0,0,0,0,0,0
0,0,0,0,0,0,0,0,0,0,0,0,0,0,0,0,0,0,0,0,0,0,0,0,0,0,0,0,0,0,0,0,0,0,0,0,0,0,0
0,0,0,0,0,0,0,0,0,0,0,0,0,0,0,0,0,0,0,0,0,0,0,0,0,0,0,0,0,0,0,0,0,0,0,0,0,0,0
0,0,0,0,0,0,0,0,0,0,0,0,0,0,0,0,0,0,0,0,0,0,0,0,0,0,0,0,0,0,0,0,0,0,0,0,0,0,0
0,0,0,0,0,0,0,21,21,21,0,0,0,0,0,0,31,0,31,0,0,0,0,0,0,0,0,0,0,0,0,0,0,0,0,0,0,0,0
0,0,0,0,0,0,21,21,21,21,0,0,0,4,0,0,0,4,0,0,0,0,0,0,0,0,0,0,0,0,0,0,0,0,0,0,0,0,0
0,0,0,0,0,0,21,21,21,21,5,5,5,0,0,0,4,4,5,0,0,0,0,0,0,0,0,0,0,0,0,0,0,0,0,0,0,0,0
0,0,0,0,0,4,21,21,21,21,4,21,4,21,6,4,4,5,5,5,5,5,5,5,5,5,5,4,4,4,0,0,0,0,0,0,0,0,0
0,0,0,9,0,4,6,7,11,11,6,11,11,11,7,6,4,6,46,5,5,5,5,5,5,5,5,4,4,4,4,0,0,0,0,0,0,32,0
0,0,0,9,4,6,7,13,0,0,13,0,0,0,13,10,4,4,1,5,5,5,5,5,5,17,5,5,5,5,4,4,0,0,0,0,0,0,0
0,0,0,0,0,12,12,0,0,0,0,0,0,0,0,12,12,50,49,48,48,0,48,13,47,13,13,5,5,5,4,4,4,0,0,0,0,0,0
0,0,9,9,21,12,12,0,0,0,0,0,0,0,0,12,6,4,49,49,6,49,13,0,0,0,13,24,4,0,5,5,4,0,0,0,0,0,0
0,0,0,9,21,21,12,0,0,0,0,0,0,0,0,12,12,14,48,48,49,42,47,0,0,0,47,24,0,5,0,5,4,0,0,0,0,0,0
0,0,0,0,17,17,17,13,0,0,13,0,0,0,13,25,6,6,20,48,48,48,47,0,0,0,47,51,6,5,5,5,5,0,0,0,0,0,0
0,0,9,17,0,0,0,12,0,0,0,0,0,0,12,8,20,12,12,12,12,12,13,0,0,0,13,20,20,6,5,5,5,5,0,0,0,0,0
0,0,9,0,0,0,0,12,52,0,0,0,0,51,12,11,20,52,0,0,0,0,39,0,0,0,47,0,0,0,14,5,5,5,0,0,0,0,0
0,0,9,17,0,0,0,12,0,0,0,0,0,0,12,7,20,12,12,12,12,12,13,0,0,0,13,21,24,5,5,5,0,0,32,0,0,0,0
0,0,0,21,17,17,17,13,0,0,13,0,0,0,13,13,14,20,20,0,21,0,47,0,0,0,47,21,5,5,5,0,0,0,0,0,0,0,0
0,0,0,0,9,17,12,0,0,0,42,0,0,0,0,12,14,14,6,0,0,6,47,0,0,0,47,21,6,4,0,40,0,0,0,0,0,0,0
0,0,0,53,17,17,12,0,0,0,0,0,0,0,0,12,21,42,21,21,6,24,13,13,39,13,13,21,21,0,0,0,0,0,0,0,0,0,0
0,0,9,17,17,21,12,0,0,0,0,0,0,0,0,12,12,21,21,21,21,6,4,21,0,21,21,21,42,0,0,0,0,0,0,0,0,0,0
0,0,9,5,4,4,8,13,0,0,13,0,0,0,13,7,21,21,0,21,21,21,4,0,43,5,0,0,0,0,0,0,0,0,0,0,0,0,0
0,0,0,4,4,4,6,10,11,11,6,11,11,11,7,25,21,3,21,21,21,21,4,4,0,3,0,0,0,0,0,0,0,0,0,0,0,0,0
0,0,0,0,0,4,4,4,21,21,21,21,21,21,21,54,21,21,21,21,21,4,4,0,0,0,0,0,0,0,0,0,0,0,0,0,0,0,0
0,0,0,0,0,0,4,4,21,21,21,21,21,21,21,21,21,0,21,21,21,52,0,0,0,0,0,0,0,0,0,0,0,0,0,0,0,0,0
0,0,0,0,0,0,0,0,55,4,21,21,21,21,0,0,0,5,4,4,0,3,0,0,0,0,0,0,0,0,0,0,0,0,0,0,0,0,0
0,0,0,0,0,0,0,0,0,0,4,4,4,0,0,56,0,0,5,0,0,0,0,0,0,0,0,0,0,0,0,0,0,0,0,0,0,0,0
0,0,0,0,0,0,0,0,0,0,0,0,0,0,0,0,0,0,0,0,0,0,0,0,0,0,0,0,0,0,0,0,0,0,0,0,0,0,0
0,0,0,0,0,0,0,0,0,0,0,0,0,0,0,0,0,0,0,0,0,0,0,0,0,0,0,0,0,0,0,0,0,0,0,0,0,0,0
endlayer

layer
2,0,0,0,0,0,0,0,0,0,0,0,0,0,0,0,0,0,0,0,0,0,0,0,0,0,0,0,0,0,0,0,0,0,0,0,0,0,0
0,0,0,0,0,0,0,0,0,0,0,0,0,0,0,0,0,0,0,0,0,0,0,0,0,0,0,0,0,0,0,0,0,0,0,0,0,0,0
0,0,0,0,0,0,0,0,0,0,0,0,0,0,0,0,0,0,0,0,0,0,0,0,0,0,0,0,0,0,0,0,0,0,0,0,0,0,0
0,0,0,0,0,0,0,0,0,0,0,0,0,0,0,0,0,0,0,0,0,0,0,0,0,0,0,0,0,0,0,0,0,0,0,0,0,0,0
0,0,0,0,0,0,0,0,0,0,0,0,0,0,0,0,0,0,0,0,0,0,0,0,0,0,0,0,0,0,0,0,0,0,0,0,0,0,0
0,0,0,0,0,0,0,0,0,0,0,0,0,0,0,0,0,0,0,0,0,0,0,0,0,0,0,0,0,0,0,0,0,0,0,0,0,0,0
0,0,0,0,0,0,0,0,0,0,0,0,0,0,31,31,31,0,31,31,0,0,0,0,0,0,0,0,0,0,0,0,0,0,0,0,0,0,0
0,0,0,0,0,0,0,0,0,3,57,0,53,16,0,0,0,4,0,0,0,0,0,0,0,0,0,0,0,0,0,0,0,0,0,0,0,0,0
0,0,0,0,0,51,21,31,31,21,0,21,21,45,15,4,4,4,5,0,5,0,0,0,0,0,0,0,0,0,0,0,0,0,0,0,0,0,0
0,0,0,0,0,0,21,21,21,15,15,21,21,21,6,4,4,5,5,5,5,5,5,5,5,5,5,5,4,4,0,0,0,0,0,0,0,0,0
0,0,0,43,0,4,6,20,20,20,6,58,58,58,58,6,20,20,46,5,6,5,5,5,5,5,5,5,4,4,4,53,0,0,0,0,0,32,0
0,0,0,9,21,6,14,13,12,12,60,12,12,12,13,60,59,59,1,48,48,48,48,5,5,5,5,5,4,5,4,5,4,0,0,0,0,0,0
0,0,0,0,0,9,60,11,0,0,11,0,0,0,11,60,50,0,48,49,48,48,48,13,12,13,5,24,5,0,5,5,5,53,0,0,0,0,0
0,0,9,9,21,9,60,11,0,0,11,0,0,0,11,60,6,4,48,48,6,48,13,0,0,0,11,24,24,5,5,0,5,5,0,0,0,0,0
0,0,0,9,43,9,60,11,0,0,11,0,0,0,11,60,4,4,48,49,48,48,11,0,0,0,11,24,20,5,5,20,5,5,0,0,0,0,0
0,0,61,0,17,24,25,58,58,58,6,12,12,12,58,6,6,6,48,49,48,49,11,0,0,0,11,6,6,6,6,14,20,5,0,0,0,0,0
0,0,9,17,17,17,17,11,0,0,60,0,0,0,11,60,6,20,6,21,5,4,13,0,0,0,13,6,6,6,6,14,20,6,5,0,0,0,0
0,0,9,17,17,17,17,11,0,0,60,0,0,0,11,60,6,20,12,12,12,12,11,52,0,51,11,6,14,14,14,14,6,5,0,32,0,0,0
0,0,9,17,17,17,17,11,0,0,60,0,0,0,11,14,6,20,6,21,21,21,13,0,0,0,13,62,14,14,6,6,5,0,43,0,0,0,0
0,0,0,9,17,21,14,58,12,12,6,12,12,12,12,6,6,6,0,0,0,0,11,0,0,0,11,21,4,4,4,0,0,0,0,0,0,0,0
0,0,0,0,9,17,14,11,0,0,14,0,0,0,11,14,6,6,6,0,0,0,11,0,0,0,11,21,33,0,0,40,0,0,0,0,0,0,0
0,0,0,9,17,17,14,11,0,0,14,0,0,0,11,14,21,21,21,0,0,6,13,12,12,12,13,21,0,0,0,0,0,0,0,0,0,0,0
0,0,9,17,17,24,14,11,0,0,14,0,0,0,11,14,63,0,21,0,21,21,4,21,21,21,21,0,0,0,0,0,0,0,0,0,0,0,0
0,0,9,17,4,4,14,13,12,12,14,12,12,12,13,14,21,21,21,4,21,0,4,0,4,0,0,0,0,0,0,0,0,0,0,0,0,0,0
0,0,0,0,4,4,6,20,20,20,25,58,58,58,58,25,21,21,21,21,4,4,4,63,0,0,0,0,0,0,0,0,0,0,0,0,0,0,0
0,0,0,0,0,0,4,0,0,21,21,21,21,21,21,21,4,0,21,21,4,0,0,0,0,0,0,0,0,0,0,0,0,0,0,0,0,0,0
0,0,0,0,0,0,40,0,21,21,21,21,21,21,21,21,21,0,40,4,0,0,0,0,0,0,0,0,0,0,0,0,0,0,0,0,0,0,0
0,0,0,0,0,0,0,0,4,0,4,4,4,4,0,0,0,40,0,0,0,0,0,0,0,0,0,0,0,0,0,0,0,0,0,0,0,0,0
0,0,0,0,0,0,0,0,0,0,0,0,0,0,0,0,0,0,0,0,0,0,0,0,0,0,0,0,0,0,0,0,0,0,0,0,0,0,0
0,0,0,0,0,0,0,0,0,0,0,0,0,0,0,0,0,0,0,0,0,0,0,0,0,0,0,0,0,0,0,0,0,0,0,0,0,0,0
0,0,0,0,0,0,0,0,0,0,0,0,0,0,0,0,0,0,0,0,0,0,0,0,0,0,0,0,0,0,0,0,0,0,0,0,0,0,0
endlayer

layer
0,0,0,0,0,0,0,0,0,0,0,0,0,0,0,0,0,0,0,0,2,2,0,0,0,0,0,0,0,0,0,0,0,0,0,0,0,0,0
0,0,0,0,0,0,0,0,0,0,0,0,0,0,0,0,0,0,0,0,0,0,0,0,0,0,0,0,0,0,0,0,0,0,0,0,0,0,0
0,0,0,0,0,0,0,0,0,0,0,0,0,0,0,0,0,0,0,0,0,0,0,0,0,0,0,0,0,0,0,0,0,0,0,0,0,0,0
0,0,0,0,0,0,0,0,0,0,0,0,0,0,0,0,0,0,0,0,0,0,0,0,0,0,0,0,0,0,0,0,0,0,0,0,0,0,0
0,0,0,0,0,0,0,0,0,0,0,0,0,0,0,0,0,0,0,0,0,0,0,0,0,0,0,0,0,0,0,0,0,0,0,0,0,0,0
0,0,0,0,0,0,0,0,0,0,0,0,0,0,0,0,0,0,0,0,0,0,0,0,0,0,0,0,0,0,0,0,0,0,0,0,0,0,0
0,0,0,0,0,0,0,0,0,0,0,0,0,0,31,31,31,0,31,31,0,0,0,0,0,0,0,0,0,0,0,0,0,0,0,0,0,0,0
0,0,0,0,0,0,0,0,0,0,0,0,0,16,0,0,0,5,0,0,0,0,0,0,0,0,0,0,0,0,0,0,0,0,0,0,0,0,0
0,0,0,0,0,0,0,0,0,0,57,0,9,0,0,4,4,4,5,5,0,5,5,0,0,1,0,0,0,0,0,0,0,0,0,0,0,0,0
0,0,0,0,0,0,4,4,4,4,31,21,21,21,6,4,6,5,6,6,20,5,5,5,5,0,0,5,5,5,5,5,0,0,0,0,0,0,0
0,0,0,21,14,4,6,64,64,64,6,64,64,64,64,14,6,6,0,6,6,0,5,5,0,1,5,5,5,5,4,4,4,0,0,0,0,32,0
0,0,0,9,14,24,64,8,8,8,64,7,7,7,8,14,14,0,0,0,0,0,20,0,4,5,5,0,24,5,5,0,5,4,0,0,0,0,0
0,0,51,21,6,24,64,8,17,17,64,17,17,17,8,6,0,0,0,49,49,48,1,21,24,24,24,24,24,24,5,20,20,5,0,0,0,0,0
0,0,9,21,14,24,64,8,17,17,64,17,17,17,8,64,6,50,0,48,6,48,65,17,17,17,24,24,24,24,24,20,20,5,0,0,40,0,0
0,43,0,9,14,15,64,8,17,17,17,17,17,17,21,21,67,0,1,48,48,66,66,17,42,17,6,6,20,6,6,14,20,21,0,0,0,0,0
0,0,21,21,20,20,25,64,64,17,17,17,17,17,64,25,6,4,1,0,66,66,68,17,0,17,6,6,6,6,6,33,33,21,4,0,0,0,0
0,61,21,20,21,21,64,7,17,17,17,17,17,17,10,64,6,6,3,50,68,1,68,17,0,17,6,6,6,6,33,33,33,21,21,0,0,0,0
0,0,21,33,17,17,17,17,17,17,17,17,17,17,10,64,6,6,6,21,21,68,68,17,0,17,6,21,21,21,33,33,33,4,4,32,0,0,0
0,0,0,33,17,17,17,17,17,17,17,17,17,17,10,64,6,6,21,21,21,21,21,17,0,17,0,21,21,21,33,33,13,21,4,0,0,0,0
0,0,0,9,17,17,6,17,17,17,17,64,64,64,64,6,24,0,0,0,0,48,48,17,53,17,0,0,0,0,0,0,21,21,0,0,0,0,0
0,0,0,0,9,17,17,17,17,17,17,17,17,17,7,64,69,6,0,48,48,48,48,17,17,17,21,40,0,0,32,40,0,0,0,0,0,0,0
0,0,0,9,17,17,17,17,17,17,17,17,17,17,8,64,32,21,21,48,48,6,48,48,21,21,21,0,0,0,0,0,0,0,0,0,0,0,0
0,0,0,33,17,24,17,17,17,17,17,17,17,17,8,64,21,0,0,0,48,48,48,32,32,0,0,0,0,0,0,0,0,0,0,0,0,0,0
0,0,0,33,17,4,64,8,8,10,64,7,7,7,8,64,21,21,21,4,4,48,0,0,32,0,0,0,0,0,0,0,0,0,0,0,0,0,0
0,0,0,0,0,4,6,64,64,64,25,64,64,64,64,25,21,21,21,4,0,40,0,63,0,0,0,0,0,0,0,0,0,0,0,0,0,0,0
0,0,0,0,0,0,4,4,15,21,21,21,21,21,21,21,70,0,4,4,0,0,0,0,0,0,0,0,0,0,0,0,0,0,0,0,0,0,0
0,0,0,0,0,0,40,0,40,40,4,4,72,72,72,9,3,0,71,32,0,0,0,0,0,0,0,0,0,0,0,0,0,0,0,0,0,0,0
0,0,0,0,0,0,0,0,0,0,0,0,0,0,0,0,0,40,72,0,0,0,0,0,0,0,0,0,0,0,0,0,0,0,0,0,0,0,0
0,0,0,0,0,0,0,0,0,0,0,0,0,0,0,0,0,0,0,0,0,0,0,0,0,0,0,0,0,0,0,0,0,0,0,0,0,0,0
0,0,0,0,0,0,0,0,0,0,0,0,0,0,0,0,0,0,0,0,0,0,0,0,0,0,0,0,0,0,0,0,0,0,0,0,0,0,0
0,0,0,0,0,0,0,0,0,0,0,0,0,0,0,0,0,0,0,0,0,0,0,0,0,0,0,0,0,0,0,0,0,0,0,0,0,0,0
endlayer

layer
0,0,0,0,24,0,24,0,0,0,0,0,0,0,0,0,0,0,0,0,2,2,0,0,0,0,0,0,0,0,0,0,0,0,0,0,0,0,0
0,0,0,0,0,0,0,0,0,0,0,0,0,0,0,0,0,0,0,0,0,0,0,0,0,0,0,0,0,0,0,0,0,0,0,0,0,0,0
0,0,0,0,0,0,0,0,0,0,0,0,0,0,0,0,0,0,0,0,0,0,0,0,0,0,0,0,0,0,0,0,0,0,0,0,0,0,0
0,0,0,0,0,0,0,0,0,0,0,0,0,0,0,0,0,0,0,0,0,0,0,0,0,0,0,0,0,0,0,0,0,0,0,0,0,0,0
0,0,0,0,0,0,0,0,0,0,0,0,0,0,0,0,0,0,0,0,0,0,0,0,0,0,0,0,0,0,0,0,0,0,0,0,0,0,0
0,0,0,0,0,0,0,0,0,0,0,0,0,0,0,0,0,0,0,0,0,0,0,0,0,0,0,0,0,0,0,0,0,0,0,0,0,0,0
0,0,0,0,0,0,0,0,0,0,0,0,0,0,31,31,31,0,31,31,0,0,0,0,0,0,0,0,0,0,0,0,0,0,0,0,0,0,0
0,0,0,0,0,0,0,0,0,0,0,0,0,16,0,0,6,6,6,5,5,0,0,0,0,0,0,0,0,0,31,31,0,0,0,0,0,0,0
0,0,0,0,0,0,0,0,0,0,0,0,9,0,21,6,6,6,6,6,5,5,5,5,0,0,61,0,0,5,5,4,0,0,0,0,0,31,0
0,0,0,0,0,0,0,0,0,0,31,9,0,21,6,6,25,6,6,6,6,6,5,5,0,0,5,5,4,5,5,5,5,0,0,0,0,0,0
0,0,0,0,21,15,4,4,4,4,15,3,21,6,6,6,6,6,20,20,20,20,20,20,5,5,5,5,5,5,5,14,20,4,0,0,0,32,0
0,0,0,0,21,15,24,4,4,5,15,17,17,17,6,6,6,20,20,20,20,20,0,20,24,24,5,24,5,5,5,14,20,21,0,0,0,0,0
0,0,0,21,6,24,24,4,4,5,24,17,17,17,17,6,20,0,0,0,48,50,0,21,20,24,24,24,24,24,6,20,21,21,0,0,0,0,0
0,0,0,21,21,15,15,4,0,5,17,73,73,17,6,20,6,0,0,48,48,49,65,21,42,21,24,24,6,6,20,6,21,21,21,0,40,0,0
0,21,21,21,21,0,15,24,15,17,42,33,33,17,21,21,0,0,0,0,49,50,1,5,47,6,14,6,6,6,21,6,0,21,21,0,0,0,0
21,21,21,20,6,21,6,24,17,33,33,33,33,17,6,6,6,50,0,0,74,68,68,5,47,0,6,6,6,6,46,42,0,0,4,0,0,0,0
0,21,21,21,21,77,17,17,33,33,33,33,33,17,6,0,6,6,21,50,1,76,68,75,47,6,6,6,6,21,46,0,0,0,4,0,0,0,0
0,0,21,21,33,17,17,78,33,33,33,33,33,17,6,6,6,6,6,21,50,0,21,0,47,6,6,21,21,59,0,0,0,0,4,32,0,0,0
0,0,0,0,33,17,33,33,33,33,33,33,33,17,17,24,6,6,21,21,21,21,21,21,47,14,21,21,0,0,0,0,13,21,32,32,0,0,0
0,0,0,0,33,17,33,33,33,33,51,17,17,17,24,24,6,0,0,21,48,48,48,48,47,21,21,0,0,0,0,0,21,21,0,0,0,0,0
0,0,0,0,9,33,33,33,33,33,33,17,0,21,15,24,14,6,21,48,48,48,48,48,21,21,0,40,0,0,32,40,0,0,0,0,0,0,0
0,0,0,0,33,17,33,33,33,33,33,17,21,21,21,15,14,21,21,48,48,6,48,48,69,0,40,0,0,0,0,40,0,0,0,0,0,0,0
0,0,0,0,33,17,33,33,33,33,33,17,21,21,3,21,21,21,21,48,48,48,48,48,32,40,0,40,40,0,0,40,0,0,0,0,0,0,0
0,0,0,0,33,77,17,17,17,17,17,21,79,21,21,3,21,21,4,4,48,48,48,48,63,0,0,0,0,0,0,0,0,0,0,0,0,0,0
0,0,0,0,0,0,4,15,21,21,21,21,21,21,21,21,4,21,4,4,0,40,0,63,0,0,0,0,0,0,0,0,0,0,0,0,0,0,0
0,0,0,0,0,0,21,21,21,21,21,21,70,21,21,21,70,0,0,40,0,0,0,0,0,0,0,0,0,0,0,0,0,0,0,0,0,0,0
0,0,0,0,0,0,40,0,42,0,0,0,0,72,0,9,0,0,71,32,0,0,0,0,0,0,0,0,0,0,0,0,0,0,0,0,0,0,0
0,0,0,0,0,0,0,0,0,0,0,0,0,0,0,0,0,40,72,0,0,0,0,0,0,0,0,0,0,0,0,0,0,0,0,0,0,0,0
0,0,0,0,0,0,0,0,0,0,0,0,0,0,0,0,0,0,0,0,0,0,0,0,0,0,0,0,0,0,0,0,0,0,0,0,0,0,0
0,0,0,0,0,0,0,0,0,0,0,0,0,0,0,0,0,0,0,0,0,0,0,0,0,0,0,0,0,0,0,0,0,0,0,0,0,0,0
0,0,0,0,0,0,0,0,0,0,0,0,0,0,0,0,0,0,0,0,0,0,0,0,0,0,0,0,0,0,0,0,0,0,0,0,0,0,0
endlayer

layer
0,0,0,0,0,24,0,0,0,0,0,0,0,0,0,0,0,0,0,0,0,0,0,0,2,2,0,0,0,0,0,0,0,0,0,0,0,0,0
0,0,0,0,0,0,0,0,0,0,0,0,0,0,0,0,0,0,0,0,0,0,0,0,0,0,0,0,0,0,0,0,0,0,0,0,0,0,0
0,0,0,0,0,0,0,0,0,0,0,0,0,0,0,0,0,0,0,0,0,0,0,0,0,0,0,0,0,0,0,0,0,0,0,0,0,0,0
0,0,0,0,0,0,0,0,0,0,0,0,0,0,0,0,0,0,0,0,0,0,0,0,0,0,0,0,0,0,0,0,0,0,0,0,0,0,0
0,0,0,0,0,0,0,0,0,0,0,0,0,0,0,0,0,0,0,0,0,0,0,0,0,0,0,0,0,0,0,0,0,0,0,0,0,0,0
0,0,0,0,0,0,0,0,0,0,0,0,0,0,0,0,0,0,0,0,0,0,0,0,0,0,0,0,0,0,0,0,0,0,0,0,0,0,0
0,0,0,0,0,0,0,0,0,0,0,0,0,0,31,31,31,31,31,31,0,0,0,0,0,0,0,0,0,0,0,31,0,0,0,0,0,0,0
0,0,0,0,0,0,0,0,0,0,0,0,0,16,0,21,21,14,21,5,5,5,0,0,0,0,0,0,0,0,31,0,0,0,0,0,0,0,0
0,0,0,0,0,0,0,0,0,0,0,0,9,0,21,21,20,6,20,5,21,15,5,5,5,0,5,0,0,4,4,4,5,0,0,0,0,31,0
0,0,0,0,0,0,0,0,0,21,0,9,21,21,51,20,6,6,6,20,21,21,21,15,15,5,5,4,4,4,24,17,5,21,53,0,0,0,0
0,0,0,0,0,54,0,0,0,0,9,21,21,33,33,33,80,0,67,67,67,81,80,67,20,6,6,6,6,6,6,17,21,21,21,0,32,32,0
0,0,0,0,0,54,15,0,0,0,21,33,33,33,33,33,33,0,0,80,0,3,50,70,20,6,6,6,6,6,4,17,21,21,21,0,0,0,0
0,0,0,0,21,6,15,0,0,0,15,33,33,33,33,33,35,35,35,35,35,35,35,35,35,6,6,6,6,14,6,21,0,21,21,0,0,0,0
0,0,0,0,9,21,21,0,0,0,21,0,0,33,6,6,21,0,0,68,50,32,50,75,21,9,6,6,6,6,63,6,0,21,21,0,40,0,0
0,0,0,0,21,21,83,24,82,21,0,0,0,33,21,14,21,21,0,0,50,50,0,75,21,21,6,6,6,6,0,59,0,0,32,0,0,0,0
21,21,21,21,21,21,6,6,46,46,0,0,0,33,6,6,6,21,0,21,76,68,68,0,21,21,6,6,6,6,32,0,0,0,0,0,0,0,0
21,21,21,0,0,0,9,6,46,0,0,0,0,51,6,0,6,6,21,21,21,76,1,75,21,6,6,6,21,59,0,0,0,0,0,0,0,0,0
0,21,21,0,0,33,3,78,0,0,1,0,0,33,6,6,6,23,20,6,21,21,50,0,21,6,21,40,0,0,0,0,0,0,0,32,0,0,0
0,0,42,0,0,33,0,9,40,0,0,0,0,33,84,6,6,14,20,21,21,21,0,21,0,21,21,0,0,0,0,21,13,21,32,32,0,0,0
0,0,0,0,0,33,0,9,40,0,0,21,21,21,15,15,14,0,0,0,21,85,0,0,40,21,0,0,0,0,0,0,21,21,0,0,0,0,0
0,0,0,0,9,1,40,0,0,0,0,21,21,21,21,6,6,6,0,0,0,48,32,40,0,42,0,40,0,0,32,40,0,0,0,0,0,0,0
0,0,0,0,0,33,40,0,0,40,0,21,21,21,21,21,6,14,0,0,48,6,48,52,62,0,40,0,40,0,0,40,32,0,0,0,0,0,0
0,0,0,0,0,3,40,40,72,0,0,21,21,0,9,0,21,21,0,0,48,48,40,3,0,40,0,40,40,0,0,40,0,0,0,0,0,0,0
0,0,0,0,0,0,79,21,79,79,21,79,79,21,86,21,4,4,4,0,0,0,40,32,40,0,0,0,0,0,0,0,0,0,0,0,0,0,0
0,0,0,0,0,0,21,21,21,30,30,30,0,72,0,21,4,0,0,0,0,0,0,32,0,0,0,0,0,0,0,0,0,0,0,0,0,0,0
0,0,0,0,0,0,42,21,42,0,3,0,0,0,0,9,70,0,0,40,0,0,0,0,0,0,0,0,0,0,0,0,0,0,0,0,0,0,0
0,0,0,0,0,0,0,0,0,0,0,0,0,0,0,9,0,0,71,32,0,0,0,0,0,0,0,0,0,0,0,0,0,0,0,0,0,0,0
0,0,0,0,0,0,0,0,0,0,0,0,0,0,0,0,0,40,72,0,0,0,0,0,0,0,0,0,0,0,0,0,0,0,0,0,0,0,0
0,0,0,0,0,0,0,0,0,0,0,0,0,0,0,0,0,0,0,0,0,0,0,0,0,0,0,0,0,0,0,0,0,0,0,0,0,0,0
0,0,0,0,0,0,0,0,0,0,0,0,0,0,0,0,0,0,0,0,0,0,0,0,0,0,0,0,0,0,0,0,0,0,0,0,0,0,0
0,0,0,0,0,0,0,0,0,0,0,0,0,0,0,0,0,0,0,0,0,0,0,0,0,0,0,0,0,0,0,0,0,0,0,0,0,0,0
endlayer

layer
0,0,0,0,0,0,0,0,0,0,0,0,0,0,0,0,0,0,0,0,0,0,0,0,0,0,0,0,0,0,0,0,0,0,0,0,0,0,0
0,0,0,0,0,0,0,0,0,0,0,0,0,0,0,0,0,0,0,0,0,0,0,0,0,0,0,0,0,0,0,0,0,0,0,0,0,0,0
0,0,0,0,0,0,0,0,0,0,0,0,0,0,0,0,0,0,0,0,0,0,0,0,0,0,0,0,0,0,0,0,0,0,0,0,0,0,0
0,0,0,0,0,0,0,0,0,0,0,0,0,0,0,0,0,0,0,0,0,0,0,0,0,0,0,0,0,0,0,0,0,0,0,0,0,0,0
1,0,0,0,0,0,0,0,0,0,0,0,0,0,0,0,0,0,0,0,0,0,0,0,0,0,0,0,0,0,0,0,0,0,0,0,0,0,0
0,0,0,0,0,0,0,0,0,0,0,0,0,0,0,0,0,0,0,0,0,0,0,0,0,0,0,0,0,0,0,0,0,0,0,0,0,0,0
0,0,0,0,0,0,0,0,0,0,0,0,0,0,31,31,31,31,31,31,0,31,0,0,0,0,0,0,0,0,0,31,0,0,0,0,0,0,0
0,0,0,0,0,0,0,0,0,0,0,0,0,16,0,31,0,21,21,21,0,0,0,0,0,0,0,0,0,53,4,43,53,0,31,0,0,0,0
0,0,0,0,0,0,0,0,0,0,0,0,9,0,79,21,6,6,6,21,21,21,0,0,5,5,5,4,4,4,17,0,21,0,0,0,0,31,0
0,0,0,0,0,0,0,0,0,0,0,9,0,21,0,21,6,6,6,21,21,21,21,21,0,6,6,6,6,17,17,17,21,21,0,0,0,32,0
0,0,0,0,0,0,0,0,0,0,9,21,0,0,0,0,42,0,67,67,67,81,87,67,1,40,40,33,33,1,1,1,17,21,21,0,32,32,0
0,0,0,0,0,0,88,0,0,21,21,21,0,0,0,0,0,0,0,50,0,50,50,67,67,67,0,0,32,0,0,1,17,21,21,32,0,0,0
0,0,0,0,0,0,54,0,9,15,21,0,0,0,0,21,21,21,21,50,50,50,16,0,75,21,21,21,21,6,89,89,21,21,21,0,32,32,0
0,0,0,0,0,31,21,0,0,0,0,0,0,0,21,6,21,21,0,68,50,32,50,0,9,0,6,6,6,6,21,6,21,0,32,0,40,0,0
0,0,0,0,9,21,21,6,46,0,0,0,0,20,20,6,6,21,21,21,50,50,0,9,0,68,21,20,20,6,21,21,21,0,32,0,0,0,0
0,21,0,0,0,21,6,6,20,46,0,0,0,21,6,6,6,21,21,21,50,68,68,68,75,75,6,6,6,6,32,0,0,0,0,0,0,0,0
0,21,0,0,0,0,9,6,46,0,0,0,0,90,6,0,6,6,21,21,21,68,0,0,75,6,6,21,59,59,0,0,0,0,0,0,0,0,0
0,0,0,0,0,0,0,16,0,0,0,0,0,0,21,6,6,0,6,6,21,21,50,0,0,21,40,0,0,0,0,0,21,0,0,32,0,0,0
0,0,0,0,0,9,0,9,40,0,0,0,0,0,90,6,6,0,6,21,21,21,0,0,0,21,0,0,0,0,0,21,13,21,32,32,0,0,0
0,0,0,0,0,9,0,9,40,0,0,21,0,66,33,21,14,0,14,21,21,63,0,0,40,0,0,0,0,0,0,21,21,21,0,0,0,0,0
0,0,0,0,9,0,40,0,0,0,0,40,0,66,9,21,6,6,14,0,0,48,0,40,0,0,0,40,0,0,32,40,0,0,0,0,0,0,0
0,0,0,0,0,0,40,0,0,40,0,9,0,0,9,21,6,6,14,0,48,48,48,91,62,0,40,0,40,0,40,40,32,0,0,0,0,0,0
0,0,0,0,0,0,40,40,72,0,0,0,0,0,9,0,21,21,14,21,21,48,21,32,0,40,0,40,40,0,0,40,0,0,0,0,0,0,0
0,0,0,0,0,0,0,0,30,30,30,30,40,72,0,9,0,21,21,0,0,0,40,32,40,0,0,0,0,40,0,0,0,0,0,0,0,0,0
0,0,0,0,0,0,0,21,30,0,0,0,0,0,0,9,0,42,0,0,0,0,0,32,0,0,0,0,0,0,0,0,0,0,0,0,0,0,0
0,0,0,0,0,0,0,0,0,0,0,0,0,0,0,9,70,0,0,40,0,0,0,0,0,0,0,0,0,0,0,0,0,0,0,0,0,0,0
0,0,0,0,0,0,0,0,0,0,0,0,0,0,0,9,0,0,71,32,0,0,0,0,0,0,0,0,0,0,0,0,0,0,0,0,0,0,0
0,0,0,0,0,0,0,0,0,0,0,0,0,0,0,0,0,40,72,0,0,0,0,0,0,0,0,0,0,0,0,0,0,0,0,0,0,0,0
0,0,0,0,0,0,0,0,0,0,0,0,0,0,0,0,0,0,0,0,0,0,0,0,0,0,0,0,0,0,0,0,0,0,0,0,0,0,0
0,0,0,0,0,0,0,0,0,0,0,0,0,0,0,0,0,0,0,0,0,0,0,0,0,0,0,0,0,0,0,0,0,0,0,0,0,0,0
0,0,0,0,0,0,0,0,0,0,0,0,0,0,0,0,0,0,0,0,0,0,0,0,0,0,0,0,0,0,0,0,0,0,0,0,0,0,0
endlayer

layer
0,0,0,0,0,0,0,0,0,0,15,15,0,0,0,0,0,0,0,0,0,0,0,0,0,0,0,0,0,0,0,15,0,0,0,0,0,0,0
0,0,0,0,0,0,0,0,0,0,0,0,0,0,0,0,0,0,0,0,0,0,0,0,0,0,0,0,0,0,0,0,0,0,0,0,0,0,0
0,0,0,0,0,0,0,0,0,0,0,0,0,0,0,0,0,0,0,0,0,0,0,0,0,0,0,0,0,0,0,0,0,0,0,0,0,0,0
0,0,0,0,0,0,0,0,0,0,0,0,0,0,0,0,0,0,0,0,0,0,0,0,0,0,0,0,0,0,0,0,0,0,0,0,0,0,0
0,0,0,0,0,0,0,0,0,0,0,0,0,0,0,0,0,0,0,0,0,0,0,0,0,0,0,0,0,0,0,0,0,0,0,0,0,0,0
0,0,0,0,0,0,0,0,0,0,0,0,0,0,0,0,0,0,0,0,31,0,0,0,0,0,0,0,0,0,0,0,0,0,0,0,0,0,0
0,0,0,0,0,0,0,0,0,0,0,0,0,0,31,31,31,31,31,31,0,31,0,0,0,0,0,0,0,0,0,31,0,0,0,0,0,0,0
0,0,0,0,0,0,0,0,0,0,0,0,0,16,0,79,0,0,0,21,0,0,0,0,0,0,0,0,0,0,4,4,0,0,31,0,0,0,0
0,0,0,0,0,0,0,0,0,0,0,0,9,0,0,0,79,6,21,0,0,0,21,21,5,5,5,4,0,4,31,4,4,0,0,0,0,31,0
0,0,0,0,0,0,0,0,0,0,0,9,0,0,0,21,6,6,6,21,21,21,21,21,21,6,6,6,6,21,21,21,21,21,0,0,0,32,0
0,0,0,0,0,0,0,0,0,0,9,0,0,0,0,0,0,6,67,67,67,81,87,67,0,42,40,40,40,0,0,0,21,21,31,0,32,32,0
0,0,0,0,0,0,92,0,0,0,31,0,0,0,0,0,0,0,0,50,0,50,50,67,67,67,0,0,32,0,0,0,21,21,0,32,0,0,0
0,0,0,0,0,0,0,0,9,3,0,0,0,0,20,20,6,21,21,21,50,50,16,0,0,93,21,21,21,21,0,1,21,21,0,0,32,32,0
0,0,0,0,0,0,0,0,21,0,0,0,0,0,21,14,14,21,21,21,50,32,50,0,9,0,6,6,6,6,89,89,13,21,32,0,40,0,0
0,0,0,0,0,53,21,6,21,0,0,21,21,21,21,14,14,21,21,21,50,50,0,9,0,68,0,0,0,6,21,21,21,0,32,0,0,0,0
0,0,0,0,0,21,6,6,6,46,0,42,79,21,0,6,6,20,21,21,21,68,68,68,75,75,6,6,6,6,0,21,21,0,0,0,0,0,0
79,79,0,0,0,21,21,6,46,0,0,0,0,90,6,0,6,6,21,21,14,21,21,0,75,6,21,40,59,21,21,21,21,0,0,0,0,0,0
42,0,0,0,0,0,21,43,79,0,0,0,0,79,21,6,21,21,21,6,20,20,21,0,0,32,0,0,0,79,21,21,79,79,0,32,0,0,0
0,0,0,0,0,9,0,9,40,0,0,0,0,0,21,21,21,21,21,79,21,21,0,0,0,32,0,0,0,0,79,79,13,79,32,32,0,0,0
0,0,0,0,0,9,0,9,40,51,21,0,0,0,0,0,21,21,21,21,21,40,0,0,40,0,0,0,0,0,0,79,79,79,0,0,0,0,0
0,0,0,0,9,0,40,0,0,0,0,40,0,0,9,21,21,14,21,20,21,32,0,40,0,0,0,40,0,0,32,40,0,0,0,0,0,0,0
0,0,0,0,0,0,40,40,0,40,0,9,0,0,9,21,21,14,20,21,21,21,63,78,62,0,40,0,40,0,40,40,32,0,0,0,0,0,0
0,0,0,0,0,0,40,40,72,0,0,0,0,0,9,0,21,6,20,20,20,21,21,32,0,40,0,40,40,0,0,40,0,0,0,0,0,0,0
0,0,0,0,0,0,0,0,0,0,0,0,40,72,0,9,0,21,6,21,21,21,21,32,40,0,0,0,0,40,0,0,0,0,0,0,0,0,0
0,0,0,0,0,0,0,0,0,0,0,0,0,0,0,9,0,0,21,21,0,21,0,32,0,0,0,0,0,0,0,0,0,0,0,0,0,0,0
0,0,0,0,0,0,0,0,0,0,0,0,0,0,0,9,70,0,0,40,0,0,0,0,0,0,0,0,0,0,0,0,0,0,0,0,0,0,0
0,0,0,0,0,0,0,0,0,0,0,0,0,0,0,9,0,0,71,32,0,0,0,0,0,0,0,0,0,0,0,0,0,0,0,0,0,0,0
0,0,0,0,0,0,0,0,0,0,0,0,0,0,0,0,0,40,72,0,0,0,0,0,0,0,0,0,0,0,0,0,0,0,0,0,0,0,0
0,0,0,0,0,0,0,0,0,0,0,0,0,0,0,0,0,0,0,0,0,0,0,0,0,0,0,0,0,0,0,0,0,0,0,0,0,0,0
0,0,0,0,0,0,0,0,0,0,0,0,0,0,0,0,0,0,0,0,0,0,0,0,0,0,0,0,0,0,0,0,0,0,0,0,0,0,0
0,0,0,0,0,0,0,0,0,0,0,0,0,0,0,0,0,0,0,0,0,0,0,0,0,0,0,0,0,0,0,0,0,0,0,0,0,0,0
endlayer

layer
0,0,0,0,0,0,0,0,0,0,0,0,0,0,0,0,0,0,0,0,0,0,0,0,0,0,0,0,0,0,0,0,0,0,0,0,0,0,0
0,0,0,0,0,0,0,0,0,0,0,0,0,0,0,0,0,0,0,0,0,0,0,0,0,0,0,0,0,0,0,0,0,0,0,0,0,0,0
0,0,0,0,0,0,0,0,0,0,0,0,0,0,0,0,0,0,0,0,0,0,0,0,0,0,0,0,0,0,0,0,0,0,0,0,0,0,0
0,0,0,0,0,0,0,0,0,0,0,0,0,0,0,0,0,0,0,0,0,0,0,0,0,0,0,0,0,0,31,0,0,0,0,0,0,0,0
0,0,0,0,0,0,0,0,0,0,0,0,0,0,0,0,0,0,0,0,0,0,0,0,0,0,0,0,0,0,0,0,0,0,0,0,0,0,0
0,0,0,0,0,0,0,0,0,0,0,0,0,0,0,0,0,0,0,0,31,0,0,0,0,0,0,0,0,0,0,0,0,0,0,0,0,0,0
0,0,1,0,0,0,0,0,0,0,0,0,0,0,31,31,31,31,31,31,0,31,0,0,0,0,0,0,0,0,0,31,0,0,31,0,0,0,0
0,0,0,0,0,0,0,0,0,0,0,0,0,16,0,43,0,21,0,0,0,0,0,0,0,0,0,0,0,0,4,31,0,0,31,0,0,0,0
0,0,0,0,0,0,0,0,0,0,0,0,9,0,0,0,0,6,21,21,0,0,0,0,0,5,5,4,21,21,4,4,31,0,0,0,0,31,0
0,0,0,0,0,0,0,0,0,0,0,9,0,0,21,21,6,6,6,21,50,0,0,75,75,21,6,14,6,21,21,4,21,0,0,0,0,32,0
0,0,0,0,0,0,0,0,0,0,9,0,0,0,21,0,14,14,67,67,31,68,75,21,21,75,21,21,21,21,21,21,21,21,31,0,32,32,0
0,0,0,0,0,0,0,0,0,0,31,0,0,21,6,20,20,21,21,50,0,50,50,67,67,67,0,0,32,0,0,0,21,32,0,32,0,0,0
0,0,0,0,0,0,0,0,9,0,0,0,0,20,20,20,14,20,21,21,0,50,16,0,0,68,21,53,21,21,0,0,21,0,40,0,32,32,0
0,0,0,0,0,0,0,0,9,0,0,0,0,21,0,21,21,21,21,21,50,32,50,0,9,21,6,6,6,6,0,0,13,21,32,0,40,0,0
0,0,0,0,0,0,53,21,0,0,21,21,21,21,21,21,21,21,14,21,50,50,0,9,0,68,0,0,0,6,89,89,13,21,32,0,0,0,0
0,0,0,0,0,9,21,6,79,79,21,21,21,20,6,6,6,6,20,21,66,68,68,68,75,20,6,6,6,59,17,17,11,21,0,0,0,0,0
79,79,0,0,0,0,21,21,79,79,21,21,21,21,6,20,6,21,21,66,21,21,21,21,32,21,40,59,59,21,17,17,11,21,0,0,0,0,0
0,0,0,0,0,0,0,21,79,79,21,0,21,21,21,6,21,21,21,79,21,21,21,21,0,32,0,0,0,21,17,17,11,79,0,32,0,0,0
0,0,0,0,0,9,0,9,40,0,0,0,0,21,21,21,21,21,21,94,0,21,21,0,0,32,0,0,0,21,12,12,13,79,32,32,0,0,0
0,0,0,0,0,9,0,9,40,9,21,0,0,0,21,21,21,21,21,32,21,0,9,0,40,0,0,0,0,0,21,21,79,79,0,0,0,0,0
0,0,0,0,9,9,40,0,0,0,0,40,0,0,9,21,9,21,21,6,21,32,0,40,0,0,0,40,0,0,32,40,0,0,0,0,0,0,0
0,0,0,0,0,0,40,40,0,40,0,9,0,0,0,40,21,21,21,21,21,21,40,78,62,0,40,0,40,40,40,40,32,0,0,0,0,0,0
0,0,0,0,0,0,40,40,72,0,0,0,0,0,9,0,21,21,6,21,6,21,21,21,0,40,0,40,40,0,0,40,0,0,0,0,0,0,0
0,0,0,0,0,0,0,0,0,0,0,0,40,72,0,9,0,21,14,21,21,14,21,42,40,0,0,0,0,40,0,0,0,0,0,0,0,0,0
0,0,0,0,0,0,0,0,0,0,0,0,0,0,0,9,21,21,14,21,21,21,21,32,0,0,0,0,0,0,0,0,0,0,0,0,0,0,0
0,0,0,0,0,0,0,0,0,0,0,0,0,0,0,9,70,21,21,40,0,0,0,0,0,0,0,0,0,0,0,0,0,0,0,0,0,0,0
0,0,0,0,0,0,0,0,0,0,0,0,0,0,0,9,0,0,71,32,0,0,0,0,0,0,0,0,0,0,0,0,0,0,0,0,0,0,0
0,0,0,0,0,0,0,0,0,0,0,0,0,0,0,0,0,40,72,0,0,0,0,0,0,0,0,0,0,0,0,0,0,0,0,0,0,0,0
0,0,0,0,0,0,0,0,0,0,0,0,0,0,0,0,0,0,0,0,0,0,0,0,0,0,0,0,0,0,0,0,0,0,0,0,0,0,0
0,0,0,0,0,0,0,0,0,0,0,0,0,0,0,0,0,0,0,0,0,0,0,0,0,0,0,0,0,0,0,0,0,0,0,0,0,0,0
0,0,0,0,0,0,0,0,0,0,0,0,0,0,0,0,0,0,0,0,0,0,0,0,0,0,0,0,0,0,0,0,0,0,0,0,0,0,0
endlayer

layer
0,0,0,0,0,0,0,0,0,0,0,0,0,0,0,0,0,0,0,0,0,0,0,0,0,0,0,0,15,0,0,0,0,0,0,0,0,0,0
0,0,0,0,0,0,0,0,0,0,0,0,0,0,0,0,0,0,0,0,0,0,0,0,0,0,0,0,0,0,0,0,0,0,0,0,0,0,0
0,0,0,0,0,0,0,0,0,0,0,0,0,0,0,0,0,0,0,0,0,0,0,0,0,0,0,0,0,0,0,0,0,0,0,0,0,0,0
0,0,0,0,0,0,0,0,0,0,0,0,0,0,0,0,0,0,0,0,0,0,0,0,0,0,0,0,0,0,31,0,0,0,0,0,0,0,0
0,0,0,0,0,0,0,0,0,0,0,0,0,0,0,0,0,0,0,0,0,0,0,0,0,0,0,31,0,0,0,0,0,0,0,0,0,0,0
0,0,0,0,0,0,0,0,0,0,0,0,0,0,0,0,0,0,0,0,31,0,0,0,0,0,0,0,31,0,0,0,31,0,0,32,0,0,0
0,0,0,0,0,0,0,0,0,0,0,0,0,0,31,31,31,31,31,31,0,31,0,0,0,0,0,0,0,0,0,31,0,0,31,0,0,0,0
0,0,0,0,0,0,0,0,0,0,0,0,0,16,21,21,21,53,21,0,0,0,0,0,0,0,0,0,0,0,31,31,0,0,31,0,0,0,0
0,0,0,0,0,0,0,0,0,0,0,0,9,21,14,21,21,21,21,21,0,0,0,0,0,4,4,4,4,31,31,0,31,0,0,0,0,31,0
0,0,0,0,0,0,0,0,0,0,0,9,21,21,14,21,0,6,21,21,50,0,0,75,75,79,6,14,6,21,32,31,31,0,0,0,0,32,0
0,0,0,0,0,0,0,0,0,0,9,0,0,21,14,0,0,21,21,67,31,68,0,75,75,21,21,14,21,21,21,21,21,0,31,0,32,32,0
0,0,0,0,0,0,0,0,0,0,31,0,21,21,6,21,21,14,21,21,21,50,50,0,67,67,0,0,32,0,21,21,21,32,0,32,0,0,0
0,0,0,0,0,0,0,0,9,0,0,0,21,21,21,21,21,21,21,21,21,50,16,0,0,0,21,6,32,21,32,0,21,0,40,0,32,32,0
0,0,0,0,0,0,0,0,9,0,21,21,21,21,0,21,21,21,21,14,21,32,50,0,75,21,6,6,6,6,46,0,21,0,32,0,40,0,0
0,0,0,0,0,0,0,79,79,0,21,21,21,6,14,21,21,21,21,20,21,50,0,9,21,20,20,6,0,6,0,1,13,21,32,0,0,0,0
0,0,0,0,0,9,21,3,0,79,21,21,21,20,20,6,21,21,6,21,0,68,68,68,0,21,6,6,6,17,0,0,21,21,0,0,0,0,0
79,79,0,0,0,0,0,79,79,79,21,21,21,21,6,24,6,21,21,0,0,21,21,21,32,0,40,59,21,28,0,0,21,21,0,0,0,0,0
0,0,0,0,0,0,0,21,79,79,21,21,21,21,21,6,21,79,79,0,94,21,21,21,21,32,0,0,21,28,0,40,79,79,0,32,0,0,0
0,0,0,0,0,9,0,9,40,0,0,0,0,21,21,14,21,79,79,94,0,0,21,21,21,32,0,0,21,12,13,21,13,79,32,32,0,0,0
0,0,0,0,0,9,0,9,40,9,21,0,0,0,21,14,21,0,21,94,9,0,9,0,40,0,0,0,0,21,21,21,79,79,0,0,0,0,0
0,0,0,0,9,9,40,0,0,0,0,40,0,0,0,21,21,21,21,21,40,95,0,40,0,0,0,40,0,0,32,40,0,0,0,0,0,0,0
0,0,0,0,0,0,40,40,0,40,0,9,0,0,0,21,21,0,21,21,4,40,40,62,62,0,40,0,40,40,40,40,32,0,0,0,0,0,0
0,0,0,0,0,0,40,40,72,0,0,0,0,0,9,42,21,21,6,21,21,4,0,40,0,40,0,40,40,0,0,40,0,0,0,0,0,0,0
0,0,0,0,0,0,0,0,0,0,0,0,40,72,0,9,21,21,21,79,79,21,52,0,40,0,0,0,0,40,0,0,0,0,0,0,0,0,0
0,0,0,0,0,0,0,0,0,0,0,0,0,0,0,9,21,21,21,79,79,0,0,0,0,0,0,0,0,0,0,0,0,0,0,0,0,0,0
0,0,0,0,0,0,0,0,0,0,0,0,0,0,0,9,21,14,21,72,0,0,0,0,0,0,0,0,0,0,0,0,0,0,0,0,0,0,0
0,0,0,0,0,0,0,0,0,0,0,0,0,0,0,9,0,79,86,32,0,0,0,0,0,0,0,0,0,0,0,0,0,0,0,0,0,0,0
0,0,0,0,0,0,0,0,0,0,0,0,0,0,0,0,0,40,72,0,0,0,0,0,0,0,0,0,0,0,40,0,0,0,0,0,0,0,0
0,0,0,0,0,0,0,0,0,0,0,0,0,0,0,0,0,0,0,0,0,0,0,0,0,0,0,0,0,0,0,0,0,0,0,0,0,0,0
0,0,0,0,0,0,0,0,0,0,0,0,0,0,0,0,0,0,0,0,0,0,0,0,0,0,0,0,0,0,0,0,0,0,0,0,0,0,0
0,0,0,0,0,0,0,0,0,0,0,0,0,0,0,0,0,0,0,0,0,0,0,0,0,0,0,0,0,0,0,0,0,0,0,0,0,0,0
endlayer

layer
0,0,0,0,0,0,0,0,0,0,0,0,0,0,0,0,0,0,0,0,0,0,0,0,0,0,0,0,0,0,0,0,0,0,0,0,0,0,0
0,0,0,0,0,0,0,0,0,0,0,0,0,0,0,0,0,0,0,0,0,0,0,0,0,0,0,0,0,0,0,0,0,0,0,0,0,0,0
0,0,0,0,0,0,0,0,0,0,0,0,0,0,0,0,0,0,0,0,0,0,0,0,0,0,0,0,0,0,0,0,0,0,0,0,0,0,0
0,0,0,0,0,0,0,0,0,0,0,0,0,0,0,0,0,0,0,0,0,0,0,0,0,0,0,0,0,0,31,0,0,0,0,0,0,0,0
0,0,0,0,0,0,0,0,0,0,0,0,0,0,0,0,0,0,0,0,0,0,0,0,0,0,0,31,0,0,0,0,0,0,0,0,0,0,0
0,0,0,0,0,0,0,0,0,0,0,0,0,0,0,0,0,0,0,0,31,0,0,31,0,0,0,0,31,0,0,0,31,0,0,32,0,0,0
0,0,0,0,0,0,0,0,0,0,0,0,0,0,31,31,31,31,0,31,0,31,0,0,0,0,0,0,0,0,0,31,0,0,31,0,0,0,0
0,0,0,0,0,0,0,0,0,0,0,0,0,31,21,21,21,21,9,0,0,0,0,0,0,0,0,0,0,0,31,31,0,0,31,0,0,0,0
0,0,0,0,0,0,0,0,0,0,0,0,9,21,21,21,21,21,21,0,0,0,0,0,0,4,4,4,4,0,31,0,31,0,0,0,0,31,0
0,0,0,0,0,0,0,0,0,0,0,9,21,20,21,21,0,6,21,21,0,0,0,75,21,21,6,6,6,21,0,0,0,0,0,0,0,32,0
0,0,0,0,0,0,0,0,0,0,9,21,21,21,21,21,21,21,21,21,50,68,0,75,21,21,6,6,32,21,21,3,31,0,31,0,32,32,0
0,0,0,0,0,0,0,0,0,0,31,21,21,21,21,0,0,6,20,21,21,21,50,0,67,21,21,14,32,43,21,21,0,32,0,32,0,0,0
0,0,0,0,0,0,0,0,9,0,0,21,21,21,14,21,21,21,21,21,21,31,16,0,21,21,6,14,6,21,21,0,0,0,40,0,32,32,0
0,0,0,0,0,0,0,0,9,0,21,21,21,21,14,21,21,21,21,21,20,21,50,0,21,20,6,6,6,6,46,0,0,0,32,0,40,0,0
0,0,0,0,0,0,0,79,0,0,21,21,21,6,14,21,21,21,21,21,21,0,0,0,3,21,6,6,0,6,46,0,21,0,32,0,0,0,0
0,0,0,0,0,0,0,79,79,21,20,20,20,20,20,6,21,21,21,21,0,0,0,0,0,21,6,6,6,63,32,0,0,32,0,0,0,0,0
79,0,0,0,0,0,0,79,79,21,21,21,21,21,21,6,6,21,21,0,0,21,21,0,0,0,40,21,28,1,0,0,0,0,0,0,0,0,0
0,0,0,0,0,0,0,9,0,21,21,21,21,21,21,21,21,79,32,0,94,21,21,21,21,32,0,21,28,31,0,40,53,0,0,32,0,0,0
0,0,0,0,0,9,0,9,40,0,79,79,79,21,0,21,79,79,32,9,0,0,0,21,21,32,0,21,12,13,21,32,79,0,32,32,0,0,0
0,0,0,0,0,9,0,9,40,9,79,0,79,21,0,21,21,21,21,9,9,0,9,0,40,0,0,0,21,21,32,0,0,0,0,0,0,0,0
0,0,0,0,9,9,40,0,0,0,0,40,61,21,21,14,21,21,21,21,40,95,0,40,0,0,0,40,0,0,32,40,0,0,0,0,0,0,0
0,0,0,0,0,0,40,40,0,40,0,9,0,21,21,14,21,0,21,21,0,40,40,62,62,0,40,0,40,40,40,40,32,0,0,0,0,0,0
0,0,0,0,0,0,40,40,72,0,0,0,0,0,9,21,21,21,6,21,21,0,0,40,0,40,0,40,40,0,0,40,0,0,0,0,0,0,0
0,0,0,0,0,0,0,0,0,0,0,0,40,72,96,9,21,21,21,21,79,0,0,0,40,0,0,0,0,40,0,0,0,0,0,0,0,0,0
0,0,0,0,0,0,0,0,0,0,0,0,0,0,0,9,21,21,21,21,32,0,0,0,0,0,0,0,0,0,0,0,0,0,0,0,0,0,0
0,0,0,0,0,0,0,0,0,0,0,0,0,0,0,9,21,21,21,72,0,0,0,0,0,0,72,0,0,0,0,0,0,0,0,0,0,0,0
0,0,0,0,0,0,0,0,0,0,0,0,0,0,0,9,79,79,21,32,0,0,0,0,0,0,0,0,0,0,0,0,0,0,0,0,0,0,0
0,0,0,0,0,0,0,0,0,0,0,0,0,0,0,0,42,40,72,0,0,0,0,0,0,0,0,0,0,0,40,0,32,0,0,0,0,0,0
0,0,0,0,0,0,0,0,0,0,0,0,0,0,0,0,0,0,0,0,0,0,0,0,0,0,0,0,0,0,0,0,0,0,0,0,0,0,0
0,0,0,0,0,0,0,0,0,0,0,0,0,0,0,0,0,0,0,0,0,0,0,0,0,0,0,0,0,0,0,0,0,0,0,0,0,0,0
0,0,0,0,0,0,0,0,0,0,0,0,0,0,0,0,0,0,0,0,0,0,0,0,0,0,0,0,0,0,0,0,0,0,0,0,0,0,0
endlayer

layer
0,0,0,0,0,0,0,0,0,0,0,0,0,0,0,0,0,0,0,0,0,0,0,0,0,0,0,0,0,0,0,0,0,0,0,0,0,0,0
0,0,0,0,0,0,0,0,0,0,0,0,0,0,0,0,0,0,0,0,0,0,0,0,0,0,0,0,0,0,0,0,0,0,0,0,0,0,0
0,0,0,0,0,0,0,0,0,0,0,0,0,0,0,0,0,0,0,0,0,0,0,0,0,0,0,0,0,0,0,0,0,0,0,0,0,0,0
0,0,0,0,0,0,0,0,0,0,0,0,0,0,0,0,0,0,0,0,0,0,0,0,0,0,0,0,0,0,31,0,0,31,0,0,0,0,0
0,0,0,0,0,0,0,0,0,0,0,0,0,0,0,0,0,0,0,0,0,0,0,0,0,0,0,31,0,0,0,0,0,0,0,0,32,0,0
0,0,0,0,0,0,0,1,0,0,0,0,0,0,0,0,0,0,0,0,31,0,0,31,31,0,0,0,31,31,0,0,31,0,0,32,0,0,0
0,0,0,0,0,0,0,0,0,0,0,0,0,0,0,31,31,0,0,31,0,31,0,0,0,0,0,0,0,0,0,31,0,0,31,0,0,0,0
0,0,1,0,0,0,0,0,0,0,0,0,0,51,21,21,21,0,9,0,0,0,0,0,0,0,0,0,0,0,31,31,0,0,31,0,0,0,0
0,0,0,0,0,0,0,0,0,0,0,0,0,31,21,21,21,21,9,0,0,0,53,21,0,4,5,4,21,21,31,0,31,0,0,0,0,31,0
0,0,0,0,0,0,0,0,0,0,0,9,21,21,21,21,21,21,21,21,21,21,21,21,21,21,6,6,6,44,0,0,0,0,0,0,0,32,0
0,0,0,0,0,0,0,0,0,0,0,0,21,21,14,21,21,21,21,21,21,21,21,21,21,6,20,6,32,0,0,0,31,0,31,0,32,32,0
0,0,0,0,0,0,0,0,0,0,31,0,21,21,14,21,21,21,21,21,21,21,21,21,21,20,6,6,6,21,21,0,0,32,0,32,0,0,0
0,0,0,0,0,0,0,0,9,21,21,21,20,20,6,21,21,21,21,21,21,21,16,0,21,20,6,6,6,6,21,21,0,0,40,0,32,32,0
0,0,0,0,0,0,0,0,9,21,21,21,21,21,0,21,21,21,21,21,21,42,0,0,21,21,6,6,6,6,46,0,0,0,32,0,40,0,0
0,0,0,0,0,0,0,9,21,21,14,21,21,21,0,48,48,21,21,21,0,0,0,0,0,21,6,6,0,6,32,0,0,0,32,0,0,0,0
0,0,0,0,0,0,0,79,21,21,6,21,21,21,48,6,0,48,21,66,0,0,0,0,0,21,6,6,6,63,32,0,0,32,0,0,0,0,0
79,0,0,0,0,0,0,9,21,97,97,97,21,21,48,6,6,48,48,0,0,0,3,0,0,0,21,28,0,0,0,0,0,0,0,0,0,0,0
0,0,0,0,0,0,0,9,97,97,21,21,21,21,48,48,48,48,48,79,94,0,0,3,3,0,21,28,31,0,0,40,0,0,0,32,0,0,0
0,0,0,0,0,9,0,9,40,0,79,79,79,97,0,48,48,48,79,9,0,0,0,0,0,0,21,12,13,0,0,32,0,0,32,32,0,0,0
0,0,0,0,0,9,0,9,40,9,79,79,79,97,97,21,21,21,0,9,9,0,9,0,40,0,0,21,21,0,32,0,0,0,0,0,0,0,0
0,0,0,0,9,9,40,0,0,0,42,40,79,97,21,21,21,21,21,79,40,95,0,40,0,0,0,40,0,0,32,40,0,0,0,0,0,0,0
0,0,0,0,0,0,40,40,0,40,0,9,79,21,21,6,20,21,21,21,0,40,40,62,62,0,40,0,40,40,40,40,32,0,0,0,0,0,0
0,0,0,0,0,0,40,40,72,0,0,51,21,21,21,14,21,21,21,21,0,0,0,40,0,40,0,40,40,0,0,40,0,0,0,0,0,0,0
0,0,0,0,0,0,0,0,0,0,0,0,40,72,21,21,21,21,79,21,0,0,0,0,40,0,40,0,0,40,0,0,0,0,0,0,0,0,0
0,0,0,0,0,0,0,0,0,0,0,0,0,0,42,79,21,79,21,21,0,0,0,0,0,0,0,0,0,0,0,0,0,0,0,0,0,0,0
0,0,0,0,0,0,0,0,0,0,0,0,0,0,0,0,21,21,21,0,0,0,0,0,0,0,72,0,0,0,0,0,0,0,0,0,0,0,0
0,0,0,0,0,0,0,0,0,0,0,0,0,0,0,9,79,21,21,86,0,0,0,0,0,0,0,0,0,0,0,0,0,0,0,0,0,0,0
0,0,0,0,0,0,0,0,0,0,0,0,0,0,0,0,0,40,72,0,0,0,0,0,0,0,0,0,0,0,40,0,32,0,0,0,0,0,0
0,0,0,0,0,0,0,0,0,0,0,0,0,0,0,0,0,0,0,0,0,0,0,0,0,0,0,0,0,0,0,32,0,0,0,0,0,0,0
0,0,0,0,0,0,0,0,0,0,0,0,0,0,0,0,0,0,0,0,0,0,0,0,0,0,0,0,0,0,40,0,0,0,0,0,0,0,0
0,0,0,0,0,0,0,0,0,0,0,0,0,0,0,0,0,0,0,0,0,0,0,0,0,0,0,0,0,0,0,0,0,0,0,0,0,0,0
endlayer

layer
0,0,0,0,0,0,0,0,0,0,0,0,0,0,0,0,0,0,0,0,0,0,0,0,0,0,0,0,0,0,0,0,0,0,0,0,0,0,0
0,0,0,0,0,0,0,0,0,0,0,0,0,0,0,0,0,0,0,0,0,0,0,0,0,0,0,0,0,0,0,0,0,0,0,0,0,0,0
0,0,0,0,0,0,0,0,0,0,0,0,0,0,0,0,0,0,0,0,0,0,0,0,0,0,0,0,0,0,0,0,0,0,0,0,0,0,0
0,0,0,0,0,0,0,0,0,0,0,0,0,0,0,0,0,0,0,0,0,0,0,0,0,0,0,0,0,0,31,0,0,31,0,0,0,0,0
0,0,0,0,0,0,0,0,0,0,0,0,0,0,0,0,0,0,0,0,0,0,0,0,31,0,0,31,0,0,0,0,0,0,0,0,32,0,0
0,0,0,0,0,0,0,0,0,0,0,0,0,0,0,0,0,31,0,0,31,0,0,31,31,0,0,0,31,31,0,0,31,0,0,32,0,0,0
0,0,0,0,0,0,0,0,0,0,0,0,0,0,0,31,53,0,0,31,0,31,0,0,0,0,0,0,0,0,0,31,0,0,31,0,0,0,0
0,0,0,0,0,0,0,0,0,0,0,0,0,0,9,21,21,0,9,0,0,0,0,0,0,0,0,4,0,0,31,31,0,0,31,0,0,0,0
0,0,0,0,0,0,0,0,0,0,0,0,0,31,79,21,21,0,9,53,0,21,21,4,4,5,5,4,0,32,31,0,31,0,0,0,0,31,0
0,0,0,0,0,0,0,0,0,0,0,9,21,21,21,21,21,21,21,21,21,21,21,21,21,6,6,6,6,44,21,0,0,0,0,0,0,32,0
0,0,0,0,0,0,0,0,0,0,0,21,21,21,21,79,21,21,21,21,21,21,20,20,20,20,6,6,6,21,0,0,31,0,31,0,32,32,0
0,0,0,0,0,0,0,0,0,0,31,21,14,21,21,21,21,21,0,21,21,21,21,21,21,6,6,6,6,6,21,21,21,32,0,32,0,0,0
0,0,0,0,0,0,0,0,9,21,21,20,21,21,21,21,21,21,0,21,21,21,16,0,21,0,6,6,6,6,21,21,0,0,40,0,32,32,0
0,0,0,0,0,0,0,0,9,21,21,21,21,21,48,48,48,21,21,21,3,0,0,0,21,21,6,6,6,6,6,0,0,0,32,0,40,0,0
0,0,0,0,0,0,0,0,0,21,21,21,21,48,48,48,48,48,21,21,0,0,0,0,0,21,20,6,20,6,32,0,0,0,32,0,0,0,0
0,0,0,0,0,0,0,9,21,21,21,21,21,48,48,6,0,48,48,0,0,0,0,0,0,21,28,73,6,98,32,0,0,32,0,0,0,0,0
3,0,0,0,0,0,0,51,21,21,21,21,21,48,48,6,6,48,48,0,0,0,0,0,0,21,28,1,0,34,0,0,0,0,0,0,0,0,0
0,0,0,0,0,0,0,9,21,97,79,79,79,48,48,48,48,48,48,32,9,0,0,0,0,21,28,31,1,0,0,40,0,0,0,32,0,0,0
0,0,0,0,0,9,0,9,40,21,79,79,79,48,48,48,48,48,32,9,0,0,0,0,0,21,12,13,0,0,0,32,0,0,32,32,0,0,0
0,0,0,0,0,9,0,9,40,9,79,79,79,79,21,21,79,0,0,9,9,0,9,0,40,21,21,21,0,0,32,0,0,0,0,0,0,0,0
0,0,0,0,9,9,40,0,0,0,71,40,79,97,21,21,0,79,79,0,40,95,0,40,0,0,0,40,0,0,32,40,0,0,0,0,0,0,0
0,0,0,0,0,0,40,40,0,40,86,0,79,21,21,21,21,21,79,79,0,40,40,62,62,0,40,0,40,40,40,40,32,0,0,0,0,0,0
0,0,0,0,0,0,40,40,72,0,0,0,9,21,21,21,21,6,21,21,0,0,0,40,0,40,0,40,40,0,0,40,0,0,0,0,0,0,0
0,0,0,0,0,0,0,0,0,0,0,0,0,40,0,79,21,21,79,79,0,0,0,0,40,40,40,0,0,40,0,0,0,0,0,0,0,0,0
0,0,0,0,0,0,0,0,0,0,0,0,0,0,51,79,21,21,21,4,0,0,0,0,0,0,0,0,0,0,0,0,0,0,0,0,0,0,0
0,0,0,0,0,0,0,0,0,0,0,0,0,0,0,0,0,21,21,0,0,0,0,0,0,0,72,0,0,0,0,0,0,0,0,0,0,0,0
0,0,0,0,0,0,0,0,0,0,0,0,0,0,0,0,9,21,86,0,0,0,0,0,0,0,0,40,0,0,0,0,0,0,0,0,0,0,0
0,0,0,0,0,0,0,0,0,0,0,0,0,0,0,0,0,40,0,0,0,0,0,0,0,0,0,0,0,0,40,0,32,0,0,0,0,0,0
0,0,0,0,0,0,0,0,0,0,0,0,0,0,0,0,0,0,0,0,0,0,0,0,0,0,0,0,0,0,0,32,0,0,0,0,0,0,0
0,0,0,0,0,0,0,0,0,0,0,0,0,0,0,0,0,0,0,0,0,0,0,0,0,0,0,0,40,0,40,0,0,0,0,0,0,0,0
0,0,0,0,0,0,0,0,0,0,0,0,0,0,0,0,0,0,0,0,0,0,0,0,0,0,0,0,0,0,0,0,0,0,0,0,0,0,0
endlayer

layer
0,0,0,0,0,0,0,0,0,0,0,0,0,0,0,0,0,0,0,0,0,0,0,0,0,0,0,0,0,0,0,0,0,0,0,0,0,0,0
0,0,0,0,0,0,0,0,0,0,0,0,0,0,0,0,0,0,0,0,0,0,0,0,0,0,0,0,0,0,0,0,0,0,0,0,0,0,0
0,0,0,0,0,0,0,0,0,0,0,0,0,0,0,0,0,0,0,0,0,0,0,0,0,0,0,0,0,0,0,0,0,0,0,0,0,0,0
0,0,0,0,0,0,0,0,0,0,0,0,0,0,0,0,0,0,0,0,0,0,0,0,0,0,0,0,0,0,31,0,0,31,0,0,0,0,0
0,0,0,0,0,0,0,0,0,0,0,0,0,0,0,0,0,0,0,0,0,0,0,0,31,31,0,31,0,0,0,0,0,0,0,0,32,0,0
0,0,0,0,0,0,0,0,0,0,0,0,0,0,0,0,0,31,0,0,31,0,0,31,31,0,0,0,31,31,0,0,31,0,0,32,0,0,0
0,0,0,0,0,0,0,0,0,0,0,0,0,0,0,0,9,0,0,31,0,31,21,0,0,0,0,0,0,0,0,31,0,0,31,0,0,0,0
0,0,0,0,0,0,0,0,0,0,0,0,0,0,0,0,62,0,9,0,0,0,21,0,0,0,0,21,21,0,31,31,0,0,31,0,0,0,0
0,0,0,0,0,0,0,0,0,0,0,0,0,0,9,21,31,0,9,40,21,21,14,4,21,4,5,21,21,32,31,0,31,0,0,0,0,31,0
0,0,0,0,0,0,0,0,0,0,0,0,3,0,79,21,21,79,0,21,21,21,14,4,21,6,6,6,6,53,21,52,0,0,0,0,0,32,0
0,0,0,0,0,0,0,0,0,0,0,0,21,21,79,79,21,21,21,21,21,21,21,21,6,0,0,6,6,6,21,0,0,21,31,0,32,32,0
0,0,0,0,0,0,0,0,0,0,0,31,21,21,79,21,21,21,0,21,21,21,21,21,21,6,21,21,6,20,20,20,21,21,21,32,0,0,0
0,0,0,0,0,0,0,0,0,9,21,21,21,21,21,21,21,21,0,21,21,21,16,0,21,0,17,14,20,6,21,21,0,0,40,0,32,32,0
0,0,0,0,0,0,0,0,51,21,21,21,21,48,48,48,48,21,21,21,42,0,0,0,21,0,0,14,6,6,6,21,21,0,32,0,40,0,40
0,0,0,0,0,0,0,0,0,21,21,21,21,48,48,48,48,48,21,9,0,0,0,21,21,6,73,73,6,6,0,0,0,0,32,0,0,0,0
0,0,0,0,0,0,0,0,16,21,21,21,21,48,48,6,0,48,48,0,0,0,0,0,21,11,1,51,6,6,32,0,0,32,0,0,0,0,0
0,0,0,0,0,0,0,9,79,79,21,21,21,48,48,6,6,48,48,0,0,0,0,0,21,11,1,0,59,21,0,0,0,0,0,0,0,0,0
0,0,0,0,0,0,0,9,79,79,97,79,79,48,48,48,48,48,94,0,9,0,0,0,21,11,31,31,0,0,0,40,0,0,0,32,0,0,0
0,0,0,0,0,9,0,9,21,21,79,79,79,79,48,48,48,48,32,9,0,0,0,0,21,11,21,21,0,0,0,32,0,0,32,32,0,0,0
0,0,0,0,0,9,0,9,40,21,79,79,79,79,21,79,79,79,0,9,9,0,9,0,40,21,0,0,0,0,32,0,0,0,0,0,0,0,0
0,0,0,0,9,9,40,0,0,42,71,72,79,21,21,79,79,79,53,0,40,95,0,40,0,0,0,40,0,0,32,40,0,0,0,0,0,0,0
0,0,0,0,0,0,40,40,0,40,86,0,0,79,40,40,79,79,79,0,0,40,40,62,62,0,40,0,40,40,40,40,32,0,0,0,0,0,0
0,0,0,0,0,0,40,40,72,0,0,0,0,0,0,0,79,6,21,79,0,0,0,40,0,40,0,40,40,0,0,40,0,0,0,0,0,0,0
0,0,0,0,0,0,0,0,0,0,0,0,0,0,0,0,79,79,21,79,0,0,0,0,40,40,40,0,40,40,0,0,0,0,0,0,0,0,0
0,0,0,0,0,0,0,0,0,0,0,0,0,0,0,3,70,21,21,86,0,0,0,0,0,0,0,0,0,0,0,0,0,0,0,0,0,0,0
0,0,0,0,0,0,0,0,0,0,0,0,0,0,0,0,0,72,72,0,0,0,0,0,0,0,72,0,0,0,0,0,0,0,0,0,0,0,0
0,0,0,0,0,0,0,0,0,0,0,0,0,0,0,0,0,0,0,0,0,0,0,0,0,0,0,40,0,0,0,0,0,0,0,0,0,0,0
0,0,0,0,0,0,0,0,0,0,0,0,0,0,0,0,0,0,0,0,0,0,0,0,0,0,0,0,0,0,40,0,32,0,0,0,0,0,0
0,0,0,0,0,0,0,0,0,0,0,0,0,0,0,0,0,0,0,0,0,0,0,0,0,0,0,0,0,0,0,32,0,0,0,0,0,0,0
0,0,0,0,0,0,0,0,0,0,0,0,0,0,0,0,0,0,0,0,0,0,0,0,0,0,0,0,40,0,40,0,0,0,0,0,0,0,0
0,0,0,0,0,0,0,0,0,0,0,0,0,0,0,0,0,0,0,0,0,0,0,0,0,0,0,0,0,0,0,0,0,0,0,0,0,0,0
endlayer

layer
0,0,0,0,0,0,0,0,0,0,0,0,0,0,0,0,0,0,0,0,0,0,0,0,0,0,0,0,0,0,0,0,0,0,0,0,0,0,0
0,0,0,0,0,0,0,0,0,0,0,0,0,0,0,0,0,0,0,0,0,0,0,0,0,0,0,0,0,0,0,0,0,0,0,0,0,0,0
0,0,0,0,0,0,0,0,0,0,0,0,0,0,0,0,0,0,0,0,0,0,0,0,0,0,0,0,0,0,0,0,0,0,0,0,0,0,0
0,0,0,0,0,0,0,0,0,0,0,0,0,0,0,0,0,0,0,0,0,0,0,0,31,0,0,0,0,0,31,0,0,31,0,0,0,0,0
0,0,0,0,0,0,0,0,0,0,0,0,0,0,0,0,0,9,0,0,0,0,0,0,31,31,0,31,0,0,0,0,0,0,0,0,32,0,0
0,0,0,0,0,0,0,0,0,0,0,0,0,0,0,0,0,31,0,0,31,0,0,31,31,0,0,0,31,31,0,0,31,0,0,32,0,0,0
0,0,0,0,0,0,0,0,0,0,0,0,0,0,0,0,9,0,0,31,0,31,31,21,21,0,21,0,0,0,0,31,0,0,31,0,0,0,0
0,0,0,0,0,0,0,0,0,0,0,0,0,0,0,53,62,0,9,0,0,21,21,21,21,21,21,21,21,0,31,31,0,0,31,0,0,0,0
0,0,0,0,0,0,0,0,0,0,0,0,0,0,9,79,31,0,9,40,0,21,21,4,21,21,21,21,21,0,0,21,31,0,0,0,0,31,0
0,0,0,0,0,0,0,0,0,0,0,0,0,51,79,79,79,32,0,62,21,21,21,0,6,6,0,6,6,6,32,21,21,21,0,53,0,32,0
0,0,0,0,0,0,0,0,0,0,0,0,0,0,79,79,79,66,0,21,21,21,21,21,6,21,21,6,6,6,0,21,21,21,21,21,32,32,0
0,0,0,0,0,0,0,0,0,0,0,53,21,21,79,79,21,21,21,21,21,0,0,0,21,6,17,17,17,20,32,6,20,20,20,21,79,0,0
0,0,0,0,0,0,0,0,0,0,9,21,21,21,21,21,21,21,21,21,0,0,16,0,0,0,17,17,14,6,0,0,21,21,0,0,32,32,0
0,0,0,0,0,0,0,0,0,53,21,21,21,21,21,21,97,21,21,42,0,0,0,0,0,0,73,73,6,14,6,0,0,21,32,0,40,0,40
0,0,0,0,0,0,0,0,0,21,21,21,21,21,79,48,48,21,79,9,0,0,0,21,21,6,52,1,6,20,20,21,21,0,32,0,0,0,0
0,0,0,0,0,0,0,0,16,21,21,21,21,21,48,6,0,48,79,0,0,0,0,0,21,0,1,0,6,6,0,0,21,32,0,0,0,0,0
0,0,0,0,0,0,0,9,79,79,21,21,21,79,48,6,48,48,62,0,0,0,0,0,21,21,0,0,14,21,0,0,0,0,0,0,0,0,0
0,0,0,0,0,0,0,9,21,79,21,21,21,79,79,48,48,79,9,0,9,0,0,0,21,21,1,0,21,21,21,40,0,0,0,32,0,0,0
0,0,0,0,0,9,0,0,21,21,79,21,21,79,79,79,79,79,0,9,0,0,0,0,21,21,21,21,0,42,0,32,0,0,32,32,0,0,0
0,0,0,0,0,9,0,9,79,21,79,79,79,79,79,79,79,79,0,9,9,0,9,0,40,0,0,0,0,0,32,0,0,0,0,0,0,0,0
0,0,0,0,9,9,40,0,0,0,71,72,72,0,0,0,0,3,0,0,40,95,0,40,0,0,0,40,0,0,32,40,0,0,0,0,0,0,0
0,0,0,0,0,0,40,40,0,40,86,0,0,0,0,0,0,3,99,0,0,40,40,62,62,0,40,0,40,40,40,40,32,0,0,0,0,0,0
0,0,0,0,0,0,40,40,72,72,0,0,0,0,0,0,0,21,21,86,0,0,0,40,0,40,0,40,40,0,0,40,40,0,0,0,0,0,0
0,0,0,0,0,0,0,0,0,0,0,0,0,0,0,0,0,21,79,79,0,0,0,0,40,40,40,0,40,40,0,0,0,0,0,0,0,0,0
0,0,0,0,0,0,0,0,0,0,0,0,0,0,0,0,0,0,0,42,0,0,0,0,0,9,0,0,0,0,0,0,0,0,0,0,0,0,0
0,0,0,0,0,0,0,0,0,0,0,0,0,0,0,0,0,0,0,0,0,0,0,0,0,0,72,0,0,0,0,0,0,0,0,0,0,0,0
0,0,0,0,0,0,0,0,0,0,0,0,0,0,0,0,0,0,0,0,0,0,0,0,0,0,0,40,0,40,0,0,32,0,0,0,0,0,0
0,0,0,0,0,0,0,0,0,0,0,0,0,0,0,0,0,0,0,0,0,0,0,0,0,0,0,0,0,0,40,0,32,0,0,0,0,0,0
0,0,0,0,0,0,0,0,0,0,0,0,0,0,0,0,0,0,0,0,0,0,0,0,0,0,0,0,0,0,0,32,0,0,0,0,0,0,0
0,0,0,0,0,0,0,0,0,0,0,0,0,0,0,0,0,0,0,0,0,0,0,0,0,0,0,0,40,0,40,0,0,0,0,0,0,0,0
0,0,0,0,0,0,0,0,0,0,0,0,0,0,0,0,0,0,0,0,0,0,0,0,0,0,0,0,0,0,0,0,0,0,0,0,0,0,0
endlayer

layer
0,0,0,0,0,0,0,0,0,0,0,0,0,0,0,0,0,0,0,0,0,0,0,0,0,0,0,0,0,0,0,0,0,0,0,0,0,0,0
0,0,0,0,0,0,0,0,0,0,0,0,0,0,0,0,0,0,0,0,0,0,0,0,0,0,0,0,0,0,0,0,0,0,0,0,0,0,0
0,0,0,0,0,0,0,0,0,0,0,0,0,0,0,0,0,0,0,0,0,0,0,0,0,0,0,0,0,0,0,0,0,0,0,0,0,0,0
0,0,0,0,0,0,0,0,0,0,0,0,0,0,0,0,0,0,0,0,0,0,0,0,31,0,0,0,0,0,31,0,0,31,0,0,0,0,0
0,0,0,0,0,0,0,0,0,0,0,0,0,0,0,0,9,9,0,0,0,0,0,0,31,31,0,31,0,0,0,0,0,0,0,0,32,0,0
0,0,0,0,0,0,0,0,0,0,0,0,0,0,0,0,0,31,0,0,31,0,0,0,31,0,0,0,31,31,0,0,31,0,0,32,0,0,0
0,0,0,0,0,0,0,0,0,0,0,0,0,0,0,0,9,0,0,31,21,31,31,16,21,0,0,0,0,0,0,31,0,0,31,0,32,0,0
0,0,0,0,0,0,0,0,0,0,0,0,0,0,0,0,62,0,9,21,21,79,21,31,21,0,21,21,21,21,31,0,0,0,31,0,0,0,0
0,0,0,0,0,0,0,0,0,0,0,0,0,0,9,79,0,0,9,40,21,21,21,21,21,0,21,0,6,21,21,31,0,0,21,0,0,31,0
0,0,0,0,0,0,0,0,0,0,0,0,0,9,79,79,79,32,0,40,62,79,21,21,6,6,0,6,6,6,32,21,21,21,21,53,0,32,0
0,0,0,0,0,0,0,0,0,0,0,0,0,0,79,79,79,0,0,3,79,9,21,21,6,0,17,17,6,20,0,21,0,21,21,21,32,32,0
0,0,0,0,0,0,0,0,0,0,0,0,0,0,0,62,40,0,0,79,0,0,0,0,21,17,1,42,26,0,0,21,0,21,21,21,32,0,0
0,0,0,0,0,0,0,0,0,0,0,9,21,31,79,32,40,79,79,0,0,0,16,0,0,20,32,0,26,14,6,21,0,21,21,21,32,32,0
0,0,0,0,0,0,0,0,0,0,31,21,21,21,21,79,79,79,79,52,0,0,0,21,6,20,40,0,6,20,20,21,21,21,0,0,40,0,40
0,0,0,0,0,0,0,0,0,21,21,21,21,21,79,48,48,79,0,9,0,0,0,62,6,0,9,0,6,20,20,20,21,0,43,0,0,0,0
0,0,0,0,0,0,0,0,16,21,21,21,21,21,48,48,48,48,9,0,0,0,0,21,21,0,1,0,6,20,21,21,21,0,0,0,0,0,0
0,0,0,0,0,0,0,0,21,79,79,79,21,79,48,48,48,40,62,0,0,0,21,21,21,21,0,0,6,20,0,21,21,0,0,0,0,0,0
0,0,0,0,0,0,0,0,21,79,79,79,79,79,79,48,0,0,9,0,9,0,0,21,21,6,0,6,20,6,32,40,0,0,0,32,0,0,0
0,0,0,0,0,9,0,79,21,79,79,79,79,79,79,0,3,0,0,9,0,0,0,0,21,21,6,21,21,21,0,32,0,0,32,32,0,0,0
0,0,0,0,0,9,0,42,21,79,79,79,79,0,0,0,0,3,0,9,9,0,9,0,40,0,21,21,0,0,32,0,0,0,0,0,0,0,0
0,0,0,0,9,9,40,0,0,79,71,72,0,0,0,0,0,0,0,0,40,95,0,40,0,0,21,40,0,0,32,40,0,0,0,0,0,0,0
0,0,0,0,0,0,40,40,0,40,86,0,0,0,0,0,0,0,99,0,0,40,40,62,62,0,40,0,40,40,40,40,32,0,0,32,0,0,0
0,0,0,0,0,0,40,40,72,72,0,0,0,0,0,0,0,79,79,86,0,0,0,40,0,40,0,40,40,0,0,40,40,0,0,0,0,0,0
0,0,0,0,0,0,0,0,0,0,0,0,0,0,0,0,0,79,79,52,0,0,0,0,40,40,40,0,40,40,0,0,0,0,0,0,32,0,0
0,0,0,0,0,0,0,0,0,0,0,0,0,0,0,0,0,0,0,0,0,0,0,0,0,9,0,0,0,0,0,0,0,0,0,40,0,0,0
0,0,0,0,0,0,0,0,0,0,0,0,0,0,0,0,0,0,0,0,0,0,0,0,0,0,72,0,0,0,40,0,32,0,0,0,0,0,0
0,0,0,0,0,0,0,0,0,0,0,0,0,0,0,0,0,0,0,0,0,0,0,0,0,0,0,62,40,40,0,0,32,0,0,0,0,0,0
0,0,0,0,0,0,0,0,0,0,0,0,0,0,0,0,0,0,0,0,0,0,0,0,0,0,0,0,0,0,40,0,32,0,0,0,0,0,0
0,0,0,0,0,0,0,0,0,0,0,0,0,0,0,0,0,0,0,0,0,0,0,0,0,0,0,0,0,0,0,32,0,0,0,0,0,0,0
0,0,0,0,0,0,0,0,0,0,0,0,0,0,0,0,0,0,0,0,0,0,0,0,0,0,0,0,40,0,40,0,0,0,0,0,0,0,0
0,0,0,0,0,0,0,0,0,0,0,0,0,0,0,0,0,0,0,0,0,0,0,0,0,0,0,0,0,0,0,0,0,0,0,0,0,0,0
endlayer

layer
0,0,0,0,0,0,0,0,0,0,0,0,0,0,0,0,0,0,0,0,0,0,0,0,0,0,0,0,0,0,0,0,0,0,0,0,0,0,0
0,0,0,0,0,0,0,0,0,0,0,0,0,0,0,0,0,0,0,0,0,0,0,0,0,0,0,0,0,0,0,0,0,0,0,0,0,0,0
0,0,0,0,0,0,0,0,0,0,0,0,0,0,0,0,0,0,0,0,0,0,0,0,0,0,0,0,0,0,0,0,0,0,0,0,0,0,0
0,0,0,0,0,0,0,0,0,0,0,0,0,0,0,0,0,0,0,0,0,0,0,0,31,9,0,0,0,31,31,0,0,31,0,0,0,0,0
0,0,0,0,0,0,0,0,0,0,0,0,0,0,0,0,9,9,0,0,0,0,0,0,31,31,0,31,0,0,0,0,0,0,0,0,32,0,0
0,0,0,0,0,0,0,0,0,0,0,0,0,0,0,0,0,31,0,0,53,0,0,0,0,0,0,0,31,31,0,0,31,0,0,32,0,0,0
0,0,0,0,0,0,0,0,0,0,0,0,0,0,0,0,9,0,0,31,21,0,31,31,31,0,21,0,21,0,0,31,0,0,31,0,32,0,0
0,0,0,0,0,0,0,0,0,0,0,0,0,0,0,0,62,0,9,21,21,79,79,21,21,21,21,21,21,0,53,21,0,0,0,0,0,0,0
0,0,0,0,0,0,0,0,0,0,0,0,0,0,9,79,0,0,9,40,40,79,21,21,21,21,21,21,6,21,21,21,0,0,0,0,0,31,0
0,0,0,0,0,0,0,0,0,0,0,0,0,9,79,79,79,32,0,40,40,42,21,21,6,20,20,6,6,6,32,21,21,21,0,32,0,32,0
0,0,0,0,0,0,0,0,0,0,0,0,0,0,40,79,40,0,0,0,0,9,21,21,6,0,21,21,6,17,0,0,0,21,21,52,32,32,0
0,0,0,0,0,0,0,0,0,0,0,0,0,0,0,62,0,0,0,0,0,0,0,0,0,0,21,40,42,26,0,0,0,0,21,0,32,0,0
0,0,0,0,0,0,0,0,0,0,0,0,53,31,3,0,40,0,0,0,0,0,16,0,6,6,32,0,0,26,20,32,0,21,21,40,0,32,0
0,0,0,0,0,0,0,0,0,0,0,3,79,79,79,3,0,3,0,0,0,0,0,14,14,6,40,31,9,14,6,0,0,21,0,0,40,0,40
0,0,0,0,0,0,0,0,0,79,79,21,79,79,79,31,0,0,0,9,0,0,0,40,6,0,9,0,6,20,21,0,20,20,21,0,0,0,0
0,0,0,0,0,0,0,0,16,79,79,79,79,79,79,0,0,9,9,0,0,21,21,21,0,0,0,0,6,20,21,21,21,21,21,0,0,0,0
0,0,0,0,0,0,0,0,21,79,79,79,79,79,79,32,3,40,62,0,0,21,21,21,0,0,21,21,6,14,21,21,21,0,0,0,0,0,0
0,0,0,0,0,0,0,0,21,79,79,79,79,79,86,0,0,0,9,0,9,0,21,21,21,6,6,6,20,6,21,21,0,0,0,32,0,0,0
0,0,0,0,0,9,0,79,21,79,79,79,79,0,0,0,0,0,0,9,0,0,21,21,21,21,6,21,21,21,21,32,0,0,32,32,0,0,0
0,0,0,0,0,9,0,79,21,79,79,79,32,0,0,0,0,0,0,9,9,0,9,21,40,0,21,0,0,21,32,0,0,0,0,0,0,0,0
0,0,0,0,9,9,40,0,79,79,86,0,0,0,0,0,0,0,0,0,40,95,0,40,0,0,21,21,21,21,32,40,0,0,0,32,0,0,0
0,0,0,0,0,0,40,40,0,72,86,0,0,0,0,0,0,0,99,0,0,40,40,62,62,0,40,0,40,40,40,40,32,0,0,32,0,0,0
0,0,0,0,0,0,40,40,72,72,0,0,0,0,0,0,0,79,79,86,0,0,0,40,0,40,0,40,40,0,0,40,40,40,40,0,0,31,0
0,0,0,0,0,0,0,0,0,0,0,0,0,0,0,0,0,79,79,86,0,0,0,0,40,40,40,0,40,40,0,0,0,0,40,0,32,0,0
0,0,0,0,0,0,0,0,0,0,0,0,0,0,0,0,0,0,42,0,0,0,0,0,0,9,0,0,0,0,0,40,0,0,0,40,0,0,0
0,0,0,0,0,0,0,0,0,0,0,0,0,0,0,0,0,0,0,0,0,0,0,0,0,0,72,0,0,0,40,0,32,0,0,0,0,0,0
0,0,0,0,0,0,0,0,0,0,0,0,0,0,0,0,0,0,0,0,0,0,0,0,0,0,0,62,40,40,0,0,32,0,0,0,0,0,0
0,0,0,0,0,0,0,0,0,0,0,0,0,0,0,0,0,0,0,0,0,0,0,0,0,0,0,0,0,0,40,0,32,0,0,0,0,0,0
0,0,0,0,0,0,0,0,0,0,0,0,0,0,0,0,0,0,0,0,0,0,0,0,0,0,0,0,0,0,0,32,0,0,0,0,0,0,0
0,0,0,0,0,0,0,0,0,0,0,0,0,0,0,0,0,0,0,0,0,0,0,0,0,0,0,0,40,0,40,0,0,0,0,0,0,0,0
0,0,0,0,0,0,0,0,0,0,0,0,0,0,0,0,0,0,0,0,0,0,0,0,0,0,0,0,0,0,0,0,0,0,0,0,0,0,0
endlayer

layer
0,0,0,0,0,0,0,0,0,0,0,0,0,0,0,0,0,0,0,0,0,0,0,0,0,0,0,0,0,0,0,0,0,0,0,0,0,0,0
0,0,0,0,0,0,0,0,0,0,0,0,0,0,0,0,0,0,0,0,0,0,0,0,0,0,0,0,0,0,0,0,0,0,0,0,0,0,0
0,0,0,0,0,0,0,0,0,0,0,0,0,0,0,0,0,0,0,0,0,0,0,0,0,0,31,0,0,0,0,0,0,0,0,0,0,0,0
0,0,0,0,0,0,0,0,0,0,0,0,0,0,0,0,0,9,0,0,0,0,0,31,31,16,0,31,0,31,31,0,0,31,0,0,0,0,0
0,0,0,0,0,0,0,0,0,0,0,0,0,0,0,0,9,9,0,0,0,0,0,0,31,31,0,31,0,0,0,0,0,31,0,0,32,0,0
0,0,0,0,0,0,0,0,0,0,0,0,0,0,0,0,0,31,0,0,31,0,0,0,0,79,0,0,0,31,0,0,31,0,0,32,0,0,0
0,0,0,0,0,0,0,0,0,0,0,0,0,0,0,0,9,0,0,0,21,0,0,0,53,21,21,0,0,0,0,0,0,0,31,0,32,0,0
0,0,0,0,0,0,0,0,0,0,0,0,0,0,0,0,62,0,0,0,21,21,0,21,21,21,31,21,31,0,0,0,0,0,0,0,0,0,0
0,0,0,0,0,0,0,0,0,0,0,0,0,0,53,79,0,0,9,21,21,21,21,21,21,21,21,21,6,0,0,3,0,0,0,0,0,31,0
0,0,0,0,0,0,0,0,0,0,0,0,0,9,79,79,79,32,0,40,40,9,21,21,6,6,21,6,6,6,0,21,21,21,0,32,0,32,0
0,0,0,0,0,0,0,0,0,0,0,0,0,0,40,40,40,0,0,0,0,0,9,21,14,21,21,21,6,21,21,21,21,0,0,0,32,32,0
0,0,0,0,0,0,0,0,0,0,0,0,0,0,0,9,0,0,0,0,0,0,0,21,14,0,21,42,40,42,26,17,21,21,0,0,32,0,0
0,0,0,0,0,0,0,0,0,0,0,0,0,0,0,0,40,0,0,0,0,0,16,14,14,21,21,32,0,0,89,17,0,0,32,40,0,32,0
0,0,0,0,0,0,0,0,0,0,0,0,0,3,0,0,0,0,0,0,0,21,21,6,6,21,40,31,9,6,6,21,21,21,0,0,40,0,40
0,0,0,0,0,0,0,0,0,0,79,31,0,0,0,31,0,0,0,9,0,0,21,21,6,6,9,6,6,6,0,0,21,21,6,21,0,0,0
0,0,0,0,0,0,0,0,16,79,79,79,79,0,9,0,0,9,9,0,79,21,21,21,6,0,21,6,6,40,21,21,21,0,21,0,0,0,0
0,0,0,0,0,0,0,51,79,79,79,79,79,3,0,0,0,40,62,0,0,21,21,21,0,0,21,21,0,6,0,0,21,21,21,0,0,0,0
0,0,0,0,0,0,0,0,21,21,79,79,0,0,0,0,0,0,9,0,9,0,21,21,21,6,6,21,6,6,6,21,0,0,42,32,0,0,0
0,0,0,0,0,9,0,79,21,21,21,79,86,0,0,0,0,0,0,9,0,0,21,21,21,21,6,21,21,6,21,21,0,0,32,32,0,0,0
0,0,0,0,0,9,0,79,21,21,21,21,32,0,40,0,0,0,0,9,9,0,21,21,21,21,21,21,21,42,0,21,0,0,0,0,0,0,0
0,0,0,0,9,9,40,79,79,21,0,0,0,0,0,0,0,0,0,0,40,95,0,21,21,21,21,21,21,32,0,40,0,0,0,32,0,0,0
0,0,0,0,0,0,40,40,0,72,86,0,0,0,0,0,0,0,0,0,0,40,40,62,62,42,40,21,21,40,40,40,32,0,0,32,0,0,0
0,0,0,0,0,0,40,40,72,72,0,0,0,0,0,0,0,0,3,0,0,0,0,40,0,40,0,40,40,0,0,40,40,40,40,0,0,31,0
0,0,0,0,0,0,0,0,0,0,0,0,0,0,0,0,0,0,79,86,0,0,0,0,40,40,40,0,40,40,0,0,0,0,40,0,32,0,0
0,0,0,0,0,0,0,0,0,0,0,0,0,0,0,0,0,0,0,0,0,0,0,0,0,9,0,86,0,0,0,40,0,0,40,40,0,0,32
0,0,0,0,0,0,0,0,0,0,0,0,0,0,0,0,0,0,0,0,0,0,0,0,0,0,72,0,0,0,40,0,32,0,0,0,0,0,0
0,0,0,0,0,0,0,0,0,0,0,0,0,0,0,0,0,0,0,0,0,0,0,0,0,0,0,62,40,40,0,0,32,0,0,0,0,0,0
0,0,0,0,0,0,0,0,0,0,0,0,0,0,0,0,0,0,0,0,0,0,0,0,0,0,0,0,0,0,40,0,32,0,0,0,40,0,0
0,0,0,0,0,0,0,0,0,0,0,0,0,0,0,0,0,0,0,0,0,0,0,0,0,0,0,0,0,0,0,32,0,0,0,0,0,0,0
0,0,0,0,0,0,0,0,0,0,0,0,0,0,0,0,0,0,0,0,0,0,0,0,0,0,0,0,40,0,40,0,0,0,0,0,0,0,0
0,0,0,0,0,0,0,0,0,0,0,0,0,0,0,0,0,0,0,0,0,0,0,0,0,0,0,0,0,0,0,0,0,0,0,0,0,0,0
endlayer

layer
0,0,0,0,0,0,0,0,0,0,0,0,0,0,0,0,0,0,0,0,0,0,0,0,0,0,0,0,0,0,0,0,0,0,0,0,0,0,0
0,0,0,0,0,0,0,0,0,0,0,0,0,0,0,0,0,0,0,0,0,0,0,0,0,0,0,0,0,0,0,0,0,0,0,0,0,0,0
0,0,0,0,0,0,0,0,0,0,0,0,0,0,0,0,0,0,0,0,0,0,0,0,0,0,31,0,0,0,0,0,0,0,0,0,0,0,0
0,0,0,0,0,0,0,0,0,0,0,0,0,0,0,0,0,9,0,0,0,0,0,31,31,16,0,31,0,31,31,0,0,31,0,0,0,0,0
0,0,0,0,0,0,0,0,0,0,0,0,0,0,0,0,9,9,0,0,0,0,0,0,31,31,0,31,0,0,0,0,0,31,31,0,32,32,0
0,0,0,0,0,0,0,0,0,0,0,0,0,0,0,9,0,31,0,0,0,0,0,0,0,0,53,0,0,31,0,0,31,0,0,32,63,0,0
0,0,0,0,0,0,0,0,0,0,0,0,0,0,0,0,9,0,0,0,0,0,0,0,31,0,21,0,0,0,0,0,0,0,31,0,32,0,0
0,0,0,0,0,0,0,0,0,0,0,0,0,0,0,9,62,0,0,0,0,0,0,31,21,21,21,21,21,0,0,21,0,0,0,0,0,0,0
0,0,0,0,0,0,0,0,0,0,0,0,0,0,0,0,0,0,0,0,0,0,0,21,14,21,21,21,6,21,21,21,0,0,0,0,0,31,0
0,0,0,0,0,0,0,0,0,0,0,0,0,0,9,79,32,0,0,0,51,21,21,21,14,21,21,6,6,6,21,0,53,0,0,32,0,32,0
0,0,0,0,0,0,0,0,0,0,0,0,0,0,0,40,0,0,0,0,0,0,9,0,14,21,21,9,6,79,79,14,21,0,0,0,32,32,0
0,0,0,0,0,0,0,0,0,0,0,0,0,0,0,9,0,0,0,0,0,21,21,14,14,21,79,79,40,1,40,42,21,21,21,21,32,0,0
0,0,0,0,0,0,0,0,0,0,0,0,0,0,0,9,40,0,0,0,21,0,16,14,14,21,0,21,0,0,1,9,21,21,32,40,0,32,0
0,0,0,0,0,0,0,0,0,0,0,0,0,0,0,0,0,0,0,0,0,0,20,6,6,0,0,21,6,6,89,89,21,0,0,21,40,0,40
0,0,0,0,0,0,0,0,0,0,79,31,0,0,0,16,0,0,0,9,79,21,21,6,6,20,9,6,6,20,20,21,0,0,6,21,0,0,0
0,0,0,0,0,0,0,0,16,79,79,79,3,0,9,0,0,9,9,0,79,21,21,21,6,21,0,40,6,21,21,21,0,0,21,21,0,0,0
0,0,0,0,0,0,0,0,79,79,79,21,79,16,9,0,0,40,62,0,0,21,21,21,21,21,21,21,21,21,21,21,0,21,0,21,0,0,0
0,0,0,0,0,0,0,0,21,21,79,79,0,0,0,0,0,0,62,0,9,21,21,21,0,0,21,21,6,6,6,21,21,21,21,32,0,0,0
0,0,0,0,0,9,0,79,21,21,21,21,52,0,0,0,0,0,0,9,0,21,21,21,21,21,6,21,0,6,21,21,21,0,32,32,0,0,0
0,0,0,0,0,9,79,79,21,21,21,21,86,0,40,0,0,0,0,9,9,21,21,21,21,21,14,21,21,21,21,21,0,0,0,0,0,0,0
0,0,0,0,9,9,40,79,79,21,0,0,0,0,0,0,0,0,0,0,40,95,21,21,21,21,21,21,21,21,21,40,0,0,0,32,0,32,0
0,0,0,0,0,0,40,40,79,42,86,0,0,0,0,0,0,0,0,0,0,40,40,62,9,21,21,21,21,40,40,40,32,0,0,32,0,0,0
0,0,0,0,0,0,40,40,72,72,0,0,0,0,0,0,0,0,53,0,0,0,0,40,0,40,42,40,40,0,0,40,40,40,40,0,0,31,0
0,0,0,0,0,0,0,0,0,0,0,0,0,0,0,0,0,0,79,0,0,0,0,0,40,40,40,0,40,40,0,0,0,40,40,0,32,0,0
0,0,0,0,0,0,0,0,0,0,0,0,0,0,0,0,0,0,42,0,0,0,0,0,0,9,0,86,0,0,0,40,0,0,40,40,0,0,32
0,0,0,0,0,0,0,0,0,0,0,0,0,0,0,0,0,0,0,0,0,0,0,0,0,0,72,0,0,0,40,0,32,0,0,0,0,0,0
0,0,0,0,0,0,0,0,0,0,0,0,0,0,0,0,0,0,0,0,0,0,0,0,0,0,0,62,40,40,0,0,32,0,0,0,0,0,0
0,0,0,0,0,0,0,0,0,0,0,0,0,0,0,0,0,0,0,0,0,0,0,0,0,0,0,0,0,0,40,0,32,0,0,0,40,0,0
0,0,0,0,0,0,0,0,0,0,0,0,0,0,0,0,0,0,0,0,0,0,0,0,0,0,0,0,0,0,0,32,0,0,0,0,0,0,0
0,0,0,0,0,0,0,0,0,0,0,0,0,0,0,0,0,0,0,0,0,0,0,0,0,0,0,0,40,0,40,0,0,0,0,0,0,0,0
0,0,0,0,0,0,0,0,0,0,0,0,0,0,0,0,0,0,0,0,0,0,0,0,0,0,0,0,0,0,0,0,0,0,0,0,0,0,0
endlayer

layer
0,0,0,0,0,0,0,0,0,0,0,0,0,0,0,0,0,0,0,0,0,0,0,0,0,0,0,0,0,0,0,0,0,0,0,0,0,0,0
0,0,0,0,0,0,0,0,0,0,0,0,0,0,0,0,0,0,0,0,0,0,0,0,0,0,0,0,0,0,0,0,0,0,0,0,0,0,0
0,0,0,0,0,0,0,0,0,0,0,0,0,0,0,0,0,0,0,0,0,0,0,0,0,0,31,0,0,0,0,0,0,0,0,0,0,0,0
0,0,0,0,0,0,0,0,0,0,0,0,0,0,0,0,0,9,0,0,0,0,0,31,31,16,0,31,0,31,31,0,0,31,0,0,0,0,0
0,0,0,0,0,0,0,0,0,0,0,0,0,0,0,0,9,9,0,0,0,0,0,0,31,31,0,31,0,0,0,0,0,31,31,31,32,32,0
0,0,0,0,0,0,0,0,0,0,0,0,0,0,0,9,0,31,0,0,0,0,0,0,0,0,0,0,0,31,0,0,31,0,0,32,63,0,0
0,0,0,0,0,0,0,0,0,0,0,0,0,0,0,0,9,0,0,0,0,0,0,53,0,0,0,0,21,21,0,0,0,0,31,0,32,0,0
0,0,0,0,0,0,0,0,0,0,0,0,0,0,0,9,62,0,0,0,0,0,0,21,21,21,21,21,21,21,21,21,21,0,0,0,0,0,0
0,0,0,0,0,0,0,0,0,0,0,0,0,0,0,0,0,0,0,0,0,21,21,21,21,0,0,0,21,21,21,21,21,0,0,0,0,31,0
0,0,0,0,0,0,0,0,0,0,0,0,0,0,9,79,32,0,0,51,21,21,21,0,21,21,21,9,6,21,21,21,21,21,52,32,0,32,0
0,0,0,0,0,0,0,0,0,0,0,0,0,0,0,0,0,0,0,0,21,0,9,6,6,32,40,0,6,79,79,6,21,0,0,0,32,32,1
0,0,0,0,0,0,0,0,0,0,0,0,0,0,0,9,0,0,0,21,21,21,0,0,3,0,79,79,79,0,40,9,21,0,0,21,32,0,0
0,0,0,0,0,0,0,0,0,0,0,0,0,0,0,9,40,0,21,21,21,21,21,0,6,0,21,21,6,53,0,1,9,21,21,21,0,32,0
0,0,0,0,0,0,0,0,0,0,0,0,0,0,0,0,0,61,0,42,0,21,6,20,6,21,21,0,14,6,1,1,0,0,0,32,40,0,40
0,0,0,0,0,0,0,0,0,0,3,0,0,0,0,16,0,0,51,79,79,21,6,6,6,21,9,21,6,6,89,89,21,0,21,21,0,0,0
0,0,0,0,0,0,0,0,31,79,79,0,0,0,9,0,0,9,9,21,21,0,21,6,6,21,0,40,40,21,21,21,21,21,21,0,0,0,0
0,0,0,0,0,0,0,0,79,79,79,21,31,16,9,0,0,40,62,79,79,21,21,21,21,21,21,21,21,21,21,21,21,21,21,0,0,0,0
0,0,0,0,0,0,51,79,21,21,79,79,79,0,0,0,40,0,62,0,9,21,21,21,21,21,21,21,21,0,6,21,21,0,0,32,0,0,0
0,0,0,0,0,9,0,79,21,21,21,21,0,0,0,0,0,0,0,9,0,21,21,0,21,21,6,21,0,6,6,21,21,21,32,32,0,0,0
0,0,0,0,0,9,79,79,21,21,21,0,0,0,63,0,0,0,0,9,21,21,21,21,21,21,6,21,21,21,21,21,0,0,1,0,0,0,0
0,0,0,0,9,9,79,79,79,21,79,0,0,0,0,0,0,0,0,0,40,95,21,21,21,21,21,21,21,21,21,21,0,0,0,32,0,32,0
0,0,0,0,0,0,40,79,79,0,86,0,0,0,0,0,0,0,0,0,0,40,40,9,21,21,21,21,21,40,40,40,32,0,0,32,0,0,0
0,0,0,0,0,0,40,40,40,72,0,0,0,0,0,0,0,0,0,0,0,0,0,40,0,40,62,0,0,0,0,40,40,40,40,0,0,31,0
0,0,0,0,0,0,0,0,0,0,0,0,0,0,0,0,0,51,79,0,0,0,0,0,40,40,40,0,40,40,0,0,0,40,40,0,32,0,0
0,0,0,0,0,0,0,0,0,0,0,0,0,0,0,0,0,0,0,0,0,0,0,0,0,9,0,86,0,0,0,40,0,0,40,40,0,0,32
0,0,0,0,0,0,0,0,0,0,0,0,0,0,0,0,0,0,0,0,0,0,0,0,0,0,72,0,0,0,40,0,32,0,0,0,0,0,0
0,0,0,0,0,0,0,0,0,0,0,0,0,0,0,0,0,0,0,0,0,0,0,0,0,0,0,62,40,40,0,0,32,0,0,0,0,0,0
0,0,0,0,0,0,0,0,0,0,0,0,0,0,0,0,0,0,0,0,0,0,0,0,0,0,0,0,0,0,40,0,32,0,0,0,40,0,0
0,0,0,0,0,0,0,0,0,0,0,0,0,0,0,0,0,0,0,0,0,0,0,0,0,0,0,0,0,0,0,32,0,0,0,0,0,0,0
0,0,0,0,0,0,0,0,0,0,0,0,0,0,0,0,0,0,0,0,0,0,0,0,0,0,0,0,40,0,40,0,0,0,0,0,0,0,0
0,0,0,0,0,0,0,0,0,0,0,0,0,0,0,0,0,0,0,0,0,0,0,0,0,0,0,0,0,0,0,0,0,0,0,0,0,0,0
endlayer

layer
0,0,0,0,0,0,0,0,0,0,0,0,0,0,0,0,0,0,0,0,0,0,0,0,0,0,1,0,0,0,0,0,0,0,0,0,0,0,0
0,0,0,0,0,0,0,0,0,0,0,0,0,0,0,0,0,0,0,0,0,0,0,0,0,0,0,0,0,0,0,0,0,0,0,0,0,0,0
0,0,0,0,0,0,0,0,0,0,0,0,0,0,0,0,0,31,0,0,0,0,0,0,0,0,31,0,0,0,0,0,0,0,0,0,0,0,0
0,0,0,0,0,0,0,0,0,0,0,0,0,0,0,0,0,9,0,0,0,0,0,31,31,16,0,31,0,31,31,0,0,31,31,0,0,0,0
0,0,0,0,0,0,0,0,0,0,0,0,0,0,0,9,9,9,0,0,0,0,0,0,31,31,53,31,0,0,0,0,0,31,31,31,32,32,0
0,0,0,0,0,0,0,0,0,0,0,0,0,0,0,9,0,31,0,0,0,0,0,0,21,21,79,21,53,31,0,0,31,0,0,32,63,0,0
0,0,0,0,0,0,0,0,0,0,0,0,0,0,0,0,9,0,0,0,0,0,53,0,79,79,79,79,79,79,0,79,0,53,31,0,32,0,0
0,0,0,0,0,0,0,0,0,0,0,0,0,0,0,9,62,0,0,0,0,0,79,79,79,79,21,21,21,0,21,21,21,21,0,0,0,0,0
0,0,0,0,0,0,0,0,0,0,0,0,0,0,0,53,0,0,0,21,21,0,79,0,79,0,21,21,21,0,21,21,21,21,21,0,0,31,0
0,0,0,0,0,0,0,0,0,0,0,0,0,0,9,79,32,51,21,21,21,21,79,0,0,0,21,21,6,21,21,21,0,0,21,32,0,32,0
0,0,0,0,0,0,0,0,0,0,0,0,0,0,0,0,0,0,0,0,21,21,20,6,6,32,40,21,6,79,79,6,6,0,21,21,32,32,0
0,0,0,0,0,0,0,0,0,0,0,0,0,0,0,9,0,79,79,79,21,20,20,0,0,0,0,40,14,0,0,0,0,0,21,21,32,0,0
0,0,0,0,0,0,0,0,0,0,0,0,0,0,0,9,40,0,0,0,79,0,14,0,0,0,0,0,21,53,0,0,0,0,21,0,0,32,0
0,0,0,0,0,0,0,0,0,0,0,0,0,0,0,0,51,79,0,79,79,20,20,14,6,21,0,21,6,6,52,51,21,21,0,32,40,0,40
0,0,0,0,0,0,0,0,0,0,0,0,0,0,0,16,0,42,0,79,79,20,6,6,6,21,21,21,6,6,0,9,21,21,0,32,0,0,0
0,0,0,0,0,0,0,0,31,79,79,0,0,0,9,0,0,9,9,21,21,21,21,6,21,0,21,21,21,21,89,89,21,21,21,0,0,0,0
0,0,0,0,0,0,0,0,79,79,21,21,0,16,9,0,0,40,62,79,79,21,21,21,21,0,0,21,21,21,21,21,21,21,21,52,0,0,0
0,0,0,0,0,0,0,79,79,79,79,79,79,0,0,0,40,40,62,79,79,21,21,21,0,0,21,21,0,21,6,21,21,21,21,32,0,0,0
0,0,0,0,0,9,79,21,79,79,21,21,42,9,0,0,0,0,0,9,79,21,21,21,0,21,6,20,0,6,6,20,21,21,32,32,0,0,0
0,0,0,0,0,9,21,21,79,21,21,0,0,0,63,0,0,0,0,9,79,21,21,21,21,21,6,21,21,21,14,21,21,21,61,0,0,0,0
0,0,0,0,9,0,79,79,21,21,21,52,0,0,0,0,0,0,0,0,40,70,79,21,79,79,42,21,21,0,21,21,0,0,0,32,0,32,0
0,0,0,0,0,51,79,79,21,21,86,0,0,0,0,0,0,0,0,0,0,40,70,79,21,79,79,79,21,21,79,79,32,0,0,32,0,0,0
0,0,0,0,0,0,40,40,40,72,0,0,0,0,0,0,0,0,0,0,0,0,0,40,79,79,9,79,79,61,61,40,40,40,40,0,0,31,0
0,0,0,0,0,0,0,0,0,0,0,0,0,0,0,0,0,51,79,0,0,0,0,0,40,40,40,42,40,40,0,0,0,40,40,0,32,0,86
0,0,0,0,0,0,0,0,0,0,0,0,0,0,0,0,0,0,0,0,0,0,0,0,0,9,0,86,0,0,0,40,0,0,40,40,0,0,32
0,0,0,0,0,0,0,0,0,0,0,0,0,0,0,0,0,0,0,0,0,0,0,0,0,0,72,0,0,0,40,0,32,0,0,40,0,0,0
0,0,0,0,0,0,0,0,0,0,0,0,0,0,0,0,0,0,0,0,0,0,0,0,0,0,0,62,40,40,0,0,32,0,0,0,0,0,0
0,0,0,0,0,0,0,0,0,0,0,0,0,0,0,0,0,0,0,0,0,0,0,0,0,0,0,0,0,0,40,0,32,0,0,0,40,0,0
0,0,0,0,0,0,0,0,0,0,0,0,0,0,0,0,0,0,0,0,0,0,0,0,0,0,0,0,0,0,0,32,0,0,0,0,0,0,0
0,0,0,0,0,0,0,0,0,0,0,0,0,0,0,0,0,0,0,0,0,0,0,0,0,0,0,0,40,0,40,0,0,0,0,0,0,0,0
0,0,0,0,0,0,0,0,0,0,0,0,0,0,0,0,0,0,0,0,0,0,0,0,0,0,0,0,0,0,0,0,0,0,0,0,0,0,0
endlayer

layer
0,0,0,0,0,0,0,0,0,0,0,0,0,0,0,0,0,0,0,0,0,0,0,0,0,0,0,0,32,0,0,0,0,0,0,0,0,0,0
0,0,0,0,0,0,0,0,0,0,0,0,0,0,0,0,0,0,0,0,0,0,0,0,0,0,31,0,0,0,0,0,0,0,0,0,0,0,0
0,0,0,0,0,0,0,0,0,0,0,0,0,0,0,0,0,31,0,0,0,0,0,0,0,0,31,0,0,0,0,0,0,0,0,31,0,0,0
0,0,0,0,0,0,0,0,0,0,0,0,0,0,0,0,0,9,0,0,0,0,0,31,31,16,0,31,0,31,31,0,0,31,31,0,0,0,0
0,0,0,0,0,0,0,0,0,0,0,0,0,0,0,9,9,9,0,0,0,0,0,0,0,31,0,31,53,0,0,0,0,31,31,31,32,32,0
0,0,0,0,0,0,0,0,0,0,0,0,0,0,0,9,0,31,0,0,0,0,0,21,21,21,79,79,21,31,0,53,31,0,0,32,63,0,0
0,0,0,0,0,0,0,0,0,0,0,0,0,0,0,0,9,0,0,53,21,21,53,79,79,79,79,79,79,0,0,79,0,0,31,0,32,0,0
0,0,0,0,0,0,0,0,0,0,0,0,0,0,0,9,62,0,0,21,79,0,79,20,79,79,0,0,21,0,21,21,21,21,21,53,0,0,0
0,0,0,0,0,0,0,0,0,0,0,0,0,0,0,9,0,0,21,21,79,20,14,14,14,0,0,21,14,21,21,21,21,21,0,21,0,31,0
0,0,0,0,0,0,0,0,0,0,0,0,0,0,9,79,52,53,21,0,0,0,6,14,14,0,0,20,14,0,21,14,21,21,21,21,79,32,0
0,0,0,0,0,0,0,0,0,0,0,0,0,0,0,0,0,79,21,79,20,20,20,20,6,20,20,20,14,20,20,6,20,20,20,20,21,32,0
0,0,0,0,0,0,0,0,0,0,0,0,0,0,0,9,0,79,79,79,6,20,20,6,14,0,0,0,14,0,0,14,21,21,21,32,0,0,0
0,0,0,0,0,0,0,0,0,0,0,0,0,0,0,9,40,79,79,0,14,6,20,20,14,0,21,21,21,21,0,0,0,21,0,0,0,32,0
0,0,0,0,0,0,0,0,0,0,0,0,0,0,0,0,9,79,79,79,14,17,0,6,6,20,21,21,0,6,52,0,0,21,0,32,40,0,40
0,0,0,0,0,0,0,0,0,53,0,0,0,0,0,16,0,62,79,79,20,20,20,6,20,21,0,0,6,6,52,51,20,21,0,32,0,0,0
0,0,0,0,0,0,0,0,31,79,21,0,0,0,9,0,0,9,0,40,79,42,21,6,21,0,0,21,21,21,52,1,21,21,0,0,0,0,0
0,0,0,0,0,0,0,0,79,21,21,21,0,16,9,0,0,40,62,79,79,21,21,14,21,0,0,0,21,17,89,89,21,21,21,0,0,0,0
0,0,0,0,0,0,0,79,21,21,21,21,21,0,0,0,40,40,62,79,79,21,21,21,0,21,14,21,21,14,14,1,0,21,21,32,0,0,0
0,0,0,0,0,0,53,21,21,79,21,21,32,9,40,0,0,0,0,9,79,79,21,21,0,0,14,6,20,14,6,20,20,20,21,32,0,0,0
0,0,0,0,0,9,21,21,79,79,21,42,0,0,63,0,0,0,0,9,79,79,79,21,21,20,6,20,20,6,6,14,21,0,21,0,0,0,0
0,0,0,0,9,0,21,21,21,21,79,0,0,0,0,0,0,0,0,0,40,79,79,79,79,79,14,21,21,14,14,21,21,21,0,32,0,32,0
0,0,0,0,0,0,21,21,21,0,0,0,0,0,0,0,0,0,0,0,0,40,42,79,79,79,79,79,21,21,21,79,79,0,0,32,0,0,0
0,0,0,0,0,0,0,0,40,0,0,0,0,0,0,0,0,0,0,0,0,0,0,40,42,79,79,79,79,21,21,40,40,40,40,0,0,31,0
0,0,0,0,0,0,0,0,0,0,0,0,0,0,0,0,0,0,3,0,0,0,0,0,0,40,40,40,40,40,0,0,0,40,40,0,32,0,86
0,0,0,0,0,0,0,0,0,0,0,0,0,0,0,0,0,0,0,0,0,0,0,0,0,9,0,86,0,0,0,40,0,0,40,40,0,0,32
0,0,0,0,0,0,0,0,0,0,0,0,0,0,0,0,0,0,0,0,0,0,0,0,0,0,72,0,0,0,40,0,32,0,40,40,0,0,0
0,0,0,0,0,0,0,0,0,0,0,0,0,0,0,0,0,0,0,0,0,0,0,0,0,0,0,62,40,40,0,0,32,0,0,0,0,0,0
0,0,0,0,0,0,0,0,0,0,0,0,0,0,0,0,0,0,0,0,0,0,0,0,0,0,0,0,0,0,40,0,32,0,0,0,40,0,0
0,0,0,0,0,0,0,0,0,0,0,0,0,0,0,0,0,0,0,0,0,0,0,0,0,0,0,0,0,0,0,32,0,0,0,0,0,0,0
0,0,0,0,0,0,0,0,0,0,0,0,0,0,0,0,0,0,0,0,0,0,0,0,0,0,0,0,40,0,40,0,0,0,0,0,0,0,0
0,0,0,0,0,0,0,0,0,0,0,0,0,0,0,0,0,0,0,0,0,0,0,0,0,0,0,0,0,0,0,0,0,0,0,0,0,0,0
endlayer

layer
0,0,0,0,0,0,0,0,0,0,0,0,0,0,0,0,0,0,0,0,0,0,0,0,0,0,0,0,32,0,0,0,0,0,0,0,0,0,0
0,0,0,0,0,0,0,0,0,0,0,0,0,0,0,0,0,0,0,0,0,0,0,0,0,0,31,0,0,0,0,0,0,0,0,0,0,0,0
0,0,0,0,0,0,0,0,0,0,0,0,0,0,0,0,0,31,0,0,0,0,0,0,0,0,31,0,0,0,0,0,0,0,0,31,0,0,0
0,0,0,0,0,0,0,0,0,0,0,0,0,0,0,0,0,9,0,0,0,0,53,31,31,16,0,31,0,31,31,0,0,31,31,31,0,32,0
0,0,0,0,0,0,0,0,0,0,0,0,0,0,0,9,9,9,0,0,21,79,79,0,0,21,21,31,44,0,0,0,0,31,31,31,32,32,0
0,0,0,0,0,0,0,0,0,0,0,0,0,0,0,9,0,31,0,21,21,21,79,21,21,21,79,79,32,31,0,0,31,0,0,32,63,0,0
0,0,0,0,0,0,0,0,0,0,0,0,0,0,0,0,9,0,21,21,21,21,21,79,21,79,79,79,0,21,21,79,79,0,0,0,32,0,0
0,0,0,0,0,0,0,0,0,0,0,0,0,0,0,9,62,0,0,79,6,20,20,14,6,21,0,21,6,21,0,21,21,21,21,53,0,0,0
0,0,0,0,0,0,0,0,0,0,0,0,0,0,0,9,0,0,21,21,14,7,7,6,7,7,20,6,6,6,20,7,7,21,0,21,79,31,53
0,0,0,0,0,0,0,0,0,0,0,0,0,0,51,79,0,0,79,79,14,7,7,7,7,7,7,7,7,7,7,7,7,21,21,21,79,79,79
0,0,0,0,0,0,0,0,0,0,0,0,0,0,0,0,0,79,21,20,6,6,7,7,7,7,7,7,7,7,7,7,7,6,21,21,79,21,21
0,0,0,0,0,0,0,0,0,0,0,0,0,0,0,9,0,79,0,79,6,7,7,17,17,17,7,7,7,7,7,7,7,21,21,21,79,21,0
0,0,0,0,0,0,0,0,0,0,0,0,0,0,0,9,40,79,79,79,79,7,17,17,24,17,17,7,7,100,17,17,7,21,21,21,79,32,0
0,0,0,0,0,0,0,0,0,0,0,0,0,0,0,70,9,79,79,0,0,17,17,24,24,24,17,7,7,6,32,0,6,21,0,32,40,0,40
0,0,0,0,0,0,0,0,0,0,0,0,0,0,0,16,0,62,79,79,6,17,24,24,24,17,17,7,6,6,52,51,6,21,0,32,0,0,0
0,0,0,0,0,0,0,0,0,0,0,0,0,0,9,0,0,9,42,79,79,17,17,24,17,17,7,7,21,21,52,51,6,21,21,0,0,0,0
0,0,0,0,0,0,0,0,31,79,21,0,0,16,9,0,0,40,62,79,79,7,7,17,17,7,7,7,7,28,1,51,7,21,21,0,0,0,0
0,0,0,0,0,0,0,16,21,21,21,21,16,0,0,0,40,40,40,16,79,7,7,7,7,7,7,101,7,89,89,89,7,21,21,21,0,0,0
0,0,0,0,0,0,53,21,21,21,21,32,0,9,40,0,0,0,0,9,79,7,7,7,7,7,7,7,7,7,7,7,7,6,21,32,0,0,0
0,0,0,0,0,0,79,21,79,79,79,52,0,0,63,0,0,0,0,9,79,7,7,7,7,7,7,7,7,7,7,7,7,21,21,52,0,0,0
0,0,0,0,9,79,21,21,21,79,40,0,0,0,0,0,0,0,0,0,0,79,79,21,0,0,6,20,6,14,20,20,21,21,21,32,0,32,0
0,0,0,0,0,0,21,21,79,0,0,0,0,0,0,0,0,0,0,0,0,0,40,40,21,21,79,21,21,6,0,79,79,21,0,32,0,0,0
0,0,0,0,0,0,0,79,40,0,0,0,0,0,0,0,0,0,0,0,0,0,0,40,40,79,21,21,79,21,21,61,40,40,40,0,0,31,0
0,0,0,0,0,0,0,42,0,0,0,0,0,0,0,0,0,0,0,0,0,0,0,0,0,40,40,40,40,40,0,0,0,40,40,0,32,0,86
0,0,0,0,0,0,0,0,0,0,0,0,0,0,0,0,0,0,0,0,0,0,0,0,0,9,0,86,0,0,0,40,0,0,40,40,0,0,32
0,0,0,0,0,0,0,0,0,0,0,0,0,0,0,0,0,0,0,0,0,0,0,0,0,0,72,0,0,0,40,0,32,0,40,40,0,0,0
0,0,0,0,0,0,0,0,0,0,0,0,0,0,0,0,0,0,0,0,0,0,0,0,0,0,0,62,40,40,0,0,32,0,0,0,0,0,0
0,0,0,0,0,0,0,0,0,0,0,0,0,0,0,0,0,0,0,0,0,0,0,0,0,0,0,0,0,0,40,0,32,0,0,0,40,0,0
0,0,0,0,0,0,0,0,0,0,0,0,0,0,0,0,0,0,0,0,0,0,0,0,0,0,0,0,0,0,0,32,0,0,0,0,0,0,0
0,0,0,0,0,0,0,0,0,0,0,0,0,0,0,0,0,0,0,0,0,0,0,0,0,0,0,0,40,0,40,0,0,0,0,0,0,0,0
0,0,0,0,0,0,0,0,0,0,0,0,0,0,0,0,0,0,0,0,0,0,0,0,0,0,0,0,0,0,0,0,0,0,0,0,0,0,0
endlayer

layer
0,0,0,0,0,0,0,0,0,0,0,0,0,0,0,0,0,0,0,0,0,0,0,0,0,0,0,0,32,0,0,0,0,0,0,0,0,0,0
0,0,0,0,0,0,0,0,0,0,0,0,0,0,0,0,0,0,0,0,0,0,0,0,0,0,31,0,0,0,0,0,0,0,0,0,0,0,0
0,0,0,0,0,0,0,0,0,0,0,0,0,0,0,0,0,31,0,0,0,0,0,0,0,0,31,0,0,0,0,0,0,0,0,31,31,0,0
0,0,0,0,0,0,0,0,0,0,0,0,0,0,0,0,0,9,0,53,79,79,0,31,31,16,0,31,0,31,31,0,0,31,31,31,0,32,0
0,0,0,0,0,0,0,0,0,0,0,0,0,0,0,9,9,9,0,21,21,79,79,79,0,21,21,21,44,0,79,53,53,31,31,31,32,32,0
0,0,0,0,0,0,0,0,0,0,0,0,0,0,9,9,0,31,0,0,21,21,79,79,79,79,79,79,79,31,21,79,79,0,0,32,63,0,0
0,0,0,0,0,0,0,0,0,0,0,0,0,0,0,0,9,0,0,0,0,21,0,79,0,79,79,79,79,79,21,21,79,79,79,0,32,0,0
0,0,0,0,0,0,0,0,0,0,0,0,0,0,0,9,62,21,21,0,0,0,0,6,6,79,79,79,6,79,79,79,21,21,79,0,0,0,0
0,0,0,0,0,0,0,0,0,0,0,0,0,0,0,9,0,79,21,21,0,0,0,6,6,7,47,47,47,47,47,7,7,79,79,0,0,0,0
0,0,0,0,0,0,0,0,0,0,0,0,0,0,0,9,0,79,79,79,0,0,0,79,6,21,21,21,79,102,79,79,7,21,0,79,79,79,31
0,0,0,0,0,0,0,0,0,0,0,0,0,0,0,0,0,79,79,6,6,0,0,79,79,21,100,101,100,100,102,79,47,21,21,21,79,21,21
0,0,0,0,0,0,0,0,0,0,0,0,0,0,0,9,79,79,79,79,6,7,6,79,100,100,101,33,33,100,102,21,47,0,21,21,79,21,21
0,0,0,0,0,0,0,0,0,0,0,0,0,0,0,9,40,79,79,79,79,7,21,100,102,100,101,33,33,1,102,21,47,0,21,21,79,21,0
0,0,0,0,0,0,0,0,0,0,0,0,0,0,0,70,9,79,79,79,79,47,15,102,102,100,101,33,21,6,17,17,6,0,0,32,79,0,40
0,0,0,0,0,0,0,0,0,0,0,0,0,0,0,16,0,62,79,79,6,47,102,102,102,102,101,51,6,6,52,42,47,21,21,32,0,0,0
0,0,0,0,0,0,0,0,0,0,0,0,0,0,9,0,0,9,9,79,0,47,102,102,102,102,101,3,21,6,0,51,6,21,21,0,0,0,0
0,0,0,0,0,0,0,0,31,0,0,0,0,16,9,0,0,40,40,79,9,47,102,102,102,100,101,52,42,42,0,0,47,21,21,21,0,0,0
0,0,0,0,0,0,0,16,21,21,21,0,16,0,0,0,40,40,40,16,9,47,24,102,102,101,100,101,3,1,1,1,47,21,21,21,0,0,0
0,0,0,0,0,0,0,21,21,21,21,0,0,9,40,40,0,0,0,9,9,21,24,24,102,102,101,100,101,52,3,80,7,21,21,32,0,0,0
0,0,0,0,0,0,21,21,21,21,21,52,0,0,63,0,0,0,0,9,79,21,21,47,47,47,47,47,47,47,47,7,7,21,21,32,0,0,0
0,0,0,0,51,21,21,79,21,21,40,0,0,0,0,0,0,1,0,51,79,79,40,21,21,79,6,21,6,6,6,21,21,21,21,32,0,32,0
0,0,0,0,0,0,21,21,21,42,0,0,40,0,0,0,0,0,0,0,0,0,0,21,21,79,79,0,79,6,0,79,79,21,21,32,0,0,0
0,0,0,0,0,0,0,21,40,0,0,0,0,0,0,0,0,0,0,0,0,0,0,40,70,79,21,79,21,21,21,21,42,40,40,0,0,31,0
0,0,0,0,0,0,0,0,0,0,0,0,0,0,0,0,0,0,0,0,0,0,0,0,0,42,40,40,0,40,21,42,0,40,40,0,32,0,86
0,0,0,0,0,0,0,0,0,0,0,0,0,0,0,0,0,0,0,0,0,0,0,0,0,9,0,86,0,0,0,40,0,0,40,40,0,0,32
0,0,0,0,0,0,0,0,0,0,0,0,0,0,0,0,0,0,0,0,0,0,0,0,0,0,72,0,0,0,40,0,32,0,40,40,0,0,0
0,0,0,0,0,0,0,0,0,0,0,0,0,0,0,0,0,0,0,0,0,0,0,0,0,0,0,62,40,40,0,0,32,0,0,0,40,0,0
0,0,0,0,0,0,0,0,0,0,0,0,0,0,0,0,0,0,0,0,0,0,0,0,0,0,0,0,0,0,40,0,32,0,0,0,40,0,0
0,0,0,0,0,0,0,0,0,0,0,0,0,0,0,0,0,0,0,0,0,0,0,0,0,0,0,0,0,0,0,32,0,0,0,0,0,0,0
0,0,0,0,0,0,0,0,0,0,0,0,0,0,0,0,0,0,0,0,0,1,0,0,0,0,0,0,40,0,40,0,0,0,0,0,0,0,0
0,0,0,0,0,0,0,0,0,0,0,0,0,0,0,0,0,0,0,0,0,0,0,0,0,0,0,0,0,0,0,0,0,0,0,0,0,0,0
endlayer

layer
0,0,0,0,0,0,0,0,0,0,0,0,0,0,0,0,0,0,0,0,0,0,0,0,0,0,0,0,32,0,0,0,0,0,0,0,0,0,0
0,0,0,0,0,0,0,0,0,0,0,0,0,0,0,0,0,0,0,0,0,0,0,0,0,0,31,0,0,0,0,0,0,0,0,0,0,0,0
0,0,0,0,0,0,0,0,0,0,0,0,0,0,0,0,0,31,0,79,79,0,0,0,0,0,31,0,0,0,0,0,0,0,0,31,31,0,0
0,0,0,0,0,0,0,0,0,0,0,0,0,0,0,0,0,9,79,79,79,79,0,31,31,9,79,0,0,31,0,0,0,31,31,31,32,32,0
0,0,0,0,0,0,0,0,0,0,0,0,0,0,0,9,9,9,21,21,21,79,79,79,79,21,21,21,32,0,31,31,31,31,31,31,32,32,0
0,0,0,0,0,0,0,0,0,0,0,0,0,0,9,9,0,31,0,0,21,21,79,79,79,79,21,21,21,79,79,79,79,79,0,32,63,0,0
0,0,0,0,0,0,0,0,0,0,0,0,0,0,0,0,9,21,0,0,0,0,0,79,0,79,79,79,79,0,79,79,79,79,79,52,32,0,0
0,0,0,0,0,0,0,0,0,0,0,0,0,1,0,9,62,21,21,0,0,0,21,6,3,79,79,79,6,0,79,0,21,79,79,0,0,0,0
0,0,0,0,0,0,0,0,0,0,0,0,0,0,0,9,0,79,21,21,0,0,0,0,6,47,47,47,47,47,20,47,7,79,79,79,0,0,0
0,0,0,0,0,0,0,0,0,0,0,0,0,0,0,9,79,0,79,79,79,0,0,0,6,21,21,21,79,79,79,79,47,0,21,79,79,31,31
0,0,0,0,0,0,0,0,0,0,0,0,0,0,0,51,79,21,21,6,6,0,0,79,79,101,101,42,40,100,100,1,47,21,21,21,79,79,21
0,0,0,0,0,0,0,0,0,0,0,0,0,0,0,9,79,79,79,79,6,7,6,79,101,101,42,1,40,51,100,1,47,0,21,21,79,21,21
0,0,0,0,0,0,0,0,0,0,0,0,0,0,0,9,0,79,0,79,79,47,79,101,103,101,52,1,53,51,100,31,47,21,21,21,79,21,0
0,0,0,0,0,0,0,0,0,0,0,0,0,0,0,70,51,79,79,79,79,47,79,101,103,101,52,51,21,6,21,21,47,21,21,32,79,42,40
0,0,0,0,0,0,0,0,0,0,0,0,0,0,0,16,0,62,79,79,79,47,103,103,103,100,52,1,6,6,17,17,6,0,21,32,0,0,0
0,0,0,0,0,0,0,0,0,0,0,0,0,0,9,0,0,9,79,79,79,47,103,103,103,100,3,0,5,6,42,42,6,21,21,21,52,0,0
0,0,0,0,0,0,0,0,53,0,0,0,0,16,9,0,0,40,40,40,9,47,103,103,103,101,52,1,0,1,0,0,47,0,21,21,0,0,0
0,0,0,0,0,0,0,16,79,79,79,0,16,0,0,0,40,40,40,16,9,47,79,103,103,103,101,53,1,0,0,0,47,21,21,21,0,0,0
0,0,0,0,0,0,0,21,79,79,79,0,0,9,40,40,0,0,0,9,9,21,79,79,103,103,104,101,0,0,1,0,47,21,21,21,0,0,0
0,0,0,0,0,0,21,21,21,79,79,0,0,0,63,0,0,0,0,9,79,21,21,47,47,47,47,47,47,47,47,47,7,21,21,42,0,0,0
0,0,0,0,0,0,21,21,21,21,0,0,40,0,0,0,0,0,0,0,79,79,40,79,79,0,6,0,6,6,20,20,21,21,21,32,0,32,0
0,0,0,0,0,0,21,21,21,40,0,0,40,0,0,0,0,0,0,0,0,0,0,3,79,79,79,0,6,14,79,79,79,79,79,32,0,0,0
0,0,0,0,0,0,0,40,40,0,0,0,0,0,0,0,0,0,0,0,0,0,0,0,79,21,0,21,21,21,21,21,40,40,40,0,0,31,0
0,0,0,0,0,0,0,0,0,0,0,0,0,0,0,0,0,0,0,0,0,0,0,0,0,9,21,21,0,40,21,21,52,40,40,0,32,0,86
0,0,0,0,0,0,0,0,0,0,0,0,0,0,0,0,0,0,0,0,0,0,0,0,0,9,21,86,96,0,21,40,0,0,40,40,0,0,32
0,0,0,0,0,0,0,0,0,0,0,0,0,0,0,0,0,0,0,0,0,0,0,0,0,0,72,0,0,0,40,0,32,0,40,40,0,0,0
0,0,0,0,0,0,0,0,0,0,0,0,0,0,0,0,0,0,0,0,0,0,0,0,0,0,0,62,40,40,0,0,32,0,0,0,40,0,0
0,0,0,0,0,0,0,0,0,0,0,0,0,0,0,0,0,0,0,0,0,0,0,0,0,0,0,0,0,0,40,0,32,0,0,0,40,0,0
0,0,0,0,0,0,0,0,0,0,0,0,0,0,0,0,0,0,0,0,0,0,0,0,0,0,0,0,0,0,0,32,0,0,0,0,0,0,0
0,0,0,0,0,0,0,0,0,0,0,0,0,0,0,0,0,0,0,0,0,0,0,0,0,0,0,0,40,0,40,0,0,0,0,0,0,0,0
0,0,0,0,0,0,0,0,0,0,0,0,0,0,0,0,0,0,0,0,0,0,0,0,0,0,0,0,0,0,0,0,0,0,0,0,0,0,0
endlayer

layer
0,0,0,0,0,0,0,0,0,0,0,0,0,0,0,0,0,0,0,0,0,0,0,0,0,0,0,0,32,0,0,0,0,0,0,0,0,0,0
0,0,0,0,0,0,0,0,0,0,0,0,0,0,0,0,0,0,0,0,0,0,0,0,0,53,31,0,0,0,0,0,0,0,0,0,0,0,0
0,0,0,0,0,0,0,0,0,0,0,0,0,0,0,0,31,31,0,79,79,0,0,0,0,79,79,0,0,0,0,0,0,0,0,31,31,0,0
0,0,0,0,0,0,0,0,0,0,0,0,0,0,0,0,0,9,79,79,79,79,0,31,79,79,21,79,0,31,0,0,0,31,31,31,32,32,0
0,0,0,0,0,0,0,0,0,0,0,0,0,0,0,9,9,9,21,21,21,79,79,79,79,21,21,21,0,0,31,31,31,31,31,31,32,32,0
0,0,0,0,0,0,0,0,0,0,0,0,0,0,9,9,0,0,21,21,21,21,79,79,79,79,21,21,0,79,79,79,79,79,79,32,63,0,0
0,0,0,0,0,0,0,0,0,0,0,0,0,0,0,0,51,21,21,0,21,21,79,79,79,79,79,79,0,79,79,79,79,21,21,53,32,0,0
0,0,0,0,0,0,0,0,0,0,0,0,0,0,0,9,62,21,21,21,21,21,6,6,79,79,0,79,6,79,79,0,21,21,79,79,0,0,0
0,0,0,0,0,0,0,0,0,0,0,0,0,0,0,9,79,79,79,21,21,0,0,0,6,7,47,47,47,6,47,7,6,6,79,79,53,0,0
0,0,0,0,0,0,0,0,0,0,0,0,0,0,0,9,79,79,79,79,6,0,0,0,6,6,21,79,79,79,100,79,7,21,21,79,79,79,31
0,0,0,0,0,0,0,0,0,0,0,0,0,0,0,9,79,79,0,3,6,14,0,3,0,79,42,5,21,40,100,100,47,21,21,21,21,21,79
0,0,0,0,0,0,0,0,0,0,0,0,0,0,0,9,79,79,79,20,6,7,6,79,52,3,61,0,40,1,0,0,47,21,21,21,21,21,21
0,0,0,0,0,0,0,0,0,0,0,0,0,0,0,9,79,79,21,79,6,7,14,79,52,3,61,0,0,4,4,0,47,21,21,21,21,21,79
0,0,0,0,0,0,0,0,0,0,0,0,0,0,0,70,9,79,21,21,21,47,14,79,52,3,0,51,21,6,79,79,47,0,21,32,0,42,40
0,0,0,0,0,0,0,0,0,0,0,0,0,0,0,16,0,70,79,21,79,47,79,32,0,0,1,51,20,6,89,89,6,0,31,32,0,0,0
0,0,0,0,0,0,0,0,0,0,0,0,0,0,9,0,0,9,0,40,9,47,79,61,1,61,61,0,5,6,52,0,47,21,21,32,0,0,0
0,0,0,0,0,0,0,0,0,0,0,0,0,16,9,0,0,40,0,40,9,47,79,32,0,61,61,61,61,61,0,61,47,21,21,21,0,0,0
0,0,0,0,0,0,0,16,79,79,0,0,16,0,0,0,40,40,40,16,9,47,21,32,61,61,0,61,61,61,61,61,47,21,21,21,0,0,0
0,0,0,0,0,0,0,21,79,79,79,0,0,9,40,40,0,0,9,9,9,21,21,21,52,61,61,61,61,53,61,61,7,21,21,0,0,0,0
0,0,0,0,0,0,53,21,21,79,79,0,0,0,63,0,0,0,0,9,79,21,21,47,47,47,47,47,47,6,0,7,7,0,21,0,0,0,0
0,0,0,0,0,0,21,21,21,21,0,0,40,0,0,0,0,0,0,0,79,79,40,40,40,79,6,20,20,6,6,0,6,21,21,32,0,32,0
0,0,0,0,0,0,40,21,0,0,0,0,40,0,0,0,0,0,0,0,0,0,0,0,0,0,79,79,20,14,79,0,79,21,79,32,0,0,0
0,0,0,0,0,0,0,0,0,0,0,0,0,0,0,0,0,0,0,0,0,0,0,0,0,9,0,79,0,14,79,79,0,0,40,0,0,31,0
0,0,0,0,0,0,0,0,0,0,0,0,0,0,0,0,0,0,0,0,0,0,0,0,0,9,0,79,21,21,79,79,32,40,40,0,32,0,86
0,0,0,0,0,0,0,0,0,0,0,0,0,0,0,0,0,0,0,0,0,0,0,0,0,0,3,0,21,21,79,40,0,0,40,40,0,0,32
0,0,0,0,0,0,0,0,0,0,0,0,0,0,0,0,0,0,0,0,0,0,0,0,0,0,9,0,0,21,21,0,32,0,40,40,0,0,0
0,0,0,0,0,0,0,0,0,0,0,0,0,0,0,0,0,0,0,0,0,0,0,0,0,0,0,62,40,40,21,0,32,0,0,0,40,0,0
0,0,0,0,0,0,0,0,0,0,0,0,0,0,0,0,0,0,0,0,0,0,0,0,0,0,0,0,0,0,40,0,32,0,0,0,40,0,0
0,0,0,0,0,0,0,0,0,0,0,0,0,0,0,0,0,0,0,0,0,0,0,0,0,0,0,0,0,0,0,32,0,0,0,0,0,0,0
0,0,0,0,0,0,0,0,0,0,0,0,0,0,0,0,0,0,0,0,0,0,0,0,0,0,0,0,40,0,40,0,0,0,0,0,0,0,0
0,0,0,0,0,0,0,0,0,0,0,0,0,0,0,0,0,0,0,0,0,0,0,0,0,0,0,0,0,0,0,0,0,0,0,0,0,0,0
endlayer

layer
0,0,0,0,0,0,0,0,0,0,0,0,0,0,0,0,0,0,0,0,0,0,0,0,0,53,61,0,32,0,0,0,0,0,0,0,0,0,0
0,0,0,0,0,0,0,0,0,0,0,0,0,0,0,0,0,0,0,0,0,0,0,0,61,79,21,53,0,0,0,0,0,0,0,0,0,0,0
0,0,0,0,0,0,0,0,0,0,0,0,0,0,0,0,31,31,53,44,31,0,0,0,79,79,79,79,0,0,0,0,0,0,0,31,31,0,0
0,0,0,0,0,0,0,0,0,0,0,0,0,0,0,0,0,0,79,79,79,44,43,79,79,21,21,21,0,31,0,0,0,31,31,31,32,32,0
0,0,0,0,0,0,0,0,0,0,0,0,0,0,0,9,9,9,79,79,79,79,43,79,79,21,21,21,21,79,31,31,31,31,31,31,32,32,0
0,0,0,0,0,0,0,0,0,0,0,0,0,0,9,9,0,0,79,79,79,79,79,79,79,79,21,21,21,0,79,21,21,21,79,32,63,0,0
0,0,0,0,0,0,0,0,0,0,0,0,0,0,0,0,9,9,21,21,0,0,14,79,79,79,79,0,79,79,79,79,79,21,21,79,32,0,0
0,0,0,0,0,0,0,0,0,0,0,0,0,0,0,9,62,79,79,21,79,79,14,6,20,20,79,79,6,79,79,79,6,21,79,79,0,0,0
0,0,0,0,0,0,0,0,0,0,0,0,0,0,0,0,9,79,79,79,79,6,14,20,20,20,20,20,20,20,20,20,6,6,79,32,0,0,0
0,0,0,0,0,0,0,0,0,0,0,0,0,0,0,9,79,79,79,20,20,14,6,20,14,20,20,6,14,7,7,6,14,21,21,0,0,0,31
0,0,0,0,0,0,0,0,0,0,0,0,0,0,0,0,3,79,79,79,6,14,14,7,7,7,7,7,14,7,7,7,14,21,21,79,79,21,79
0,0,0,0,0,0,0,0,0,0,0,0,0,0,0,9,79,79,79,79,14,20,6,20,7,7,7,7,7,7,0,7,14,21,21,21,21,21,21
0,0,0,0,0,0,0,0,0,0,0,0,0,0,0,0,40,79,21,14,14,20,14,7,7,7,7,7,7,7,7,7,14,21,21,0,79,21,79
0,0,0,0,0,0,0,0,0,0,0,0,0,0,0,70,0,42,79,21,79,7,6,20,7,7,7,7,7,6,7,7,14,0,21,0,0,0,40
0,0,0,0,0,0,0,0,0,0,0,0,0,0,0,16,0,9,79,79,79,7,14,7,7,7,7,6,20,6,20,7,6,20,21,32,0,0,0
0,0,0,0,0,0,0,0,0,0,0,0,0,0,9,0,0,9,42,79,9,7,7,7,7,7,7,7,7,6,7,7,14,21,21,32,0,0,0
0,0,0,0,0,0,0,0,0,0,0,0,0,16,9,0,0,40,0,40,9,7,7,7,7,7,7,7,7,7,7,7,14,21,21,0,0,0,0
0,0,0,0,0,0,0,31,21,0,0,0,16,0,0,0,40,40,40,16,9,7,7,7,7,7,7,7,7,7,7,7,7,21,21,0,0,0,0
0,0,0,0,0,0,0,21,21,79,0,0,0,9,40,40,0,0,9,9,9,7,7,7,7,7,7,7,7,7,7,7,21,0,21,0,0,0,0
0,0,0,0,0,0,0,21,21,21,21,52,0,0,63,0,0,0,0,9,79,7,7,7,7,7,14,7,7,14,7,7,7,21,21,21,0,0,0
0,0,0,0,0,0,9,21,21,21,0,0,40,0,0,0,0,0,0,0,79,79,40,40,40,9,6,20,6,6,6,0,6,79,79,42,61,32,0
0,0,0,0,0,0,0,40,42,0,0,0,40,0,0,0,0,0,0,0,0,0,0,0,79,79,79,79,3,6,79,79,79,79,79,79,0,0,0
0,0,0,0,0,0,0,0,0,0,0,0,0,0,0,0,0,0,0,0,0,0,0,0,0,9,79,79,79,6,21,21,42,0,79,0,0,31,0
0,0,0,0,0,0,0,0,0,0,0,0,0,0,0,0,0,0,0,0,0,0,0,0,0,9,79,21,21,14,21,79,0,40,40,0,32,0,86
0,0,0,0,0,0,0,0,0,0,0,0,0,0,0,0,0,0,0,0,0,0,0,0,0,0,40,0,21,14,79,0,0,0,40,40,0,0,32
0,0,0,0,0,0,0,0,0,0,0,0,0,0,0,0,0,0,0,0,0,0,0,0,0,0,9,21,21,14,21,79,32,0,40,40,0,0,0
0,0,0,0,0,0,0,0,0,0,0,0,0,0,0,0,0,0,0,0,0,0,0,0,0,0,0,62,40,21,21,21,32,0,0,0,40,0,0
0,0,0,0,0,0,0,0,0,0,0,0,0,0,0,0,0,0,0,0,0,0,0,0,0,0,0,0,0,0,0,0,32,0,0,0,40,0,0
0,0,0,0,0,0,0,0,0,0,0,0,0,0,0,0,0,0,0,0,0,0,0,0,0,0,0,0,0,0,0,32,0,0,0,0,0,0,0
0,0,0,0,0,0,0,0,0,0,0,0,0,0,0,0,0,0,0,0,0,0,0,0,0,0,0,0,40,0,40,0,0,0,0,0,0,0,0
0,0,0,0,0,0,0,0,0,0,0,0,0,0,0,0,0,0,0,0,0,0,0,0,0,0,0,0,0,0,0,0,0,0,0,0,0,0,0
endlayer

layer
0,0,0,0,0,0,0,0,0,0,0,0,0,0,0,0,0,0,0,0,0,0,0,0,0,79,21,0,32,0,0,0,0,0,0,0,0,0,0
0,0,0,0,0,0,0,0,0,0,0,0,0,0,0,0,0,0,31,0,0,0,0,53,79,79,21,21,0,0,0,0,0,0,0,0,0,0,0
0,0,0,0,0,0,0,0,0,0,0,0,0,0,0,0,31,31,31,44,31,0,53,79,79,21,21,21,0,0,0,0,0,0,0,31,31,0,0
0,0,0,0,0,0,0,0,0,0,0,0,0,0,0,0,0,0,0,31,44,44,79,79,79,79,79,79,53,53,0,0,0,31,31,31,32,32,0
0,0,0,0,0,0,0,0,0,0,0,0,0,0,0,9,9,0,0,79,79,79,79,79,79,79,79,79,79,79,31,31,21,21,21,31,32,32,0
0,0,0,0,0,0,0,0,0,0,0,0,0,0,9,9,0,51,79,79,79,79,79,79,79,79,79,79,79,79,79,79,21,21,21,79,63,0,0
0,0,0,0,0,0,0,0,0,0,0,0,0,0,0,9,9,9,79,79,79,79,0,79,79,79,79,79,0,79,79,79,79,79,79,79,32,0,0
0,0,0,0,0,0,0,0,0,0,0,0,0,0,0,9,62,9,79,79,79,79,14,79,79,79,79,79,79,79,79,79,79,79,79,79,0,0,0
0,0,0,0,0,0,0,0,0,0,0,0,0,0,0,0,9,79,79,79,79,6,6,6,6,20,20,20,6,79,79,79,79,79,79,0,0,0,0
0,0,0,0,0,0,0,0,0,0,0,0,0,0,0,0,51,79,79,79,20,6,6,6,20,20,21,21,21,21,21,21,6,21,21,0,0,0,31
0,0,0,0,0,0,0,0,0,0,0,0,0,0,0,0,9,79,79,79,79,6,6,6,20,79,0,21,21,21,1,1,21,21,21,0,0,79,79
0,0,0,0,0,0,0,0,0,0,0,0,0,0,0,9,79,105,79,79,79,79,14,6,0,0,0,0,21,21,1,1,21,21,21,52,0,21,79
0,0,0,0,0,0,0,0,0,0,0,0,0,0,0,0,42,9,79,21,79,79,0,0,0,0,21,21,0,0,0,0,21,21,21,0,0,79,79
0,0,0,0,0,0,0,0,0,0,0,0,0,0,0,70,0,0,79,21,79,79,6,79,79,0,21,0,20,6,6,0,21,21,21,0,0,0,40
0,0,0,0,0,0,0,0,0,0,0,0,0,0,0,16,0,9,79,79,79,79,79,0,79,79,20,6,20,6,20,20,6,21,21,32,0,0,0
0,0,0,0,0,0,0,0,0,0,0,0,0,0,9,0,0,9,40,79,79,79,79,79,0,79,0,21,6,14,6,21,21,21,0,0,0,0,0
0,0,0,0,0,0,0,0,0,0,0,0,0,16,9,0,0,40,0,40,79,79,79,79,21,21,21,21,0,21,0,21,21,21,0,0,0,0,0
0,0,0,0,0,0,0,0,99,0,0,0,16,0,0,0,40,40,40,16,42,79,79,79,79,21,21,21,0,14,21,21,21,21,21,0,0,0,0
0,0,0,0,0,0,0,31,21,99,0,0,0,9,40,40,0,0,9,9,0,33,33,79,79,21,21,21,21,14,32,21,21,21,21,0,0,0,0
0,0,0,0,0,0,51,21,21,21,0,0,0,0,63,0,0,0,0,9,0,79,33,33,79,79,6,0,0,6,79,79,0,79,79,0,0,0,0
0,0,0,0,0,0,9,79,21,3,0,0,40,40,0,0,0,0,0,0,3,79,0,0,40,79,79,79,6,14,6,79,79,79,79,79,79,32,0
0,0,0,0,0,0,0,40,72,0,0,0,40,0,0,0,0,0,0,0,0,0,0,0,51,79,79,79,79,6,79,79,79,79,79,79,79,52,0
0,0,0,0,0,0,0,0,0,0,0,0,0,0,0,0,0,0,0,0,0,0,0,0,0,9,79,79,0,79,79,79,79,79,79,79,79,31,0
0,0,0,0,0,0,0,0,0,0,0,0,0,0,0,0,0,0,0,0,0,0,0,0,0,9,42,0,0,0,21,21,21,40,40,79,32,0,86
0,0,0,0,0,0,0,0,0,0,0,0,0,0,0,0,0,0,0,0,0,0,0,0,0,0,40,21,20,21,21,0,42,0,40,40,0,0,32
0,0,0,0,0,0,0,0,0,0,0,0,0,0,0,0,0,0,0,0,0,0,0,0,0,0,9,0,21,21,21,0,0,0,40,40,0,0,0
0,0,0,0,0,0,0,0,0,0,0,0,0,0,0,0,0,0,0,0,0,0,0,0,0,0,0,9,21,6,21,79,0,0,0,0,40,0,0
0,0,0,0,0,0,0,0,0,0,0,0,0,0,0,0,0,0,0,0,0,0,0,0,0,0,0,0,79,79,79,79,32,0,0,0,40,0,0
0,0,0,0,0,0,0,0,0,0,0,0,0,0,0,0,0,0,0,0,0,0,0,0,0,0,0,0,0,79,79,32,0,0,0,0,0,0,0
0,0,0,0,0,0,0,0,0,0,0,0,0,0,0,0,0,0,0,0,0,0,0,0,0,0,0,0,40,0,40,0,0,0,0,0,0,0,0
0,0,0,0,0,0,0,0,0,0,0,0,0,0,0,0,0,0,0,0,0,0,0,0,0,0,0,0,0,0,0,0,0,0,0,0,0,0,0
endlayer

layer
0,0,0,0,0,0,0,0,0,0,0,0,0,0,0,0,0,0,0,0,0,0,0,0,0,21,21,21,32,0,0,0,0,0,0,0,0,0,0
0,0,0,0,0,0,0,0,0,0,0,0,0,0,0,0,0,0,31,0,0,0,0,0,0,79,21,79,0,0,0,0,0,0,0,0,0,0,0
0,0,0,0,0,0,0,0,0,0,0,0,0,0,0,0,31,31,31,44,31,0,0,0,0,79,79,79,0,0,0,0,0,0,0,31,31,0,0
0,0,0,0,0,0,0,0,0,0,0,0,0,0,0,0,0,0,0,31,44,44,31,79,79,79,21,21,31,31,0,0,53,31,31,31,32,32,0
0,0,0,0,0,0,0,0,0,0,0,0,0,0,0,9,9,0,0,16,79,79,79,79,21,21,21,21,79,79,31,31,79,79,79,79,32,32,0
0,0,0,0,0,0,0,0,0,0,0,0,0,0,9,9,0,0,31,79,79,79,79,79,21,21,21,21,21,79,79,79,79,79,79,79,63,0,0
0,0,0,0,0,0,0,0,0,0,0,0,0,0,0,9,9,9,79,79,79,79,0,0,21,79,79,79,0,79,79,79,79,79,79,79,32,0,0
0,0,0,0,0,0,0,0,0,0,0,0,0,0,0,9,62,9,79,79,79,79,79,0,79,79,0,79,79,79,79,79,79,79,79,0,0,0,0
0,0,0,0,0,0,0,0,0,0,0,0,0,0,0,0,0,9,79,79,79,6,6,6,79,79,79,79,6,0,0,79,79,79,79,52,0,0,0
0,0,0,0,0,0,0,0,0,0,0,0,0,0,0,0,9,79,79,79,79,6,6,6,6,0,0,0,0,0,79,0,79,79,0,0,0,0,31
0,0,0,0,0,0,0,0,0,0,0,0,0,0,0,0,0,40,79,79,79,6,6,6,6,79,0,21,21,0,0,0,0,21,0,0,0,53,79
0,0,0,0,0,0,0,0,0,0,0,0,0,0,0,0,0,31,79,79,0,79,6,6,6,0,0,0,21,21,21,0,0,21,0,0,0,79,79
0,0,0,0,0,0,0,0,0,0,0,0,0,0,0,0,9,0,79,79,79,79,79,79,79,0,0,21,0,6,21,21,0,21,32,0,0,0,79
0,0,0,0,0,0,0,0,0,0,0,0,0,0,0,70,0,0,79,79,79,79,79,79,0,0,0,0,6,6,6,21,21,21,32,0,0,0,40
0,0,0,0,0,0,0,0,0,0,0,0,0,0,0,16,0,9,79,79,79,79,79,79,0,20,20,6,6,6,6,6,21,0,32,0,0,0,0
0,0,0,0,0,0,0,0,0,0,0,0,0,0,9,0,0,9,40,21,21,79,79,21,79,79,21,6,6,6,6,21,21,53,0,0,0,0,0
0,0,0,0,0,0,0,0,0,0,0,0,0,16,9,0,0,40,0,42,79,79,79,79,79,79,21,21,0,6,21,42,21,21,0,0,0,0,0
0,0,0,0,0,0,0,0,99,0,0,0,16,0,0,0,40,40,40,16,79,40,40,79,79,79,21,21,0,14,21,21,21,21,3,0,0,0,0
0,0,0,0,0,0,0,106,79,0,0,0,0,9,40,40,0,0,9,9,0,0,0,0,42,79,21,21,21,14,32,21,21,21,53,0,0,0,0
0,0,0,0,0,0,70,21,21,79,9,0,0,0,63,0,0,0,0,9,0,79,0,0,0,79,21,21,79,14,79,79,79,79,79,0,0,0,0
0,0,0,0,0,0,0,79,79,0,0,0,40,40,0,0,0,0,0,0,40,0,0,0,0,42,79,79,20,14,20,79,79,79,79,79,53,0,0
0,0,0,0,0,0,0,0,72,0,0,0,40,0,0,0,0,0,0,0,0,0,0,0,0,9,79,79,79,14,79,79,79,79,79,79,79,0,0
0,0,0,0,0,0,0,0,0,0,0,0,0,0,0,0,0,0,0,0,0,0,0,0,0,9,79,79,0,79,79,79,79,79,79,79,21,31,0
0,0,0,0,0,0,0,0,0,0,0,0,0,0,0,0,0,0,0,0,0,0,0,0,0,9,21,6,79,79,0,3,0,0,79,79,21,21,86
0,0,0,0,0,0,0,0,0,0,0,0,0,0,0,0,0,0,0,0,0,0,0,0,0,0,40,21,21,0,0,0,0,0,40,79,0,42,32
0,0,0,0,0,0,0,0,0,0,0,0,0,0,0,0,0,0,0,0,0,0,0,0,0,0,9,21,21,0,79,0,0,0,40,40,0,0,0
0,0,0,0,0,0,0,0,0,0,0,0,0,0,0,0,0,0,0,0,0,0,0,0,0,0,0,9,21,6,79,79,0,0,0,0,40,0,0
0,0,0,0,0,0,0,0,0,0,0,0,0,0,0,0,0,0,0,0,0,0,0,0,0,0,0,0,79,79,21,79,0,0,0,0,40,0,0
0,0,0,0,0,0,0,0,0,0,0,0,0,0,0,0,0,0,0,0,0,0,0,0,0,0,0,0,79,79,79,32,0,0,0,0,0,0,0
0,0,0,0,0,0,0,0,0,0,0,0,0,0,0,0,0,0,0,0,0,0,0,0,0,0,0,0,40,42,40,0,0,0,0,0,0,0,0
0,0,0,0,0,0,0,0,0,0,0,0,0,0,0,0,0,0,0,0,0,0,0,0,0,0,0,0,0,0,0,0,0,0,0,0,0,0,0
endlayer

layer
0,0,0,0,0,0,0,0,0,0,0,0,0,0,0,0,0,0,0,0,0,0,0,0,0,21,21,21,32,0,0,0,0,0,0,0,0,0,0
0,0,0,0,0,0,0,0,0,0,0,0,0,0,0,0,0,0,31,0,0,0,0,0,0,79,21,21,0,0,0,0,0,0,0,0,0,0,0
0,0,0,0,0,0,0,0,0,0,0,0,0,0,0,0,31,31,31,44,31,0,0,0,0,79,79,79,0,0,0,0,0,0,0,31,31,0,0
0,0,0,0,0,0,0,0,0,0,0,0,0,0,0,0,0,0,0,31,44,44,31,79,0,0,79,0,0,0,0,0,0,31,53,53,32,32,0
0,0,0,0,0,0,0,0,0,0,0,0,0,0,0,9,9,0,0,16,79,79,79,79,31,31,79,53,31,0,0,0,0,79,79,79,52,32,0
0,0,0,0,0,0,0,0,0,0,0,0,0,0,9,9,0,0,53,79,79,79,79,79,43,21,21,79,21,31,31,0,79,79,79,79,63,0,0
0,0,0,0,0,0,0,0,0,0,0,0,0,0,0,9,9,9,79,79,79,79,0,79,79,79,79,79,79,79,21,21,21,79,79,79,32,0,0
0,0,0,0,0,0,0,0,0,0,0,0,0,0,0,9,62,9,79,79,21,14,0,79,0,79,0,0,79,79,21,21,21,79,0,0,0,0,0
0,0,0,0,0,0,0,0,0,0,0,0,0,0,0,0,0,9,79,79,21,6,20,6,79,79,0,0,6,79,0,21,21,0,0,0,0,0,0
0,0,0,0,0,0,0,0,0,0,0,0,0,0,0,0,0,51,79,79,79,14,6,6,6,0,0,0,79,79,79,79,79,0,0,0,0,0,0
0,0,0,0,0,0,0,0,0,0,0,0,0,0,0,0,0,0,79,79,79,6,6,6,6,0,0,0,0,0,21,21,21,21,0,0,0,0,3
0,0,0,0,0,0,0,0,0,0,0,0,0,0,0,0,0,31,79,79,79,79,6,6,6,20,0,43,21,21,21,21,21,21,52,0,0,9,21
0,0,0,0,0,0,0,0,0,0,0,0,0,0,0,0,9,79,79,79,79,79,79,0,14,0,0,43,43,31,0,21,21,21,32,0,0,0,21
0,0,0,0,0,0,0,0,0,0,0,0,0,0,0,70,0,79,79,21,79,21,21,0,14,0,6,43,6,6,6,21,21,21,32,0,0,0,40
0,0,0,0,0,0,0,0,0,0,0,0,0,0,0,16,0,79,79,79,79,79,79,79,6,20,6,20,6,6,6,21,21,0,32,0,0,0,0
0,0,0,0,0,0,0,0,0,0,0,0,0,0,9,0,0,9,21,21,21,79,79,79,79,79,21,6,20,6,21,21,21,32,0,0,0,0,0
0,0,0,0,0,0,0,0,0,0,0,0,0,16,9,0,0,40,0,0,79,79,79,79,79,79,21,0,21,14,21,21,21,32,0,0,0,0,0
0,0,0,0,0,0,0,0,99,0,0,0,16,0,0,0,40,40,40,16,62,40,40,79,79,9,21,21,0,14,21,21,21,0,0,0,0,0,0
0,0,0,0,0,0,0,70,79,0,0,0,0,9,40,40,0,0,9,9,0,0,0,0,0,9,21,21,21,21,21,21,21,0,0,0,0,0,0
0,0,0,0,0,0,0,79,79,79,9,0,0,0,63,0,0,0,0,9,0,79,0,0,0,0,79,21,79,79,79,79,79,0,0,0,0,0,0
0,0,0,0,0,0,0,70,79,42,0,0,40,40,0,0,0,0,0,0,40,0,0,0,0,0,79,79,79,79,79,79,79,0,0,0,0,0,0
0,0,0,0,0,0,0,0,72,0,0,0,40,0,0,0,0,0,0,0,0,0,0,0,0,9,79,79,79,79,79,79,0,0,0,31,0,0,0
0,0,0,0,0,0,0,0,0,0,0,0,0,0,0,0,0,0,0,0,0,0,0,0,0,9,79,79,79,79,79,0,3,0,79,79,21,31,0
0,0,0,0,0,0,0,0,0,0,0,0,0,0,0,0,0,0,0,0,0,0,0,0,0,0,79,6,79,3,0,0,0,0,79,79,21,52,32
0,0,0,0,0,0,0,0,0,0,0,0,0,0,0,0,0,0,0,0,0,0,0,0,0,0,40,42,0,0,0,0,0,0,79,79,21,0,32
0,0,0,0,0,0,0,0,0,0,0,0,0,0,0,0,0,0,0,0,0,0,0,0,0,0,0,0,0,0,0,0,0,0,40,40,0,0,0
0,0,0,0,0,0,0,0,0,0,0,0,0,0,0,0,0,0,0,0,0,0,0,0,0,0,0,0,79,79,79,0,0,0,0,0,40,0,0
0,0,0,0,0,0,0,0,0,0,0,0,0,0,0,0,0,0,0,0,0,0,0,0,0,0,0,0,79,79,79,52,0,0,0,0,40,0,0
0,0,0,0,0,0,0,0,0,0,0,0,0,0,0,0,0,0,0,0,0,0,0,0,0,0,0,0,79,79,79,0,0,0,0,0,0,0,0
0,0,0,0,0,0,0,0,0,0,0,0,0,0,0,0,0,0,0,0,0,0,0,0,0,0,0,0,40,40,0,0,0,0,0,0,0,0,0
0,0,0,0,0,0,0,0,0,0,0,0,0,0,0,0,0,0,0,0,0,0,0,0,0,0,0,0,0,0,0,0,0,0,0,0,0,0,0
endlayer

layer
0,0,0,0,0,0,0,0,0,0,0,0,0,0,0,0,0,0,0,0,0,0,0,0,0,16,21,0,0,0,0,0,0,0,0,0,0,0,0
0,0,0,0,0,0,0,0,0,0,0,0,0,0,0,0,0,0,31,0,0,0,0,0,0,79,21,21,0,0,0,0,0,0,0,0,0,0,0
0,0,0,0,0,0,0,0,0,0,0,0,0,0,0,0,31,31,31,44,31,0,0,0,0,9,79,0,0,0,0,0,0,0,0,31,31,0,0
0,0,0,0,0,0,0,0,0,0,0,0,0,0,0,0,0,0,0,31,44,32,0,0,0,0,0,0,0,0,0,0,0,0,16,0,32,32,0
0,0,0,0,0,0,0,0,0,0,0,0,0,0,0,9,9,0,0,16,0,44,0,53,31,31,0,0,0,0,0,0,0,0,79,79,32,32,0
0,0,0,0,0,0,0,0,0,0,0,0,0,0,9,9,0,0,79,79,21,0,79,79,21,21,0,3,0,0,0,0,0,79,79,79,63,0,0
0,0,0,0,0,0,0,0,0,0,0,0,0,0,0,9,9,9,79,79,79,0,21,0,79,21,21,21,53,31,31,0,0,79,79,32,0,0,0
0,0,0,0,0,0,0,0,0,0,0,0,0,0,0,9,62,9,79,21,14,14,21,79,79,21,21,21,79,79,21,53,0,0,0,0,0,0,0
0,0,0,0,0,0,0,0,0,0,0,0,0,0,0,0,0,0,9,79,20,6,0,79,0,0,79,79,79,79,21,21,0,0,0,0,0,0,0
0,0,0,0,0,0,0,0,0,0,0,0,0,0,0,0,0,0,79,79,79,79,6,6,6,20,20,20,79,79,79,79,3,0,0,0,0,0,0
0,0,0,0,0,0,0,0,0,0,0,0,0,0,0,0,0,0,79,79,79,79,6,6,20,6,79,21,21,21,79,79,0,0,0,0,0,0,0
0,1,0,0,0,0,0,0,0,0,0,0,0,0,0,0,0,99,79,79,79,79,79,14,6,20,20,20,79,79,79,79,79,32,0,0,0,9,21
0,0,0,0,0,0,0,0,0,0,0,0,0,0,0,0,99,79,79,79,79,79,79,14,14,6,20,20,21,21,79,79,79,79,32,0,0,0,40
0,0,0,0,0,0,0,0,0,0,0,0,0,0,0,70,79,79,21,21,79,79,79,0,6,14,20,20,20,6,79,79,79,79,0,0,0,0,0
0,0,0,0,0,0,0,0,0,0,0,0,0,0,0,16,79,79,79,79,79,79,79,79,6,6,6,20,6,6,6,0,79,79,32,0,0,0,0
0,0,0,0,0,0,0,0,0,0,0,0,0,0,9,51,79,79,21,21,79,79,79,79,79,79,79,6,6,6,79,79,31,86,0,0,0,0,0
0,0,0,0,0,0,0,0,0,0,0,0,0,16,9,0,0,40,21,0,42,79,79,79,79,79,79,79,79,0,79,42,79,32,0,0,0,0,0
0,0,0,0,0,0,0,0,0,0,0,0,16,0,0,0,40,40,40,16,9,0,21,21,79,9,79,21,79,79,79,79,0,0,0,0,0,0,0
0,0,0,0,0,0,0,31,79,0,0,16,0,9,40,40,0,0,9,9,0,0,0,79,0,9,79,79,79,79,21,3,0,0,0,0,0,0,0
0,0,0,0,0,0,51,79,79,79,9,0,0,0,63,0,0,0,0,9,0,79,0,42,0,51,79,79,79,79,21,0,0,0,0,0,0,0,0
0,0,0,0,0,0,0,40,79,0,0,40,40,40,0,0,0,0,0,0,40,0,0,0,0,0,79,79,79,79,21,0,0,0,0,0,0,0,0
0,0,0,0,0,0,0,0,72,0,0,0,40,0,0,0,0,0,0,0,0,0,0,0,0,9,79,79,79,79,79,0,0,0,0,0,0,0,0
0,0,0,0,0,0,0,0,0,0,0,0,0,0,0,0,0,0,0,0,0,0,0,0,0,51,79,79,42,79,0,0,0,0,0,79,31,31,0
0,0,0,0,0,0,0,0,0,0,0,0,0,0,0,0,0,0,0,0,0,0,0,0,0,0,40,79,0,42,0,0,0,0,79,79,21,32,32
0,0,0,0,0,0,0,0,0,0,0,0,0,0,0,0,0,0,0,0,0,0,0,0,0,0,0,0,0,0,0,0,0,0,3,79,79,52,32
0,0,0,0,0,0,0,0,0,0,0,0,0,0,0,0,0,0,0,0,0,0,0,0,0,0,0,0,0,0,0,0,0,0,0,40,0,0,0
0,0,0,0,0,0,0,0,0,0,0,0,0,0,0,0,0,0,0,0,0,0,0,0,0,0,0,0,0,79,0,0,0,0,0,0,40,0,0
0,0,0,0,0,0,0,0,0,0,0,0,0,0,0,0,0,0,0,0,0,0,0,0,0,0,0,0,79,79,79,0,0,0,0,0,40,0,0
0,0,0,0,0,0,0,0,0,0,0,0,0,0,0,0,0,0,0,0,0,0,0,0,0,0,0,0,0,79,0,0,0,0,0,0,0,0,0
0,0,0,0,0,0,0,0,0,0,0,0,0,0,0,0,0,0,0,0,0,0,0,0,0,0,0,0,0,0,0,0,0,0,0,0,0,0,0
0,0,0,0,0,0,0,0,0,0,0,0,0,0,0,0,0,0,0,0,0,0,0,0,0,0,0,0,0,0,0,0,0,0,0,0,0,0,0
endlayer

layer
0,0,0,0,0,0,0,0,0,0,0,0,0,0,0,0,0,0,0,0,0,0,0,0,0,16,21,0,0,0,0,0,0,0,0,0,0,0,0
0,0,0,0,0,0,0,0,0,0,0,0,0,0,0,0,0,0,31,0,0,0,0,0,0,79,21,79,0,0,0,0,0,0,0,0,0,0,0
0,0,0,0,0,0,0,0,0,0,0,0,0,0,0,0,31,31,31,44,31,0,0,0,0,9,79,0,0,0,0,0,0,0,0,31,31,0,0
0,0,0,0,0,0,0,0,0,0,0,0,0,0,0,0,0,0,0,31,44,32,0,0,0,0,0,0,0,0,0,0,0,0,16,0,32,32,0
0,0,0,0,0,0,0,0,0,0,0,0,0,0,0,9,9,0,0,16,79,44,0,31,0,0,0,0,0,0,0,0,0,0,79,79,32,32,0
0,0,0,0,0,0,0,0,0,0,0,0,0,0,9,9,0,51,79,79,79,79,32,79,31,3,0,0,0,0,0,0,0,3,79,79,63,0,0
0,0,0,0,0,0,0,0,0,0,0,0,0,0,0,9,9,0,79,79,14,0,79,79,79,31,31,31,0,0,0,0,0,0,3,0,0,0,0
0,0,0,0,0,0,0,0,0,0,0,0,0,0,0,9,62,9,79,20,6,79,79,79,79,79,21,21,79,79,32,0,0,0,0,0,0,0,0
0,0,0,0,0,0,0,0,0,0,0,0,0,0,0,0,0,0,9,79,79,79,79,79,14,79,79,79,79,79,86,0,0,0,0,0,0,0,0
0,0,0,0,0,0,0,0,0,0,0,0,0,0,0,0,0,0,40,79,79,62,79,20,20,20,79,79,79,79,86,0,0,0,0,0,0,0,0
0,0,0,0,0,0,0,0,0,0,0,0,0,0,0,0,0,0,0,21,21,21,14,20,20,14,79,79,79,79,79,3,0,0,0,0,0,0,0
0,0,0,0,0,0,0,0,0,0,0,0,0,0,0,0,0,99,0,21,21,21,79,14,14,14,6,79,0,79,79,3,0,0,0,0,0,9,21
0,0,0,0,0,0,0,0,0,0,0,0,0,0,0,0,9,79,21,21,21,21,21,14,14,14,20,6,44,79,79,79,3,0,0,0,0,0,40
0,0,0,0,0,0,0,0,0,0,0,0,0,0,0,0,79,21,21,21,21,79,21,21,79,14,6,6,6,79,79,79,3,0,0,0,0,0,0
0,0,0,0,0,0,0,0,0,0,0,0,0,0,0,16,79,79,79,79,79,79,21,21,21,21,79,6,6,20,20,79,79,52,0,0,0,0,0
0,0,0,0,0,0,0,0,0,0,0,0,0,0,9,9,79,79,79,9,79,79,21,21,21,21,79,79,14,79,79,32,0,86,0,0,0,0,0
0,0,0,0,0,0,0,0,0,0,0,0,0,16,9,0,0,79,0,0,78,21,21,21,21,21,79,79,79,79,79,0,0,32,0,0,0,0,0
0,0,0,0,0,0,0,0,0,0,0,0,16,0,0,0,40,40,0,16,9,21,21,21,21,0,0,107,21,79,0,79,0,0,0,0,0,0,0
0,0,0,0,0,0,0,31,79,0,0,16,0,9,40,40,0,0,9,9,0,42,21,21,0,0,0,107,21,79,79,79,0,0,0,0,0,0,0
0,0,0,0,0,0,70,79,79,79,9,0,0,0,63,0,0,0,0,9,0,0,42,0,0,0,3,107,21,79,32,0,0,0,0,0,0,0,0
0,0,0,0,0,0,0,72,79,42,0,40,40,40,0,0,0,0,0,0,40,0,0,0,0,0,0,30,79,21,79,0,0,0,0,0,0,0,0
0,0,0,0,0,0,0,0,0,0,0,0,40,0,0,0,0,0,0,0,0,0,1,0,0,0,3,0,40,79,32,0,0,0,0,0,0,0,0
0,0,0,0,0,0,0,0,0,0,0,0,0,0,0,0,0,0,0,0,0,0,0,0,0,0,0,0,0,0,0,0,0,0,0,79,0,31,0
0,0,0,0,0,0,0,0,0,0,0,0,0,0,0,0,0,0,0,0,0,0,0,0,0,0,0,0,0,0,0,0,0,0,79,79,79,32,32
0,0,0,0,0,0,0,0,0,0,0,0,0,0,0,0,0,0,0,0,0,0,0,0,0,0,0,0,0,0,0,0,0,0,0,79,79,79,32
0,0,0,0,0,0,0,0,0,0,0,0,0,0,0,0,0,0,0,0,0,0,0,0,0,0,0,0,0,0,0,0,0,0,0,0,79,0,0
0,0,0,0,0,0,0,0,0,0,0,0,0,0,0,0,0,0,0,0,0,0,0,0,0,0,0,0,0,79,0,0,0,0,0,0,40,0,0
0,0,0,0,0,0,0,0,0,0,0,0,0,0,0,0,0,0,0,0,0,0,0,0,0,0,0,0,79,79,79,0,0,0,0,0,40,0,0
0,0,0,0,0,0,0,0,0,0,0,0,0,0,0,0,0,0,0,0,0,0,0,0,0,0,0,0,42,79,0,0,0,0,0,0,0,0,0
0,0,0,0,0,0,0,0,0,0,0,0,0,0,0,0,0,0,0,0,0,0,0,0,0,0,0,0,0,0,0,0,0,0,0,0,0,0,0
0,0,0,0,0,0,0,0,0,0,0,0,0,0,0,0,0,0,0,0,0,0,0,0,0,0,0,0,0,0,0,0,0,0,0,0,0,0,0
endlayer

layer
0,0,0,0,0,0,0,0,0,0,0,0,0,0,0,0,0,0,0,0,0,0,0,0,0,9,79,0,0,0,0,0,0,0,0,0,0,0,0
0,0,0,0,0,0,0,0,0,0,0,0,0,0,0,0,0,0,31,0,0,0,0,0,0,9,79,52,0,0,0,0,0,0,0,0,0,0,0
0,0,0,0,0,0,0,0,0,0,0,0,0,0,0,0,31,31,31,44,31,0,0,0,0,9,79,0,0,0,0,0,0,0,0,31,31,0,0
0,0,0,0,0,0,0,0,0,0,0,0,0,0,0,0,0,0,0,31,44,32,0,0,0,0,0,0,0,0,0,0,0,0,16,79,32,32,0
0,0,0,0,0,0,0,0,0,0,0,0,0,0,0,9,9,0,79,31,79,32,0,0,0,0,0,0,0,0,0,0,0,51,79,79,79,32,0
0,0,0,0,0,0,0,0,0,0,0,0,0,0,9,9,0,31,79,79,79,32,32,0,0,0,0,0,0,0,0,0,0,9,79,79,40,0,0
0,0,0,0,0,0,0,0,0,0,0,0,0,0,0,9,9,21,79,14,79,79,0,0,0,0,0,0,0,0,0,0,0,0,0,0,0,0,0
0,0,0,0,0,0,0,0,0,0,0,0,0,0,0,9,62,0,79,20,6,79,79,79,79,0,0,3,31,31,0,0,0,0,0,0,0,0,0
0,0,0,0,0,0,0,0,0,0,0,0,0,0,0,0,0,0,79,79,79,79,79,79,79,0,31,79,79,79,86,0,0,0,0,0,0,0,0
0,0,0,0,0,0,0,0,0,0,0,0,0,0,0,0,0,0,40,0,0,40,9,79,79,79,79,79,79,79,52,0,0,0,0,0,0,0,0
0,0,0,0,0,0,0,0,0,0,0,0,0,0,0,0,0,0,0,0,0,9,79,79,79,79,31,31,79,79,0,0,0,0,0,0,0,0,0
0,0,0,0,0,0,0,0,0,0,0,0,0,0,0,0,0,0,0,0,0,0,40,79,79,6,6,79,79,79,79,0,0,0,0,0,0,9,79
0,0,0,0,0,0,0,0,0,0,0,0,0,0,0,0,0,99,3,0,0,53,79,21,79,6,6,6,44,79,79,86,0,0,0,0,0,0,40
0,0,0,0,0,0,0,0,0,0,0,0,0,0,0,0,31,79,21,0,0,79,79,21,79,79,6,6,6,0,79,0,99,0,0,0,0,0,0
0,0,0,0,0,0,0,0,0,0,0,0,0,0,0,16,21,21,79,0,9,79,79,79,21,21,79,6,6,0,79,0,79,86,0,0,0,0,0
0,0,0,0,0,0,0,0,0,0,0,0,0,0,9,79,79,21,0,0,0,0,79,79,79,21,79,79,79,79,79,32,0,86,0,0,0,0,0
0,0,0,0,0,0,0,0,0,0,0,0,0,16,9,79,79,42,0,0,16,9,21,79,79,0,79,79,79,79,79,0,0,32,0,0,0,0,0
0,0,0,0,0,0,0,0,0,0,0,0,16,0,0,0,40,0,0,16,9,21,21,21,0,0,42,0,21,79,0,0,0,0,0,0,0,0,0
0,0,0,0,0,0,0,0,0,0,0,16,0,9,40,40,0,0,9,9,0,21,21,0,0,0,0,0,21,79,0,0,0,0,0,0,0,0,0
0,0,0,0,0,0,0,9,79,3,9,0,0,0,63,0,0,0,0,9,0,0,0,0,0,0,0,51,21,79,32,0,0,0,0,0,0,0,0
0,0,0,0,0,0,0,0,40,0,0,40,40,40,0,0,0,0,0,0,40,0,0,0,0,0,0,9,79,21,79,0,0,0,0,0,0,0,0
0,0,0,0,0,0,0,0,0,0,0,0,40,0,0,0,0,0,0,0,0,0,1,0,0,0,0,0,40,79,32,0,0,0,0,0,0,0,0
0,0,0,0,0,0,0,0,0,0,0,0,0,0,0,0,0,0,0,0,0,0,0,0,0,0,0,0,0,0,0,0,0,0,0,0,0,31,0
0,0,0,0,0,0,0,0,0,0,0,0,0,0,0,0,0,0,0,0,0,0,0,0,0,0,0,0,0,0,0,0,0,0,0,79,79,79,32
0,0,0,0,0,0,0,0,0,0,0,0,0,0,0,0,0,0,0,0,0,0,0,0,0,0,0,0,0,0,0,0,0,0,51,21,21,79,32
0,0,0,0,0,0,0,0,0,0,0,0,0,0,0,0,0,0,0,0,0,0,0,0,0,0,0,0,0,0,0,0,0,0,0,79,21,79,0
0,0,0,0,0,0,0,0,0,0,0,0,0,0,0,0,0,0,0,0,0,0,0,0,0,0,0,0,0,31,0,0,0,0,0,42,0,0,0
0,0,0,0,0,0,0,0,0,0,0,0,0,0,0,0,0,0,0,0,0,0,0,0,0,0,0,0,9,79,52,0,0,0,0,0,40,0,0
0,0,0,0,0,0,0,0,0,0,0,0,0,0,0,0,0,0,0,0,0,0,0,0,0,0,0,0,0,40,0,0,0,0,0,0,0,0,0
0,0,0,0,0,0,0,0,0,0,0,0,0,0,0,0,0,0,0,0,0,0,0,0,0,0,0,0,0,0,0,0,0,0,0,0,0,0,0
0,0,0,0,0,0,0,0,0,0,0,0,0,0,0,0,0,0,0,0,0,0,0,0,0,0,0,0,0,0,0,0,0,0,0,0,0,0,0
endlayer

layer
0,0,0,0,0,0,0,0,0,0,0,0,0,0,0,0,0,0,0,0,0,0,0,0,0,0,31,0,0,0,0,0,0,0,0,0,0,0,0
0,0,0,0,0,0,0,0,0,0,0,0,0,0,0,0,0,0,31,0,0,0,0,0,0,9,79,32,0,0,0,0,0,0,0,0,0,0,0
0,0,0,0,0,0,0,0,0,0,0,0,0,0,0,0,31,31,31,44,31,0,0,0,0,9,79,0,0,0,0,0,0,0,0,31,31,0,0
0,0,0,0,0,0,0,0,0,0,0,0,0,0,0,0,0,53,0,31,32,32,0,0,0,0,0,0,0,0,0,0,0,0,9,79,32,32,0
0,0,0,0,0,0,0,0,0,0,0,0,0,0,0,9,9,79,21,79,0,0,0,0,0,0,0,0,0,0,0,0,0,9,79,79,79,32,0
0,0,0,0,0,0,0,0,0,0,0,0,0,0,9,9,0,79,14,79,79,32,32,0,0,0,0,0,0,0,0,0,0,0,79,79,0,0,0
0,0,0,0,0,0,0,0,0,0,0,0,0,0,0,9,9,21,20,6,79,32,0,0,0,0,0,0,0,0,0,0,0,0,0,42,0,0,0
0,0,0,0,0,0,0,0,0,0,0,0,0,0,0,9,62,79,79,79,32,32,0,0,0,0,0,0,31,31,0,0,0,0,0,0,0,0,0
0,0,0,0,0,0,0,0,0,0,0,0,0,0,0,0,0,0,3,0,40,0,0,79,0,0,0,31,79,79,86,0,0,0,0,0,0,0,0
0,0,0,0,0,0,0,0,0,0,0,0,0,0,0,0,0,0,40,0,0,0,0,0,0,0,0,79,79,79,32,0,0,0,0,0,0,0,0
0,0,0,0,0,0,0,0,0,0,0,0,0,0,0,0,0,0,0,0,0,0,0,79,79,79,79,79,79,72,0,0,0,0,0,0,0,0,0
0,0,0,0,0,0,0,0,0,0,0,0,0,0,0,0,0,0,0,0,0,0,51,79,79,79,6,79,79,0,0,0,0,0,0,0,0,9,79
0,0,0,0,0,0,0,0,0,0,0,0,0,0,0,0,0,0,0,0,0,0,9,21,79,6,6,6,0,79,0,0,0,0,0,0,0,0,40
0,0,0,0,0,0,0,0,0,0,0,0,0,0,0,0,31,31,0,0,0,9,79,79,79,79,6,6,6,0,0,0,0,0,0,0,0,0,0
0,0,0,0,0,0,0,0,0,0,0,0,0,0,0,16,21,21,0,0,0,9,79,79,79,21,79,6,79,0,79,0,79,86,0,0,0,0,0
0,0,0,0,0,0,0,0,0,0,0,0,0,0,9,21,21,21,0,0,0,0,0,79,79,79,79,79,0,79,79,0,79,86,0,0,0,0,0
0,0,0,0,0,0,0,0,0,0,0,0,0,16,61,79,21,0,0,0,16,21,21,79,0,0,3,0,79,79,86,0,79,32,0,0,0,0,0
0,0,0,0,0,0,0,0,0,0,0,0,16,0,0,79,40,0,0,16,9,21,21,21,0,0,0,0,0,0,0,0,0,0,0,0,0,0,0
0,0,0,0,0,0,0,0,53,0,0,16,0,9,40,40,0,0,9,9,79,79,21,79,0,1,0,0,3,0,0,0,0,0,0,0,0,0,0
0,0,0,0,0,0,0,9,79,0,9,0,0,0,63,0,0,0,0,9,42,79,0,0,0,0,0,0,0,79,32,0,0,0,0,0,0,0,0
0,0,0,0,0,0,0,0,40,0,0,40,40,40,0,0,0,0,0,0,40,0,0,0,0,1,0,0,79,21,79,52,0,0,0,0,0,0,0
0,0,0,0,0,0,0,0,0,0,0,0,40,0,0,0,0,0,0,0,0,0,0,0,0,0,0,0,40,79,32,0,0,0,0,0,0,0,0
0,0,0,0,0,0,0,0,0,0,0,0,0,0,0,0,0,0,0,0,0,0,0,0,0,0,0,0,0,0,0,0,0,0,0,0,53,31,0
0,0,0,0,0,0,0,0,0,0,0,0,0,0,0,0,0,0,0,0,0,0,0,0,0,0,0,0,0,0,0,0,0,0,0,79,79,79,32
0,0,0,0,0,0,0,0,0,0,0,0,0,0,0,0,0,0,0,0,0,0,0,0,0,0,0,0,0,0,0,0,0,0,0,21,21,79,79
0,0,0,0,0,0,0,0,0,0,0,0,0,0,0,0,0,0,0,0,0,0,0,0,0,0,0,0,0,0,0,0,0,0,0,79,21,79,42
0,0,0,0,0,0,0,0,0,0,0,0,0,0,0,0,0,0,0,0,0,0,0,0,0,0,0,0,0,31,0,0,0,0,0,0,79,0,0
0,0,0,0,0,0,0,0,0,0,0,0,0,0,0,0,0,0,0,0,0,0,0,0,0,0,0,0,9,79,32,0,0,0,0,0,40,0,0
0,0,0,0,0,0,0,0,0,0,0,0,0,0,0,0,0,0,0,0,0,0,0,0,0,0,0,0,0,40,0,0,0,0,0,0,0,0,0
0,0,0,0,0,0,0,0,0,0,0,0,0,0,0,0,0,0,0,0,0,1,0,0,0,0,0,0,0,0,0,0,0,0,0,0,0,0,0
0,0,0,0,0,0,0,0,0,0,0,0,0,0,0,0,0,0,0,0,0,0,0,0,0,0,0,0,0,0,0,0,0,0,0,0,0,0,0
endlayer

layer
0,0,0,0,0,0,0,0,0,0,0,0,0,0,0,0,0,0,0,0,0,0,0,0,0,0,31,0,0,0,0,0,0,0,0,0,0,0,0
0,0,0,0,0,0,0,0,0,0,0,0,0,0,0,0,0,0,31,0,0,0,0,0,0,9,79,32,0,0,0,0,0,0,0,0,0,0,0
0,0,0,0,0,0,0,0,0,0,0,0,0,0,0,0,31,31,31,44,31,0,0,0,0,9,79,0,0,0,0,0,0,0,0,53,31,0,0
0,0,0,0,0,0,0,0,0,0,0,0,0,0,0,0,0,16,0,31,32,32,0,0,0,0,0,0,0,0,0,0,0,0,9,79,79,32,0
