
# Created by Ruins mod version 14.6 Ingame Parser
# authoring Player: ArchNihil

weight=1
embed_into_distance=0
acceptable_target_blocks=
unacceptable_target_blocks=flowing_water,water,flowing_lava,lava
dimensions=16,12,12
allowable_overhang=0
max_leveling=2
leveling_buffer=0
preserve_water=0
preserve_lava=0

rule1=0,100,Railcraft:tile.railcraft.residual.heat-0
rule2=0,100,minecraft:log-0
rule3=0,100,ChestGenHook:dungeonChest:5-3
rule4=0,100,minecraft:log-8
rule5=0,100,minecraft:log-4
rule6=0,100,minecraft:leaves-12
rule7=0,100,minecraft:leaves-4

layer
0,1,1,0,0,1,1,1,0,0,0,1
0,1,1,1,0,1,0,0,1,1,0,0
0,1,1,0,0,0,1,0,1,0,0,0
0,0,0,0,0,1,0,0,0,0,1,0
1,1,0,0,1,2,0,0,0,1,1,1
1,0,1,0,2,2,2,0,0,0,1,0
0,1,1,4,2,3,2,2,0,0,0,0
1,0,1,1,2,2,2,0,0,1,1,0
1,1,0,0,0,5,0,0,0,0,1,0
0,0,0,1,1,0,0,0,0,0,1,0
1,1,1,0,0,0,0,1,0,0,1,0
0,1,1,0,1,1,1,1,0,0,0,0
endlayer

layer
0,0,0,0,0,0,0,0,0,0,0,0
0,0,0,0,0,0,0,0,0,0,0,1
0,0,0,0,0,0,0,0,0,0,0,0
0,0,0,0,0,0,0,0,0,0,0,0
0,0,0,0,0,0,0,0,0,0,0,0
0,0,0,5,2,2,2,1,0,0,0,0
0,0,1,0,2,0,2,1,0,0,0,0
0,0,0,0,2,2,2,1,0,0,0,1
0,0,0,0,0,0,0,0,0,0,0,0
0,0,0,0,0,0,0,0,0,0,0,0
0,0,0,0,0,0,0,0,0,0,0,0
0,0,0,0,0,0,0,0,0,0,0,0
endlayer

layer
0,0,0,0,0,0,0,0,0,0,0,0
0,1,0,0,0,0,0,0,0,0,0,0
0,0,0,0,0,6,0,0,0,0,0,0
0,0,0,6,0,6,6,0,0,0,0,0
0,0,0,6,0,0,6,6,0,0,0,0
0,0,6,6,2,2,2,0,0,0,0,1
0,0,6,6,2,0,2,0,0,0,0,0
0,0,6,6,2,2,2,0,0,0,0,0
0,0,0,0,0,6,0,0,0,0,0,0
0,0,0,0,0,0,0,0,0,0,0,0
0,0,0,0,0,0,0,0,0,0,0,0
0,0,0,0,0,0,0,0,0,0,0,0
endlayer

layer
0,0,0,0,0,0,0,0,0,0,0,0
0,0,0,0,0,0,0,0,0,0,0,0
1,0,0,0,0,6,6,6,0,0,0,0
0,0,0,6,6,6,5,6,0,0,0,0
0,1,0,6,5,0,5,6,0,0,0,0
0,0,6,6,5,2,2,6,0,0,0,0
0,0,6,6,2,0,2,6,6,0,0,0
0,0,6,6,6,2,2,6,6,6,0,0
0,0,6,6,6,6,6,0,0,0,0,0
0,0,0,6,6,6,0,0,0,0,0,0
0,0,0,0,0,6,0,0,0,1,0,0
0,0,0,0,0,0,0,0,0,0,0,0
endlayer

layer
0,1,0,0,0,0,0,0,0,0,0,0
0,1,0,0,0,0,0,0,1,0,0,0
1,0,0,0,0,7,6,1,0,0,0,0
0,0,1,6,6,6,2,6,6,0,1,0
0,0,6,6,2,6,6,6,0,0,0,0
0,0,6,6,6,2,6,6,0,0,0,0
0,0,6,4,2,0,2,4,6,6,7,0
0,0,6,6,5,2,2,4,6,6,0,0
0,0,6,6,5,6,6,6,6,0,0,0
0,0,0,6,6,6,6,6,0,1,0,0
0,0,0,0,0,7,6,0,1,0,0,0
0,0,0,1,0,0,0,1,0,0,0,0
endlayer

layer
0,0,0,0,0,0,0,0,0,0,0,0
0,0,0,0,0,0,0,0,1,0,0,0
0,1,0,0,0,7,6,0,0,0,0,0
0,0,0,7,7,7,6,6,6,7,0,0
0,1,6,7,7,7,7,7,7,7,7,0
0,6,5,7,7,2,7,7,6,7,7,0
0,6,4,2,2,0,2,2,4,4,7,0
0,6,6,6,6,2,0,2,7,6,0,0
0,0,7,4,2,7,0,7,7,6,0,0
0,0,0,6,6,7,7,7,0,0,0,1
0,1,0,0,7,6,7,6,0,0,0,0
1,0,0,0,0,0,0,0,0,0,0,0
endlayer

layer
0,0,0,0,0,1,0,1,0,0,0,0
0,0,0,0,0,0,0,0,1,0,0,0
0,0,0,0,7,7,7,7,0,0,0,0
0,1,0,7,7,7,6,6,7,1,0,0
0,0,6,0,7,7,7,7,7,7,0,0
0,6,2,0,7,2,7,7,6,7,7,0
0,6,6,7,2,0,2,7,6,6,6,0
0,6,6,7,7,2,0,5,7,6,6,0
0,1,6,7,7,7,0,5,0,6,6,0
1,0,0,7,0,7,7,7,7,0,7,0
0,0,0,6,6,6,6,6,0,0,1,0
0,1,0,0,0,0,0,0,0,0,0,0
endlayer

layer
0,0,0,0,0,1,0,0,0,0,0,0
0,0,0,0,1,1,0,0,0,0,0,0
1,0,1,0,6,7,6,0,6,1,1,0
0,0,7,7,7,7,7,7,7,1,0,0
0,6,7,7,7,7,7,7,7,7,1,0
0,6,7,7,7,2,2,7,7,7,1,0
0,7,7,7,2,4,2,7,7,7,0,0
0,6,6,7,7,2,7,7,6,7,0,1
0,0,6,7,7,5,7,2,4,6,0,0
0,0,0,7,7,7,7,7,7,7,0,0
0,0,0,6,6,6,7,7,0,0,0,0
1,1,0,1,0,7,7,0,0,0,0,0
endlayer

layer
0,0,1,1,1,0,0,0,0,0,0,0
1,0,0,0,0,0,0,0,0,0,0,0
0,0,0,0,7,6,7,6,0,1,0,0
0,0,7,7,7,7,6,7,7,0,0,0
0,6,7,7,7,7,5,4,7,0,0,1
0,6,7,7,7,2,2,7,7,7,0,0
0,7,7,7,7,2,7,7,7,7,1,1
0,6,6,7,7,5,7,7,7,7,0,0
1,0,6,4,4,5,7,6,7,7,0,0
0,0,6,7,0,5,7,6,6,0,0,0
0,0,0,6,6,6,7,7,0,0,1,0
0,1,0,0,0,7,7,0,0,1,0,1
endlayer

layer
0,0,0,0,0,0,0,0,0,0,0,0
0,0,0,0,0,0,0,0,0,0,0,0
0,0,0,1,6,7,7,6,7,1,0,0
0,0,7,7,7,7,7,5,7,0,0,0
0,7,7,7,5,7,0,2,7,0,0,0
0,7,7,7,4,2,0,7,7,0,1,0
0,7,6,7,7,2,7,7,7,7,1,0
0,1,6,7,0,0,7,7,7,7,0,1
0,1,6,7,0,7,7,7,7,7,0,0
0,1,6,7,7,2,7,6,6,0,0,0
1,0,0,7,7,5,7,6,0,0,0,1
0,0,0,1,0,7,7,0,1,0,1,1
endlayer

layer
0,0,0,0,0,1,0,0,0,0,0,0
0,1,0,0,0,0,0,7,0,0,0,0
0,0,1,1,7,7,7,7,7,1,0,0
1,0,7,7,7,7,7,7,7,0,0,1
0,1,7,4,2,7,7,7,7,0,0,0
0,1,6,7,7,7,0,7,7,7,0,0
0,0,6,7,1,2,7,7,7,0,0,1
0,0,6,7,7,2,7,7,7,7,0,0
0,0,6,0,0,7,7,7,7,0,0,0
0,0,6,7,7,7,7,6,6,0,0,1
0,0,0,7,7,7,7,6,0,0,0,0
0,0,0,0,0,7,7,0,0,0,0,0
endlayer

layer
0,0,0,0,0,0,0,0,0,0,0,0
0,0,0,0,0,0,0,0,0,0,0,0
0,0,1,6,7,7,0,0,7,0,0,0
0,0,7,7,7,7,7,7,7,0,0,1
0,0,7,7,7,7,7,7,7,1,0,0
0,0,7,7,7,7,7,7,7,0,0,0
0,0,7,4,4,2,4,7,7,1,0,0
1,0,6,7,7,5,7,7,7,1,1,0
0,0,6,0,7,5,7,7,7,7,0,0
0,0,6,6,7,7,7,6,6,0,0,0
0,0,0,6,7,7,7,6,0,0,0,0
1,0,0,0,0,7,0,0,0,0,0,0
endlayer

layer
0,0,0,0,0,0,0,0,0,0,0,0
0,0,0,0,0,1,0,0,0,0,0,0
0,0,0,7,7,1,1,0,1,0,0,0
1,0,0,6,7,7,7,0,0,0,0,1
0,0,7,7,7,7,5,7,7,0,0,0
0,0,6,6,7,7,5,7,7,1,0,0
0,0,7,7,7,2,2,7,7,0,0,0
0,0,7,7,7,7,7,7,7,7,1,0
0,1,6,7,7,2,4,4,7,7,0,0
0,0,6,7,7,7,7,7,6,6,1,0
0,0,0,0,7,7,0,0,6,0,0,0
0,1,0,0,1,0,0,0,0,1,0,0
endlayer

layer
0,0,1,0,0,0,0,0,0,0,0,0
0,0,0,0,0,0,0,0,0,0,0,0
0,1,0,1,0,0,0,0,1,0,1,0
0,0,0,6,7,0,0,1,0,0,0,0
1,0,0,6,7,7,7,0,0,0,0,0
0,0,0,7,7,0,7,7,0,0,0,1
0,0,0,7,7,2,7,7,7,0,0,0
0,0,7,7,0,7,0,7,7,0,0,0
0,0,0,7,7,7,7,7,7,7,0,0
0,0,0,0,7,7,7,0,6,6,1,0
0,0,0,0,0,0,6,0,6,0,0,0
0,0,0,0,0,0,0,0,0,0,0,0
endlayer

layer
0,0,0,0,0,0,0,0,0,0,0,0
0,0,0,0,0,0,0,0,0,0,0,0
0,0,0,0,0,0,0,0,0,0,0,0
0,0,0,1,0,0,0,0,0,0,0,0
0,0,0,6,7,1,7,0,0,0,0,0
0,0,1,6,7,0,7,0,0,0,0,0
0,0,0,0,7,1,7,0,0,0,0,0
0,0,0,0,0,7,0,0,7,0,0,0
0,0,0,0,0,7,0,0,7,0,0,0
0,0,0,0,0,0,0,0,0,0,0,0
0,1,0,0,0,0,0,0,0,0,0,0
0,0,0,0,0,0,0,0,0,0,0,0
endlayer

layer
0,0,0,0,0,0,0,0,0,0,0,0
0,0,0,0,0,0,0,0,0,0,0,0
0,0,0,0,0,0,0,0,0,0,0,0
0,0,0,0,0,0,0,0,0,0,0,0
0,0,0,0,0,0,0,0,0,0,0,0
0,0,0,0,0,0,7,0,0,0,0,0
0,0,0,0,0,0,0,0,0,0,0,0
0,0,0,0,0,0,0,1,0,0,0,0
0,0,0,0,0,0,0,0,0,0,0,0
0,0,0,0,0,0,0,0,0,0,0,0
0,0,0,0,0,0,0,0,0,0,0,0
0,0,0,0,0,0,0,0,0,0,0,0
endlayer

