
# Created by Ruins mod version 14.6 Ingame Parser
# authoring Player: ArchNihil

weight=1
embed_into_distance=0
acceptable_target_blocks=
unacceptable_target_blocks=flowing_water,water,flowing_lava,lava
dimensions=9,16,28
allowable_overhang=0
max_leveling=2
leveling_buffer=0
preserve_water=0
preserve_lava=0

rule1=0,100,minecraft:planks-5
rule2=0,100,minecraft:log-9
rule3=0,100,Railcraft:tile.railcraft.residual.heat-0
rule4=0,100,RedLogic:redlogic.wire-0
rule5=0,100,minecraft:sticky_piston-5
rule6=0,100,ChestGenHook:dungeonChest:5-5
rule7=0,100,minecraft:tripwire_hook-7
rule8=0,100,minecraft:wooden_slab-5
rule9=0,100,minecraft:tripwire-4
rule10=0,100,minecraft:tripwire-0
rule11=0,100,minecraft:tripwire_hook-5
rule12=0,100,ChestGenHook:dungeonChest:5-4
rule13=0,100,minecraft:sticky_piston-4
rule14=0,100,TConstruct:GlassBlock-0
rule15=0,100,minecraft:redstone_lamp-0
rule16=0,100,minecraft:unpowered_repeater-14
rule17=0,100,minecraft:unpowered_repeater-12

layer
0,0,0,0,0,0,0,0,0,0,0,0,0,0,0,0,0,0,0,0,0,0,0,0,0,0,0,0
0,0,0,0,1,2,2,2,2,2,2,2,2,2,2,2,2,2,2,2,2,2,2,2,1,0,0,0
0,0,0,0,1,0,0,0,0,1,0,3,3,3,1,3,3,0,0,1,0,0,0,0,1,0,0,0
0,0,0,0,1,0,0,0,0,1,0,0,3,3,1,0,3,0,0,1,0,0,0,0,0,0,0,0
0,0,0,0,4,4,4,4,4,4,4,4,4,1,5,1,4,4,4,4,4,4,4,4,4,0,0,0
0,0,0,0,2,2,2,2,2,2,2,2,2,2,6,2,2,2,2,2,2,2,2,2,2,0,0,0
0,0,0,0,7,0,0,0,0,7,0,0,0,8,1,8,0,3,0,7,0,0,0,0,7,0,0,0
0,0,3,3,10,0,3,3,3,9,3,0,3,8,1,8,3,3,3,9,3,0,3,0,9,0,3,3
0,0,0,3,9,0,3,0,3,10,3,0,3,8,1,8,0,3,3,10,0,3,3,0,10,3,3,3
0,0,0,0,11,0,0,0,0,11,3,0,0,8,1,8,0,0,0,11,0,0,0,0,11,0,0,3
0,0,0,0,2,2,2,2,2,2,2,2,2,2,12,2,2,2,2,2,2,2,2,2,2,0,0,0
0,0,0,0,4,4,4,4,4,4,4,4,4,1,13,1,4,4,4,4,4,4,4,4,4,0,0,0
0,0,0,0,1,0,0,0,0,1,0,3,0,0,1,3,3,0,0,1,0,0,0,0,1,0,0,0
0,0,0,0,1,0,0,3,0,1,0,0,3,0,1,0,0,3,0,1,0,0,0,0,1,0,0,0
0,0,0,0,1,2,2,2,2,2,2,2,2,2,2,2,2,2,2,2,2,2,2,2,1,0,0,0
0,0,0,0,0,0,0,0,0,0,0,0,0,0,0,0,0,0,0,0,0,0,0,0,0,0,0,0
endlayer

layer
0,0,0,0,0,0,0,0,0,0,0,0,0,0,0,0,0,0,0,0,0,0,0,0,0,0,0,0
0,0,0,0,1,14,14,14,14,1,14,14,14,14,1,14,14,14,14,1,14,14,14,14,1,0,0,0
0,0,0,0,1,0,0,0,0,1,0,0,0,0,1,0,0,0,0,1,0,0,0,0,1,0,0,0
0,0,0,0,0,0,0,0,0,0,0,0,0,3,3,0,0,0,0,0,0,0,0,0,0,0,0,0
0,0,0,0,4,0,3,0,0,4,0,0,3,0,1,0,3,0,0,4,0,0,0,0,4,0,0,0
0,0,0,0,1,0,0,0,0,1,0,0,4,4,1,4,4,0,0,1,0,0,0,0,1,0,0,0
0,0,0,0,0,0,0,0,0,0,0,0,3,0,7,0,3,0,0,0,0,0,0,0,0,0,0,0
0,0,0,0,3,0,0,0,0,0,0,0,0,3,10,3,0,0,0,3,0,0,0,0,0,0,3,0
0,0,0,0,0,0,0,0,0,0,0,0,0,0,9,3,0,0,0,0,0,0,0,0,0,0,0,0
0,0,0,0,0,0,0,0,3,0,0,0,0,0,11,0,3,3,0,0,0,0,0,0,0,0,0,0
0,0,0,0,1,0,0,0,0,1,3,0,4,4,1,4,4,3,0,1,0,0,0,0,1,0,0,0
0,0,0,0,4,0,0,0,0,4,0,3,3,0,1,3,3,0,3,4,0,0,0,0,4,0,0,0
0,0,0,0,0,0,0,0,0,0,0,0,0,0,3,0,0,0,0,0,0,0,0,0,0,0,0,0
0,0,0,0,1,0,0,0,0,1,0,0,0,0,1,0,0,0,0,1,0,0,0,0,1,0,0,0
0,0,0,0,1,14,14,14,14,1,14,14,14,14,1,14,14,14,14,1,14,14,14,14,1,0,0,0
0,0,0,0,0,0,0,0,0,0,0,0,0,0,0,0,0,0,0,0,0,0,0,0,0,0,0,0
endlayer

layer
0,0,0,0,0,0,0,0,0,0,0,0,0,0,0,0,0,0,0,0,0,0,0,0,0,0,0,0
0,0,0,0,1,14,14,14,14,1,14,14,14,14,1,14,14,14,14,1,14,14,14,14,1,0,0,0
0,0,0,0,1,0,0,0,0,1,0,0,0,0,1,0,0,0,0,1,0,0,0,0,1,0,0,0
0,0,0,0,0,0,0,0,0,0,0,0,0,0,0,0,0,0,0,0,0,0,0,0,0,0,0,0
0,0,0,0,4,0,0,0,0,4,0,0,0,0,4,0,0,0,0,4,0,0,0,0,4,0,0,0
0,0,0,0,1,0,0,0,0,1,0,0,0,4,1,4,0,0,0,1,0,0,0,0,1,0,0,0
0,3,0,0,0,0,0,0,0,0,0,0,0,0,0,0,0,0,0,0,0,0,0,0,0,0,0,0
0,0,0,0,0,0,0,0,3,0,0,0,0,0,0,0,0,0,0,0,0,0,0,0,0,0,0,0
0,0,0,0,0,0,0,0,0,0,0,0,0,0,0,0,0,0,0,0,0,0,0,0,0,0,0,0
0,0,0,0,0,0,0,0,0,0,0,0,0,0,0,0,0,0,0,0,0,0,0,0,0,0,0,0
0,0,0,0,1,0,0,0,0,1,0,0,0,4,1,4,0,0,0,1,0,0,0,0,1,0,0,0
0,0,0,0,4,0,0,0,0,4,0,0,0,0,4,0,0,0,0,4,0,0,0,0,4,0,0,0
0,0,0,0,0,0,0,0,0,0,0,0,0,0,0,0,0,0,0,0,0,0,0,0,0,0,0,0
0,0,0,0,1,0,0,0,0,1,0,0,0,0,1,0,0,0,0,1,0,0,0,0,1,0,0,0
0,0,0,0,1,14,14,14,14,1,14,14,14,14,1,14,14,14,14,1,14,14,14,14,1,0,0,0
0,0,0,0,0,0,0,0,0,0,0,0,0,0,0,0,0,0,0,0,0,0,0,0,0,0,0,0
endlayer

layer
0,0,0,0,0,0,0,0,0,0,0,0,0,0,0,0,0,0,0,0,0,0,0,0,0,0,0,0
0,0,0,0,2,2,2,2,2,2,2,2,2,2,2,2,2,2,2,2,2,2,2,2,2,0,0,0
0,0,0,0,1,0,0,0,0,1,0,0,0,0,1,0,0,0,0,1,0,0,0,0,1,0,0,0
0,0,0,0,1,0,0,0,0,1,0,0,0,0,1,0,0,0,0,1,0,0,0,0,1,0,0,0
0,0,0,0,4,0,0,0,0,4,0,0,3,0,4,0,0,0,0,4,0,0,0,0,4,0,0,0
0,0,0,2,2,2,2,2,2,2,2,2,2,2,2,2,2,2,2,2,2,2,2,2,2,2,0,0
0,0,0,0,1,0,0,0,0,1,0,0,0,0,1,0,0,0,0,1,0,0,0,0,1,0,0,0
0,0,0,0,0,0,0,0,0,0,0,0,0,0,0,0,0,0,0,0,0,0,0,0,0,0,0,0
0,0,0,0,0,0,3,0,0,0,0,0,0,0,0,0,0,0,0,0,0,0,0,0,0,0,0,0
0,0,0,0,1,0,0,0,0,1,0,0,0,0,1,0,0,0,0,1,0,0,0,0,1,0,0,3
0,0,0,2,2,2,2,2,2,2,2,2,2,2,2,2,2,2,2,2,2,2,2,2,2,2,0,0
0,0,0,0,4,0,0,0,0,4,0,0,0,0,4,0,0,0,3,4,0,0,0,0,4,0,0,0
0,0,0,0,1,0,0,0,0,1,0,0,0,0,1,0,0,0,0,1,0,0,0,0,1,0,0,0
0,0,0,0,1,0,0,0,0,1,0,0,0,0,1,0,0,0,0,1,0,0,0,0,1,0,0,0
0,0,0,0,2,2,2,2,2,2,2,2,2,2,2,2,2,2,2,2,2,2,2,2,2,0,0,0
0,0,0,0,0,0,0,0,0,0,0,0,0,0,0,0,0,0,0,0,0,0,0,0,0,0,0,0
endlayer

layer
0,0,0,0,0,0,0,0,0,0,0,0,0,0,0,0,0,0,0,0,0,0,0,0,0,0,0,0
0,0,0,0,0,0,0,0,0,0,0,0,0,0,0,0,0,0,0,0,0,0,0,0,0,0,0,0
0,0,0,0,1,14,14,14,14,1,14,14,14,14,1,14,14,14,14,1,14,14,14,14,1,0,0,0
0,0,0,0,1,0,0,0,0,1,0,0,0,0,1,0,0,0,0,1,0,0,0,0,1,0,0,0
0,0,0,0,0,0,0,0,0,0,0,0,0,0,0,0,0,0,3,0,0,0,0,0,0,0,0,0
0,0,0,0,4,0,0,0,0,4,0,0,0,0,4,0,0,0,0,4,0,0,0,0,4,0,0,0
0,0,2,2,2,2,2,2,2,2,2,2,2,2,2,2,2,2,2,2,2,2,2,2,2,2,2,0
0,0,0,0,15,0,3,0,0,15,0,3,0,0,15,0,0,0,0,15,0,0,0,0,15,0,0,0
0,0,0,0,15,0,0,0,0,15,0,0,0,0,15,0,0,0,0,15,0,0,0,0,15,0,0,0
0,0,2,2,2,2,2,2,2,2,2,2,2,2,2,2,2,2,2,2,2,2,2,2,2,2,2,0
0,0,0,0,4,0,0,0,0,4,0,0,0,0,4,0,0,0,0,4,0,0,0,0,4,0,0,0
0,0,0,0,0,0,0,0,0,0,0,0,0,0,0,0,0,0,0,0,0,0,0,0,0,0,0,0
0,0,0,0,1,0,0,0,0,1,0,0,0,0,1,0,0,0,0,1,0,0,0,0,1,0,0,0
0,0,0,0,1,14,14,14,14,1,14,14,14,14,1,14,14,14,14,1,14,14,14,14,1,0,0,0
0,0,0,0,0,0,0,0,0,0,0,0,0,0,0,0,0,0,0,0,0,0,0,0,0,0,0,0
0,0,0,0,0,0,0,0,0,0,0,0,0,0,0,0,0,0,0,0,0,0,0,0,0,0,0,0
endlayer

layer
0,0,0,0,0,0,0,0,0,0,0,0,0,0,0,0,0,0,0,0,0,0,0,0,0,0,0,0
0,0,0,0,0,0,0,0,0,0,0,0,0,0,0,0,0,0,0,0,0,0,0,0,0,0,0,0
0,0,0,0,2,2,2,2,2,2,2,2,2,2,2,2,2,2,2,2,2,2,2,2,2,0,0,0
0,0,0,0,1,0,0,0,0,1,0,0,0,0,1,0,0,0,0,1,0,0,0,0,1,0,0,0
0,0,0,0,1,0,0,0,0,1,0,0,0,0,1,0,3,0,0,1,0,0,0,0,1,0,0,0
0,0,0,0,0,0,0,0,0,0,0,0,0,0,0,0,0,0,0,0,0,0,0,0,0,0,0,0
0,0,0,0,4,17,4,4,4,4,0,0,0,0,4,0,0,0,0,4,4,4,4,16,4,0,0,0
0,0,3,3,4,3,3,3,3,4,0,3,3,3,4,3,3,0,3,4,3,3,3,3,4,0,0,0
0,0,0,3,4,3,3,3,3,4,3,0,3,0,4,3,3,3,3,4,3,0,0,3,4,0,0,0
0,0,0,0,4,17,4,4,4,4,0,0,0,0,4,0,0,0,0,4,4,4,4,16,4,0,3,0
0,0,0,0,0,3,3,0,0,0,0,0,0,0,0,0,0,0,0,0,0,0,0,0,0,0,0,3
0,0,0,0,1,0,0,0,0,1,0,0,0,0,1,0,0,3,0,1,0,0,0,0,1,0,0,0
0,0,0,0,1,0,0,0,0,1,0,0,0,0,1,0,0,0,0,1,0,0,0,0,1,0,0,0
0,0,0,0,2,2,2,2,2,2,2,2,2,2,2,2,2,2,2,2,2,2,2,2,2,0,0,0
0,0,0,0,0,0,0,0,0,0,0,0,0,0,0,0,0,0,0,0,0,0,0,0,0,0,0,0
0,0,0,0,0,0,0,0,0,0,0,0,0,0,0,0,0,0,0,0,0,0,0,0,0,0,0,0
endlayer

layer
0,0,0,0,0,0,0,0,0,0,0,0,0,0,0,0,0,0,0,0,0,0,0,0,0,0,0,0
0,0,0,0,0,0,0,0,0,0,0,0,0,0,0,0,0,0,0,0,0,0,0,0,0,0,0,0
0,0,0,0,0,0,0,0,0,0,0,0,0,0,0,0,0,0,0,0,0,0,0,0,0,0,0,0
0,0,0,2,2,2,2,2,2,2,2,2,2,2,2,2,2,2,2,2,2,2,2,2,2,2,0,0
0,0,0,0,1,0,0,0,0,1,0,0,0,0,1,0,0,0,0,1,0,0,0,0,1,0,0,0
0,0,0,0,1,0,0,0,0,1,0,0,0,0,1,0,3,0,0,1,0,0,0,0,1,0,0,0
0,0,0,0,1,0,0,0,0,1,0,0,0,0,1,0,0,0,0,1,0,0,0,0,1,0,0,0
0,0,0,0,0,0,0,0,0,0,0,0,0,0,0,3,3,0,0,0,0,0,3,0,3,0,0,0
0,0,0,0,3,0,3,0,0,0,3,0,0,0,0,0,0,0,0,0,0,3,0,0,3,0,0,0
0,0,0,0,1,0,0,3,0,1,0,0,0,0,1,0,3,0,0,1,0,3,0,0,1,0,0,0
0,0,0,0,1,0,0,0,0,1,0,0,0,0,1,0,0,3,0,1,0,0,0,0,1,0,0,0
0,0,0,0,1,0,0,0,0,1,0,0,0,0,1,0,0,0,0,1,0,0,0,0,1,0,0,0
0,0,0,2,2,2,2,2,2,2,2,2,2,2,2,2,2,2,2,2,2,2,2,2,2,2,0,0
0,0,0,0,0,0,0,0,0,0,0,0,0,0,0,0,0,0,0,0,0,0,0,0,0,0,0,0
0,0,0,0,0,0,0,0,0,0,0,0,0,0,0,0,0,0,0,0,0,0,0,0,0,0,0,0
0,0,0,0,0,0,0,0,0,0,0,0,0,0,0,0,0,0,0,0,0,0,0,0,0,0,0,0
endlayer

layer
0,0,0,0,0,0,0,0,0,0,0,0,0,0,0,0,0,0,0,0,0,0,0,0,0,0,0,0
0,0,0,0,0,0,0,0,0,0,0,0,0,0,0,0,0,0,0,0,0,0,0,0,0,0,0,0
0,0,0,0,0,0,0,0,0,0,0,0,0,0,0,0,0,0,0,0,0,0,0,0,0,0,0,0
0,0,0,0,0,0,0,0,0,0,0,0,0,0,0,0,0,0,0,0,0,0,0,0,0,0,0,0
0,0,2,2,2,2,2,2,2,2,2,2,2,2,2,2,2,2,2,2,2,2,2,2,2,2,2,0
0,0,0,0,1,14,14,14,14,1,14,14,14,14,1,14,14,14,14,1,14,14,14,14,1,0,0,0
0,0,0,0,1,0,0,0,0,1,0,0,0,0,1,0,0,0,0,1,0,0,0,0,1,0,0,0
0,0,0,0,1,0,0,0,0,1,0,0,0,0,1,0,3,0,0,1,0,0,0,0,1,0,0,0
0,0,0,0,1,0,0,0,0,1,0,0,0,0,1,0,0,0,0,1,3,3,0,0,1,0,0,0
0,0,0,0,1,0,0,0,0,1,0,0,0,0,1,0,0,0,0,1,0,0,0,0,1,0,0,0
0,0,0,0,1,14,14,14,14,1,14,14,14,14,1,14,14,14,14,1,14,14,14,14,1,0,0,0
0,0,2,2,2,2,2,2,2,2,2,2,2,2,2,2,2,2,2,2,2,2,2,2,2,2,2,0
0,0,0,0,0,0,0,0,0,0,0,0,0,0,0,0,0,0,0,0,0,0,0,0,0,0,0,0
0,0,0,0,0,0,0,0,0,0,0,0,0,0,0,0,0,0,0,0,0,0,0,0,0,0,0,0
0,0,0,0,0,0,0,0,0,0,0,0,0,0,0,0,0,0,0,0,0,0,0,0,0,0,0,0
0,0,0,0,0,0,0,0,0,0,0,0,0,0,0,0,0,0,0,0,0,0,0,0,0,0,0,0
endlayer

layer
0,0,0,0,0,0,0,0,0,0,0,0,0,0,0,0,0,0,0,0,0,0,0,0,0,0,0,0
0,0,0,0,0,0,0,0,0,0,0,0,0,0,0,0,0,0,0,0,0,0,0,0,0,0,0,0
0,0,0,0,0,0,0,0,0,0,0,0,0,0,0,0,0,0,0,0,0,0,0,0,0,0,0,0
0,0,0,0,0,0,0,0,0,0,0,0,0,0,0,0,0,0,0,0,0,0,0,0,0,0,0,0
0,0,0,0,0,0,0,0,0,0,0,0,0,0,0,0,0,0,0,0,0,0,0,0,0,0,0,0
0,0,0,0,0,0,0,0,0,0,0,0,0,0,0,0,0,0,0,0,0,0,0,0,0,0,0,0
0,2,2,2,2,2,2,2,2,2,2,2,2,2,2,2,2,2,2,2,2,2,2,2,2,2,2,2
0,0,0,0,1,14,14,14,14,1,14,14,14,14,1,14,14,14,14,1,14,14,14,14,1,0,0,0
0,0,0,0,1,14,14,14,14,1,14,14,14,14,1,14,14,14,14,1,14,14,14,14,1,0,0,0
0,2,2,2,2,2,2,2,2,2,2,2,2,2,2,2,2,2,2,2,2,2,2,2,2,2,2,2
0,0,0,0,0,0,0,0,0,0,0,0,0,0,0,0,0,0,0,0,0,0,0,0,0,0,0,0
0,0,0,0,0,0,0,0,0,0,0,0,0,0,0,0,0,0,0,0,0,0,0,0,0,0,0,0
0,0,0,0,0,0,0,0,0,0,0,0,0,0,0,0,0,0,0,0,0,0,0,0,0,0,0,0
0,0,0,0,0,0,0,0,0,0,0,0,0,0,0,0,0,0,0,0,0,0,0,0,0,0,0,0
0,0,0,0,0,0,0,0,0,0,0,0,0,0,0,0,0,0,0,0,0,0,0,0,0,0,0,0
0,0,0,0,0,0,0,0,0,0,0,0,0,0,0,0,0,0,0,0,0,0,0,0,0,0,0,0
endlayer

