
# Created by Ruins mod version 14.6 Ingame Parser
# authoring Player: ArchNihil

weight=1
embed_into_distance=0
acceptable_target_blocks=
unacceptable_target_blocks=flowing_water,water,flowing_lava,lava
dimensions=19,17,16
allowable_overhang=0
max_leveling=2
leveling_buffer=0
preserve_water=0
preserve_lava=0

rule1=0,100,Railcraft:tile.railcraft.residual.heat-0
rule2=0,100,minecraft:log-4
rule3=0,100,ForgeMultipart:block-0
rule4=0,100,minecraft:stonebrick-0
rule5=0,100,minecraft:stone_slab-5
rule6=0,100,minecraft:log-0
rule7=0,100,minecraft:log-8
rule8=0,100,minecraft:iron_door-0
rule9=0,100,minecraft:stonebrick-2
rule10=0,100,minecraft:web-0
rule11=0,100,minecraft:monster_egg-3
rule12=0,100,minecraft:vine-2
rule13=0,100,minecraft:monster_egg-4
rule14=0,100,minecraft:cobblestone-0
rule15=0,100,minecraft:vine-1
rule16=0,100,minecraft:tnt-0
rule17=0,100,minecraft:vine-3
rule18=0,100,minecraft:lever-2
rule19=0,100,minecraft:iron_door-8
rule20=0,100,minecraft:iron_door-9
rule21=0,100,minecraft:redstone_wire-0
rule22=0,100,minecraft:vine-4
rule23=0,100,minecraft:vine-8
rule24=0,100,minecraft:vine-12
rule25=0,100,minecraft:leaves-12
rule26=0,100,minecraft:vine-0
rule27=0,100,minecraft:leaves-4
rule28=0,100,minecraft:iron_bars-0
rule29=0,100,IInventory;minecraft:chest;AWWayofTime:mundaneLengtheningCatalyst#1#0#3+gregtech:gt.metaitem.01#6#11089#15+gregtech:gt.metaitem.01#6#8528#19+gregtech:gt.metaitem.01#4#8527#23+minecraft:skull#1#2#24-5
rule30=0,100,IInventory;minecraft:chest;minecraft:skull#1#3#0+gregtech:gt.metaitem.01#6#11300#6+minecraft:wheat#1#0#7+blocklings:item.health_2#1#0#25+gregtech:gt.metaitem.01#1#8504#26-3
rule31=0,100,IInventory;minecraft:chest;gregtech:gt.metaitem.02#14#32100#3+minecraft:record_wait#1#0#4+RotaryCraft:rotarycraft_item_shaftcraft#15#9#11+gregtech:gt.metaitem.02#16#32100#21+gregtech:gt.metaitem.01#6#11305#25-2
rule32=0,100,IInventory;minecraft:chest;blocklings:item.health_1#1#0#5+minecraft:skull#2#0#6+gregtech:gt.metaitem.01#5#11305#9+gregtech:gt.metaitem.02#10#32100#23-3
rule33=0,100,IInventory;minecraft:chest;gregtech:gt.metaitem.01#1#11300#7+gregtech:gt.metaitem.01#5#11054#9+gregtech:gt.metaitem.02#15#32100#15+gregtech:gt.metaitem.01#5#11054#21+ExtraUtilities:plant/ender_lilly#4#0#26-2

layer
1,0,1,1,0,1,1,1,0,1,1,0,0,1,0,0
1,1,1,1,1,0,0,1,1,1,1,1,1,1,1,1
0,1,0,1,5,5,4,1,1,4,3,2,2,1,1,1
1,1,0,5,9,4,4,8,8,4,7,6,6,1,1,1
1,0,0,9,0,1,11,1,0,0,10,6,6,7,1,1
0,0,13,10,0,12,11,1,1,1,1,1,0,9,3,1
1,0,9,0,0,1,11,1,1,1,0,1,0,14,3,1
0,9,0,0,1,1,11,1,1,1,1,1,1,10,11,3
0,9,0,0,1,1,11,16,16,1,1,1,0,0,4,15
0,9,0,15,1,1,1,16,16,1,1,1,1,0,9,3
0,9,0,0,1,1,1,1,1,1,14,1,0,0,14,3
0,0,9,0,1,1,1,1,1,1,1,1,0,9,5,1
0,0,9,0,0,1,1,1,1,1,1,0,10,4,0,1
0,0,0,13,0,0,0,0,0,0,0,0,11,0,0,0
1,0,0,0,9,13,0,0,0,0,9,9,17,0,0,1
1,1,0,0,0,12,13,9,11,11,12,12,0,0,1,0
0,1,0,0,0,1,12,12,1,0,0,0,0,1,1,1
endlayer

layer
0,0,0,0,0,1,0,0,0,0,0,0,0,0,0,0
0,0,0,0,0,0,0,1,0,0,0,0,0,1,1,0
0,0,0,0,0,0,18,0,1,3,0,1,0,0,0,1
0,0,0,0,3,3,9,20,19,9,3,6,6,0,0,0
0,0,0,3,4,4,21,0,1,0,9,6,6,0,0,0
0,0,0,9,0,12,21,1,0,0,0,0,4,15,0,0
0,0,0,4,15,1,21,1,0,1,0,0,4,3,0,0
0,0,13,0,0,1,21,0,0,0,1,0,0,4,15,0
0,0,9,0,0,0,11,16,16,0,0,0,0,9,3,0
0,0,9,15,0,0,0,16,16,0,0,0,0,4,3,0
0,0,9,0,0,0,0,0,0,0,0,0,22,9,3,0
0,0,0,9,0,0,0,1,0,0,1,0,9,3,0,0
0,0,22,4,0,0,0,0,0,0,0,0,9,3,0,0
0,0,0,0,9,9,0,0,0,0,9,9,0,0,0,0
0,0,0,0,0,22,9,9,9,11,0,0,0,0,0,0
0,0,0,0,0,0,0,12,0,0,0,0,0,0,0,0
0,0,0,0,0,0,0,0,0,0,0,0,0,0,0,0
endlayer

layer
0,0,0,0,0,0,0,0,0,0,0,0,0,0,0,0
0,0,0,0,0,0,0,0,0,0,0,0,0,0,0,0
0,0,0,0,0,0,1,23,0,23,0,0,0,0,0,0
0,0,0,0,23,0,9,4,9,9,15,6,6,0,1,0
0,0,0,24,4,4,10,0,0,0,9,6,6,0,0,0
0,0,0,9,1,12,0,0,1,0,0,0,9,0,0,0
0,0,0,4,0,1,0,0,0,0,12,0,4,23,0,0
0,0,9,0,0,0,0,0,0,1,0,0,0,4,0,0
0,0,9,0,0,1,21,16,16,0,0,0,0,9,0,0
0,0,11,0,0,0,0,16,16,1,1,0,0,4,15,0
0,0,13,0,0,0,0,0,0,0,22,0,0,11,0,0
0,0,0,9,0,0,0,0,1,0,0,0,9,0,0,0
0,0,22,9,10,0,1,0,22,0,0,0,9,15,0,0
0,0,0,22,9,9,0,0,0,0,9,11,0,0,0,0
0,0,0,0,0,22,9,9,9,11,0,0,0,0,0,0
0,0,0,0,0,0,0,12,0,0,0,0,0,0,0,0
0,0,0,0,0,0,0,0,0,0,0,0,0,0,0,0
endlayer

layer
0,0,0,0,0,0,0,0,0,0,0,0,0,0,0,0
0,0,0,0,0,0,1,1,0,0,1,0,0,0,0,0
0,0,0,0,0,0,0,1,0,23,25,25,25,25,0,0
0,0,0,0,0,0,23,9,4,4,25,25,25,25,0,0
0,0,0,23,4,4,0,0,0,10,9,6,25,25,0,0
0,0,0,9,10,0,0,1,0,0,0,10,9,0,0,0
0,0,0,9,0,0,12,0,0,0,12,0,9,0,0,0
0,0,9,0,0,0,0,0,0,1,0,0,0,14,0,0
0,0,0,0,1,0,22,16,16,0,0,0,0,14,0,0
0,0,9,0,1,0,0,16,16,1,1,0,0,9,0,0
0,0,11,10,0,0,0,0,1,0,22,0,26,11,0,0
0,0,0,9,0,1,0,0,1,1,0,0,4,0,0,1
0,0,22,4,10,0,0,0,22,0,10,10,4,15,0,0
0,0,0,22,9,9,0,0,0,0,9,11,0,0,0,0
0,0,0,0,0,0,9,9,9,9,0,0,0,0,0,0
0,0,0,0,0,0,0,12,0,0,0,0,0,0,0,0
0,0,0,0,0,0,0,0,0,0,0,0,0,0,0,0
endlayer

layer
0,0,0,0,0,0,0,0,0,0,0,0,0,0,0,0
0,0,0,0,0,0,0,1,25,25,25,25,25,1,1,1
0,0,0,1,0,1,0,1,25,25,6,25,25,25,0,0
0,0,0,0,0,0,23,0,1,25,2,25,25,25,25,0
0,0,0,23,0,9,9,9,9,9,7,6,7,7,25,27
0,0,0,22,9,9,9,12,1,9,9,2,25,0,25,1
0,0,0,22,9,0,12,0,1,0,12,2,7,25,25,0
0,0,0,9,9,15,1,1,0,0,1,9,9,15,1,1
0,0,0,9,1,0,0,16,16,1,0,0,14,0,0,0
0,0,0,9,0,0,0,16,16,0,1,0,11,1,0,0
0,0,0,9,9,0,1,0,0,0,22,9,9,0,0,0
0,0,0,0,9,1,0,1,1,1,0,9,0,0,0,0
0,0,0,0,0,9,9,0,22,9,9,13,0,0,0,0
0,0,0,0,12,0,9,9,9,9,0,0,0,0,0,0
0,0,0,0,0,0,12,12,0,0,0,0,0,0,0,0
0,0,0,0,0,0,0,0,0,0,0,0,0,0,0,0
0,0,0,0,0,0,0,0,0,0,0,0,0,0,0,0
endlayer

layer
0,0,0,0,0,0,0,0,0,0,0,0,0,0,0,0
0,0,0,0,0,0,0,0,25,25,25,27,27,1,0,1
0,0,0,1,0,0,0,0,25,7,6,25,25,25,1,0
0,0,0,0,0,1,23,0,0,23,27,27,27,25,25,27
0,0,0,23,0,0,9,28,28,9,27,27,27,6,25,27
0,0,0,22,9,9,9,1,0,9,9,9,27,25,25,0
0,0,0,0,9,1,12,1,0,0,12,9,27,25,0,0
0,0,0,9,9,15,1,1,1,1,0,9,9,15,0,0
0,0,0,28,0,1,0,16,16,0,0,1,28,1,0,0
0,0,0,0,0,1,1,16,16,1,0,0,28,0,0,0
0,0,0,0,13,1,0,1,0,1,0,14,14,1,0,0
0,0,0,0,9,0,0,1,0,0,0,9,15,0,0,1
0,0,0,0,0,9,9,0,22,9,9,11,0,0,0,0
0,0,0,0,12,0,9,28,28,9,0,0,0,0,0,0
0,0,0,0,0,0,12,0,0,0,0,0,0,0,0,0
0,0,0,0,0,0,0,0,0,0,0,0,0,0,0,0
0,0,0,0,0,0,0,0,0,0,0,0,0,0,0,0
endlayer

layer
0,0,0,0,0,0,0,0,0,0,0,0,0,0,0,0
0,0,0,0,0,0,0,0,0,0,0,25,0,0,0,0
0,0,0,0,0,0,0,0,0,27,25,25,25,0,0,1
0,0,0,0,0,0,23,0,0,23,0,25,25,25,0,0
0,0,0,23,1,0,9,28,28,9,0,0,1,25,0,0
0,0,0,22,9,9,9,0,22,9,14,9,15,0,0,1
0,0,0,0,9,10,12,1,1,0,0,9,0,0,0,0
0,0,0,9,9,15,0,1,1,0,0,9,9,15,0,0
0,0,0,28,0,0,0,16,16,0,0,0,28,0,1,1
0,0,0,28,0,0,1,16,16,0,0,0,0,0,0,0
0,0,0,11,9,15,0,0,0,0,0,14,14,0,15,0
0,0,0,0,13,0,1,1,0,0,10,9,15,0,0,0
0,0,0,0,0,11,9,1,0,9,9,11,0,0,0,0
0,0,0,0,12,22,9,28,0,9,0,0,0,0,0,0
0,0,0,0,0,0,12,0,0,0,0,0,0,0,0,0
0,0,0,0,0,0,0,0,0,0,0,0,0,0,0,0
0,0,0,0,0,0,0,0,0,0,0,0,0,0,0,0
endlayer

layer
0,0,0,0,0,0,0,0,0,0,0,0,0,0,0,0
0,0,0,0,0,0,0,1,0,0,0,0,0,0,0,0
0,0,0,0,0,0,0,0,0,0,0,0,0,0,0,0
0,0,0,0,0,0,23,0,0,0,23,0,0,0,0,0
0,0,0,23,0,1,9,28,28,9,0,0,0,0,0,0
0,0,0,22,9,9,9,0,22,9,14,14,0,0,0,0
0,0,0,0,9,10,12,0,0,1,10,9,0,0,0,0
0,0,0,9,9,0,0,0,0,0,0,9,9,0,0,0
0,0,0,28,0,0,0,16,16,0,0,0,28,0,0,0
0,0,0,28,0,0,0,16,16,0,0,0,0,0,0,0
0,0,0,9,9,15,1,0,1,1,1,14,11,0,15,0
0,0,0,0,9,0,10,0,0,0,10,9,15,15,0,0
0,0,0,22,9,9,9,0,0,9,9,11,0,0,0,0
0,0,0,0,12,22,4,28,28,4,0,0,0,0,0,0
0,0,0,0,0,0,0,0,0,0,0,0,0,0,0,0
0,0,0,0,0,0,0,0,0,0,0,0,0,0,0,0
0,0,0,0,0,0,0,0,0,0,0,0,0,0,0,0
endlayer

layer
0,0,0,0,0,0,0,0,0,0,0,0,0,0,0,0
0,0,0,0,0,0,0,0,0,0,0,0,1,0,0,0
0,0,0,0,0,0,23,0,0,0,0,0,0,0,0,0
0,0,0,0,0,0,0,0,0,0,23,0,0,0,0,0
0,0,0,23,0,0,14,9,4,9,0,0,15,0,0,0
0,0,0,0,0,14,9,16,9,4,9,14,0,0,0,0
0,0,0,0,14,9,4,16,9,1,10,4,0,0,0,0
0,0,0,11,9,9,9,16,14,9,9,9,9,0,0,0
0,0,0,9,16,16,16,16,14,9,4,9,14,0,0,0
0,0,0,9,10,0,9,16,16,16,16,16,14,0,15,0
0,0,0,11,9,9,9,16,1,9,9,0,9,0,15,0
0,0,0,0,4,9,9,16,9,4,9,9,0,15,0,0
0,0,0,0,9,9,9,16,9,9,9,11,0,0,0,0
0,0,0,0,0,0,4,16,4,4,0,0,0,0,0,0
0,0,0,0,0,0,0,0,0,0,0,12,0,0,0,0
0,0,0,0,0,0,0,0,0,12,0,0,0,0,0,0
0,0,0,0,0,0,0,0,0,0,0,0,0,0,0,0
endlayer

layer
0,0,0,0,0,0,0,0,0,0,0,0,0,0,0,0
0,0,0,0,0,0,0,0,0,0,0,0,0,0,0,0
0,0,0,0,0,0,23,0,0,0,0,0,0,0,0,0
0,0,0,0,0,0,9,14,9,9,23,0,0,0,0,0
0,0,0,23,0,0,0,29,10,0,9,0,15,0,0,0
0,0,0,14,15,0,1,0,0,0,0,10,9,0,0,0
0,0,0,9,0,1,1,1,1,0,0,0,9,0,0,0
0,0,11,10,1,0,1,1,0,1,1,1,22,9,0,0
0,0,4,31,1,0,1,14,0,1,1,0,30,9,0,0
0,0,4,33,0,0,0,14,0,1,0,0,32,9,15,0
0,0,4,0,0,0,1,1,0,1,1,0,10,9,15,0
0,0,0,9,0,0,1,0,1,1,0,0,9,15,0,0
0,0,0,11,0,23,1,0,1,1,10,0,0,0,0,0
0,0,0,0,9,9,1,0,0,0,9,9,15,0,0,0
0,0,0,0,0,0,9,9,9,9,0,12,0,0,0,0
0,0,0,0,0,0,12,12,0,12,0,0,0,0,0,0
0,0,0,0,0,0,0,0,0,0,0,0,0,0,0,0
endlayer

layer
0,0,0,0,0,0,0,0,0,0,0,0,0,0,0,0
0,0,0,0,0,0,0,0,0,0,0,0,0,0,0,0
0,0,0,0,0,0,0,0,1,0,0,0,0,0,0,0
0,0,0,0,0,0,0,0,28,9,23,23,0,0,0,0
0,0,0,23,0,0,0,0,12,0,9,9,15,0,0,0
0,0,0,9,0,0,0,0,0,0,0,12,9,0,0,0
0,0,0,11,15,0,0,0,0,1,0,0,9,0,0,0
0,0,9,0,0,0,0,0,0,1,0,0,22,9,0,0
0,0,9,0,0,0,0,10,0,0,0,0,0,0,0,0
0,0,9,0,0,1,0,9,1,1,1,0,0,0,15,0
0,0,9,15,0,0,0,0,1,0,0,0,10,9,15,0
0,0,0,9,0,0,0,0,0,0,0,22,9,15,0,0
0,0,0,11,0,23,0,0,0,0,0,0,9,0,0,0
0,0,0,0,9,9,0,0,0,0,9,9,0,0,0,0
0,0,0,0,0,0,9,9,9,9,0,0,0,0,0,0
0,0,0,0,0,0,0,0,0,0,0,0,0,0,0,0
0,0,0,0,0,0,0,0,0,0,0,0,0,0,0,0
endlayer

layer
0,0,0,0,0,0,0,0,0,0,0,0,0,0,0,0
0,0,0,0,0,0,0,0,0,0,0,0,0,0,0,0
0,0,0,0,0,0,0,0,0,0,0,0,0,0,0,0
0,0,0,0,0,0,0,0,14,9,0,0,0,0,0,0
0,0,0,0,0,0,0,0,12,10,9,9,0,0,0,0
0,0,0,0,0,0,0,0,0,0,0,12,9,0,0,0
0,0,0,14,15,0,1,0,0,0,0,0,9,0,0,0
0,0,9,0,0,0,0,0,0,0,0,0,22,9,0,0
0,0,9,0,0,0,0,0,0,0,0,0,0,9,0,0
0,0,0,0,1,0,0,0,0,0,0,0,0,9,15,0
0,0,9,0,0,0,0,0,0,0,0,0,0,9,0,0
0,0,0,9,0,0,0,0,0,0,0,22,9,0,0,0
0,0,0,11,0,23,0,0,0,0,0,0,0,0,0,0
0,0,0,0,9,9,0,0,0,0,9,9,0,0,0,0
0,0,0,0,0,0,9,9,9,9,0,0,0,0,0,0
0,0,0,0,0,0,0,0,0,12,0,0,0,0,0,0
0,0,0,0,0,0,0,0,0,0,0,0,0,0,0,0
endlayer

layer
0,0,0,0,0,0,0,0,0,0,0,0,0,0,0,0
0,0,0,0,0,0,0,0,0,0,0,0,0,0,0,0
0,0,0,0,1,0,0,0,0,0,0,0,0,0,0,0
0,0,0,0,0,0,0,0,0,9,0,0,0,0,0,0
0,0,0,0,0,0,0,0,0,0,0,9,0,0,0,0
0,0,0,0,0,0,0,0,0,0,0,12,9,0,0,0
0,0,0,0,0,0,0,0,1,0,0,0,0,0,0,0
0,0,9,0,0,1,0,0,0,1,0,0,22,9,0,0
0,0,0,0,0,0,0,0,0,1,0,0,0,28,0,0
0,0,0,0,0,0,0,0,1,0,1,0,0,28,0,0
0,0,9,0,0,0,0,0,0,1,0,0,0,9,0,0
0,0,0,0,0,0,1,0,0,0,0,0,0,0,0,0
0,0,0,9,0,0,0,0,0,0,0,0,0,0,0,0
0,0,0,0,9,0,0,0,0,0,0,9,0,0,0,0
0,0,0,0,0,0,9,0,0,9,0,0,0,0,0,0
0,0,0,0,0,0,0,0,0,12,0,0,0,0,0,0
0,0,0,0,0,0,0,0,0,0,0,0,0,0,0,0
endlayer

layer
0,0,0,0,0,0,0,0,0,0,0,0,0,0,0,0
0,0,0,0,0,0,0,0,0,0,0,0,0,0,0,0
0,0,0,0,0,0,0,0,0,0,0,0,0,0,0,0
0,0,0,0,0,0,0,0,0,0,0,0,0,0,0,0
0,0,0,0,0,0,0,0,0,0,0,0,0,0,0,0
0,0,0,0,0,0,0,0,0,0,0,0,0,0,0,0
0,0,0,0,0,0,0,0,0,0,0,0,0,0,0,0
0,0,0,0,0,0,0,0,0,0,0,0,0,0,0,0
0,0,0,0,0,0,0,0,0,0,0,0,0,0,0,0
0,0,0,0,0,0,0,0,0,0,0,0,0,0,0,0
0,0,0,0,0,0,1,0,0,0,0,0,0,0,0,0
0,0,0,0,0,0,0,0,0,0,0,0,0,0,0,0
0,0,0,0,0,0,0,0,0,0,0,0,0,0,0,0
0,0,0,0,0,0,0,0,0,0,0,0,0,0,0,0
0,0,0,0,0,0,0,0,0,0,0,0,0,0,0,0
0,0,0,0,0,0,0,0,0,0,0,0,0,0,0,0
0,0,0,0,0,0,0,0,0,0,0,0,0,0,0,0
endlayer

layer
0,0,0,0,0,0,0,0,0,0,0,0,0,0,0,0
0,0,0,0,0,0,0,0,0,0,0,0,0,0,0,0
0,0,0,0,0,0,0,0,0,0,0,0,0,0,0,0
0,0,0,0,0,0,0,0,0,0,0,0,0,0,0,0
0,0,0,0,0,0,0,0,0,0,0,0,0,0,0,0
0,0,0,0,0,0,0,0,0,0,0,0,0,0,0,0
0,0,0,0,0,0,0,0,0,0,0,0,0,0,0,0
0,0,0,0,0,1,0,1,0,0,0,0,0,0,0,0
0,0,0,0,0,0,0,0,0,0,0,0,0,0,0,0
0,0,0,0,0,0,0,0,0,0,0,0,0,0,0,0
0,0,0,0,0,0,0,0,0,0,0,0,0,0,0,0
0,0,0,0,0,0,0,0,0,0,0,0,0,0,0,0
0,0,0,0,0,0,0,0,0,0,0,0,0,0,0,0
0,0,0,0,0,0,0,0,0,0,0,0,0,0,0,0
0,0,0,0,0,0,0,0,0,0,0,0,0,0,0,0
0,0,0,0,0,0,0,0,0,0,0,0,0,0,0,0
0,0,0,0,0,0,0,0,0,0,0,0,0,0,0,0
endlayer

layer
0,0,0,0,0,0,0,0,0,0,0,0,0,0,0,0
0,0,0,0,0,0,0,0,0,0,0,0,0,0,0,0
0,0,0,0,0,0,0,0,0,0,0,0,0,0,0,0
0,0,0,0,0,0,0,0,0,0,0,0,0,0,0,0
0,0,0,0,0,0,0,0,0,0,0,0,0,0,0,0
0,0,0,0,0,0,0,0,0,0,0,0,0,0,0,0
0,0,0,0,0,0,0,0,0,0,0,0,0,0,0,0
0,0,0,0,0,0,0,0,0,0,0,0,0,0,0,0
0,0,0,0,0,0,0,0,0,0,0,0,0,0,0,0
0,0,0,0,0,0,0,0,0,0,0,0,0,0,0,0
0,0,0,0,0,0,0,0,0,0,0,0,0,0,0,0
0,0,0,0,0,0,0,0,0,0,0,0,0,0,0,0
0,0,0,0,0,0,0,0,0,0,0,0,0,0,0,0
0,0,0,0,0,0,0,0,0,0,0,0,0,0,0,0
0,0,0,0,0,0,0,0,0,0,0,0,0,0,0,0
0,0,0,0,0,0,0,0,0,0,0,0,0,0,0,0
0,0,0,0,0,0,0,0,0,0,0,0,0,0,0,0
endlayer

layer
0,0,0,0,0,0,0,0,0,0,0,0,0,0,0,0
0,0,0,0,0,0,0,0,0,0,0,0,0,0,0,0
0,0,0,0,0,0,0,0,0,0,0,0,0,0,0,0
0,0,0,0,0,0,0,0,0,0,0,0,0,0,0,0
0,0,0,0,0,0,0,0,0,0,0,0,0,0,0,0
0,0,0,0,0,0,0,0,0,0,0,0,0,0,0,0
0,0,0,0,0,0,0,0,0,0,0,0,0,0,0,0
0,0,0,0,0,0,1,0,0,0,0,0,0,0,0,0
0,0,0,0,0,0,0,0,0,0,0,0,0,0,0,0
0,0,0,0,0,0,0,0,0,0,0,0,0,0,0,0
0,0,0,0,0,0,0,0,0,0,0,0,0,0,0,0
0,0,0,0,0,0,0,0,0,0,0,0,0,0,0,0
0,0,0,0,0,0,0,0,0,0,0,0,0,0,0,0
0,0,0,0,0,0,0,0,0,0,0,0,0,0,0,0
0,0,0,0,0,0,0,0,0,0,0,0,0,0,0,0
0,0,0,0,0,0,0,0,0,0,0,0,0,0,0,0
0,0,0,0,0,0,0,0,0,0,0,0,0,0,0,0
endlayer

layer
0,0,0,0,0,0,0,0,0,0,0,0,0,0,0,0
0,0,0,0,0,0,0,0,0,0,0,0,0,0,0,0
0,0,0,0,0,0,0,0,0,0,0,0,0,0,0,0
0,0,0,0,0,0,0,0,0,0,0,0,0,0,0,0
0,0,0,0,0,0,0,0,0,0,0,0,0,0,0,0
0,0,0,0,0,0,0,0,0,0,0,0,0,0,0,0
0,0,0,0,0,1,0,0,0,0,0,0,0,0,0,0
0,0,0,0,0,0,0,0,0,0,0,0,0,0,0,0
0,0,0,0,0,0,0,0,0,0,0,0,0,0,0,0
0,0,0,0,0,0,0,0,0,0,0,0,0,0,0,0
0,0,0,0,0,0,0,0,0,0,0,0,0,0,0,0
0,0,0,0,0,0,0,0,0,0,0,0,0,0,0,0
0,0,0,0,0,0,0,0,0,0,0,0,0,0,0,0
0,0,0,0,0,0,0,0,0,0,0,0,0,0,0,0
0,0,0,0,0,0,0,0,0,0,0,0,0,0,0,0
0,0,0,0,0,0,0,0,0,0,0,0,0,0,0,0
0,0,0,0,0,0,0,0,0,0,0,0,0,0,0,0
endlayer

layer
0,0,0,0,0,0,0,0,0,0,0,0,0,0,0,0
0,0,0,0,0,0,0,0,0,0,0,0,0,0,0,0
0,0,0,0,0,0,0,0,0,0,0,0,0,0,0,0
0,0,0,0,0,0,0,0,0,0,0,0,0,0,0,0
0,0,0,0,0,0,0,0,0,0,0,0,0,0,0,0
0,0,0,0,0,0,0,0,0,0,0,0,0,0,0,0
0,0,0,0,0,1,0,0,0,0,0,0,0,0,0,0
0,0,0,0,0,0,0,0,0,0,0,0,0,0,0,0
0,0,0,0,0,0,0,0,0,0,0,0,0,0,0,0
0,0,0,0,0,0,0,0,0,0,0,0,0,0,0,0
0,0,0,0,0,0,0,0,0,0,0,0,0,0,0,0
0,0,0,0,0,0,0,0,0,0,0,0,0,0,0,0
0,0,0,0,0,0,0,0,0,0,0,0,0,0,0,0
0,0,0,0,0,0,0,0,0,0,0,0,0,0,0,0
0,0,0,0,0,0,0,0,0,0,0,0,0,0,0,0
0,0,0,0,0,0,0,0,0,0,0,0,0,0,0,0
0,0,0,0,0,0,0,0,0,0,0,0,0,0,0,0
endlayer

