
# Created by Ruins mod version 14.6 Ingame Parser
# authoring Player: ArchNihil

weight=1
embed_into_distance=0
acceptable_target_blocks=
unacceptable_target_blocks=flowing_water,water,flowing_lava,lava
dimensions=19,17,16
allowable_overhang=0
max_leveling=2
leveling_buffer=0
preserve_water=0
preserve_lava=0

rule1=0,100,Railcraft:tile.railcraft.residual.heat-0
rule2=0,100,minecraft:log-4
rule3=0,100,ForgeMultipart:block-0
rule4=0,100,minecraft:stonebrick-0
rule5=0,100,minecraft:stone_slab-5
rule6=0,100,minecraft:log-0
rule7=0,100,minecraft:monster_egg-3
rule8=0,100,minecraft:iron_door-0
rule9=0,100,minecraft:stonebrick-2
rule10=0,100,minecraft:log-8
rule11=0,100,minecraft:web-0
rule12=0,100,minecraft:vine-2
rule13=0,100,minecraft:cobblestone-0
rule14=0,100,minecraft:vine-1
rule15=0,100,minecraft:vine-4
rule16=0,100,MobSpawner:Spider
rule17=0,100,minecraft:ladder-5
rule18=0,100,minecraft:monster_egg-4
rule19=0,100,minecraft:vine-3
rule20=0,100,minecraft:vine-8
rule21=0,100,minecraft:iron_door-8
rule22=0,100,minecraft:monster_egg-1
rule23=0,100,minecraft:vine-12
rule24=0,100,minecraft:leaves-12
rule25=0,100,minecraft:vine-0
rule26=0,100,minecraft:leaves-4
rule27=0,100,minecraft:iron_bars-0
rule28=0,100,IInventory;minecraft:chest;AWWayofTime:mundaneLengtheningCatalyst#1#0#3+gregtech:gt.metaitem.01#6#11089#15+gregtech:gt.metaitem.01#6#8528#19+gregtech:gt.metaitem.01#4#8527#23+minecraft:skull#1#2#24-5
rule29=0,100,IInventory;minecraft:chest;minecraft:skull#1#3#0+gregtech:gt.metaitem.01#6#11300#6+minecraft:wheat#1#0#7+blocklings:item.health_2#1#0#25+gregtech:gt.metaitem.01#1#8504#26-3
rule30=0,100,IInventory;minecraft:chest;gregtech:gt.metaitem.02#14#32100#3+minecraft:record_wait#1#0#4+RotaryCraft:rotarycraft_item_shaftcraft#15#9#11+gregtech:gt.metaitem.02#16#32100#21+gregtech:gt.metaitem.01#6#11305#25-2
rule31=0,100,IInventory;minecraft:chest;blocklings:item.health_1#1#0#5+minecraft:skull#2#0#6+gregtech:gt.metaitem.01#5#11305#9+gregtech:gt.metaitem.02#10#32100#23-3
rule32=0,100,IInventory;minecraft:chest;gregtech:gt.metaitem.01#1#11300#7+gregtech:gt.metaitem.01#5#11054#9+gregtech:gt.metaitem.02#15#32100#15+gregtech:gt.metaitem.01#5#11054#21+ExtraUtilities:plant/ender_lilly#4#0#26-2

layer
1,0,1,1,0,1,1,1,0,1,1,0,0,1,0,0
1,1,1,1,1,0,0,1,1,0,1,1,1,1,1,1
0,1,0,1,5,5,4,1,1,4,3,3,2,1,1,1
1,1,0,5,9,4,4,1,8,4,7,0,6,1,1,1
1,0,0,9,0,1,0,1,0,0,11,6,6,10,1,1
0,0,9,11,0,12,0,1,1,1,1,1,0,9,3,1
1,0,9,0,0,1,1,1,0,1,0,1,0,13,3,1
0,9,0,0,1,1,0,1,1,1,1,1,1,11,7,3
0,9,0,0,1,1,15,13,13,1,0,1,0,0,4,14
0,9,0,14,1,1,1,13,16,1,1,1,1,0,9,3
0,9,0,0,1,1,1,17,1,1,13,1,0,0,13,3
0,0,9,0,1,1,1,1,1,1,1,1,0,9,5,1
0,0,9,0,0,1,1,1,1,1,1,0,11,4,0,1
0,0,0,18,0,0,0,0,0,0,0,0,7,0,0,0
1,1,1,0,9,9,0,0,0,0,9,9,19,0,1,1
1,1,0,1,0,12,18,9,7,7,12,12,0,1,1,1
0,1,0,0,1,1,12,12,1,0,0,0,1,1,1,1
endlayer

layer
0,0,0,0,0,0,0,0,0,0,0,0,0,0,0,0
0,0,0,0,0,0,0,1,0,0,0,0,0,1,1,0
0,0,0,0,0,0,3,20,1,3,0,1,0,0,0,1
0,0,0,0,3,3,9,0,21,9,3,6,6,0,0,0
0,0,0,3,4,4,11,0,1,0,9,6,6,0,0,0
0,0,0,9,0,12,0,1,0,0,0,0,4,14,0,0
0,0,0,4,14,0,0,0,0,1,0,0,4,3,0,0
0,0,18,0,0,0,1,0,0,0,1,0,0,4,14,0
0,0,9,0,0,0,15,22,0,0,0,0,0,9,3,0
0,0,9,14,0,0,0,7,0,0,0,0,0,4,3,0
0,0,9,0,0,0,0,17,0,0,0,0,15,9,3,0
0,0,0,9,0,0,0,1,0,0,1,0,9,3,0,0
0,0,15,4,0,0,0,0,0,0,0,0,9,3,0,0
0,0,0,0,9,9,0,0,0,0,9,9,0,0,0,0
0,0,0,0,0,15,9,9,9,7,1,0,0,0,0,0
0,0,0,0,0,0,1,12,0,0,0,0,0,0,0,0
0,0,0,0,0,0,0,0,0,0,0,0,0,0,0,0
endlayer

layer
0,0,0,0,0,0,0,0,0,0,0,0,0,0,0,0
0,0,0,0,0,0,0,0,0,0,0,0,0,0,0,0
0,0,0,0,0,0,1,20,0,20,0,0,0,0,0,0
0,0,0,0,20,0,9,4,9,9,14,6,6,0,1,0
0,0,0,23,4,4,11,0,0,0,9,6,6,0,0,0
0,0,0,9,1,12,0,0,1,0,0,0,9,0,0,0
0,0,0,4,0,1,0,0,0,0,12,0,4,20,0,0
0,0,9,0,0,0,0,0,0,1,0,0,0,4,0,0
0,0,9,0,0,1,15,13,9,0,0,0,0,9,0,0
0,0,7,0,0,0,0,7,7,1,1,0,0,4,14,0
0,0,18,0,0,0,0,17,0,0,15,0,0,7,0,0
0,0,0,9,0,0,0,0,0,0,0,0,9,0,0,0
0,0,15,9,11,0,1,0,15,0,0,0,9,14,0,0
0,0,0,15,9,9,0,0,0,0,9,7,0,0,0,0
0,0,0,0,0,15,9,9,9,7,0,0,0,0,0,0
0,0,0,0,0,0,0,12,1,0,0,0,0,0,0,0
0,0,0,1,0,0,0,0,0,0,0,0,0,0,0,0
endlayer

layer
0,0,0,0,0,0,0,0,0,0,0,0,0,0,0,0
0,0,0,0,0,0,1,1,0,0,1,0,0,0,0,0
0,0,0,0,0,0,0,1,0,20,24,24,24,24,0,0
0,0,0,0,0,0,20,9,4,4,24,24,24,24,0,0
0,0,0,20,4,4,0,0,0,11,9,6,24,24,0,0
0,0,0,9,11,0,0,1,0,0,0,11,9,0,0,0
0,0,0,9,0,0,12,0,0,0,12,0,9,0,0,0
0,0,9,0,0,0,0,0,0,1,0,0,0,13,0,0
0,0,0,0,1,0,15,9,9,0,0,0,0,13,0,0
0,0,9,0,1,0,0,13,11,1,1,0,0,9,0,0
0,0,7,11,0,0,0,17,1,0,15,0,25,7,0,0
0,0,0,9,0,1,0,0,1,1,0,0,4,0,0,1
0,0,15,4,11,0,0,0,15,0,11,11,4,14,0,0
0,0,0,15,9,9,0,0,0,0,9,7,0,0,0,0
0,0,0,1,0,0,9,9,9,9,0,0,0,0,0,0
0,0,0,0,1,0,0,12,0,0,0,0,0,0,0,0
0,0,0,0,0,0,1,0,0,0,0,0,1,0,0,0
endlayer

layer
0,0,0,0,0,0,0,0,0,0,0,0,0,0,0,0
0,0,0,0,0,0,0,1,24,24,24,24,24,1,1,1
0,0,0,1,0,1,0,1,24,24,6,24,24,24,0,0
0,0,0,0,0,0,20,0,1,24,2,24,24,24,24,0
0,0,0,20,0,9,9,9,9,9,10,6,10,10,24,26
0,0,0,15,9,9,9,12,1,9,9,2,24,0,24,1
0,0,0,15,9,0,12,0,0,0,12,2,10,24,24,0
0,0,0,9,9,14,0,1,0,0,1,9,9,14,1,1
0,0,0,9,1,0,15,9,1,1,0,0,13,0,0,0
0,0,0,9,0,0,0,11,0,0,1,0,7,1,0,0
0,0,0,9,9,0,0,0,0,0,15,9,9,0,0,0
0,0,0,0,9,1,0,1,1,0,0,9,0,0,0,0
0,0,0,0,0,9,9,0,15,9,9,18,0,0,0,0
0,0,0,0,12,0,9,9,9,9,0,0,0,0,0,0
0,0,0,0,0,0,12,12,0,0,0,0,0,0,0,1
0,0,0,0,0,0,0,0,0,0,0,0,1,0,0,0
0,0,0,1,0,0,0,0,0,0,0,0,0,0,0,0
endlayer

layer
0,0,0,0,0,0,0,0,0,0,0,0,0,0,0,0
0,0,0,0,0,0,0,0,24,24,24,26,26,1,0,1
0,0,0,1,0,0,0,0,24,10,6,24,24,24,1,0
0,0,0,0,0,1,20,0,0,20,26,26,26,24,24,26
0,0,0,20,0,0,9,27,27,9,26,26,26,6,24,26
0,0,0,15,9,9,9,1,0,9,9,9,26,24,24,0
0,0,0,0,9,1,12,1,0,0,12,9,26,24,0,0
0,0,0,9,9,14,1,1,1,1,0,9,9,14,0,0
0,0,0,27,0,1,15,9,4,0,0,1,27,1,0,0
0,0,0,0,0,1,1,4,4,0,0,0,27,0,0,0
0,0,0,7,9,0,0,1,17,1,0,13,13,1,0,0
0,0,0,0,9,0,0,1,0,0,0,9,14,0,0,1
0,0,0,0,0,9,9,0,15,9,9,7,0,0,0,0
0,0,0,0,12,0,9,27,27,9,0,0,0,0,0,0
0,0,0,0,0,0,12,0,0,0,0,0,0,0,0,0
0,1,0,0,0,0,0,0,0,0,0,0,0,0,0,0
0,0,0,0,0,0,1,0,1,0,0,0,0,0,0,0
endlayer

layer
0,0,0,0,0,0,0,0,0,0,0,0,0,0,0,0
0,0,0,0,0,0,0,0,0,0,0,24,0,0,0,0
0,0,0,0,0,0,0,0,0,26,24,24,24,0,0,1
0,0,0,0,0,0,20,0,0,20,0,24,24,24,0,0
0,0,0,20,1,0,9,27,27,9,0,0,1,24,0,0
0,0,0,15,9,9,9,0,15,9,13,9,14,0,0,1
0,0,0,0,9,11,12,0,0,0,0,9,0,0,0,0
0,0,0,9,9,14,0,1,1,0,0,9,9,14,0,0
0,0,0,27,0,0,15,4,4,0,0,0,27,0,1,1
0,0,0,27,0,0,0,4,4,0,0,0,0,0,0,0
0,0,0,7,9,14,0,17,17,0,0,13,13,0,14,0
0,0,0,0,18,0,0,1,0,0,11,9,14,0,0,0
0,0,0,0,0,7,9,1,0,9,9,7,0,0,0,0
0,0,0,0,12,15,9,27,0,9,0,0,0,0,0,0
0,0,0,0,0,0,12,0,0,0,0,0,0,0,0,0
0,0,0,0,0,0,0,0,0,0,0,0,0,0,0,0
0,0,0,0,1,0,0,0,0,0,0,0,0,0,0,0
endlayer

layer
0,0,0,0,0,0,0,0,0,0,0,0,0,0,0,0
0,0,0,0,0,0,0,1,0,0,0,0,0,0,0,0
0,0,0,0,0,0,0,0,0,0,0,0,0,0,0,0
0,0,0,0,0,0,20,0,0,0,20,0,0,0,0,0
0,0,0,20,0,1,9,27,27,9,0,0,0,0,0,0
0,0,0,15,9,9,9,0,15,9,13,13,0,0,0,0
0,0,0,0,9,11,12,0,0,1,11,9,0,0,0,0
0,0,0,9,9,0,0,0,0,0,0,9,9,0,0,0
0,0,0,27,0,0,15,9,9,0,0,0,27,0,0,0
0,0,0,27,0,0,0,9,7,0,0,0,0,0,0,0
0,0,0,9,9,14,0,17,1,1,0,13,7,0,14,0
0,0,0,0,9,0,11,0,0,0,11,9,14,14,0,0
0,0,0,15,9,9,9,0,0,9,9,7,0,0,0,0
0,0,0,0,12,15,4,27,27,4,0,0,0,0,0,0
0,0,0,0,0,0,0,0,0,0,0,0,0,0,0,0
0,0,0,0,0,0,0,0,0,0,0,0,0,0,0,0
0,0,0,0,0,0,0,0,0,0,0,0,0,0,0,0
endlayer

layer
0,0,0,0,0,0,0,0,0,0,0,0,0,0,0,0
0,0,0,0,0,0,0,0,0,0,0,0,1,0,0,0
0,0,0,0,0,0,20,0,0,0,0,0,0,0,0,0
0,0,0,0,0,0,0,0,0,0,20,0,0,0,0,0
0,0,0,20,0,0,13,9,4,9,0,0,14,0,0,0
0,0,0,0,0,13,9,9,9,4,9,13,0,0,0,0
0,0,0,0,13,9,4,9,9,1,11,4,0,0,0,0
0,0,0,7,9,9,9,4,13,9,9,9,9,0,0,0
0,0,0,9,4,11,9,9,13,9,4,9,13,0,0,0
0,0,0,9,11,0,9,13,13,9,9,9,13,0,14,0
0,0,0,7,9,9,9,17,0,9,9,0,9,0,14,0
0,0,0,0,4,9,9,9,9,4,9,9,0,14,0,0
0,0,0,0,9,9,9,4,9,9,9,7,0,0,0,0
0,0,0,0,0,0,4,4,4,4,0,0,0,0,0,0
0,0,0,0,0,0,0,0,0,0,0,12,0,0,0,0
0,0,0,0,0,0,0,0,0,0,0,0,1,0,1,0
0,0,0,0,0,0,0,0,0,0,0,0,0,0,0,0
endlayer

layer
0,0,0,0,0,0,0,0,0,0,0,0,0,0,0,0
0,0,0,0,0,0,0,0,0,0,0,0,0,0,0,0
0,0,0,0,0,0,20,0,0,0,0,0,0,0,0,0
0,0,0,0,0,0,9,13,9,9,20,0,0,0,0,0
0,0,0,20,0,0,0,28,11,0,9,0,14,0,0,0
0,0,0,13,14,0,0,0,0,0,0,11,9,0,0,0
0,0,0,9,0,1,0,1,0,0,0,0,9,0,0,0
0,0,7,11,0,0,1,1,0,1,1,1,15,9,0,0
0,0,4,30,1,0,1,13,16,1,1,0,29,9,0,0
0,0,4,32,0,0,0,13,13,0,0,0,31,9,14,0
0,0,4,0,0,0,1,0,0,0,1,0,11,9,14,0
0,0,0,9,0,0,0,0,1,1,0,0,9,14,0,0
0,0,0,7,0,20,0,0,0,0,11,0,0,0,0,0
0,0,0,0,9,9,0,0,0,0,9,9,14,0,0,0
0,0,0,0,0,0,9,9,9,9,0,12,0,0,0,0
0,0,0,0,0,0,12,12,0,12,0,0,0,0,0,0
0,0,0,0,0,0,0,0,0,0,0,0,0,0,0,0
endlayer

layer
0,0,0,0,0,0,0,0,0,0,0,0,0,0,0,0
0,0,0,0,0,0,0,0,0,0,0,0,0,0,0,0
0,0,0,0,0,0,0,0,1,0,0,0,0,0,0,0
0,0,0,0,0,0,0,0,27,9,20,20,0,0,0,0
0,0,0,20,0,0,0,0,12,0,9,9,14,0,0,0
0,0,0,9,0,0,0,0,0,0,0,12,9,0,0,0
0,0,0,7,14,0,0,0,0,1,0,0,9,0,0,0
0,0,9,0,0,0,0,0,0,1,0,0,15,9,0,0
0,0,9,0,0,0,0,11,0,0,0,0,0,0,0,0
0,0,9,0,0,1,0,9,0,0,1,0,0,0,14,0
0,0,9,14,0,0,0,0,1,0,0,0,11,9,14,0
0,0,0,9,0,0,0,0,0,0,0,15,9,14,0,0
0,0,0,7,0,20,0,0,0,0,0,0,9,0,0,0
0,0,0,0,9,9,0,0,0,0,9,9,0,0,0,0
0,0,0,0,0,0,9,9,9,9,0,0,0,0,0,0
0,0,0,0,0,1,0,0,0,0,1,0,0,0,0,0
0,0,0,0,0,0,1,1,0,0,0,0,0,0,0,0
endlayer

layer
0,0,0,0,0,0,0,0,0,0,0,0,0,0,0,0
0,0,0,0,0,0,0,0,0,0,0,0,0,0,0,0
0,0,0,0,0,0,0,0,0,0,0,0,0,0,0,0
0,0,0,0,0,0,0,0,13,9,0,0,0,0,0,0
0,0,0,0,0,0,0,0,12,11,9,9,0,0,0,0
0,0,0,0,0,0,0,0,0,0,0,12,9,0,0,0
0,0,0,13,14,0,1,0,0,0,0,0,9,0,0,0
0,0,9,0,0,0,0,0,0,0,0,0,15,9,0,0
0,0,9,0,0,0,0,0,0,0,0,0,0,9,0,0
0,0,0,0,1,0,0,13,0,0,0,0,0,9,14,0
0,0,9,0,0,0,0,0,0,0,0,0,0,9,0,0
0,0,0,9,0,0,0,0,0,0,0,15,9,0,0,0
0,0,0,7,0,20,0,0,0,0,0,0,0,0,0,0
0,0,0,0,9,9,0,0,0,0,9,9,0,0,0,0
0,0,0,0,0,0,9,9,9,9,0,0,0,0,0,0
0,0,0,0,0,0,0,0,0,12,1,0,0,0,0,0
0,0,0,0,0,0,1,0,1,0,0,0,0,0,0,0
endlayer

layer
0,0,0,0,0,0,0,0,0,0,0,0,0,0,0,0
0,0,0,0,0,0,0,0,0,0,0,0,0,0,0,0
0,0,0,0,1,0,0,0,0,0,0,0,0,0,0,0
0,0,0,0,0,0,0,0,0,9,0,0,0,0,0,0
0,0,0,0,0,0,0,0,0,0,0,9,0,0,0,0
0,0,0,0,0,0,0,0,0,0,0,12,9,0,0,0
0,0,0,0,0,0,0,0,1,0,0,0,0,0,0,0
0,0,9,0,0,1,0,0,0,1,0,0,15,9,0,0
0,0,0,0,0,0,0,0,0,1,0,0,0,27,0,0
0,0,0,0,0,0,0,0,0,0,1,0,0,27,0,0
0,0,9,0,0,0,0,0,0,1,0,0,0,9,0,0
0,0,0,0,0,0,0,0,0,0,0,0,0,0,0,0
0,0,0,9,0,0,0,0,0,0,0,0,0,0,0,0
0,0,0,0,9,0,0,0,0,0,0,9,0,0,0,0
0,0,0,0,0,0,9,0,0,9,0,0,0,0,0,0
0,0,0,0,0,0,0,0,0,12,0,0,0,0,0,0
0,0,0,0,0,0,0,0,0,0,0,0,0,0,0,0
endlayer

layer
0,0,0,0,0,0,0,0,0,0,0,0,0,0,0,0
0,0,0,0,0,0,0,0,0,0,0,0,0,0,0,0
0,0,0,0,0,0,0,0,0,0,0,0,0,0,0,0
0,0,0,0,0,0,0,0,0,0,0,0,0,0,0,0
0,0,0,0,0,0,0,0,0,0,0,0,0,0,0,0
0,0,0,0,0,0,0,0,0,0,0,0,0,0,0,0
0,0,0,0,0,0,0,0,0,0,0,0,0,0,0,0
0,0,0,0,0,0,0,0,0,0,0,0,0,0,0,0
0,0,0,0,0,0,0,0,0,0,0,0,0,0,0,0
0,0,0,0,0,0,0,0,0,0,0,0,0,0,0,0
0,0,0,0,0,0,1,0,0,0,0,0,0,0,0,0
0,0,0,0,0,0,0,0,0,0,0,0,0,0,0,0
0,0,0,0,0,0,0,0,0,0,0,0,0,0,0,0
0,0,0,0,0,0,0,0,0,0,0,0,0,0,0,0
0,0,0,0,0,0,0,0,0,0,0,0,0,0,0,1
0,0,0,0,0,0,0,0,0,0,0,0,0,0,0,0
0,0,0,0,0,1,0,0,0,0,0,0,0,0,0,0
endlayer

layer
0,0,0,0,0,0,0,0,0,0,0,0,0,0,0,0
0,0,0,0,0,0,0,0,0,0,0,0,0,0,0,0
0,0,0,0,0,0,0,0,0,0,0,0,0,0,0,0
0,0,0,0,0,0,0,0,0,0,0,0,0,0,0,0
0,0,0,0,0,0,0,0,0,0,0,0,0,0,0,0
0,0,0,0,0,0,0,0,0,0,0,0,0,0,0,0
0,0,0,0,1,0,0,0,0,0,0,0,0,0,0,0
0,0,0,0,0,1,0,1,0,0,0,0,0,0,0,0
0,0,0,0,0,0,0,0,0,0,0,0,0,0,0,0
0,0,0,0,0,0,0,0,0,0,0,0,0,0,0,0
0,0,0,0,0,0,0,0,0,0,0,0,0,0,0,0
0,0,0,0,0,0,0,0,0,0,0,0,0,0,0,0
0,0,0,0,0,0,0,0,0,0,0,0,0,0,0,0
0,0,0,0,0,0,0,0,0,0,0,0,0,0,0,0
0,0,0,0,0,0,0,0,0,0,0,0,0,0,0,0
0,0,0,0,0,0,0,0,0,0,0,0,0,0,0,0
0,0,0,0,0,0,0,0,0,0,0,0,0,0,0,0
endlayer

layer
0,0,0,0,0,0,0,0,0,0,0,0,0,0,0,0
0,0,0,0,0,0,0,0,0,0,0,0,0,0,0,0
0,0,0,0,0,0,0,0,0,0,0,0,0,0,0,0
0,0,0,0,0,0,0,0,0,0,0,0,0,0,0,0
0,0,0,0,0,0,0,0,0,0,0,0,0,0,0,0
0,0,0,0,0,0,0,0,0,0,0,0,0,0,0,0
0,0,0,0,0,0,0,0,0,0,0,0,0,0,0,0
0,0,0,0,0,0,0,0,0,0,0,0,0,0,0,0
0,0,0,0,0,0,0,0,0,0,0,0,0,0,0,0
0,0,0,0,0,0,0,0,0,0,0,0,0,0,0,0
0,0,0,0,0,0,0,0,0,0,0,0,0,0,0,0
0,0,0,0,0,0,0,0,0,0,0,0,0,0,0,0
0,0,0,0,0,0,0,0,0,0,0,0,0,0,0,0
0,0,0,0,0,0,0,0,0,0,0,0,0,0,0,0
0,0,0,0,0,0,0,0,0,0,0,0,0,0,0,0
0,0,0,0,0,0,0,0,0,0,0,0,0,0,0,0
0,0,0,0,0,0,0,0,0,0,0,0,0,0,0,0
endlayer

layer
0,0,0,0,0,0,0,0,0,0,0,0,0,0,0,0
0,0,0,0,0,0,0,0,0,0,0,0,0,0,0,0
0,0,0,0,0,0,0,0,0,0,0,0,0,0,0,0
0,0,0,0,0,0,0,0,0,0,0,0,0,0,0,0
0,0,0,0,0,0,0,0,0,0,0,0,0,0,0,0
0,0,0,0,0,0,0,0,0,0,0,0,0,0,0,0
0,0,0,0,0,0,0,0,0,0,0,1,0,0,0,0
0,0,0,0,0,0,1,0,0,0,0,0,0,0,0,0
0,0,0,0,0,0,0,0,0,0,0,0,0,0,0,0
0,0,0,0,0,0,0,0,0,0,0,0,0,0,0,0
0,0,0,0,0,0,0,0,0,0,0,0,0,0,0,0
0,0,0,0,0,0,0,0,0,0,0,0,0,0,0,0
0,0,0,0,0,0,0,0,0,0,0,0,0,0,0,0
0,0,0,0,0,0,0,0,0,0,0,0,0,0,0,0
0,0,0,0,0,0,0,0,0,0,0,0,0,0,0,0
0,0,0,0,0,0,0,0,0,0,0,0,0,0,0,0
0,0,0,0,0,0,0,0,0,0,0,0,0,0,0,0
endlayer

layer
0,0,0,0,0,0,0,0,0,0,0,0,0,0,0,0
0,0,0,0,0,0,0,0,0,0,0,0,0,0,0,0
0,0,0,0,0,0,0,0,0,0,0,0,0,0,0,0
0,0,0,0,0,0,0,0,0,0,0,0,0,0,0,0
0,0,0,0,0,0,0,0,0,0,0,0,0,0,0,0
0,0,0,0,0,0,0,0,0,0,0,0,0,0,0,0
0,0,0,0,0,1,0,0,0,0,0,0,0,0,0,0
0,0,0,0,0,0,0,0,0,0,0,0,0,0,0,0
0,0,0,0,0,0,0,0,0,0,0,0,0,0,0,0
0,0,0,0,0,0,0,0,0,0,0,0,0,0,0,0
0,0,0,0,0,0,0,0,0,0,0,0,0,0,0,0
0,0,0,0,0,0,0,0,0,0,0,0,0,0,0,0
0,0,0,0,0,0,0,0,0,0,0,0,0,0,0,0
0,0,0,0,0,0,0,0,0,0,0,0,0,0,0,0
0,0,0,0,0,0,0,0,0,0,0,0,0,0,0,0
0,0,0,0,0,0,0,0,0,0,0,0,0,0,0,0
0,0,0,0,0,0,0,0,0,0,0,0,0,0,0,0
endlayer

layer
0,0,0,0,0,0,0,0,0,0,0,0,0,0,0,0
0,0,0,0,0,0,0,0,0,0,0,0,0,0,0,0
0,0,0,0,0,0,0,0,0,0,0,0,0,0,0,0
0,0,0,0,0,0,0,0,0,0,0,0,0,0,0,0
0,0,0,0,0,0,0,0,0,0,0,0,0,0,0,0
0,0,0,0,0,0,0,0,0,0,0,0,0,0,0,0
0,0,0,0,0,1,0,0,0,0,0,0,0,0,0,0
0,0,0,0,0,0,0,0,0,0,0,0,0,0,0,0
0,0,0,0,0,0,0,0,0,0,0,0,0,0,0,0
0,0,0,0,0,0,0,0,0,0,0,0,0,0,0,0
0,0,0,0,0,0,0,0,0,0,0,0,0,0,0,0
0,0,0,0,0,0,0,0,0,0,0,0,0,0,0,0
0,0,0,0,0,0,0,0,0,0,0,0,0,0,0,0
0,0,0,0,0,0,0,0,0,0,0,0,0,0,0,0
0,0,0,0,0,0,0,0,0,0,0,0,0,0,0,0
0,0,0,0,0,0,0,0,0,0,0,0,0,0,0,0
0,0,0,0,0,0,0,0,0,0,0,0,0,0,0,0
endlayer

