
# Created by Ruins mod version 14.6 Ingame Parser
# authoring Player: ArchNihil

weight=1
embed_into_distance=0
acceptable_target_blocks=
unacceptable_target_blocks=flowing_water,water,flowing_lava,lava
dimensions=169,34,42
allowable_overhang=0
max_leveling=2
leveling_buffer=0
preserve_water=0
preserve_lava=0

rule1=0,100,Railcraft:tile.railcraft.residual.heat-0
rule2=0,100,minecraft:tallgrass-1
rule3=0,100,BiomesOPlenty:foliage-14
rule4=0,100,BiomesOPlenty:foliage-10
rule5=0,100,BiomesOPlenty:foliage-2
rule6=0,100,BiomesOPlenty:foliage-11
rule7=0,100,TwilightForest:tile.TFFirefly-5
rule8=0,100,Natura:Thornvines-8
rule9=0,100,minecraft:leaves-5
rule10=0,100,minecraft:planks-5
rule11=0,100,minecraft:leaves-6
rule12=0,100,minecraft:leaves-13
rule13=0,100,Natura:Thornvines-4
rule14=0,100,minecraft:vine-8
rule15=0,100,minecraft:log-0
rule16=0,100,BiomesOPlenty:planks-9
rule17=0,100,ExtraUtilities:colorWoodPlanks-13
rule18=0,100,minecraft:vine-4
rule19=0,100,ExtraUtilities:colorWoodPlanks-5
rule20=0,100,BiomesOPlenty:logs1-5
rule21=0,100,BiomesOPlenty:logs1-9
rule22=0,100,BiomesOPlenty:logs1-1
rule23=0,100,Natura:Thornvines-1
rule24=0,100,minecraft:log-4
rule25=0,100,minecraft:grass-0
rule26=0,100,MobSpawner:Spider
rule27=0,100,Natura:Thornvines-12
rule28=0,100,BiomesOPlenty:planks-1
rule29=0,100,minecraft:water-2
rule30=0,100,minecraft:water-3
rule31=0,100,minecraft:log-8
rule32=0,100,minecraft:leaves-12
rule33=0,100,minecraft:water-1
rule34=0,100,minecraft:water-0
rule35=0,100,minecraft:dirt-0
rule36=0,100,BiomesOPlenty:logs3-1
rule37=0,100,BiomesOPlenty:cherryStairs-3
rule38=0,100,minecraft:wooden_door-3
rule39=0,100,BiomesOPlenty:cherryStairs-2
rule40=0,100,BiomesOPlenty:woodenDoubleSlab1-1
rule41=0,100,Natura:Thornvines-2
rule42=0,100,MobSpawner:Witch
rule43=0,100,Natura:Thornvines-3
rule44=0,100,TwilightForest:tile.TFFirefly-2
rule45=0,100,Natura:Thornvines-0
rule46=0,100,minecraft:leaves-14
rule47=0,100,minecraft:vine-1
rule48=0,100,TwilightForest:tile.TFPlant-3
rule49=0,100,BiomesOPlenty:moss-0
rule50=0,100,minecraft:fence-0
rule51=0,100,BiomesOPlenty:moss-8
rule52=0,100,BiomesOPlenty:moss-11
rule53=0,100,minecraft:wooden_door-1
rule54=0,100,minecraft:wooden_door-8
rule55=0,100,MobSpawner:Creeper
rule56=0,100,minecraft:dark_oak_stairs-3
rule57=0,100,Natura:Thornvines-14
rule58=0,100,minecraft:wooden_door-2
rule59=0,100,minecraft:vine-2
rule60=0,100,TwilightForest:tile.TFFirefly-1
rule61=0,100,minecraft:vine-0
rule62=0,100,minecraft:vine-9
rule63=0,100,Natura:BerryBush-12
rule64=0,100,BiomesOPlenty:moss-1
rule65=0,100,BiomesOPlenty:moss-2
rule66=0,100,TConstruct:GlassBlock-0
rule67=0,100,minecraft:leaves-0
rule68=0,100,TwilightForest:tile.TFFirefly-4
rule69=0,100,BiomesOPlenty:flowerVine-9
rule70=0,100,TwilightForest:tile.TFFirefly-3
rule71=0,100,minecraft:tallgrass-0
rule72=0,100,Natura:BerryBush-0
rule73=0,100,Natura:BerryBush-9
rule74=0,100,Natura:Thornvines-6
rule75=0,100,Natura:BerryBush-8
rule76=0,100,Natura:BerryBush-14
rule77=0,100,BiomesOPlenty:logs3-9
rule78=0,100,BiomesOPlenty:logs3-5
rule79=0,100,BiomesOPlenty:flowerVine-11
rule80=0,100,BiomesOPlenty:flowerVine-1
rule81=0,100,minecraft:vine-3
rule82=0,100,Natura:BerryBush-10
rule83=0,100,minecraft:planks-0
rule84=0,100,BiomesOPlenty:flowerVine-8
rule85=0,100,TwilightForest:tile.TFFirefly-6
rule86=0,100,minecraft:vine-7
rule87=0,100,BiomesOPlenty:cherryStairs-1
rule88=0,100,BiomesOPlenty:woodenSingleSlab1-1
rule89=0,100,MobSpawner:CaveSpider
rule90=0,100,BiomesOPlenty:flowerVine-2
rule91=0,100,TwilightForest:tile.TFPlant-9
rule92=0,100,BiomesOPlenty:flowerVine-10
rule93=0,100,BiomesOPlenty:flowers2-4
rule94=0,100,minecraft:yellow_flower-0
rule95=0,100,minecraft:dark_oak_stairs-1
rule96=0,100,BiomesOPlenty:moss-14
rule97=0,100,minecraft:wooden_slab-13
rule98=0,100,minecraft:leaves-4
rule99=0,100,BiomesOPlenty:flowerVine-6
rule100=0,100,BiomesOPlenty:cherryStairs-0
rule101=0,100,BiomesOPlenty:flowerVine-4
rule102=0,100,BiomesOPlenty:flowerVine-0
rule103=0,100,BiomesOPlenty:moss-4
rule104=0,100,minecraft:brown_mushroom-0
rule105=0,100,minecraft:double_wooden_slab-5
rule106=0,100,minecraft:wooden_slab-5
rule107=0,100,minecraft:vine-6
rule108=0,100,ChestGenHook:dungeonChest:5-5
rule109=0,100,BiomesOPlenty:colorizedLeaves2-0
rule110=0,100,BiomesOPlenty:moss-3
rule111=0,100,minecraft:dark_oak_stairs-0
rule112=0,100,minecraft:vine-12
rule113=0,100,MobSpawner:Skeleton
rule114=0,100,ChestGenHook:dungeonChest:5-3
rule115=0,100,ChestGenHook:dungeonChest:5-2
rule116=0,100,minecraft:bed-3
rule117=0,100,minecraft:bed-11
rule118=0,100,minecraft:vine-10
rule119=0,100,Natura:Cloud-0

layer
1,0,0,1,1,0,0,1,0,0,1,1,0,1,0,1,1,0,1,0,1,0,1,1,0,1,1,0,1,0,1,1,1,1,0,1,0,1,1,0,0,1
0,5,0,5,5,0,2,0,5,0,5,0,0,0,2,0,0,2,0,0,0,2,2,2,2,2,0,2,2,2,4,2,0,0,2,0,2,3,0,2,0,0
0,5,1,0,0,0,0,0,0,0,0,0,0,0,0,0,0,0,0,0,0,0,0,0,0,0,0,0,0,0,0,0,0,0,0,0,0,0,0,0,0,1
0,6,1,0,0,0,0,1,0,0,0,0,0,0,0,1,0,0,0,0,0,0,0,0,0,0,0,0,0,0,0,0,0,1,0,0,0,0,0,0,0,1
1,0,0,0,0,0,0,0,0,0,0,0,0,0,0,1,0,0,0,0,0,0,0,0,0,0,0,0,0,0,0,0,0,0,0,0,0,0,0,0,0,0
1,1,0,0,0,0,0,1,0,0,1,1,0,0,0,0,0,1,1,1,0,1,1,0,0,0,0,0,0,0,0,0,0,0,0,1,0,0,0,0,0,0
1,0,0,0,0,0,0,1,0,1,0,0,1,0,1,0,1,0,1,8,0,0,0,1,0,1,1,0,0,0,0,1,1,0,7,0,0,0,0,0,0,1
0,0,0,0,0,0,0,0,8,8,8,8,0,0,0,10,1,0,0,9,8,1,1,1,0,0,0,0,0,1,0,0,0,0,7,0,1,0,0,0,0,1
0,0,0,0,1,0,0,13,12,9,12,0,8,8,8,8,8,11,9,9,9,8,8,0,1,7,8,8,8,0,0,0,0,0,1,0,0,0,0,1,0,1
1,5,0,0,1,1,0,12,12,9,12,12,12,12,12,9,9,9,12,9,9,9,9,8,8,9,9,9,9,9,9,1,0,0,0,0,0,0,0,0,0,1
1,0,0,0,1,1,13,9,9,9,9,9,12,12,9,9,9,9,12,12,9,9,9,9,9,9,9,9,9,9,9,9,0,1,0,0,0,0,0,14,0,1
0,5,0,0,1,13,9,9,9,9,9,9,9,9,9,9,9,7,9,9,9,9,9,9,9,9,9,9,9,9,9,9,9,9,0,1,1,0,0,0,0,1
0,5,0,0,1,18,9,9,15,17,17,17,15,17,17,16,16,15,12,12,12,9,12,12,12,12,12,12,12,12,12,9,9,9,9,1,1,0,0,0,0,1
1,6,0,0,0,13,9,9,19,22,21,21,22,21,21,21,20,19,15,12,12,12,12,12,12,12,12,12,12,12,12,9,9,9,12,9,1,1,0,0,0,0
1,0,0,0,0,27,13,12,19,20,0,0,26,0,0,0,20,19,24,15,25,15,24,12,12,12,12,12,7,12,12,12,12,9,12,12,23,1,0,0,0,0
1,0,0,8,13,28,32,25,19,20,0,0,7,0,0,0,20,19,15,31,31,29,30,29,28,28,28,28,12,12,12,12,12,9,9,9,23,0,0,0,0,1
0,0,8,28,28,28,24,35,19,20,0,0,0,0,1,0,20,16,33,34,34,33,29,33,29,28,26,28,0,12,12,12,12,12,12,12,23,0,0,0,0,0
1,13,28,28,28,28,28,28,28,22,0,0,22,1,0,0,22,36,15,15,31,31,33,34,33,28,22,28,15,12,12,12,12,12,12,12,23,0,0,1,0,1
1,13,28,28,28,28,0,0,0,21,0,0,0,0,0,0,21,22,21,21,21,31,15,31,31,28,22,28,12,12,12,0,7,12,12,12,23,23,1,0,0,0
1,0,28,28,28,39,0,0,0,0,0,0,0,0,0,0,38,1,0,0,1,37,28,28,28,28,22,28,12,12,12,12,12,12,12,12,23,23,0,0,0,1
0,0,28,28,28,28,0,0,0,21,0,0,0,0,0,1,21,22,21,21,21,21,35,35,35,28,22,28,15,12,12,12,12,12,12,23,0,1,0,0,0,0
1,0,28,28,28,28,28,28,28,22,0,0,22,0,1,0,22,22,35,35,35,31,31,31,35,28,26,28,10,12,12,12,12,12,12,1,0,1,0,0,0,0
1,0,40,28,28,28,28,35,21,20,0,0,0,0,0,0,20,16,35,35,35,35,35,35,0,28,28,28,12,12,12,12,12,12,23,0,1,0,0,0,0,1
0,0,40,28,28,28,28,25,21,20,0,0,0,0,0,0,20,16,35,25,25,35,35,0,12,12,28,12,12,12,12,12,12,23,0,1,0,1,1,0,0,1
0,0,12,12,12,12,28,0,0,0,7,0,42,0,0,0,20,21,25,25,25,25,0,0,12,12,12,12,12,12,12,12,41,1,0,0,0,0,0,0,0,0
0,0,9,9,9,9,9,0,9,9,21,21,22,21,21,21,22,16,25,25,25,25,0,12,12,12,12,12,12,12,12,23,0,1,1,0,0,0,0,0,0,1
0,0,11,9,9,9,9,9,9,9,0,20,15,20,20,20,16,35,35,25,15,25,0,9,9,9,12,12,12,12,23,7,0,0,0,7,0,0,0,0,0,0
1,0,0,0,11,9,9,9,9,12,9,9,0,0,25,25,25,35,35,31,15,15,25,24,9,9,9,9,9,41,0,0,0,0,0,0,0,0,0,0,0,1
1,0,0,0,41,11,9,9,9,9,9,9,9,9,25,25,0,0,9,0,15,25,31,9,9,9,9,9,41,0,0,0,0,0,0,0,0,0,0,0,0,0
1,0,0,0,0,13,11,9,9,9,9,9,9,9,25,0,9,9,9,9,9,15,9,9,9,9,9,41,0,0,0,0,0,0,0,0,0,7,0,0,0,1
0,0,0,0,0,0,13,11,11,9,9,9,9,9,9,9,43,41,9,9,24,9,9,9,41,41,41,0,0,0,0,0,0,0,0,0,0,0,0,0,0,1
1,0,0,0,0,1,0,41,1,11,9,9,9,9,9,41,0,0,41,9,9,9,41,0,0,0,0,0,0,0,0,0,0,0,0,0,0,0,0,0,0,0
0,0,0,0,0,0,0,0,1,41,41,41,41,41,41,0,0,1,1,41,1,41,1,0,0,0,0,0,0,0,0,0,0,0,0,0,1,0,0,0,0,1
1,1,0,1,0,1,0,0,0,1,1,0,1,0,1,1,1,1,0,1,0,1,1,0,1,0,0,1,0,0,0,1,0,1,0,0,0,0,0,0,0,1
endlayer

layer
0,0,0,0,0,0,0,0,0,0,0,0,0,0,0,0,0,0,0,0,0,0,0,0,0,0,0,0,0,0,0,0,0,0,0,0,0,0,0,0,0,0
0,0,0,0,0,0,0,0,0,0,0,0,0,0,0,0,0,0,0,0,0,0,0,0,0,0,0,0,0,0,0,0,0,0,0,0,0,0,0,0,0,0
0,0,0,0,0,0,0,0,0,0,0,0,0,0,0,0,0,0,0,0,0,0,0,0,0,0,0,0,0,0,0,0,0,0,0,0,0,0,0,0,0,0
0,0,0,0,0,0,0,0,0,0,0,0,0,0,0,0,0,0,0,0,0,0,0,0,0,0,0,0,0,0,0,0,0,0,0,0,0,0,0,0,0,0
0,0,0,0,0,0,0,0,0,0,0,0,0,0,0,0,0,0,0,0,0,0,0,0,0,0,0,0,0,0,0,0,0,0,0,0,0,0,0,0,0,0
0,0,0,0,0,0,0,0,0,0,0,0,0,0,0,0,0,0,0,0,0,0,0,0,0,0,0,0,0,1,0,0,0,0,0,0,0,0,0,0,0,0
0,0,0,0,0,0,0,0,0,0,0,0,0,0,0,0,0,0,0,0,0,0,0,0,0,1,0,0,0,0,0,0,0,0,0,0,0,0,0,0,0,0
0,0,0,0,0,0,0,0,8,8,8,8,0,0,0,0,0,0,0,8,1,0,0,1,0,0,0,0,0,0,0,0,0,1,0,0,0,0,0,0,0,0
0,0,0,0,0,0,0,0,32,32,32,0,0,0,0,8,14,44,8,9,8,14,0,0,0,1,0,0,0,0,0,0,0,14,0,1,0,0,0,0,0,0
0,0,0,0,0,0,0,13,12,32,0,45,8,8,0,8,0,11,12,9,12,1,1,0,0,0,8,0,44,0,0,0,0,0,0,0,0,0,0,0,0,0
0,0,0,0,0,0,13,9,9,32,32,8,12,12,12,12,46,46,12,12,12,0,8,7,8,8,12,12,12,9,9,8,1,0,0,1,0,0,0,14,0,0
0,1,0,0,0,0,13,9,9,32,32,9,9,20,20,20,12,12,12,12,12,12,12,12,12,12,12,12,12,9,9,9,23,0,0,0,0,1,0,0,0,0
0,0,0,0,0,0,13,9,15,17,20,20,15,20,20,20,16,15,12,12,12,12,12,12,12,12,12,12,12,12,12,9,9,44,0,0,0,0,0,0,0,0
0,0,0,0,0,13,9,24,16,22,0,0,22,0,0,0,22,19,25,15,12,12,12,12,12,12,12,12,12,12,12,9,9,9,23,0,0,0,0,0,0,0
0,0,0,0,0,13,32,21,21,0,0,0,0,0,0,0,0,21,21,24,48,48,48,12,12,21,21,21,12,12,12,9,9,9,9,23,0,0,47,0,0,0
0,0,0,0,13,50,32,32,21,0,0,0,0,0,0,0,0,21,15,15,49,49,15,0,20,0,0,0,20,12,12,12,12,9,9,23,1,0,0,0,0,0
0,0,8,50,50,50,32,20,21,0,0,0,0,0,0,0,0,21,21,52,51,0,0,0,20,0,0,0,20,12,12,12,12,12,12,23,0,0,0,0,0,0
0,13,50,50,48,32,28,28,28,22,0,0,22,0,0,0,22,36,15,31,31,0,0,0,20,0,0,1,20,12,12,12,12,12,45,0,0,0,0,0,0,0
0,13,50,48,48,28,0,0,0,21,0,0,0,0,0,0,21,22,21,21,21,21,21,21,22,0,0,1,22,12,12,12,12,12,23,0,23,23,0,0,0,0
0,0,50,48,48,1,0,0,0,0,0,0,0,0,0,0,54,0,0,0,0,0,0,0,53,0,1,0,20,12,12,12,12,12,23,0,0,23,0,0,0,0
0,1,50,48,55,28,0,0,0,21,0,0,0,0,0,0,21,22,21,21,21,21,21,21,22,0,0,1,22,10,12,12,12,12,23,23,0,0,0,0,0,0
0,1,50,48,0,46,28,28,28,22,0,0,22,0,0,0,22,22,35,35,15,10,46,0,20,0,0,0,56,10,12,12,12,12,23,1,0,0,0,0,0,0
0,0,50,48,48,48,57,28,21,0,0,0,0,0,0,0,0,21,35,35,31,31,31,31,20,0,0,1,20,10,12,12,12,23,41,0,0,0,0,0,0,0
0,0,50,48,48,48,28,32,21,0,0,0,0,0,0,0,0,21,25,59,59,25,31,15,22,22,58,22,22,12,12,12,41,0,0,1,0,0,0,0,0,0
0,0,50,50,50,28,28,32,21,0,0,0,0,0,0,0,0,21,0,61,32,60,31,24,12,32,47,32,32,12,12,41,0,0,0,0,0,0,0,0,0,0
0,0,0,13,12,12,9,9,17,22,0,0,22,0,0,0,22,16,62,61,7,0,32,24,32,41,47,12,41,41,41,0,0,0,0,0,0,0,0,0,0,0
0,0,0,0,41,12,9,9,15,19,20,20,15,20,20,20,16,15,25,32,32,32,32,24,32,9,47,12,0,0,0,0,0,0,0,0,0,0,0,0,0,0
0,0,0,0,0,60,9,9,9,0,32,32,32,32,32,32,32,25,25,32,15,32,32,32,32,9,23,41,0,0,0,0,0,0,0,0,0,0,0,0,0,0
0,0,0,0,0,0,41,60,9,9,0,32,32,32,32,32,32,32,32,32,32,32,32,32,63,9,23,1,0,0,0,0,0,0,0,0,0,0,0,0,0,0
0,0,0,1,0,0,13,11,11,9,9,9,32,32,32,32,32,32,9,9,32,32,32,9,9,9,23,0,0,0,0,0,0,0,0,0,0,0,0,0,0,0
0,0,0,0,0,0,0,41,41,11,9,9,32,32,32,32,23,41,41,9,32,9,41,41,41,41,0,0,0,0,0,0,0,0,0,0,0,0,0,0,0,0
0,0,0,0,0,0,0,0,0,41,41,41,41,0,41,41,0,0,0,41,41,41,0,0,0,0,0,0,0,0,0,0,0,0,0,0,0,0,0,0,0,0
0,0,0,0,0,0,1,1,0,0,1,0,0,0,0,0,0,0,1,1,1,0,0,0,0,0,0,0,0,0,0,0,0,0,0,0,0,0,0,0,0,0
0,0,0,0,0,0,0,0,0,0,0,0,0,0,0,0,0,0,0,0,0,0,0,0,0,0,0,0,0,0,0,0,0,0,0,0,0,0,0,0,0,0
endlayer

layer
0,0,0,0,0,0,0,0,0,0,0,0,0,0,0,0,0,0,0,0,0,0,0,0,0,0,0,0,0,0,0,0,0,0,0,0,0,0,0,0,0,0
0,0,0,0,0,0,0,0,0,0,0,0,0,0,0,0,0,0,0,0,0,0,0,0,0,0,0,0,0,0,0,0,0,0,0,0,0,0,0,0,0,0
0,0,0,0,0,0,0,0,0,0,0,0,0,0,0,0,0,0,0,0,0,0,0,0,1,0,0,0,0,0,0,0,0,0,0,0,0,0,0,0,0,0
0,0,0,0,0,0,0,0,0,0,0,0,0,0,0,0,0,0,0,0,0,0,0,1,0,0,0,0,0,0,0,0,0,0,0,0,0,0,0,0,0,0
0,0,0,0,0,0,0,0,0,0,0,0,0,0,0,0,0,0,0,0,0,0,0,0,0,0,0,0,1,0,0,0,0,0,0,0,0,0,0,0,0,0
0,0,0,0,0,0,0,0,0,0,0,0,0,0,0,0,0,0,0,0,0,0,0,0,0,0,0,0,0,0,0,0,0,0,0,0,0,0,0,0,0,0
0,0,0,0,0,0,0,0,0,0,0,0,0,0,0,0,0,0,0,0,0,1,0,0,0,0,0,0,1,0,0,0,0,0,0,0,0,0,0,0,0,0
0,0,0,0,0,0,0,0,0,0,8,8,0,0,0,0,0,0,0,0,0,0,0,0,0,0,0,0,0,1,0,0,0,0,0,0,0,0,0,0,0,0
0,0,0,0,0,0,0,0,13,32,32,32,0,0,0,8,14,8,8,14,14,14,0,0,0,0,0,0,0,1,0,1,0,14,0,1,0,0,0,0,0,0
0,0,0,0,0,0,0,0,32,32,32,32,0,8,0,12,0,27,8,12,0,0,1,0,0,0,0,0,0,0,1,0,14,0,0,0,0,0,0,0,0,0
0,0,0,0,0,0,0,13,32,32,32,32,12,12,0,0,46,46,12,12,12,0,8,0,8,8,8,0,8,8,8,8,0,0,0,1,0,0,1,14,0,0
0,0,0,0,0,0,0,9,32,32,32,32,9,32,12,32,15,12,12,12,12,12,12,12,12,12,12,12,12,12,12,9,23,0,1,0,0,0,0,0,0,0
0,0,0,0,0,0,13,9,15,16,20,20,15,20,20,20,16,15,12,15,64,12,12,12,12,12,12,12,12,12,12,9,9,0,0,0,0,0,0,0,0,0
0,0,0,0,0,13,9,15,16,22,0,0,22,0,0,0,22,19,0,65,0,12,12,12,12,12,12,28,12,12,12,12,9,9,23,0,0,0,0,0,1,0
0,0,0,0,0,0,13,21,21,0,0,0,0,0,0,0,0,21,21,0,67,67,67,0,67,22,66,22,22,12,12,12,9,9,9,23,0,0,47,0,0,0
0,0,0,0,13,13,32,21,21,0,0,0,0,0,0,0,0,21,15,69,67,67,15,67,22,0,0,0,22,35,12,0,12,12,9,68,0,0,0,0,0,0
0,0,8,0,0,18,32,32,21,0,0,0,0,0,0,0,0,21,21,24,67,67,67,60,0,0,0,0,66,35,0,12,0,12,12,23,0,0,0,0,0,0
0,13,0,0,0,0,28,28,28,22,0,0,22,0,0,0,22,36,15,15,31,67,67,67,66,0,0,0,66,70,15,12,12,12,12,0,0,0,0,1,0,0
0,13,0,1,18,28,0,0,0,21,0,0,0,0,0,0,21,17,31,21,21,21,21,21,22,0,0,0,22,31,31,15,12,12,12,12,23,23,0,0,0,0
0,0,0,0,18,0,0,0,0,21,0,0,0,0,0,70,21,20,31,68,0,0,0,0,54,0,0,0,66,0,10,0,24,12,12,12,68,23,0,0,0,0
0,0,1,0,18,28,0,0,0,21,0,0,0,0,0,0,21,16,31,21,21,21,21,21,22,0,0,0,22,10,10,12,12,12,0,23,0,0,0,1,0,0
0,0,1,0,46,46,28,28,28,22,0,0,22,0,0,0,22,22,24,31,31,10,32,0,66,0,0,0,0,56,10,12,12,10,47,0,0,1,0,0,0,0
0,0,0,0,0,41,57,28,21,0,0,0,60,0,0,0,0,21,24,24,15,0,0,15,66,0,0,0,66,10,10,12,60,59,41,0,0,1,0,0,0,0
0,0,0,0,0,44,28,28,21,0,0,0,0,0,0,0,0,21,32,60,32,32,15,35,22,22,54,22,22,32,32,0,0,0,0,0,1,0,0,0,0,0
0,0,0,0,11,28,28,32,21,0,0,0,0,0,0,0,0,21,21,32,32,32,32,15,12,32,47,32,32,32,60,0,0,0,0,0,0,0,0,0,0,0
0,0,0,0,11,12,9,9,17,22,0,0,22,0,0,0,22,16,32,32,0,32,32,32,12,41,61,12,41,41,0,0,0,0,0,0,0,0,0,0,0,0
0,0,0,0,0,9,9,9,15,19,20,20,15,20,20,20,16,36,32,7,32,32,32,32,9,9,43,0,0,0,0,1,0,0,0,0,0,0,0,0,0,0
0,0,0,0,0,41,41,9,9,9,32,32,32,32,32,32,32,71,32,32,32,32,32,9,9,41,0,0,0,0,0,0,0,0,0,0,0,0,0,0,0,0
0,0,0,1,0,1,1,41,9,9,32,32,32,32,32,32,32,32,32,0,32,32,32,68,72,0,0,0,0,0,0,0,0,0,0,1,0,0,0,0,0,0
0,0,0,0,0,0,0,0,0,74,73,9,32,32,32,32,0,0,0,12,9,9,0,7,0,0,0,0,0,0,0,0,0,0,0,0,0,0,0,0,0,0
0,0,0,0,0,1,0,0,0,0,0,41,9,9,9,41,0,75,0,0,12,23,0,0,0,0,0,0,0,0,0,0,0,1,0,0,0,0,0,0,0,0
0,0,0,0,0,0,0,0,0,0,0,0,0,60,0,0,0,0,0,0,41,0,0,0,0,0,0,0,0,0,0,0,0,0,0,0,0,0,0,0,0,0
0,0,0,0,0,0,0,0,0,0,0,0,0,0,0,0,1,0,0,0,0,0,0,0,0,0,0,0,0,0,0,0,0,0,0,0,0,0,0,0,0,0
0,0,0,0,0,0,0,0,0,0,0,0,0,0,0,0,0,0,0,0,0,0,0,0,0,0,0,0,0,0,0,0,0,0,0,0,0,0,0,0,0,0
endlayer

layer
0,0,0,0,0,0,0,0,0,0,0,0,0,0,0,0,0,0,0,0,0,0,0,0,0,0,0,0,0,0,0,0,0,0,0,0,0,0,0,0,0,0
0,0,0,0,0,0,0,0,0,0,0,0,0,0,0,0,0,0,0,0,0,0,0,0,0,0,0,0,0,0,0,0,0,0,0,0,0,0,0,0,0,0
0,0,0,0,0,0,0,0,0,0,0,0,0,0,0,0,0,0,0,0,0,0,0,0,0,0,0,0,0,0,0,0,0,0,0,0,0,0,0,0,0,0
0,0,0,0,0,0,0,0,0,0,0,0,0,0,0,0,0,0,0,0,0,0,0,0,0,0,0,0,0,0,0,0,0,0,0,0,0,0,0,0,0,0
0,0,0,0,0,0,0,0,0,0,0,0,0,0,0,0,0,0,0,0,0,0,0,0,0,0,0,0,0,0,0,0,0,0,0,0,0,0,0,0,0,0
0,0,0,0,0,0,0,0,0,0,0,0,0,0,0,0,1,0,0,0,0,0,0,0,0,0,0,0,0,0,0,0,0,0,0,0,0,0,0,0,0,0
0,0,0,0,0,0,0,0,0,0,0,0,0,0,0,0,0,0,0,0,0,0,0,0,0,0,0,0,0,0,0,1,0,0,0,0,0,0,0,0,0,0
0,0,0,0,0,0,0,0,0,0,0,0,0,0,0,0,1,0,0,0,0,0,0,0,0,1,0,0,0,1,0,1,1,0,0,0,0,0,0,0,0,0
0,0,0,0,0,0,0,0,0,0,0,0,0,0,0,0,14,8,8,14,14,14,0,0,0,0,0,0,0,0,0,1,1,14,1,0,0,0,0,0,0,0
0,0,0,0,0,0,0,0,0,0,0,7,76,8,0,0,0,27,8,12,0,0,1,0,1,0,0,1,0,1,1,0,14,1,0,1,0,0,0,0,0,0
0,0,0,0,0,0,0,70,32,14,14,32,0,32,32,46,46,12,12,12,12,0,12,0,0,0,8,0,8,8,8,0,1,0,0,0,0,0,0,14,0,0
0,0,0,0,0,0,0,8,32,32,32,25,25,32,32,32,15,12,12,12,12,12,12,12,12,12,12,12,12,12,12,9,23,0,0,0,0,0,0,0,0,0
0,0,0,0,0,61,0,9,15,31,31,31,15,77,77,77,77,15,31,31,64,12,15,12,12,12,12,12,12,12,12,9,9,0,0,0,0,0,0,0,0,0
0,0,0,0,0,13,32,15,24,22,21,21,78,21,21,21,22,78,65,65,0,67,67,67,67,12,12,12,12,12,12,12,9,12,9,0,0,0,0,0,0,0
0,0,0,0,0,0,0,18,78,20,0,0,20,0,0,0,20,78,79,0,67,67,67,67,67,22,21,22,12,35,12,0,12,12,12,0,0,0,47,0,0,0
0,0,0,0,13,13,32,18,78,20,0,0,20,0,0,0,20,78,15,80,67,67,15,67,22,0,0,0,20,35,35,12,12,0,12,12,0,0,0,1,0,0
0,0,8,0,0,18,61,18,78,20,0,0,20,0,0,0,20,78,46,80,67,67,67,67,20,0,0,0,20,35,31,12,12,31,12,12,0,0,0,0,0,0
0,13,0,0,0,0,28,35,36,77,77,77,15,21,21,21,77,15,15,15,67,67,67,67,20,0,0,0,20,15,15,15,15,24,31,12,0,0,0,0,0,0
0,13,0,0,18,28,28,28,28,20,0,0,78,0,0,0,20,78,15,31,46,32,46,46,22,0,0,0,22,15,15,15,15,24,31,15,12,23,0,0,0,0
0,0,0,0,18,28,28,28,28,20,0,0,78,0,0,0,20,78,15,31,21,21,21,21,20,0,0,70,20,15,24,24,24,24,15,12,61,23,0,0,0,0
0,0,0,0,11,28,28,28,28,20,0,0,78,0,0,0,20,24,15,31,15,32,32,32,22,0,0,0,22,81,56,10,15,15,12,23,61,0,0,0,0,0
0,0,0,0,11,46,28,32,24,77,21,21,15,21,21,21,21,15,15,15,24,10,0,0,20,0,0,0,46,41,56,10,10,10,0,0,0,0,0,0,0,0
0,0,0,0,0,41,57,28,24,20,0,0,24,0,0,0,20,24,15,15,15,0,0,7,20,0,0,46,20,46,10,10,10,10,41,0,0,0,0,0,0,0
0,0,0,0,0,11,28,28,24,20,0,0,24,0,0,0,20,24,32,32,32,0,0,15,22,21,21,21,22,32,0,0,0,0,0,0,0,0,0,0,0,0
0,0,0,0,11,28,28,35,24,20,0,0,24,0,0,0,20,24,81,59,32,0,32,32,12,32,32,32,32,60,0,0,0,0,0,0,0,0,0,0,0,0
0,0,0,0,11,28,9,9,24,22,21,21,24,21,21,21,22,24,32,32,32,12,32,0,12,41,12,0,0,0,0,0,0,0,0,1,0,0,0,0,0,0
0,0,0,0,0,11,9,9,15,31,31,31,36,77,77,77,77,36,32,32,32,32,12,12,9,47,41,0,0,0,0,0,0,0,0,0,0,0,0,0,0,0
0,0,0,0,0,0,0,0,9,0,0,32,32,32,32,32,32,32,9,13,32,32,9,41,1,0,0,0,41,0,0,0,0,0,0,0,0,0,0,0,0,0
0,0,0,0,0,0,0,0,59,59,32,32,32,32,32,32,32,32,32,0,59,9,0,0,0,0,0,41,0,0,0,0,0,0,0,0,0,0,0,0,0,0
0,0,0,0,0,1,1,0,0,13,9,0,9,9,9,9,0,0,0,59,41,0,0,0,0,0,1,0,0,0,0,0,0,0,0,0,0,0,0,0,0,0
0,0,0,0,0,0,0,0,0,0,0,0,0,0,0,0,0,0,0,0,0,0,0,0,0,0,0,0,0,0,0,0,0,0,0,0,0,0,0,0,0,0
0,0,0,0,0,0,0,0,1,1,0,0,0,0,0,0,0,0,0,0,0,0,0,0,0,0,0,0,0,0,0,0,0,0,0,0,0,0,0,0,0,0
0,0,0,0,0,0,0,0,0,0,0,0,0,0,1,0,0,0,0,0,0,0,0,0,0,0,0,0,0,0,0,0,0,0,0,0,0,0,0,0,0,0
0,0,0,0,0,0,0,0,0,0,0,0,0,0,0,0,0,0,0,0,0,0,0,0,0,0,0,0,0,0,0,0,0,0,0,0,0,0,0,0,0,0
endlayer

layer
0,0,0,0,0,0,0,0,0,0,0,0,0,0,0,0,0,0,0,0,0,0,0,0,0,0,0,0,0,0,0,0,0,0,0,0,0,0,0,0,0,0
0,0,0,0,0,0,0,0,0,0,0,0,0,0,0,0,1,0,0,0,0,0,0,0,0,0,0,0,0,0,0,0,0,0,0,0,0,0,0,0,0,0
0,0,0,0,0,0,0,0,0,0,0,0,0,0,0,0,0,0,0,0,0,0,0,0,0,0,0,0,0,0,0,0,0,0,0,0,1,0,0,0,0,0
0,0,0,0,0,0,0,0,0,0,0,0,0,0,1,0,0,0,0,0,0,0,0,0,0,0,0,0,0,0,0,0,0,0,0,0,0,0,0,0,0,0
0,0,0,0,0,0,0,0,0,0,0,0,0,0,0,0,0,0,0,0,0,0,0,0,0,0,0,0,0,0,0,0,0,0,0,0,0,0,0,0,0,0
0,0,0,0,0,0,0,0,0,0,0,0,0,0,0,0,0,0,0,0,0,0,0,0,0,0,0,0,0,0,0,0,0,0,0,0,0,0,0,0,0,0
0,0,0,0,0,0,0,0,0,0,0,0,0,0,0,0,1,0,0,0,0,0,0,0,0,0,0,0,0,0,0,0,0,1,0,0,0,0,0,0,0,0
0,0,0,0,0,0,0,0,0,0,0,0,0,0,0,0,0,0,0,0,0,0,0,0,0,0,0,0,0,0,0,1,0,0,0,0,0,0,0,0,0,0
0,0,0,0,0,0,0,0,0,0,0,0,0,0,0,0,14,8,8,14,14,14,14,0,0,0,0,0,0,0,0,1,0,14,0,0,0,0,0,0,0,0
0,0,0,0,0,0,0,0,0,0,0,0,82,0,0,0,0,13,0,12,0,0,0,0,0,0,1,0,0,1,0,0,14,0,0,0,0,0,0,0,0,0
0,0,0,0,0,0,0,0,0,0,14,0,76,11,46,46,46,12,12,12,12,12,0,12,12,0,0,0,8,44,8,0,0,0,0,0,0,0,0,14,0,0
0,0,0,0,0,0,0,0,9,9,9,9,14,32,32,32,15,12,15,12,15,15,31,12,12,12,12,0,12,12,12,12,12,12,44,0,0,0,0,0,0,0
0,0,0,0,0,32,24,9,15,83,83,83,15,83,83,83,83,24,15,15,0,15,15,0,12,12,12,12,12,12,12,12,9,9,9,0,0,0,0,0,0,0
0,0,0,0,0,18,24,35,83,17,17,17,83,16,16,16,17,24,24,0,0,0,0,0,31,12,0,12,12,0,35,12,12,0,12,9,0,0,0,0,0,0
0,0,0,0,70,32,15,35,83,17,28,28,83,28,28,28,17,15,79,84,0,67,67,67,46,32,35,35,35,35,35,35,12,31,31,12,0,0,47,0,0,0
0,0,0,0,13,32,24,35,83,17,28,28,83,28,28,28,17,83,15,46,46,67,15,67,46,28,28,28,35,35,35,35,35,31,31,12,0,0,0,0,0,0
0,0,8,61,0,18,24,25,83,17,28,28,28,28,28,28,32,32,46,46,46,67,67,46,46,28,60,28,15,15,31,15,15,24,31,32,0,0,0,0,0,0
0,13,0,0,32,32,31,31,36,83,83,28,28,28,28,28,83,36,15,46,46,46,46,46,46,28,0,28,15,15,15,15,15,48,48,32,9,0,0,0,0,0
0,13,1,85,32,0,32,32,83,16,28,28,28,28,28,28,19,83,15,15,46,7,24,46,46,28,0,28,15,15,15,15,48,48,48,32,32,23,0,0,0,0
0,0,0,0,32,11,28,28,28,28,28,28,28,28,28,28,19,83,15,15,15,32,32,46,46,28,0,28,15,32,32,32,48,48,48,12,9,23,0,0,0,0
0,0,0,0,0,11,28,28,28,28,28,28,28,28,46,28,19,83,15,15,0,10,32,32,32,28,0,28,0,32,0,0,48,48,22,32,9,0,0,0,0,0
0,0,0,0,0,11,28,28,15,28,28,28,28,83,83,83,83,15,35,0,0,10,0,67,67,28,44,28,0,41,41,0,0,11,32,32,0,1,0,0,0,0
0,0,0,0,0,41,57,28,28,28,28,28,28,28,28,28,16,83,86,15,0,67,67,67,67,28,28,28,32,46,46,10,10,10,41,0,0,0,0,0,0,0
0,0,0,0,0,11,28,28,28,28,28,28,28,28,28,28,17,83,47,32,32,67,67,15,67,67,32,32,32,46,0,0,0,0,0,0,0,0,0,0,0,0
0,0,0,0,11,11,28,35,28,28,28,28,28,28,28,28,17,83,32,0,0,0,67,67,67,23,46,59,0,0,0,0,0,0,0,0,0,0,0,0,0,0
0,0,1,0,0,11,28,9,83,17,17,19,83,16,16,16,17,83,32,32,32,12,12,67,0,0,47,0,0,0,0,0,0,0,0,0,0,0,0,0,0,0
0,0,0,0,0,0,11,9,15,83,83,83,36,83,83,83,83,36,32,32,32,12,0,59,41,41,0,0,0,0,0,0,0,0,0,0,0,0,0,0,0,0
0,0,0,0,0,0,0,60,9,9,25,32,32,32,32,32,32,32,13,13,9,9,41,41,1,0,0,0,41,0,0,0,0,0,0,0,0,1,0,0,0,0
0,0,0,0,0,0,1,0,59,59,59,59,9,9,41,41,41,18,7,0,43,47,0,0,1,0,0,41,0,0,0,0,0,0,0,0,0,0,0,0,0,0
0,0,0,0,0,1,0,0,0,0,0,0,0,0,0,0,0,0,0,59,41,0,0,0,0,0,0,0,0,0,0,0,0,0,0,0,0,0,0,0,0,0
0,0,0,0,0,0,0,0,0,0,0,0,0,0,0,0,0,0,0,0,0,0,0,0,0,1,0,0,0,0,0,0,0,0,0,0,0,0,0,0,0,0
0,0,0,0,0,0,0,0,1,0,0,0,1,0,0,0,0,0,0,0,0,0,0,0,1,0,0,0,0,0,0,0,0,0,0,0,0,0,0,0,0,0
0,0,0,0,1,0,0,0,0,0,0,0,0,0,0,0,0,0,0,0,0,0,0,0,0,0,0,0,0,0,0,0,0,0,0,0,0,0,0,0,0,0
0,0,0,0,0,0,0,0,0,0,0,0,0,0,0,0,0,0,0,0,0,0,0,0,0,0,0,0,0,0,0,0,0,0,0,0,0,0,0,0,0,0
endlayer

layer
0,0,0,0,0,0,0,0,1,0,0,0,0,0,0,0,0,0,0,0,0,0,0,0,0,0,0,0,0,0,0,0,0,0,0,0,0,0,0,0,0,0
0,0,0,0,0,0,0,0,0,0,0,0,0,0,0,0,0,0,0,0,0,0,0,0,0,0,0,0,0,0,0,0,0,0,0,0,0,0,0,0,0,0
0,0,0,0,0,0,0,0,0,0,0,0,0,0,0,0,0,0,0,0,1,0,0,0,0,0,0,0,0,0,0,0,0,0,0,0,0,0,0,0,0,0
0,0,0,0,0,0,0,0,0,0,0,0,0,0,0,0,0,0,0,0,0,0,0,0,0,0,0,0,0,0,0,0,0,0,0,0,0,0,0,0,0,0
0,0,0,0,0,0,0,0,0,0,0,0,0,0,0,0,0,0,0,0,0,1,0,0,1,0,0,0,0,0,0,0,0,0,0,0,0,0,0,1,0,0
0,0,0,0,0,0,0,0,0,0,0,0,0,0,0,0,0,0,0,0,0,0,0,0,0,0,0,0,0,0,0,0,0,0,0,0,0,0,0,0,0,0
0,0,0,0,0,0,0,0,0,0,0,0,0,0,0,0,0,0,0,0,0,0,0,0,1,0,0,0,0,0,0,0,0,0,0,0,0,0,0,0,0,0
0,0,0,0,0,0,0,0,1,0,0,0,0,0,0,0,0,0,0,0,0,1,0,0,0,1,0,0,0,0,0,0,1,0,0,0,0,0,0,0,0,0
0,0,0,0,1,0,1,0,0,0,0,0,0,0,0,0,14,8,8,14,14,14,14,0,0,0,0,0,0,0,0,0,0,14,0,0,0,0,0,0,0,0
0,0,0,0,0,0,0,0,0,0,0,0,0,0,44,0,0,13,15,15,15,12,12,0,0,0,0,0,0,0,0,0,14,0,0,0,14,0,0,0,0,0
0,0,0,0,0,1,0,0,0,0,0,0,82,0,46,46,32,15,15,15,15,15,12,12,12,12,0,0,0,0,0,12,12,9,0,0,0,0,0,14,0,0
0,0,0,0,0,0,0,0,0,0,0,0,11,11,46,32,15,15,36,15,15,15,15,15,12,12,0,0,12,12,12,12,12,12,12,0,0,0,0,0,0,0
0,0,0,0,0,0,32,25,9,9,9,9,25,7,32,15,15,15,15,15,31,31,31,31,31,31,12,12,12,12,12,12,12,24,31,9,0,0,0,0,0,0
0,0,0,0,0,0,32,25,35,9,9,12,25,28,28,28,15,15,15,31,31,31,31,31,10,31,35,35,12,35,12,12,12,24,31,32,0,0,0,0,0,0
0,0,0,0,0,32,15,35,35,12,9,12,35,28,28,28,28,15,10,10,10,10,10,10,10,10,31,35,35,35,35,35,15,31,32,32,0,0,47,0,0,0
0,0,0,0,0,32,32,25,25,12,11,12,28,87,87,28,15,31,10,10,10,10,10,10,10,10,60,32,35,35,15,15,31,15,32,32,32,0,0,1,0,0
0,0,8,32,32,32,32,0,25,35,25,28,48,48,48,28,32,32,10,10,10,10,10,10,10,10,66,15,24,15,15,15,32,15,0,32,32,0,0,0,0,0
0,13,32,32,32,31,15,32,15,35,28,48,48,48,48,28,15,15,15,10,10,10,10,10,10,10,66,0,15,15,15,15,64,60,0,0,9,0,1,0,0,0
0,13,0,32,32,32,32,88,28,28,48,48,48,48,48,28,15,10,15,10,10,10,10,10,10,10,66,15,15,15,15,32,64,0,0,23,9,0,0,0,0,0
0,0,0,0,32,32,48,28,28,48,48,48,48,48,48,28,15,15,15,10,10,10,10,10,10,10,66,15,15,32,32,65,0,0,0,8,9,68,0,0,0,0
0,0,0,0,0,0,46,28,48,48,48,48,48,48,46,28,28,35,15,10,10,10,32,32,32,32,66,24,32,32,0,0,0,0,22,32,47,0,0,0,0,0
0,0,0,0,0,0,11,28,48,48,48,48,48,28,28,28,35,25,15,10,10,10,67,67,67,67,66,32,0,41,41,0,0,11,32,32,0,0,0,0,0,0
0,0,0,0,0,0,8,48,48,48,48,48,48,56,46,32,25,35,24,15,10,67,67,67,67,67,32,32,0,59,0,11,11,11,41,0,0,0,0,0,0,0
0,0,0,0,0,13,11,28,48,48,48,48,48,56,32,32,32,25,24,32,32,67,67,15,67,67,46,46,0,0,0,1,1,59,0,0,0,0,1,0,0,0
0,0,0,0,0,11,11,28,48,48,48,48,48,28,32,32,11,32,32,32,32,67,67,67,67,67,47,0,0,0,0,0,1,0,0,0,0,0,0,0,0,0
0,0,0,0,0,0,11,88,28,28,28,28,28,32,32,32,32,7,32,32,12,12,67,67,67,67,47,0,0,0,59,0,0,0,0,0,0,0,0,0,0,0
0,0,0,0,0,0,0,11,9,25,32,32,32,32,32,32,32,32,12,32,12,12,1,59,41,41,0,0,0,0,0,1,0,0,0,0,0,0,0,0,0,0
0,0,0,0,0,0,0,0,32,32,32,32,32,32,13,32,32,32,13,0,1,59,41,41,1,0,0,0,41,0,0,0,0,0,0,0,0,0,0,0,0,0
0,0,0,0,0,1,0,0,59,59,60,0,0,0,0,41,0,18,0,0,43,47,0,0,1,0,0,41,0,0,0,0,0,0,0,1,0,0,0,0,0,0
0,0,0,0,0,1,0,0,0,0,0,0,0,0,0,0,0,0,0,59,41,0,0,0,0,1,0,0,0,0,0,0,0,0,0,0,0,0,0,0,0,0
0,0,0,0,0,1,0,0,0,0,0,0,0,0,0,0,0,0,0,0,0,0,1,0,1,0,0,0,0,0,0,0,0,0,0,0,0,0,0,0,0,0
0,0,0,0,0,0,0,0,0,0,0,0,0,1,0,0,0,0,0,0,0,0,0,1,0,0,0,0,0,0,0,0,0,0,0,0,0,0,0,0,0,0
0,0,0,0,0,0,0,0,0,0,0,0,0,0,0,0,0,0,0,0,0,0,0,0,0,0,0,0,0,0,0,0,0,0,0,0,0,0,0,0,0,0
0,0,0,0,0,0,0,0,0,0,0,0,0,0,0,0,0,0,0,0,0,0,0,0,0,0,0,0,0,0,0,0,0,0,0,0,0,0,0,0,0,0
endlayer

layer
0,0,0,0,0,0,0,0,0,0,0,0,0,0,0,0,0,0,0,0,0,0,0,0,0,0,0,0,0,0,0,0,0,0,0,0,0,0,0,0,0,0
0,0,0,0,0,0,0,0,0,0,0,0,0,0,0,0,0,0,0,0,0,0,0,0,0,0,0,0,0,0,0,0,0,0,0,0,0,0,0,0,0,0
0,0,0,0,0,0,0,0,0,0,0,0,0,0,0,0,0,0,0,0,0,0,0,0,0,0,0,0,0,0,0,0,0,0,0,0,0,0,0,0,0,0
0,0,0,0,0,0,0,0,0,0,0,0,0,0,0,0,0,0,0,0,0,0,0,0,0,0,0,0,0,0,0,0,0,0,0,0,0,0,0,0,0,0
0,0,0,0,0,0,0,0,0,0,0,0,0,0,0,0,0,0,0,0,0,0,0,0,0,0,0,0,0,0,0,0,0,0,0,0,0,0,0,0,0,0
0,0,0,0,0,0,0,0,0,0,0,0,0,0,0,0,0,0,0,0,0,0,0,0,0,0,0,0,0,0,0,0,1,0,0,0,0,0,0,0,0,0
0,0,0,1,0,0,0,0,0,0,0,0,0,0,0,0,0,0,0,0,0,0,0,0,0,0,14,0,0,0,0,0,0,0,0,0,0,0,0,0,0,0
0,0,0,0,0,0,0,0,0,0,0,0,0,0,0,0,0,0,0,0,0,0,0,0,0,0,14,0,0,0,14,0,0,0,0,0,0,0,0,0,0,0
0,0,0,0,0,0,0,0,0,0,1,0,0,0,0,14,14,8,11,11,11,14,14,44,0,0,0,0,0,0,0,0,0,14,0,0,0,0,0,0,0,0
0,0,0,0,0,0,0,0,0,0,0,0,0,0,0,46,46,32,32,11,32,12,12,12,0,0,0,0,0,0,0,0,14,0,0,0,14,0,0,0,0,0
0,0,0,0,0,0,0,0,0,0,0,0,0,0,46,46,89,32,31,15,31,12,32,25,12,12,12,0,12,0,0,9,9,9,12,0,0,0,0,14,0,0
0,0,0,0,0,0,0,0,1,1,0,32,11,11,32,32,70,31,15,15,15,31,32,32,32,25,25,12,12,12,12,9,35,28,12,32,0,0,0,0,0,0
0,0,0,0,0,0,0,71,1,0,0,11,11,32,32,48,48,48,91,0,90,90,90,92,91,90,56,15,15,15,15,15,15,28,32,32,32,0,0,0,0,0
0,0,0,0,0,0,0,71,25,0,0,11,32,48,48,48,48,48,48,0,0,91,0,7,48,90,56,15,15,15,15,15,26,28,32,32,32,68,0,0,0,0
0,0,0,0,0,0,32,15,25,0,11,0,25,48,48,48,48,48,50,50,10,50,50,50,48,50,50,15,15,15,15,24,15,32,0,32,32,0,47,0,0,0
0,0,0,0,0,0,18,32,32,0,11,11,32,0,0,48,15,15,0,7,10,11,11,48,48,48,32,46,15,15,15,15,81,15,0,32,32,0,0,0,0,0
0,0,0,0,0,0,32,32,94,35,93,32,0,0,0,48,32,24,0,0,10,11,48,7,48,48,32,32,15,15,15,15,0,65,0,23,47,0,1,0,0,0
0,13,32,32,32,32,32,32,15,15,64,64,0,0,0,48,15,15,10,10,10,11,48,48,48,10,32,32,15,15,15,15,47,0,0,0,23,0,0,1,0,0
0,13,32,32,32,0,0,46,46,15,64,0,0,0,0,70,15,11,11,95,95,48,48,48,7,48,32,15,15,15,32,65,0,0,0,23,23,0,0,0,0,0
0,0,0,32,32,0,46,11,7,0,0,1,0,0,0,48,15,15,11,48,48,48,48,48,48,48,26,15,32,59,0,0,0,0,0,8,23,0,0,0,0,0
0,0,0,0,60,0,0,11,0,18,59,0,0,0,0,48,96,15,46,46,11,11,11,32,46,32,0,32,32,0,0,0,0,32,22,32,47,0,0,0,0,0
0,0,0,0,0,0,0,11,0,18,59,18,0,7,32,32,25,11,11,11,11,11,32,97,46,0,46,32,0,0,41,0,0,11,32,32,1,0,0,0,0,0
0,0,0,0,0,0,0,0,0,0,1,0,1,59,56,10,32,15,15,11,10,10,0,67,46,46,46,60,0,59,0,0,47,59,41,0,0,0,0,0,0,0
0,0,0,0,0,0,0,46,0,0,0,59,23,18,56,32,32,32,15,24,0,10,67,15,67,46,0,0,0,0,0,59,0,59,0,0,1,0,0,0,0,0
0,0,0,0,0,0,11,7,0,0,0,0,0,32,32,11,11,11,32,32,0,0,67,67,46,46,0,0,0,23,0,0,0,0,0,0,0,0,0,0,0,0
0,0,0,0,0,0,0,11,98,32,32,32,32,32,32,32,11,32,12,12,12,0,60,0,59,47,0,0,0,0,59,0,0,0,0,0,0,0,0,0,0,0
0,0,0,0,0,0,0,0,32,32,32,11,11,46,0,41,11,32,12,0,1,0,0,0,0,47,0,0,0,0,0,0,0,0,0,0,0,0,0,0,0,0
0,0,0,0,0,0,0,0,60,32,60,0,7,0,0,0,0,18,13,1,0,59,41,41,0,0,0,0,41,0,0,0,0,0,0,0,0,0,0,0,0,0
0,0,0,0,0,0,1,0,0,0,0,0,0,0,0,0,0,18,0,0,43,47,0,0,0,0,0,41,0,0,0,0,0,0,0,0,0,0,0,0,0,0
0,0,0,0,0,0,0,0,0,0,0,0,0,0,0,0,0,0,0,59,41,0,0,0,0,0,0,0,0,1,0,0,0,0,0,0,0,0,0,0,0,0
0,0,0,0,0,0,0,0,0,0,0,0,0,0,0,0,0,0,0,1,1,0,0,0,0,0,0,0,0,0,0,0,0,0,0,0,0,0,0,0,0,0
0,0,0,0,0,0,0,0,0,0,0,0,0,0,0,0,0,0,0,0,0,0,0,0,0,0,0,0,0,0,0,0,0,0,0,0,0,0,0,0,0,0
0,0,0,0,0,0,0,1,1,0,0,0,0,0,0,0,0,0,0,0,0,0,0,0,0,0,0,0,0,0,0,0,0,0,0,0,0,0,0,0,0,0
0,0,0,0,0,0,0,0,0,0,0,0,0,0,0,0,0,0,0,0,0,0,0,0,0,0,0,0,0,0,0,0,0,0,0,0,0,0,0,0,0,0
endlayer

layer
0,0,0,0,0,0,0,0,0,0,0,0,0,0,0,0,0,0,0,0,0,0,0,0,0,0,0,0,0,0,0,0,0,0,0,0,0,0,0,0,0,0
0,0,0,0,0,0,0,0,0,0,0,0,0,0,0,0,0,0,0,0,0,0,0,0,0,0,0,0,0,0,0,0,0,0,0,0,0,0,0,0,0,0
0,0,0,0,0,0,0,0,0,0,0,0,0,0,0,0,0,0,0,0,0,0,0,0,0,0,1,0,0,0,0,0,0,0,0,0,0,0,0,0,0,0
0,0,0,0,0,0,0,0,0,0,0,0,0,0,0,0,0,0,0,0,0,0,0,0,0,0,0,0,0,0,0,0,0,1,0,0,0,0,0,0,0,0
0,0,0,0,0,0,0,0,0,0,0,0,0,0,0,0,0,0,0,0,0,0,0,0,0,0,0,0,0,0,0,0,1,0,0,0,0,0,0,0,0,0
0,0,0,0,0,0,0,0,0,0,0,0,0,0,0,0,0,0,0,0,0,0,0,0,0,0,0,0,0,0,0,0,0,0,0,0,0,0,0,0,0,0
0,0,0,0,0,0,0,0,0,0,0,0,0,0,0,0,0,0,0,0,0,0,0,0,0,0,14,0,0,0,0,0,0,0,0,0,0,0,0,0,0,0
0,0,0,0,0,0,0,0,0,0,0,0,0,0,0,0,0,0,0,11,0,0,0,0,0,14,14,0,0,0,14,0,0,0,0,0,0,0,0,0,0,0
0,0,0,0,0,0,0,0,0,1,0,0,0,0,0,14,11,11,11,46,11,11,14,14,0,0,0,0,0,0,0,0,0,14,0,0,0,0,0,0,0,0
0,0,0,0,0,0,0,0,0,0,0,0,0,0,0,46,0,46,46,32,32,32,46,46,0,0,0,0,0,0,0,44,9,61,0,0,14,0,0,0,0,0
0,0,0,0,0,0,0,0,0,0,0,0,0,0,0,46,32,32,15,15,15,32,32,32,0,0,12,12,12,12,12,9,28,0,32,0,0,0,0,14,0,0
0,0,0,0,0,0,0,0,1,0,0,0,0,11,46,32,0,32,15,15,15,32,32,32,32,32,0,15,15,15,15,28,28,28,32,32,0,0,0,47,0,0
0,0,0,0,0,0,0,0,0,0,0,0,11,32,0,0,0,0,60,0,90,90,90,92,99,90,0,59,59,48,48,0,0,0,28,32,32,0,0,0,0,0
0,0,0,0,0,0,0,0,0,0,0,32,32,32,0,0,1,0,0,0,0,80,0,80,80,90,90,90,0,1,47,1,0,1,28,32,32,47,0,0,0,0
0,0,0,0,0,0,0,0,71,0,18,25,32,0,0,0,0,32,32,32,10,0,0,80,1,0,0,84,32,32,32,15,100,100,32,32,32,0,47,0,0,0
0,0,0,0,0,0,18,46,32,0,0,0,0,0,0,0,32,15,32,0,10,11,0,47,1,0,18,46,15,15,15,15,32,15,32,0,47,0,0,0,59,0
0,0,0,0,0,0,18,32,32,15,64,0,0,0,0,31,31,15,10,10,10,11,0,1,0,18,46,46,32,31,31,15,32,32,32,23,47,0,0,0,0,0
0,0,8,32,0,0,0,32,15,15,31,64,0,0,0,32,15,15,10,95,95,0,0,0,102,10,46,101,15,15,15,15,47,0,0,0,23,0,0,0,0,0
0,13,0,32,0,0,0,0,18,15,64,0,0,0,0,103,15,46,11,0,1,0,0,0,1,0,46,15,15,32,65,65,0,0,0,23,23,0,0,0,0,0
0,0,0,0,0,0,0,0,0,0,0,0,0,0,0,0,32,15,11,0,0,0,0,0,1,0,46,32,59,0,0,0,1,0,32,8,23,0,0,0,0,0
0,0,0,0,0,0,0,18,0,18,59,0,0,0,0,0,103,15,46,46,11,11,11,32,0,46,0,32,0,0,0,0,0,32,22,32,47,0,0,0,0,0
0,0,0,0,0,0,0,0,0,18,59,18,0,0,104,104,48,32,11,11,11,32,32,81,46,46,46,0,0,0,41,0,11,32,32,32,0,0,0,0,0,0
0,0,0,0,0,0,0,0,0,0,0,0,0,59,0,56,10,32,15,10,24,0,0,67,46,46,46,0,0,59,0,0,47,59,41,0,0,0,0,0,0,0
0,0,0,0,0,0,0,0,0,0,0,59,23,18,0,56,10,32,15,15,24,0,67,67,67,46,0,0,0,0,0,59,59,59,0,0,0,0,0,0,0,0
0,0,0,0,0,0,0,46,0,0,0,0,0,0,0,0,11,11,32,32,24,32,32,67,32,46,0,0,0,23,0,0,0,0,59,0,0,0,0,0,0,0
0,0,0,0,0,0,0,0,0,0,11,11,11,46,0,11,11,11,0,32,32,0,0,0,59,61,0,0,0,0,59,0,0,0,0,0,0,0,0,0,0,0
0,0,0,0,0,0,0,0,0,32,11,0,0,0,0,0,0,18,0,60,0,0,0,0,0,47,0,0,0,0,0,0,0,0,0,0,0,0,0,0,0,0
0,0,0,0,0,0,0,0,0,0,0,0,1,0,0,0,0,18,13,0,0,59,41,41,41,0,0,0,41,0,0,0,0,0,0,0,0,0,0,0,0,0
0,0,0,1,0,0,0,0,0,0,0,0,0,0,0,0,0,18,0,0,43,47,0,0,0,0,0,41,0,0,0,0,0,0,0,0,0,0,0,0,0,0
0,0,0,1,0,0,0,0,0,0,0,0,0,0,0,0,0,0,0,59,41,0,0,0,0,0,0,0,0,0,0,0,0,0,0,0,0,0,0,0,0,0
0,0,0,0,0,0,0,0,0,0,0,0,0,0,0,0,0,0,0,0,0,0,0,0,0,0,0,0,0,0,0,0,0,0,0,0,0,0,0,0,0,0
0,0,0,0,0,0,0,0,0,0,0,0,0,0,0,0,1,0,0,0,0,0,0,0,0,0,0,0,0,0,0,0,0,0,0,0,0,0,0,0,0,0
0,0,0,0,0,0,0,0,0,0,0,0,0,0,0,0,0,0,0,0,0,0,0,0,0,0,0,0,0,0,0,0,0,0,0,0,0,0,0,0,0,0
0,0,0,0,0,0,0,0,0,0,0,0,0,0,0,0,0,0,0,0,0,0,0,0,0,0,0,0,0,0,0,0,0,0,0,0,0,0,0,0,0,0
endlayer

layer
0,0,0,0,0,0,0,0,0,0,0,0,0,0,0,0,0,0,0,0,1,0,0,0,0,0,0,0,0,0,0,0,0,0,0,0,0,0,0,0,0,0
0,0,0,0,0,0,0,0,0,0,0,0,0,0,0,0,0,0,0,0,0,0,0,0,0,0,0,0,0,0,0,0,0,0,0,0,0,0,0,0,0,0
0,0,0,0,0,0,0,0,0,0,0,0,0,0,0,0,0,0,0,0,0,0,0,0,0,0,0,0,0,0,0,0,0,0,0,0,0,0,0,0,0,0
0,0,0,0,0,0,0,0,0,0,0,0,0,0,0,0,0,0,0,0,0,0,0,0,0,0,0,0,0,0,0,0,0,0,0,0,0,0,0,0,0,0
0,0,0,0,0,0,0,0,0,0,0,0,0,0,0,0,0,0,0,0,0,0,0,0,0,0,0,0,0,0,0,0,0,0,0,0,0,0,0,0,0,0
0,0,0,0,0,0,0,0,0,0,0,0,0,0,0,0,0,0,0,0,0,0,0,0,0,0,0,0,0,0,0,0,0,0,0,0,0,0,0,0,0,0
0,0,0,0,0,0,0,0,0,0,0,0,0,0,0,0,0,0,0,0,0,0,0,0,0,0,14,0,0,0,0,0,0,1,0,0,0,0,0,0,0,0
0,0,0,0,0,0,0,0,0,0,0,0,0,0,0,0,0,0,0,11,0,0,14,0,0,14,14,0,0,0,14,14,0,0,0,1,1,0,0,0,0,0
0,0,0,0,0,0,0,0,0,0,0,0,0,0,0,14,14,11,11,46,11,11,0,0,0,0,0,0,0,0,0,0,0,14,0,0,1,0,0,1,0,0
0,0,0,0,0,0,0,0,0,0,0,0,0,0,0,11,11,32,46,0,0,32,46,0,0,0,0,0,0,0,0,0,9,9,0,0,14,0,0,0,0,0
0,0,0,0,0,0,0,0,1,0,0,0,0,0,0,11,11,11,32,15,32,0,46,46,32,32,12,12,12,12,0,9,14,9,9,0,0,0,1,14,0,0
0,0,0,0,0,0,0,0,0,0,0,0,0,11,0,0,0,32,15,15,15,32,32,32,32,32,32,15,15,15,15,32,32,32,32,32,0,0,0,47,0,0
0,0,0,0,0,0,0,0,0,0,0,0,18,0,0,0,0,0,0,15,90,90,90,92,99,90,0,60,59,59,59,0,0,0,32,32,14,0,47,0,0,0
0,0,0,0,0,0,0,0,0,0,0,0,14,0,0,0,0,0,0,0,0,80,0,80,80,90,90,90,0,0,47,0,0,0,32,32,0,47,0,0,0,0
0,0,0,0,0,0,0,0,0,0,18,7,0,0,0,0,31,31,15,32,10,0,0,80,0,0,0,84,32,32,32,32,47,0,32,32,59,0,47,47,0,0
0,0,0,0,0,0,0,0,0,0,32,0,0,0,0,0,32,24,24,10,10,0,80,47,0,0,18,46,15,15,15,15,100,100,22,32,47,0,0,0,59,0
0,0,0,0,0,0,0,44,32,15,32,0,0,32,32,32,32,24,0,95,95,0,0,0,0,61,0,46,46,0,0,15,32,32,32,23,47,0,0,0,0,0
0,0,8,0,0,0,0,32,15,15,15,64,0,60,32,32,0,15,10,0,0,85,0,0,10,10,46,101,15,15,15,15,0,32,32,0,23,0,0,0,0,0
0,13,32,32,0,0,0,32,32,15,64,0,0,0,0,103,15,11,46,0,0,0,0,0,0,0,101,15,32,59,65,32,32,32,32,23,23,0,0,1,0,0
0,0,60,0,0,0,0,0,32,61,98,0,0,0,0,32,32,15,46,0,0,0,0,0,0,0,0,46,0,0,0,32,32,32,32,32,23,0,0,0,0,0
0,0,0,0,0,0,0,18,0,18,59,0,0,0,0,0,32,32,46,46,46,46,46,32,0,0,0,46,0,0,0,0,32,32,22,32,47,0,0,0,0,0
0,0,0,0,0,0,0,0,0,18,59,18,0,0,0,0,0,0,11,11,32,32,32,59,46,46,46,0,0,0,41,0,11,32,32,32,68,0,0,0,0,0
0,0,0,0,0,0,0,0,59,0,0,0,0,59,0,0,56,32,32,11,32,31,32,47,46,46,0,0,0,59,0,0,47,59,41,0,0,0,0,0,0,0
0,0,0,0,0,0,0,0,0,0,0,59,23,18,0,0,56,32,32,24,31,32,32,32,46,46,0,0,23,0,0,59,59,59,47,0,0,0,0,0,0,0
0,0,0,0,0,0,0,0,0,0,0,41,0,0,0,0,46,46,32,15,31,31,31,32,32,46,0,0,0,23,59,0,0,0,59,0,0,0,0,0,0,0
0,0,0,0,0,0,0,0,0,0,0,0,0,0,0,41,0,18,0,32,15,32,32,32,32,46,0,0,0,0,59,0,0,0,0,0,0,0,0,0,0,0
0,0,0,0,0,0,0,0,0,0,0,0,0,0,0,0,0,18,0,0,32,32,0,32,0,61,0,0,0,0,0,0,0,0,0,0,0,0,0,0,0,0
0,0,0,0,0,0,0,0,0,0,0,0,0,0,0,0,0,18,13,0,0,59,41,41,41,0,0,0,41,0,0,0,0,0,0,0,0,0,0,0,0,0
0,0,0,0,0,0,1,0,0,0,0,0,0,0,0,0,0,18,0,0,43,47,0,0,0,41,41,41,0,0,0,0,0,0,0,0,0,0,0,0,0,0
0,0,0,0,1,0,0,0,0,0,0,0,0,0,0,0,0,0,0,59,41,0,0,0,0,0,0,0,0,0,0,0,0,0,0,0,0,0,0,0,0,0
0,0,1,0,0,0,0,0,0,0,0,0,0,0,0,0,0,0,0,0,0,0,0,0,0,0,0,0,0,0,0,0,0,0,0,0,0,0,0,0,0,0
0,0,0,0,0,0,0,0,0,0,0,0,0,0,0,0,0,0,0,0,0,0,0,0,0,0,0,0,0,0,0,0,0,0,0,0,0,0,0,0,0,0
0,0,0,0,0,0,0,0,0,0,0,0,0,0,0,0,0,0,0,0,0,0,0,0,0,0,0,0,0,0,0,0,0,0,0,0,0,0,0,0,0,0
0,0,0,0,0,0,0,0,0,0,0,0,0,0,0,0,0,0,0,0,0,0,0,0,0,0,0,0,0,0,0,0,0,0,0,0,0,0,0,0,0,0
endlayer

layer
0,0,0,0,0,0,0,0,0,0,0,0,0,0,0,0,0,0,0,0,0,0,0,0,0,0,0,0,0,0,0,0,0,0,0,0,0,0,0,0,0,0
0,0,0,0,0,0,0,0,0,0,0,0,0,0,0,0,0,0,0,0,0,0,0,0,0,0,0,0,0,0,0,0,0,0,0,0,0,0,0,0,0,0
0,0,0,0,0,0,0,0,0,0,0,0,0,0,0,0,0,0,0,0,0,0,0,0,0,0,0,0,0,0,0,0,0,0,0,0,0,0,0,0,0,0
0,0,0,0,0,0,0,0,0,0,0,0,0,0,0,0,0,0,0,0,0,0,0,0,0,0,0,0,0,0,0,0,0,0,0,0,0,0,0,0,0,0
0,0,0,0,0,0,0,0,0,0,0,0,0,0,0,0,0,0,0,0,0,0,0,0,0,0,0,0,0,0,0,0,0,0,0,0,0,0,0,0,0,0
0,0,0,0,0,0,0,0,0,0,0,0,0,0,0,0,0,0,0,0,0,0,0,0,0,0,0,0,0,0,0,0,0,0,0,0,0,0,0,0,0,0
0,0,0,0,0,0,0,0,0,0,0,0,0,0,0,0,0,0,0,44,0,0,0,0,0,0,14,14,0,0,0,1,0,0,0,0,0,0,0,0,0,0
0,0,0,0,0,0,0,0,0,0,0,0,0,0,0,0,0,0,11,11,0,0,14,0,0,14,14,0,0,0,14,14,0,0,0,0,0,1,0,0,0,0
0,0,0,0,0,0,0,0,0,0,0,0,0,0,0,0,11,11,11,46,11,11,0,0,0,0,1,0,0,0,0,0,0,14,0,0,0,1,0,0,0,0
0,0,0,0,0,0,0,0,0,0,0,0,0,0,0,11,11,11,0,32,0,0,0,0,0,0,0,0,0,44,0,0,9,14,0,0,14,0,0,0,0,0
0,0,0,0,0,1,0,0,0,0,0,0,0,0,11,11,11,11,0,15,32,32,46,46,46,46,46,12,12,12,32,32,9,9,14,0,0,0,0,14,0,0
0,0,0,0,0,0,0,0,0,0,0,0,0,0,0,0,32,32,15,15,15,32,80,0,0,46,101,32,15,24,15,32,32,9,32,0,0,0,0,47,0,0
0,0,0,0,0,0,0,0,0,0,0,0,18,0,0,0,32,0,24,24,90,90,14,84,101,32,32,101,32,32,32,32,32,32,32,32,14,0,47,0,0,0
0,0,0,0,0,0,0,0,0,0,0,0,14,0,0,32,15,31,31,32,32,80,0,80,80,90,90,90,0,0,47,0,0,0,32,47,0,47,0,0,0,0
0,0,0,0,0,0,0,0,0,0,18,0,0,0,0,31,31,31,24,31,32,32,0,80,0,0,0,84,32,44,32,32,47,0,32,0,59,0,47,47,0,0
0,0,0,0,0,0,0,0,0,0,18,0,0,0,0,32,0,32,32,95,95,32,80,47,0,0,18,32,15,15,15,15,47,0,22,32,47,0,59,0,59,0
0,0,0,0,0,0,0,0,44,32,0,0,32,32,32,32,32,32,0,0,0,0,0,0,0,11,0,46,46,0,0,15,100,100,22,32,47,0,0,0,0,0
0,0,8,0,0,0,0,18,32,15,98,98,32,32,32,31,15,15,15,0,0,10,10,10,10,11,101,31,15,15,15,65,28,28,20,32,23,0,0,0,0,0
0,13,98,98,0,0,0,0,32,32,98,98,32,32,32,32,15,31,46,0,0,0,46,46,46,0,47,32,41,41,65,32,28,28,20,32,23,0,0,0,0,0
0,0,41,0,0,0,0,0,0,32,98,98,32,0,32,32,32,15,46,46,0,0,32,0,32,0,0,46,0,0,0,32,28,26,20,32,0,47,0,0,0,0
0,0,0,0,0,0,0,18,0,18,59,0,0,0,0,32,32,32,11,11,46,97,97,97,32,0,0,46,0,0,0,32,21,21,22,32,23,0,0,0,0,0
0,0,0,0,0,0,0,0,0,18,59,18,0,0,0,0,32,32,11,97,97,97,97,97,97,46,46,0,0,0,41,0,32,32,32,32,0,0,0,0,0,0
0,0,0,0,0,0,0,0,59,0,0,0,0,59,0,0,1,56,10,97,97,97,97,97,97,46,0,0,0,59,0,0,47,59,41,0,0,0,0,0,0,0
0,0,0,0,0,0,0,0,0,0,0,59,23,18,0,0,44,56,10,97,97,32,10,97,97,46,0,0,23,0,0,59,59,59,47,0,0,0,0,0,0,0
0,0,0,0,0,0,0,0,0,0,41,41,0,0,0,0,46,11,32,32,15,32,15,32,32,32,46,0,0,23,59,0,0,0,59,0,0,0,0,0,0,0
0,0,0,0,0,1,0,1,0,0,0,0,0,0,0,41,0,18,0,32,24,32,32,24,32,46,46,46,0,0,59,0,0,0,0,0,0,0,0,0,0,0
0,0,0,0,0,0,0,0,0,0,0,0,0,0,0,0,0,18,32,32,24,32,32,32,32,46,46,0,0,0,0,0,0,0,0,0,0,0,0,0,0,0
0,0,0,0,0,0,0,0,0,0,0,0,0,1,0,0,0,18,13,32,32,59,41,41,41,0,0,0,41,0,0,0,0,0,0,0,0,0,0,0,0,0
0,0,0,0,0,0,0,0,0,0,1,0,0,0,0,0,0,18,0,0,43,47,0,0,0,41,41,41,0,0,0,0,0,0,0,0,0,0,0,0,0,0
0,0,0,0,0,0,0,0,0,0,0,0,0,0,0,0,0,0,0,59,41,0,0,0,0,0,0,0,0,0,0,0,0,1,0,0,0,0,0,0,0,0
0,0,0,0,0,0,0,0,0,0,0,0,0,0,0,0,0,0,0,0,0,0,0,0,0,0,0,0,0,0,0,0,0,0,0,0,0,0,0,0,0,0
0,0,0,0,0,0,0,0,0,0,0,0,0,0,0,0,0,0,0,0,0,0,0,0,0,0,0,0,0,0,0,0,0,0,0,0,0,0,0,0,0,0
0,0,0,0,0,0,0,0,0,0,0,0,0,0,0,0,0,0,0,0,0,0,0,0,0,0,0,0,0,0,0,0,0,0,0,0,0,0,0,0,0,0
0,0,0,0,0,0,0,0,0,0,0,0,0,0,0,0,0,0,0,0,0,0,0,0,0,0,0,0,0,0,0,0,0,0,0,0,0,0,0,0,0,0
endlayer

layer
0,0,0,0,0,0,0,0,0,0,0,0,0,0,0,0,0,0,0,0,0,0,0,0,0,0,0,0,0,0,0,0,0,0,0,0,0,0,0,0,0,0
0,0,0,0,0,0,0,0,0,0,0,0,0,0,0,0,0,0,0,0,0,0,0,0,0,0,0,0,0,0,0,0,0,0,0,0,0,0,0,0,0,0
0,0,0,0,0,0,0,0,0,0,0,0,0,0,0,0,1,0,0,0,0,0,0,0,0,0,0,0,0,0,0,0,0,0,0,0,0,0,0,0,0,0
0,0,0,0,0,0,0,0,0,0,0,0,0,0,0,0,0,0,0,0,0,0,0,0,0,0,0,0,0,0,0,0,0,0,0,0,0,0,0,0,0,0
0,0,0,0,0,0,0,0,0,0,0,0,0,0,0,0,0,0,0,0,0,0,0,0,0,0,0,0,0,0,0,0,0,0,0,0,0,0,0,0,0,0
0,0,0,0,0,0,0,0,0,0,0,0,1,0,0,0,0,0,0,0,0,0,0,0,0,0,0,0,0,14,0,14,0,0,0,0,0,0,0,0,0,0
0,0,0,0,0,0,0,0,0,0,0,0,0,0,0,0,0,0,0,0,0,0,0,0,0,0,14,14,0,0,0,0,0,0,0,0,0,0,0,0,0,0
1,0,0,0,0,0,0,0,0,0,0,0,0,0,0,0,0,11,11,11,11,0,14,0,0,14,14,1,0,1,14,14,0,0,0,0,0,0,0,0,0,0
0,0,0,0,0,0,0,0,0,0,0,0,0,0,0,0,11,11,11,11,11,11,0,0,0,0,1,0,1,0,0,1,0,14,0,0,0,0,0,0,0,0
0,0,0,0,0,0,0,0,0,0,0,0,0,0,11,11,32,32,32,7,32,0,0,0,0,0,0,0,0,0,0,0,14,14,0,0,14,0,0,0,0,0
0,0,0,0,0,0,0,0,0,0,0,0,0,0,11,32,24,32,32,0,32,32,46,46,46,46,46,12,12,12,12,14,14,0,14,0,0,0,0,14,0,0
0,0,1,0,0,0,0,0,0,0,0,0,0,18,32,32,24,32,0,15,32,32,80,0,0,46,101,32,15,24,15,32,47,14,0,0,0,47,0,47,0,0
0,0,0,0,0,0,0,0,0,0,0,0,18,0,0,32,24,0,0,32,32,90,14,84,0,101,101,32,32,24,32,32,32,32,32,0,14,0,47,0,0,0
0,0,0,0,0,0,0,0,0,0,0,0,14,0,32,32,15,32,32,24,46,0,32,80,102,46,46,90,0,0,47,0,32,32,32,47,0,47,0,0,0,0
0,0,0,0,0,0,0,0,0,0,18,0,0,0,32,32,32,32,32,95,95,32,32,80,0,0,0,0,32,15,47,32,47,0,32,0,59,0,47,47,0,0
0,0,0,0,0,0,0,0,0,0,18,0,32,32,32,32,0,32,32,0,0,24,32,47,0,0,101,32,15,15,15,15,64,0,32,0,47,0,59,0,59,0
0,0,0,0,0,0,0,0,0,98,98,0,32,32,32,15,24,32,32,0,0,0,32,11,11,46,32,31,31,15,0,15,47,0,22,32,68,0,0,0,0,0
0,0,8,0,0,0,0,18,32,7,0,98,32,32,32,31,31,15,32,0,0,0,46,11,11,84,0,32,15,15,15,28,47,1,10,32,23,0,0,0,0,0
0,13,98,98,0,0,0,0,0,98,98,98,32,32,32,32,15,35,15,32,32,46,0,0,32,32,47,46,41,65,32,39,0,0,10,46,23,0,0,0,0,0
0,0,41,0,0,0,0,0,0,32,98,98,32,32,32,32,32,15,32,32,32,46,46,32,32,32,32,46,0,0,32,39,1,59,10,46,0,47,0,0,0,0
0,0,0,0,0,0,0,18,0,18,59,0,0,0,0,32,32,24,32,32,32,46,0,95,95,32,32,46,0,0,32,21,22,10,10,46,47,0,0,0,0,0
0,0,0,0,0,0,0,0,0,18,59,18,0,0,0,0,32,24,0,0,0,10,1,1,56,46,46,46,0,0,41,32,32,32,32,7,0,0,0,0,0,0
0,0,0,0,0,0,0,0,59,0,0,0,0,59,0,0,0,60,0,0,0,0,0,74,18,10,46,46,0,59,0,0,47,59,41,0,0,0,0,0,0,0
0,0,0,0,0,0,0,0,0,0,0,59,23,18,0,0,0,0,0,1,0,10,0,59,106,105,46,46,23,0,0,59,59,59,47,0,0,0,0,0,0,0
0,0,0,0,0,0,0,0,0,59,41,41,0,0,0,0,18,11,10,32,15,32,32,12,105,97,97,0,46,23,59,0,0,59,59,59,0,0,0,0,0,0
0,0,0,0,0,0,0,0,0,0,0,0,0,0,0,41,0,18,32,32,32,32,32,32,46,97,97,97,46,68,59,0,0,0,0,0,0,0,47,0,0,0
0,0,0,0,0,0,0,0,0,0,0,0,0,0,0,0,0,18,32,32,32,32,32,46,46,0,97,0,46,23,0,0,0,0,0,0,0,0,0,0,0,0
0,0,0,0,0,0,0,0,0,0,0,0,0,0,0,0,0,18,32,24,32,46,41,41,41,46,46,46,41,0,0,0,0,0,47,0,0,0,0,0,0,0
0,0,0,0,0,0,0,0,0,0,0,0,0,0,0,0,0,18,0,98,23,47,0,0,0,41,41,41,0,0,0,0,0,0,0,0,0,0,0,0,0,0
0,0,0,0,0,0,0,0,0,0,0,0,0,0,0,0,0,0,0,59,41,0,0,0,0,0,0,0,0,0,0,0,0,0,0,0,0,0,0,0,0,0
0,0,0,0,0,0,0,0,0,0,0,0,0,0,0,0,0,0,0,0,0,0,0,0,0,0,0,0,0,0,0,0,0,0,0,0,0,0,0,0,0,0
0,0,0,0,0,0,0,0,0,0,0,0,0,0,0,0,0,0,0,0,0,0,0,0,0,0,0,0,0,0,0,0,0,0,0,0,0,0,0,0,0,0
0,0,0,0,0,0,0,0,0,0,0,0,0,0,0,0,0,0,0,0,0,0,0,0,0,0,0,0,0,0,0,0,0,0,0,0,0,0,0,0,0,0
0,0,0,0,0,0,0,0,0,0,0,0,0,0,0,0,0,0,0,0,0,0,0,0,0,0,0,0,0,0,0,0,0,0,0,0,0,0,0,0,0,0
endlayer

layer
0,0,0,0,0,0,0,0,0,0,0,0,0,0,0,0,0,0,0,0,0,0,0,0,0,0,0,0,0,0,0,0,0,0,0,0,0,0,0,0,0,0
0,0,0,0,0,0,0,0,0,0,0,0,0,0,0,0,0,0,0,0,0,0,0,0,0,0,0,0,0,0,0,0,0,0,0,0,0,0,0,0,0,0
0,0,0,0,0,0,0,0,0,0,0,0,0,0,0,0,0,0,0,0,0,0,0,0,0,0,0,0,0,0,0,0,0,0,0,0,0,0,0,0,0,0
0,0,0,0,0,0,0,0,0,0,0,0,0,0,0,0,0,0,0,0,0,0,0,0,0,0,0,0,0,0,0,0,0,0,0,0,0,0,0,0,0,0
0,0,0,0,0,0,0,0,0,0,0,0,0,0,0,0,0,0,0,0,0,0,0,0,0,0,0,0,14,0,0,0,0,0,0,0,0,0,0,0,0,0
0,0,0,0,0,0,0,0,0,0,0,0,0,0,0,0,0,0,0,0,0,0,0,0,0,0,0,0,0,14,0,14,14,0,0,0,0,0,0,0,0,0
0,0,0,0,0,0,0,0,0,0,0,0,0,0,0,0,0,0,0,0,0,0,0,0,0,0,14,14,0,0,0,0,0,0,0,0,0,0,0,0,0,0
0,0,0,0,0,0,0,0,0,0,0,0,0,0,0,0,11,11,11,11,11,0,14,0,0,14,14,0,0,0,14,14,0,0,14,0,0,0,0,0,0,0
0,0,0,0,0,0,0,0,0,0,0,0,0,0,0,0,11,11,11,11,11,11,0,0,0,0,1,0,0,0,0,0,0,14,0,0,0,0,0,0,0,0
0,0,0,0,0,0,0,0,0,0,0,0,0,0,11,46,32,32,32,32,46,0,0,0,0,0,0,0,0,0,1,0,14,14,0,0,14,0,0,0,0,0
0,0,0,0,0,0,0,0,0,0,0,0,0,0,46,32,32,32,32,32,32,61,46,46,46,46,46,12,12,12,12,0,14,0,14,0,0,0,0,14,0,0
0,0,0,0,0,0,0,0,0,0,0,0,0,18,32,31,32,32,0,15,32,32,0,0,0,101,32,32,15,15,15,32,0,0,0,0,0,47,0,47,0,0
0,0,0,0,0,0,0,0,0,0,0,0,18,32,32,32,32,32,32,32,32,32,80,84,0,101,32,32,15,15,47,32,32,7,14,0,14,0,47,0,0,0
0,0,0,0,0,0,0,0,0,0,0,0,14,32,32,32,32,0,0,95,95,32,32,32,46,46,90,32,32,24,47,61,32,32,0,47,0,47,0,0,0,0
0,0,0,0,0,0,0,0,0,0,18,0,0,32,32,32,24,32,32,0,0,32,32,46,46,46,32,32,15,24,15,32,32,0,0,0,59,0,47,47,0,0
0,0,0,0,0,0,0,0,0,0,18,0,32,32,32,32,24,32,32,0,0,32,31,32,46,46,32,31,15,15,15,15,64,0,0,0,47,0,59,0,59,0
0,0,0,0,0,0,0,0,0,98,0,0,32,32,32,15,24,32,32,0,0,32,32,46,46,46,46,32,15,15,0,15,64,0,32,0,47,0,0,0,0,0
0,0,8,0,0,0,0,0,0,98,98,32,31,31,31,31,31,15,32,32,32,32,46,46,46,46,46,32,15,15,15,81,47,0,0,47,0,0,0,0,0,0
0,13,98,0,0,0,0,0,0,98,98,32,32,32,32,32,32,15,15,32,32,46,46,32,32,46,46,46,59,32,39,0,0,0,0,0,0,0,0,0,0,0
0,0,41,0,0,0,0,0,0,18,0,32,32,32,32,32,32,32,32,32,0,0,46,95,95,95,32,46,0,32,39,14,0,59,0,0,0,47,0,0,0,0
0,0,0,0,0,0,0,18,0,18,59,0,32,32,32,32,0,32,32,32,0,46,0,0,1,56,32,46,0,32,21,22,0,47,0,0,47,47,0,0,0,0
0,0,0,0,0,0,0,0,0,18,59,18,32,0,32,32,0,32,0,0,0,10,0,0,0,56,46,46,0,0,32,32,47,0,0,0,0,0,0,0,0,0
0,0,0,0,0,0,0,18,59,0,0,0,0,59,85,32,0,0,0,0,0,0,0,74,18,10,46,46,0,59,0,0,47,59,0,0,0,0,0,0,0,0
0,0,0,0,0,0,0,0,0,0,0,59,23,18,0,0,0,0,0,0,0,10,0,59,0,107,46,46,23,0,0,59,59,59,47,0,0,0,0,0,0,0
0,0,0,0,0,0,0,0,59,59,41,41,0,0,0,0,18,32,32,32,15,32,32,46,0,59,0,106,46,23,59,0,0,59,59,59,0,0,0,0,0,0
0,0,0,1,0,0,0,0,0,0,0,0,0,0,0,41,45,18,32,32,32,32,32,46,46,0,59,0,46,43,59,41,0,0,0,0,0,0,47,0,0,0
0,0,0,0,0,0,0,0,0,0,0,0,0,0,0,0,0,18,32,32,32,32,46,46,46,106,0,106,46,23,0,0,0,0,0,0,0,0,0,0,0,0
0,0,0,0,0,0,0,0,0,0,0,0,0,0,0,0,0,18,32,32,32,46,60,0,41,46,46,46,41,0,0,0,0,0,47,0,0,59,0,0,0,0
0,0,0,0,0,0,0,0,0,0,0,0,0,0,0,0,0,18,98,98,32,47,0,0,0,41,41,41,0,0,0,0,0,0,0,0,0,0,0,0,0,0
0,0,0,0,0,0,0,0,0,0,0,0,0,0,0,0,0,0,60,11,41,0,0,0,0,0,0,0,0,0,0,0,0,0,0,0,0,0,0,0,0,0
0,0,0,0,0,0,0,0,0,0,0,0,0,0,0,0,0,0,0,0,0,0,0,0,0,0,0,0,0,0,0,0,0,0,0,0,0,0,0,0,0,0
0,0,0,0,0,0,0,0,0,0,0,0,0,0,0,0,0,0,0,0,0,0,0,0,0,0,0,0,0,0,0,0,0,0,0,0,0,0,0,0,0,0
0,0,0,0,0,0,0,0,0,0,0,0,0,0,0,0,0,0,0,0,0,0,0,0,0,0,0,0,0,0,0,0,0,0,0,0,0,0,0,0,0,0
0,0,0,0,0,0,0,0,0,0,0,0,0,0,0,0,0,0,0,0,0,0,0,0,0,0,0,0,0,0,0,0,0,0,0,0,0,0,0,0,0,0
endlayer

layer
0,0,0,0,0,0,0,0,0,0,0,0,0,0,0,0,0,0,0,0,0,0,0,0,0,0,1,0,0,0,0,0,0,0,0,0,0,0,0,0,0,0
0,0,0,0,0,0,0,0,0,0,0,0,0,0,0,0,0,0,0,0,0,0,0,0,0,0,0,0,0,0,0,0,0,0,0,0,0,0,0,0,0,0
0,0,0,0,0,0,0,0,0,0,0,0,0,0,0,0,0,0,0,0,0,0,0,0,0,0,0,0,0,0,0,0,0,0,0,0,0,0,0,0,0,0
0,0,0,0,0,0,0,0,0,0,0,0,0,0,0,0,0,0,0,0,0,0,0,0,0,0,0,0,0,0,0,0,0,0,0,0,0,0,0,0,0,0
0,0,0,0,0,0,0,0,0,0,0,0,0,0,0,0,0,0,0,0,0,0,0,0,0,0,0,0,14,0,0,0,0,0,0,0,0,0,0,0,0,0
0,0,0,0,0,0,0,0,0,0,0,0,0,0,0,0,0,44,0,0,0,0,0,0,0,0,0,0,0,14,0,14,14,0,0,0,0,0,0,0,0,0
0,0,0,0,0,0,0,0,0,0,0,0,0,0,0,0,0,11,46,46,46,0,0,0,0,0,14,14,0,0,47,0,0,0,0,0,0,0,0,0,0,0
0,0,0,0,0,0,0,0,0,0,0,0,0,0,11,11,11,46,46,46,46,46,61,0,0,14,14,0,0,0,14,14,0,0,14,0,0,0,0,0,0,0
0,0,0,0,0,0,0,0,0,0,0,0,0,11,46,11,46,10,46,46,46,46,0,0,0,0,0,0,0,0,0,0,0,14,0,0,0,0,0,0,0,0
0,0,0,0,0,0,0,0,0,0,0,0,0,46,46,46,32,32,32,46,46,46,0,0,0,0,0,0,0,0,0,0,14,14,0,0,14,0,0,0,0,0
0,0,0,0,0,0,0,0,0,0,0,0,0,11,46,46,32,32,32,32,46,46,46,46,44,32,0,12,12,12,32,32,14,0,14,0,0,0,0,14,0,0
0,0,0,0,0,0,0,0,0,0,0,0,0,11,32,32,32,32,32,32,32,32,32,32,32,32,32,32,15,15,15,62,0,0,0,0,0,47,0,47,0,0
0,0,0,0,0,0,0,0,0,0,0,0,0,0,32,32,24,32,0,95,95,32,32,32,32,32,32,15,31,15,47,0,0,0,14,0,14,0,47,0,0,0
0,0,0,0,0,0,0,0,0,0,0,0,14,0,32,32,24,32,32,0,0,32,32,32,108,32,32,31,15,15,15,32,32,0,0,47,0,47,0,0,0,0
0,0,0,0,0,0,0,0,0,0,18,32,32,32,31,31,15,32,0,0,0,32,32,32,0,7,32,31,15,15,15,15,32,32,0,0,59,0,47,47,0,0
0,0,0,0,0,0,0,0,0,0,18,32,32,32,32,32,0,32,32,0,0,32,32,60,7,7,32,32,15,15,15,15,64,0,0,0,47,0,59,0,59,0
0,0,0,0,0,0,0,0,0,18,32,32,24,32,32,32,0,67,67,32,32,32,60,7,7,7,60,32,15,15,0,15,47,0,0,0,47,0,0,0,0,0
0,0,8,0,0,0,0,0,0,98,32,32,15,32,32,32,67,15,0,67,32,7,7,7,7,7,7,32,15,15,15,81,47,0,0,47,0,0,0,0,0,0
0,13,98,0,0,0,0,0,0,18,32,109,109,109,32,32,67,15,15,67,67,8,7,7,7,7,7,60,32,39,59,0,0,0,0,0,0,0,0,0,0,0
0,0,41,0,0,0,0,0,0,18,109,109,32,32,32,32,67,67,67,67,67,32,23,0,1,0,7,7,32,39,14,0,0,59,0,0,0,47,0,0,0,0
0,0,0,0,0,0,0,18,0,18,59,0,98,32,32,109,0,67,67,67,32,46,0,0,0,1,0,0,32,21,22,46,0,47,0,0,47,47,0,0,0,0
0,0,0,0,0,0,0,18,0,18,59,18,98,32,32,109,109,32,32,32,46,10,0,0,0,8,59,1,0,32,32,0,47,0,0,0,0,0,0,0,0,0
0,0,0,0,0,0,0,18,59,0,0,0,60,59,32,109,32,32,0,32,32,10,0,74,18,10,89,0,0,59,0,0,47,59,0,0,0,0,0,0,0,0
0,0,0,0,0,0,0,0,0,59,0,59,23,18,32,32,32,0,0,0,32,10,0,59,0,107,107,0,59,0,0,59,59,59,47,1,0,0,0,0,0,0
0,0,0,0,0,0,0,0,59,59,41,41,0,0,0,32,32,24,32,32,32,32,46,0,1,59,0,59,0,59,59,0,0,59,59,59,0,0,0,0,0,0
0,0,0,0,0,0,0,0,0,0,0,0,0,0,0,41,32,32,32,32,32,32,46,46,0,0,59,59,0,41,59,41,0,0,0,0,0,0,47,0,0,0
0,0,0,0,0,0,0,0,0,0,0,0,0,0,0,0,60,32,32,32,32,32,46,0,0,0,0,18,0,23,0,0,0,59,0,0,0,0,0,0,0,0
0,0,0,0,0,0,0,0,0,0,0,0,0,0,0,0,0,0,32,32,32,46,0,0,0,0,0,7,0,0,0,0,0,0,47,0,0,59,0,0,0,0
0,0,0,0,0,0,0,0,0,0,0,0,0,0,0,0,0,18,98,32,32,23,0,1,0,0,0,0,0,0,0,0,0,0,0,0,0,0,0,0,0,0
0,0,0,0,0,0,0,0,0,0,0,0,0,0,0,0,0,0,0,11,41,0,0,1,0,0,0,0,0,0,0,0,0,0,0,0,0,0,0,0,0,0
0,0,0,0,0,0,0,0,0,0,0,0,0,0,0,0,0,0,0,0,0,0,0,0,0,0,0,0,0,0,0,0,0,0,0,0,0,0,0,0,0,0
0,0,0,0,0,0,0,0,0,0,0,0,0,0,0,0,0,0,0,0,0,0,0,0,0,0,0,0,0,0,0,0,0,0,0,0,0,0,0,0,0,0
0,0,0,0,0,0,0,0,0,0,0,0,0,0,0,0,0,0,0,0,0,0,0,0,0,0,0,0,0,0,0,0,0,0,0,0,0,0,0,0,0,0
0,0,0,0,0,0,0,0,0,0,0,0,0,0,0,0,0,0,0,0,0,0,0,0,0,0,0,0,0,0,0,0,0,0,0,0,0,0,0,0,0,0
endlayer

layer
0,0,0,0,0,0,0,0,0,0,0,0,0,0,0,0,0,0,0,0,0,0,0,0,0,0,0,0,0,0,0,0,0,0,0,0,0,0,0,0,0,0
0,0,0,0,0,0,0,0,0,0,0,0,0,0,0,0,0,0,0,0,0,0,0,0,0,0,0,0,0,0,0,0,0,0,0,0,0,0,0,0,0,0
0,0,0,0,0,0,0,0,0,0,0,0,0,0,0,0,0,0,0,0,0,0,0,0,0,0,0,0,0,0,0,0,0,0,0,0,0,0,0,0,0,0
0,0,0,0,0,0,0,0,0,0,0,0,0,0,0,0,0,0,0,0,0,0,0,0,0,0,0,0,0,0,0,0,0,0,0,0,0,0,0,0,0,0
0,0,0,0,0,0,0,0,0,0,0,0,0,0,0,0,0,0,0,0,0,0,0,0,0,0,0,0,14,0,0,0,0,0,0,0,0,0,0,0,0,0
0,0,0,0,0,0,0,0,0,0,0,0,0,0,0,0,0,0,11,46,11,0,0,0,0,0,14,0,8,14,0,14,14,0,0,0,0,0,0,0,0,0
0,0,0,0,0,0,0,0,0,0,0,0,0,0,0,0,11,46,46,46,46,11,0,0,0,0,14,14,0,0,62,0,0,0,14,0,0,0,0,0,0,0
0,0,0,0,0,0,0,0,0,0,0,0,0,46,46,11,10,10,10,10,10,10,11,0,0,14,14,0,0,0,14,14,0,0,14,0,0,0,0,0,0,0
0,0,0,0,0,0,0,0,0,0,0,0,46,97,97,97,97,10,10,10,10,10,0,0,0,0,1,0,1,1,0,0,0,14,0,0,0,0,0,0,0,0
0,0,0,0,0,0,0,0,0,0,0,0,46,97,97,97,97,10,10,10,10,10,46,46,0,0,0,0,0,12,0,0,14,14,0,0,14,0,0,0,0,0
0,0,0,0,0,0,0,0,0,0,0,0,11,97,97,97,10,10,10,10,10,10,46,32,32,12,12,12,12,12,0,47,14,0,14,0,0,0,0,14,0,0
0,0,0,0,0,0,0,0,0,0,0,0,0,11,11,32,32,32,32,95,95,32,32,32,32,32,32,15,15,15,15,62,32,0,0,0,0,47,0,47,0,0
0,0,0,0,0,0,0,0,0,0,0,0,0,32,32,32,32,32,32,0,1,32,32,32,31,31,31,31,15,15,15,32,0,0,14,0,14,0,47,0,0,0
0,0,0,0,0,0,0,0,0,0,0,0,14,32,24,32,32,32,32,0,0,32,32,32,32,32,32,15,15,15,15,15,32,32,32,47,0,47,0,0,0,0
0,0,0,0,0,0,0,0,0,0,18,32,32,31,32,32,32,32,32,0,0,32,32,32,60,60,32,0,15,15,15,15,32,32,0,0,59,0,47,47,0,0
0,0,0,0,0,0,0,0,0,0,18,32,32,32,32,32,67,67,67,32,32,32,60,60,0,0,32,32,15,15,15,15,15,0,0,0,47,0,59,0,59,0
0,0,0,0,0,0,0,0,0,0,0,32,32,32,32,67,67,67,67,67,32,32,0,0,0,85,60,32,31,15,31,15,47,0,0,0,47,0,0,0,0,0
0,0,0,0,0,0,0,0,0,18,32,32,32,32,32,67,67,15,0,67,67,60,0,0,0,0,0,32,39,87,15,110,47,0,0,47,0,0,0,0,0,0
0,0,7,0,0,0,0,0,0,70,32,32,32,32,32,67,67,15,15,67,67,0,0,0,0,0,0,32,39,0,65,49,0,0,0,0,0,0,0,0,0,0
0,0,0,0,0,0,0,0,0,18,32,109,98,32,32,67,67,67,67,67,67,47,18,0,0,0,0,32,39,14,1,0,0,59,0,0,0,47,0,0,0,0
0,0,0,0,0,0,0,18,0,18,59,32,98,32,32,67,67,67,67,67,46,18,0,0,0,0,0,32,21,22,46,0,0,47,0,0,47,47,0,0,0,0
0,0,0,0,0,0,0,18,0,18,59,18,98,32,32,32,32,32,32,46,46,46,0,0,0,8,59,32,32,32,0,0,47,0,0,0,0,0,0,0,0,0
0,0,0,0,0,0,18,18,59,0,0,0,43,59,32,0,32,32,0,32,32,46,59,74,18,10,42,0,0,59,0,0,47,59,0,0,0,0,0,0,0,0
0,0,0,0,0,0,0,0,59,59,0,59,23,0,32,32,32,32,32,32,32,32,0,59,0,107,107,0,59,0,0,59,59,59,47,0,0,47,0,0,0,0
0,0,0,0,0,0,0,0,59,59,41,41,0,0,46,32,32,32,32,15,32,32,0,0,0,59,0,59,0,59,59,0,0,59,59,59,59,0,0,0,0,0
0,0,0,0,0,0,0,0,0,0,0,0,0,0,0,59,46,32,32,32,32,32,46,0,0,1,59,59,0,41,59,41,0,0,0,0,0,0,47,0,0,0
0,0,0,0,0,0,0,0,0,0,0,0,0,0,0,0,70,32,32,32,32,12,0,0,0,0,0,18,0,23,0,0,0,59,0,0,0,0,0,0,0,0
0,0,0,0,0,0,0,0,0,0,0,0,0,0,0,0,0,0,46,32,32,0,0,0,0,0,0,0,0,0,0,0,0,0,47,0,0,59,0,0,0,0
0,0,0,0,0,0,0,0,0,0,0,0,0,0,0,0,0,0,18,32,23,0,0,0,0,0,0,0,0,0,0,0,0,0,0,0,0,0,0,0,0,0
0,0,0,0,0,0,0,0,0,0,0,0,0,0,0,0,0,0,0,59,0,0,1,0,0,0,0,0,0,0,0,0,0,0,0,0,0,0,0,0,0,0
0,0,0,0,0,0,0,0,0,0,0,0,0,0,0,0,0,0,0,0,0,0,0,1,1,0,0,0,0,0,0,0,0,0,0,0,0,0,0,0,0,0
0,0,0,0,0,0,0,0,0,0,0,0,0,0,0,0,0,0,0,0,0,0,0,0,0,0,0,0,0,1,59,0,59,0,0,0,0,0,0,0,0,0
0,0,0,0,0,0,0,0,0,0,0,0,0,0,0,0,0,0,0,0,0,0,0,0,0,0,0,0,0,0,0,0,0,0,0,0,0,0,0,0,0,0
0,0,0,0,0,0,0,0,0,0,0,0,0,0,0,0,0,0,0,0,0,0,0,0,0,0,0,0,0,0,0,0,0,0,0,0,0,0,0,0,0,0
endlayer

layer
0,0,0,0,0,0,0,0,0,0,0,0,0,0,0,0,0,0,0,0,0,0,0,0,0,0,0,0,0,0,0,0,0,0,0,0,0,0,0,0,0,0
0,0,0,0,0,0,0,0,0,0,0,0,0,0,0,0,0,0,0,0,0,0,0,0,0,0,0,0,0,0,0,0,0,0,0,0,0,0,0,0,0,0
0,0,0,0,0,0,0,0,0,0,0,0,0,0,0,0,0,0,0,0,0,0,0,0,0,1,0,0,0,0,0,0,0,0,0,0,0,0,0,0,0,0
0,0,0,0,0,0,0,0,0,0,0,0,0,0,0,0,0,0,0,0,0,0,0,0,0,0,0,0,0,0,0,0,0,0,0,0,0,0,0,0,0,0
0,0,0,0,0,0,0,0,0,0,0,0,0,0,0,0,0,0,11,11,11,0,0,0,0,0,0,0,14,0,0,0,0,0,0,0,0,0,0,0,0,0
0,0,0,0,0,0,0,0,0,0,0,0,0,0,0,0,0,0,46,46,46,0,0,0,0,0,14,0,8,14,0,14,14,0,0,0,0,0,0,0,0,0
0,0,0,0,0,0,0,0,0,0,0,0,0,0,0,0,7,0,0,46,0,0,0,0,0,0,14,14,0,0,62,0,0,14,14,0,0,0,0,0,0,0
0,0,0,0,0,0,0,0,0,0,0,0,0,7,0,0,50,50,50,50,50,50,14,0,0,14,14,0,0,0,14,14,0,0,14,0,0,0,0,0,0,0
0,0,0,0,0,0,0,0,0,0,0,0,7,50,50,50,50,48,48,48,48,50,0,11,32,0,0,0,0,0,0,0,0,14,0,0,14,0,0,0,0,0
0,0,0,0,0,0,0,0,0,0,0,0,0,50,0,0,0,48,48,48,48,50,46,0,32,0,0,0,0,32,32,0,14,14,0,0,14,0,0,0,0,0
0,0,0,0,0,0,0,0,0,0,0,0,0,50,0,0,48,48,48,48,48,59,32,32,24,12,32,12,44,32,32,47,14,0,14,0,0,0,0,14,0,0
0,0,0,0,0,0,0,0,0,0,0,0,11,10,111,111,32,32,32,0,0,32,32,32,24,12,32,15,10,10,15,44,32,0,0,0,0,47,0,47,0,0
0,0,0,0,0,0,0,0,0,0,0,0,0,11,46,46,32,32,32,0,0,32,32,32,32,32,15,0,10,10,15,15,32,0,0,32,14,0,47,0,0,0
0,0,0,0,0,0,0,0,0,0,0,0,0,11,32,32,32,32,32,0,0,32,32,32,32,32,32,15,32,32,15,31,31,31,32,32,32,47,0,0,0,0
0,0,0,0,0,0,0,0,0,0,0,18,32,32,32,32,32,32,32,32,0,32,32,32,60,60,32,0,28,24,31,15,32,32,0,0,59,0,47,47,0,0
0,0,0,0,0,0,0,0,0,0,70,32,32,32,32,67,67,67,67,32,32,32,46,60,0,0,32,0,0,24,15,15,15,32,32,0,47,0,59,0,59,0
1,0,0,0,0,0,0,0,0,0,0,32,32,32,32,67,67,67,67,67,32,46,60,0,70,32,32,15,87,87,15,15,0,0,0,0,47,0,0,0,0,0
0,0,0,0,0,0,0,0,0,0,112,32,32,32,32,67,67,15,0,67,67,60,0,0,0,60,32,20,0,103,15,15,47,0,0,47,0,1,1,0,0,0
0,0,0,0,0,0,0,0,0,18,98,98,32,32,32,67,67,15,15,67,67,68,0,0,0,70,32,20,0,0,65,32,0,0,0,0,0,0,0,0,0,0
0,0,0,0,0,0,0,0,0,18,98,98,109,32,32,67,67,67,67,67,86,0,18,0,0,0,32,20,14,14,0,0,0,59,0,0,0,47,0,0,0,0
0,0,0,0,0,0,0,18,0,18,32,32,98,32,32,32,67,67,67,67,47,18,0,0,0,0,32,20,32,32,0,0,0,47,0,0,47,47,0,0,0,1
0,0,0,0,0,0,0,18,0,18,59,32,98,32,32,32,32,32,32,32,46,18,18,0,18,8,59,32,0,0,0,0,47,0,0,0,0,0,0,0,0,0
0,0,0,0,0,0,18,18,59,0,0,60,43,41,32,32,32,32,32,32,11,11,59,74,18,10,0,0,0,59,0,0,47,59,0,0,0,0,0,0,0,0
0,0,0,0,0,0,0,0,59,59,0,59,23,0,0,32,46,46,32,32,11,11,0,59,0,107,107,0,59,0,0,59,59,59,47,0,0,47,0,0,0,0
0,0,0,0,0,0,0,0,59,59,41,41,0,0,0,0,46,46,32,15,32,32,0,0,0,59,0,59,0,59,59,0,0,59,59,59,59,0,0,0,0,0
0,0,0,0,0,0,0,0,0,0,0,0,0,0,0,0,0,46,32,32,32,32,46,68,0,0,59,59,41,41,59,41,0,0,0,0,0,0,47,0,0,0
0,0,0,0,0,0,0,0,0,0,0,0,0,0,0,0,0,7,46,32,32,46,0,0,0,0,1,18,1,23,0,0,0,59,0,0,0,0,0,0,0,0
0,0,0,0,0,0,0,0,0,0,0,0,0,0,0,0,0,0,46,46,46,46,0,0,0,0,0,0,0,0,0,0,0,0,47,0,0,59,0,0,0,0
0,0,0,0,0,0,0,0,0,0,0,0,0,0,0,0,0,0,0,0,0,0,0,0,0,0,0,0,0,107,0,0,0,0,0,0,0,0,0,0,0,0
0,0,0,0,0,0,0,0,0,0,0,0,0,0,0,0,0,0,0,0,0,0,0,0,0,0,0,0,0,0,0,0,0,0,0,0,0,0,0,0,0,0
0,0,0,0,0,0,0,0,0,0,0,0,0,0,0,0,0,0,0,0,0,0,0,0,0,0,0,0,0,0,0,0,0,0,0,0,0,0,0,0,0,0
0,0,0,0,0,0,0,0,0,0,0,0,0,0,0,0,0,0,0,0,0,0,0,0,0,0,0,0,0,0,59,0,59,0,0,0,0,0,0,0,0,0
0,0,0,0,0,0,0,0,0,0,0,0,0,0,0,0,0,0,0,0,0,0,0,0,0,0,0,0,0,0,0,0,0,0,0,0,0,0,0,0,0,0
0,0,0,0,0,0,0,0,0,0,0,0,0,0,0,0,0,0,0,0,0,0,0,0,0,0,0,0,0,0,0,0,0,0,0,0,0,0,0,0,0,0
endlayer

layer
0,0,0,0,0,0,0,0,0,0,0,0,0,0,0,0,0,0,0,0,0,0,0,0,0,0,0,0,0,0,0,0,0,0,0,0,0,0,0,0,0,0
0,0,0,0,0,0,0,0,0,0,0,0,0,0,0,0,0,0,0,0,0,0,0,0,0,0,0,0,0,0,0,0,0,0,0,0,0,0,0,0,0,0
0,0,0,0,0,0,0,0,0,0,0,0,0,0,0,0,0,0,0,0,0,0,0,0,0,0,0,0,0,0,47,0,0,0,0,0,0,0,0,0,0,0
0,0,0,0,0,0,0,0,0,0,0,0,0,0,1,0,0,0,11,11,11,0,0,0,0,0,0,0,0,0,0,0,0,0,0,0,0,0,0,0,0,0
0,0,0,0,0,0,0,0,0,0,0,0,0,0,0,0,0,70,11,11,11,0,0,0,0,0,0,0,14,0,0,0,0,0,0,0,0,0,0,0,0,0
0,0,0,0,0,0,0,0,0,0,0,0,0,0,0,0,0,0,0,11,0,0,0,0,0,0,14,0,8,14,0,14,14,0,0,14,0,0,0,0,0,0
0,0,0,0,0,0,0,0,0,0,0,0,0,0,0,0,0,0,0,0,0,0,0,0,0,0,14,14,0,0,62,0,0,14,14,0,14,0,0,0,0,0
0,0,0,0,0,0,0,0,0,0,0,0,0,0,0,0,0,0,0,0,0,8,14,0,0,14,14,0,0,0,14,14,0,0,14,0,0,0,0,0,0,0
0,0,0,0,0,0,0,0,0,0,0,0,0,0,0,0,0,0,0,0,0,14,0,14,46,32,32,0,44,0,0,0,0,14,0,0,14,0,0,0,0,0
0,0,0,0,0,0,0,0,0,0,0,0,0,0,0,0,0,0,0,0,18,0,0,32,32,32,32,32,10,10,32,0,14,14,0,0,14,0,0,0,0,0
0,0,0,0,0,0,0,0,0,0,0,0,0,0,0,0,18,0,14,0,18,59,0,32,32,12,32,32,10,10,32,0,0,32,14,0,0,0,0,14,0,0
0,0,0,0,0,0,0,0,1,0,0,0,7,50,0,70,32,32,32,47,0,46,32,32,32,0,15,15,10,10,15,15,47,32,32,32,0,47,0,47,0,0
0,0,0,0,0,0,0,0,0,0,0,0,11,10,111,111,32,32,32,0,0,32,32,32,32,32,15,32,10,10,15,15,0,32,32,32,32,32,47,0,0,0
0,0,0,0,0,0,0,0,0,0,0,0,11,10,32,32,32,32,32,32,32,32,32,0,11,11,32,15,113,28,28,31,47,15,31,31,31,32,98,68,0,0
0,0,0,0,0,0,0,0,0,0,0,0,0,11,32,32,32,32,32,32,32,32,0,0,11,11,0,0,28,28,24,15,0,0,32,32,0,0,47,47,0,0
0,0,0,0,0,0,0,0,0,0,0,0,32,32,32,32,32,32,109,32,32,0,0,0,0,0,0,1,87,87,15,24,15,0,0,32,47,0,59,0,59,0
0,0,0,0,0,0,0,0,0,0,0,32,32,32,32,32,32,67,67,32,32,18,0,0,0,32,32,15,18,18,15,31,31,32,32,0,47,0,0,0,0,0
0,0,0,0,0,0,0,0,0,0,112,32,32,32,32,32,67,15,0,67,32,0,0,0,0,60,32,0,0,0,15,15,0,0,32,47,0,0,0,0,0,0
0,0,0,0,0,0,0,0,0,18,98,98,32,32,32,32,67,15,67,67,107,0,0,0,0,70,32,32,0,0,24,32,0,0,0,0,0,0,0,0,0,0
0,0,0,0,0,0,0,0,0,18,32,98,32,32,32,32,32,67,67,32,107,0,18,0,0,0,32,32,0,0,32,32,32,59,0,0,0,47,0,0,0,0
0,0,0,0,0,0,0,18,0,0,32,32,98,32,32,32,32,32,32,32,0,18,0,0,0,0,32,32,32,32,0,60,0,47,0,0,47,47,0,0,0,0
0,0,0,0,0,0,0,18,0,18,98,32,98,32,32,32,32,32,32,32,0,18,18,0,18,8,59,0,0,0,0,0,47,0,0,0,0,0,0,0,0,0
0,0,0,0,0,0,18,18,59,0,0,0,43,41,41,46,46,46,46,46,11,0,59,74,18,10,0,0,0,59,0,0,47,59,0,0,0,0,0,0,0,0
0,0,0,0,0,0,0,0,59,59,0,59,23,0,0,60,46,46,46,46,11,0,0,59,0,59,107,0,59,0,0,59,59,59,47,0,0,47,0,0,0,0
0,0,0,0,0,0,0,0,59,59,41,41,0,0,0,0,0,46,46,32,32,23,0,0,0,59,0,59,0,59,59,0,0,59,59,59,59,0,0,0,0,0
0,0,0,0,0,0,0,0,0,0,0,0,0,0,0,0,0,0,46,32,0,46,0,0,1,0,59,59,41,41,59,41,0,0,0,0,0,0,47,0,0,0
0,0,0,0,0,0,0,0,0,0,0,0,0,0,0,0,0,0,46,46,46,46,0,0,0,0,0,18,0,23,0,0,0,59,0,0,59,0,0,0,0,0
0,0,0,0,0,0,0,0,0,0,0,0,0,0,0,0,0,0,0,46,46,46,0,0,0,0,0,0,0,0,0,0,1,0,47,0,0,59,0,0,0,0
0,0,0,0,0,0,0,0,0,0,0,0,0,0,0,0,0,0,0,0,0,0,0,0,0,0,0,0,0,107,0,0,0,0,0,0,0,0,0,0,0,0
0,0,0,0,0,0,0,1,0,0,0,0,0,0,0,0,0,0,0,0,0,0,0,0,0,0,0,0,0,0,0,0,0,0,0,0,0,0,0,0,0,0
0,0,0,0,0,0,0,0,0,0,0,0,0,0,0,0,0,0,0,0,0,0,0,0,0,0,0,0,0,0,0,0,0,0,0,0,0,0,0,0,0,0
0,0,0,0,0,0,0,0,0,0,0,0,0,0,0,0,0,0,0,0,0,0,0,0,0,0,0,0,0,0,59,0,59,0,0,0,0,0,0,0,0,0
0,0,0,0,0,0,0,0,0,0,0,0,0,0,0,0,0,0,0,0,0,0,0,0,0,0,0,0,0,0,0,0,0,0,0,0,0,0,0,0,0,0
0,0,0,0,0,0,0,0,0,0,0,0,0,0,0,0,0,0,0,0,0,0,0,0,0,0,0,0,0,0,0,0,0,0,0,0,0,0,0,0,0,0
endlayer

layer
0,0,0,0,0,0,0,0,0,0,0,0,0,0,0,0,0,0,0,0,0,0,0,0,0,0,0,0,0,0,0,0,0,0,0,0,0,0,0,0,0,0
0,0,0,0,0,0,0,0,0,0,0,0,0,0,0,0,0,0,0,0,0,0,0,0,0,0,1,0,0,0,0,0,0,0,0,0,0,0,0,0,0,0
0,0,0,0,0,0,0,0,0,0,0,0,0,0,0,0,0,0,0,46,0,0,0,0,0,0,0,0,0,0,47,0,0,0,0,0,0,0,0,0,0,0
0,0,0,0,0,0,0,0,0,0,0,0,0,0,0,0,0,0,11,46,11,68,0,0,0,0,0,0,0,0,0,0,0,0,0,0,0,0,0,0,0,0
0,0,0,0,0,0,0,0,0,0,0,0,0,0,0,0,0,0,0,46,0,0,0,0,0,0,0,0,14,0,0,0,0,0,0,0,0,0,0,0,0,0
0,0,0,0,0,0,0,0,0,0,0,0,0,0,1,0,0,0,0,0,0,0,0,0,0,0,14,0,8,14,0,14,14,0,0,14,0,0,0,0,0,0
0,0,0,0,0,0,0,0,0,0,1,0,0,0,0,0,0,0,0,0,0,0,0,0,0,0,14,14,0,14,62,0,0,14,14,0,14,0,0,0,0,0
0,0,0,0,0,0,0,0,0,0,0,0,0,0,0,0,0,0,0,0,0,8,14,8,0,13,14,0,0,0,14,14,0,0,14,0,0,0,0,0,0,0
0,0,0,0,0,0,0,0,0,0,0,0,0,0,0,0,0,0,0,0,0,14,32,14,46,46,32,0,0,0,0,0,0,14,0,0,14,0,0,0,0,0
0,0,0,0,0,0,0,0,0,0,0,0,0,0,0,0,0,0,107,0,18,32,32,98,32,14,32,10,14,0,32,32,14,0,0,0,14,0,0,0,0,0
0,0,0,0,0,0,0,0,0,0,0,0,0,0,0,0,18,0,0,0,18,59,32,32,32,32,32,10,0,0,15,32,32,14,0,0,32,0,0,14,0,0
0,0,0,0,0,0,0,0,0,0,0,0,0,0,0,18,32,32,32,47,0,46,107,32,32,32,15,15,0,0,15,15,47,32,32,32,32,47,0,47,0,0
0,0,0,0,0,0,0,0,0,0,0,0,0,50,1,0,98,98,32,46,46,46,32,18,32,32,15,10,0,0,15,31,0,32,0,32,32,32,47,0,0,0
0,0,0,0,0,0,0,0,0,0,0,0,0,10,111,111,10,46,46,33,46,32,0,0,0,0,32,28,0,1,37,0,0,32,0,32,32,32,47,0,0,0
0,0,0,0,0,0,0,0,0,0,0,0,0,10,32,14,98,46,34,34,46,0,0,11,11,0,0,31,47,47,37,24,15,32,0,32,32,32,47,47,0,0
0,0,0,0,0,0,0,0,0,0,0,0,44,32,32,32,32,32,32,34,32,0,0,0,0,32,15,31,59,14,15,31,31,32,32,32,0,0,59,0,59,0
0,0,0,0,0,0,0,0,0,0,0,32,32,32,32,32,32,67,67,32,0,18,0,0,0,107,15,0,18,18,15,31,31,31,32,60,61,0,0,0,0,0
0,0,0,0,0,0,0,0,0,0,112,32,32,32,32,32,67,67,67,67,18,0,0,0,0,32,32,0,0,0,15,31,32,32,32,0,0,0,0,0,0,0
0,0,0,0,0,0,0,0,0,0,32,98,98,98,32,32,67,67,67,59,107,0,1,0,32,32,32,32,0,0,15,31,0,32,32,0,0,0,0,0,0,0
0,0,0,0,0,0,0,0,0,0,32,98,98,32,32,32,34,34,46,0,107,0,18,0,0,32,32,15,0,15,31,15,47,59,0,0,0,47,0,0,0,1
0,0,0,0,0,0,0,18,0,98,32,98,98,32,32,34,34,34,46,0,0,18,0,0,0,0,32,32,15,32,32,32,0,47,0,0,47,47,0,0,0,0
0,0,0,0,0,0,0,18,0,60,32,98,98,32,32,46,46,34,46,7,0,18,18,0,18,8,59,0,32,32,0,0,47,0,0,0,0,47,0,0,0,0
0,0,0,0,0,0,18,18,59,0,0,98,43,41,0,0,46,46,46,0,0,0,59,74,18,10,0,0,32,59,0,0,47,59,0,0,0,47,0,47,0,0
0,0,0,0,0,0,0,0,59,59,0,59,23,0,0,0,0,46,46,46,8,0,0,59,1,59,107,0,59,0,0,59,59,59,47,0,0,47,0,0,0,0
0,0,0,0,0,0,0,0,59,59,41,41,0,0,0,0,0,60,46,32,32,23,0,0,0,59,0,59,0,59,59,0,0,59,59,59,59,0,0,0,1,0
0,0,0,0,0,0,0,0,0,0,0,0,0,0,0,0,0,0,46,32,32,46,0,0,0,0,59,59,41,41,59,41,0,0,47,59,0,0,47,0,0,0
0,0,0,0,0,0,0,0,0,0,0,0,0,0,0,0,0,0,46,46,46,46,0,0,0,0,0,18,0,23,0,0,0,59,0,0,59,0,0,0,0,0
0,0,0,0,0,0,0,0,0,0,0,0,0,0,0,0,0,0,0,46,46,46,0,0,0,0,0,0,0,0,0,0,0,0,47,0,0,59,0,0,0,0
0,0,0,0,0,0,0,0,0,0,0,0,0,0,0,0,0,0,0,0,0,0,0,0,0,0,0,0,0,107,0,0,0,0,0,0,0,0,0,0,0,0
0,0,0,0,0,0,0,0,0,0,0,0,0,0,0,0,0,0,0,0,0,0,1,0,0,0,1,0,0,0,0,0,0,0,0,0,0,0,0,0,0,0
0,0,0,0,0,0,0,0,0,0,0,0,0,0,0,0,0,0,0,0,0,0,0,0,0,0,0,0,0,0,0,0,0,0,0,0,0,0,0,0,0,0
0,0,0,0,0,0,0,0,0,0,0,0,0,0,0,0,0,0,0,0,0,0,0,0,0,0,0,0,0,0,59,0,59,0,0,0,0,0,0,0,0,0
0,0,0,0,0,0,0,0,0,0,0,0,0,0,0,0,0,0,0,0,0,0,0,0,0,0,0,0,0,0,0,0,0,0,0,0,0,0,0,0,0,0
0,0,0,0,0,0,0,0,0,0,0,0,0,0,0,0,0,0,0,0,0,0,0,0,0,0,0,0,0,0,0,0,0,0,0,0,0,0,0,0,0,0
endlayer

layer
0,0,0,0,0,0,0,0,0,0,0,0,0,0,0,0,0,0,0,0,0,0,0,0,0,0,0,0,0,0,0,0,0,0,0,0,0,0,0,0,0,0
0,0,0,0,0,0,0,0,0,0,0,0,0,0,0,0,0,0,0,0,0,0,0,0,0,0,0,0,0,0,0,0,0,0,0,0,0,0,0,0,0,0
0,0,0,0,0,0,0,0,0,0,0,0,0,0,0,0,0,0,11,46,11,0,0,0,0,0,1,0,0,0,47,0,0,0,0,0,0,0,0,0,0,0
0,0,0,0,0,0,0,0,0,0,0,0,0,0,0,0,0,0,0,46,0,0,0,0,0,0,0,0,0,0,0,0,0,0,0,0,0,0,0,0,0,0
0,0,0,0,0,0,0,0,0,0,0,0,0,0,0,0,0,0,0,0,0,0,0,0,0,0,0,0,14,0,0,0,0,0,0,0,0,0,0,0,0,0
0,0,0,0,0,0,0,0,0,0,0,0,0,0,1,0,0,1,0,0,1,0,0,1,1,0,14,14,8,14,14,14,14,0,0,14,0,0,0,0,0,0
0,0,0,0,0,0,0,0,0,0,0,0,0,0,0,0,0,0,0,0,0,0,0,0,0,0,14,14,0,14,62,0,0,14,14,0,14,0,0,0,0,0
0,0,0,0,0,0,0,0,0,0,0,0,0,0,0,0,0,0,0,0,0,8,8,8,0,13,0,0,0,0,14,14,0,0,14,0,0,0,0,0,0,0
0,0,0,0,0,0,0,0,0,0,0,0,0,0,0,0,0,0,0,0,0,11,32,46,46,46,46,0,0,0,32,0,0,14,0,0,14,0,0,0,0,0
0,0,0,0,0,0,0,0,0,0,0,0,0,0,0,0,0,0,107,0,18,32,32,98,32,32,32,32,14,0,32,0,44,32,0,0,0,0,0,1,0,0
0,0,0,0,0,0,0,0,0,0,0,0,0,0,0,0,18,32,0,0,18,59,59,32,32,32,32,32,0,0,15,32,32,32,0,0,0,0,0,14,0,0
0,0,0,0,0,0,0,0,0,0,0,0,0,0,0,18,32,32,32,47,0,46,46,60,32,32,15,31,0,0,15,15,47,32,32,32,0,47,0,47,0,0
0,0,0,0,0,0,0,0,0,0,0,0,0,0,0,0,59,98,59,0,0,46,46,46,32,32,15,0,0,0,15,28,0,0,0,32,32,68,47,0,0,0
0,0,0,0,0,0,0,0,1,0,0,0,0,50,0,0,48,107,0,0,0,46,46,46,46,11,0,0,0,0,59,37,0,0,0,0,32,0,47,0,0,0
0,0,0,0,0,0,0,1,0,1,0,0,0,10,111,111,7,18,59,0,0,46,46,11,46,11,15,15,47,47,0,37,31,47,0,32,32,59,0,47,0,0
0,0,0,0,0,0,0,0,0,0,0,0,0,10,32,32,32,46,46,0,0,11,46,46,46,24,24,15,59,14,18,24,15,0,0,32,0,0,59,0,59,0
0,0,0,0,0,0,0,0,0,0,0,98,98,32,32,34,34,34,46,0,0,18,0,0,0,59,15,0,18,0,15,31,32,0,31,31,32,0,0,0,0,0
0,0,0,0,0,0,0,0,0,0,112,98,98,98,32,34,34,11,11,18,18,0,0,32,32,32,0,0,0,0,15,31,32,32,32,32,32,0,0,0,0,0
0,0,0,0,0,0,0,0,0,0,32,98,98,98,32,32,32,46,7,0,107,0,0,32,32,32,0,0,32,32,15,24,32,32,32,0,0,0,23,0,0,0
0,0,0,0,0,0,0,0,0,0,32,98,98,98,32,32,23,0,0,0,107,0,18,0,32,32,32,15,15,15,31,15,32,32,0,0,0,47,0,0,0,0
0,0,0,0,0,0,0,18,0,98,32,98,98,98,32,0,0,0,0,0,0,18,0,0,32,32,32,32,15,32,32,32,32,47,0,0,47,47,0,0,0,0
0,0,0,0,0,0,0,18,0,98,32,98,98,98,47,0,7,0,0,0,0,18,18,0,18,32,59,0,32,0,0,32,47,0,0,0,0,47,0,0,0,0
0,0,0,0,0,0,18,18,59,0,98,98,23,0,0,0,0,0,0,0,0,0,59,74,18,10,0,0,32,32,32,32,47,59,0,0,0,47,0,47,0,0
0,0,0,0,0,0,0,0,59,59,0,41,23,0,0,0,0,0,0,0,0,0,0,59,0,0,107,0,59,0,60,59,59,59,47,0,0,47,0,0,0,0
0,0,0,0,0,0,0,0,59,59,41,41,0,0,0,0,1,0,11,32,7,0,0,0,1,59,0,59,0,59,59,0,0,59,59,59,59,0,0,0,0,0
0,0,0,0,0,0,0,0,0,0,0,0,0,0,0,0,0,0,46,32,32,46,0,0,0,0,59,59,41,41,59,41,0,0,47,59,59,0,47,0,0,0
0,0,0,0,0,0,0,0,0,0,0,0,0,0,0,0,0,0,46,46,46,46,11,68,0,0,0,18,0,23,0,0,0,59,0,0,59,0,0,0,0,0
0,0,0,0,0,0,0,0,0,0,0,0,0,0,0,0,0,0,0,46,11,11,0,0,0,0,0,0,41,0,0,0,59,0,47,0,0,59,0,0,0,0
0,0,0,0,0,0,0,0,0,0,0,0,0,0,0,0,0,0,0,46,46,11,0,0,0,0,0,0,0,107,0,0,0,0,0,0,0,0,0,0,0,0
0,0,0,0,0,0,0,0,0,0,0,0,0,0,0,0,0,0,0,0,0,0,0,0,0,0,0,0,0,0,0,0,59,0,0,0,0,0,0,0,0,0
0,0,0,0,0,0,0,0,0,0,0,0,0,0,0,0,0,0,0,0,0,0,0,0,0,0,0,0,0,0,0,0,0,0,0,0,0,0,0,0,0,0
0,0,0,0,0,0,0,0,0,0,0,0,0,0,0,0,0,0,0,0,0,0,0,0,0,0,0,0,0,0,59,0,59,0,0,0,0,0,0,0,0,0
0,0,0,0,0,0,0,0,0,0,0,0,0,0,0,0,0,0,0,0,0,0,0,0,0,0,0,0,0,0,0,0,0,0,0,0,0,0,0,0,0,0
0,0,0,0,0,0,0,0,0,0,0,0,0,0,0,0,0,0,0,0,0,0,0,0,0,0,0,0,0,0,0,0,0,0,0,0,0,0,0,0,0,0
endlayer

layer
0,0,0,0,0,0,0,0,0,0,0,0,0,0,0,0,0,0,0,44,0,0,0,0,0,0,0,0,0,0,0,0,0,0,0,0,0,0,0,0,0,0
0,0,0,0,0,0,0,0,0,0,0,0,0,0,0,0,0,0,0,11,0,0,0,0,0,0,0,0,0,0,0,0,0,0,0,0,0,0,0,0,0,0
0,0,0,0,0,0,0,0,0,0,0,0,0,0,0,0,0,0,11,46,11,0,0,0,0,0,0,0,0,0,47,0,0,0,0,0,0,0,0,0,0,0
0,0,0,0,0,0,0,0,0,0,0,0,0,0,0,0,0,0,0,0,0,0,0,0,0,0,0,0,0,0,0,0,0,0,0,0,0,0,0,0,0,0
0,0,0,0,0,0,0,0,0,0,0,0,0,0,0,0,0,0,0,0,0,0,0,0,0,0,0,0,14,0,0,0,0,0,0,0,0,0,0,0,0,0
0,0,0,0,0,0,0,0,0,0,0,0,0,0,0,0,0,0,0,0,0,0,0,0,0,14,14,14,8,14,14,14,14,0,0,14,0,0,0,0,0,0
0,0,0,0,0,0,0,0,0,0,0,0,0,0,0,0,0,0,0,0,0,0,0,85,0,0,14,14,0,14,62,0,0,14,14,1,14,0,0,0,0,0
0,0,0,0,0,0,0,0,0,0,0,0,0,0,0,0,0,0,0,0,0,46,46,8,0,13,0,32,0,0,0,14,0,0,14,0,0,47,0,0,0,0
0,0,0,0,0,0,0,0,0,0,0,0,0,0,0,0,0,0,18,0,0,11,32,46,46,46,44,32,32,0,0,0,0,0,0,0,14,0,0,0,1,0
0,0,0,0,0,0,0,0,0,0,0,0,0,0,0,0,0,0,107,0,0,11,32,32,46,32,32,32,14,32,14,0,0,0,0,0,0,0,0,0,0,0
0,0,0,0,0,0,0,0,0,0,0,0,0,0,0,0,44,98,0,0,18,32,32,32,32,32,32,32,32,32,15,0,0,7,0,0,0,0,0,14,0,0
0,0,0,0,0,0,0,0,0,0,0,0,0,0,0,18,98,98,98,47,0,46,46,46,32,32,15,15,32,15,15,15,0,32,32,32,0,47,0,47,0,0
0,0,0,0,0,0,0,0,0,0,0,0,0,0,0,0,59,59,59,0,0,0,0,46,46,32,24,32,32,32,15,32,32,32,32,0,0,0,47,0,0,0
0,0,0,0,0,0,0,0,0,0,0,0,0,0,0,0,0,18,0,0,0,0,0,0,0,32,24,0,32,60,59,59,37,113,32,32,0,0,47,0,0,0
0,0,0,0,0,0,1,0,0,0,0,0,0,50,0,0,0,18,59,0,0,0,0,0,0,11,24,32,32,47,0,1,100,28,0,0,47,59,0,47,0,0
0,0,0,0,0,0,0,0,0,0,0,0,0,50,0,7,0,0,0,0,0,0,0,0,7,114,15,32,59,14,18,15,15,32,32,32,0,0,59,0,59,0
0,0,0,0,0,0,0,0,0,0,0,0,98,50,0,0,0,18,1,0,0,18,0,0,32,32,15,15,18,15,15,15,0,0,32,32,15,32,0,0,1,0
0,0,0,0,0,0,0,0,0,0,112,98,98,98,32,0,0,0,0,18,18,0,32,32,32,32,15,0,32,15,15,59,32,32,32,0,32,0,0,0,0,0
0,0,0,0,0,0,0,0,0,70,98,98,98,98,32,7,0,0,0,0,107,0,0,32,32,32,0,0,32,32,0,15,0,0,32,32,32,0,23,0,0,0
0,0,0,0,0,0,0,0,0,0,32,32,98,98,115,11,0,0,0,0,107,0,18,0,32,32,32,15,15,32,15,15,15,32,0,0,60,47,0,0,0,0
0,0,0,0,0,0,0,18,0,98,32,32,32,98,46,0,0,0,0,0,0,18,0,0,32,32,32,32,15,32,32,15,32,32,0,0,47,47,0,0,0,0
0,0,0,0,0,0,0,18,0,98,32,32,32,32,47,0,0,0,0,0,0,18,18,0,32,32,32,32,32,32,32,60,0,32,0,0,0,47,0,0,0,0
0,0,0,0,0,0,18,18,59,98,98,32,60,0,0,0,0,1,0,0,0,0,59,74,18,10,32,32,32,32,32,47,0,59,0,0,0,47,0,47,0,0
0,0,0,0,0,0,0,0,59,59,0,41,23,0,0,0,0,0,0,0,0,0,0,59,0,0,107,60,59,32,32,59,59,59,47,0,0,47,0,0,0,0
0,0,0,0,0,0,0,0,59,59,41,41,0,0,0,0,0,0,0,46,0,0,0,0,0,59,0,59,0,59,59,0,0,59,59,59,59,0,0,0,0,0
0,0,0,0,0,0,0,0,0,0,0,0,0,0,0,0,0,0,0,46,0,0,0,0,0,0,59,59,41,41,59,41,0,0,47,59,59,0,47,0,23,0
0,0,0,1,0,0,0,0,0,0,0,0,0,0,0,0,0,0,0,46,46,46,0,0,0,0,0,18,0,23,0,0,0,59,0,0,59,0,0,0,0,0
0,0,0,0,0,0,0,0,0,0,0,0,0,0,0,0,0,0,46,46,11,11,11,0,0,0,0,0,41,0,0,0,59,0,47,0,0,59,0,0,0,0
0,0,0,0,0,0,0,0,0,0,0,0,0,0,0,0,0,0,0,46,46,46,0,0,0,0,0,0,0,107,0,0,0,0,47,0,0,0,0,0,0,0
0,0,0,0,0,0,0,0,0,0,0,0,0,0,0,0,0,0,0,0,0,11,0,0,0,0,0,0,0,0,0,0,59,0,0,0,0,0,0,0,0,0
0,0,0,0,0,0,0,0,0,0,0,0,0,0,0,0,0,0,0,0,0,0,0,0,0,0,0,0,0,0,0,0,0,47,0,0,0,0,0,0,0,0
0,0,0,0,0,0,0,0,0,0,0,0,0,0,0,0,0,0,0,0,0,0,0,0,0,0,0,0,0,0,59,0,59,0,0,0,0,0,0,0,0,0
0,0,0,0,0,0,0,0,0,0,0,0,0,0,0,0,0,0,0,0,0,0,0,0,0,0,0,0,0,0,0,0,0,0,0,0,0,0,0,0,0,0
0,0,0,0,0,0,0,0,0,0,0,0,0,0,0,0,0,0,0,0,0,0,0,0,0,0,0,0,0,0,0,0,0,0,0,0,0,0,0,0,0,0
endlayer

layer
0,0,0,0,0,0,0,0,0,0,0,0,0,0,0,0,0,0,0,0,0,0,0,0,0,0,0,0,0,0,0,0,0,0,0,0,0,0,0,0,0,0
0,0,0,0,0,0,0,0,0,0,0,0,0,0,0,0,0,0,0,11,0,0,0,0,0,0,0,0,0,0,0,0,0,0,0,0,0,0,0,0,0,0
0,0,0,0,0,0,0,0,0,0,0,0,0,0,0,0,0,0,11,46,11,0,0,0,0,0,0,0,0,0,47,0,0,0,0,0,0,0,0,0,0,0
0,0,0,0,0,0,0,0,0,0,0,0,0,0,0,0,0,0,0,0,0,0,0,0,0,0,0,0,0,0,0,0,0,0,0,0,0,0,0,0,0,0
0,0,0,0,0,0,0,0,0,0,0,0,0,0,0,0,0,0,0,0,0,0,0,0,0,0,0,0,14,0,0,0,0,0,0,0,0,0,14,0,0,0
0,0,0,0,0,0,0,0,0,0,0,0,0,0,0,0,0,0,0,0,0,0,0,0,0,14,14,14,8,14,14,14,14,0,8,14,0,0,0,0,0,0
0,0,0,0,0,0,0,0,0,0,0,0,0,0,0,0,0,0,0,0,0,0,0,46,0,0,14,14,0,14,62,0,0,14,14,14,14,0,0,0,0,0
0,0,0,0,0,0,0,0,0,0,0,0,0,0,0,0,0,0,0,0,0,46,46,46,0,13,0,0,0,0,0,14,0,0,14,0,0,47,0,0,0,0
0,0,0,0,0,0,0,0,0,0,0,0,0,0,0,0,0,0,18,0,0,11,46,46,46,46,14,8,32,0,0,0,0,0,0,0,14,0,0,0,0,0
0,0,0,0,0,0,0,0,0,0,0,0,0,0,0,0,0,0,107,0,0,11,11,11,46,46,32,32,32,32,32,0,0,32,0,0,0,0,0,0,0,0
0,0,0,0,0,0,0,0,0,0,0,0,0,0,0,0,0,18,0,0,0,46,46,46,46,32,24,32,32,32,15,32,32,32,0,0,0,0,0,14,0,0
0,0,0,0,0,0,0,0,0,0,0,0,0,0,0,0,18,98,47,0,0,0,46,32,32,32,24,32,32,15,15,15,32,0,44,0,0,47,0,47,0,0
0,0,0,0,0,0,0,0,0,0,0,0,0,0,0,0,0,59,0,0,0,0,0,0,46,0,24,32,32,18,15,32,32,24,32,0,0,0,47,0,0,0
0,0,0,1,0,0,0,0,0,0,0,0,0,0,0,0,0,18,0,0,0,0,0,32,32,24,24,32,32,32,59,0,59,1,32,32,32,32,47,0,0,0
0,0,0,0,0,0,0,0,0,0,0,0,0,0,0,0,0,18,59,0,0,0,0,0,0,24,24,32,0,32,0,0,1,18,32,32,47,59,0,47,0,0
0,0,0,0,0,0,0,0,0,0,0,0,0,0,0,0,0,13,0,0,0,0,0,0,0,0,15,0,0,32,15,15,100,100,32,0,0,32,59,0,59,0
0,0,0,0,0,0,0,0,0,0,0,0,98,14,0,0,0,18,0,0,0,18,32,32,32,15,15,31,18,15,15,31,31,32,0,0,15,32,0,0,0,0
0,0,0,0,0,0,0,0,0,0,112,98,98,98,7,0,0,0,0,18,18,0,32,32,32,32,15,32,0,59,15,32,32,32,0,0,32,32,0,0,0,0
0,0,0,0,0,0,0,0,0,0,98,98,98,32,32,0,0,0,0,0,107,0,46,32,32,32,32,32,32,32,32,32,32,32,0,32,0,32,23,0,0,0
0,0,0,0,0,0,0,0,0,0,32,32,98,98,46,0,0,0,0,0,107,0,18,32,32,32,0,0,32,32,15,15,15,32,32,32,32,47,23,0,0,0
0,0,0,0,0,0,0,18,0,98,32,32,32,32,0,0,0,0,0,0,0,18,0,32,32,32,32,32,15,32,0,15,32,32,32,0,47,47,0,0,0,0
0,0,0,0,0,0,0,18,98,98,32,32,32,32,23,0,0,0,0,0,0,18,18,32,32,32,32,32,24,32,32,32,32,32,0,0,0,47,0,0,0,0
0,0,0,0,0,0,18,18,59,98,98,32,0,0,0,0,0,0,0,0,0,0,59,74,18,10,32,32,32,32,32,32,32,59,0,0,0,47,0,47,0,0
0,0,0,0,0,0,0,0,59,59,98,60,23,0,0,0,0,0,0,0,0,0,1,59,0,61,18,32,32,32,32,59,59,59,47,0,0,47,0,0,0,0
0,0,0,0,0,0,0,0,59,59,41,41,0,0,0,0,0,0,0,0,0,0,0,0,0,59,0,59,60,59,59,0,0,59,59,59,59,0,0,0,0,0
0,0,0,0,0,0,0,0,0,0,0,0,0,0,0,0,0,0,0,0,0,0,0,0,0,0,59,59,41,41,59,41,0,0,47,59,59,0,47,0,23,0
0,0,0,0,0,0,0,0,0,0,0,0,0,0,1,1,0,0,0,7,0,0,0,0,0,0,1,18,0,23,0,0,0,59,0,0,59,0,0,0,0,0
0,0,0,0,0,0,0,0,0,0,0,0,0,0,0,0,0,0,0,46,46,11,0,0,0,0,0,0,41,0,0,0,59,0,47,0,59,59,0,0,0,0
0,0,0,0,0,0,0,0,0,0,0,0,0,0,0,0,0,70,11,46,46,46,11,68,0,0,0,0,0,107,59,59,0,0,47,0,0,0,0,0,0,0
0,0,0,0,0,0,0,0,0,0,0,0,0,0,0,0,0,0,0,46,46,11,0,0,0,0,0,0,0,0,0,0,59,0,0,0,0,0,0,0,0,0
0,0,0,0,0,0,0,0,0,0,0,0,0,0,0,0,0,0,0,0,0,0,0,0,0,0,0,0,0,0,0,0,0,47,0,0,0,0,0,0,0,0
0,0,0,0,0,0,0,0,0,0,0,0,0,0,0,0,0,0,0,0,0,0,0,0,0,0,0,0,0,0,59,0,59,0,0,0,0,0,0,0,0,0
0,0,0,0,0,0,0,0,0,0,0,0,0,0,0,0,0,0,0,0,0,0,0,0,0,0,0,0,0,0,0,0,0,0,0,0,0,0,0,0,0,0
0,0,0,0,0,0,0,0,0,0,0,0,0,0,0,0,0,0,0,0,0,0,0,0,0,0,0,0,0,0,0,0,0,0,0,0,0,0,0,0,0,0
endlayer

layer
0,0,0,0,0,0,0,0,0,0,0,0,0,0,0,0,0,0,0,0,0,1,0,0,0,0,0,0,0,0,0,0,0,0,0,0,0,0,0,0,0,0
0,0,0,0,0,0,0,0,0,0,0,0,0,0,0,0,0,0,0,0,0,0,0,0,0,0,0,0,0,0,0,0,0,0,0,0,0,0,0,0,0,0
0,0,0,0,0,0,0,0,0,0,0,0,0,0,0,0,0,0,46,46,46,0,0,0,0,0,0,0,0,0,47,0,0,0,0,0,0,0,0,0,0,0
0,0,0,0,0,0,0,0,0,0,0,0,0,0,0,0,0,0,0,0,0,0,0,0,0,0,0,0,0,0,0,0,0,0,0,0,0,0,0,0,0,0
0,0,0,0,0,0,0,0,0,0,0,0,0,0,0,0,0,0,0,0,0,0,0,0,0,0,0,0,14,0,0,0,0,0,0,0,0,0,14,0,0,0
0,0,0,0,0,0,0,0,0,0,0,0,0,0,0,0,0,0,0,0,0,0,46,46,0,14,14,14,8,14,14,14,14,0,8,14,0,0,0,0,0,0
0,0,0,0,0,0,0,0,0,0,0,0,0,0,0,0,0,0,0,0,0,46,46,46,0,8,14,14,0,14,62,0,0,14,14,14,14,0,0,0,0,0
0,0,0,0,0,0,0,0,0,0,0,0,0,0,0,0,0,0,0,0,0,46,46,0,0,13,45,0,0,0,0,14,0,0,14,0,0,47,0,0,0,0
0,0,0,0,0,0,0,0,0,0,0,0,0,0,0,0,0,0,18,0,0,11,11,0,46,0,8,8,0,0,32,32,0,0,0,0,14,0,0,0,0,0
0,0,0,0,0,0,0,0,0,0,0,0,0,0,0,0,0,0,107,0,0,0,11,11,46,32,32,32,32,32,32,32,32,32,32,0,0,0,0,0,0,0
0,0,0,0,0,0,0,0,0,0,0,0,0,0,0,0,0,18,0,0,0,0,46,32,32,32,32,0,0,0,32,32,32,32,32,0,0,0,0,14,0,0
0,0,0,0,0,0,0,0,0,0,0,0,0,0,0,0,18,98,47,0,0,70,32,32,32,0,32,32,32,18,15,32,32,32,32,32,0,47,0,47,0,0
0,0,0,0,0,0,0,0,0,0,0,0,0,0,0,0,0,0,0,0,0,0,32,0,18,15,15,47,59,0,15,32,32,15,32,0,0,0,47,0,1,0
0,0,0,1,0,0,0,0,0,0,0,0,0,0,0,0,0,18,0,0,0,32,32,32,0,0,7,0,32,32,32,0,59,18,32,0,0,32,47,0,0,0
0,0,0,0,0,0,0,0,0,0,0,0,0,0,0,0,0,18,59,0,0,0,32,32,32,0,15,0,32,32,15,0,0,1,18,32,32,32,0,47,0,0
0,0,0,0,0,0,0,0,0,0,0,0,0,0,0,0,0,13,18,0,0,0,0,32,15,31,15,32,32,0,24,15,47,18,1,0,0,47,59,0,59,0
0,0,0,0,0,0,0,0,0,0,0,0,7,0,0,0,0,112,0,0,70,32,32,32,15,15,15,32,18,32,15,15,100,100,32,0,32,32,0,0,0,0
0,0,0,0,0,0,0,0,0,0,14,98,98,0,0,0,0,0,0,18,18,32,32,0,32,15,15,32,0,59,59,32,32,32,32,32,32,0,0,0,0,1
0,0,0,0,0,0,0,0,0,0,98,98,98,32,14,0,0,0,0,0,107,32,32,32,32,32,32,32,32,32,32,32,32,32,32,32,32,8,23,0,0,0
0,0,0,0,0,0,0,0,70,98,32,32,98,98,98,0,0,0,0,0,107,0,18,32,32,32,32,32,32,32,32,0,15,32,32,0,0,47,23,0,0,0
0,0,0,0,0,0,0,18,0,98,32,32,32,32,0,0,0,0,0,0,0,18,0,32,32,0,32,32,15,32,0,15,15,32,32,32,47,47,0,0,0,0
0,0,0,0,0,0,0,18,98,98,32,32,32,0,0,0,0,0,0,0,0,18,32,32,32,32,32,32,15,32,32,32,32,32,0,0,1,47,0,0,0,0
0,0,0,0,0,0,18,18,98,98,98,32,98,0,0,0,0,0,0,0,0,0,59,74,107,10,32,32,32,32,32,32,32,32,0,0,0,47,0,47,0,0
0,0,0,0,0,0,0,0,59,98,98,0,23,0,0,0,0,0,1,0,0,0,0,59,0,11,32,32,32,32,32,59,59,59,47,0,0,47,0,0,0,0
0,0,0,0,0,0,0,0,59,59,59,41,0,0,0,0,0,0,0,0,0,0,0,0,0,59,0,59,59,41,0,0,0,59,59,59,59,0,0,0,0,0
0,0,0,0,0,0,0,0,0,0,0,0,0,0,0,0,0,0,0,0,0,0,0,0,0,0,59,59,41,41,59,41,0,0,47,59,59,0,47,0,23,0
0,0,0,0,0,0,0,0,0,0,0,0,0,0,0,0,0,0,0,0,0,0,0,0,0,0,0,18,0,23,0,0,0,59,0,0,59,0,0,0,0,0
0,0,0,0,0,0,0,0,1,0,0,0,0,0,1,0,0,0,0,0,46,0,0,0,0,0,0,0,41,0,0,0,59,0,47,0,59,59,0,0,0,0
0,0,0,0,0,0,0,0,0,0,0,0,0,0,0,0,0,0,0,46,11,11,0,0,0,0,0,0,0,107,59,59,0,0,47,0,0,0,59,0,0,0
0,0,0,0,0,0,0,0,0,0,0,0,0,0,0,0,0,0,11,11,11,11,11,0,0,0,0,0,0,0,0,0,59,0,0,0,0,0,59,0,0,0
0,0,0,0,0,0,0,0,0,0,0,0,0,0,0,0,0,0,0,11,11,11,0,0,0,0,0,0,0,0,0,0,0,47,0,0,0,1,0,0,0,0
0,0,0,0,0,0,0,0,0,0,0,0,0,0,0,0,0,0,0,0,0,0,0,0,0,0,0,0,0,0,59,0,59,0,0,0,0,0,0,0,0,0
0,0,0,0,0,0,0,0,0,0,0,0,0,0,0,0,0,0,0,0,0,0,0,0,0,0,0,0,0,0,0,0,0,0,0,0,0,0,0,0,0,0
0,0,0,0,0,0,0,0,0,0,0,0,0,0,0,0,0,0,0,0,0,0,0,0,0,0,0,0,0,0,0,0,0,0,0,0,0,0,0,0,0,0
endlayer

layer
0,0,0,0,0,0,0,0,0,0,0,0,0,0,0,0,0,0,0,0,0,0,0,0,0,0,0,0,0,0,0,0,0,0,0,1,0,0,0,0,0,0
0,0,0,0,0,0,0,0,0,0,0,0,0,0,0,0,0,0,0,0,44,0,0,0,0,0,0,0,0,0,0,0,0,0,0,0,0,0,0,0,0,0
0,0,0,0,0,0,0,0,0,0,0,0,0,0,0,0,0,0,0,46,46,0,0,0,0,1,0,0,1,0,47,0,0,0,0,0,0,0,0,0,0,0
0,0,0,0,0,0,0,0,0,0,0,0,0,0,0,0,0,0,0,0,0,0,0,0,0,0,0,0,0,0,0,0,0,0,0,0,1,1,0,0,0,0
0,0,0,0,0,0,0,0,0,0,0,0,0,0,0,0,0,0,0,0,0,0,0,0,0,0,0,0,14,0,0,0,0,0,0,0,0,14,14,0,0,0
0,0,0,0,0,0,0,0,0,0,0,0,0,0,0,0,0,0,0,0,0,46,46,46,0,14,14,14,8,14,14,14,14,0,8,14,14,0,0,0,0,0
0,0,0,0,0,0,0,0,0,0,0,0,0,0,0,0,0,0,0,0,0,46,46,11,0,8,14,14,0,14,62,0,0,14,14,14,14,14,47,0,0,0
0,0,0,0,0,0,0,0,0,0,0,0,0,0,0,0,0,0,0,0,0,11,11,0,0,13,32,32,32,32,0,14,0,0,14,0,0,47,0,0,0,0
0,0,0,0,0,0,0,0,0,0,0,0,0,0,0,0,0,0,18,0,0,0,11,0,46,0,32,32,32,32,32,32,0,32,0,0,14,0,47,0,0,0
0,0,0,0,0,0,0,0,0,0,0,0,0,0,0,0,0,0,107,0,0,0,11,0,32,32,32,32,32,32,32,0,32,32,32,32,0,0,0,0,0,0
0,0,0,0,0,0,0,0,0,0,0,0,0,0,0,0,0,18,0,0,0,32,32,0,32,0,32,0,32,32,32,0,32,32,32,32,32,0,0,14,0,0
0,0,0,0,0,0,0,0,0,0,0,0,0,0,0,0,18,98,47,70,32,32,32,32,32,0,0,0,32,32,15,32,32,32,0,0,32,47,0,47,0,0
0,0,0,0,0,0,0,0,0,0,0,0,0,0,0,0,0,0,0,0,0,0,32,32,31,15,15,47,59,32,15,32,32,15,15,0,32,32,47,0,0,0
0,0,0,0,0,0,0,0,0,0,0,0,0,0,0,0,0,18,0,32,32,32,32,31,31,0,0,0,0,59,24,0,0,0,0,0,32,32,47,0,0,0
0,0,0,0,0,0,0,0,0,0,0,0,0,0,0,0,0,18,59,0,0,0,32,0,24,0,0,0,0,0,32,0,0,0,0,0,32,0,0,47,0,0
0,0,0,0,0,0,0,0,0,0,0,0,0,0,0,0,0,13,18,0,0,32,32,31,31,24,15,32,0,32,15,15,47,18,32,32,0,47,59,0,59,0
0,0,0,0,0,0,0,0,0,0,0,0,0,0,0,0,0,112,0,107,0,32,32,31,15,15,15,32,32,32,15,15,59,107,32,32,0,7,0,0,0,0
0,0,0,0,0,0,0,0,0,0,14,98,98,0,0,0,0,0,0,18,18,32,32,32,32,15,32,0,32,32,32,32,100,100,32,32,32,0,0,0,0,0
0,0,0,0,0,0,0,0,0,0,98,98,32,32,0,0,0,1,0,0,107,32,32,32,32,32,32,0,0,32,32,32,32,32,32,32,32,8,23,0,0,0
0,0,0,0,0,0,0,0,0,98,98,98,98,98,98,0,0,0,0,0,107,32,32,32,32,32,0,0,32,32,0,32,15,32,32,32,32,47,23,0,0,0
0,0,0,0,0,0,0,18,98,32,98,98,32,32,60,0,0,0,0,0,0,18,98,32,32,32,0,32,15,31,0,15,15,31,32,32,47,47,0,0,0,0
0,0,0,0,0,0,0,18,32,32,98,32,32,0,0,0,1,0,0,0,0,18,98,32,32,32,32,32,15,32,32,32,24,32,32,32,0,47,0,0,0,0
0,0,0,0,0,0,18,0,98,98,32,32,32,0,0,0,0,0,0,0,0,0,59,45,107,10,32,32,60,32,32,0,32,32,0,0,0,47,0,47,0,0
0,0,0,0,0,0,0,70,98,98,32,32,23,0,0,0,0,0,0,0,0,0,0,59,46,46,32,32,32,32,32,32,98,98,47,0,0,47,0,0,0,0
0,0,0,0,0,0,0,0,59,59,59,41,0,0,0,0,0,0,0,0,0,0,0,0,60,59,32,32,61,0,32,85,85,59,59,59,59,0,0,0,0,0
0,0,0,0,0,0,0,0,0,0,0,0,0,0,0,0,0,0,0,0,0,0,0,0,0,0,59,59,41,41,59,41,0,0,47,59,59,0,47,0,23,0
0,0,0,0,0,0,0,0,0,0,0,0,0,0,0,0,0,0,0,0,0,0,0,0,0,0,0,18,0,23,0,0,0,59,0,0,59,59,0,0,0,0
0,0,0,0,0,0,0,0,0,0,0,0,0,0,0,0,0,0,0,0,46,0,0,0,0,0,0,0,41,0,0,0,59,0,47,0,59,59,0,0,0,0
0,0,0,0,0,0,0,0,0,0,0,0,0,0,0,0,0,0,0,46,46,0,0,0,0,0,0,1,0,107,59,59,0,0,47,0,0,0,59,0,0,0
0,0,0,0,0,0,0,0,0,0,0,0,0,0,0,0,0,0,0,11,11,11,0,0,0,0,0,1,0,0,0,0,59,0,0,0,0,0,59,0,0,0
0,0,0,0,0,0,0,0,0,0,0,0,0,0,0,1,0,0,11,11,11,11,11,0,0,0,0,0,0,0,0,0,0,47,0,0,0,0,0,0,0,0
0,0,0,0,0,0,0,0,0,0,0,0,0,0,0,0,0,0,11,11,11,11,11,0,0,0,0,0,0,0,59,0,59,0,0,0,0,0,0,0,0,0
0,0,0,0,0,0,0,0,0,0,0,0,0,0,0,0,0,0,0,0,0,0,0,0,0,0,0,0,0,0,0,0,0,0,0,0,0,0,0,0,0,0
0,0,0,0,0,0,0,0,0,0,0,0,0,0,0,0,0,0,0,0,0,0,0,0,0,0,0,0,0,0,0,0,0,0,0,0,0,0,0,0,0,0
endlayer

layer
0,0,0,0,0,0,0,0,0,0,0,0,0,0,0,0,0,0,0,0,0,0,0,0,0,0,0,0,0,0,0,0,0,0,0,0,0,0,0,0,0,0
0,0,0,0,0,0,0,0,0,0,0,0,0,0,0,0,0,0,0,0,0,0,0,0,0,0,0,0,0,0,0,0,0,0,0,0,0,0,0,0,0,0
0,0,0,0,0,0,0,0,0,0,0,0,0,0,0,0,0,0,0,46,0,0,0,0,0,0,0,0,0,0,47,0,0,0,0,0,0,0,0,0,0,0
0,0,0,0,0,0,0,0,0,0,0,0,0,0,0,0,0,0,0,46,46,44,0,0,0,0,0,0,0,0,0,0,0,0,0,0,0,0,0,0,0,0
0,0,0,0,0,0,0,0,0,0,0,0,0,0,0,0,0,0,0,0,46,46,46,44,0,0,0,0,14,0,0,0,0,0,0,0,0,14,14,0,0,0
0,0,0,0,0,0,0,0,0,0,0,0,0,0,0,0,0,0,0,0,0,46,46,46,0,14,14,14,8,14,14,14,14,0,8,14,14,8,0,0,0,0
0,0,0,0,0,0,0,0,0,0,0,0,0,0,0,0,0,0,0,0,0,0,11,11,0,8,8,8,0,14,14,0,0,14,14,14,14,14,47,0,0,0
0,0,0,0,0,0,0,0,0,0,0,0,0,0,0,0,0,0,0,61,0,46,11,11,0,32,32,32,98,98,32,14,0,0,14,0,0,47,0,0,0,0
0,0,0,0,0,0,0,0,0,0,0,0,0,0,0,0,0,0,18,0,0,44,32,32,44,98,98,98,98,98,98,0,0,98,0,0,14,0,47,0,0,0
0,0,0,0,0,0,0,0,0,0,0,0,0,0,0,0,0,0,107,0,0,32,98,0,98,31,98,98,0,0,32,0,32,32,32,32,32,0,0,0,0,0
0,0,0,0,0,0,0,0,0,0,0,0,0,0,0,0,0,18,0,0,32,32,32,31,24,24,24,0,0,32,24,32,32,32,32,32,0,32,0,14,0,0
0,0,0,0,0,0,0,0,0,0,0,0,0,0,0,0,18,98,0,0,32,0,0,0,15,24,24,0,0,31,24,0,32,24,32,32,32,32,98,47,0,0
0,0,0,0,0,0,0,0,0,0,0,0,1,0,0,0,0,0,0,98,32,32,31,31,31,31,15,31,31,31,24,31,31,15,31,31,31,31,32,85,0,0
0,0,0,0,0,0,0,0,0,0,0,0,0,0,0,0,0,18,0,98,32,32,15,31,31,15,24,0,0,0,24,0,0,24,32,32,32,47,0,0,0,0
0,0,0,0,0,0,0,0,0,0,0,0,0,0,0,0,0,18,59,32,32,0,24,15,31,31,24,0,32,32,32,32,0,0,0,32,0,0,0,47,0,0
0,0,0,0,0,0,0,0,0,0,0,0,0,0,0,0,0,13,18,32,32,32,24,28,0,15,15,31,32,32,0,15,47,0,0,32,0,47,59,0,59,0
0,0,0,0,0,0,0,0,0,0,0,0,0,0,0,0,0,112,0,107,32,32,31,31,31,15,31,32,0,0,15,15,59,107,31,32,0,47,0,0,0,0
0,0,0,0,0,0,0,0,0,0,14,98,32,0,0,0,0,0,0,18,0,59,32,60,32,15,32,0,0,32,32,32,47,59,32,32,0,0,0,0,0,0
0,0,0,0,0,0,0,0,0,0,98,32,32,32,0,0,0,0,0,0,107,32,32,32,32,24,32,0,0,0,32,28,100,100,32,32,32,8,23,0,0,0
0,0,0,0,0,0,0,0,0,98,32,32,32,32,32,0,0,0,0,0,18,32,32,32,32,32,0,32,24,32,32,24,24,0,0,32,32,47,23,0,0,0
0,0,0,0,0,0,0,0,44,32,32,98,32,32,47,0,0,0,0,0,0,18,32,32,32,32,0,0,24,15,31,24,15,31,31,31,32,47,0,0,0,0
0,0,0,0,0,0,0,18,32,32,98,32,32,60,0,0,0,0,0,0,0,70,32,32,32,32,32,31,15,31,31,15,15,24,32,0,32,47,0,0,0,0
0,0,0,0,0,0,18,0,32,32,32,32,11,0,0,0,0,0,0,0,0,0,59,32,59,0,0,114,24,32,32,24,24,32,32,32,0,47,0,47,0,0
0,0,0,0,0,0,0,0,32,32,32,0,0,0,0,0,0,0,0,0,0,0,0,59,46,32,0,114,32,32,32,32,32,98,98,0,0,47,0,0,0,0
0,0,0,0,0,0,0,0,0,0,59,0,0,0,0,0,1,0,0,0,0,0,0,0,0,59,11,32,32,32,32,32,32,59,59,59,59,0,0,14,0,0
0,0,0,0,0,0,0,0,0,0,0,0,0,0,0,0,0,0,0,0,0,0,0,0,0,0,0,41,41,41,59,41,0,0,47,59,59,0,47,0,23,0
0,0,0,0,0,0,0,0,0,0,0,0,0,0,0,0,0,0,0,0,0,0,0,0,0,0,0,18,0,23,0,0,0,59,0,0,59,59,0,0,0,0
0,0,0,0,0,0,0,0,0,0,0,0,0,0,0,0,0,0,0,0,0,0,0,0,0,0,0,0,41,0,0,0,59,0,47,0,59,59,0,0,0,0
0,0,0,0,0,0,0,0,0,0,0,0,0,0,0,0,0,0,0,0,0,0,0,0,0,0,0,0,0,107,59,59,0,0,47,0,0,0,59,0,0,0
0,0,0,0,0,0,0,0,0,0,0,0,0,0,0,0,0,0,0,0,0,0,0,0,0,0,0,0,0,0,0,0,59,0,0,0,0,0,59,0,0,0
0,0,0,0,0,0,0,0,0,0,0,0,0,0,0,0,0,0,0,11,11,11,0,0,0,0,0,0,0,0,0,0,0,47,0,0,0,0,0,0,0,0
0,0,0,0,0,0,0,0,0,0,0,0,0,0,0,0,0,0,7,11,11,11,0,0,0,0,0,0,0,0,59,0,59,0,0,0,0,0,0,0,0,0
0,0,0,0,0,0,0,0,0,0,0,0,0,0,0,0,0,0,0,0,11,0,0,0,0,0,0,0,0,0,0,0,0,0,0,0,0,0,0,0,0,0
0,0,0,0,0,0,0,0,0,0,0,0,0,0,0,0,0,0,0,0,0,0,0,0,0,0,0,0,0,0,0,0,0,0,0,0,0,0,0,0,0,0
endlayer

layer
0,0,0,0,0,0,0,0,0,0,0,0,0,0,0,0,0,0,0,0,0,0,0,0,0,0,0,0,0,0,0,0,0,0,0,0,0,0,0,0,0,0
0,0,0,0,0,0,0,0,0,0,0,0,0,0,0,0,0,0,0,0,0,0,0,0,0,0,1,0,0,0,0,0,0,0,0,0,0,0,0,0,0,0
0,0,0,0,0,0,0,0,0,0,0,0,0,0,0,0,0,0,0,46,0,0,0,0,0,0,0,0,0,0,47,0,0,0,0,0,0,0,0,0,0,0
0,0,0,0,0,0,0,0,0,0,0,0,0,0,0,0,0,0,0,46,46,46,0,0,0,0,0,0,0,0,0,0,0,0,0,0,0,0,0,0,0,0
0,0,0,0,0,0,0,0,0,0,0,0,0,0,0,0,0,0,0,11,46,46,46,0,0,0,0,0,14,0,0,0,0,0,0,0,0,14,14,0,0,0
0,0,0,0,0,0,0,0,0,0,0,0,0,0,0,0,0,0,0,0,0,46,46,46,0,14,14,14,8,14,14,14,14,0,8,14,14,8,0,0,0,0
0,0,0,0,0,0,0,0,0,0,0,0,0,0,0,0,0,0,0,0,0,46,32,32,98,0,0,32,32,14,8,0,0,14,14,14,14,14,47,0,0,0
0,0,0,0,0,0,0,0,0,0,0,0,0,0,0,0,0,0,0,11,11,32,32,32,98,32,32,32,98,98,47,14,0,44,14,0,0,47,0,0,0,0
0,0,0,0,0,0,0,0,0,0,0,0,0,0,0,0,0,0,18,0,32,32,32,32,32,98,32,98,98,98,0,32,32,98,98,0,0,0,47,0,0,0
0,0,0,0,0,0,0,0,0,0,0,0,0,0,0,0,0,0,107,0,0,98,15,31,31,24,15,32,0,32,15,32,0,32,32,32,32,0,0,0,0,0
0,0,0,0,0,0,0,0,0,0,0,0,0,0,0,0,0,18,0,0,32,32,24,16,16,15,16,16,31,15,15,15,31,16,16,32,0,32,98,14,0,0
0,0,0,0,0,0,0,0,0,0,0,0,0,0,0,0,70,98,0,0,32,32,24,16,16,16,16,16,16,16,16,16,16,16,16,32,32,32,98,98,98,0
0,0,0,0,0,0,0,0,0,0,0,0,0,0,0,0,0,0,0,98,32,31,15,15,16,16,16,16,16,16,16,16,16,16,16,15,32,32,98,32,32,0
0,0,0,0,0,0,0,0,0,0,0,0,0,0,0,0,0,18,0,98,0,32,15,16,16,28,28,28,16,16,16,16,16,16,16,32,32,32,98,32,0,0
0,0,0,0,0,0,0,0,0,0,0,0,0,0,0,0,0,18,59,98,32,32,32,16,28,28,35,28,28,16,16,16,28,28,16,32,32,32,98,47,0,0
0,0,0,0,0,0,0,0,0,0,0,0,0,0,0,0,0,13,18,98,32,0,0,28,28,35,35,35,28,16,16,15,47,0,15,32,0,61,59,0,59,0
0,0,0,0,0,0,0,0,0,0,0,0,0,0,0,0,0,112,0,11,32,32,15,28,35,35,35,28,28,16,15,15,59,59,15,32,0,47,0,0,0,0
0,0,0,0,0,0,0,0,0,0,0,0,7,0,0,0,0,0,0,61,60,32,32,28,28,35,28,28,16,16,32,98,47,59,15,32,32,0,0,0,0,0
0,0,0,0,0,0,0,0,0,0,14,98,32,0,0,0,0,0,0,59,107,32,32,16,16,28,28,16,16,16,16,39,1,1,16,32,32,8,23,0,0,0
0,0,0,0,0,0,0,0,0,112,32,32,32,32,0,0,0,0,0,0,0,46,46,16,16,16,16,16,16,16,16,100,100,100,16,32,32,32,23,0,0,0
0,0,0,0,0,0,0,0,44,32,32,32,32,47,0,0,0,0,0,0,0,0,46,16,16,16,16,16,16,16,16,42,16,16,16,15,32,47,0,0,0,0
0,0,0,0,0,0,0,0,98,32,98,32,32,0,0,0,0,0,0,0,0,18,46,16,16,16,16,16,16,16,16,16,16,16,16,32,32,47,0,0,0,0
0,0,0,0,0,0,18,98,32,32,32,32,59,0,0,0,0,0,0,0,0,0,59,46,59,0,0,0,15,31,15,24,31,31,32,32,32,47,0,47,0,0
0,0,0,0,0,0,0,0,32,32,98,0,0,0,0,0,0,0,0,0,0,0,0,0,46,46,0,0,32,32,32,15,0,98,98,32,0,47,0,0,0,0
0,0,0,0,0,0,0,0,0,98,59,0,0,0,0,0,0,0,0,0,0,0,0,0,0,59,11,32,32,32,98,32,32,85,59,59,59,0,0,14,0,0
0,0,0,0,0,0,0,0,0,60,0,0,0,0,0,0,0,0,0,0,0,0,0,0,0,0,0,59,59,59,59,59,0,0,47,59,59,0,47,0,23,0
0,0,0,0,0,0,0,0,0,0,0,0,0,0,0,0,0,0,0,0,0,0,0,0,0,0,0,18,0,23,0,0,0,59,0,0,59,59,0,0,0,0
0,0,0,0,0,0,0,0,0,0,0,0,0,0,0,0,0,0,0,0,0,0,0,0,0,0,0,0,41,0,0,0,59,0,47,0,59,59,0,0,0,0
0,0,0,0,0,0,0,0,0,0,0,0,0,0,0,0,0,0,0,0,0,0,0,0,0,0,0,0,0,107,59,59,0,0,47,0,0,0,59,0,0,0
0,0,0,0,0,0,0,0,0,0,0,0,0,0,0,0,0,0,0,0,0,0,0,0,0,0,0,0,0,0,0,0,59,0,0,0,0,0,59,0,0,0
0,0,0,0,0,0,0,0,0,0,0,0,0,0,0,0,0,0,0,0,0,0,0,0,0,0,1,0,0,0,0,0,0,47,0,0,0,0,0,0,0,0
0,0,0,0,0,0,0,0,0,0,0,0,0,0,0,0,0,0,0,0,11,7,0,0,0,0,0,0,0,0,59,0,59,0,0,0,0,0,0,0,0,0
0,0,0,0,0,0,0,0,0,0,0,0,0,0,0,0,0,0,0,0,11,0,0,0,0,0,0,0,0,0,0,0,0,0,0,0,0,0,0,0,0,0
0,0,0,0,0,0,0,0,0,0,0,0,0,0,0,0,0,0,0,0,0,0,0,0,0,0,0,0,0,0,0,0,0,0,0,0,0,0,0,0,0,0
endlayer

layer
0,0,0,0,0,0,0,0,0,0,0,0,0,0,0,0,0,0,0,0,0,0,0,0,0,0,0,0,0,0,0,0,0,0,0,0,0,0,0,0,0,0
0,0,0,0,0,0,0,0,0,0,0,0,0,0,0,0,0,0,0,0,0,0,0,0,0,0,0,0,0,0,0,0,0,0,0,0,0,0,0,0,0,0
0,0,0,0,0,0,0,0,0,0,0,0,0,0,0,0,0,0,0,0,0,0,0,0,0,0,0,0,0,0,47,0,0,0,0,0,0,0,0,0,0,0
0,0,0,0,0,0,0,0,0,0,0,0,0,0,0,0,0,0,0,46,46,46,0,0,0,0,0,0,0,0,0,0,0,0,0,0,0,0,0,0,0,0
0,0,0,0,0,0,0,0,0,0,0,0,0,0,0,0,0,0,0,46,11,46,46,0,0,0,0,0,14,0,0,0,0,0,0,0,0,14,14,0,0,0
0,0,0,0,0,0,0,0,0,0,0,0,0,0,0,0,0,0,0,11,11,11,0,32,0,14,14,8,8,14,14,14,14,0,8,14,14,8,0,0,0,0
0,0,0,0,0,0,0,0,0,0,0,0,0,0,0,0,0,0,0,11,0,32,32,32,98,98,0,32,32,32,8,0,98,14,14,14,14,14,47,0,0,0
0,0,0,0,0,0,0,0,0,0,0,0,0,0,0,0,0,0,0,11,11,11,32,32,98,98,98,98,98,98,98,14,32,98,98,0,0,47,0,0,0,0
0,0,0,0,0,0,0,0,0,0,0,0,0,0,0,0,0,0,18,0,11,11,11,32,0,98,0,98,98,98,98,98,32,32,98,98,98,0,47,0,0,0
0,0,0,0,0,0,0,0,0,0,0,0,0,0,0,0,0,0,107,32,32,0,11,0,0,15,15,98,98,98,15,98,98,98,32,32,98,0,0,0,0,0
0,0,0,0,0,0,0,0,0,0,0,0,0,0,0,0,0,18,0,98,32,32,11,11,0,15,15,16,66,66,66,66,66,16,16,98,98,44,0,0,0,0
0,0,0,0,0,0,0,0,0,0,0,0,0,0,0,0,0,18,0,98,98,98,0,0,0,98,15,98,98,98,98,108,98,98,16,32,0,98,98,98,14,0
0,0,0,0,0,0,0,0,0,0,0,0,0,0,0,0,0,0,0,98,98,15,15,0,0,98,98,98,98,48,48,48,48,98,66,32,32,32,98,32,32,0
0,0,0,0,0,0,0,0,0,0,0,0,0,0,0,0,0,18,98,98,98,98,15,16,15,98,25,25,48,48,48,48,116,32,66,0,32,32,98,32,32,0
0,0,0,0,0,0,0,0,0,0,0,0,0,0,0,0,0,18,59,98,98,98,98,16,32,25,34,25,48,48,48,48,117,32,66,0,32,32,98,32,0,0
0,0,0,0,0,0,0,0,0,0,0,0,0,0,0,0,0,13,18,98,98,98,98,66,25,34,34,25,48,48,98,15,28,28,15,0,0,11,98,0,59,0
0,0,0,0,0,0,0,0,0,0,0,0,0,0,0,0,0,112,0,11,98,98,15,66,34,34,34,25,48,48,15,15,59,59,66,32,32,47,0,0,0,0
0,0,0,0,0,0,0,0,0,0,0,0,0,0,0,0,0,0,0,11,18,98,1,66,34,34,34,25,48,48,32,15,47,59,15,32,32,0,0,0,0,0
0,0,0,0,0,0,0,0,0,0,14,0,0,0,0,0,0,0,0,59,59,32,18,66,34,34,34,11,48,48,48,59,0,0,66,32,32,32,23,0,0,0
0,0,0,0,0,0,0,0,0,112,32,32,32,0,0,0,0,0,0,0,0,18,18,66,35,34,34,11,11,48,91,1,1,1,66,32,32,32,23,0,0,0
0,0,0,0,0,0,0,0,0,32,32,32,32,0,0,0,0,0,1,0,0,0,18,46,35,35,34,34,11,11,48,14,0,91,16,32,32,47,0,0,0,0
0,0,0,0,0,0,0,0,32,32,32,32,32,0,0,0,0,0,0,0,0,18,0,46,46,66,66,66,66,66,66,66,66,16,16,32,32,47,0,0,0,0
0,0,0,0,0,0,70,32,32,98,32,32,59,0,0,0,0,0,0,1,0,0,59,46,59,32,32,32,15,32,15,15,15,32,32,32,32,47,0,47,0,0
0,0,0,0,0,0,0,0,32,32,32,60,0,0,0,0,0,0,0,0,0,0,0,0,46,32,32,32,32,0,98,15,0,98,98,32,32,47,0,0,0,0
0,0,0,0,0,0,0,0,0,32,59,0,0,0,0,0,0,0,0,0,0,0,0,0,0,59,13,32,32,98,32,32,32,32,60,59,59,0,0,14,0,0
0,0,0,0,0,0,0,0,0,0,0,0,0,0,0,0,0,0,0,0,0,0,0,0,0,0,0,60,59,59,0,59,32,60,47,59,59,0,47,0,23,0
0,0,0,0,0,0,0,0,0,0,0,0,0,0,0,0,0,0,0,0,0,0,0,0,0,0,0,18,0,23,0,0,0,59,0,0,59,59,0,0,0,0
0,0,0,0,0,0,0,0,0,0,0,0,0,0,0,0,0,0,0,0,0,0,0,0,0,0,0,0,41,0,0,0,59,0,47,0,59,59,0,0,0,0
0,0,0,0,0,0,0,0,0,0,0,0,0,0,0,0,0,0,0,0,0,0,0,0,0,0,0,0,0,107,59,59,0,0,47,0,0,0,59,0,0,0
0,0,0,0,0,0,0,0,0,0,0,0,0,0,0,0,0,0,0,0,0,0,0,0,0,0,0,0,0,0,0,0,59,0,0,0,0,0,59,0,0,0
0,0,0,0,0,0,0,0,0,0,0,0,0,0,0,0,0,0,0,0,0,0,0,0,0,0,0,0,0,0,0,0,0,47,0,0,0,0,0,0,0,0
0,0,0,0,0,0,0,0,0,0,0,0,0,0,0,0,0,0,0,0,11,0,0,1,0,0,0,0,0,0,59,0,59,0,0,0,0,0,0,0,0,0
0,0,0,0,0,0,0,0,0,0,0,0,0,0,0,0,0,0,0,0,11,0,0,0,0,0,0,0,0,0,0,0,0,0,0,0,0,0,0,0,0,0
0,0,0,0,0,0,0,0,0,0,0,0,0,0,0,0,0,0,0,0,0,0,0,0,0,0,0,0,0,0,0,0,0,0,0,0,0,0,0,0,0,0
endlayer

layer
0,0,0,0,0,0,0,0,0,0,0,0,0,0,0,0,0,0,0,0,0,0,0,0,0,0,0,0,0,0,0,0,0,0,0,0,0,0,0,0,0,0
0,0,0,0,0,0,0,0,0,0,0,0,0,0,0,0,0,0,0,0,0,0,0,0,0,0,0,0,0,0,0,0,0,0,0,0,0,0,0,0,0,0
0,0,0,0,0,0,0,0,0,0,0,0,0,0,0,0,0,0,0,0,0,44,0,0,0,0,0,0,0,0,47,0,0,0,0,0,0,0,0,0,0,0
0,0,0,0,0,0,0,0,0,0,0,1,0,0,0,0,0,0,0,46,11,11,0,0,0,0,0,0,0,0,0,0,0,0,0,0,0,0,0,0,0,0
0,0,0,0,0,0,0,0,0,0,0,0,0,0,0,0,0,0,46,46,11,32,32,0,0,0,0,0,14,0,0,0,0,0,0,0,0,14,14,0,0,0
0,0,0,0,0,0,0,0,0,0,0,0,0,0,0,0,0,0,0,11,32,32,32,32,0,14,14,18,98,0,14,14,0,0,8,14,14,8,0,0,0,0
0,0,0,0,0,0,0,0,0,0,0,0,0,0,0,0,0,0,0,46,32,32,32,32,98,98,98,32,32,32,47,0,8,14,14,14,14,14,47,47,0,0
0,0,0,0,0,0,0,0,0,0,0,0,0,0,0,0,0,0,0,14,11,0,32,32,98,98,98,98,32,32,32,98,98,98,98,98,0,47,0,0,0,0
0,0,0,0,0,0,0,0,0,0,0,0,0,0,0,0,0,0,18,32,11,11,0,0,0,98,0,98,98,98,98,0,98,98,98,98,98,0,47,0,0,0
0,0,0,0,0,0,0,0,0,0,0,0,0,0,0,1,0,0,107,32,32,11,11,0,32,15,7,98,98,98,15,0,98,0,32,98,98,0,0,0,0,0
0,0,0,0,0,0,0,0,0,0,0,0,0,0,0,0,0,18,0,98,32,32,0,11,0,0,15,66,66,66,66,66,31,66,16,98,98,98,0,0,0,0
0,0,0,0,0,0,0,0,0,0,0,0,0,0,0,0,0,18,98,0,98,98,98,0,0,0,15,98,98,98,98,98,98,98,66,0,32,98,98,14,14,0
0,0,0,0,0,0,0,0,0,0,0,0,0,0,0,0,0,70,98,32,32,15,15,0,0,98,98,47,47,59,59,59,60,26,66,32,32,32,98,98,32,0
0,0,0,0,0,0,0,0,0,0,0,0,0,0,0,0,0,18,98,98,98,98,15,16,15,98,0,0,0,0,59,1,1,114,66,0,32,32,98,32,32,0
0,0,0,0,0,0,0,0,0,0,0,0,0,0,0,0,0,18,0,98,0,98,98,66,32,115,0,94,1,1,14,14,14,114,66,32,32,32,32,32,0,0
0,0,0,0,0,0,0,0,0,0,0,0,0,0,0,0,0,13,70,98,98,98,98,66,89,0,0,0,1,18,98,15,32,32,66,32,32,11,32,60,59,0
0,0,0,0,0,0,0,0,0,0,0,0,0,0,0,0,0,112,0,11,98,98,98,66,0,47,0,7,0,70,15,15,28,28,15,0,32,0,0,0,0,0
0,0,0,0,0,0,0,0,0,0,0,0,0,0,0,0,0,0,0,11,98,98,98,66,0,47,0,0,59,18,98,15,0,59,15,32,32,32,0,0,0,0
0,0,0,0,0,0,0,0,0,0,0,0,0,0,0,0,0,0,0,59,59,59,18,66,0,47,0,0,1,1,0,0,0,0,66,0,32,32,68,0,0,0
0,0,0,0,0,0,0,0,0,112,98,98,98,0,0,0,0,0,0,0,59,18,18,66,32,47,0,0,0,0,0,0,0,0,66,32,32,32,23,0,0,0
0,0,0,0,0,0,0,0,0,32,98,98,98,0,0,0,0,59,0,0,0,0,18,11,32,32,47,0,0,0,0,14,0,18,66,32,32,32,0,0,0,0
0,0,0,0,0,0,0,0,32,32,32,32,32,0,0,0,0,0,0,0,0,18,0,46,46,66,66,66,66,66,66,66,66,66,16,32,32,60,0,0,0,0
0,0,0,0,0,0,0,0,32,32,32,32,0,0,0,0,0,0,0,0,0,0,59,46,0,32,98,0,15,0,15,15,31,31,32,32,32,47,0,47,0,0
0,0,0,0,0,0,0,0,32,32,32,59,0,0,0,0,0,0,0,0,0,0,0,0,11,7,98,98,98,0,15,24,98,98,98,98,98,47,0,0,0,0
0,0,0,0,0,0,0,0,0,59,59,0,0,0,0,0,0,0,0,0,0,0,0,0,60,0,98,32,0,32,32,32,32,32,59,59,59,0,0,14,0,0
0,0,0,0,0,0,0,0,0,0,0,0,0,0,0,0,0,0,0,0,0,0,0,0,0,0,0,18,32,32,0,59,32,32,47,59,59,0,47,0,23,0
0,0,0,0,0,0,0,0,0,0,0,0,0,0,0,0,0,0,0,0,0,0,0,0,0,0,0,18,32,23,45,0,32,59,0,0,59,59,0,0,0,0
0,0,0,0,0,0,0,0,0,0,0,0,0,0,0,0,0,0,0,0,0,0,0,0,0,0,0,0,41,0,0,0,59,0,47,0,59,59,0,0,0,0
0,0,0,0,0,0,0,0,0,0,0,0,0,0,0,0,0,0,0,0,0,0,0,0,0,0,0,0,0,107,59,59,0,0,47,0,0,0,59,0,0,0
0,0,0,0,0,0,0,0,0,0,0,0,0,0,0,0,0,0,0,0,0,0,0,0,0,0,0,0,0,0,0,0,59,0,0,0,0,0,59,0,0,0
0,0,0,0,0,0,0,0,0,0,0,0,0,0,0,0,0,0,0,0,0,0,0,0,0,0,0,0,0,0,0,0,0,47,0,0,0,0,0,0,0,0
0,0,0,0,0,0,0,0,0,0,0,0,0,0,0,0,0,0,0,0,11,0,0,0,0,0,0,0,0,0,59,0,59,0,0,0,0,0,0,0,0,0
0,0,0,0,0,0,0,0,0,0,0,0,0,0,0,0,0,0,0,0,11,0,0,0,0,0,0,0,0,0,0,0,0,0,0,0,0,0,0,0,0,0
0,0,0,0,0,0,0,0,0,0,0,0,0,0,0,0,0,0,0,0,0,0,0,0,0,0,0,0,0,0,0,0,0,0,0,0,0,0,0,0,0,0
endlayer

layer
0,0,0,0,0,0,0,0,0,0,0,0,0,0,0,0,0,0,0,0,0,0,0,0,0,0,0,0,0,0,0,0,0,0,0,0,0,0,0,0,0,0
0,0,0,0,0,0,0,0,0,0,0,0,0,0,0,0,0,0,0,0,0,0,0,0,0,0,0,0,0,0,0,0,0,0,0,0,0,0,0,0,0,0
0,0,0,0,0,0,0,0,0,0,0,0,0,0,0,0,0,0,0,0,0,0,0,0,0,0,0,0,0,0,47,0,0,0,0,0,0,0,0,0,0,0
0,0,0,0,0,0,0,0,0,0,0,0,0,0,0,0,0,0,0,46,11,11,0,0,0,0,0,0,0,0,0,0,0,0,0,0,0,0,0,0,0,0
0,0,0,0,0,0,0,0,0,0,0,0,0,0,0,0,0,0,46,46,11,98,98,0,0,0,0,98,98,0,0,0,0,0,0,0,0,14,14,0,0,0
0,0,0,0,0,0,0,0,0,0,0,0,0,0,0,0,0,0,11,11,98,98,98,98,0,14,98,98,32,98,14,14,0,0,8,14,14,8,0,1,0,0
0,0,0,0,0,0,0,0,0,0,0,0,0,0,0,0,0,0,0,11,32,32,32,98,98,98,98,32,32,32,0,0,14,14,8,14,14,14,47,47,0,0
0,0,0,0,0,0,0,0,0,0,0,0,0,0,0,0,0,0,0,11,32,32,32,32,98,98,98,98,32,32,0,98,98,98,98,98,98,47,0,0,0,0
0,0,0,0,0,0,0,0,0,0,0,0,0,0,0,0,0,0,70,32,32,0,32,32,98,98,98,98,98,98,0,98,98,98,98,32,32,0,47,0,0,0
0,0,0,0,0,0,0,0,0,0,0,0,0,0,0,0,0,0,107,32,32,32,32,32,15,15,98,98,0,98,15,98,98,0,32,32,98,98,0,0,0,0
0,0,0,0,0,0,0,0,0,0,0,0,0,0,0,0,0,18,98,98,98,32,32,0,0,0,15,16,66,66,66,15,66,16,15,15,98,98,0,44,0,0
0,0,0,0,0,0,0,0,0,0,0,0,0,0,0,0,0,18,98,98,98,98,15,0,0,0,15,15,32,98,98,98,18,98,16,32,32,98,98,98,14,0
0,0,0,0,0,0,0,0,0,0,0,0,0,0,0,0,0,18,98,98,0,7,15,24,0,0,0,98,47,0,98,59,0,0,66,32,32,32,32,32,98,0
0,0,0,0,0,0,0,0,0,0,0,0,0,0,0,0,0,18,98,98,98,31,15,16,15,98,0,0,0,0,59,0,0,0,66,32,32,32,32,32,32,0
0,0,0,0,0,0,0,0,0,0,0,0,0,0,0,0,0,18,98,98,32,98,15,16,24,32,0,0,0,0,0,14,0,0,66,32,32,32,32,32,32,0
0,0,0,0,0,0,0,0,0,0,0,0,0,0,0,0,0,13,18,98,32,32,32,66,24,32,0,0,0,18,98,15,98,98,66,0,32,47,0,60,59,0
0,0,0,0,0,0,0,0,0,0,0,0,0,0,0,0,0,112,0,11,98,32,98,66,32,47,0,0,98,98,31,15,100,100,15,0,14,61,0,0,0,0
0,0,0,0,0,0,0,0,0,0,0,0,0,0,0,0,0,0,0,11,0,59,18,66,98,47,0,0,59,98,98,15,0,0,66,32,32,47,0,0,0,0
0,0,0,0,0,0,0,0,0,0,0,0,0,0,0,0,0,0,0,59,0,59,18,66,98,47,0,0,0,0,0,0,0,0,66,32,32,32,0,0,0,0
0,0,0,0,0,0,0,0,0,112,98,98,0,0,0,0,0,0,0,59,59,18,18,66,32,47,0,0,0,0,0,0,0,0,66,32,32,32,0,0,0,0
0,0,0,0,0,0,0,0,0,32,98,32,32,68,0,0,0,59,0,0,0,0,18,32,32,32,47,0,0,0,0,14,0,18,16,32,32,23,0,0,0,0
0,0,0,0,0,0,0,0,44,32,32,32,32,0,0,1,0,0,0,0,0,18,0,32,32,66,66,66,66,66,66,15,0,16,16,0,32,0,0,0,1,0
0,0,0,0,0,0,0,0,32,32,32,46,0,0,0,0,0,0,0,0,0,0,59,0,11,11,11,98,15,31,31,15,15,0,15,32,32,47,0,47,0,0
0,0,0,0,0,0,0,0,59,32,0,0,0,0,0,0,0,0,0,0,0,0,0,0,0,0,0,0,98,98,31,24,98,0,32,32,32,47,0,0,0,0
0,0,0,0,0,0,0,0,0,0,0,0,0,0,0,0,0,0,0,0,0,0,0,0,0,0,0,18,0,98,0,24,98,98,46,0,59,0,0,14,0,0
0,0,0,0,0,0,0,0,0,0,0,0,0,0,0,0,0,1,0,0,0,0,0,0,0,0,0,18,0,98,32,32,98,98,47,59,59,0,47,0,23,0
0,0,0,0,0,0,0,0,0,0,0,0,0,0,0,0,0,0,0,0,0,0,0,0,0,0,0,0,7,0,32,32,98,59,0,0,59,59,0,0,47,0
0,0,0,0,0,0,0,0,0,0,0,0,0,0,0,0,0,0,0,0,0,0,0,0,0,0,0,0,18,0,0,32,32,0,47,0,59,59,0,0,0,0
0,0,0,0,0,0,0,0,0,0,0,0,0,0,0,0,0,0,0,0,0,0,0,0,0,0,0,0,0,107,59,59,32,0,47,0,0,0,59,0,0,0
0,0,0,0,0,0,0,0,0,0,0,0,0,0,0,0,0,0,0,0,0,0,0,0,0,0,0,0,0,0,0,0,59,0,0,0,0,0,59,0,0,0
0,0,0,0,0,0,0,0,0,0,0,0,0,0,0,0,0,0,0,0,0,0,0,0,0,0,0,0,0,0,0,0,0,47,0,0,0,0,0,0,0,0
0,0,0,0,0,0,0,0,0,0,0,0,0,0,0,0,0,0,0,0,0,0,0,0,0,0,0,0,0,0,59,0,59,0,0,0,0,0,0,0,0,0
0,0,0,0,0,0,0,0,0,0,0,0,0,0,0,0,0,0,0,0,11,68,0,0,0,0,0,0,0,0,0,0,0,0,0,0,0,0,0,0,0,0
0,0,0,0,0,0,0,0,0,0,0,0,0,0,0,0,0,0,0,0,0,0,0,0,0,0,0,0,0,0,0,0,0,0,0,0,0,0,0,0,0,0
endlayer

layer
0,0,0,0,0,0,0,0,0,0,0,0,0,0,0,0,0,0,0,0,0,0,0,0,0,0,0,0,0,0,0,0,0,0,0,0,0,0,0,0,0,0
0,0,0,0,0,0,0,0,0,0,0,0,0,0,0,0,0,0,0,0,0,0,0,0,0,0,0,0,0,0,0,0,0,0,0,0,0,0,0,0,0,0
0,0,0,0,0,0,0,0,0,0,0,0,0,0,0,0,0,0,0,0,0,0,0,0,0,0,0,0,0,0,47,0,0,0,0,0,0,0,0,0,0,0
0,0,0,0,0,0,0,0,0,0,0,0,0,0,0,0,0,0,0,11,11,11,0,0,0,0,85,98,32,0,0,0,0,0,0,0,0,0,0,0,0,0
0,0,0,0,0,0,0,0,0,0,0,0,0,0,0,0,0,0,11,11,11,11,11,11,0,0,98,98,98,98,0,0,0,0,0,0,0,14,14,0,0,0
0,0,0,0,0,0,0,0,0,0,0,0,0,0,0,0,0,0,11,11,98,98,98,11,61,98,98,32,32,32,14,14,0,0,8,14,14,8,0,0,0,0
0,0,0,0,0,0,0,0,0,0,0,0,0,0,0,0,0,0,0,11,98,98,98,98,61,98,98,32,32,32,32,98,14,14,14,14,14,14,47,47,1,0
0,0,0,0,0,0,0,0,0,0,0,0,0,0,0,0,0,0,0,0,98,98,98,98,98,98,98,98,32,32,32,0,98,32,32,32,98,47,0,0,1,0
0,0,0,0,0,0,0,0,0,0,0,0,0,0,0,0,0,0,18,18,32,32,0,0,24,98,98,98,98,0,98,98,98,98,98,32,32,98,47,0,0,1
0,0,0,0,0,0,0,0,0,0,0,0,0,0,0,0,0,0,107,98,98,32,98,98,24,15,31,31,98,98,15,98,98,98,15,32,98,98,0,0,0,0
0,0,0,0,0,0,0,0,0,0,0,0,0,0,0,0,0,0,107,98,98,98,98,15,24,31,31,31,31,31,31,31,31,31,15,15,98,47,0,0,0,0
0,0,0,0,0,0,0,0,0,0,0,0,0,0,0,0,0,18,98,98,98,31,31,24,15,31,24,31,31,15,24,16,16,15,24,32,32,11,11,11,11,0
0,0,0,0,0,0,0,0,0,0,0,0,0,0,0,0,0,0,7,98,98,98,15,24,24,16,16,16,16,16,24,16,16,16,24,32,32,32,32,32,98,11
0,0,0,0,0,0,0,0,0,0,0,0,0,0,0,0,0,18,98,98,98,98,24,31,15,31,16,16,16,16,16,16,16,16,24,32,32,11,32,32,32,46
0,0,0,0,0,0,0,0,0,0,0,0,0,0,0,0,0,0,59,98,32,24,24,31,24,16,16,16,16,16,16,16,16,16,24,32,32,46,32,32,32,0
0,0,0,0,0,0,0,0,0,0,0,0,0,0,0,0,0,13,0,11,98,32,98,16,15,31,16,16,16,16,16,15,16,16,24,0,0,47,0,0,59,0
0,0,0,0,0,0,0,0,0,0,0,0,0,0,0,0,0,112,0,11,98,98,98,16,24,16,16,16,16,15,31,15,31,16,15,31,32,11,0,0,0,0
0,0,0,0,0,0,0,0,0,0,0,0,0,0,0,0,0,0,0,11,60,98,18,16,16,16,16,16,16,16,16,15,16,16,24,32,32,47,0,0,0,0
0,0,0,0,0,0,0,0,0,0,0,0,0,0,0,0,0,0,0,59,0,59,18,16,16,16,16,16,16,16,16,16,16,16,24,32,11,23,0,0,0,0
0,0,0,0,0,0,0,0,0,14,32,0,0,0,0,0,0,0,0,59,59,112,18,16,16,16,16,16,16,16,16,16,16,16,16,32,32,23,0,0,0,0
0,0,0,0,0,0,0,0,0,32,32,32,0,0,0,0,0,59,0,0,0,1,18,16,16,16,16,16,16,16,16,16,16,16,32,0,32,23,0,0,0,0
0,0,0,0,0,0,0,0,0,32,32,32,11,0,0,0,0,0,0,0,0,18,0,16,16,16,16,16,24,16,16,24,16,16,16,32,32,32,0,0,0,0
0,0,0,0,0,0,0,0,18,32,32,46,0,0,0,0,0,0,0,0,0,0,59,0,59,59,59,18,15,31,15,15,15,0,15,32,32,60,0,47,0,0
0,0,0,0,0,0,0,0,0,59,60,0,0,0,0,0,0,0,0,0,0,0,0,0,0,0,98,98,98,98,7,15,98,98,32,11,32,98,0,0,0,0
0,0,0,0,0,0,0,0,0,0,0,0,0,0,0,0,0,0,0,0,0,0,0,0,0,0,0,18,98,98,98,15,32,32,46,46,32,0,0,14,0,0
0,0,0,0,0,0,0,0,0,0,0,0,0,0,0,0,0,0,0,0,0,0,0,0,0,0,0,18,98,32,32,24,32,32,46,61,59,0,47,0,23,0
0,0,0,0,0,0,0,0,0,0,0,0,0,0,0,0,0,0,0,0,0,0,0,0,0,0,0,0,59,0,32,24,98,46,11,0,59,59,0,0,47,0
0,0,0,0,0,0,0,0,0,0,0,0,0,0,0,0,0,0,0,0,0,0,0,0,0,0,0,0,18,32,32,24,32,98,47,0,59,59,0,0,0,0
0,0,0,0,0,0,0,0,0,0,0,0,0,0,0,0,0,0,0,0,0,0,0,0,0,0,0,0,0,107,59,32,32,32,47,0,0,0,59,0,0,0
0,0,0,0,0,0,0,0,0,0,0,0,0,0,0,0,0,0,0,0,0,0,0,0,0,0,0,0,0,0,0,0,0,0,0,0,0,0,59,0,0,0
0,0,0,0,0,0,0,0,0,0,0,0,0,0,0,0,0,0,0,0,0,0,0,0,0,0,0,0,0,0,0,0,0,47,0,0,0,0,0,0,0,0
0,0,0,0,0,0,0,0,0,0,0,0,0,0,0,0,0,0,0,0,0,0,0,0,0,0,0,0,0,0,59,0,59,0,0,0,0,0,0,0,0,0
0,0,0,0,0,0,0,0,0,0,0,0,0,0,0,0,0,0,0,0,11,0,0,0,0,0,0,0,0,0,0,0,0,0,0,0,0,0,0,0,0,0
0,0,0,0,0,0,0,0,0,0,0,0,0,0,0,0,0,0,0,0,0,0,0,0,0,0,0,0,0,0,0,0,0,0,0,0,0,0,0,0,0,0
endlayer

layer
0,0,0,0,0,0,0,0,0,0,0,0,0,0,0,0,0,0,0,0,0,0,0,0,0,0,0,0,0,0,0,0,0,0,0,0,0,0,0,0,0,0
0,0,0,0,0,0,0,0,0,0,0,0,0,0,0,0,0,0,0,0,0,0,0,0,0,0,0,0,0,0,0,0,0,0,0,0,0,0,0,0,0,0
0,0,0,0,0,0,0,0,0,0,0,0,0,0,0,0,0,0,0,0,0,0,0,0,0,0,0,98,32,0,47,0,0,0,0,0,0,0,0,0,0,0
0,0,0,0,0,0,0,0,0,0,0,0,0,0,0,0,0,0,44,11,11,0,0,0,0,44,98,98,32,32,0,0,0,0,0,0,0,0,0,0,0,0
0,0,0,0,0,0,0,0,0,0,0,0,0,0,0,0,0,0,11,46,11,11,11,11,44,98,98,32,32,32,0,0,0,0,0,0,0,14,14,0,0,0
0,0,0,0,0,0,0,0,0,0,0,0,0,0,0,0,0,0,0,46,11,11,11,11,98,98,98,98,98,98,14,14,0,0,8,14,14,8,0,0,0,0
0,0,0,0,0,0,0,0,0,0,0,0,0,0,0,0,0,18,0,46,11,98,98,98,98,98,98,98,98,98,98,98,14,14,32,32,32,14,47,47,0,0
0,0,0,0,0,0,0,0,0,0,0,0,0,0,0,0,0,0,0,70,98,98,98,98,98,98,98,98,98,98,98,98,98,98,32,32,32,98,68,0,1,0
0,0,0,0,0,0,0,0,0,0,0,0,0,0,0,0,0,0,18,18,98,98,98,98,0,98,98,98,98,98,0,98,98,98,98,98,98,98,47,0,0,0
0,0,0,0,0,0,0,0,0,0,0,0,0,0,0,0,0,18,107,18,98,98,98,98,24,98,98,98,98,98,98,98,98,98,98,98,98,98,11,0,0,0
0,0,0,0,0,0,0,0,0,0,0,0,0,0,0,0,0,0,107,98,98,98,98,15,15,15,15,31,31,31,15,98,98,98,98,98,98,11,11,11,0,0
0,0,0,0,0,0,0,0,0,0,0,0,0,0,0,0,0,0,70,98,98,98,31,15,15,15,31,31,32,32,32,32,32,32,15,32,32,11,11,11,11,11
0,0,0,0,0,0,0,0,0,0,0,0,0,0,0,0,0,0,18,98,98,98,98,15,15,15,31,98,0,32,32,32,0,0,32,32,32,46,46,98,98,11
0,0,0,0,0,0,0,0,0,0,0,0,0,0,0,0,0,18,98,118,98,98,98,98,24,15,0,0,0,0,32,32,0,0,32,32,32,11,46,32,32,46
0,0,0,0,0,0,0,0,0,0,0,0,0,0,0,0,0,0,60,18,98,32,98,98,0,0,0,0,32,32,0,0,0,0,32,32,32,0,0,98,32,11
0,0,0,0,0,0,0,0,0,0,0,0,0,0,0,0,0,13,0,11,98,32,98,98,15,98,98,0,32,0,31,15,15,0,32,32,32,47,0,0,59,0
0,0,0,0,0,0,0,0,0,0,0,0,0,0,0,0,0,112,0,11,98,98,98,98,98,0,98,98,31,15,31,15,31,31,15,32,11,0,0,0,0,0
0,0,0,0,0,0,0,0,0,0,0,0,0,0,0,0,0,0,0,11,59,98,98,98,98,98,0,98,0,32,15,24,15,32,32,32,0,0,0,0,0,0
0,0,0,0,0,0,0,0,0,0,0,0,0,0,0,0,0,0,0,59,0,59,98,32,32,32,32,32,32,32,0,32,0,32,32,32,11,23,0,0,0,0
0,0,0,0,0,0,0,0,0,0,7,0,0,0,0,0,0,0,0,59,59,112,60,32,11,32,98,32,32,32,0,24,32,32,32,32,32,23,0,0,0,0
0,0,0,0,0,0,0,0,0,14,32,8,0,0,0,0,0,59,0,0,0,18,0,48,46,32,98,32,32,32,32,24,47,32,32,32,32,23,0,0,0,0
0,0,0,0,0,0,0,0,70,32,32,32,11,0,0,0,0,0,0,0,0,18,0,7,48,11,98,98,15,0,0,15,98,98,0,32,46,0,0,0,0,0
0,0,0,0,0,0,0,0,18,98,32,0,0,0,0,59,0,0,0,0,0,0,59,0,0,0,59,98,98,98,15,24,15,98,32,32,32,32,98,47,0,0
0,0,0,0,0,0,0,0,0,59,41,0,0,0,0,0,0,0,0,0,0,0,0,0,0,0,70,98,98,98,98,15,98,98,32,32,32,32,98,0,0,0
0,0,0,0,0,0,0,0,0,0,0,0,0,0,0,0,0,0,0,0,0,0,0,0,0,0,0,18,98,98,0,98,98,32,32,32,32,32,98,14,0,0
0,0,0,0,0,0,0,0,0,0,0,0,0,0,0,0,0,0,0,0,0,0,0,0,0,0,0,18,60,0,0,0,32,32,11,46,59,98,47,0,23,0
0,0,0,0,0,0,0,0,0,0,0,0,0,0,0,0,0,0,0,0,0,0,0,0,0,0,0,0,59,32,31,32,32,46,11,11,59,59,0,0,47,0
0,0,0,0,0,0,0,0,0,0,0,0,0,0,0,0,0,0,0,1,0,0,0,0,0,0,0,0,18,0,32,32,32,11,11,0,59,59,0,0,0,0
0,0,0,0,0,0,0,0,0,0,0,0,0,0,0,0,0,0,0,0,0,0,0,0,0,0,0,0,0,18,32,15,32,98,0,0,0,0,59,0,0,0
0,0,0,0,0,0,0,0,0,0,0,0,0,0,0,0,0,0,0,0,0,0,0,0,0,0,0,0,0,0,32,98,98,98,68,0,0,0,59,0,0,0
0,0,0,0,0,0,0,0,0,0,0,0,0,0,0,0,0,0,0,0,0,0,0,0,0,0,0,0,0,0,0,98,98,47,0,0,0,0,0,0,0,0
0,0,0,0,0,0,0,0,0,0,0,0,0,0,0,0,0,0,0,0,0,0,0,0,0,0,0,0,0,0,59,0,59,0,0,0,0,0,0,0,0,0
0,0,0,0,0,0,0,0,0,0,0,0,0,0,0,0,0,0,0,0,11,0,0,0,0,0,0,0,0,0,0,0,0,0,0,0,0,0,0,0,0,0
0,0,0,0,0,0,0,0,0,0,0,0,0,0,0,0,0,0,0,0,0,0,0,0,0,0,0,0,0,0,0,0,0,0,0,0,0,0,0,0,0,0
endlayer

layer
0,0,0,0,0,0,0,0,0,0,0,0,0,0,0,0,0,0,0,0,0,0,0,0,0,0,0,0,0,0,0,0,0,0,0,0,0,0,0,0,0,0
0,0,0,0,0,0,0,0,0,0,0,0,0,0,0,0,0,0,0,0,0,0,0,0,0,0,0,0,0,0,0,0,0,0,0,0,0,0,0,0,0,0
0,0,0,0,0,0,0,0,0,0,0,0,0,0,0,0,0,0,0,0,0,0,0,0,0,0,11,32,32,32,47,0,0,0,0,0,0,0,0,0,0,0
0,0,0,0,0,0,0,0,0,0,0,0,0,0,0,0,0,0,0,11,11,0,0,0,0,11,46,32,32,98,0,0,0,0,0,0,0,0,0,0,0,0
0,0,0,0,0,0,0,0,0,0,0,0,0,0,0,0,0,0,11,11,11,11,11,11,11,11,11,98,98,98,0,0,0,0,0,0,0,14,14,0,0,0
0,0,0,0,0,0,0,0,0,0,0,0,0,0,0,0,0,0,0,46,11,11,11,11,11,98,98,98,32,32,14,14,0,0,0,14,8,8,0,47,0,0
