
# Created by Ruins mod version 14.6 Ingame Parser
# authoring Player: ArchNihil

weight=1
embed_into_distance=0
acceptable_target_blocks=
unacceptable_target_blocks=flowing_water,water,flowing_lava,lava
dimensions=7,10,10
allowable_overhang=0
max_leveling=2
leveling_buffer=0
preserve_water=0
preserve_lava=0

rule1=0,100,minecraft:fence-0
rule2=0,100,minecraft:log2-1
rule3=0,100,minecraft:log2-9
rule4=0,100,minecraft:log2-5
rule5=0,100,ChestGenHook:dungeonChest:5-5
rule6=0,100,chisel:birch_planks-5
rule7=0,100,minecraft:spruce_stairs-0
rule8=0,100,minecraft:spruce_stairs-2
rule9=0,100,minecraft:glowstone-0
rule10=0,100,minecraft:spruce_stairs-3
rule11=0,100,minecraft:spruce_stairs-1
rule12=0,100,Railcraft:tile.railcraft.residual.heat-0
rule13=0,100,minecraft:planks-2
rule14=0,100,MobSpawner:Witch
rule15=0,100,ChestGenHook:dungeonChest:5-2
rule16=0,100,minecraft:double_stone_slab-0
rule17=0,100,minecraft:stone_slab-8
rule18=0,100,minecraft:wooden_door-1
rule19=0,100,minecraft:carpet-14
rule20=0,100,minecraft:wooden_door-3
rule21=0,100,BiblioCraft:BiblioTable-1
rule22=2,100,WallSign:null:null:null:null-2
rule23=0,100,minecraft:oak_stairs-0
rule24=2,100,WallSign:null:null:null:null-3
rule25=0,100,TConstruct:GlassBlock-0
rule26=0,100,minecraft:carpet-11
rule27=0,100,minecraft:wooden_door-9
rule28=0,100,minecraft:wooden_door-8
rule29=0,100,minecraft:flower_pot-0
rule30=0,100,Railcraft:tile.railcraft.lantern.stone-0

layer
1,1,1,1,1,1,1,1,1,1
1,2,3,3,2,3,3,3,2,1
1,4,6,6,6,6,6,5,4,0
7,4,6,6,6,6,6,6,4,7
10,4,6,6,9,9,6,6,4,8
10,4,6,6,9,9,6,6,4,8
11,4,6,6,6,6,6,6,4,11
1,4,6,6,6,6,6,6,4,0
1,2,3,3,2,3,3,3,2,1
1,1,1,1,1,1,1,1,1,1
endlayer

layer
0,0,0,0,12,0,0,0,0,0
0,2,13,13,2,13,13,13,2,0
0,13,15,0,0,0,0,14,13,0
0,13,17,17,16,12,0,12,13,0
12,20,19,19,19,19,19,19,18,0
0,20,19,19,19,19,19,19,18,0
0,13,0,0,12,12,0,0,13,0
0,13,21,24,23,23,22,21,13,0
0,2,13,13,2,13,13,13,2,0
0,12,0,0,0,0,0,0,0,0
endlayer

layer
0,0,0,0,0,0,0,0,0,0
0,2,25,25,2,25,25,25,2,0
0,25,0,0,0,0,0,0,25,0
0,13,26,26,26,0,0,0,13,0
0,28,0,0,12,12,0,0,27,0
0,27,0,0,12,0,0,0,28,0
0,13,0,0,0,0,0,0,13,0
0,25,29,0,0,0,0,29,25,0
0,2,25,25,2,25,25,25,2,0
12,0,0,0,0,0,0,0,0,0
endlayer

layer
0,0,0,0,0,0,0,0,0,0
0,2,25,25,2,25,25,25,2,0
0,13,0,0,0,0,0,0,25,0
12,13,0,0,0,0,0,0,13,0
0,13,0,0,0,0,0,0,13,0
12,13,0,0,0,0,0,0,13,0
0,13,0,0,0,0,0,0,13,0
0,13,0,0,0,0,0,0,25,0
0,2,25,25,2,25,25,25,2,0
0,0,0,0,0,0,0,0,0,0
endlayer

layer
0,4,0,0,0,12,0,0,0,0
3,2,3,13,2,25,25,25,2,0
0,4,30,0,0,0,0,0,25,0
0,4,0,0,0,0,0,0,13,0
0,4,0,0,0,0,0,0,25,0
0,4,0,0,0,0,0,0,25,0
0,4,0,0,0,0,0,0,13,0
0,4,30,0,0,0,0,0,25,0
0,2,3,13,2,25,25,25,2,0
0,4,0,0,0,0,0,0,0,0
endlayer

layer
0,0,0,0,4,0,0,0,0,0
0,0,3,3,2,3,13,13,2,0
0,0,25,25,4,0,0,30,13,0
0,0,25,25,4,0,0,0,13,0
0,0,25,25,4,0,0,0,13,0
0,0,25,25,4,0,0,0,13,0
0,0,25,25,4,0,0,0,13,0
0,0,25,25,4,0,0,30,13,0
0,0,3,3,2,3,13,13,2,0
0,0,0,0,4,0,0,0,0,0
endlayer

layer
0,0,0,0,0,0,0,0,4,0
0,0,0,0,0,3,3,3,2,3
0,0,0,0,0,25,25,25,4,0
3,0,0,0,0,25,25,25,4,0
0,0,0,0,0,25,25,25,4,0
0,0,0,0,0,25,25,25,4,0
0,0,0,0,0,25,25,25,4,0
0,0,0,0,0,25,25,25,4,0
0,0,0,0,0,3,3,3,2,3
0,0,0,0,0,0,0,0,4,0
endlayer

